Workbook

Sheet Início
A1: CONTROLE DE ORÇAMENTO E DESPESAS - INÍCIO

Sheet Orçamento
A1: CONTROLE DE ORÇAMENTO E DESPESAS - ORÇAMENTO
B3: JANEIRO | E3: FEVEREIRO | H3: MARÇO | K3: ABRIL | N3: MAIO | Q3: JUNHO | T3: JULHO | W3: AGOSTO | Z3: SETEMBRO | AC3: OUTUBRO | AF3: NOVEMBRO | AI3: DEZEMBRO | AL3: TOTAL
A4: ORÇAMENTO | AL4: =SUM(B4:AK4) -> 0
A5: ORÇADO MENOS PLANEJADO | B5: =B4-B75 -> 0 | E5: =E4-E75 -> 0 | H5: =H4-H75 -> 0 | K5: =K4-K75 -> 0 | N5: =N4-N75 -> 0 | Q5: =Q4-Q75 -> 0 | T5: =T4-T75 -> 0 | W5: =W4-W75 -> 0 | Z5: =Z4-Z75 -> 0 | AC5: =AC4-AC75 -> 0 | AF5: =AF4-AF75 -> 0 | AI5: =AI4-AI75 -> 0 | AL5: =SUM(B5:AK5) -> 0
A6: DIFERENÇA (%) | B6: =IF(B4<>0,(B5/B4),"n/a") -> n/a | E6: =IF(E4<>0,(E5/E4),"n/a") -> n/a | H6: =IF(H4<>0,(H5/H4),"n/a") -> n/a | K6: =IF(K4<>0,(K5/K4),"n/a") -> n/a | N6: =IF(N4<>0,(N5/N4),"n/a") -> n/a | Q6: =IF(Q4<>0,(Q5/Q4),"n/a") -> n/a | T6: =IF(T4<>0,(T5/T4),"n/a") -> n/a | W6: =IF(W4<>0,(W5/W4),"n/a") -> n/a | Z6: =IF(Z4<>0,(Z5/Z4),"n/a") -> n/a | AC6: =IF(AC4<>0,(AC5/AC4),"n/a") -> n/a | AF6: =IF(AF4<>0,(AF5/AF4),"n/a") -> n/a | AI6: =IF(AI4<>0,(AI5/AI4),"n/a") -> n/a | AL6: =IF(AL4<>0,(AL5/AL4),"n/a") -> n/a
B7: Planejado | C7: Realizado | D7: Dif. | E7: Planejado | F7: Realizado | G7: Dif. | H7: Planejado | I7: Realizado | J7: Dif. | K7: Planejado | L7: Realizado | M7: Dif. | N7: Planejado | O7: Realizado | P7: Dif. | Q7: Planejado | R7: Realizado | S7: Dif. | T7: Planejado | U7: Realizado | V7: Dif. | W7: Planejado | X7: Realizado | Y7: Dif. | Z7: Planejado | AA7: Realizado | AB7: Dif. | AC7: Planejado | AD7: Realizado | AE7: Dif. | AF7: Planejado | AG7: Realizado | AH7: Dif. | AI7: Planejado | AJ7: Realizado | AK7: Dif. | AL7: Planejado | AM7: Realizado | AN7: Dif.
A9: PRODUÇÃO/INDUSTRIAL | B9: =SUM(B10:B18) -> 0 | C9: =SUM(C10:C18) -> 0 | D9: =B9-C9 -> 0 | E9: =SUM(E10:E18) -> 0 | F9: =SUM(F10:F18) -> 0 | G9: =E9-F9 -> 0 | H9: =SUM(H10:H18) -> 0 | I9: =SUM(I10:I18) -> 0 | J9: =H9-I9 -> 0 | K9: =SUM(K10:K18) -> 0 | L9: =SUM(L10:L18) -> 0 | M9: =K9-L9 -> 0 | N9: =SUM(N10:N18) -> 0 | O9: =SUM(O10:O18) -> 0 | P9: =N9-O9 -> 0 | Q9: =SUM(Q10:Q18) -> 0 | R9: =SUM(R10:R18) -> 0 | S9: =Q9-R9 -> 0 | T9: =SUM(T10:T18) -> 0 | U9: =SUM(U10:U18) -> 0 | V9: =T9-U9 -> 0 | W9: =SUM(W10:W18) -> 0 | X9: =SUM(X10:X18) -> 0 | Y9: =W9-X9 -> 0 | Z9: =SUM(Z10:Z18) -> 0 | AA9: =SUM(AA10:AA18) -> 0 | AB9: =Z9-AA9 -> 0 | AC9: =SUM(AC10:AC18) -> 0 | AD9: =SUM(AD10:AD18) -> 0 | AE9: =AC9-AD9 -> 0 | AF9: =SUM(AF10:AF18) -> 0 | AG9: =SUM(AG10:AG18) -> 0 | AH9: =AF9-AG9 -> 0 | AI9: =SUM(AI10:AI18) -> 0 | AJ9: =SUM(AJ10:AJ18) -> 0 | AK9: =AI9-AJ9 -> 0 | AL9: =SUM(AL10:AL18) -> 0 | AM9: =SUM(AM10:AM18) -> 0 | AN9: =AL9-AM9 -> 0
A10: Matéria-prima | D10: =B10-C10 -> 0 | G10: =E10-F10 -> 0 | J10: =H10-I10 -> 0 | M10: =K10-L10 -> 0 | P10: =N10-O10 -> 0 | S10: =Q10-R10 -> 0 | V10: =T10-U10 -> 0 | Y10: =W10-X10 -> 0 | AB10: =Z10-AA10 -> 0 | AE10: =AC10-AD10 -> 0 | AH10: =AF10-AG10 -> 0 | AK10: =AI10-AJ10 -> 0 | AL10: =B10+E10+H10+K10+N10+Q10+T10+W10+Z10+AC10+AF10+AI10 -> 0 | AM10: =C10+F10+I10+L10+O10+R10+U10+X10+AA10+AD10+AG10+AJ10 -> 0 | AN10: =AL10-AM10 -> 0
A11: Mão-de-obra operação | D11: =B11-C11 -> 0 | G11: =E11-F11 -> 0 | J11: =H11-I11 -> 0 | M11: =K11-L11 -> 0 | P11: =N11-O11 -> 0 | S11: =Q11-R11 -> 0 | V11: =T11-U11 -> 0 | Y11: =W11-X11 -> 0 | AB11: =Z11-AA11 -> 0 | AE11: =AC11-AD11 -> 0 | AH11: =AF11-AG11 -> 0 | AK11: =AI11-AJ11 -> 0 | AL11: =B11+E11+H11+K11+N11+Q11+T11+W11+Z11+AC11+AF11+AI11 -> 0 | AM11: =C11+F11+I11+L11+O11+R11+U11+X11+AA11+AD11+AG11+AJ11 -> 0 | AN11: =AL11-AM11 -> 0
A12: Manutenção | D12: =B12-C12 -> 0 | G12: =E12-F12 -> 0 | J12: =H12-I12 -> 0 | M12: =K12-L12 -> 0 | P12: =N12-O12 -> 0 | S12: =Q12-R12 -> 0 | V12: =T12-U12 -> 0 | Y12: =W12-X12 -> 0 | AB12: =Z12-AA12 -> 0 | AE12: =AC12-AD12 -> 0 | AH12: =AF12-AG12 -> 0 | AK12: =AI12-AJ12 -> 0 | AL12: =B12+E12+H12+K12+N12+Q12+T12+W12+Z12+AC12+AF12+AI12 -> 0 | AM12: =C12+F12+I12+L12+O12+R12+U12+X12+AA12+AD12+AG12+AJ12 -> 0 | AN12: =AL12-AM12 -> 0
A13: Material indireto | D13: =B13-C13 -> 0 | G13: =E13-F13 -> 0 | J13: =H13-I13 -> 0 | M13: =K13-L13 -> 0 | P13: =N13-O13 -> 0 | S13: =Q13-R13 -> 0 | V13: =T13-U13 -> 0 | Y13: =W13-X13 -> 0 | AB13: =Z13-AA13 -> 0 | AE13: =AC13-AD13 -> 0 | AH13: =AF13-AG13 -> 0 | AK13: =AI13-AJ13 -> 0 | AL13: =B13+E13+H13+K13+N13+Q13+T13+W13+Z13+AC13+AF13+AI13 -> 0 | AM13: =C13+F13+I13+L13+O13+R13+U13+X13+AA13+AD13+AG13+AJ13 -> 0 | AN13: =AL13-AM13 -> 0
A14: Estoques de Matéria-prima | D14: =B14-C14 -> 0 | G14: =E14-F14 -> 0 | J14: =H14-I14 -> 0 | M14: =K14-L14 -> 0 | P14: =N14-O14 -> 0 | S14: =Q14-R14 -> 0 | V14: =T14-U14 -> 0 | Y14: =W14-X14 -> 0 | AB14: =Z14-AA14 -> 0 | AE14: =AC14-AD14 -> 0 | AH14: =AF14-AG14 -> 0 | AK14: =AI14-AJ14 -> 0 | AL14: =B14+E14+H14+K14+N14+Q14+T14+W14+Z14+AC14+AF14+AI14 -> 0 | AM14: =C14+F14+I14+L14+O14+R14+U14+X14+AA14+AD14+AG14+AJ14 -> 0 | AN14: =AL14-AM14 -> 0
A15: Equipamentos | D15: =B15-C15 -> 0 | G15: =E15-F15 -> 0 | J15: =H15-I15 -> 0 | M15: =K15-L15 -> 0 | P15: =N15-O15 -> 0 | S15: =Q15-R15 -> 0 | V15: =T15-U15 -> 0 | Y15: =W15-X15 -> 0 | AB15: =Z15-AA15 -> 0 | AE15: =AC15-AD15 -> 0 | AH15: =AF15-AG15 -> 0 | AK15: =AI15-AJ15 -> 0 | AL15: =B15+E15+H15+K15+N15+Q15+T15+W15+Z15+AC15+AF15+AI15 -> 0 | AM15: =C15+F15+I15+L15+O15+R15+U15+X15+AA15+AD15+AG15+AJ15 -> 0 | AN15: =AL15-AM15 -> 0
A16: Outras despesas | D16: =B16-C16 -> 0 | G16: =E16-F16 -> 0 | J16: =H16-I16 -> 0 | M16: =K16-L16 -> 0 | P16: =N16-O16 -> 0 | S16: =Q16-R16 -> 0 | V16: =T16-U16 -> 0 | Y16: =W16-X16 -> 0 | AB16: =Z16-AA16 -> 0 | AE16: =AC16-AD16 -> 0 | AH16: =AF16-AG16 -> 0 | AK16: =AI16-AJ16 -> 0 | AL16: =B16+E16+H16+K16+N16+Q16+T16+W16+Z16+AC16+AF16+AI16 -> 0 | AM16: =C16+F16+I16+L16+O16+R16+U16+X16+AA16+AD16+AG16+AJ16 -> 0 | AN16: =AL16-AM16 -> 0
D17: =B17-C17 -> 0 | G17: =E17-F17 -> 0 | J17: =H17-I17 -> 0 | M17: =K17-L17 -> 0 | P17: =N17-O17 -> 0 | S17: =Q17-R17 -> 0 | V17: =T17-U17 -> 0 | Y17: =W17-X17 -> 0 | AB17: =Z17-AA17 -> 0 | AE17: =AC17-AD17 -> 0 | AH17: =AF17-AG17 -> 0 | AK17: =AI17-AJ17 -> 0 | AL17: =B17+E17+H17+K17+N17+Q17+T17+W17+Z17+AC17+AF17+AI17 -> 0 | AM17: =C17+F17+I17+L17+O17+R17+U17+X17+AA17+AD17+AG17+AJ17 -> 0 | AN17: =AL17-AM17 -> 0
D18: =B18-C18 -> 0 | G18: =E18-F18 -> 0 | J18: =H18-I18 -> 0 | M18: =K18-L18 -> 0 | P18: =N18-O18 -> 0 | S18: =Q18-R18 -> 0 | V18: =T18-U18 -> 0 | Y18: =W18-X18 -> 0 | AB18: =Z18-AA18 -> 0 | AE18: =AC18-AD18 -> 0 | AH18: =AF18-AG18 -> 0 | AK18: =AI18-AJ18 -> 0 | AL18: =B18+E18+H18+K18+N18+Q18+T18+W18+Z18+AC18+AF18+AI18 -> 0 | AM18: =C18+F18+I18+L18+O18+R18+U18+X18+AA18+AD18+AG18+AJ18 -> 0 | AN18: =AL18-AM18 -> 0
A20: COMERCIAL/VENDAS | B20: =SUM(B21:B29) -> 0 | C20: =SUM(C21:C29) -> 0 | D20: =B20-C20 -> 0 | E20: =SUM(E21:E29) -> 0 | F20: =SUM(F21:F29) -> 0 | G20: =E20-F20 -> 0 | H20: =SUM(H21:H29) -> 0 | I20: =SUM(I21:I29) -> 0 | J20: =H20-I20 -> 0 | K20: =SUM(K21:K29) -> 0 | L20: =SUM(L21:L29) -> 0 | M20: =K20-L20 -> 0 | N20: =SUM(N21:N29) -> 0 | O20: =SUM(O21:O29) -> 0 | P20: =N20-O20 -> 0 | Q20: =SUM(Q21:Q29) -> 0 | R20: =SUM(R21:R29) -> 0 | S20: =Q20-R20 -> 0 | T20: =SUM(T21:T29) -> 0 | U20: =SUM(U21:U29) -> 0 | V20: =T20-U20 -> 0 | W20: =SUM(W21:W29) -> 0 | X20: =SUM(X21:X29) -> 0 | Y20: =W20-X20 -> 0 | Z20: =SUM(Z21:Z29) -> 0 | AA20: =SUM(AA21:AA29) -> 0 | AB20: =Z20-AA20 -> 0 | AC20: =SUM(AC21:AC29) -> 0 | AD20: =SUM(AD21:AD29) -> 0 | AE20: =AC20-AD20 -> 0 | AF20: =SUM(AF21:AF29) -> 0 | AG20: =SUM(AG21:AG29) -> 0 | AH20: =AF20-AG20 -> 0 | AI20: =SUM(AI21:AI29) -> 0 | AJ20: =SUM(AJ21:AJ29) -> 0 | AK20: =AI20-AJ20 -> 0 | AL20: =SUM(AL21:AL29) -> 0 | AM20: =SUM(AM21:AM29) -> 0 | AN20: =AL20-AM20 -> 0
A21: Transporte de produtos | D21: =B21-C21 -> 0 | G21: =E21-F21 -> 0 | J21: =H21-I21 -> 0 | M21: =K21-L21 -> 0 | P21: =N21-O21 -> 0 | S21: =Q21-R21 -> 0 | V21: =T21-U21 -> 0 | Y21: =W21-X21 -> 0 | AB21: =Z21-AA21 -> 0 | AE21: =AC21-AD21 -> 0 | AH21: =AF21-AG21 -> 0 | AK21: =AI21-AJ21 -> 0 | AL21: =B21+E21+H21+K21+N21+Q21+T21+W21+Z21+AC21+AF21+AI21 -> 0 | AM21: =C21+F21+I21+L21+O21+R21+U21+X21+AA21+AD21+AG21+AJ21 -> 0 | AN21: =AL21-AM21 -> 0
A22: Comissão de vendas | D22: =B22-C22 -> 0 | G22: =E22-F22 -> 0 | J22: =H22-I22 -> 0 | M22: =K22-L22 -> 0 | P22: =N22-O22 -> 0 | S22: =Q22-R22 -> 0 | V22: =T22-U22 -> 0 | Y22: =W22-X22 -> 0 | AB22: =Z22-AA22 -> 0 | AE22: =AC22-AD22 -> 0 | AH22: =AF22-AG22 -> 0 | AK22: =AI22-AJ22 -> 0 | AL22: =B22+E22+H22+K22+N22+Q22+T22+W22+Z22+AC22+AF22+AI22 -> 0 | AM22: =C22+F22+I22+L22+O22+R22+U22+X22+AA22+AD22+AG22+AJ22 -> 0 | AN22: =AL22-AM22 -> 0
A23: Transporte de resíduos | D23: =B23-C23 -> 0 | G23: =E23-F23 -> 0 | J23: =H23-I23 -> 0 | M23: =K23-L23 -> 0 | P23: =N23-O23 -> 0 | S23: =Q23-R23 -> 0 | V23: =T23-U23 -> 0 | Y23: =W23-X23 -> 0 | AB23: =Z23-AA23 -> 0 | AE23: =AC23-AD23 -> 0 | AH23: =AF23-AG23 -> 0 | AK23: =AI23-AJ23 -> 0 | AL23: =B23+E23+H23+K23+N23+Q23+T23+W23+Z23+AC23+AF23+AI23 -> 0 | AM23: =C23+F23+I23+L23+O23+R23+U23+X23+AA23+AD23+AG23+AJ23 -> 0 | AN23: =AL23-AM23 -> 0
A24: Outras despesas | D24: =B24-C24 -> 0 | G24: =E24-F24 -> 0 | J24: =H24-I24 -> 0 | M24: =K24-L24 -> 0 | P24: =N24-O24 -> 0 | S24: =Q24-R24 -> 0 | V24: =T24-U24 -> 0 | Y24: =W24-X24 -> 0 | AB24: =Z24-AA24 -> 0 | AE24: =AC24-AD24 -> 0 | AH24: =AF24-AG24 -> 0 | AK24: =AI24-AJ24 -> 0 | AL24: =B24+E24+H24+K24+N24+Q24+T24+W24+Z24+AC24+AF24+AI24 -> 0 | AM24: =C24+F24+I24+L24+O24+R24+U24+X24+AA24+AD24+AG24+AJ24 -> 0 | AN24: =AL24-AM24 -> 0
D25: =B25-C25 -> 0 | G25: =E25-F25 -> 0 | J25: =H25-I25 -> 0 | M25: =K25-L25 -> 0 | P25: =N25-O25 -> 0 | S25: =Q25-R25 -> 0 | V25: =T25-U25 -> 0 | Y25: =W25-X25 -> 0 | AB25: =Z25-AA25 -> 0 | AE25: =AC25-AD25 -> 0 | AH25: =AF25-AG25 -> 0 | AK25: =AI25-AJ25 -> 0 | AL25: =B25+E25+H25+K25+N25+Q25+T25+W25+Z25+AC25+AF25+AI25 -> 0 | AM25: =C25+F25+I25+L25+O25+R25+U25+X25+AA25+AD25+AG25+AJ25 -> 0 | AN25: =AL25-AM25 -> 0
D26: =B26-C26 -> 0 | G26: =E26-F26 -> 0 | J26: =H26-I26 -> 0 | M26: =K26-L26 -> 0 | P26: =N26-O26 -> 0 | S26: =Q26-R26 -> 0 | V26: =T26-U26 -> 0 | Y26: =W26-X26 -> 0 | AB26: =Z26-AA26 -> 0 | AE26: =AC26-AD26 -> 0 | AH26: =AF26-AG26 -> 0 | AK26: =AI26-AJ26 -> 0 | AL26: =B26+E26+H26+K26+N26+Q26+T26+W26+Z26+AC26+AF26+AI26 -> 0 | AM26: =C26+F26+I26+L26+O26+R26+U26+X26+AA26+AD26+AG26+AJ26 -> 0 | AN26: =AL26-AM26 -> 0
D27: =B27-C27 -> 0 | G27: =E27-F27 -> 0 | J27: =H27-I27 -> 0 | M27: =K27-L27 -> 0 | P27: =N27-O27 -> 0 | S27: =Q27-R27 -> 0 | V27: =T27-U27 -> 0 | Y27: =W27-X27 -> 0 | AB27: =Z27-AA27 -> 0 | AE27: =AC27-AD27 -> 0 | AH27: =AF27-AG27 -> 0 | AK27: =AI27-AJ27 -> 0 | AL27: =B27+E27+H27+K27+N27+Q27+T27+W27+Z27+AC27+AF27+AI27 -> 0 | AM27: =C27+F27+I27+L27+O27+R27+U27+X27+AA27+AD27+AG27+AJ27 -> 0 | AN27: =AL27-AM27 -> 0
D28: =B28-C28 -> 0 | G28: =E28-F28 -> 0 | J28: =H28-I28 -> 0 | M28: =K28-L28 -> 0 | P28: =N28-O28 -> 0 | S28: =Q28-R28 -> 0 | V28: =T28-U28 -> 0 | Y28: =W28-X28 -> 0 | AB28: =Z28-AA28 -> 0 | AE28: =AC28-AD28 -> 0 | AH28: =AF28-AG28 -> 0 | AK28: =AI28-AJ28 -> 0 | AL28: =B28+E28+H28+K28+N28+Q28+T28+W28+Z28+AC28+AF28+AI28 -> 0 | AM28: =C28+F28+I28+L28+O28+R28+U28+X28+AA28+AD28+AG28+AJ28 -> 0 | AN28: =AL28-AM28 -> 0
D29: =B29-C29 -> 0 | G29: =E29-F29 -> 0 | J29: =H29-I29 -> 0 | M29: =K29-L29 -> 0 | P29: =N29-O29 -> 0 | S29: =Q29-R29 -> 0 | V29: =T29-U29 -> 0 | Y29: =W29-X29 -> 0 | AB29: =Z29-AA29 -> 0 | AE29: =AC29-AD29 -> 0 | AH29: =AF29-AG29 -> 0 | AK29: =AI29-AJ29 -> 0 | AL29: =B29+E29+H29+K29+N29+Q29+T29+W29+Z29+AC29+AF29+AI29 -> 0 | AM29: =C29+F29+I29+L29+O29+R29+U29+X29+AA29+AD29+AG29+AJ29 -> 0 | AN29: =AL29-AM29 -> 0
A31: MARKETING e PUBLICIDADE | B31: =SUM(B32:B40) -> 0 | C31: =SUM(C32:C40) -> 0 | D31: =B31-C31 -> 0 | E31: =SUM(E32:E40) -> 0 | F31: =SUM(F32:F40) -> 0 | G31: =E31-F31 -> 0 | H31: =SUM(H32:H40) -> 0 | I31: =SUM(I32:I40) -> 0 | J31: =H31-I31 -> 0 | K31: =SUM(K32:K40) -> 0 | L31: =SUM(L32:L40) -> 0 | M31: =K31-L31 -> 0 | N31: =SUM(N32:N40) -> 0 | O31: =SUM(O32:O40) -> 0 | P31: =N31-O31 -> 0 | Q31: =SUM(Q32:Q40) -> 0 | R31: =SUM(R32:R40) -> 0 | S31: =Q31-R31 -> 0 | T31: =SUM(T32:T40) -> 0 | U31: =SUM(U32:U40) -> 0 | V31: =T31-U31 -> 0 | W31: =SUM(W32:W40) -> 0 | X31: =SUM(X32:X40) -> 0 | Y31: =W31-X31 -> 0 | Z31: =SUM(Z32:Z40) -> 0 | AA31: =SUM(AA32:AA40) -> 0 | AB31: =Z31-AA31 -> 0 | AC31: =SUM(AC32:AC40) -> 0 | AD31: =SUM(AD32:AD40) -> 0 | AE31: =AC31-AD31 -> 0 | AF31: =SUM(AF32:AF40) -> 0 | AG31: =SUM(AG32:AG40) -> 0 | AH31: =AF31-AG31 -> 0 | AI31: =SUM(AI32:AI40) -> 0 | AJ31: =SUM(AJ32:AJ40) -> 0 | AK31: =AI31-AJ31 -> 0 | AL31: =SUM(AL32:AL40) -> 0 | AM31: =SUM(AM32:AM40) -> 0 | AN31: =AL31-AM31 -> 0
A32: Propaganda | D32: =B32-C32 -> 0 | G32: =E32-F32 -> 0 | J32: =H32-I32 -> 0 | M32: =K32-L32 -> 0 | P32: =N32-O32 -> 0 | S32: =Q32-R32 -> 0 | V32: =T32-U32 -> 0 | Y32: =W32-X32 -> 0 | AB32: =Z32-AA32 -> 0 | AE32: =AC32-AD32 -> 0 | AH32: =AF32-AG32 -> 0 | AK32: =AI32-AJ32 -> 0 | AL32: =B32+E32+H32+K32+N32+Q32+T32+W32+Z32+AC32+AF32+AI32 -> 0 | AM32: =C32+F32+I32+L32+O32+R32+U32+X32+AA32+AD32+AG32+AJ32 -> 0 | AN32: =AL32-AM32 -> 0
A33: Endomarketing | D33: =B33-C33 -> 0 | G33: =E33-F33 -> 0 | J33: =H33-I33 -> 0 | M33: =K33-L33 -> 0 | P33: =N33-O33 -> 0 | S33: =Q33-R33 -> 0 | V33: =T33-U33 -> 0 | Y33: =W33-X33 -> 0 | AB33: =Z33-AA33 -> 0 | AE33: =AC33-AD33 -> 0 | AH33: =AF33-AG33 -> 0 | AK33: =AI33-AJ33 -> 0 | AL33: =B33+E33+H33+K33+N33+Q33+T33+W33+Z33+AC33+AF33+AI33 -> 0 | AM33: =C33+F33+I33+L33+O33+R33+U33+X33+AA33+AD33+AG33+AJ33 -> 0 | AN33: =AL33-AM33 -> 0
A34: Plano de marketing | D34: =B34-C34 -> 0 | G34: =E34-F34 -> 0 | J34: =H34-I34 -> 0 | M34: =K34-L34 -> 0 | P34: =N34-O34 -> 0 | S34: =Q34-R34 -> 0 | V34: =T34-U34 -> 0 | Y34: =W34-X34 -> 0 | AB34: =Z34-AA34 -> 0 | AE34: =AC34-AD34 -> 0 | AH34: =AF34-AG34 -> 0 | AK34: =AI34-AJ34 -> 0 | AL34: =B34+E34+H34+K34+N34+Q34+T34+W34+Z34+AC34+AF34+AI34 -> 0 | AM34: =C34+F34+I34+L34+O34+R34+U34+X34+AA34+AD34+AG34+AJ34 -> 0 | AN34: =AL34-AM34 -> 0
A35: Pesquisa de mercado | D35: =B35-C35 -> 0 | G35: =E35-F35 -> 0 | J35: =H35-I35 -> 0 | M35: =K35-L35 -> 0 | P35: =N35-O35 -> 0 | S35: =Q35-R35 -> 0 | V35: =T35-U35 -> 0 | Y35: =W35-X35 -> 0 | AB35: =Z35-AA35 -> 0 | AE35: =AC35-AD35 -> 0 | AH35: =AF35-AG35 -> 0 | AK35: =AI35-AJ35 -> 0 | AL35: =B35+E35+H35+K35+N35+Q35+T35+W35+Z35+AC35+AF35+AI35 -> 0 | AM35: =C35+F35+I35+L35+O35+R35+U35+X35+AA35+AD35+AG35+AJ35 -> 0 | AN35: =AL35-AM35 -> 0
A36: Marketing virtual | D36: =B36-C36 -> 0 | G36: =E36-F36 -> 0 | J36: =H36-I36 -> 0 | M36: =K36-L36 -> 0 | P36: =N36-O36 -> 0 | S36: =Q36-R36 -> 0 | V36: =T36-U36 -> 0 | Y36: =W36-X36 -> 0 | AB36: =Z36-AA36 -> 0 | AE36: =AC36-AD36 -> 0 | AH36: =AF36-AG36 -> 0 | AK36: =AI36-AJ36 -> 0 | AL36: =B36+E36+H36+K36+N36+Q36+T36+W36+Z36+AC36+AF36+AI36 -> 0 | AM36: =C36+F36+I36+L36+O36+R36+U36+X36+AA36+AD36+AG36+AJ36 -> 0 | AN36: =AL36-AM36 -> 0
A37: Outras despesas | D37: =B37-C37 -> 0 | G37: =E37-F37 -> 0 | J37: =H37-I37 -> 0 | M37: =K37-L37 -> 0 | P37: =N37-O37 -> 0 | S37: =Q37-R37 -> 0 | V37: =T37-U37 -> 0 | Y37: =W37-X37 -> 0 | AB37: =Z37-AA37 -> 0 | AE37: =AC37-AD37 -> 0 | AH37: =AF37-AG37 -> 0 | AK37: =AI37-AJ37 -> 0 | AL37: =B37+E37+H37+K37+N37+Q37+T37+W37+Z37+AC37+AF37+AI37 -> 0 | AM37: =C37+F37+I37+L37+O37+R37+U37+X37+AA37+AD37+AG37+AJ37 -> 0 | AN37: =AL37-AM37 -> 0
D38: =B38-C38 -> 0 | G38: =E38-F38 -> 0 | J38: =H38-I38 -> 0 | M38: =K38-L38 -> 0 | P38: =N38-O38 -> 0 | S38: =Q38-R38 -> 0 | V38: =T38-U38 -> 0 | Y38: =W38-X38 -> 0 | AB38: =Z38-AA38 -> 0 | AE38: =AC38-AD38 -> 0 | AH38: =AF38-AG38 -> 0 | AK38: =AI38-AJ38 -> 0 | AL38: =B38+E38+H38+K38+N38+Q38+T38+W38+Z38+AC38+AF38+AI38 -> 0 | AM38: =C38+F38+I38+L38+O38+R38+U38+X38+AA38+AD38+AG38+AJ38 -> 0 | AN38: =AL38-AM38 -> 0
D39: =B39-C39 -> 0 | G39: =E39-F39 -> 0 | J39: =H39-I39 -> 0 | M39: =K39-L39 -> 0 | P39: =N39-O39 -> 0 | S39: =Q39-R39 -> 0 | V39: =T39-U39 -> 0 | Y39: =W39-X39 -> 0 | AB39: =Z39-AA39 -> 0 | AE39: =AC39-AD39 -> 0 | AH39: =AF39-AG39 -> 0 | AK39: =AI39-AJ39 -> 0 | AL39: =B39+E39+H39+K39+N39+Q39+T39+W39+Z39+AC39+AF39+AI39 -> 0 | AM39: =C39+F39+I39+L39+O39+R39+U39+X39+AA39+AD39+AG39+AJ39 -> 0 | AN39: =AL39-AM39 -> 0
D40: =B40-C40 -> 0 | G40: =E40-F40 -> 0 | J40: =H40-I40 -> 0 | M40: =K40-L40 -> 0 | P40: =N40-O40 -> 0 | S40: =Q40-R40 -> 0 | V40: =T40-U40 -> 0 | Y40: =W40-X40 -> 0 | AB40: =Z40-AA40 -> 0 | AE40: =AC40-AD40 -> 0 | AH40: =AF40-AG40 -> 0 | AK40: =AI40-AJ40 -> 0 | AL40: =B40+E40+H40+K40+N40+Q40+T40+W40+Z40+AC40+AF40+AI40 -> 0 | AM40: =C40+F40+I40+L40+O40+R40+U40+X40+AA40+AD40+AG40+AJ40 -> 0 | AN40: =AL40-AM40 -> 0
A42: DEPARTAMENTO PESSOAL | B42: =SUM(B43:B51) -> 0 | C42: =SUM(C43:C51) -> 0 | D42: =B42-C42 -> 0 | E42: =SUM(E43:E51) -> 0 | F42: =SUM(F43:F51) -> 0 | G42: =E42-F42 -> 0 | H42: =SUM(H43:H51) -> 0 | I42: =SUM(I43:I51) -> 0 | J42: =H42-I42 -> 0 | K42: =SUM(K43:K51) -> 0 | L42: =SUM(L43:L51) -> 0 | M42: =K42-L42 -> 0 | N42: =SUM(N43:N51) -> 0 | O42: =SUM(O43:O51) -> 0 | P42: =N42-O42 -> 0 | Q42: =SUM(Q43:Q51) -> 0 | R42: =SUM(R43:R51) -> 0 | S42: =Q42-R42 -> 0 | T42: =SUM(T43:T51) -> 0 | U42: =SUM(U43:U51) -> 0 | V42: =T42-U42 -> 0 | W42: =SUM(W43:W51) -> 0 | X42: =SUM(X43:X51) -> 0 | Y42: =W42-X42 -> 0 | Z42: =SUM(Z43:Z51) -> 0 | AA42: =SUM(AA43:AA51) -> 0 | AB42: =Z42-AA42 -> 0 | AC42: =SUM(AC43:AC51) -> 0 | AD42: =SUM(AD43:AD51) -> 0 | AE42: =AC42-AD42 -> 0 | AF42: =SUM(AF43:AF51) -> 0 | AG42: =SUM(AG43:AG51) -> 0 | AH42: =AF42-AG42 -> 0 | AI42: =SUM(AI43:AI51) -> 0 | AJ42: =SUM(AJ43:AJ51) -> 0 | AK42: =AI42-AJ42 -> 0 | AL42: =SUM(AL43:AL51) -> 0 | AM42: =SUM(AM43:AM51) -> 0 | AN42: =AL42-AM42 -> 0
A43: Pró-labore | D43: =B43-C43 -> 0 | G43: =E43-F43 -> 0 | J43: =H43-I43 -> 0 | M43: =K43-L43 -> 0 | P43: =N43-O43 -> 0 | S43: =Q43-R43 -> 0 | V43: =T43-U43 -> 0 | Y43: =W43-X43 -> 0 | AB43: =Z43-AA43 -> 0 | AE43: =AC43-AD43 -> 0 | AH43: =AF43-AG43 -> 0 | AK43: =AI43-AJ43 -> 0 | AL43: =B43+E43+H43+K43+N43+Q43+T43+W43+Z43+AC43+AF43+AI43 -> 0 | AM43: =C43+F43+I43+L43+O43+R43+U43+X43+AA43+AD43+AG43+AJ43 -> 0 | AN43: =AL43-AM43 -> 0
A44: Auxilio doença | D44: =B44-C44 -> 0 | G44: =E44-F44 -> 0 | J44: =H44-I44 -> 0 | M44: =K44-L44 -> 0 | P44: =N44-O44 -> 0 | S44: =Q44-R44 -> 0 | V44: =T44-U44 -> 0 | Y44: =W44-X44 -> 0 | AB44: =Z44-AA44 -> 0 | AE44: =AC44-AD44 -> 0 | AH44: =AF44-AG44 -> 0 | AK44: =AI44-AJ44 -> 0 | AL44: =B44+E44+H44+K44+N44+Q44+T44+W44+Z44+AC44+AF44+AI44 -> 0 | AM44: =C44+F44+I44+L44+O44+R44+U44+X44+AA44+AD44+AG44+AJ44 -> 0 | AN44: =AL44-AM44 -> 0
A45: Benefícios | D45: =B45-C45 -> 0 | G45: =E45-F45 -> 0 | J45: =H45-I45 -> 0 | M45: =K45-L45 -> 0 | P45: =N45-O45 -> 0 | S45: =Q45-R45 -> 0 | V45: =T45-U45 -> 0 | Y45: =W45-X45 -> 0 | AB45: =Z45-AA45 -> 0 | AE45: =AC45-AD45 -> 0 | AH45: =AF45-AG45 -> 0 | AK45: =AI45-AJ45 -> 0 | AL45: =B45+E45+H45+K45+N45+Q45+T45+W45+Z45+AC45+AF45+AI45 -> 0 | AM45: =C45+F45+I45+L45+O45+R45+U45+X45+AA45+AD45+AG45+AJ45 -> 0 | AN45: =AL45-AM45 -> 0
...

Sheet Gráficos
A1: CONTROLE DE ORÇAMENTO E DESPESAS - GRÁFICOS
B2: Orçado | C2: Planejado | D2: Realizado | F2: Orçado (%) | G2: Planejado (%) | H2: Realizado (%)
A3: JANEIRO | B3: =HLOOKUP(A3,Orçamento!$3:$4,2,0) -> 0 | C3: =HLOOKUP(CONCATENATE(A3," - ",$C$2),Orçamento!$74:$75,2,0) -> 0 | D3: =HLOOKUP(CONCATENATE(A3," - ",$D$2),Orçamento!$74:$75,2,0) -> 0 | E3: JANEIRO | F3: =B3/$B$15 -> #DIV/0! | G3: =C3/$C$15 -> #DIV/0! | H3: =D3/$D$15 -> #DIV/0!
A4: FEVEREIRO | B4: =HLOOKUP(A4,Orçamento!$3:$4,2,0) -> 0 | C4: =HLOOKUP(CONCATENATE(A4," - ",$C$2),Orçamento!$74:$75,2,0) -> 0 | D4: =HLOOKUP(CONCATENATE(A4," - ",$D$2),Orçamento!$74:$75,2,0) -> 0 | E4: FEVEREIRO | F4: =B4/$B$15 -> #DIV/0! | G4: =C4/$C$15 -> #DIV/0! | H4: =D4/$D$15 -> #DIV/0!
A5: MARÇO | B5: =HLOOKUP(A5,Orçamento!$3:$4,2,0) -> 0 | C5: =HLOOKUP(CONCATENATE(A5," - ",$C$2),Orçamento!$74:$75,2,0) -> 0 | D5: =HLOOKUP(CONCATENATE(A5," - ",$D$2),Orçamento!$74:$75,2,0) -> 0 | E5: MARÇO | F5: =B5/$B$15 -> #DIV/0! | G5: =C5/$C$15 -> #DIV/0! | H5: =D5/$D$15 -> #DIV/0!
A6: ABRIL | B6: =HLOOKUP(A6,Orçamento!$3:$4,2,0) -> 0 | C6: =HLOOKUP(CONCATENATE(A6," - ",$C$2),Orçamento!$74:$75,2,0) -> 0 | D6: =HLOOKUP(CONCATENATE(A6," - ",$D$2),Orçamento!$74:$75,2,0) -> 0 | E6: ABRIL | F6: =B6/$B$15 -> #DIV/0! | G6: =C6/$C$15 -> #DIV/0! | H6: =D6/$D$15 -> #DIV/0!
A7: MAIO | B7: =HLOOKUP(A7,Orçamento!$3:$4,2,0) -> 0 | C7: =HLOOKUP(CONCATENATE(A7," - ",$C$2),Orçamento!$74:$75,2,0) -> 0 | D7: =HLOOKUP(CONCATENATE(A7," - ",$D$2),Orçamento!$74:$75,2,0) -> 0 | E7: MAIO | F7: =B7/$B$15 -> #DIV/0! | G7: =C7/$C$15 -> #DIV/0! | H7: =D7/$D$15 -> #DIV/0!
A8: JUNHO | B8: =HLOOKUP(A8,Orçamento!$3:$4,2,0) -> 0 | C8: =HLOOKUP(CONCATENATE(A8," - ",$C$2),Orçamento!$74:$75,2,0) -> 0 | D8: =HLOOKUP(CONCATENATE(A8," - ",$D$2),Orçamento!$74:$75,2,0) -> 0 | E8: JUNHO | F8: =B8/$B$15 -> #DIV/0! | G8: =C8/$C$15 -> #DIV/0! | H8: =D8/$D$15 -> #DIV/0!
A9: JULHO | B9: =HLOOKUP(A9,Orçamento!$3:$4,2,0) -> 0 | C9: =HLOOKUP(CONCATENATE(A9," - ",$C$2),Orçamento!$74:$75,2,0) -> 0 | D9: =HLOOKUP(CONCATENATE(A9," - ",$D$2),Orçamento!$74:$75,2,0) -> 0 | E9: JULHO | F9: =B9/$B$15 -> #DIV/0! | G9: =C9/$C$15 -> #DIV/0! | H9: =D9/$D$15 -> #DIV/0!
A10: AGOSTO | B10: =HLOOKUP(A10,Orçamento!$3:$4,2,0) -> 0 | C10: =HLOOKUP(CONCATENATE(A10," - ",$C$2),Orçamento!$74:$75,2,0) -> 0 | D10: =HLOOKUP(CONCATENATE(A10," - ",$D$2),Orçamento!$74:$75,2,0) -> 0 | E10: AGOSTO | F10: =B10/$B$15 -> #DIV/0! | G10: =C10/$C$15 -> #DIV/0! | H10: =D10/$D$15 -> #DIV/0!
A11: SETEMBRO | B11: =HLOOKUP(A11,Orçamento!$3:$4,2,0) -> 0 | C11: =HLOOKUP(CONCATENATE(A11," - ",$C$2),Orçamento!$74:$75,2,0) -> 0 | D11: =HLOOKUP(CONCATENATE(A11," - ",$D$2),Orçamento!$74:$75,2,0) -> 0 | E11: SETEMBRO | F11: =B11/$B$15 -> #DIV/0! | G11: =C11/$C$15 -> #DIV/0! | H11: =D11/$D$15 -> #DIV/0!
A12: OUTUBRO | B12: =HLOOKUP(A12,Orçamento!$3:$4,2,0) -> 0 | C12: =HLOOKUP(CONCATENATE(A12," - ",$C$2),Orçamento!$74:$75,2,0) -> 0 | D12: =HLOOKUP(CONCATENATE(A12," - ",$D$2),Orçamento!$74:$75,2,0) -> 0 | E12: OUTUBRO | F12: =B12/$B$15 -> #DIV/0! | G12: =C12/$C$15 -> #DIV/0! | H12: =D12/$D$15 -> #DIV/0!
A13: NOVEMBRO | B13: =HLOOKUP(A13,Orçamento!$3:$4,2,0) -> 0 | C13: =HLOOKUP(CONCATENATE(A13," - ",$C$2),Orçamento!$74:$75,2,0) -> 0 | D13: =HLOOKUP(CONCATENATE(A13," - ",$D$2),Orçamento!$74:$75,2,0) -> 0 | E13: NOVEMBRO | F13: =B13/$B$15 -> #DIV/0! | G13: =C13/$C$15 -> #DIV/0! | H13: =D13/$D$15 -> #DIV/0!
A14: DEZEMBRO | B14: =HLOOKUP(A14,Orçamento!$3:$4,2,0) -> 0 | C14: =HLOOKUP(CONCATENATE(A14," - ",$C$2),Orçamento!$74:$75,2,0) -> 0 | D14: =HLOOKUP(CONCATENATE(A14," - ",$D$2),Orçamento!$74:$75,2,0) -> 0 | E14: DEZEMBRO | F14: =B14/$B$15 -> #DIV/0! | G14: =C14/$C$15 -> #DIV/0! | H14: =D14/$D$15 -> #DIV/0!
A15: TOTAL | B15: =HLOOKUP(A15,Orçamento!$3:$4,2,0) -> 0 | C15: =HLOOKUP(CONCATENATE(A15," - ",$C$2),Orçamento!$74:$75,2,0) -> 0 | D15: =HLOOKUP(CONCATENATE(A15," - ",$D$2),Orçamento!$74:$75,2,0) -> 0 | E15: TOTAL | F15: =B15/$B$15 -> #DIV/0! | G15: =C15/$C$15 -> #DIV/0! | H15: =D15/$D$15 -> #DIV/0!
A49: Selecione o setor: | B49: DEPARTAMENTO PESSOAL
A50: Selecione o mês: | B50: JANEIRO
A52: =IF(B49=B65,Orçamento!A9,IF(B49=B66,Orçamento!A20,IF(B49=B67,Orçamento!A31,IF(B49=B68,Orçamento!A42,IF(B49=B69,Orçamento!A53,IF(B49=B70,Orçamento!A64,"")))))) -> DEPARTAMENTO PESSOAL | B52: PLANEJADO | C52: REALIZADO
A53: =IF($A$52=$B$65,Orçamento!A10,IF(Gráficos!$A$52=Gráficos!$B$66,Orçamento!A21,IF(Gráficos!$A$52=Gráficos!$B$67,Orçamento!A32,IF(Gráficos!$A$52=Gráficos!$B$68,Orçamento!A43,IF(Gráficos!$A$52=Gráficos!$B$69,Orçamento!A54,IF(Gráficos!$A$52=Gráficos!$B$70,Orçamento!A65,0)))))) -> Pró-labore | B53: =IF($B$50=$A$65,VLOOKUP(A53,Orçamento!$A:$AO,2,0),IF($B$50=$A$66,VLOOKUP(A53,Orçamento!$A:$AO,5,0),IF($B$50=$A$67,VLOOKUP(A53,Orçamento!$A:$AO,8,0),IF($B$50=$A$68,VLOOKUP(A53,Orçamento!$A:$AO,11,0),IF($B$50=$A$69,VLOOKUP(A53,Orçamento!$A:$AO,14,0),IF($B$50=$A$70,VLOOKUP(A53,Orçamento!$A:$AO,17,0),IF($B$50=$A$71,VLOOKUP(A53,Orçamento!$A:$AO,20,0),IF($B$50=$A$72,VLOOKUP(A53,Orçamento!$A:$AO,23,0),IF($B$50=$A$73,VLOOKUP(A53,Orçamento!$A:$AO,26,0),IF($B$50=$A$74,VLOOKUP(A53,Orçamento!$A:$AO,29,0),IF($B$50=$A$75,VLOOKUP(A53,Orçamento!$A:$AO,32,0),IF($B$50=$A$76,VLOOKUP(A53,Orçamento!$A:$AO,35,0),IF($B$50=$A$77,VLOOKUP(A53,Orçamento!$A:$AO,38,0),""))))))))))))) -> 0 | C53: =IF($B$50=$A$65,VLOOKUP(A53,Orçamento!$A:$AO,3,0),IF($B$50=$A$66,VLOOKUP(A53,Orçamento!$A:$AO,6,0),IF($B$50=$A$67,VLOOKUP(A53,Orçamento!$A:$AO,9,0),IF($B$50=$A$68,VLOOKUP(A53,Orçamento!$A:$AO,12,0),IF($B$50=$A$69,VLOOKUP(A53,Orçamento!$A:$AO,15,0),IF($B$50=$A$70,VLOOKUP(A53,Orçamento!$A:$AO,18,0),IF($B$50=$A$71,VLOOKUP(A53,Orçamento!$A:$AO,21,0),IF($B$50=$A$72,VLOOKUP(A53,Orçamento!$A:$AO,24,0),IF($B$50=$A$73,VLOOKUP(A53,Orçamento!$A:$AO,27,0),IF($B$50=$A$74,VLOOKUP(A53,Orçamento!$A:$AO,30,0),IF($B$50=$A$75,VLOOKUP(A53,Orçamento!$A:$AO,33,0),IF($B$50=$A$76,VLOOKUP(A53,Orçamento!$A:$AO,36,0),IF($B$50=$A$77,VLOOKUP(A53,Orçamento!$A:$AO,39,0),""))))))))))))) -> 0
A54: =IF($A$52=$B$65,Orçamento!A11,IF(Gráficos!$A$52=Gráficos!$B$66,Orçamento!A22,IF(Gráficos!$A$52=Gráficos!$B$67,Orçamento!A33,IF(Gráficos!$A$52=Gráficos!$B$68,Orçamento!A44,IF(Gráficos!$A$52=Gráficos!$B$69,Orçamento!A55,IF(Gráficos!$A$52=Gráficos!$B$70,Orçamento!A66,0)))))) -> Auxilio doença | B54: =IF($B$50=$A$65,VLOOKUP(A54,Orçamento!$A:$AO,2,0),IF($B$50=$A$66,VLOOKUP(A54,Orçamento!$A:$AO,5,0),IF($B$50=$A$67,VLOOKUP(A54,Orçamento!$A:$AO,8,0),IF($B$50=$A$68,VLOOKUP(A54,Orçamento!$A:$AO,11,0),IF($B$50=$A$69,VLOOKUP(A54,Orçamento!$A:$AO,14,0),IF($B$50=$A$70,VLOOKUP(A54,Orçamento!$A:$AO,17,0),IF($B$50=$A$71,VLOOKUP(A54,Orçamento!$A:$AO,20,0),IF($B$50=$A$72,VLOOKUP(A54,Orçamento!$A:$AO,23,0),IF($B$50=$A$73,VLOOKUP(A54,Orçamento!$A:$AO,26,0),IF($B$50=$A$74,VLOOKUP(A54,Orçamento!$A:$AO,29,0),IF($B$50=$A$75,VLOOKUP(A54,Orçamento!$A:$AO,32,0),IF($B$50=$A$76,VLOOKUP(A54,Orçamento!$A:$AO,35,0),IF($B$50=$A$77,VLOOKUP(A54,Orçamento!$A:$AO,38,0),""))))))))))))) -> 0 | C54: =IF($B$50=$A$65,VLOOKUP(A54,Orçamento!$A:$AO,3,0),IF($B$50=$A$66,VLOOKUP(A54,Orçamento!$A:$AO,6,0),IF($B$50=$A$67,VLOOKUP(A54,Orçamento!$A:$AO,9,0),IF($B$50=$A$68,VLOOKUP(A54,Orçamento!$A:$AO,12,0),IF($B$50=$A$69,VLOOKUP(A54,Orçamento!$A:$AO,15,0),IF($B$50=$A$70,VLOOKUP(A54,Orçamento!$A:$AO,18,0),IF($B$50=$A$71,VLOOKUP(A54,Orçamento!$A:$AO,21,0),IF($B$50=$A$72,VLOOKUP(A54,Orçamento!$A:$AO,24,0),IF($B$50=$A$73,VLOOKUP(A54,Orçamento!$A:$AO,27,0),IF($B$50=$A$74,VLOOKUP(A54,Orçamento!$A:$AO,30,0),IF($B$50=$A$75,VLOOKUP(A54,Orçamento!$A:$AO,33,0),IF($B$50=$A$76,VLOOKUP(A54,Orçamento!$A:$AO,36,0),IF($B$50=$A$77,VLOOKUP(A54,Orçamento!$A:$AO,39,0),""))))))))))))) -> 0
A55: =IF($A$52=$B$65,Orçamento!A12,IF(Gráficos!$A$52=Gráficos!$B$66,Orçamento!A23,IF(Gráficos!$A$52=Gráficos!$B$67,Orçamento!A34,IF(Gráficos!$A$52=Gráficos!$B$68,Orçamento!A45,IF(Gráficos!$A$52=Gráficos!$B$69,Orçamento!A56,IF(Gráficos!$A$52=Gráficos!$B$70,Orçamento!A67,0)))))) -> Benefícios | B55: =IF($B$50=$A$65,VLOOKUP(A55,Orçamento!$A:$AO,2,0),IF($B$50=$A$66,VLOOKUP(A55,Orçamento!$A:$AO,5,0),IF($B$50=$A$67,VLOOKUP(A55,Orçamento!$A:$AO,8,0),IF($B$50=$A$68,VLOOKUP(A55,Orçamento!$A:$AO,11,0),IF($B$50=$A$69,VLOOKUP(A55,Orçamento!$A:$AO,14,0),IF($B$50=$A$70,VLOOKUP(A55,Orçamento!$A:$AO,17,0),IF($B$50=$A$71,VLOOKUP(A55,Orçamento!$A:$AO,20,0),IF($B$50=$A$72,VLOOKUP(A55,Orçamento!$A:$AO,23,0),IF($B$50=$A$73,VLOOKUP(A55,Orçamento!$A:$AO,26,0),IF($B$50=$A$74,VLOOKUP(A55,Orçamento!$A:$AO,29,0),IF($B$50=$A$75,VLOOKUP(A55,Orçamento!$A:$AO,32,0),IF($B$50=$A$76,VLOOKUP(A55,Orçamento!$A:$AO,35,0),IF($B$50=$A$77,VLOOKUP(A55,Orçamento!$A:$AO,38,0),""))))))))))))) -> 0 | C55: =IF($B$50=$A$65,VLOOKUP(A55,Orçamento!$A:$AO,3,0),IF($B$50=$A$66,VLOOKUP(A55,Orçamento!$A:$AO,6,0),IF($B$50=$A$67,VLOOKUP(A55,Orçamento!$A:$AO,9,0),IF($B$50=$A$68,VLOOKUP(A55,Orçamento!$A:$AO,12,0),IF($B$50=$A$69,VLOOKUP(A55,Orçamento!$A:$AO,15,0),IF($B$50=$A$70,VLOOKUP(A55,Orçamento!$A:$AO,18,0),IF($B$50=$A$71,VLOOKUP(A55,Orçamento!$A:$AO,21,0),IF($B$50=$A$72,VLOOKUP(A55,Orçamento!$A:$AO,24,0),IF($B$50=$A$73,VLOOKUP(A55,Orçamento!$A:$AO,27,0),IF($B$50=$A$74,VLOOKUP(A55,Orçamento!$A:$AO,30,0),IF($B$50=$A$75,VLOOKUP(A55,Orçamento!$A:$AO,33,0),IF($B$50=$A$76,VLOOKUP(A55,Orçamento!$A:$AO,36,0),IF($B$50=$A$77,VLOOKUP(A55,Orçamento!$A:$AO,39,0),""))))))))))))) -> 0
A56: =IF($A$52=$B$65,Orçamento!A13,IF(Gráficos!$A$52=Gráficos!$B$66,Orçamento!A24,IF(Gráficos!$A$52=Gráficos!$B$67,Orçamento!A35,IF(Gráficos!$A$52=Gráficos!$B$68,Orçamento!A46,IF(Gráficos!$A$52=Gráficos!$B$69,Orçamento!A57,IF(Gráficos!$A$52=Gráficos!$B$70,Orçamento!A68,0)))))) -> Treinamentos | B56: =IF($B$50=$A$65,VLOOKUP(A56,Orçamento!$A:$AO,2,0),IF($B$50=$A$66,VLOOKUP(A56,Orçamento!$A:$AO,5,0),IF($B$50=$A$67,VLOOKUP(A56,Orçamento!$A:$AO,8,0),IF($B$50=$A$68,VLOOKUP(A56,Orçamento!$A:$AO,11,0),IF($B$50=$A$69,VLOOKUP(A56,Orçamento!$A:$AO,14,0),IF($B$50=$A$70,VLOOKUP(A56,Orçamento!$A:$AO,17,0),IF($B$50=$A$71,VLOOKUP(A56,Orçamento!$A:$AO,20,0),IF($B$50=$A$72,VLOOKUP(A56,Orçamento!$A:$AO,23,0),IF($B$50=$A$73,VLOOKUP(A56,Orçamento!$A:$AO,26,0),IF($B$50=$A$74,VLOOKUP(A56,Orçamento!$A:$AO,29,0),IF($B$50=$A$75,VLOOKUP(A56,Orçamento!$A:$AO,32,0),IF($B$50=$A$76,VLOOKUP(A56,Orçamento!$A:$AO,35,0),IF($B$50=$A$77,VLOOKUP(A56,Orçamento!$A:$AO,38,0),""))))))))))))) -> 0 | C56: =IF($B$50=$A$65,VLOOKUP(A56,Orçamento!$A:$AO,3,0),IF($B$50=$A$66,VLOOKUP(A56,Orçamento!$A:$AO,6,0),IF($B$50=$A$67,VLOOKUP(A56,Orçamento!$A:$AO,9,0),IF($B$50=$A$68,VLOOKUP(A56,Orçamento!$A:$AO,12,0),IF($B$50=$A$69,VLOOKUP(A56,Orçamento!$A:$AO,15,0),IF($B$50=$A$70,VLOOKUP(A56,Orçamento!$A:$AO,18,0),IF($B$50=$A$71,VLOOKUP(A56,Orçamento!$A:$AO,21,0),IF($B$50=$A$72,VLOOKUP(A56,Orçamento!$A:$AO,24,0),IF($B$50=$A$73,VLOOKUP(A56,Orçamento!$A:$AO,27,0),IF($B$50=$A$74,VLOOKUP(A56,Orçamento!$A:$AO,30,0),IF($B$50=$A$75,VLOOKUP(A56,Orçamento!$A:$AO,33,0),IF($B$50=$A$76,VLOOKUP(A56,Orçamento!$A:$AO,36,0),IF($B$50=$A$77,VLOOKUP(A56,Orçamento!$A:$AO,39,0),""))))))))))))) -> 0
A57: =IF($A$52=$B$65,Orçamento!A14,IF(Gráficos!$A$52=Gráficos!$B$66,Orçamento!A25,IF(Gráficos!$A$52=Gráficos!$B$67,Orçamento!A36,IF(Gráficos!$A$52=Gráficos!$B$68,Orçamento!A47,IF(Gráficos!$A$52=Gráficos!$B$69,Orçamento!A58,IF(Gráficos!$A$52=Gráficos!$B$70,Orçamento!A69,0)))))) -> Programas de saúde | B57: =IF($B$50=$A$65,VLOOKUP(A57,Orçamento!$A:$AO,2,0),IF($B$50=$A$66,VLOOKUP(A57,Orçamento!$A:$AO,5,0),IF($B$50=$A$67,VLOOKUP(A57,Orçamento!$A:$AO,8,0),IF($B$50=$A$68,VLOOKUP(A57,Orçamento!$A:$AO,11,0),IF($B$50=$A$69,VLOOKUP(A57,Orçamento!$A:$AO,14,0),IF($B$50=$A$70,VLOOKUP(A57,Orçamento!$A:$AO,17,0),IF($B$50=$A$71,VLOOKUP(A57,Orçamento!$A:$AO,20,0),IF($B$50=$A$72,VLOOKUP(A57,Orçamento!$A:$AO,23,0),IF($B$50=$A$73,VLOOKUP(A57,Orçamento!$A:$AO,26,0),IF($B$50=$A$74,VLOOKUP(A57,Orçamento!$A:$AO,29,0),IF($B$50=$A$75,VLOOKUP(A57,Orçamento!$A:$AO,32,0),IF($B$50=$A$76,VLOOKUP(A57,Orçamento!$A:$AO,35,0),IF($B$50=$A$77,VLOOKUP(A57,Orçamento!$A:$AO,38,0),""))))))))))))) -> 0 | C57: =IF($B$50=$A$65,VLOOKUP(A57,Orçamento!$A:$AO,3,0),IF($B$50=$A$66,VLOOKUP(A57,Orçamento!$A:$AO,6,0),IF($B$50=$A$67,VLOOKUP(A57,Orçamento!$A:$AO,9,0),IF($B$50=$A$68,VLOOKUP(A57,Orçamento!$A:$AO,12,0),IF($B$50=$A$69,VLOOKUP(A57,Orçamento!$A:$AO,15,0),IF($B$50=$A$70,VLOOKUP(A57,Orçamento!$A:$AO,18,0),IF($B$50=$A$71,VLOOKUP(A57,Orçamento!$A:$AO,21,0),IF($B$50=$A$72,VLOOKUP(A57,Orçamento!$A:$AO,24,0),IF($B$50=$A$73,VLOOKUP(A57,Orçamento!$A:$AO,27,0),IF($B$50=$A$74,VLOOKUP(A57,Orçamento!$A:$AO,30,0),IF($B$50=$A$75,VLOOKUP(A57,Orçamento!$A:$AO,33,0),IF($B$50=$A$76,VLOOKUP(A57,Orçamento!$A:$AO,36,0),IF($B$50=$A$77,VLOOKUP(A57,Orçamento!$A:$AO,39,0),""))))))))))))) -> 0
A58: =IF($A$52=$B$65,Orçamento!A15,IF(Gráficos!$A$52=Gráficos!$B$66,Orçamento!A26,IF(Gráficos!$A$52=Gráficos!$B$67,Orçamento!A37,IF(Gráficos!$A$52=Gráficos!$B$68,Orçamento!A48,IF(Gráficos!$A$52=Gráficos!$B$69,Orçamento!A59,IF(Gráficos!$A$52=Gráficos!$B$70,Orçamento!A70,0)))))) -> Responsabilidade Social | B58: =IF($B$50=$A$65,VLOOKUP(A58,Orçamento!$A:$AO,2,0),IF($B$50=$A$66,VLOOKUP(A58,Orçamento!$A:$AO,5,0),IF($B$50=$A$67,VLOOKUP(A58,Orçamento!$A:$AO,8,0),IF($B$50=$A$68,VLOOKUP(A58,Orçamento!$A:$AO,11,0),IF($B$50=$A$69,VLOOKUP(A58,Orçamento!$A:$AO,14,0),IF($B$50=$A$70,VLOOKUP(A58,Orçamento!$A:$AO,17,0),IF($B$50=$A$71,VLOOKUP(A58,Orçamento!$A:$AO,20,0),IF($B$50=$A$72,VLOOKUP(A58,Orçamento!$A:$AO,23,0),IF($B$50=$A$73,VLOOKUP(A58,Orçamento!$A:$AO,26,0),IF($B$50=$A$74,VLOOKUP(A58,Orçamento!$A:$AO,29,0),IF($B$50=$A$75,VLOOKUP(A58,Orçamento!$A:$AO,32,0),IF($B$50=$A$76,VLOOKUP(A58,Orçamento!$A:$AO,35,0),IF($B$50=$A$77,VLOOKUP(A58,Orçamento!$A:$AO,38,0),""))))))))))))) -> 0 | C58: =IF($B$50=$A$65,VLOOKUP(A58,Orçamento!$A:$AO,3,0),IF($B$50=$A$66,VLOOKUP(A58,Orçamento!$A:$AO,6,0),IF($B$50=$A$67,VLOOKUP(A58,Orçamento!$A:$AO,9,0),IF($B$50=$A$68,VLOOKUP(A58,Orçamento!$A:$AO,12,0),IF($B$50=$A$69,VLOOKUP(A58,Orçamento!$A:$AO,15,0),IF($B$50=$A$70,VLOOKUP(A58,Orçamento!$A:$AO,18,0),IF($B$50=$A$71,VLOOKUP(A58,Orçamento!$A:$AO,21,0),IF($B$50=$A$72,VLOOKUP(A58,Orçamento!$A:$AO,24,0),IF($B$50=$A$73,VLOOKUP(A58,Orçamento!$A:$AO,27,0),IF($B$50=$A$74,VLOOKUP(A58,Orçamento!$A:$AO,30,0),IF($B$50=$A$75,VLOOKUP(A58,Orçamento!$A:$AO,33,0),IF($B$50=$A$76,VLOOKUP(A58,Orçamento!$A:$AO,36,0),IF($B$50=$A$77,VLOOKUP(A58,Orçamento!$A:$AO,39,0),""))))))))))))) -> 0
A59: =IF($A$52=$B$65,Orçamento!A16,IF(Gráficos!$A$52=Gráficos!$B$66,Orçamento!A27,IF(Gráficos!$A$52=Gráficos!$B$67,Orçamento!A38,IF(Gráficos!$A$52=Gráficos!$B$68,Orçamento!A49,IF(Gráficos!$A$52=Gráficos!$B$69,Orçamento!A60,IF(Gráficos!$A$52=Gráficos!$B$70,Orçamento!A71,0)))))) -> Outras despesas | B59: =IF($B$50=$A$65,VLOOKUP(A59,Orçamento!$A:$AO,2,0),IF($B$50=$A$66,VLOOKUP(A59,Orçamento!$A:$AO,5,0),IF($B$50=$A$67,VLOOKUP(A59,Orçamento!$A:$AO,8,0),IF($B$50=$A$68,VLOOKUP(A59,Orçamento!$A:$AO,11,0),IF($B$50=$A$69,VLOOKUP(A59,Orçamento!$A:$AO,14,0),IF($B$50=$A$70,VLOOKUP(A59,Orçamento!$A:$AO,17,0),IF($B$50=$A$71,VLOOKUP(A59,Orçamento!$A:$AO,20,0),IF($B$50=$A$72,VLOOKUP(A59,Orçamento!$A:$AO,23,0),IF($B$50=$A$73,VLOOKUP(A59,Orçamento!$A:$AO,26,0),IF($B$50=$A$74,VLOOKUP(A59,Orçamento!$A:$AO,29,0),IF($B$50=$A$75,VLOOKUP(A59,Orçamento!$A:$AO,32,0),IF($B$50=$A$76,VLOOKUP(A59,Orçamento!$A:$AO,35,0),IF($B$50=$A$77,VLOOKUP(A59,Orçamento!$A:$AO,38,0),""))))))))))))) -> 0 | C59: =IF($B$50=$A$65,VLOOKUP(A59,Orçamento!$A:$AO,3,0),IF($B$50=$A$66,VLOOKUP(A59,Orçamento!$A:$AO,6,0),IF($B$50=$A$67,VLOOKUP(A59,Orçamento!$A:$AO,9,0),IF($B$50=$A$68,VLOOKUP(A59,Orçamento!$A:$AO,12,0),IF($B$50=$A$69,VLOOKUP(A59,Orçamento!$A:$AO,15,0),IF($B$50=$A$70,VLOOKUP(A59,Orçamento!$A:$AO,18,0),IF($B$50=$A$71,VLOOKUP(A59,Orçamento!$A:$AO,21,0),IF($B$50=$A$72,VLOOKUP(A59,Orçamento!$A:$AO,24,0),IF($B$50=$A$73,VLOOKUP(A59,Orçamento!$A:$AO,27,0),IF($B$50=$A$74,VLOOKUP(A59,Orçamento!$A:$AO,30,0),IF($B$50=$A$75,VLOOKUP(A59,Orçamento!$A:$AO,33,0),IF($B$50=$A$76,VLOOKUP(A59,Orçamento!$A:$AO,36,0),IF($B$50=$A$77,VLOOKUP(A59,Orçamento!$A:$AO,39,0),""))))))))))))) -> 0
A60: =IF($A$52=$B$65,Orçamento!A17,IF(Gráficos!$A$52=Gráficos!$B$66,Orçamento!A28,IF(Gráficos!$A$52=Gráficos!$B$67,Orçamento!A39,IF(Gráficos!$A$52=Gráficos!$B$68,Orçamento!A50,IF(Gráficos!$A$52=Gráficos!$B$69,Orçamento!A61,IF(Gráficos!$A$52=Gráficos!$B$70,Orçamento!A72,0)))))) -> 0 | B60: =IF($B$50=$A$65,VLOOKUP(A60,Orçamento!$A:$AO,2,0),IF($B$50=$A$66,VLOOKUP(A60,Orçamento!$A:$AO,5,0),IF($B$50=$A$67,VLOOKUP(A60,Orçamento!$A:$AO,8,0),IF($B$50=$A$68,VLOOKUP(A60,Orçamento!$A:$AO,11,0),IF($B$50=$A$69,VLOOKUP(A60,Orçamento!$A:$AO,14,0),IF($B$50=$A$70,VLOOKUP(A60,Orçamento!$A:$AO,17,0),IF($B$50=$A$71,VLOOKUP(A60,Orçamento!$A:$AO,20,0),IF($B$50=$A$72,VLOOKUP(A60,Orçamento!$A:$AO,23,0),IF($B$50=$A$73,VLOOKUP(A60,Orçamento!$A:$AO,26,0),IF($B$50=$A$74,VLOOKUP(A60,Orçamento!$A:$AO,29,0),IF($B$50=$A$75,VLOOKUP(A60,Orçamento!$A:$AO,32,0),IF($B$50=$A$76,VLOOKUP(A60,Orçamento!$A:$AO,35,0),IF($B$50=$A$77,VLOOKUP(A60,Orçamento!$A:$AO,38,0),""))))))))))))) -> #N/A | C60: =IF($B$50=$A$65,VLOOKUP(A60,Orçamento!$A:$AO,3,0),IF($B$50=$A$66,VLOOKUP(A60,Orçamento!$A:$AO,6,0),IF($B$50=$A$67,VLOOKUP(A60,Orçamento!$A:$AO,9,0),IF($B$50=$A$68,VLOOKUP(A60,Orçamento!$A:$AO,12,0),IF($B$50=$A$69,VLOOKUP(A60,Orçamento!$A:$AO,15,0),IF($B$50=$A$70,VLOOKUP(A60,Orçamento!$A:$AO,18,0),IF($B$50=$A$71,VLOOKUP(A60,Orçamento!$A:$AO,21,0),IF($B$50=$A$72,VLOOKUP(A60,Orçamento!$A:$AO,24,0),IF($B$50=$A$73,VLOOKUP(A60,Orçamento!$A:$AO,27,0),IF($B$50=$A$74,VLOOKUP(A60,Orçamento!$A:$AO,30,0),IF($B$50=$A$75,VLOOKUP(A60,Orçamento!$A:$AO,33,0),IF($B$50=$A$76,VLOOKUP(A60,Orçamento!$A:$AO,36,0),IF($B$50=$A$77,VLOOKUP(A60,Orçamento!$A:$AO,39,0),""))))))))))))) -> #N/A
A61: =IF($A$52=$B$65,Orçamento!A18,IF(Gráficos!$A$52=Gráficos!$B$66,Orçamento!A29,IF(Gráficos!$A$52=Gráficos!$B$67,Orçamento!A40,IF(Gráficos!$A$52=Gráficos!$B$68,Orçamento!A51,IF(Gráficos!$A$52=Gráficos!$B$69,Orçamento!A62,IF(Gráficos!$A$52=Gráficos!$B$70,Orçamento!A73,0)))))) -> 0 | B61: =IF($B$50=$A$65,VLOOKUP(A61,Orçamento!$A:$AO,2,0),IF($B$50=$A$66,VLOOKUP(A61,Orçamento!$A:$AO,5,0),IF($B$50=$A$67,VLOOKUP(A61,Orçamento!$A:$AO,8,0),IF($B$50=$A$68,VLOOKUP(A61,Orçamento!$A:$AO,11,0),IF($B$50=$A$69,VLOOKUP(A61,Orçamento!$A:$AO,14,0),IF($B$50=$A$70,VLOOKUP(A61,Orçamento!$A:$AO,17,0),IF($B$50=$A$71,VLOOKUP(A61,Orçamento!$A:$AO,20,0),IF($B$50=$A$72,VLOOKUP(A61,Orçamento!$A:$AO,23,0),IF($B$50=$A$73,VLOOKUP(A61,Orçamento!$A:$AO,26,0),IF($B$50=$A$74,VLOOKUP(A61,Orçamento!$A:$AO,29,0),IF($B$50=$A$75,VLOOKUP(A61,Orçamento!$A:$AO,32,0),IF($B$50=$A$76,VLOOKUP(A61,Orçamento!$A:$AO,35,0),IF($B$50=$A$77,VLOOKUP(A61,Orçamento!$A:$AO,38,0),""))))))))))))) -> #N/A | C61: =IF($B$50=$A$65,VLOOKUP(A61,Orçamento!$A:$AO,3,0),IF($B$50=$A$66,VLOOKUP(A61,Orçamento!$A:$AO,6,0),IF($B$50=$A$67,VLOOKUP(A61,Orçamento!$A:$AO,9,0),IF($B$50=$A$68,VLOOKUP(A61,Orçamento!$A:$AO,12,0),IF($B$50=$A$69,VLOOKUP(A61,Orçamento!$A:$AO,15,0),IF($B$50=$A$70,VLOOKUP(A61,Orçamento!$A:$AO,18,0),IF($B$50=$A$71,VLOOKUP(A61,Orçamento!$A:$AO,21,0),IF($B$50=$A$72,VLOOKUP(A61,Orçamento!$A:$AO,24,0),IF($B$50=$A$73,VLOOKUP(A61,Orçamento!$A:$AO,27,0),IF($B$50=$A$74,VLOOKUP(A61,Orçamento!$A:$AO,30,0),IF($B$50=$A$75,VLOOKUP(A61,Orçamento!$A:$AO,33,0),IF($B$50=$A$76,VLOOKUP(A61,Orçamento!$A:$AO,36,0),IF($B$50=$A$77,VLOOKUP(A61,Orçamento!$A:$AO,39,0),""))))))))))))) -> #N/A
A65: JANEIRO | B65: PRODUÇÃO/INDUSTRIAL
A66: FEVEREIRO | B66: COMERCIAL/VENDAS
A67: MARÇO | B67: MARKETING e PUBLICIDADE
A68: ABRIL | B68: DEPARTAMENTO PESSOAL
A69: MAIO | B69: ADMINISTRATIVO
A70: JUNHO | B70: OUTROS
A71: JULHO
A72: AGOSTO
A73: SETEMBRO
A74: OUTUBRO
A75: NOVEMBRO
A76: DEZEMBRO
A77: TOTAL
