Workbook

Sheet Início
A1: CONTROLE DE ESTOQUES- INÍCIO

Sheet Inventário
A1: CONTROLE DE ESTOQUES- INVENTÁRIO
C3: ID Produto | D3: NOME DO PRODUTO | E3: DESCRIÇÃO | F3: UNIDADE | G3: VALOR DA UNIDADE | H3: ESTOQUE INICIAL | I3: ESTOQUE MÍNIMO
J4: =Inventário!I4-Controle!D8 -> #VALUE!
J5: =Inventário!I5-Controle!D9 -> #VALUE!
J6: =Inventário!I6-Controle!D10 -> #VALUE!
J7: =Inventário!I7-Controle!D11 -> #VALUE!
J8: =Inventário!I8-Controle!D12 -> #VALUE!
J9: =Inventário!I9-Controle!D13 -> #VALUE!
J10: =Inventário!I10-Controle!D14 -> #VALUE!
J11: =Inventário!I11-Controle!D15 -> #VALUE!
J12: =Inventário!I12-Controle!D16 -> #VALUE!
J13: =Inventário!I13-Controle!D17 -> #VALUE!
J14: =Inventário!I14-Controle!D18 -> #VALUE!
J15: =Inventário!I15-Controle!D19 -> #VALUE!
... J53: =Inventário!I53-Controle!D57 -> #VALUE!

Sheet Entradas e Saídas
A1: CONTROLE DE ESTOQUES- ENTRADAS E SAÍDAS
B3: JANEIRO | H3: FEVEREIRO | N3: MARÇO | T3: ABRIL | Z3: MAIO | AF3: JUNHO | AL3: JULHO | AR3: AGOSTO | AX3: SETEMBRO | BD3: OUTUBRO | BJ3: NOVEMBRO | BP3: DEZEMBRO
B4: DATA | C4: NOTA | D4: PRODUTO | E4: ENTRADA | F4: SAÍDA | H4: DATA | I4: NOTA FISCAL | J4: PRODUTO | K4: ENTRADA | L4: SAÍDA | N4: DATA | O4: NOTA FISCAL | P4: PRODUTO | Q4: ENTRADA | R4: SAÍDA | T4: DATA | U4: NOTA FISCAL | V4: PRODUTO | W4: ENTRADA | X4: SAÍDA | Z4: DATA | AA4: NOTA FISCAL | AB4: PRODUTO | AC4: ENTRADA | AD4: SAÍDA | AF4: DATA | AG4: NOTA FISCAL | AH4: PRODUTO | AI4: ENTRADA | AJ4: SAÍDA | AL4: DATA | AM4: NOTA FISCAL | AN4: PRODUTO | AO4: ENTRADA | AP4: SAÍDA | AR4: DATA | AS4: NOTA FISCAL | AT4: PRODUTO | AU4: ENTRADA | AV4: SAÍDA | AX4: DATA | AY4: NOTA FISCAL | AZ4: PRODUTO | BA4: ENTRADA | BB4: SAÍDA | BD4: DATA | BE4: NOTA FISCAL | BF4: PRODUTO | BG4: ENTRADA | BH4: SAÍDA | BJ4: DATA | BK4: NOTA FISCAL | BL4: PRODUTO | BM4: ENTRADA | BN4: SAÍDA | BP4: DATA | BQ4: NOTA FISCAL | BR4: PRODUTO | BS4: ENTRADA | BT4: SAÍDA
A5: PAGAMENTO EFETUADO
A6: PAGAMENTO ADIADO
A7: PAGAMENTO ATRASADO
A8: NÃO VENCIDO
B46: SALDO MENSAL: | H46: SALDO MENSAL: | N46: SALDO MENSAL: | T46: SALDO MENSAL: | Z46: SALDO MENSAL: | AF46: SALDO MENSAL: | AL46: SALDO MENSAL: | AR46: SALDO MENSAL: | AX46: SALDO MENSAL: | BD46: SALDO MENSAL: | BJ46: SALDO MENSAL: | BP46: SALDO MENSAL:

Sheet Controle
A1: CONTROLE DE ESTOQUES- CONTROLE
G3: JANEIRO | K3: FEVEREIRO | O3: MARÇO | S3: ABRIL | W3: MAIO | AA3: JUNHO | AE3: JULHO | AI3: AGOSTO | AM3: SETEMBRO | AQ3: OUTUBRO | AU3: NOVEMBRO | AY3: DEZEMBRO
D5: ESTOQUE ATUAL | E5: VALOR DO ESTOQUE | F5: NECESSIDADE DE ESTOQUE (?)
G6: ENTRADA | H6: SAÍDA | I6: TOTAL | J6: VALOR EM ESTOQUE | K6: ENTRADA | L6: SAÍDA | M6: TOTAL | N6: VALOR EM ESTOQUE | O6: ENTRADA | P6: SAÍDA | Q6: TOTAL | R6: VALOR EM ESTOQUE | S6: ENTRADA | T6: SAÍDA | U6: TOTAL | V6: VALOR EM ESTOQUE | W6: ENTRADA | X6: SAÍDA | Y6: TOTAL | Z6: VALOR EM ESTOQUE | AA6: ENTRADA | AB6: SAÍDA | AC6: TOTAL | AD6: VALOR EM ESTOQUE | AE6: ENTRADA | AF6: SAÍDA | AG6: TOTAL | AH6: VALOR EM ESTOQUE | AI6: ENTRADA | AJ6: SAÍDA | AK6: TOTAL | AL6: VALOR EM ESTOQUE | AM6: ENTRADA | AN6: SAÍDA | AO6: TOTAL | AP6: VALOR EM ESTOQUE | AQ6: ENTRADA | AR6: SAÍDA | AS6: TOTAL | AT6: VALOR EM ESTOQUE | AU6: ENTRADA | AV6: SAÍDA | AW6: TOTAL | AX6: VALOR EM ESTOQUE | AY6: ENTRADA | AZ6: SAÍDA | BA6: TOTAL | BB6: VALOR EM ESTOQUE
B8: =IF(Inventário!C4="","",Inventário!C4) | C8: =IF(B8="","",VLOOKUP(B8,Inventário!$C$4:$D$53,2,FALSE)) | D8: =IF(B8="","",I8+M8+Q8+U8+Y8+AC8+AG8+AK8+AO8+AS8+AW8+BA8+Inventário!H4) | E8: =IF(B8="","",IF(D8<0,"-",(D8*Inventário!G4))) | F8: =IF(B8="","",IF(D8>Inventário!I4,"NÃO",CONCATENATE("SIM:"," ",Inventário!J4," ","unid"))) | G8: =SUMIF('Entradas e Saídas'!$D$5:$D$44,Controle!$C8,'Entradas e Saídas'!$E$5:$E$44) -> 0 | H8: =SUMIF('Entradas e Saídas'!$D$5:$D$44,Controle!$C8,'Entradas e Saídas'!$F$5:$F$44) -> 0 | I8: =G8-H8 -> 0 | J8: =I8*Inventário!$G4 -> 0 | K8: =SUMIF('Entradas e Saídas'!$J$5:$J$44,Controle!$C8,'Entradas e Saídas'!$K$5:$K$44) -> 0 | L8: =SUMIF('Entradas e Saídas'!$J$5:$J$44,Controle!$C8,'Entradas e Saídas'!$L$5:$L$44) -> 0 | M8: =K8-L8 -> 0 | N8: =M8*Inventário!$G4 -> 0 | O8: =SUMIF('Entradas e Saídas'!$P$5:$P$44,Controle!$C8,'Entradas e Saídas'!$Q$5:$Q$44) -> 0 | P8: =SUMIF('Entradas e Saídas'!$P$5:$P$44,Controle!$C8,'Entradas e Saídas'!$R$5:$R$44) -> 0 | Q8: =O8-P8 -> 0 | R8: =Q8*Inventário!$G4 -> 0 | S8: =SUMIF('Entradas e Saídas'!$V$5:$V$44,Controle!$C8,'Entradas e Saídas'!$W$5:$W$44) -> 0 | T8: =SUMIF('Entradas e Saídas'!$V$5:$V$44,Controle!$C8,'Entradas e Saídas'!$X$5:$X$44) -> 0 | U8: =S8-T8 -> 0 | V8: =U8*Inventário!$G4 -> 0 | W8: =SUMIF('Entradas e Saídas'!$AB$5:$AB$44,Controle!$C8,'Entradas e Saídas'!$AC$5:$AC$44) -> 0 | X8: =SUMIF('Entradas e Saídas'!$AB$5:$AB$44,Controle!$C8,'Entradas e Saídas'!$AD$5:$AD$44) -> 0 | Y8: =W8-X8 -> 0 | Z8: =Y8*Inventário!$G4 -> 0 | AA8: =SUMIF('Entradas e Saídas'!$AH$5:$AH$44,Controle!$C8,'Entradas e Saídas'!$AI$5:$AI$44) -> 0 | AB8: =SUMIF('Entradas e Saídas'!$AH$5:$AH$44,Controle!$C8,'Entradas e Saídas'!$AJ$5:$AJ$44) -> 0 | AC8: =AA8-AB8 -> 0 | AD8: =AC8*Inventário!$G4 -> 0 | AE8: =SUMIF('Entradas e Saídas'!$AN$5:$AN$44,Controle!$C8,'Entradas e Saídas'!$AO$5:$AO$44) -> 0 | AF8: =SUMIF('Entradas e Saídas'!$AH$5:$AH$44,Controle!$C8,'Entradas e Saídas'!$AP$5:$AP$44) -> 0 | AG8: =AE8-AF8 -> 0 | AH8: =AG8*Inventário!$G4 -> 0 | AI8: =SUMIF('Entradas e Saídas'!$AT$5:$AT$44,Controle!$C8,'Entradas e Saídas'!$AU$5:$AU$44) -> 0 | AJ8: =SUMIF('Entradas e Saídas'!$AT$5:$AT$44,Controle!$C8,'Entradas e Saídas'!$AV$5:$AV$44) -> 0 | AK8: =AI8-AJ8 -> 0 | AL8: =AK8*Inventário!$G4 -> 0 | AM8: =SUMIF('Entradas e Saídas'!$AZ$5:$AZ$44,Controle!$C8,'Entradas e Saídas'!$BA$5:$BA$44) -> 0 | AN8: =SUMIF('Entradas e Saídas'!$AZ$5:$AZ$44,Controle!$C8,'Entradas e Saídas'!$BB$5:$BB$44) -> 0 | AO8: =AM8-AN8 -> 0 | AP8: =AO8*Inventário!$G4 -> 0 | AQ8: =SUMIF('Entradas e Saídas'!$BF$5:$BF$44,Controle!$C8,'Entradas e Saídas'!$BG$5:$BG$44) -> 0 | AR8: =SUMIF('Entradas e Saídas'!$BF$5:$BF$44,Controle!$C8,'Entradas e Saídas'!$BH$5:$BH$44) -> 0 | AS8: =AQ8-AR8 -> 0 | AT8: =AS8*Inventário!$G4 -> 0 | AU8: =SUMIF('Entradas e Saídas'!$BL$5:$BL$44,Controle!$C8,'Entradas e Saídas'!$BM$5:$BM$44) -> 0 | AV8: =SUMIF('Entradas e Saídas'!$BL$5:$BL$44,Controle!$C8,'Entradas e Saídas'!$BN$5:$BN$44) -> 0 | AW8: =AU8-AV8 -> 0 | AX8: =AW8*Inventário!$G4 -> 0 | AY8: =SUMIF('Entradas e Saídas'!$BR$5:$BR$44,Controle!$C8,'Entradas e Saídas'!$BS$5:$BS$44) -> 0 | AZ8: =SUMIF('Entradas e Saídas'!$BR$5:$BR$44,Controle!$C8,'Entradas e Saídas'!$BT$5:$BT$44) -> 0 | BA8: =AY8-AZ8 -> 0 | BB8: =BA8*Inventário!$G4 -> 0
B9: =IF(Inventário!C5="","",Inventário!C5) | C9: =IF(B9="","",VLOOKUP(B9,Inventário!$C$4:$D$53,2,FALSE)) | D9: =IF(B9="","",I9+M9+Q9+U9+Y9+AC9+AG9+AK9+AO9+AS9+AW9+BA9+Inventário!H5) | E9: =IF(B9="","",IF(D9<0,"-",(D9*Inventário!G5))) | F9: =IF(B9="","",IF(D9>Inventário!I5,"NÃO",CONCATENATE("SIM:"," ",Inventário!J5," ","unid"))) | G9: =SUMIF('Entradas e Saídas'!$D$5:$D$44,Controle!$C9,'Entradas e Saídas'!$E$5:$E$44) -> 0 | H9: =SUMIF('Entradas e Saídas'!$D$5:$D$44,Controle!$C9,'Entradas e Saídas'!$F$5:$F$44) -> 0 | I9: =G9-H9 -> 0 | J9: =I9*Inventário!G5 -> 0 | K9: =SUMIF('Entradas e Saídas'!$J$5:$J$44,Controle!$C9,'Entradas e Saídas'!$K$5:$K$44) -> 0 | L9: =SUMIF('Entradas e Saídas'!$J$5:$J$44,Controle!$C9,'Entradas e Saídas'!$L$5:$L$44) -> 0 | M9: =K9-L9 -> 0 | N9: =M9*Inventário!$G5 -> 0 | O9: =SUMIF('Entradas e Saídas'!$P$5:$P$44,Controle!$C9,'Entradas e Saídas'!$Q$5:$Q$44) -> 0 | P9: =SUMIF('Entradas e Saídas'!$P$5:$P$44,Controle!$C9,'Entradas e Saídas'!$R$5:$R$44) -> 0 | Q9: =O9-P9 -> 0 | R9: =Q9*Inventário!$G5 -> 0 | S9: =SUMIF('Entradas e Saídas'!$V$5:$V$44,Controle!$C9,'Entradas e Saídas'!$W$5:$W$44) -> 0 | T9: =SUMIF('Entradas e Saídas'!$V$5:$V$44,Controle!$C9,'Entradas e Saídas'!$X$5:$X$44) -> 0 | U9: =S9-T9 -> 0 | V9: =U9*Inventário!$G5 -> 0 | W9: =SUMIF('Entradas e Saídas'!$AB$5:$AB$44,Controle!$C9,'Entradas e Saídas'!$AC$5:$AC$44) -> 0 | X9: =SUMIF('Entradas e Saídas'!$AB$5:$AB$44,Controle!$C9,'Entradas e Saídas'!$AD$5:$AD$44) -> 0 | Y9: =W9-X9 -> 0 | Z9: =Y9*Inventário!$G5 -> 0 | AA9: =SUMIF('Entradas e Saídas'!$AH$5:$AH$44,Controle!$C9,'Entradas e Saídas'!$AI$5:$AI$44) -> 0 | AB9: =SUMIF('Entradas e Saídas'!$AH$5:$AH$44,Controle!$C9,'Entradas e Saídas'!$AJ$5:$AJ$44) -> 0 | AC9: =AA9-AB9 -> 0 | AD9: =AC9*Inventário!$G5 -> 0 | AE9: =SUMIF('Entradas e Saídas'!$AN$5:$AN$44,Controle!$C9,'Entradas e Saídas'!$AO$5:$AO$44) -> 0 | AF9: =SUMIF('Entradas e Saídas'!$AH$5:$AH$44,Controle!$C9,'Entradas e Saídas'!$AP$5:$AP$44) -> 0 | AG9: =AE9-AF9 -> 0 | AH9: =AG9*Inventário!$G5 -> 0 | AI9: =SUMIF('Entradas e Saídas'!$AT$5:$AT$44,Controle!$C9,'Entradas e Saídas'!$AU$5:$AU$44) -> 0 | AJ9: =SUMIF('Entradas e Saídas'!$AT$5:$AT$44,Controle!$C9,'Entradas e Saídas'!$AV$5:$AV$44) -> 0 | AK9: =AI9-AJ9 -> 0 | AL9: =AK9*Inventário!$G5 -> 0 | AM9: =SUMIF('Entradas e Saídas'!$AZ$5:$AZ$44,Controle!$C9,'Entradas e Saídas'!$BA$5:$BA$44) -> 0 | AN9: =SUMIF('Entradas e Saídas'!$AZ$5:$AZ$44,Controle!$C9,'Entradas e Saídas'!$BB$5:$BB$44) -> 0 | AO9: =AM9-AN9 -> 0 | AP9: =AO9*Inventário!$G5 -> 0 | AQ9: =SUMIF('Entradas e Saídas'!$BF$5:$BF$44,Controle!$C9,'Entradas e Saídas'!$BG$5:$BG$44) -> 0 | AR9: =SUMIF('Entradas e Saídas'!$BF$5:$BF$44,Controle!$C9,'Entradas e Saídas'!$BH$5:$BH$44) -> 0 | AS9: =AQ9-AR9 -> 0 | AT9: =AS9*Inventário!$G5 -> 0 | AU9: =SUMIF('Entradas e Saídas'!$BL$5:$BL$44,Controle!$C9,'Entradas e Saídas'!$BM$5:$BM$44) -> 0 | AV9: =SUMIF('Entradas e Saídas'!$BL$5:$BL$44,Controle!$C9,'Entradas e Saídas'!$BN$5:$BN$44) -> 0 | AW9: =AU9-AV9 -> 0 | AX9: =AW9*Inventário!$G5 -> 0 | AY9: =SUMIF('Entradas e Saídas'!$BR$5:$BR$44,Controle!$C9,'Entradas e Saídas'!$BS$5:$BS$44) -> 0 | AZ9: =SUMIF('Entradas e Saídas'!$BR$5:$BR$44,Controle!$C9,'Entradas e Saídas'!$BT$5:$BT$44) -> 0 | BA9: =AY9-AZ9 -> 0 | BB9: =BA9*Inventário!$G5 -> 0
B10: =IF(Inventário!C6="","",Inventário!C6) | C10: =IF(B10="","",VLOOKUP(B10,Inventário!$C$4:$D$53,2,FALSE)) | D10: =IF(B10="","",I10+M10+Q10+U10+Y10+AC10+AG10+AK10+AO10+AS10+AW10+BA10+Inventário!H6) | E10: =IF(B10="","",IF(D10<0,"-",(D10*Inventário!G6))) | F10: =IF(B10="","",IF(D10>Inventário!I6,"NÃO",CONCATENATE("SIM:"," ",Inventário!J6," ","unid"))) | G10: =SUMIF('Entradas e Saídas'!$D$5:$D$44,Controle!$C10,'Entradas e Saídas'!$E$5:$E$44) -> 0 | H10: =SUMIF('Entradas e Saídas'!$D$5:$D$44,Controle!$C10,'Entradas e Saídas'!$F$5:$F$44) -> 0 | I10: =G10-H10 -> 0 | J10: =I10*Inventário!G6 -> 0 | K10: =SUMIF('Entradas e Saídas'!$J$5:$J$44,Controle!$C10,'Entradas e Saídas'!$K$5:$K$44) -> 0 | L10: =SUMIF('Entradas e Saídas'!$J$5:$J$44,Controle!$C10,'Entradas e Saídas'!$L$5:$L$44) -> 0 | M10: =K10-L10 -> 0 | N10: =M10*Inventário!$G6 -> 0 | O10: =SUMIF('Entradas e Saídas'!$P$5:$P$44,Controle!$C10,'Entradas e Saídas'!$Q$5:$Q$44) -> 0 | P10: =SUMIF('Entradas e Saídas'!$P$5:$P$44,Controle!$C10,'Entradas e Saídas'!$R$5:$R$44) -> 0 | Q10: =O10-P10 -> 0 | R10: =Q10*Inventário!$G6 -> 0 | S10: =SUMIF('Entradas e Saídas'!$V$5:$V$44,Controle!$C10,'Entradas e Saídas'!$W$5:$W$44) -> 0 | T10: =SUMIF('Entradas e Saídas'!$V$5:$V$44,Controle!$C10,'Entradas e Saídas'!$X$5:$X$44) -> 0 | U10: =S10-T10 -> 0 | V10: =U10*Inventário!$G6 -> 0 | W10: =SUMIF('Entradas e Saídas'!$AB$5:$AB$44,Controle!$C10,'Entradas e Saídas'!$AC$5:$AC$44) -> 0 | X10: =SUMIF('Entradas e Saídas'!$AB$5:$AB$44,Controle!$C10,'Entradas e Saídas'!$AD$5:$AD$44) -> 0 | Y10: =W10-X10 -> 0 | Z10: =Y10*Inventário!$G6 -> 0 | AA10: =SUMIF('Entradas e Saídas'!$AH$5:$AH$44,Controle!$C10,'Entradas e Saídas'!$AI$5:$AI$44) -> 0 | AB10: =SUMIF('Entradas e Saídas'!$AH$5:$AH$44,Controle!$C10,'Entradas e Saídas'!$AJ$5:$AJ$44) -> 0 | AC10: =AA10-AB10 -> 0 | AD10: =AC10*Inventário!$G6 -> 0 | AE10: =SUMIF('Entradas e Saídas'!$AN$5:$AN$44,Controle!$C10,'Entradas e Saídas'!$AO$5:$AO$44) -> 0 | AF10: =SUMIF('Entradas e Saídas'!$AH$5:$AH$44,Controle!$C10,'Entradas e Saídas'!$AP$5:$AP$44) -> 0 | AG10: =AE10-AF10 -> 0 | AH10: =AG10*Inventário!$G6 -> 0 | AI10: =SUMIF('Entradas e Saídas'!$AT$5:$AT$44,Controle!$C10,'Entradas e Saídas'!$AU$5:$AU$44) -> 0 | AJ10: =SUMIF('Entradas e Saídas'!$AT$5:$AT$44,Controle!$C10,'Entradas e Saídas'!$AV$5:$AV$44) -> 0 | AK10: =AI10-AJ10 -> 0 | AL10: =AK10*Inventário!$G6 -> 0 | AM10: =SUMIF('Entradas e Saídas'!$AZ$5:$AZ$44,Controle!$C10,'Entradas e Saídas'!$BA$5:$BA$44) -> 0 | AN10: =SUMIF('Entradas e Saídas'!$AZ$5:$AZ$44,Controle!$C10,'Entradas e Saídas'!$BB$5:$BB$44) -> 0 | AO10: =AM10-AN10 -> 0 | AP10: =AO10*Inventário!$G6 -> 0 | AQ10: =SUMIF('Entradas e Saídas'!$BF$5:$BF$44,Controle!$C10,'Entradas e Saídas'!$BG$5:$BG$44) -> 0 | AR10: =SUMIF('Entradas e Saídas'!$BF$5:$BF$44,Controle!$C10,'Entradas e Saídas'!$BH$5:$BH$44) -> 0 | AS10: =AQ10-AR10 -> 0 | AT10: =AS10*Inventário!$G6 -> 0 | AU10: =SUMIF('Entradas e Saídas'!$BL$5:$BL$44,Controle!$C10,'Entradas e Saídas'!$BM$5:$BM$44) -> 0 | AV10: =SUMIF('Entradas e Saídas'!$BL$5:$BL$44,Controle!$C10,'Entradas e Saídas'!$BN$5:$BN$44) -> 0 | AW10: =AU10-AV10 -> 0 | AX10: =AW10*Inventário!$G6 -> 0 | AY10: =SUMIF('Entradas e Saídas'!$BR$5:$BR$44,Controle!$C10,'Entradas e Saídas'!$BS$5:$BS$44) -> 0 | AZ10: =SUMIF('Entradas e Saídas'!$BR$5:$BR$44,Controle!$C10,'Entradas e Saídas'!$BT$5:$BT$44) -> 0 | BA10: =AY10-AZ10 -> 0 | BB10: =BA10*Inventário!$G6 -> 0
B11: =IF(Inventário!C7="","",Inventário!C7) | C11: =IF(B11="","",VLOOKUP(B11,Inventário!$C$4:$D$53,2,FALSE)) | D11: =IF(B11="","",I11+M11+Q11+U11+Y11+AC11+AG11+AK11+AO11+AS11+AW11+BA11+Inventário!H7) | E11: =IF(B11="","",IF(D11<0,"-",(D11*Inventário!G7))) | F11: =IF(B11="","",IF(D11>Inventário!I7,"NÃO",CONCATENATE("SIM:"," ",Inventário!J7," ","unid"))) | G11: =SUMIF('Entradas e Saídas'!$D$5:$D$44,Controle!$C11,'Entradas e Saídas'!$E$5:$E$44) -> 0 | H11: =SUMIF('Entradas e Saídas'!$D$5:$D$44,Controle!$C11,'Entradas e Saídas'!$F$5:$F$44) -> 0 | I11: =G11-H11 -> 0 | J11: =I11*Inventário!G7 -> 0 | K11: =SUMIF('Entradas e Saídas'!$J$5:$J$44,Controle!$C11,'Entradas e Saídas'!$K$5:$K$44) -> 0 | L11: =SUMIF('Entradas e Saídas'!$J$5:$J$44,Controle!$C11,'Entradas e Saídas'!$L$5:$L$44) -> 0 | M11: =K11-L11 -> 0 | N11: =M11*Inventário!$G7 -> 0 | O11: =SUMIF('Entradas e Saídas'!$P$5:$P$44,Controle!$C11,'Entradas e Saídas'!$Q$5:$Q$44) -> 0 | P11: =SUMIF('Entradas e Saídas'!$P$5:$P$44,Controle!$C11,'Entradas e Saídas'!$R$5:$R$44) -> 0 | Q11: =O11-P11 -> 0 | R11: =Q11*Inventário!$G7 -> 0 | S11: =SUMIF('Entradas e Saídas'!$V$5:$V$44,Controle!$C11,'Entradas e Saídas'!$W$5:$W$44) -> 0 | T11: =SUMIF('Entradas e Saídas'!$V$5:$V$44,Controle!$C11,'Entradas e Saídas'!$X$5:$X$44) -> 0 | U11: =S11-T11 -> 0 | V11: =U11*Inventário!$G7 -> 0 | W11: =SUMIF('Entradas e Saídas'!$AB$5:$AB$44,Controle!$C11,'Entradas e Saídas'!$AC$5:$AC$44) -> 0 | X11: =SUMIF('Entradas e Saídas'!$AB$5:$AB$44,Controle!$C11,'Entradas e Saídas'!$AD$5:$AD$44) -> 0 | Y11: =W11-X11 -> 0 | Z11: =Y11*Inventário!$G7 -> 0 | AA11: =SUMIF('Entradas e Saídas'!$AH$5:$AH$44,Controle!$C11,'Entradas e Saídas'!$AI$5:$AI$44) -> 0 | AB11: =SUMIF('Entradas e Saídas'!$AH$5:$AH$44,Controle!$C11,'Entradas e Saídas'!$AJ$5:$AJ$44) -> 0 | AC11: =AA11-AB11 -> 0 | AD11: =AC11*Inventário!$G7 -> 0 | AE11: =SUMIF('Entradas e Saídas'!$AN$5:$AN$44,Controle!$C11,'Entradas e Saídas'!$AO$5:$AO$44) -> 0 | AF11: =SUMIF('Entradas e Saídas'!$AH$5:$AH$44,Controle!$C11,'Entradas e Saídas'!$AP$5:$AP$44) -> 0 | AG11: =AE11-AF11 -> 0 | AH11: =AG11*Inventário!$G7 -> 0 | AI11: =SUMIF('Entradas e Saídas'!$AT$5:$AT$44,Controle!$C11,'Entradas e Saídas'!$AU$5:$AU$44) -> 0 | AJ11: =SUMIF('Entradas e Saídas'!$AT$5:$AT$44,Controle!$C11,'Entradas e Saídas'!$AV$5:$AV$44) -> 0 | AK11: =AI11-AJ11 -> 0 | AL11: =AK11*Inventário!$G7 -> 0 | AM11: =SUMIF('Entradas e Saídas'!$AZ$5:$AZ$44,Controle!$C11,'Entradas e Saídas'!$BA$5:$BA$44) -> 0 | AN11: =SUMIF('Entradas e Saídas'!$AZ$5:$AZ$44,Controle!$C11,'Entradas e Saídas'!$BB$5:$BB$44) -> 0 | AO11: =AM11-AN11 -> 0 | AP11: =AO11*Inventário!$G7 -> 0 | AQ11: =SUMIF('Entradas e Saídas'!$BF$5:$BF$44,Controle!$C11,'Entradas e Saídas'!$BG$5:$BG$44) -> 0 | AR11: =SUMIF('Entradas e Saídas'!$BF$5:$BF$44,Controle!$C11,'Entradas e Saídas'!$BH$5:$BH$44) -> 0 | AS11: =AQ11-AR11 -> 0 | AT11: =AS11*Inventário!$G7 -> 0 | AU11: =SUMIF('Entradas e Saídas'!$BL$5:$BL$44,Controle!$C11,'Entradas e Saídas'!$BM$5:$BM$44) -> 0 | AV11: =SUMIF('Entradas e Saídas'!$BL$5:$BL$44,Controle!$C11,'Entradas e Saídas'!$BN$5:$BN$44) -> 0 | AW11: =AU11-AV11 -> 0 | AX11: =AW11*Inventário!$G7 -> 0 | AY11: =SUMIF('Entradas e Saídas'!$BR$5:$BR$44,Controle!$C11,'Entradas e Saídas'!$BS$5:$BS$44) -> 0 | AZ11: =SUMIF('Entradas e Saídas'!$BR$5:$BR$44,Controle!$C11,'Entradas e Saídas'!$BT$5:$BT$44) -> 0 | BA11: =AY11-AZ11 -> 0 | BB11: =BA11*Inventário!$G7 -> 0 | BE11: JANEIRO | BF11: =J59 -> 0
B12: =IF(Inventário!C8="","",Inventário!C8) | C12: =IF(B12="","",VLOOKUP(B12,Inventário!$C$4:$D$53,2,FALSE)) | D12: =IF(B12="","",I12+M12+Q12+U12+Y12+AC12+AG12+AK12+AO12+AS12+AW12+BA12+Inventário!H8) | E12: =IF(B12="","",IF(D12<0,"-",(D12*Inventário!G8))) | F12: =IF(B12="","",IF(D12>Inventário!I8,"NÃO",CONCATENATE("SIM:"," ",Inventário!J8," ","unid"))) | G12: =SUMIF('Entradas e Saídas'!$D$5:$D$44,Controle!$C12,'Entradas e Saídas'!$E$5:$E$44) -> 0 | H12: =SUMIF('Entradas e Saídas'!$D$5:$D$44,Controle!$C12,'Entradas e Saídas'!$F$5:$F$44) -> 0 | I12: =G12-H12 -> 0 | J12: =I12*Inventário!G8 -> 0 | K12: =SUMIF('Entradas e Saídas'!$J$5:$J$44,Controle!$C12,'Entradas e Saídas'!$K$5:$K$44) -> 0 | L12: =SUMIF('Entradas e Saídas'!$J$5:$J$44,Controle!$C12,'Entradas e Saídas'!$L$5:$L$44) -> 0 | M12: =K12-L12 -> 0 | N12: =M12*Inventário!$G8 -> 0 | O12: =SUMIF('Entradas e Saídas'!$P$5:$P$44,Controle!$C12,'Entradas e Saídas'!$Q$5:$Q$44) -> 0 | P12: =SUMIF('Entradas e Saídas'!$P$5:$P$44,Controle!$C12,'Entradas e Saídas'!$R$5:$R$44) -> 0 | Q12: =O12-P12 -> 0 | R12: =Q12*Inventário!$G8 -> 0 | S12: =SUMIF('Entradas e Saídas'!$V$5:$V$44,Controle!$C12,'Entradas e Saídas'!$W$5:$W$44) -> 0 | T12: =SUMIF('Entradas e Saídas'!$V$5:$V$44,Controle!$C12,'Entradas e Saídas'!$X$5:$X$44) -> 0 | U12: =S12-T12 -> 0 | V12: =U12*Inventário!$G8 -> 0 | W12: =SUMIF('Entradas e Saídas'!$AB$5:$AB$44,Controle!$C12,'Entradas e Saídas'!$AC$5:$AC$44) -> 0 | X12: =SUMIF('Entradas e Saídas'!$AB$5:$AB$44,Controle!$C12,'Entradas e Saídas'!$AD$5:$AD$44) -> 0 | Y12: =W12-X12 -> 0 | Z12: =Y12*Inventário!$G8 -> 0 | AA12: =SUMIF('Entradas e Saídas'!$AH$5:$AH$44,Controle!$C12,'Entradas e Saídas'!$AI$5:$AI$44) -> 0 | AB12: =SUMIF('Entradas e Saídas'!$AH$5:$AH$44,Controle!$C12,'Entradas e Saídas'!$AJ$5:$AJ$44) -> 0 | AC12: =AA12-AB12 -> 0 | AD12: =AC12*Inventário!$G8 -> 0 | AE12: =SUMIF('Entradas e Saídas'!$AN$5:$AN$44,Controle!$C12,'Entradas e Saídas'!$AO$5:$AO$44) -> 0 | AF12: =SUMIF('Entradas e Saídas'!$AH$5:$AH$44,Controle!$C12,'Entradas e Saídas'!$AP$5:$AP$44) -> 0 | AG12: =AE12-AF12 -> 0 | AH12: =AG12*Inventário!$G8 -> 0 | AI12: =SUMIF('Entradas e Saídas'!$AT$5:$AT$44,Controle!$C12,'Entradas e Saídas'!$AU$5:$AU$44) -> 0 | AJ12: =SUMIF('Entradas e Saídas'!$AT$5:$AT$44,Controle!$C12,'Entradas e Saídas'!$AV$5:$AV$44) -> 0 | AK12: =AI12-AJ12 -> 0 | AL12: =AK12*Inventário!$G8 -> 0 | AM12: =SUMIF('Entradas e Saídas'!$AZ$5:$AZ$44,Controle!$C12,'Entradas e Saídas'!$BA$5:$BA$44) -> 0 | AN12: =SUMIF('Entradas e Saídas'!$AZ$5:$AZ$44,Controle!$C12,'Entradas e Saídas'!$BB$5:$BB$44) -> 0 | AO12: =AM12-AN12 -> 0 | AP12: =AO12*Inventário!$G8 -> 0 | AQ12: =SUMIF('Entradas e Saídas'!$BF$5:$BF$44,Controle!$C12,'Entradas e Saídas'!$BG$5:$BG$44) -> 0 | AR12: =SUMIF('Entradas e Saídas'!$BF$5:$BF$44,Controle!$C12,'Entradas e Saídas'!$BH$5:$BH$44) -> 0 | AS12: =AQ12-AR12 -> 0 | AT12: =AS12*Inventário!$G8 -> 0 | AU12: =SUMIF('Entradas e Saídas'!$BL$5:$BL$44,Controle!$C12,'Entradas e Saídas'!$BM$5:$BM$44) -> 0 | AV12: =SUMIF('Entradas e Saídas'!$BL$5:$BL$44,Controle!$C12,'Entradas e Saídas'!$BN$5:$BN$44) -> 0 | AW12: =AU12-AV12 -> 0 | AX12: =AW12*Inventário!$G8 -> 0 | AY12: =SUMIF('Entradas e Saídas'!$BR$5:$BR$44,Controle!$C12,'Entradas e Saídas'!$BS$5:$BS$44) -> 0 | AZ12: =SUMIF('Entradas e Saídas'!$BR$5:$BR$44,Controle!$C12,'Entradas e Saídas'!$BT$5:$BT$44) -> 0 | BA12: =AY12-AZ12 -> 0 | BB12: =BA12*Inventário!$G8 -> 0 | BE12: FEVEREIRO | BF12: =N59 -> 0
B13: =IF(Inventário!C9="","",Inventário!C9) | C13: =IF(B13="","",VLOOKUP(B13,Inventário!$C$4:$D$53,2,FALSE)) | D13: =IF(B13="","",I13+M13+Q13+U13+Y13+AC13+AG13+AK13+AO13+AS13+AW13+BA13+Inventário!H9) | E13: =IF(B13="","",IF(D13<0,"-",(D13*Inventário!G9))) | F13: =IF(B13="","",IF(D13>Inventário!I9,"NÃO",CONCATENATE("SIM:"," ",Inventário!J9," ","unid"))) | G13: =SUMIF('Entradas e Saídas'!$D$5:$D$44,Controle!$C13,'Entradas e Saídas'!$E$5:$E$44) -> 0 | H13: =SUMIF('Entradas e Saídas'!$D$5:$D$44,Controle!$C13,'Entradas e Saídas'!$F$5:$F$44) -> 0 | I13: =G13-H13 -> 0 | J13: =I13*Inventário!G9 -> 0 | K13: =SUMIF('Entradas e Saídas'!$J$5:$J$44,Controle!$C13,'Entradas e Saídas'!$K$5:$K$44) -> 0 | L13: =SUMIF('Entradas e Saídas'!$J$5:$J$44,Controle!$C13,'Entradas e Saídas'!$L$5:$L$44) -> 0 | M13: =K13-L13 -> 0 | N13: =M13*Inventário!$G9 -> 0 | O13: =SUMIF('Entradas e Saídas'!$P$5:$P$44,Controle!$C13,'Entradas e Saídas'!$Q$5:$Q$44) -> 0 | P13: =SUMIF('Entradas e Saídas'!$P$5:$P$44,Controle!$C13,'Entradas e Saídas'!$R$5:$R$44) -> 0 | Q13: =O13-P13 -> 0 | R13: =Q13*Inventário!$G9 -> 0 | S13: =SUMIF('Entradas e Saídas'!$V$5:$V$44,Controle!$C13,'Entradas e Saídas'!$W$5:$W$44) -> 0 | T13: =SUMIF('Entradas e Saídas'!$V$5:$V$44,Controle!$C13,'Entradas e Saídas'!$X$5:$X$44) -> 0 | U13: =S13-T13 -> 0 | V13: =U13*Inventário!$G9 -> 0 | W13: =SUMIF('Entradas e Saídas'!$AB$5:$AB$44,Controle!$C13,'Entradas e Saídas'!$AC$5:$AC$44) -> 0 | X13: =SUMIF('Entradas e Saídas'!$AB$5:$AB$44,Controle!$C13,'Entradas e Saídas'!$AD$5:$AD$44) -> 0 | Y13: =W13-X13 -> 0 | Z13: =Y13*Inventário!$G9 -> 0 | AA13: =SUMIF('Entradas e Saídas'!$AH$5:$AH$44,Controle!$C13,'Entradas e Saídas'!$AI$5:$AI$44) -> 0 | AB13: =SUMIF('Entradas e Saídas'!$AH$5:$AH$44,Controle!$C13,'Entradas e Saídas'!$AJ$5:$AJ$44) -> 0 | AC13: =AA13-AB13 -> 0 | AD13: =AC13*Inventário!$G9 -> 0 | AE13: =SUMIF('Entradas e Saídas'!$AN$5:$AN$44,Controle!$C13,'Entradas e Saídas'!$AO$5:$AO$44) -> 0 | AF13: =SUMIF('Entradas e Saídas'!$AH$5:$AH$44,Controle!$C13,'Entradas e Saídas'!$AP$5:$AP$44) -> 0 | AG13: =AE13-AF13 -> 0 | AH13: =AG13*Inventário!$G9 -> 0 | AI13: =SUMIF('Entradas e Saídas'!$AT$5:$AT$44,Controle!$C13,'Entradas e Saídas'!$AU$5:$AU$44) -> 0 | AJ13: =SUMIF('Entradas e Saídas'!$AT$5:$AT$44,Controle!$C13,'Entradas e Saídas'!$AV$5:$AV$44) -> 0 | AK13: =AI13-AJ13 -> 0 | AL13: =AK13*Inventário!$G9 -> 0 | AM13: =SUMIF('Entradas e Saídas'!$AZ$5:$AZ$44,Controle!$C13,'Entradas e Saídas'!$BA$5:$BA$44) -> 0 | AN13: =SUMIF('Entradas e Saídas'!$AZ$5:$AZ$44,Controle!$C13,'Entradas e Saídas'!$BB$5:$BB$44) -> 0 | AO13: =AM13-AN13 -> 0 | AP13: =AO13*Inventário!$G9 -> 0 | AQ13: =SUMIF('Entradas e Saídas'!$BF$5:$BF$44,Controle!$C13,'Entradas e Saídas'!$BG$5:$BG$44) -> 0 | AR13: =SUMIF('Entradas e Saídas'!$BF$5:$BF$44,Controle!$C13,'Entradas e Saídas'!$BH$5:$BH$44) -> 0 | AS13: =AQ13-AR13 -> 0 | AT13: =AS13*Inventário!$G9 -> 0 | AU13: =SUMIF('Entradas e Saídas'!$BL$5:$BL$44,Controle!$C13,'Entradas e Saídas'!$BM$5:$BM$44) -> 0 | AV13: =SUMIF('Entradas e Saídas'!$BL$5:$BL$44,Controle!$C13,'Entradas e Saídas'!$BN$5:$BN$44) -> 0 | AW13: =AU13-AV13 -> 0 | AX13: =AW13*Inventário!$G9 -> 0 | AY13: =SUMIF('Entradas e Saídas'!$BR$5:$BR$44,Controle!$C13,'Entradas e Saídas'!$BS$5:$BS$44) -> 0 | AZ13: =SUMIF('Entradas e Saídas'!$BR$5:$BR$44,Controle!$C13,'Entradas e Saídas'!$BT$5:$BT$44) -> 0 | BA13: =AY13-AZ13 -> 0 | BB13: =BA13*Inventário!$G9 -> 0 | BE13: MARÇO | BF13: =R59 -> 0
B14: =IF(Inventário!C10="","",Inventário!C10) | C14: =IF(B14="","",VLOOKUP(B14,Inventário!$C$4:$D$53,2,FALSE)) | D14: =IF(B14="","",I14+M14+Q14+U14+Y14+AC14+AG14+AK14+AO14+AS14+AW14+BA14+Inventário!H10) | E14: =IF(B14="","",IF(D14<0,"-",(D14*Inventário!G10))) | F14: =IF(B14="","",IF(D14>Inventário!I10,"NÃO",CONCATENATE("SIM:"," ",Inventário!J10," ","unid"))) | G14: =SUMIF('Entradas e Saídas'!$D$5:$D$44,Controle!$C14,'Entradas e Saídas'!$E$5:$E$44) -> 0 | H14: =SUMIF('Entradas e Saídas'!$D$5:$D$44,Controle!$C14,'Entradas e Saídas'!$F$5:$F$44) -> 0 | I14: =G14-H14 -> 0 | J14: =I14*Inventário!G10 -> 0 | K14: =SUMIF('Entradas e Saídas'!$J$5:$J$44,Controle!$C14,'Entradas e Saídas'!$K$5:$K$44) -> 0 | L14: =SUMIF('Entradas e Saídas'!$J$5:$J$44,Controle!$C14,'Entradas e Saídas'!$L$5:$L$44) -> 0 | M14: =K14-L14 -> 0 | N14: =M14*Inventário!$G10 -> 0 | O14: =SUMIF('Entradas e Saídas'!$P$5:$P$44,Controle!$C14,'Entradas e Saídas'!$Q$5:$Q$44) -> 0 | P14: =SUMIF('Entradas e Saídas'!$P$5:$P$44,Controle!$C14,'Entradas e Saídas'!$R$5:$R$44) -> 0 | Q14: =O14-P14 -> 0 | R14: =Q14*Inventário!$G10 -> 0 | S14: =SUMIF('Entradas e Saídas'!$V$5:$V$44,Controle!$C14,'Entradas e Saídas'!$W$5:$W$44) -> 0 | T14: =SUMIF('Entradas e Saídas'!$V$5:$V$44,Controle!$C14,'Entradas e Saídas'!$X$5:$X$44) -> 0 | U14: =S14-T14 -> 0 | V14: =U14*Inventário!$G10 -> 0 | W14: =SUMIF('Entradas e Saídas'!$AB$5:$AB$44,Controle!$C14,'Entradas e Saídas'!$AC$5:$AC$44) -> 0 | X14: =SUMIF('Entradas e Saídas'!$AB$5:$AB$44,Controle!$C14,'Entradas e Saídas'!$AD$5:$AD$44) -> 0 | Y14: =W14-X14 -> 0 | Z14: =Y14*Inventário!$G10 -> 0 | AA14: =SUMIF('Entradas e Saídas'!$AH$5:$AH$44,Controle!$C14,'Entradas e Saídas'!$AI$5:$AI$44) -> 0 | AB14: =SUMIF('Entradas e Saídas'!$AH$5:$AH$44,Controle!$C14,'Entradas e Saídas'!$AJ$5:$AJ$44) -> 0 | AC14: =AA14-AB14 -> 0 | AD14: =AC14*Inventário!$G10 -> 0 | AE14: =SUMIF('Entradas e Saídas'!$AN$5:$AN$44,Controle!$C14,'Entradas e Saídas'!$AO$5:$AO$44) -> 0 | AF14: =SUMIF('Entradas e Saídas'!$AH$5:$AH$44,Controle!$C14,'Entradas e Saídas'!$AP$5:$AP$44) -> 0 | AG14: =AE14-AF14 -> 0 | AH14: =AG14*Inventário!$G10 -> 0 | AI14: =SUMIF('Entradas e Saídas'!$AT$5:$AT$44,Controle!$C14,'Entradas e Saídas'!$AU$5:$AU$44) -> 0 | AJ14: =SUMIF('Entradas e Saídas'!$AT$5:$AT$44,Controle!$C14,'Entradas e Saídas'!$AV$5:$AV$44) -> 0 | AK14: =AI14-AJ14 -> 0 | AL14: =AK14*Inventário!$G10 -> 0 | AM14: =SUMIF('Entradas e Saídas'!$AZ$5:$AZ$44,Controle!$C14,'Entradas e Saídas'!$BA$5:$BA$44) -> 0 | AN14: =SUMIF('Entradas e Saídas'!$AZ$5:$AZ$44,Controle!$C14,'Entradas e Saídas'!$BB$5:$BB$44) -> 0 | AO14: =AM14-AN14 -> 0 | AP14: =AO14*Inventário!$G10 -> 0 | AQ14: =SUMIF('Entradas e Saídas'!$BF$5:$BF$44,Controle!$C14,'Entradas e Saídas'!$BG$5:$BG$44) -> 0 | AR14: =SUMIF('Entradas e Saídas'!$BF$5:$BF$44,Controle!$C14,'Entradas e Saídas'!$BH$5:$BH$44) -> 0 | AS14: =AQ14-AR14 -> 0 | AT14: =AS14*Inventário!$G10 -> 0 | AU14: =SUMIF('Entradas e Saídas'!$BL$5:$BL$44,Controle!$C14,'Entradas e Saídas'!$BM$5:$BM$44) -> 0 | AV14: =SUMIF('Entradas e Saídas'!$BL$5:$BL$44,Controle!$C14,'Entradas e Saídas'!$BN$5:$BN$44) -> 0 | AW14: =AU14-AV14 -> 0 | AX14: =AW14*Inventário!$G10 -> 0 | AY14: =SUMIF('Entradas e Saídas'!$BR$5:$BR$44,Controle!$C14,'Entradas e Saídas'!$BS$5:$BS$44) -> 0 | AZ14: =SUMIF('Entradas e Saídas'!$BR$5:$BR$44,Controle!$C14,'Entradas e Saídas'!$BT$5:$BT$44) -> 0 | BA14: =AY14-AZ14 -> 0 | BB14: =BA14*Inventário!$G10 -> 0 | BE14: ABRIL | BF14: =V59 -> 0
B15: =IF(Inventário!C11="","",Inventário!C11) | C15: =IF(B15="","",VLOOKUP(B15,Inventário!$C$4:$D$53,2,FALSE)) | D15: =IF(B15="","",I15+M15+Q15+U15+Y15+AC15+AG15+AK15+AO15+AS15+AW15+BA15+Inventário!H11) | E15: =IF(B15="","",IF(D15<0,"-",(D15*Inventário!G11))) | F15: =IF(B15="","",IF(D15>Inventário!I11,"NÃO",CONCATENATE("SIM:"," ",Inventário!J11," ","unid"))) | G15: =SUMIF('Entradas e Saídas'!$D$5:$D$44,Controle!$C15,'Entradas e Saídas'!$E$5:$E$44) -> 0 | H15: =SUMIF('Entradas e Saídas'!$D$5:$D$44,Controle!$C15,'Entradas e Saídas'!$F$5:$F$44) -> 0 | I15: =G15-H15 -> 0 | J15: =I15*Inventário!G11 -> 0 | K15: =SUMIF('Entradas e Saídas'!$J$5:$J$44,Controle!$C15,'Entradas e Saídas'!$K$5:$K$44) -> 0 | L15: =SUMIF('Entradas e Saídas'!$J$5:$J$44,Controle!$C15,'Entradas e Saídas'!$L$5:$L$44) -> 0 | M15: =K15-L15 -> 0 | N15: =M15*Inventário!$G11 -> 0 | O15: =SUMIF('Entradas e Saídas'!$P$5:$P$44,Controle!$C15,'Entradas e Saídas'!$Q$5:$Q$44) -> 0 | P15: =SUMIF('Entradas e Saídas'!$P$5:$P$44,Controle!$C15,'Entradas e Saídas'!$R$5:$R$44) -> 0 | Q15: =O15-P15 -> 0 | R15: =Q15*Inventário!$G11 -> 0 | S15: =SUMIF('Entradas e Saídas'!$V$5:$V$44,Controle!$C15,'Entradas e Saídas'!$W$5:$W$44) -> 0 | T15: =SUMIF('Entradas e Saídas'!$V$5:$V$44,Controle!$C15,'Entradas e Saídas'!$X$5:$X$44) -> 0 | U15: =S15-T15 -> 0 | V15: =U15*Inventário!$G11 -> 0 | W15: =SUMIF('Entradas e Saídas'!$AB$5:$AB$44,Controle!$C15,'Entradas e Saídas'!$AC$5:$AC$44) -> 0 | X15: =SUMIF('Entradas e Saídas'!$AB$5:$AB$44,Controle!$C15,'Entradas e Saídas'!$AD$5:$AD$44) -> 0 | Y15: =W15-X15 -> 0 | Z15: =Y15*Inventário!$G11 -> 0 | AA15: =SUMIF('Entradas e Saídas'!$AH$5:$AH$44,Controle!$C15,'Entradas e Saídas'!$AI$5:$AI$44) -> 0 | AB15: =SUMIF('Entradas e Saídas'!$AH$5:$AH$44,Controle!$C15,'Entradas e Saídas'!$AJ$5:$AJ$44) -> 0 | AC15: =AA15-AB15 -> 0 | AD15: =AC15*Inventário!$G11 -> 0 | AE15: =SUMIF('Entradas e Saídas'!$AN$5:$AN$44,Controle!$C15,'Entradas e Saídas'!$AO$5:$AO$44) -> 0 | AF15: =SUMIF('Entradas e Saídas'!$AH$5:$AH$44,Controle!$C15,'Entradas e Saídas'!$AP$5:$AP$44) -> 0 | AG15: =AE15-AF15 -> 0 | AH15: =AG15*Inventário!$G11 -> 0 | AI15: =SUMIF('Entradas e Saídas'!$AT$5:$AT$44,Controle!$C15,'Entradas e Saídas'!$AU$5:$AU$44) -> 0 | AJ15: =SUMIF('Entradas e Saídas'!$AT$5:$AT$44,Controle!$C15,'Entradas e Saídas'!$AV$5:$AV$44) -> 0 | AK15: =AI15-AJ15 -> 0 | AL15: =AK15*Inventário!$G11 -> 0 | AM15: =SUMIF('Entradas e Saídas'!$AZ$5:$AZ$44,Controle!$C15,'Entradas e Saídas'!$BA$5:$BA$44) -> 0 | AN15: =SUMIF('Entradas e Saídas'!$AZ$5:$AZ$44,Controle!$C15,'Entradas e Saídas'!$BB$5:$BB$44) -> 0 | AO15: =AM15-AN15 -> 0 | AP15: =AO15*Inventário!$G11 -> 0 | AQ15: =SUMIF('Entradas e Saídas'!$BF$5:$BF$44,Controle!$C15,'Entradas e Saídas'!$BG$5:$BG$44) -> 0 | AR15: =SUMIF('Entradas e Saídas'!$BF$5:$BF$44,Controle!$C15,'Entradas e Saídas'!$BH$5:$BH$44) -> 0 | AS15: =AQ15-AR15 -> 0 | AT15: =AS15*Inventário!$G11 -> 0 | AU15: =SUMIF('Entradas e Saídas'!$BL$5:$BL$44,Controle!$C15,'Entradas e Saídas'!$BM$5:$BM$44) -> 0 | AV15: =SUMIF('Entradas e Saídas'!$BL$5:$BL$44,Controle!$C15,'Entradas e Saídas'!$BN$5:$BN$44) -> 0 | AW15: =AU15-AV15 -> 0 | AX15: =AW15*Inventário!$G11 -> 0 | AY15: =SUMIF('Entradas e Saídas'!$BR$5:$BR$44,Controle!$C15,'Entradas e Saídas'!$BS$5:$BS$44) -> 0 | AZ15: =SUMIF('Entradas e Saídas'!$BR$5:$BR$44,Controle!$C15,'Entradas e Saídas'!$BT$5:$BT$44) -> 0 | BA15: =AY15-AZ15 -> 0 | BB15: =BA15*Inventário!$G11 -> 0 | BE15: MAIO | BF15: =Z59 -> 0
B16: =IF(Inventário!C12="","",Inventário!C12) | C16: =IF(B16="","",VLOOKUP(B16,Inventário!$C$4:$D$53,2,FALSE)) | D16: =IF(B16="","",I16+M16+Q16+U16+Y16+AC16+AG16+AK16+AO16+AS16+AW16+BA16+Inventário!H12) | E16: =IF(B16="","",IF(D16<0,"-",(D16*Inventário!G12))) | F16: =IF(B16="","",IF(D16>Inventário!I12,"NÃO",CONCATENATE("SIM:"," ",Inventário!J12," ","unid"))) | G16: =SUMIF('Entradas e Saídas'!$D$5:$D$44,Controle!$C16,'Entradas e Saídas'!$E$5:$E$44) -> 0 | H16: =SUMIF('Entradas e Saídas'!$D$5:$D$44,Controle!$C16,'Entradas e Saídas'!$F$5:$F$44) -> 0 | I16: =G16-H16 -> 0 | J16: =I16*Inventário!G12 -> 0 | K16: =SUMIF('Entradas e Saídas'!$J$5:$J$44,Controle!$C16,'Entradas e Saídas'!$K$5:$K$44) -> 0 | L16: =SUMIF('Entradas e Saídas'!$J$5:$J$44,Controle!$C16,'Entradas e Saídas'!$L$5:$L$44) -> 0 | M16: =K16-L16 -> 0 | N16: =M16*Inventário!$G12 -> 0 | O16: =SUMIF('Entradas e Saídas'!$P$5:$P$44,Controle!$C16,'Entradas e Saídas'!$Q$5:$Q$44) -> 0 | P16: =SUMIF('Entradas e Saídas'!$P$5:$P$44,Controle!$C16,'Entradas e Saídas'!$R$5:$R$44) -> 0 | Q16: =O16-P16 -> 0 | R16: =Q16*Inventário!$G12 -> 0 | S16: =SUMIF('Entradas e Saídas'!$V$5:$V$44,Controle!$C16,'Entradas e Saídas'!$W$5:$W$44) -> 0 | T16: =SUMIF('Entradas e Saídas'!$V$5:$V$44,Controle!$C16,'Entradas e Saídas'!$X$5:$X$44) -> 0 | U16: =S16-T16 -> 0 | V16: =U16*Inventário!$G12 -> 0 | W16: =SUMIF('Entradas e Saídas'!$AB$5:$AB$44,Controle!$C16,'Entradas e Saídas'!$AC$5:$AC$44) -> 0 | X16: =SUMIF('Entradas e Saídas'!$AB$5:$AB$44,Controle!$C16,'Entradas e Saídas'!$AD$5:$AD$44) -> 0 | Y16: =W16-X16 -> 0 | Z16: =Y16*Inventário!$G12 -> 0 | AA16: =SUMIF('Entradas e Saídas'!$AH$5:$AH$44,Controle!$C16,'Entradas e Saídas'!$AI$5:$AI$44) -> 0 | AB16: =SUMIF('Entradas e Saídas'!$AH$5:$AH$44,Controle!$C16,'Entradas e Saídas'!$AJ$5:$AJ$44) -> 0 | AC16: =AA16-AB16 -> 0 | AD16: =AC16*Inventário!$G12 -> 0 | AE16: =SUMIF('Entradas e Saídas'!$AN$5:$AN$44,Controle!$C16,'Entradas e Saídas'!$AO$5:$AO$44) -> 0 | AF16: =SUMIF('Entradas e Saídas'!$AH$5:$AH$44,Controle!$C16,'Entradas e Saídas'!$AP$5:$AP$44) -> 0 | AG16: =AE16-AF16 -> 0 | AH16: =AG16*Inventário!$G12 -> 0 | AI16: =SUMIF('Entradas e Saídas'!$AT$5:$AT$44,Controle!$C16,'Entradas e Saídas'!$AU$5:$AU$44) -> 0 | AJ16: =SUMIF('Entradas e Saídas'!$AT$5:$AT$44,Controle!$C16,'Entradas e Saídas'!$AV$5:$AV$44) -> 0 | AK16: =AI16-AJ16 -> 0 | AL16: =AK16*Inventário!$G12 -> 0 | AM16: =SUMIF('Entradas e Saídas'!$AZ$5:$AZ$44,Controle!$C16,'Entradas e Saídas'!$BA$5:$BA$44) -> 0 | AN16: =SUMIF('Entradas e Saídas'!$AZ$5:$AZ$44,Controle!$C16,'Entradas e Saídas'!$BB$5:$BB$44) -> 0 | AO16: =AM16-AN16 -> 0 | AP16: =AO16*Inventário!$G12 -> 0 | AQ16: =SUMIF('Entradas e Saídas'!$BF$5:$BF$44,Controle!$C16,'Entradas e Saídas'!$BG$5:$BG$44) -> 0 | AR16: =SUMIF('Entradas e Saídas'!$BF$5:$BF$44,Controle!$C16,'Entradas e Saídas'!$BH$5:$BH$44) -> 0 | AS16: =AQ16-AR16 -> 0 | AT16: =AS16*Inventário!$G12 -> 0 | AU16: =SUMIF('Entradas e Saídas'!$BL$5:$BL$44,Controle!$C16,'Entradas e Saídas'!$BM$5:$BM$44) -> 0 | AV16: =SUMIF('Entradas e Saídas'!$BL$5:$BL$44,Controle!$C16,'Entradas e Saídas'!$BN$5:$BN$44) -> 0 | AW16: =AU16-AV16 -> 0 | AX16: =AW16*Inventário!$G12 -> 0 | AY16: =SUMIF('Entradas e Saídas'!$BR$5:$BR$44,Controle!$C16,'Entradas e Saídas'!$BS$5:$BS$44) -> 0 | AZ16: =SUMIF('Entradas e Saídas'!$BR$5:$BR$44,Controle!$C16,'Entradas e Saídas'!$BT$5:$BT$44) -> 0 | BA16: =AY16-AZ16 -> 0 | BB16: =BA16*Inventário!$G12 -> 0 | BE16: JUNHO | BF16: =AD59 -> 0
B17: =IF(Inventário!C13="","",Inventário!C13) | C17: =IF(B17="","",VLOOKUP(B17,Inventário!$C$4:$D$53,2,FALSE)) | D17: =IF(B17="","",I17+M17+Q17+U17+Y17+AC17+AG17+AK17+AO17+AS17+AW17+BA17+Inventário!H13) | E17: =IF(B17="","",IF(D17<0,"-",(D17*Inventário!G13))) | F17: =IF(B17="","",IF(D17>Inventário!I13,"NÃO",CONCATENATE("SIM:"," ",Inventário!J13," ","unid"))) | G17: =SUMIF('Entradas e Saídas'!$D$5:$D$44,Controle!$C17,'Entradas e Saídas'!$E$5:$E$44) -> 0 | H17: =SUMIF('Entradas e Saídas'!$D$5:$D$44,Controle!$C17,'Entradas e Saídas'!$F$5:$F$44) -> 0 | I17: =G17-H17 -> 0 | J17: =I17*Inventário!G13 -> 0 | K17: =SUMIF('Entradas e Saídas'!$J$5:$J$44,Controle!$C17,'Entradas e Saídas'!$K$5:$K$44) -> 0 | L17: =SUMIF('Entradas e Saídas'!$J$5:$J$44,Controle!$C17,'Entradas e Saídas'!$L$5:$L$44) -> 0 | M17: =K17-L17 -> 0 | N17: =M17*Inventário!$G13 -> 0 | O17: =SUMIF('Entradas e Saídas'!$P$5:$P$44,Controle!$C17,'Entradas e Saídas'!$Q$5:$Q$44) -> 0 | P17: =SUMIF('Entradas e Saídas'!$P$5:$P$44,Controle!$C17,'Entradas e Saídas'!$R$5:$R$44) -> 0 | Q17: =O17-P17 -> 0 | R17: =Q17*Inventário!$G13 -> 0 | S17: =SUMIF('Entradas e Saídas'!$V$5:$V$44,Controle!$C17,'Entradas e Saídas'!$W$5:$W$44) -> 0 | T17: =SUMIF('Entradas e Saídas'!$V$5:$V$44,Controle!$C17,'Entradas e Saídas'!$X$5:$X$44) -> 0 | U17: =S17-T17 -> 0 | V17: =U17*Inventário!$G13 -> 0 | W17: =SUMIF('Entradas e Saídas'!$AB$5:$AB$44,Controle!$C17,'Entradas e Saídas'!$AC$5:$AC$44) -> 0 | X17: =SUMIF('Entradas e Saídas'!$AB$5:$AB$44,Controle!$C17,'Entradas e Saídas'!$AD$5:$AD$44) -> 0 | Y17: =W17-X17 -> 0 | Z17: =Y17*Inventário!$G13 -> 0 | AA17: =SUMIF('Entradas e Saídas'!$AH$5:$AH$44,Controle!$C17,'Entradas e Saídas'!$AI$5:$AI$44) -> 0 | AB17: =SUMIF('Entradas e Saídas'!$AH$5:$AH$44,Controle!$C17,'Entradas e Saídas'!$AJ$5:$AJ$44) -> 0 | AC17: =AA17-AB17 -> 0 | AD17: =AC17*Inventário!$G13 -> 0 | AE17: =SUMIF('Entradas e Saídas'!$AN$5:$AN$44,Controle!$C17,'Entradas e Saídas'!$AO$5:$AO$44) -> 0 | AF17: =SUMIF('Entradas e Saídas'!$AH$5:$AH$44,Controle!$C17,'Entradas e Saídas'!$AP$5:$AP$44) -> 0 | AG17: =AE17-AF17 -> 0 | AH17: =AG17*Inventário!$G13 -> 0 | AI17: =SUMIF('Entradas e Saídas'!$AT$5:$AT$44,Controle!$C17,'Entradas e Saídas'!$AU$5:$AU$44) -> 0 | AJ17: =SUMIF('Entradas e Saídas'!$AT$5:$AT$44,Controle!$C17,'Entradas e Saídas'!$AV$5:$AV$44) -> 0 | AK17: =AI17-AJ17 -> 0 | AL17: =AK17*Inventário!$G13 -> 0 | AM17: =SUMIF('Entradas e Saídas'!$AZ$5:$AZ$44,Controle!$C17,'Entradas e Saídas'!$BA$5:$BA$44) -> 0 | AN17: =SUMIF('Entradas e Saídas'!$AZ$5:$AZ$44,Controle!$C17,'Entradas e Saídas'!$BB$5:$BB$44) -> 0 | AO17: =AM17-AN17 -> 0 | AP17: =AO17*Inventário!$G13 -> 0 | AQ17: =SUMIF('Entradas e Saídas'!$BF$5:$BF$44,Controle!$C17,'Entradas e Saídas'!$BG$5:$BG$44) -> 0 | AR17: =SUMIF('Entradas e Saídas'!$BF$5:$BF$44,Controle!$C17,'Entradas e Saídas'!$BH$5:$BH$44) -> 0 | AS17: =AQ17-AR17 -> 0 | AT17: =AS17*Inventário!$G13 -> 0 | AU17: =SUMIF('Entradas e Saídas'!$BL$5:$BL$44,Controle!$C17,'Entradas e Saídas'!$BM$5:$BM$44) -> 0 | AV17: =SUMIF('Entradas e Saídas'!$BL$5:$BL$44,Controle!$C17,'Entradas e Saídas'!$BN$5:$BN$44) -> 0 | AW17: =AU17-AV17 -> 0 | AX17: =AW17*Inventário!$G13 -> 0 | AY17: =SUMIF('Entradas e Saídas'!$BR$5:$BR$44,Controle!$C17,'Entradas e Saídas'!$BS$5:$BS$44) -> 0 | AZ17: =SUMIF('Entradas e Saídas'!$BR$5:$BR$44,Controle!$C17,'Entradas e Saídas'!$BT$5:$BT$44) -> 0 | BA17: =AY17-AZ17 -> 0 | BB17: =BA17*Inventário!$G13 -> 0 | BE17: JULHO | BF17: =AH59 -> 0
B18: =IF(Inventário!C14="","",Inventário!C14) | C18: =IF(B18="","",VLOOKUP(B18,Inventário!$C$4:$D$53,2,FALSE)) | D18: =IF(B18="","",I18+M18+Q18+U18+Y18+AC18+AG18+AK18+AO18+AS18+AW18+BA18+Inventário!H14) | E18: =IF(B18="","",IF(D18<0,"-",(D18*Inventário!G14))) | F18: =IF(B18="","",IF(D18>Inventário!I14,"NÃO",CONCATENATE("SIM:"," ",Inventário!J14," ","unid"))) | G18: =SUMIF('Entradas e Saídas'!$D$5:$D$44,Controle!$C18,'Entradas e Saídas'!$E$5:$E$44) -> 0 | H18: =SUMIF('Entradas e Saídas'!$D$5:$D$44,Controle!$C18,'Entradas e Saídas'!$F$5:$F$44) -> 0 | I18: =G18-H18 -> 0 | J18: =I18*Inventário!G14 -> 0 | K18: =SUMIF('Entradas e Saídas'!$J$5:$J$44,Controle!$C18,'Entradas e Saídas'!$K$5:$K$44) -> 0 | L18: =SUMIF('Entradas e Saídas'!$J$5:$J$44,Controle!$C18,'Entradas e Saídas'!$L$5:$L$44) -> 0 | M18: =K18-L18 -> 0 | N18: =M18*Inventário!$G14 -> 0 | O18: =SUMIF('Entradas e Saídas'!$P$5:$P$44,Controle!$C18,'Entradas e Saídas'!$Q$5:$Q$44) -> 0 | P18: =SUMIF('Entradas e Saídas'!$P$5:$P$44,Controle!$C18,'Entradas e Saídas'!$R$5:$R$44) -> 0 | Q18: =O18-P18 -> 0 | R18: =Q18*Inventário!$G14 -> 0 | S18: =SUMIF('Entradas e Saídas'!$V$5:$V$44,Controle!$C18,'Entradas e Saídas'!$W$5:$W$44) -> 0 | T18: =SUMIF('Entradas e Saídas'!$V$5:$V$44,Controle!$C18,'Entradas e Saídas'!$X$5:$X$44) -> 0 | U18: =S18-T18 -> 0 | V18: =U18*Inventário!$G14 -> 0 | W18: =SUMIF('Entradas e Saídas'!$AB$5:$AB$44,Controle!$C18,'Entradas e Saídas'!$AC$5:$AC$44) -> 0 | X18: =SUMIF('Entradas e Saídas'!$AB$5:$AB$44,Controle!$C18,'Entradas e Saídas'!$AD$5:$AD$44) -> 0 | Y18: =W18-X18 -> 0 | Z18: =Y18*Inventário!$G14 -> 0 | AA18: =SUMIF('Entradas e Saídas'!$AH$5:$AH$44,Controle!$C18,'Entradas e Saídas'!$AI$5:$AI$44) -> 0 | AB18: =SUMIF('Entradas e Saídas'!$AH$5:$AH$44,Controle!$C18,'Entradas e Saídas'!$AJ$5:$AJ$44) -> 0 | AC18: =AA18-AB18 -> 0 | AD18: =AC18*Inventário!$G14 -> 0 | AE18: =SUMIF('Entradas e Saídas'!$AN$5:$AN$44,Controle!$C18,'Entradas e Saídas'!$AO$5:$AO$44) -> 0 | AF18: =SUMIF('Entradas e Saídas'!$AH$5:$AH$44,Controle!$C18,'Entradas e Saídas'!$AP$5:$AP$44) -> 0 | AG18: =AE18-AF18 -> 0 | AH18: =AG18*Inventário!$G14 -> 0 | AI18: =SUMIF('Entradas e Saídas'!$AT$5:$AT$44,Controle!$C18,'Entradas e Saídas'!$AU$5:$AU$44) -> 0 | AJ18: =SUMIF('Entradas e Saídas'!$AT$5:$AT$44,Controle!$C18,'Entradas e Saídas'!$AV$5:$AV$44) -> 0 | AK18: =AI18-AJ18 -> 0 | AL18: =AK18*Inventário!$G14 -> 0 | AM18: =SUMIF('Entradas e Saídas'!$AZ$5:$AZ$44,Controle!$C18,'Entradas e Saídas'!$BA$5:$BA$44) -> 0 | AN18: =SUMIF('Entradas e Saídas'!$AZ$5:$AZ$44,Controle!$C18,'Entradas e Saídas'!$BB$5:$BB$44) -> 0 | AO18: =AM18-AN18 -> 0 | AP18: =AO18*Inventário!$G14 -> 0 | AQ18: =SUMIF('Entradas e Saídas'!$BF$5:$BF$44,Controle!$C18,'Entradas e Saídas'!$BG$5:$BG$44) -> 0 | AR18: =SUMIF('Entradas e Saídas'!$BF$5:$BF$44,Controle!$C18,'Entradas e Saídas'!$BH$5:$BH$44) -> 0 | AS18: =AQ18-AR18 -> 0 | AT18: =AS18*Inventário!$G14 -> 0 | AU18: =SUMIF('Entradas e Saídas'!$BL$5:$BL$44,Controle!$C18,'Entradas e Saídas'!$BM$5:$BM$44) -> 0 | AV18: =SUMIF('Entradas e Saídas'!$BL$5:$BL$44,Controle!$C18,'Entradas e Saídas'!$BN$5:$BN$44) -> 0 | AW18: =AU18-AV18 -> 0 | AX18: =AW18*Inventário!$G14 -> 0 | AY18: =SUMIF('Entradas e Saídas'!$BR$5:$BR$44,Controle!$C18,'Entradas e Saídas'!$BS$5:$BS$44) -> 0 | AZ18: =SUMIF('Entradas e Saídas'!$BR$5:$BR$44,Controle!$C18,'Entradas e Saídas'!$BT$5:$BT$44) -> 0 | BA18: =AY18-AZ18 -> 0 | BB18: =BA18*Inventário!$G14 -> 0 | BE18: AGOSTO | BF18: =AL59 -> 0
B19: =IF(Inventário!C15="","",Inventário!C15) | C19: =IF(B19="","",VLOOKUP(B19,Inventário!$C$4:$D$53,2,FALSE)) | D19: =IF(B19="","",I19+M19+Q19+U19+Y19+AC19+AG19+AK19+AO19+AS19+AW19+BA19+Inventário!H15) | E19: =IF(B19="","",IF(D19<0,"-",(D19*Inventário!G15))) | F19: =IF(B19="","",IF(D19>Inventário!I15,"NÃO",CONCATENATE("SIM:"," ",Inventário!J15," ","unid"))) | G19: =SUMIF('Entradas e Saídas'!$D$5:$D$44,Controle!$C19,'Entradas e Saídas'!$E$5:$E$44) -> 0 | H19: =SUMIF('Entradas e Saídas'!$D$5:$D$44,Controle!$C19,'Entradas e Saídas'!$F$5:$F$44) -> 0 | I19: =G19-H19 -> 0 | J19: =I19*Inventário!G15 -> 0 | K19: =SUMIF('Entradas e Saídas'!$J$5:$J$44,Controle!$C19,'Entradas e Saídas'!$K$5:$K$44) -> 0 | L19: =SUMIF('Entradas e Saídas'!$J$5:$J$44,Controle!$C19,'Entradas e Saídas'!$L$5:$L$44) -> 0 | M19: =K19-L19 -> 0 | N19: =M19*Inventário!$G15 -> 0 | O19: =SUMIF('Entradas e Saídas'!$P$5:$P$44,Controle!$C19,'Entradas e Saídas'!$Q$5:$Q$44) -> 0 | P19: =SUMIF('Entradas e Saídas'!$P$5:$P$44,Controle!$C19,'Entradas e Saídas'!$R$5:$R$44) -> 0 | Q19: =O19-P19 -> 0 | R19: =Q19*Inventário!$G15 -> 0 | S19: =SUMIF('Entradas e Saídas'!$V$5:$V$44,Controle!$C19,'Entradas e Saídas'!$W$5:$W$44) -> 0 | T19: =SUMIF('Entradas e Saídas'!$V$5:$V$44,Controle!$C19,'Entradas e Saídas'!$X$5:$X$44) -> 0 | U19: =S19-T19 -> 0 | V19: =U19*Inventário!$G15 -> 0 | W19: =SUMIF('Entradas e Saídas'!$AB$5:$AB$44,Controle!$C19,'Entradas e Saídas'!$AC$5:$AC$44) -> 0 | X19: =SUMIF('Entradas e Saídas'!$AB$5:$AB$44,Controle!$C19,'Entradas e Saídas'!$AD$5:$AD$44) -> 0 | Y19: =W19-X19 -> 0 | Z19: =Y19*Inventário!$G15 -> 0 | AA19: =SUMIF('Entradas e Saídas'!$AH$5:$AH$44,Controle!$C19,'Entradas e Saídas'!$AI$5:$AI$44) -> 0 | AB19: =SUMIF('Entradas e Saídas'!$AH$5:$AH$44,Controle!$C19,'Entradas e Saídas'!$AJ$5:$AJ$44) -> 0 | AC19: =AA19-AB19 -> 0 | AD19: =AC19*Inventário!$G15 -> 0 | AE19: =SUMIF('Entradas e Saídas'!$AN$5:$AN$44,Controle!$C19,'Entradas e Saídas'!$AO$5:$AO$44) -> 0 | AF19: =SUMIF('Entradas e Saídas'!$AH$5:$AH$44,Controle!$C19,'Entradas e Saídas'!$AP$5:$AP$44) -> 0 | AG19: =AE19-AF19 -> 0 | AH19: =AG19*Inventário!$G15 -> 0 | AI19: =SUMIF('Entradas e Saídas'!$AT$5:$AT$44,Controle!$C19,'Entradas e Saídas'!$AU$5:$AU$44) -> 0 | AJ19: =SUMIF('Entradas e Saídas'!$AT$5:$AT$44,Controle!$C19,'Entradas e Saídas'!$AV$5:$AV$44) -> 0 | AK19: =AI19-AJ19 -> 0 | AL19: =AK19*Inventário!$G15 -> 0 | AM19: =SUMIF('Entradas e Saídas'!$AZ$5:$AZ$44,Controle!$C19,'Entradas e Saídas'!$BA$5:$BA$44) -> 0 | AN19: =SUMIF('Entradas e Saídas'!$AZ$5:$AZ$44,Controle!$C19,'Entradas e Saídas'!$BB$5:$BB$44) -> 0 | AO19: =AM19-AN19 -> 0 | AP19: =AO19*Inventário!$G15 -> 0 | AQ19: =SUMIF('Entradas e Saídas'!$BF$5:$BF$44,Controle!$C19,'Entradas e Saídas'!$BG$5:$BG$44) -> 0 | AR19: =SUMIF('Entradas e Saídas'!$BF$5:$BF$44,Controle!$C19,'Entradas e Saídas'!$BH$5:$BH$44) -> 0 | AS19: =AQ19-AR19 -> 0 | AT19: =AS19*Inventário!$G15 -> 0 | AU19: =SUMIF('Entradas e Saídas'!$BL$5:$BL$44,Controle!$C19,'Entradas e Saídas'!$BM$5:$BM$44) -> 0 | AV19: =SUMIF('Entradas e Saídas'!$BL$5:$BL$44,Controle!$C19,'Entradas e Saídas'!$BN$5:$BN$44) -> 0 | AW19: =AU19-AV19 -> 0 | AX19: =AW19*Inventário!$G15 -> 0 | AY19: =SUMIF('Entradas e Saídas'!$BR$5:$BR$44,Controle!$C19,'Entradas e Saídas'!$BS$5:$BS$44) -> 0 | AZ19: =SUMIF('Entradas e Saídas'!$BR$5:$BR$44,Controle!$C19,'Entradas e Saídas'!$BT$5:$BT$44) -> 0 | BA19: =AY19-AZ19 -> 0 | BB19: =BA19*Inventário!$G15 -> 0 | BE19: SETEMBRO | BF19: =AP59 -> 0
B20: =IF(Inventário!C16="","",Inventário!C16) | C20: =IF(B20="","",VLOOKUP(B20,Inventário!$C$4:$D$53,2,FALSE)) | D20: =IF(B20="","",I20+M20+Q20+U20+Y20+AC20+AG20+AK20+AO20+AS20+AW20+BA20+Inventário!H16) | E20: =IF(B20="","",IF(D20<0,"-",(D20*Inventário!G16))) | F20: =IF(B20="","",IF(D20>Inventário!I16,"NÃO",CONCATENATE("SIM:"," ",Inventário!J16," ","unid"))) | G20: =SUMIF('Entradas e Saídas'!$D$5:$D$44,Controle!$C20,'Entradas e Saídas'!$E$5:$E$44) -> 0 | H20: =SUMIF('Entradas e Saídas'!$D$5:$D$44,Controle!$C20,'Entradas e Saídas'!$F$5:$F$44) -> 0 | I20: =G20-H20 -> 0 | J20: =I20*Inventário!G16 -> 0 | K20: =SUMIF('Entradas e Saídas'!$J$5:$J$44,Controle!$C20,'Entradas e Saídas'!$K$5:$K$44) -> 0 | L20: =SUMIF('Entradas e Saídas'!$J$5:$J$44,Controle!$C20,'Entradas e Saídas'!$L$5:$L$44) -> 0 | M20: =K20-L20 -> 0 | N20: =M20*Inventário!$G16 -> 0 | O20: =SUMIF('Entradas e Saídas'!$P$5:$P$44,Controle!$C20,'Entradas e Saídas'!$Q$5:$Q$44) -> 0 | P20: =SUMIF('Entradas e Saídas'!$P$5:$P$44,Controle!$C20,'Entradas e Saídas'!$R$5:$R$44) -> 0 | Q20: =O20-P20 -> 0 | R20: =Q20*Inventário!$G16 -> 0 | S20: =SUMIF('Entradas e Saídas'!$V$5:$V$44,Controle!$C20,'Entradas e Saídas'!$W$5:$W$44) -> 0 | T20: =SUMIF('Entradas e Saídas'!$V$5:$V$44,Controle!$C20,'Entradas e Saídas'!$X$5:$X$44) -> 0 | U20: =S20-T20 -> 0 | V20: =U20*Inventário!$G16 -> 0 | W20: =SUMIF('Entradas e Saídas'!$AB$5:$AB$44,Controle!$C20,'Entradas e Saídas'!$AC$5:$AC$44) -> 0 | X20: =SUMIF('Entradas e Saídas'!$AB$5:$AB$44,Controle!$C20,'Entradas e Saídas'!$AD$5:$AD$44) -> 0 | Y20: =W20-X20 -> 0 | Z20: =Y20*Inventário!$G16 -> 0 | AA20: =SUMIF('Entradas e Saídas'!$AH$5:$AH$44,Controle!$C20,'Entradas e Saídas'!$AI$5:$AI$44) -> 0 | AB20: =SUMIF('Entradas e Saídas'!$AH$5:$AH$44,Controle!$C20,'Entradas e Saídas'!$AJ$5:$AJ$44) -> 0 | AC20: =AA20-AB20 -> 0 | AD20: =AC20*Inventário!$G16 -> 0 | AE20: =SUMIF('Entradas e Saídas'!$AN$5:$AN$44,Controle!$C20,'Entradas e Saídas'!$AO$5:$AO$44) -> 0 | AF20: =SUMIF('Entradas e Saídas'!$AH$5:$AH$44,Controle!$C20,'Entradas e Saídas'!$AP$5:$AP$44) -> 0 | AG20: =AE20-AF20 -> 0 | AH20: =AG20*Inventário!$G16 -> 0 | AI20: =SUMIF('Entradas e Saídas'!$AT$5:$AT$44,Controle!$C20,'Entradas e Saídas'!$AU$5:$AU$44) -> 0 | AJ20: =SUMIF('Entradas e Saídas'!$AT$5:$AT$44,Controle!$C20,'Entradas e Saídas'!$AV$5:$AV$44) -> 0 | AK20: =AI20-AJ20 -> 0 | AL20: =AK20*Inventário!$G16 -> 0 | AM20: =SUMIF('Entradas e Saídas'!$AZ$5:$AZ$44,Controle!$C20,'Entradas e Saídas'!$BA$5:$BA$44) -> 0 | AN20: =SUMIF('Entradas e Saídas'!$AZ$5:$AZ$44,Controle!$C20,'Entradas e Saídas'!$BB$5:$BB$44) -> 0 | AO20: =AM20-AN20 -> 0 | AP20: =AO20*Inventário!$G16 -> 0 | AQ20: =SUMIF('Entradas e Saídas'!$BF$5:$BF$44,Controle!$C20,'Entradas e Saídas'!$BG$5:$BG$44) -> 0 | AR20: =SUMIF('Entradas e Saídas'!$BF$5:$BF$44,Controle!$C20,'Entradas e Saídas'!$BH$5:$BH$44) -> 0 | AS20: =AQ20-AR20 -> 0 | AT20: =AS20*Inventário!$G16 -> 0 | AU20: =SUMIF('Entradas e Saídas'!$BL$5:$BL$44,Controle!$C20,'Entradas e Saídas'!$BM$5:$BM$44) -> 0 | AV20: =SUMIF('Entradas e Saídas'!$BL$5:$BL$44,Controle!$C20,'Entradas e Saídas'!$BN$5:$BN$44) -> 0 | AW20: =AU20-AV20 -> 0 | AX20: =AW20*Inventário!$G16 -> 0 | AY20: =SUMIF('Entradas e Saídas'!$BR$5:$BR$44,Controle!$C20,'Entradas e Saídas'!$BS$5:$BS$44) -> 0 | AZ20: =SUMIF('Entradas e Saídas'!$BR$5:$BR$44,Controle!$C20,'Entradas e Saídas'!$BT$5:$BT$44) -> 0 | BA20: =AY20-AZ20 -> 0 | BB20: =BA20*Inventário!$G16 -> 0 | BE20: OUTUBRO | BF20: =AT59 -> 0
B21: =IF(Inventário!C17="","",Inventário!C17) | C21: =IF(B21="","",VLOOKUP(B21,Inventário!$C$4:$D$53,2,FALSE)) | D21: =IF(B21="","",I21+M21+Q21+U21+Y21+AC21+AG21+AK21+AO21+AS21+AW21+BA21+Inventário!H17) | E21: =IF(B21="","",IF(D21<0,"-",(D21*Inventário!G17))) | F21: =IF(B21="","",IF(D21>Inventário!I17,"NÃO",CONCATENATE("SIM:"," ",Inventário!J17," ","unid"))) | G21: =SUMIF('Entradas e Saídas'!$D$5:$D$44,Controle!$C21,'Entradas e Saídas'!$E$5:$E$44) -> 0 | H21: =SUMIF('Entradas e Saídas'!$D$5:$D$44,Controle!$C21,'Entradas e Saídas'!$F$5:$F$44) -> 0 | I21: =G21-H21 -> 0 | J21: =I21*Inventário!G17 -> 0 | K21: =SUMIF('Entradas e Saídas'!$J$5:$J$44,Controle!$C21,'Entradas e Saídas'!$K$5:$K$44) -> 0 | L21: =SUMIF('Entradas e Saídas'!$J$5:$J$44,Controle!$C21,'Entradas e Saídas'!$L$5:$L$44) -> 0 | M21: =K21-L21 -> 0 | N21: =M21*Inventário!$G17 -> 0 | O21: =SUMIF('Entradas e Saídas'!$P$5:$P$44,Controle!$C21,'Entradas e Saídas'!$Q$5:$Q$44) -> 0 | P21: =SUMIF('Entradas e Saídas'!$P$5:$P$44,Controle!$C21,'Entradas e Saídas'!$R$5:$R$44) -> 0 | Q21: =O21-P21 -> 0 | R21: =Q21*Inventário!$G17 -> 0 | S21: =SUMIF('Entradas e Saídas'!$V$5:$V$44,Controle!$C21,'Entradas e Saídas'!$W$5:$W$44) -> 0 | T21: =SUMIF('Entradas e Saídas'!$V$5:$V$44,Controle!$C21,'Entradas e Saídas'!$X$5:$X$44) -> 0 | U21: =S21-T21 -> 0 | V21: =U21*Inventário!$G17 -> 0 | W21: =SUMIF('Entradas e Saídas'!$AB$5:$AB$44,Controle!$C21,'Entradas e Saídas'!$AC$5:$AC$44) -> 0 | X21: =SUMIF('Entradas e Saídas'!$AB$5:$AB$44,Controle!$C21,'Entradas e Saídas'!$AD$5:$AD$44) -> 0 | Y21: =W21-X21 -> 0 | Z21: =Y21*Inventário!$G17 -> 0 | AA21: =SUMIF('Entradas e Saídas'!$AH$5:$AH$44,Controle!$C21,'Entradas e Saídas'!$AI$5:$AI$44) -> 0 | AB21: =SUMIF('Entradas e Saídas'!$AH$5:$AH$44,Controle!$C21,'Entradas e Saídas'!$AJ$5:$AJ$44) -> 0 | AC21: =AA21-AB21 -> 0 | AD21: =AC21*Inventário!$G17 -> 0 | AE21: =SUMIF('Entradas e Saídas'!$AN$5:$AN$44,Controle!$C21,'Entradas e Saídas'!$AO$5:$AO$44) -> 0 | AF21: =SUMIF('Entradas e Saídas'!$AH$5:$AH$44,Controle!$C21,'Entradas e Saídas'!$AP$5:$AP$44) -> 0 | AG21: =AE21-AF21 -> 0 | AH21: =AG21*Inventário!$G17 -> 0 | AI21: =SUMIF('Entradas e Saídas'!$AT$5:$AT$44,Controle!$C21,'Entradas e Saídas'!$AU$5:$AU$44) -> 0 | AJ21: =SUMIF('Entradas e Saídas'!$AT$5:$AT$44,Controle!$C21,'Entradas e Saídas'!$AV$5:$AV$44) -> 0 | AK21: =AI21-AJ21 -> 0 | AL21: =AK21*Inventário!$G17 -> 0 | AM21: =SUMIF('Entradas e Saídas'!$AZ$5:$AZ$44,Controle!$C21,'Entradas e Saídas'!$BA$5:$BA$44) -> 0 | AN21: =SUMIF('Entradas e Saídas'!$AZ$5:$AZ$44,Controle!$C21,'Entradas e Saídas'!$BB$5:$BB$44) -> 0 | AO21: =AM21-AN21 -> 0 | AP21: =AO21*Inventário!$G17 -> 0 | AQ21: =SUMIF('Entradas e Saídas'!$BF$5:$BF$44,Controle!$C21,'Entradas e Saídas'!$BG$5:$BG$44) -> 0 | AR21: =SUMIF('Entradas e Saídas'!$BF$5:$BF$44,Controle!$C21,'Entradas e Saídas'!$BH$5:$BH$44) -> 0 | AS21: =AQ21-AR21 -> 0 | AT21: =AS21*Inventário!$G17 -> 0 | AU21: =SUMIF('Entradas e Saídas'!$BL$5:$BL$44,Controle!$C21,'Entradas e Saídas'!$BM$5:$BM$44) -> 0 | AV21: =SUMIF('Entradas e Saídas'!$BL$5:$BL$44,Controle!$C21,'Entradas e Saídas'!$BN$5:$BN$44) -> 0 | AW21: =AU21-AV21 -> 0 | AX21: =AW21*Inventário!$G17 -> 0 | AY21: =SUMIF('Entradas e Saídas'!$BR$5:$BR$44,Controle!$C21,'Entradas e Saídas'!$BS$5:$BS$44) -> 0 | AZ21: =SUMIF('Entradas e Saídas'!$BR$5:$BR$44,Controle!$C21,'Entradas e Saídas'!$BT$5:$BT$44) -> 0 | BA21: =AY21-AZ21 -> 0 | BB21: =BA21*Inventário!$G17 -> 0 | BE21: NOVEMBRO | BF21: =AX59 -> 0
B22: =IF(Inventário!C18="","",Inventário!C18) | C22: =IF(B22="","",VLOOKUP(B22,Inventário!$C$4:$D$53,2,FALSE)) | D22: =IF(B22="","",I22+M22+Q22+U22+Y22+AC22+AG22+AK22+AO22+AS22+AW22+BA22+Inventário!H18) | E22: =IF(B22="","",IF(D22<0,"-",(D22*Inventário!G18))) | F22: =IF(B22="","",IF(D22>Inventário!I18,"NÃO",CONCATENATE("SIM:"," ",Inventário!J18," ","unid"))) | G22: =SUMIF('Entradas e Saídas'!$D$5:$D$44,Controle!$C22,'Entradas e Saídas'!$E$5:$E$44) -> 0 | H22: =SUMIF('Entradas e Saídas'!$D$5:$D$44,Controle!$C22,'Entradas e Saídas'!$F$5:$F$44) -> 0 | I22: =G22-H22 -> 0 | J22: =I22*Inventário!G18 -> 0 | K22: =SUMIF('Entradas e Saídas'!$J$5:$J$44,Controle!$C22,'Entradas e Saídas'!$K$5:$K$44) -> 0 | L22: =SUMIF('Entradas e Saídas'!$J$5:$J$44,Controle!$C22,'Entradas e Saídas'!$L$5:$L$44) -> 0 | M22: =K22-L22 -> 0 | N22: =M22*Inventário!$G18 -> 0 | O22: =SUMIF('Entradas e Saídas'!$P$5:$P$44,Controle!$C22,'Entradas e Saídas'!$Q$5:$Q$44) -> 0 | P22: =SUMIF('Entradas e Saídas'!$P$5:$P$44,Controle!$C22,'Entradas e Saídas'!$R$5:$R$44) -> 0 | Q22: =O22-P22 -> 0 | R22: =Q22*Inventário!$G18 -> 0 | S22: =SUMIF('Entradas e Saídas'!$V$5:$V$44,Controle!$C22,'Entradas e Saídas'!$W$5:$W$44) -> 0 | T22: =SUMIF('Entradas e Saídas'!$V$5:$V$44,Controle!$C22,'Entradas e Saídas'!$X$5:$X$44) -> 0 | U22: =S22-T22 -> 0 | V22: =U22*Inventário!$G18 -> 0 | W22: =SUMIF('Entradas e Saídas'!$AB$5:$AB$44,Controle!$C22,'Entradas e Saídas'!$AC$5:$AC$44) -> 0 | X22: =SUMIF('Entradas e Saídas'!$AB$5:$AB$44,Controle!$C22,'Entradas e Saídas'!$AD$5:$AD$44) -> 0 | Y22: =W22-X22 -> 0 | Z22: =Y22*Inventário!$G18 -> 0 | AA22: =SUMIF('Entradas e Saídas'!$AH$5:$AH$44,Controle!$C22,'Entradas e Saídas'!$AI$5:$AI$44) -> 0 | AB22: =SUMIF('Entradas e Saídas'!$AH$5:$AH$44,Controle!$C22,'Entradas e Saídas'!$AJ$5:$AJ$44) -> 0 | AC22: =AA22-AB22 -> 0 | AD22: =AC22*Inventário!$G18 -> 0 | AE22: =SUMIF('Entradas e Saídas'!$AN$5:$AN$44,Controle!$C22,'Entradas e Saídas'!$AO$5:$AO$44) -> 0 | AF22: =SUMIF('Entradas e Saídas'!$AH$5:$AH$44,Controle!$C22,'Entradas e Saídas'!$AP$5:$AP$44) -> 0 | AG22: =AE22-AF22 -> 0 | AH22: =AG22*Inventário!$G18 -> 0 | AI22: =SUMIF('Entradas e Saídas'!$AT$5:$AT$44,Controle!$C22,'Entradas e Saídas'!$AU$5:$AU$44) -> 0 | AJ22: =SUMIF('Entradas e Saídas'!$AT$5:$AT$44,Controle!$C22,'Entradas e Saídas'!$AV$5:$AV$44) -> 0 | AK22: =AI22-AJ22 -> 0 | AL22: =AK22*Inventário!$G18 -> 0 | AM22: =SUMIF('Entradas e Saídas'!$AZ$5:$AZ$44,Controle!$C22,'Entradas e Saídas'!$BA$5:$BA$44) -> 0 | AN22: =SUMIF('Entradas e Saídas'!$AZ$5:$AZ$44,Controle!$C22,'Entradas e Saídas'!$BB$5:$BB$44) -> 0 | AO22: =AM22-AN22 -> 0 | AP22: =AO22*Inventário!$G18 -> 0 | AQ22: =SUMIF('Entradas e Saídas'!$BF$5:$BF$44,Controle!$C22,'Entradas e Saídas'!$BG$5:$BG$44) -> 0 | AR22: =SUMIF('Entradas e Saídas'!$BF$5:$BF$44,Controle!$C22,'Entradas e Saídas'!$BH$5:$BH$44) -> 0 | AS22: =AQ22-AR22 -> 0 | AT22: =AS22*Inventário!$G18 -> 0 | AU22: =SUMIF('Entradas e Saídas'!$BL$5:$BL$44,Controle!$C22,'Entradas e Saídas'!$BM$5:$BM$44) -> 0 | AV22: =SUMIF('Entradas e Saídas'!$BL$5:$BL$44,Controle!$C22,'Entradas e Saídas'!$BN$5:$BN$44) -> 0 | AW22: =AU22-AV22 -> 0 | AX22: =AW22*Inventário!$G18 -> 0 | AY22: =SUMIF('Entradas e Saídas'!$BR$5:$BR$44,Controle!$C22,'Entradas e Saídas'!$BS$5:$BS$44) -> 0 | AZ22: =SUMIF('Entradas e Saídas'!$BR$5:$BR$44,Controle!$C22,'Entradas e Saídas'!$BT$5:$BT$44) -> 0 | BA22: =AY22-AZ22 -> 0 | BB22: =BA22*Inventário!$G18 -> 0 | BE22: DEZEMBRO | BF22: =BB59 -> 0
B23: =IF(Inventário!C19="","",Inventário!C19) | C23: =IF(B23="","",VLOOKUP(B23,Inventário!$C$4:$D$53,2,FALSE)) | D23: =IF(B23="","",I23+M23+Q23+U23+Y23+AC23+AG23+AK23+AO23+AS23+AW23+BA23+Inventário!H19) | E23: =IF(B23="","",IF(D23<0,"-",(D23*Inventário!G19))) | F23: =IF(B23="","",IF(D23>Inventário!I19,"NÃO",CONCATENATE("SIM:"," ",Inventário!J19," ","unid"))) | G23: =SUMIF('Entradas e Saídas'!$D$5:$D$44,Controle!$C23,'Entradas e Saídas'!$E$5:$E$44) -> 0 | H23: =SUMIF('Entradas e Saídas'!$D$5:$D$44,Controle!$C23,'Entradas e Saídas'!$F$5:$F$44) -> 0 | I23: =G23-H23 -> 0 | J23: =I23*Inventário!G19 -> 0 | K23: =SUMIF('Entradas e Saídas'!$J$5:$J$44,Controle!$C23,'Entradas e Saídas'!$K$5:$K$44) -> 0 | L23: =SUMIF('Entradas e Saídas'!$J$5:$J$44,Controle!$C23,'Entradas e Saídas'!$L$5:$L$44) -> 0 | M23: =K23-L23 -> 0 | N23: =M23*Inventário!$G19 -> 0 | O23: =SUMIF('Entradas e Saídas'!$P$5:$P$44,Controle!$C23,'Entradas e Saídas'!$Q$5:$Q$44) -> 0 | P23: =SUMIF('Entradas e Saídas'!$P$5:$P$44,Controle!$C23,'Entradas e Saídas'!$R$5:$R$44) -> 0 | Q23: =O23-P23 -> 0 | R23: =Q23*Inventário!$G19 -> 0 | S23: =SUMIF('Entradas e Saídas'!$V$5:$V$44,Controle!$C23,'Entradas e Saídas'!$W$5:$W$44) -> 0 | T23: =SUMIF('Entradas e Saídas'!$V$5:$V$44,Controle!$C23,'Entradas e Saídas'!$X$5:$X$44) -> 0 | U23: =S23-T23 -> 0 | V23: =U23*Inventário!$G19 -> 0 | W23: =SUMIF('Entradas e Saídas'!$AB$5:$AB$44,Controle!$C23,'Entradas e Saídas'!$AC$5:$AC$44) -> 0 | X23: =SUMIF('Entradas e Saídas'!$AB$5:$AB$44,Controle!$C23,'Entradas e Saídas'!$AD$5:$AD$44) -> 0 | Y23: =W23-X23 -> 0 | Z23: =Y23*Inventário!$G19 -> 0 | AA23: =SUMIF('Entradas e Saídas'!$AH$5:$AH$44,Controle!$C23,'Entradas e Saídas'!$AI$5:$AI$44) -> 0 | AB23: =SUMIF('Entradas e Saídas'!$AH$5:$AH$44,Controle!$C23,'Entradas e Saídas'!$AJ$5:$AJ$44) -> 0 | AC23: =AA23-AB23 -> 0 | AD23: =AC23*Inventário!$G19 -> 0 | AE23: =SUMIF('Entradas e Saídas'!$AN$5:$AN$44,Controle!$C23,'Entradas e Saídas'!$AO$5:$AO$44) -> 0 | AF23: =SUMIF('Entradas e Saídas'!$AH$5:$AH$44,Controle!$C23,'Entradas e Saídas'!$AP$5:$AP$44) -> 0 | AG23: =AE23-AF23 -> 0 | AH23: =AG23*Inventário!$G19 -> 0 | AI23: =SUMIF('Entradas e Saídas'!$AT$5:$AT$44,Controle!$C23,'Entradas e Saídas'!$AU$5:$AU$44) -> 0 | AJ23: =SUMIF('Entradas e Saídas'!$AT$5:$AT$44,Controle!$C23,'Entradas e Saídas'!$AV$5:$AV$44) -> 0 | AK23: =AI23-AJ23 -> 0 | AL23: =AK23*Inventário!$G19 -> 0 | AM23: =SUMIF('Entradas e Saídas'!$AZ$5:$AZ$44,Controle!$C23,'Entradas e Saídas'!$BA$5:$BA$44) -> 0 | AN23: =SUMIF('Entradas e Saídas'!$AZ$5:$AZ$44,Controle!$C23,'Entradas e Saídas'!$BB$5:$BB$44) -> 0 | AO23: =AM23-AN23 -> 0 | AP23: =AO23*Inventário!$G19 -> 0 | AQ23: =SUMIF('Entradas e Saídas'!$BF$5:$BF$44,Controle!$C23,'Entradas e Saídas'!$BG$5:$BG$44) -> 0 | AR23: =SUMIF('Entradas e Saídas'!$BF$5:$BF$44,Controle!$C23,'Entradas e Saídas'!$BH$5:$BH$44) -> 0 | AS23: =AQ23-AR23 -> 0 | AT23: =AS23*Inventário!$G19 -> 0 | AU23: =SUMIF('Entradas e Saídas'!$BL$5:$BL$44,Controle!$C23,'Entradas e Saídas'!$BM$5:$BM$44) -> 0 | AV23: =SUMIF('Entradas e Saídas'!$BL$5:$BL$44,Controle!$C23,'Entradas e Saídas'!$BN$5:$BN$44) -> 0 | AW23: =AU23-AV23 -> 0 | AX23: =AW23*Inventário!$G19 -> 0 | AY23: =SUMIF('Entradas e Saídas'!$BR$5:$BR$44,Controle!$C23,'Entradas e Saídas'!$BS$5:$BS$44) -> 0 | AZ23: =SUMIF('Entradas e Saídas'!$BR$5:$BR$44,Controle!$C23,'Entradas e Saídas'!$BT$5:$BT$44) -> 0 | BA23: =AY23-AZ23 -> 0 | BB23: =BA23*Inventário!$G19 -> 0
