Workbook

Sheet Jan
B2: Fluxo de Caixa de Janeiro de 2015
B4: ÍTEM / DESCRIÇÃO | D4: Realizado | E4: PREVISTO | F4: PREVISTO | G4: Realizado | H4: Realizado | I4: Realizado | J4: Realizado | K4: Realizado | L4: PREVISTO | M4: PREVISTO | N4: Realizado | O4: Realizado | P4: Realizado | Q4: Realizado | R4: Realizado | S4: PREVISTO | T4: PREVISTO | U4: Realizado | V4: Realizado | W4: Realizado | X4: Realizado | Y4: Realizado | Z4: PREVISTO | AA4: PREVISTO | AB4: Realizado | AC4: Realizado | AD4: Realizado | AE4: Realizado | AF4: Realizado | AG4: PREVISTO
D5: 42006 | E5: =D5+1 -> 42007 | F5: =E5+1 -> 42008 | G5: =F5+1 -> 42009 | H5: =G5+1 -> 42010 | I5: =H5+1 -> 42011 | J5: =I5+1 -> 42012 | K5: =J5+1 -> 42013 | L5: =K5+1 -> 42014 | ... AG5: =AF5+1 -> 42035 | AH5: ACUMULADO
C6: SALDO ANTERIOR DA CONTA CORRENTE | D6: 145330.03 | E6: =D77 -> 213824.71 | F6: =E77 -> 213824.71 | G6: =F77 -> 213824.71 | H6: =G77 -> 231337.3 | I6: =H77 -> 256642.48 | J6: =I77 -> 292558.13 | K6: =J77 -> 309064.94 | L6: =K77 -> 228324.42 | ... AG6: =AF77 -> 68629.55 | AH6: =D6 -> 145330.03
B7: ENTRADAS | C7: Adiantamento de Clientes | G7: =3000+342+2660 -> 6002 | H7: =421.05 -> 421.05 | I7: =391.35 -> 391.35 | J7: =280.4 -> 280.4 | P7: =2301.6+500 -> 2801.6 | R7: =440 -> 440 | U7: =952.35+254.1 -> 1206.45 | W7: =636.3 -> 636.3 | X7: =1263+2935+825 -> 5023 | Y7: =2216.55+368.55+1986.6 -> 4571.7 | AB7: =2939.05+23100+1898.4 -> 27937.45 | AC7: =13812.45 -> 13812.45 | AD7: =1458+1052 -> 2510 | AH7: =SUM(D7:AG7) -> 66033.75
C8: Depósito RDS | K8: =1179.5+8+262.14+445.15+663.1+1032.15+1077.54+1147.6+2224 -> 8039.18 | R8: =1079.7+1152.75+900.6+720.17+476.35+33.09+121.84+2829.4+1890.33 -> 9204.23 | V8: =2728.35+660.45+849.25+1273.5 -> 5511.55 | AB8: =160.14+648.79+848.05+850.15+5296.3 -> 7803.43 | AF8: =35.09+340.45+1399.4+1443.84 -> 3218.78 | AH8: =SUM(D8:AG8) -> 33777.17
C9: Crédito Não Identificado | AH9: =SUM(D9:AG9) -> 0
C10: Fundo de Reserva | V10: 15000 | AH10: =SUM(D10:AG10) -> 15000
C11: Faturas | D11: =8893.55+288.75+254.1 -> 9436.4 | G11: =6700+254.1 -> 6954.1 | H11: =15125.52 -> 15125.52 | I11: =27254.22+1934.7 -> 29188.92 | J11: =5366.3+4382.52+424.9 -> 10173.72 | K11: =4145.35+241.4+2098+3055.5+6111 -> 15651.25 | N11: =1235+1727.25+1330+613.8+1869.56+5631.56 -> 12407.17 | O11: =16257.5+1884.23+618.02+1142.97+651.42+696.09 -> 21250.23 | P11: =2280.6 -> 2280.6 | Q11: =1530.75+1234.31 -> 2765.06 | R11: =4388.85+6382.5+283.36+222.33+271.81 -> 11548.85 | U11: =66218.67+241.4+556.72+1948.1+2066.81+271.81 -> 71303.51 | V11: =67043.57+11004+1713.71+619+505.55 -> 80885.83 | W11: =7654.19+2385.41+587.51 -> 10627.11 | X11: =83837.17+2274.81 -> 86111.98 | Y11: =6840.56+482.8+254.1+1619.34+667.59 -> 9864.39 | AB11: =22666.73+557.55+288.75+6456.21+2657.08+842.11+1122.82+2363.82+2453+2355.65+2122.48+1806.11+3872.4+2310.97+3107.29+3221.67 -> 58204.64 | AC11: =103520+6285.3+9333.45 -> 119138.75 | AD11: =76295.24+3638.95+2007.78 -> 81941.97 | AE11: =29760.76+2422.49+2441.78+2076.95 -> 36701.98 | AF11: =8551.23+735 -> 9286.23 | AH11: =SUM(D11:AG11) -> 700848.21
C12: Receitas Diversas | D12: 3.59 | G12: 3.89 | H12: 4.31 | I12: =23383.92+4.94 -> 23388.86 | J12: 5.12 | K12: =0.01+3.84 -> 3.85 | N12: 4.8 | O12: 5.27 | P12: 4.87 | Q12: =62305.99+4.06 -> 62310.05 | R12: 4.83 | U12: 6.61 | V12: 0.35 | W12: 0.18 | X12: 2.02 | Y12: 2.05 | AB12: 2.67 | AC12: =180+5.2 -> 185.2 | AD12: =180.95+2.72 -> 183.67 | AE12: 3.67 | AF12: =375+1.23 -> 376.23 | AH12: =SUM(D12:AG12) -> 86502.09
C13: Amex | D13: 6872.51 | G13: =6432.15 -> 6432.15 | H13: 4726.84 | I13: 3663.36 | J13: 2636.83 | K13: 1135.58 | N13: 3047.72 | O13: 683.06 | P13: 891.56 | Q13: 743.43 | R13: 656.39 | U13: 11218.06 | V13: 358.58 | Y13: 360.8 | AD13: 557.86 | AH13: =SUM(D13:AG13) -> 43984.73
C14: Visa Electron | D14: 3962.37 | G14: 2651.31 | H14: 586.06 | I14: 1961.41 | J14: 871.75 | K14: 1688.06 | N14: 3913.57 | O14: 1016.28 | P14: 90.12 | Q14: 678.89 | R14: 2025.99 | U14: 5426.83 | V14: 2978.83 | W14: 234.65 | X14: 165.91 | Y14: 1244.8 | AB14: 2657.85 | AC14: 1432.25 | AD14: 709.52 | AE14: 2575.32 | AF14: 740.61 | AH14: =SUM(D14:AG14) -> 37612.38
C15: Master Débito | D15: 12719.38 | G15: =556.98+458.61 -> 1015.59 | H15: 5455.06 | J15: 36.6 | K15: =3195.82+2642.86 -> 5838.68 | N15: =5131.47+74.08 -> 5205.55 | O15: =323.75+543.19 -> 866.94 | P15: =50.63+137.86 -> 188.49 | Q15: 3103.34 | R15: 419.95 | U15: =4977.5+614.96 -> 5592.46 | V15: 851.15 | W15: 114.16 | X15: 463.17 | Y15: 16.68 | AB15: 2274.59 | AC15: 2343.89 | AD15: =1188.37+12.76 -> 1201.13 | AE15: 2709.05 | AF15: 876.5 | AH15: =SUM(D15:AG15) -> 51292.36
C16: Visa Crédito | D16: 27262.61 | G16: 23040.58 | H16: 8343.95 | I16: 22416.38 | J16: 5728.06 | K16: 16816.67 | N16: 29947.47 | O16: 15031.09 | P16: 21099.34 | Q16: 868.99 | R16: 12599.17 | U16: 23976.14 | V16: 1347.06 | W16: 2753.93 | X16: 10546.28 | Y16: 1803.71 | AB16: 15595.73 | AC16: 1168.94 | AD16: 11465.86 | AE16: 8485.29 | AF16: 13114.01 | AH16: =SUM(D16:AG16) -> 273411.26
C17: Master Crédito | D17: =17658.28+822.94 -> 18481.22 | G17: 6060.69 | H17: 1328.64 | I17: 5764.28 | J17: 522.71 | K17: 1093.45 | N17: 5303.14 | O17: 3260.07 | P17: 2449.29 | Q17: 3687.63 | R17: 11082.73 | U17: 8221.43 | V17: 3004.22 | W17: 4352.27 | X17: 3304.9 | Y17: 2302.6 | AB17: 4874.44 | AC17: 5286.58 | AD17: 9006.42 | AE17: 3580.61 | AF17: 992.43 | AH17: =SUM(D17:AG17) -> 103959.75
C18: TOTAL DAS ENTRADAS | D18: =SUM(D7:D17) -> 78738.08 | E18: =SUM(E7:E17) -> 0 | F18: =SUM(F7:F17) -> 0 | G18: =SUM(G7:G17) -> 52160.31 | H18: =SUM(H7:H17) -> 35991.43 | I18: =SUM(I7:I17) -> 86774.56 | J18: =SUM(J7:J17) -> 20255.19 | K18: =SUM(K7:K17) -> 50266.72 | ... AH18: =SUM(AH7:AH17) -> 1412421.7
C19: Repasse Salários e Encargos | I19: 45378.91 | AF19: 65000 | AH19: =SUM(D19:AG19) -> 110378.91
B20: SAIDAS | C20: Repasse Aluguel de Salas e Equipamentos | G20: =6820.81+945.47 -> 7766.28 | AH20: =SUM(D20:AG20) -> 7766.28
C21: Repasse A&B | Q21: 60343.29 | AF21: =(1280+40393.29+45061+833.25)-5921.3 -> 81646.24 | AH21: =SUM(D21:AG21) -> 141989.53
C22: Repasse Telefonia | AH22: =SUM(D22:AG22) -> 0
C23: Repasse Internet | G23: =1261.93 -> 1261.93 | AH23: =SUM(D23:AG23) -> 1261.93
C24: Repasse Diversos | G24: =693.35+1060.57+1272.93 -> 3026.85 | P24: =714.92 -> 714.92 | AH24: =SUM(D24:AG24) -> 3741.77
C25: Repasse ao Condomínio | D25: =-SUM(D19:D24) -> 0 | E25: =-SUM(E19:E24) -> 0 | F25: =-SUM(F19:F24) -> 0 | G25: =-SUM(G19:G24) -> -12055.06 | H25: =-SUM(H19:H24) -> 0 | I25: =-SUM(I19:I24) -> -45378.91 | J25: =-SUM(J19:J24) -> 0 | K25: =-SUM(K19:K24) -> 0 | ... AH25: =-SUM(AH19:AH24) -> -265138.42
C26: Impostos Lei 10.833 | AH26: =SUM(D26:AG26) -> 0
C27: IRRF | U27: =10.8+141.93+56.25+613.6+42.67 -> 865.25 | AH27: =SUM(D27:AG27) -> 865.25
C28: ISS a Recolher | K28: =55786.8 -> 55786.8 | AH28: =SUM(D28:AG28) -> 55786.8
C29: ISS Retido a Recolher | AH29: =SUM(D29:AG29) -> 0
C30: INSS Retido a Recolher | AH30: =SUM(D30:AG30) -> 0
C31: IPTU a Pagar | AH31: =SUM(D31:AG31) -> 0
C32: PIS a Recolher | Y32: =6816.16-3626.68 -> 3189.48 | AH32: =SUM(D32:AG32) -> 3189.48
C33: COFINS a Recolher | Y33: =31459.14-15964.25 -> 15494.89 | AH33: =SUM(D33:AG33) -> 15494.89
C34: IRPJ a Recolher | AD34: =(86863.53+88794.35+60425.77)-80399.88 -> 155683.77 | AH34: =SUM(D34:AG34) -> 155683.77
C35: CSLL a Recolher | AD35: =(39885.97+30393.28+38470.87)-16599.87 -> 92150.25 | AH35: =SUM(D35:AG35) -> 92150.25
C36: Total de Impostos | D36: =-SUM(D26:D35) -> 0 | E36: =-SUM(E26:E35) -> 0 | F36: =-SUM(F26:F35) -> 0 | G36: =-SUM(G26:G35) -> 0 | H36: =-SUM(H26:H35) -> 0 | I36: =-SUM(I26:I35) -> 0 | J36: =-SUM(J26:J35) -> 0 | K36: =-SUM(K26:K35) -> -55786.8 | ... AH36: =-SUM(AH26:AH35) -> -323170.44
C37: Água e Esgoto | AH37: =SUM(D37:AG37) -> 0
C38: Energia Elétrica | K38: 11.06 | O38: 17506.77 | AH38: =SUM(D38:AG38) -> 17517.83
C39: Telefone | AH39: =SUM(D39:AG39) -> 0
C40: Total de Contas de Consumo | D40: =-SUM(D37:D39) -> 0 | E40: =-SUM(E37:E39) -> 0 | F40: =-SUM(F37:F39) -> 0 | G40: =-SUM(G37:G39) -> 0 | H40: =-SUM(H37:H39) -> 0 | I40: =-SUM(I37:I39) -> 0 | J40: =-SUM(J37:J39) -> 0 | K40: =-SUM(K37:K39) -> -11.06 | ... AH40: =-SUM(AH37:AH39) -> -17517.83
C41: Adiantamento Dividendos | V41: =44367.37+55696.44+48097.69+95299.9+127253.96+60476.44 -> 431191.8 | W41: =2397.95+2860.53+3028.9 -> 8287.38 | AH41: =SUM(D41:AG41) -> 439479.18
C42: Fundo de Reserva | AB42: =15000+18975.27 -> 33975.27 | AH42: =SUM(D42:AG42) -> 33975.27
...

Sheet Fev
B2: Fluxo de Caixa de Fevereiro de 2015
B4: ÍTEM / DESCRIÇÃO | D4: Realizado | E4: Realizado | F4: Realizado | G4: Realizado | H4: Realizado | I4: PREVISTO | J4: PREVISTO | K4: Realizado | L4: Realizado | M4: Realizado | N4: Realizado | O4: Realizado | P4: PREVISTO | Q4: PREVISTO | R4: PREVISTO | S4: PREVISTO | T4: Realizado | U4: Realizado | V4: Realizado | W4: PREVISTO | X4: PREVISTO | Y4: Realizado | Z4: Realizado | AA4: Realizado | AB4: Realizado | AC4: Realizado | AD4: PREVISTO | AE4: PREVISTO | AF4: PREVISTO | AG4: PREVISTO
D5: 41672 | E5: =D5+1 -> 41673 | F5: =E5+1 -> 41674 | G5: =F5+1 -> 41675 | H5: =G5+1 -> 41676 | I5: =H5+1 -> 41677 | J5: =I5+1 -> 41678 | K5: =J5+1 -> 41679 | L5: =K5+1 -> 41680 | ... AG5: =AF5+1 -> 41701 | AH5: ACUMULADO
C6: SALDO ANTERIOR DA CONTA CORRENTE | D6: =Jan!AG77 -> 68629.55 | E6: =D77 -> 71718.21 | F6: =E77 -> 154558 | G6: =F77 -> 170153.95 | H6: =G77 -> 218453.82 | I6: =H77 -> 229506.8 | J6: =I77 -> 229506.8 | K6: =J77 -> 229506.8 | L6: =K77 -> 226678.59 | ... AG6: =AF77 -> -211532.21 | AH6: =D6 -> 68629.55
B7: ENTRADAS | C7: Adiantamento de Clientes | D7: =54 -> 54 | E7: =289+346.5+318+40 -> 993.5 | F7: =500+263 -> 763 | G7: =1630+160 -> 1790 | H7: =1993 -> 1993 | K7: =3234 -> 3234 | M7: =822.15+793 -> 1615.15 | N7: =60+378 -> 438 | T7: =218.92 -> 218.92 | U7: =1512+410+263.02 -> 2185.02 | V7: =277.2 -> 277.2 | Y7: =419.47+302.4 -> 721.87 | AC7: =328.77+126.45 -> 455.22 | AE7: 105 | AG7: =1122 -> 1122 | AH7: =SUM(D7:AC7) -> 14738.88
C8: Depósito RDS | O8: =298.3+852.9+285.9+476.8+113.58+617.4+302.6+984.95+1885.25+534.75+1011.99+124.95+463.8+128.16 -> 8081.33 | V8: =2412.8+1486.9+1308.86+992.17+1628.82+918.64+3375.54 -> 12123.73 | AC8: =112+153.69+180+241.75+316.5+1786.85+1809.16 -> 4599.95 | AD8: =60.5+261.92+445.46+522.3+976.54+1005.6+1034.88+1067.2+1525.61+1951+2957.06+2993.25+695.1 -> 15496.42 | AH8: =SUM(D8:AC8) -> 24805.01
C9: Crédito Não Identificado | V9: =15608.42+14391.58 -> 30000 | AE9: 330.3 | AF9: =720+1155 -> 1875 | AH9: =SUM(D9:AC9) -> 30000
C10: Fundo de Reserva | V10: 104000 | AH10: =SUM(D10:AC10) -> 104000
C11: Faturas | D11: =1794.66+3971.75+4508.7 -> 10275.11 | E11: =66160.24+2053.32+1352.45+830.18+415.09+415.09 -> 71226.37 | F11: =55550.14+466.2 -> 56016.34 | G11: =32898.79+346.5+382.85+1455.3+1997.1 -> 37080.54 | H11: =3226.36 -> 3226.36 | K11: =24448.23+781.2 -> 25229.43 | L11: =30338.71+280.7+6172.89+5580.98+5993.85+3139.44+2807.05+1122.82+1250.7+561.41 -> 57248.55 | M11: =4929.65+1997.1 -> 6926.75 | N11: =2865.45+330.75+374.16 -> 3570.36 | O11: =10629.72+1621.93+1102.5 -> 13354.15 | T11: =6000.37 -> 6000.37 | U11: =59909.21+1102.5+1102.5+724.5 -> 62838.71 | V11: =6040.3 -> 6040.3 | Y11: =2810.42+437.85+7017.11 -> 10265.38 | Z11: =29219.49 -> 29219.49 | AA11: =3445.2+4632.47+5402.44+4750.2+288.75 -> 18519.06 | AB11: =61132.6+3253.08+2034.64 -> 66420.32 | AC11: =12142.11 -> 12142.11 | AD11: =367.5+280.7+431.55 -> 1079.75 | AE11: =16199.5+280.7+2807.02+431.55+667.8+38762.15 -> 59148.72 | AF11: =11953.14+438.9+5099.44+347.7 -> 17839.18 | AG11: =3155.25+1150.3+1213.9+1964.93+367.5+3182.55 -> 11034.43 | AH11: =SUM(D11:AC11) -> 495599.7
C12: Receitas Diversas | D12: 1.23 | E12: 2.63 | F12: 2.96 | G12: 3.8 | H12: =214.78+4.04 -> 218.82 | K12: 3.99 | L12: 5.47 | M12: 5.14 | N12: 5.21 | O12: 2.05 | T12: 4.36 | U12: 4.89 | V12: 1.6 | Y12: 0.21 | Z12: 0.68 | AA12: 0.3 | AB12: 1.87 | AC12: 0.16 | AH12: =SUM(D12:AC12) -> 265.37
C13: Amex | D13: 741.64 | E13: 0 | F13: 3975.61 | G13: 1572.35 | H13: 339.79 | K13: 7246.21 | L13: 0 | N13: 220.09 | O13: 1955.81 | T13: 17594.44 | U13: 402.96 | V13: 2034.64 | Y13: 3075.6 | Z13: 202.86 | AA13: 2076.75 | AB13: 3438.18 | AC13: 3524.01 | AD13: 62.31 | AE13: 6210.32 | AF13: 386.4 | AG13: 1763.58 | AH13: =SUM(D13:AC13) -> 48400.94
C14: Visa Electron | D14: 3904.38 | E14: 381.88 | F14: 1159.69 | G14: 736.35 | H14: 1110.38 | K14: 3289.26 | L14: 1356.62 | M14: 616.39 | N14: 2638.46 | O14: 885.87 | T14: 4522.17 | U14: 2255.59 | V14: 1111.9 | Y14: 3629.83 | Z14: 1838.47 | AA14: 1364.75 | AB14: 1228.36 | AC14: 2015.44 | AD14: 339 | AE14: 1384.02 | AF14: 1043.01 | AG14: 932.33 | AH14: =SUM(D14:AC14) -> 34045.79
C15: Master Débito | D15: =2561.81+678.68 -> 3240.49 | E15: =98.76+22.67 -> 121.43 | F15: 292.89 | G15: 497.65 | H15: =400.57+380.26 -> 780.83 | K15: =1117.21+710.53 -> 1827.74 | L15: 26.44 | M15: 13.74 | N15: 73.98 | O15: 3379.99 | T15: =9163.06+726.33 -> 9889.39 | U15: =813.07+415.73 -> 1228.8 | V15: 509.59 | Y15: =623.26+972.4 -> 1595.66 | Z15: 1298.13 | AA15: 680.59 | AB15: 794.37 | AC15: =98.9+100.47 -> 199.37 | AD15: 579.5 | AE15: 591.98 | AF15: 908.79 | AG15: 722.36 | AH15: =SUM(D15:AC15) -> 26451.08
C16: Visa Crédito | D16: 12834.6 | E16: 7694.22 | F16: 3517.95 | G16: 5767.61 | H16: 4797.8 | K16: 33579.27 | L16: 19601.14 | M16: 13555.31 | N16: 8110.71 | O16: 7402.6 | T16: =66920.52 -> 66920.52 | U16: 5090.94 | V16: 11608.59 | Y16: 19712.47 | Z16: 1431.71 | AA16: 5550.9 | AB16: 10763.38 | AC16: =411.47+33020.09 -> 33431.56 | AD16: 2469.31 | AE16: 8498.82 | AF16: 5130.87 | AG16: 3605.2 | AH16: =SUM(D16:AC16) -> 271371.28
C17: Master Crédito | D17: =12060.7+878.08 -> 12938.78 | E17: 2519.96 | F17: 3951.51 | G17: 950.9 | H17: 931.85 | K17: =17811.59+962.97 -> 18774.56 | L17: 7324.5 | M17: 1875.43 | N17: 4977.75 | O17: =6840.87+21.3987 -> 6862.2687 | T17: =26595.04+359.74 -> 26954.78 | U17: 2833.09 | V17: 3517.75 | Y17: 31550.34 | Z17: 922.12 | AA17: 2432.75 | AB17: 6749.24 | AC17: 3021.44 | AD17: 2920.6 | AE17: =1595.03 -> 1595.03 | AF17: 6574.5 | AG17: =340.34+310.06 -> 650.4 | AH17: =SUM(D17:AC17) -> 139089.02
C18: TOTAL DAS ENTRADAS | D18: =SUM(D7:D17) -> 43990.23 | E18: =SUM(E7:E17) -> 82939.99 | F18: =SUM(F7:F17) -> 69679.95 | G18: =SUM(G7:G17) -> 48399.2 | H18: =SUM(H7:H17) -> 13398.83 | I18: =SUM(I7:I17) -> 0 | J18: =SUM(J7:J17) -> 0 | K18: =SUM(K7:K17) -> 93184.46 | ... AH18: =SUM(AH7:AH17) -> 1188767.1
C19: Repasse Salários e Encargos | D19: =875.6+20145.35 -> 21020.95 | AC19: 30000 | AH19: =SUM(E19:AC19) -> 30000
B20: SAIDAS | C20: Repasse Aluguel de Salas e Equipamentos | D20: =6440.17+2784.67 -> 9224.84 | AH20: =SUM(E20:AC20) -> 0
C21: Repasse A&B | O21: =71641.47+190+51999+866.8 -> 124697.27 | AC21: =52159.27+40320+506-4 -> 92981.27 | AG21: =45546.8+28000+470.4+266.2 -> 74283.4 | AH21: =SUM(E21:AC21) -> 217678.54
C22: Repasse Telefonia | AH22: =SUM(E22:AC22) -> 0
C23: Repasse Internet | D23: =989.55 -> 989.55 | AH23: =SUM(E23:AC23) -> 0
C24: Repasse Diversos | D24: =1222.08+492.43 -> 1714.51 | O24: =3078.2+342.07 -> 3420.27 | AH24: =SUM(E24:AC24) -> 3420.27
C25: Repasse ao Condomínio | D25: =-SUM(D19:D24) -> -32949.85 | E25: =-SUM(E19:E24) -> 0 | F25: =-SUM(F19:F24) -> 0 | G25: =-SUM(G19:G24) -> 0 | H25: =-SUM(H19:H24) -> 0 | I25: =-SUM(I19:I24) -> 0 | J25: =-SUM(J19:J24) -> 0 | K25: =-SUM(K19:K24) -> 0 | ... AH25: =-SUM(AH19:AH24) -> -251098.81
C26: Impostos Lei 10.833 | AH26: =SUM(D26:AC26) -> 0
C27: IRRF | U27: =10.8+13.03+28.66+13+56.25+109.36 -> 231.1 | AH27: =SUM(D27:AC27) -> 231.1
C28: ISS a Recolher | H28: =587.15 -> 587.15 | K28: 58733.01 | AH28: =SUM(D28:AC28) -> 59320.16
C29: ISS Retido a Recolher | AH29: =SUM(D29:AC29) -> 0
C30: INSS Retido a Recolher | AH30: =SUM(D30:AC30) -> 0
C31: IPTU a Pagar | N31: 14678.84 | O31: =75+75 -> 150 | AH31: =SUM(D31:AC31) -> 14828.84
C32: PIS a Recolher | AA32: =8438.11-3431.24 -> 5006.87 | AH32: =SUM(D32:AC32) -> 5006.87
C33: COFINS a Recolher | AA33: =38945.12-15751.01 -> 23194.11 | AH33: =SUM(D33:AC33) -> 23194.11
C34: IRPJ a Recolher | AE34: =55072.82+95830.65+81485.32+802.49 -> 233191.28 | AH34: =SUM(D34:AC34) -> 0
C35: CSLL a Recolher | AE35: =37604.18+28466.22+42419.03+288.89 -> 108778.32 | AH35: =SUM(D35:AC35) -> 0
C36: Total de Impostos | D36: =-SUM(D26:D35) -> 0 | E36: =-SUM(E26:E35) -> 0 | F36: =-SUM(F26:F35) -> 0 | G36: =-SUM(G26:G35) -> 0 | H36: =-SUM(H26:H35) -> -587.15 | I36: =-SUM(I26:I35) -> 0 | J36: =-SUM(J26:J35) -> 0 | K36: =-SUM(K26:K35) -> -58733.01 | ... AH36: =-SUM(AH26:AH35) -> -102581.08
C37: Água e Esgoto | AH37: =SUM(D37:AC37) -> 0
C38: Energia Elétrica | M38: =3028.92+2225.55+2885.16+2109.63+1764.16+2554.1+2193.97+1135.45+4451.01 -> 22347.95 | AH38: =SUM(D38:AC38) -> 22347.95
C39: Telefone | AH39: =SUM(D39:AC39) -> 0
C40: Total de Contas de Consumo | D40: =-SUM(D37:D39) -> 0 | E40: =-SUM(E37:E39) -> 0 | F40: =-SUM(F37:F39) -> 0 | G40: =-SUM(G37:G39) -> 0 | H40: =-SUM(H37:H39) -> 0 | I40: =-SUM(I37:I39) -> 0 | J40: =-SUM(J37:J39) -> 0 | K40: =-SUM(K37:K39) -> 0 | ... AH40: =-SUM(AH37:AH39) -> -22347.95
C41: Adiantamento Dividendos | V41: =60476.04+35496.22+42759.96+59920.25+66029.31+43674.66 -> 308356.44 | Y41: =7824.8+13894.25+10833.89+16711.68+14866.6+17836.66+7971.03+41183.46 -> 131122.37 | Z41: =2860.53*3 -> 8581.59 | AH41: =SUM(D41:AC41) -> 448060.4
C42: Fundo de Reserva | F42: 50000 | AH42: =SUM(D42:AC42) -> 50000
...

Sheet Março
B2: Fluxo de Caixa de Março de 2015
B4: ÍTEM / DESCRIÇÃO | D4: Realizado | E4: Realizado | F4: Realizado | G4: Realizado | H4: Realizado | I4: PREVISTO | J4: PREVISTO | K4: Realizado | L4: Realizado | M4: Realizado | N4: Realizado | O4: Realizado | P4: PREVISTO | Q4: PREVISTO | R4: Realizado | S4: Realizado | T4: Realizado | U4: Realizado | V4: Realizado | W4: PREVISTO | X4: PREVISTO | Y4: Realizado | Z4: Realizado | AA4: Realizado | AB4: Realizado | AC4: Realizado | AD4: PREVISTO | AE4: PREVISTO | AF4: Realizado | AG4: Realizado | AH4: PREVISTO
D5: 42065 | E5: =D5+1 -> 42066 | F5: =E5+1 -> 42067 | G5: =F5+1 -> 42068 | H5: =G5+1 -> 42069 | I5: =H5+1 -> 42070 | J5: =I5+1 -> 42071 | K5: =J5+1 -> 42072 | L5: =K5+1 -> 42073 | ... AH5: =AG5+1 -> 42095 | AI5: ACUMULADO
C6: SALDO ANTERIOR DA CONTA CORRENTE | D6: =Fev!AC77 -> 9114.0987 | E6: =D77 -> 80963.659 | F6: =E77 -> 115898.69 | G6: =F77 -> 81249.329 | H6: =G77 -> 126891.73 | I6: =H77 -> 132739.16 | J6: =I77 -> 132739.16 | K6: =J77 -> 132739.16 | L6: =K77 -> 222786.49 | ... AH6: =AG77 -> 141151.21 | AI6: =D6 -> 9114.0987
B7: ENTRADAS | C7: Adiantamento de Clientes | D7: =372+370+279.09 -> 1021.09 | E7: =1053+35.2+318.15+80 -> 1486.35 | F7: =280+409 -> 689 | G7: =11105+320 -> 11425 | K7: =443+426.3 -> 869.3 | N7: =219 -> 219 | R7: =351+699.3 -> 1050.3 | T7: =280+420 -> 700 | U7: =280+438 -> 718 | V7: =491+4604+12165+1500+280+289.8 -> 19329.8 | Y7: =346.5 -> 346.5 | AC7: =230+1480.5 -> 1710.5 | AF7: =2722.65+1008 -> 3730.65 | AI7: =SUM(D7:AG7) -> 43295.49
C8: Depósito RDS | O8: =2235.34+1121.83+312.54+468.79+77.3+147.26+199.6+204.26+274.42+288.6+664.9+1495.15+2035.88 -> 9525.87 | AG8: =2871.78+70.4+214.82+258.17+261.63+414.49+604.75+659.59+668.35+950.7+1032.46+1403.55+1444.51+1478.66+1684+2858.4+2907.43+3050.28+3253.94-1302.2 -> 24785.71 | AI8: =SUM(D8:AG8) -> 34311.58
C9: Crédito Não Identificado | AI9: =SUM(D9:AG9) -> 0
C10: Fundo de Reserva | AI10: =SUM(D10:AG10) -> 0
C11: Faturas | D11: =37553.29+3379.53+19759.95 -> 60692.77 | E11: =13421.55+403.6+489.72 -> 14314.87 | F11: =1771.02+2192.4+25000 -> 28963.42 | G11: =9212+365.4+665.7+1638.51 -> 11881.61 | H11: =1627.5+3236.89+416.35 -> 5280.74 | K11: =166959.54+1076.46+1208.9+2179.1+1671.9 -> 173095.9 | L11: =33959.7+16707.04 -> 50666.74 | M11: =1499.2 -> 1499.2 | N11: =15054.25+775.05 -> 15829.3 | O11: =10658.41+932.4 -> 11590.81 | R11: =15096.04+5082+3954 -> 24132.04 | S11: =95977.88+708.74+14559.3 -> 111245.92 | T11: =320.25 -> 320.25 | U11: =396.1 -> 396.1 | V11: =17855.61+330.75+3645.86 -> 21832.22 | Y11: =10743.92+4794.6+3929.87+20000 -> 39468.39 | Z11: =23793.21+274.31+744.59 -> 24812.11 | AA11: =6428.06 -> 6428.06 | AB11: =9455.06+553.63 -> 10008.69 | AC11: =7013.71 -> 7013.71 | AF11: =8044.05+8400+843.92+579.6 -> 17867.57 | AG11: =68285.97+5910.49+5508.21+3222.68+1875.9+3273.27+579.6 -> 88656.12 | AI11: =SUM(D11:AG11) -> 725996.54
C12: Receitas Diversas | D12: 1.36 | E12: 2.01 | F12: 1.43 | G12: 2.28 | H12: 2.35 | K12: 4.05 | L12: 4.45 | M12: 4.23 | N12: =358.56+5.15 -> 363.71 | O12: 4.5 | R12: 7.16 | S12: 9.41 | T12: 8.31 | U12: 8.81 | V12: 0.79 | Y12: 2.13 | Z12: 2.79 | AA12: 2.41 | AB12: =366.3+2.78 -> 369.08 | AC12: =445.5+75+564.71+2.71 -> 1087.92 | AF12: =187.5+0.27 -> 187.77 | AG12: =26.24+520.82+2.57 -> 549.63 | AI12: =SUM(D12:AG12) -> 2626.58
C13: Amex | D13: 4042.67 | E13: 1779.38 | F13: 3884.19 | G13: 5967.15 | H13: 817.91 | K13: 2696 | L13: 2653.02 | M13: 5838.32 | N13: 15116.94 | O13: 4161.98 | R13: 15329.67 | T13: 418.19 | U13: 5189.74 | V13: 177.91 | Y13: =749.57 -> 749.57 | Z13: 1764.88 | AA13: 6298.27 | AB13: 630.95 | AC13: 3502.51 | AF13: 7533.97 | AG13: 14.44 | AI13: =SUM(D13:AG13) -> 88567.66
C14: Visa Electron | D14: 2292.23 | E14: 1932.17 | F14: 280.13 | G14: 33.36 | H14: 2080.54 | K14: =2438.14 -> 2438.14 | L14: 154.83 | M14: 173.43 | N14: 252.16 | O14: 1173.08 | R14: 2284.33 | S14: 1395.07 | T14: 235.69 | U14: 764.03 | Y14: 3419.3 | Z14: =1825.77 -> 1825.77 | AA14: 389.43 | AB14: 609.08 | AC14: 1954.35 | AF14: 8407.48 | AG14: 725.81 | AI14: =SUM(D14:AG14) -> 32820.41
C15: Master Débito | D15: =1106.29+553.74 -> 1660.03 | E15: =26.29+555.58 -> 581.87 | F15: 1661.12 | G15: =81.73+74.57 -> 156.3 | H15: 161.13 | K15: =1990.08+123.38 -> 2113.46 | M15: 762.88 | N15: 88.55 | O15: 356.77 | R15: =4338.57+3.92 -> 4342.49 | S15: 212.28 | T15: 202.67 | U15: =1214.09+17.66 -> 1231.75 | Y15: =845+923.51 -> 1768.51 | Z15: =643.67 -> 643.67 | AA15: =319.18 -> 319.18 | AB15: 99.83 | AC15: =535.01+103.03 -> 638.04 | AF15: =4265.26+154.54 -> 4419.8 | AG15: =630.97+459.64 -> 1090.61 | AI15: =SUM(D15:AG15) -> 22510.94
C16: Visa Crédito | D16: =42876.1 -> 42876.1 | E16: 9151.35 | F16: 8631.59 | G16: 15369.36 | H16: 5816.61 | K16: 54732 | L16: =8870.34 -> 8870.34 | M16: 24269.26 | N16: 36640.16 | O16: =3909.78 -> 3909.78 | R16: 63219.3 | S16: 2632.25 | T16: 8798.18 | U16: 20872.13 | V16: 3898.07 | Y16: 40781.77 | Z16: 9543.85 | AA16: 15791.05 | AB16: 5841.73 | AC16: 8492.97 | AF16: 20832.87 | AG16: 8497.98 | AI16: =SUM(D16:AG16) -> 419468.7
C17: Master Crédito | D17: =14352.02+25.09 -> 14377.11 | E17: 5924.46 | F17: 3674.99 | G17: 885.28 | H17: 458.29 | K17: =15300.4+408.41 -> 15708.81 | L17: =120.86+763.58 -> 884.44 | M17: 2644.6 | N17: 5161.54 | O17: 29504.88 | R17: =48763.14+677.57 -> 49440.71 | S17: =5781.26+2767.45 -> 8548.71 | T17: 1522.68 | U17: 1880.42 | V17: 8011.83 | Y17: 9389.2 | Z17: 414.88 | AA17: 6996.33 | AB17: 2560.95 | AC17: 2117.77 | AF17: 7020.29 | AG17: 2759.94 | AI17: =SUM(D17:AG17) -> 179888.11
C18: TOTAL DAS ENTRADAS | D18: =SUM(D7:D17) -> 126963.36 | E18: =SUM(E7:E17) -> 35172.46 | F18: =SUM(F7:F17) -> 47785.87 | G18: =SUM(G7:G17) -> 45720.34 | H18: =SUM(H7:H17) -> 14617.57 | I18: =SUM(I7:I17) -> 0 | J18: =SUM(J7:J17) -> 0 | K18: =SUM(K7:K17) -> 251657.66 | ... AH18: =SUM(AH7:AH17) -> 0 | AI18: =SUM(D18:AG18) -> 1549486
C19: Repasse Salários e Encargos | F19: =49213.04+875.6 -> 50088.64 | AA19: 16000 | AC19: 25000 | AF19: 50000 | AI19: =SUM(D19:AF19) -> 141088.64
B20: SAIDAS | C20: Repasse Aluguel de Salas e Equipamentos | F20: =6992.84+2756.88 -> 9749.72 | AI20: =SUM(D20:AG20) -> 9749.72
C21: Repasse A&B | O21: =34224.45+862.4+39829 -> 74915.85 | AF21: =35727.09+2158.2+38621+1073.73-355.3 -> 77224.72 | AI21: =SUM(D21:AG21) -> 152140.57
C22: Repasse Telefonia | F22: =1.98 -> 1.98 | AI22: =SUM(D22:AG22) -> 1.98
C23: Repasse Internet | F23: =2207.11 -> 2207.11 | AI23: =SUM(D23:AG23) -> 2207.11
C24: Repasse Diversos | F24: =450.36+1073.73 -> 1524.09 | O24: =108.49 -> 108.49 | AI24: =SUM(D24:AG24) -> 1632.58
C25: Repasse ao Condomínio | D25: =-SUM(D19:D24) -> 0 | E25: =-SUM(E19:E24) -> 0 | F25: =-SUM(F19:F24) -> -63571.54 | G25: =-SUM(G19:G24) -> 0 | H25: =-SUM(H19:H24) -> 0 | I25: =-SUM(I19:I24) -> 0 | J25: =-SUM(J19:J24) -> 0 | K25: =-SUM(K19:K24) -> 0 | ... AI25: =-SUM(AI19:AI24) -> -306820.6
C26: Impostos Lei 10.833 | AI26: =SUM(D26:AG26) -> 0
C27: IRRF | T27: =56.25+386.79+10.8+32.39+22.69 -> 508.92 | AI27: =SUM(D27:AG27) -> 508.92
C28: ISS a Recolher | K28: 59891.9 | AI28: =SUM(D28:AG28) -> 59891.9
C29: ISS Retido a Recolher | AI29: =SUM(D29:AG29) -> 0
C30: INSS Retido a Recolher | AI30: =SUM(D30:AG30) -> 0
C31: IPTU a Pagar | L31: 13381.47 | AI31: =SUM(D31:AG31) -> 13381.47
C32: PIS a Recolher | AA32: =5776.57 -> 5776.57 | AI32: =SUM(D32:AG32) -> 5776.57
C33: COFINS a Recolher | AA33: 26663.2 | AI33: =SUM(D33:AG33) -> 26663.2
C34: IRPJ a Recolher | AI34: =SUM(D34:AG34) -> 0
C35: CSLL a Recolher | AI35: =SUM(D35:AG35) -> 0
C36: Total de Impostos | D36: =-SUM(D26:D35) -> 0 | E36: =-SUM(E26:E35) -> 0 | F36: =-SUM(F26:F35) -> 0 | G36: =-SUM(G26:G35) -> 0 | H36: =-SUM(H26:H35) -> 0 | I36: =-SUM(I26:I35) -> 0 | J36: =-SUM(J26:J35) -> 0 | K36: =-SUM(K26:K35) -> -59891.9 | ... AI36: =-SUM(AI26:AI35) -> -106222.06
C37: Água e Esgoto | AI37: =SUM(D37:AG37) -> 0
C38: Energia Elétrica | M38: 12.32 | N38: =22488.21 -> 22488.21 | AI38: =SUM(D38:AG38) -> 22500.53
C39: Telefone | AI39: =SUM(D39:AG39) -> 0
C40: Total de Contas de Consumo | D40: =-SUM(D37:D39) -> 0 | E40: =-SUM(E37:E39) -> 0 | F40: =-SUM(F37:F39) -> 0 | G40: =-SUM(G37:G39) -> 0 | H40: =-SUM(H37:H39) -> 0 | I40: =-SUM(I37:I39) -> 0 | J40: =-SUM(J37:J39) -> 0 | K40: =-SUM(K37:K39) -> 0 | ... AI40: =-SUM(AI37:AI39) -> -22500.53
C41: Adiantamento Dividendos | V41: =36631.69+35718.18+102256.65+39740.4+42032.32+46797.33+59243.27+79919.5 -> 442339.34 | AI41: =SUM(D41:AG41) -> 442339.34
C42: Fundo de Reserva | D42: 25960.91 | K42: =16877.2+50000 -> 66877.2 | AF42: =6135.55+50000 -> 56135.55 | AI42: =SUM(D42:AF42) -> 148973.66
...

Sheet Abril
B2: Fluxo de Caixa de Abril de 2015
B4: ÍTEM / DESCRIÇÃO | D4: Realizado | E4: Realizado | F4: PREVISTO | G4: PREVISTO | H4: PREVISTO | I4: Realizado | J4: Realizado | K4: Realizado | L4: Realizado | M4: Realizado | N4: PREVISTO | O4: PREVISTO | P4: Realizado | Q4: Realizado | R4: Realizado | S4: Realizado | T4: Realizado | U4: PREVISTO | V4: PREVISTO | W4: Realizado | X4: PREVISTO | Y4: Realizado | Z4: Realizado | AA4: Realizado | AB4: PREVISTO | AC4: PREVISTO | AD4: Realizado | AE4: Realizado | AF4: Realizado | AG4: Realizado | AH4: PREVISTO
D5: 42095 | E5: =D5+1 -> 42096 | F5: =E5+1 -> 42097 | G5: =F5+1 -> 42098 | H5: =G5+1 -> 42099 | I5: =H5+1 -> 42100 | J5: =I5+1 -> 42101 | K5: =J5+1 -> 42102 | L5: =K5+1 -> 42103 | ... AH5: =AG5+1 -> 42125 | AI5: ACUMULADO
C6: SALDO ANTERIOR DA CONTA CORRENTE | D6: =Março!AG77 -> 141151.21 | E6: =D77 -> 176160.08 | F6: =E77 -> 230701.58 | G6: =F77 -> 230701.58 | H6: =G77 -> 230701.58 | I6: =H77 -> 230701.58 | J6: =I77 -> 222645.17 | K6: =J77 -> 286827.07 | L6: =K77 -> 313495.48 | ... AH6: =AG77 -> 26437.649 | AI6: =D6 -> 141151.21
B7: ENTRADAS | C7: Adiantamento de Clientes | D7: =419 -> 419 | E7: =1052.1+636 -> 1688.1 | I7: =433.12+456.23+886 -> 1775.35 | J7: =55+1500 -> 1555 | K7: =490.87+758.1+491 -> 1739.97 | L7: =439.45+431.03 -> 870.48 | M7: =11000 -> 11000 | P7: =263.03+213.05 -> 476.08 | Q7: =897 -> 897 | R7: =11000+622 -> 11622 | S7: =525+1000+239.4 -> 1764.4 | T7: =332+183 -> 515 | W7: =497.7+157.5 -> 655.2 | Y7: =771.75+1732.5 -> 2504.25 | Z7: =478 -> 478 | AD7: =650.1 -> 650.1 | AE7: =250+465.15+335 -> 1050.15 | AF7: =913.5+673.05 -> 1586.55 | AG7: =1037.31 -> 1037.31 | AI7: =SUM(D7:AG7) -> 42283.94
C8: Depósito RDS | W8: =397+1146.8+4545.1+9.72+63.4+66.2+126.94+137.05+228.09+245.45+273.98+542.9+577.2+685.14+790.9+995.29+1046.06+1080.83+1150.47+1216.57+1448.04 -> 16773.13 | AG8: =1089.9+20+37+73.1+105.6+652.11+753.42+1383.3+1514.25+4417.7 -> 10046.38 | AI8: =SUM(D8:AG8) -> 26819.51
C9: Crédito Não Identificado | AI9: =SUM(D9:AG9) -> 0
C10: Fundo de Reserva | W10: 20000 | AF10: 125000 | AI10: =SUM(D10:AG10) -> 145000
C11: Faturas | D11: =5491.95+693+2192.46+2103.17 -> 10480.58 | E11: =19311.59+1904.24+3383.54+886.71 -> 25486.08 | I11: =4710.94+397.95+2325.17+2125.2+466.2 -> 10025.46 | J11: =34173.61+3087.75+2192.36+1964.93+561.41 -> 41980.06 | K11: =18648+2146.26+3196.24+2181.99 -> 26172.49 | L11: =15680.95+1087.8+3087.75 -> 19856.5 | M11: =9972.66+2075.48 -> 12048.14 | P11: =24360.52+4771.98+3395.42+14236.95 -> 46764.87 | Q11: =58287.07+516.71+1363.8+19935.7 -> 80103.28 | R11: =15980.9+291.9+693 -> 16965.8 | S11: =430.1+8608.95+280.7+4771.98+6476.95+6335+1080.15+1161.16 -> 29144.99 | T11: =5133.14+2713 -> 7846.14 | W11: =12650.1+5557.72+397.95+1646.4+1631.3+658.35 -> 22541.82 | Y11: =26856.02+245+505.12 -> 27606.14 | Z11: =10975.92 -> 10975.92 | AA11: =7478.09+444 -> 7922.09 | AD11: =21183.48 -> 21183.48 | AE11: =44730.64+661.5 -> 45392.14 | AF11: =12183.95 -> 12183.95 | AG11: =5597.95+8309.95+280.7+280.7+10359.77+9852.4+992.25+726.5 -> 36400.22 | AI11: =SUM(D11:AG11) -> 511080.15
C12: Receitas Diversas | D12: =111.25+3.2 -> 114.45 | E12: 4.18 | I12: =168.51+4.08 -> 172.59 | J12: 5.19 | K12: 5.72 | L12: 6.43 | M12: 4.81 | P12: =720+6.74 -> 726.74 | Q12: 8.32 | R12: 5.65 | S12: 6.42 | T12: 6.44 | W12: 0.45 | Y12: =2574.48+2585.49+1.06 -> 5161.03 | Z12: 1.58 | AA12: 1.12 | AD12: =2574.48+2585.49+2.34 -> 5162.31 | AE12: =2574.48+2585.49+3.38 -> 5163.35 | AF12: 0.02 | AG12: 0.48 | AI12: =SUM(D12:AG12) -> 16557.28
C13: Amex | D13: 16010.24 | E13: 3480.27 | I13: 7912.18 | J13: 8789.94 | K13: 1019.37 | L13: 6083.43 | M13: 1869.75 | P13: 15622.97 | Q13: 2667.75 | R13: 144.61 | S13: 2897.11 | T13: 6327.23 | W13: 10950.96 | Y13: 3690.57 | Z13: =774.93 -> 774.93 | AA13: 823.46 | AD13: 12090.26 | AE13: 68.49 | AF13: 801.59 | AG13: 1269.42 | AI13: =SUM(D13:AG13) -> 103294.53
C14: Visa Electron | D14: 996.72 | E14: 884.48 | I14: 6631.59 | J14: 137.35 | K14: 66.33 | L14: 2605.56 | M14: 373.35 | P14: 6130.71 | Q14: 80.95 | R14: 1718.77 | S14: 512.94 | T14: 1265.01 | W14: 3587.31 | Y14: 1129.26 | Z14: 0 | AA14: 2765.77 | AD14: 5645.78 | AE14: 163.37 | AF14: 63.93 | AG14: 232.7 | AI14: =SUM(D14:AG14) -> 34991.88
C15: Master Débito | D15: 909.19 | E15: =877.02+1527.5 -> 2404.52 | I15: =3175.71+45.33 -> 3221.04 | J15: =245.59+69.05 -> 314.64 | L15: =1047.92+22.57 -> 1070.49 | M15: =1228.73+182.7 -> 1411.43 | P15: =1589.54+40.42 -> 1629.96 | Q15: 141.78 | R15: 3234.78 | S15: 747.34 | T15: 428.79 | W15: =1857.62+1236.37 -> 3093.99 | Y15: 517.73 | Z15: 0 | AD15: =1536.65+9.81 -> 1546.46 | AE15: =919.85+51.51 -> 971.36 | AF15: 218.81 | AG15: 52.3 | AI15: =SUM(D15:AG15) -> 21914.61
C16: Visa Crédito | D16: 11550.2 | E16: 7272.47 | I16: 28930.7 | J16: 6741.7 | K16: =3199.65+287.93 -> 3487.58 | L16: 8229.27 | M16: 3490.71 | P16: 37197.02 | Q16: 9549.19 | R16: =1984.86+4460.64 -> 6445.5 | S16: 2189.95 | T16: 5202.67 | W16: =561.56+27428.91 -> 27990.47 | Y16: =21375.47 -> 21375.47 | Z16: =11034.69 -> 11034.69 | AD16: 26849.35 | AE16: 2836.4 | AF16: 10281.51 | AG16: 9386.94 | AI16: =SUM(D16:AG16) -> 240041.79
C17: Master Crédito | D17: 2906.26 | E17: 13417.22 | I17: 12591.14 | J17: =4133.53+571.77 -> 4705.3 | K17: 587 | L17: 2877.38 | M17: =287.93+3165.49 -> 3453.42 | P17: =324.68+24715.23+1820.92 -> 26860.83 | Q17: 5952.98 | R17: =1323.25+143.33 -> 1466.58 | S17: =605.46+6096.86 -> 6702.32 | T17: 1778.17 | W17: =1162.94+9710.56+14.59 -> 10888.09 | Y17: =3668.47 -> 3668.47 | Z17: =4921.21 -> 4921.21 | AA17: =661.62+4201.81 -> 4863.43 | AD17: 11489.71 | AE17: 8023.14 | AF17: 3980.32 | AG17: 6860.8 | AI17: =SUM(D17:AG17) -> 137993.77
C18: TOTAL DAS ENTRADAS | D18: =SUM(D7:D17) -> 43386.64 | E18: =SUM(E7:E17) -> 54637.32 | F18: =SUM(F7:F17) -> 0 | G18: =SUM(G7:G17) -> 0 | H18: =SUM(H7:H17) -> 0 | I18: =SUM(I7:I17) -> 71260.05 | J18: =SUM(J7:J17) -> 64229.18 | K18: =SUM(K7:K17) -> 33078.46 | ... AH18: =SUM(AH7:AH17) -> 0 | AI18: =SUM(D18:AG18) -> 1279977.5
C19: Repasse Salários e Encargos | I19: =6246.47+1573.47 -> 7819.94 | AI19: =SUM(D19:AF19) -> 7819.94
B20: SAIDAS | C20: Repasse Aluguel de Salas e Equipamentos | I20: =4457.56 -> 4457.56 | AI20: =SUM(D20:AG20) -> 4457.56
C21: Repasse A&B | R21: =62029.4+1482.2+891+594+41927.6 -> 106924.2 | AI21: =SUM(D21:AG21) -> 106924.2
C22: Repasse Telefonia | I22: =651.92 -> 651.92 | AI22: =SUM(D22:AG22) -> 651.92
C23: Repasse Internet | I23: =1256.61 -> 1256.61 | AI23: =SUM(D23:AG23) -> 1256.61
C24: Repasse Diversos | I24: =630.32+603.69 -> 1234.01 | P24: =100.27 -> 100.27 | AI24: =SUM(D24:AG24) -> 1334.28
C25: Repasse ao Condomínio | D25: =-SUM(D19:D24) -> 0 | E25: =-SUM(E19:E24) -> 0 | F25: =-SUM(F19:F24) -> 0 | G25: =-SUM(G19:G24) -> 0 | H25: =-SUM(H19:H24) -> 0 | I25: =-SUM(I19:I24) -> -15420.04 | J25: =-SUM(J19:J24) -> 0 | K25: =-SUM(K19:K24) -> 0 | ... AI25: =-SUM(AI19:AI24) -> -122444.51
C26: Impostos Lei 10.833 | AI26: =SUM(D26:AG26) -> 0
C27: IRRF | T27: =42.61+33.81+11.76+16.23+18.65+439.53+10.8+56.25+29.36 -> 659 | AI27: =SUM(D27:AG27) -> 659
C28: ISS a Recolher | AI28: =SUM(D28:AG28) -> 0
C29: ISS Retido a Recolher | M29: 54224.86 | AI29: =SUM(D29:AG29) -> 54224.86
C30: INSS Retido a Recolher | AI30: =SUM(D30:AG30) -> 0
C31: IPTU a Pagar | M31: 13381.47 | AI31: =SUM(D31:AG31) -> 13381.47
C32: PIS a Recolher | Y32: =7389.88-2699.34 -> 4690.54 | AI32: =SUM(D32:AG32) -> 4690.54
C33: COFINS a Recolher | Y33: =34107.12-12523.47 -> 21583.65 | AI33: =SUM(D33:AG33) -> 21583.65
C34: IRPJ a Recolher | AF34: =(85319.98+90317+102167.39)-58877.14 -> 218927.23 | AI34: =SUM(D34:AG34) -> 218927.23
C35: CSLL a Recolher | AF35: =(37500.26+33954.12+32875.19)-12182.02 -> 92147.55 | AI35: =SUM(D35:AG35) -> 92147.55
C36: Total de Impostos | D36: =-SUM(D26:D35) -> 0 | E36: =-SUM(E26:E35) -> 0 | F36: =-SUM(F26:F35) -> 0 | G36: =-SUM(G26:G35) -> 0 | H36: =-SUM(H26:H35) -> 0 | I36: =-SUM(I26:I35) -> 0 | J36: =-SUM(J26:J35) -> 0 | K36: =-SUM(K26:K35) -> 0 | ... AI36: =-SUM(AI26:AI35) -> -405614.3
C37: Água e Esgoto | AI37: =SUM(D37:AG37) -> 0
C38: Energia Elétrica | P38: 20933.14 | AI38: =SUM(D38:AG38) -> 20933.14
C39: Telefone | AI39: =SUM(D39:AG39) -> 0
C40: Total de Contas de Consumo | D40: =-SUM(D37:D39) -> 0 | E40: =-SUM(E37:E39) -> 0 | F40: =-SUM(F37:F39) -> 0 | G40: =-SUM(G37:G39) -> 0 | H40: =-SUM(H37:H39) -> 0 | I40: =-SUM(I37:I39) -> 0 | J40: =-SUM(J37:J39) -> 0 | K40: =-SUM(K37:K39) -> 0 | ... AI40: =-SUM(AI37:AI39) -> -20933.14
C41: Adiantamento Dividendos | W41: =(2520*159)-2574.18 -> 398105.82 | AD41: =2574.48+2585.49 -> 5159.97 | AE41: =2574.48+2585.49 -> 5159.97 | AI41: =SUM(D41:AG41) -> 408425.76
C42: Fundo de Reserva | AI42: =SUM(D42:AF42) -> 0
...

Sheet Maio
B2: Fluxo de Caixa de Maio de 2015
B4: ÍTEM / DESCRIÇÃO | D4: PREVISTO | E4: PREVISTO | F4: PREVISTO | G4: Realizado | H4: Realizado | I4: Realizado | J4: Realizado | K4: Realizado | L4: PREVISTO | M4: PREVISTO | N4: Realizado | O4: Realizado | P4: Realizado | Q4: Realizado | R4: Realizado | S4: PREVISTO | T4: PREVISTO | U4: Realizado | V4: Realizado | W4: Realizado | X4: Realizado | Y4: Realizado | Z4: PREVISTO | AA4: PREVISTO | AB4: Realizado | AC4: Realizado | AD4: Realizado | AE4: Realizado | AF4: Realizado | AG4: PREVISTO | AH4: PREVISTO
D5: 42125 | E5: =D5+1 -> 42126 | F5: =E5+1 -> 42127 | G5: =F5+1 -> 42128 | H5: =G5+1 -> 42129 | I5: =H5+1 -> 42130 | J5: =I5+1 -> 42131 | K5: =J5+1 -> 42132 | L5: =K5+1 -> 42133 | ... AH5: =AG5+1 -> 42155 | AI5: ACUMULADO
C6: SALDO ANTERIOR DA CONTA CORRENTE | D6: =Abril!AG77 -> 26437.649 | E6: =D77 -> 26437.649 | F6: =E77 -> 26437.649 | G6: =F77 -> 26437.649 | H6: =G77 -> 37345.819 | I6: =H77 -> 115064.37 | J6: =I77 -> 48953.569 | K6: =J77 -> 131426.74 | L6: =K77 -> 80839.179 | ... AH6: =AG77 -> 32489.369 | AI6: =D6 -> 26437.649
B7: ENTRADAS | C7: Adiantamento de Clientes | G7: =157+1774.85+456 -> 2387.85 | H7: =199.5+157+902.75+684+160+434+187 -> 2724.25 | I7: =1421+157+1500 -> 3078 | N7: =1144.5+2047.5+346+270 -> 3808 | O7: =157 -> 157 | P7: =1966.1+46.3 -> 2012.4 | Q7: 5670 | R7: =2000 -> 2000 | U7: =443.62+172 -> 615.62 | V7: =302.4+3201.45+157+500 -> 4160.85 | X7: =610 -> 610 | Y7: =2000+530 -> 2530 | AB7: =500+30.5+250 -> 780.5 | AC7: =10840+735 -> 11575 | AE7: =1310.4+4830 -> 6140.4 | AF7: =1620+1753.11+490+887.25 -> 4750.36 | AI7: =SUM(D7:AG7) -> 53000.23
C8: Depósito RDS | N8: =274.5+425.3+448.72+470+540.9+664.45+701.7+1023.77+1121.38+1649.05+1842.9 -> 9162.67 | W8: =2638.45+446+496.17+522.92+674.35+1251.55+1562.7+1611.2+1856.55+2423.45 -> 13483.34 | AE8: =761.28+882.85+51+343.78+425.75+855.33+1200.1+2176 -> 6696.09 | AI8: =SUM(D8:AG8) -> 29342.1
C9: Crédito Não Identificado | AI9: =SUM(D9:AG9) -> 0
C10: Fundo de Reserva | W10: =13248.56+9805.58+12258.24+11231.77+6455.85 -> 53000 | AI10: =SUM(D10:AG10) -> 53000
C11: Faturas | G11: =50030.45+1734.03+330.75+1323+9081.45 -> 62499.68 | H11: =6628.75+57027.68+760.2 -> 64416.63 | I11: =423.15+1584.64+15594.6+11578.7 -> 29181.09 | J11: =9234.59+22747.78+9478.72+4040.41+4491.28+6002.01+1162.67+415.8 -> 57573.26 | K11: 5510.01 | N11: =20481.33 -> 20481.33 | O11: =48143.7 -> 48143.7 | P11: =5416.55+16258.24 -> 21674.79 | Q11: =1+16233.08 -> 16234.08 | R11: =9860.4+2079 -> 11939.4 | U11: =10022.95+422.25+215.6 -> 10660.8 | V11: =5793.18+41612.12+351.75+728.7+578.45+330.75 -> 49394.95 | W11: =606.33+5750.64+280.7 -> 6637.67 | X11: =622+1362.9 -> 1984.9 | Y11: =496.29+3735.92+397.95+8460.9+900.9+532 -> 14523.96 | AB11: =2574.35+634.2+351.75+1268.4 -> 4828.7 | AC11: =5566.85+30672.65+598.98+588 -> 37426.48 | AD11: =1066.08+588+693+4192.93+798 -> 7338.01 | AE11: =2381.48+1318.98+220.5+1493.12+207.9+294+693 -> 6608.98 | AF11: =1157.3+1375.84+294+882+3391.5+1206.4+215.96+611.8+588 -> 9722.8 | AI11: =SUM(D11:AG11) -> 486781.22
C12: Receitas Diversas | G12: 0.71 | H12: 2.14 | I12: 0.93 | J12: 2.49 | K12: 1.54 | N12: 1.94 | O12: 3.25 | P12: 3.57 | Q12: 4.29 | R12: 4.44 | U12: 3.47 | V12: 4.57 | W12: 0.14 | X12: 0.62 | Y12: 0.78 | AB12: =70.2+0.58 -> 70.78 | AC12: 1.81 | AD12: 1.79 | AE12: 2.62 | AF12: 0.62 | AI12: =SUM(D12:AG12) -> 112.5
C13: Amex | G13: 2164.77 | H13: 1308.59 | I13: 1531.59 | J13: 9840.72 | K13: 1227.83 | N13: 5289.62 | O13: 9945.46 | P13: 5654.72 | Q13: 2185.81 | R13: 461.45 | U13: 4394.14 | V13: 339.79 | X13: 969.75 | Y13: 2953.65 | AB13: 4160.17 | AC13: 1745.85 | AD13: 956.73 | AE13: 1809.94 | AF13: 2224.36 | AI13: =SUM(D13:AG13) -> 59164.94
C14: Visa Electron | G14: 3004.29 | H14: 2359.29 | I14: 211.9 | J14: 193.18 | K14: 1746.33 | N14: 2484.04 | O14: 396.7 | P14: 2255.84 | Q14: 1033.1 | R14: 255.51 | U14: 4920.11 | V14: 1125.58 | W14: 3259.75 | X14: 1740.57 | Y14: 1631.83 | AB14: 1148.48 | AC14: 1458.53 | AD14: 1214.2 | AE14: 532.29 | AF14: 1510.75 | AI14: =SUM(D14:AG14) -> 32482.27
C15: Master Débito | G15: =1829.23+13.74 -> 1842.97 | H15: 1204 | I15: =3.92+1302.25 -> 1306.17 | J15: 161.7 | K15: 59.81 | N15: =1324.47+43.71 -> 1368.18 | O15: =865.42+254.48 -> 1119.9 | P15: =2143.91+283.47 -> 2427.38 | Q15: =134.81+21.58 -> 156.39 | R15: =380.6+164.15 -> 544.75 | U15: =2405.35+68 -> 2473.35 | V15: =88.75 -> 88.75 | W15: =177.52+115.88 -> 293.4 | X15: 761.85 | Y15: =869.73+14.72 -> 884.45 | AB15: 1791.75 | AC15: =96.85+91.84 -> 188.69 | AD15: =1136.33+288.47 -> 1424.8 | AE15: 261.25 | AF15: =2184.63+14.72 -> 2199.35 | AI15: =SUM(D15:AG15) -> 20558.89
C16: Visa Crédito | G16: 22041.56 | H16: 4408.06 | I16: 11964.4 | J16: 12833.73 | K16: 10062 | N16: 22737.17 | O16: 5779.84 | P16: 24281.66 | Q16: 10387.02 | R16: 4196.41 | U16: 18690.15 | V16: 5568.64 | W16: 8453.17 | X16: 12711.99 | Y16: 10640.24 | AB16: 30823.76 | AC16: 7509.77 | AD16: 8623.24 | AE16: 12855.86 | AF16: 15150.51 | AI16: =SUM(D16:AG16) -> 259719.18
C17: Master Crédito | G17: 20137.5 | H17: 1497.01 | I17: 991.6 | J17: 1994.82 | K17: 4124.68 | N17: 12910.68 | O17: 1168.93 | P17: 3719.08 | Q17: 1940.71 | R17: 1625.12 | U17: 20084.56 | V17: 2035.25 | W17: 3256.96 | X17: 6053.53 | Y17: 3195.16 | AB17: 11506.09 | AC17: 3780.13 | AD17: 2750.92 | AE17: 7712.84 | AF17: 514.31 | AI17: =SUM(D17:AG17) -> 110999.88
C18: TOTAL DAS ENTRADAS | D18: =SUM(D7:D17) -> 0 | E18: =SUM(E7:E17) -> 0 | F18: =SUM(F7:F17) -> 0 | G18: =SUM(G7:G17) -> 114079.33 | H18: =SUM(H7:H17) -> 77919.97 | I18: =SUM(I7:I17) -> 48265.68 | J18: =SUM(J7:J17) -> 82599.9 | K18: =SUM(K7:K17) -> 22732.2 | ... AH18: =SUM(AH7:AH17) -> 0 | AI18: =SUM(D18:AG18) -> 1105161.2
C19: Repasse Salários e Encargos | I19: 6606.47 | K19: 1621.6 | AI19: =SUM(D19:AF19) -> 8228.07
B20: SAIDAS | C20: Repasse Aluguel de Salas e Equipamentos | AI20: =SUM(D20:AG20) -> 0
C21: Repasse A&B | G21: =47073.66+2090+15000 -> 64163.66 | I21: 18637 | U21: =415.2+910.8+1942.45+33930+42395.09 -> 79593.54 | AF21: =(33539+514.8+36444.14)-4555.68 -> 65942.26 | AI21: =SUM(D21:AG21) -> 228336.46
C22: Repasse Telefonia | AI22: =SUM(D22:AG22) -> 0
C23: Repasse Internet | AI23: =SUM(D23:AG23) -> 0
C24: Repasse Diversos | K24: =968.31+261.21 -> 1229.52 | AI24: =SUM(D24:AG24) -> 1229.52
C25: Repasse ao Condomínio | D25: =-SUM(D19:D24) -> 0 | E25: =-SUM(E19:E24) -> 0 | F25: =-SUM(F19:F24) -> 0 | G25: =-SUM(G19:G24) -> -64163.66 | H25: =-SUM(H19:H24) -> 0 | I25: =-SUM(I19:I24) -> -25243.47 | J25: =-SUM(J19:J24) -> 0 | K25: =-SUM(K19:K24) -> -2851.12 | ... AI25: =-SUM(AI19:AI24) -> -237794.05
C26: Impostos Lei 10.833 | AI26: =SUM(D26:AG26) -> 0
C27: IRRF | U27: =59.69+12.36+59.45+26.7+56.25+286.73+55.02+29.87 -> 586.07 | AI27: =SUM(D27:AG27) -> 586.07
C28: ISS a Recolher | K28: 55810.06 | AI28: =SUM(D28:AG28) -> 55810.06
C29: ISS Retido a Recolher | AI29: =SUM(D29:AG29) -> 0
C30: INSS Retido a Recolher | AI30: =SUM(D30:AG30) -> 0
C31: IPTU a Pagar | K31: 13381.47 | AB31: =70.46 -> 70.46 | AF31: 11466.76 | AI31: =SUM(D31:AG31) -> 24918.69
C32: PIS a Recolher | AB32: 4548.29 | AI32: =SUM(D32:AG32) -> 4548.29
C33: COFINS a Recolher | AB33: 21158.47 | AI33: =SUM(D33:AG33) -> 21158.47
C34: IRPJ a Recolher | AI34: =SUM(D34:AG34) -> 0
C35: CSLL a Recolher | AI35: =SUM(D35:AG35) -> 0
C36: Total de Impostos | D36: =-SUM(D26:D35) -> 0 | E36: =-SUM(E26:E35) -> 0 | F36: =-SUM(F26:F35) -> 0 | G36: =-SUM(G26:G35) -> 0 | H36: =-SUM(H26:H35) -> 0 | I36: =-SUM(I26:I35) -> 0 | J36: =-SUM(J26:J35) -> 0 | K36: =-SUM(K26:K35) -> -69191.53 | ... AI36: =-SUM(AI26:AI35) -> -107021.58
C37: Água e Esgoto | AI37: =SUM(D37:AG37) -> 0
C38: Energia Elétrica | I38: =22294.37 -> 22294.37 | K38: 12.92 | P38: 106.06 | AI38: =SUM(D38:AG38) -> 22413.35
C39: Telefone | AI39: =SUM(D39:AG39) -> 0
C40: Total de Contas de Consumo | D40: =-SUM(D37:D39) -> 0 | E40: =-SUM(E37:E39) -> 0 | F40: =-SUM(F37:F39) -> 0 | G40: =-SUM(G37:G39) -> 0 | H40: =-SUM(H37:H39) -> 0 | I40: =-SUM(I37:I39) -> -22294.37 | J40: =-SUM(J37:J39) -> 0 | K40: =-SUM(K37:K39) -> -12.92 | ... AI40: =-SUM(AI37:AI39) -> -22413.35
C41: Adiantamento Dividendos | G41: =2574.48+2585.49 -> 5159.97 | W41: =270300.17-1736.75 -> 268563.42 | AI41: =SUM(D41:AG41) -> 273723.39
C42: Fundo de Reserva | Y42: 19173.37 | AF42: 20000 | AI42: =SUM(D42:AF42) -> 39173.37
...

Sheet Junho
B2: Fluxo de Caixa de Junho de 2015
B4: ÍTEM / DESCRIÇÃO | D4: Realizado | E4: Realizado | F4: Realizado | G4: PREVISTO | H4: Realizado | I4: PREVISTO | J4: PREVISTO | K4: Realizado | L4: Realizado | M4: Realizado | N4: Realizado | O4: Realizado | P4: PREVISTO | Q4: PREVISTO | R4: Realizado | S4: Realizado | T4: Realizado | U4: Realizado | V4: Realizado | W4: PREVISTO | X4: PREVISTO | Y4: Realizado | Z4: Realizado | AA4: Realizado | AB4: Realizado | AC4: Realizado | AD4: PREVISTO | AE4: PREVISTO | AF4: Realizado | AG4: Realizado | AH4: PREVISTO
D5: 42156 | E5: =D5+1 -> 42157 | F5: =E5+1 -> 42158 | G5: =F5+1 -> 42159 | H5: =G5+1 -> 42160 | I5: =H5+1 -> 42161 | J5: =I5+1 -> 42162 | K5: =J5+1 -> 42163 | L5: =K5+1 -> 42164 | ... AH5: =AG5+1 -> 42186 | AI5: ACUMULADO
C6: SALDO ANTERIOR DA CONTA CORRENTE | D6: =Maio!AF77 -> 32489.369 | E6: =D77 -> 66941.619 | F6: =E77 -> 107903.77 | G6: =F77 -> 116423.69 | H6: =G77 -> 116423.69 | I6: =H77 -> 121304.9 | J6: =I77 -> 121304.9 | K6: =J77 -> 121304.9 | L6: =K77 -> 197642 | ... AH6: =AG77 -> 118497.17 | AI6: =D6 -> 32489.369
B7: ENTRADAS | C7: Adiantamento de Clientes | D7: =514+300+246 -> 1060 | E7: =945+450 -> 1395 | F7: =218.92 -> 218.92 | H7: =156.95+294 -> 450.95 | K7: =1549.8+945+157 -> 2651.8 | L7: =700+187 -> 887 | M7: =129.15+443.62 -> 572.77 | N7: =200+490.75 -> 690.75 | O7: =645.75+600+6350.4+237 -> 7833.15 | R7: =6350.4 -> 6350.4 | S7: =271.67+710 -> 981.67 | T7: =564.9+346+280+532 -> 1722.9 | U7: =2750 -> 2750 | V7: 171.92 | Y7: 9667.5 | Z7: =630 -> 630 | AB7: =165+275+907.2 -> 1347.2 | AC7: =302.4 -> 302.4 | AF7: =840+2429.2 -> 3269.2 | AG7: 262.5 | AI7: =SUM(D7:AG7) -> 43216.03
C8: Depósito RDS | O8: =1465.25+293.24+395.2+440.2+476.33+592+746.2+927.4+1039.56+1228.64+1319.2+1621+1855+2765.75+5048.2 -> 20213.17 | V8: =1086+157+2578.2+309.9+421.35+478.51+775.2+1752.6+250 -> 7808.76 | AG8: =10+22+519.7+815+816.4+857.95+1242.7+1299.2+1696.98+2346.91+3879.07 -> 13505.91 | AI8: =SUM(D8:AG8) -> 41527.84
C9: Crédito Não Identificado | AI9: =SUM(D9:AG9) -> 0
C10: Fundo de Reserva | U10: 33052.61 | AI10: =SUM(D10:AG10) -> 33052.61
C11: Faturas | D11: =3356.48+2391.56+317.1+317.1+294+588+588+1814.41+872+872+872+6234.9+1796.97+6888.36 -> 27202.88 | E11: =17719.31+247.94+3197.25+3762.22+495.88+1461.46+2266.88 -> 29150.94 | F11: =5090.03+338.1+294+507.16+206+798 -> 7233.29 | H11: =14751.68+574.35+1350+1471.47+215.6+431.2 -> 18794.3 | K11: =10910.69+290.66+3371.18+2325.33+581.33+581.33+1268.4+4065.6+1323+247.94+431.2+2593.92 -> 27990.58 | L11: =6904.63+1080.15+1212+4410+951.3+338.1+3476.95 -> 18373.13 | M11: =4318.42+1011.15+1064+1176 -> 7569.57 | N11: =9979.53+385.35+2509.5+7949.6+294 -> 21117.98 | O11: =4027.69+1412.01+2929.5+2262.75+470.93 -> 11102.88 | R11: =6107.81+221.55+2156+1078+659.12+951.3 -> 11173.78 | S11: =22355.91+47560.37+294+598.5+1541.4+1356.08+929.5+703.5 -> 75339.26 | T11: =6225.2+581.33+588+1753.5+267.75+3197.32+3197.32+1162.66+3197.32+1130+270.27 -> 21570.67 | U11: =426.46+994.35+2833.8 -> 4254.61 | V11: =5998.06+294 -> 6292.06 | Y11: =9768.45+872+636.02+751.8+389.03+753+266+423.06+26.99 -> 13886.35 | Z11: =50693.44+613.75+564.9+595.35+362.25+2142+1667.83+4727.8 -> 61367.32 | AB11: =4035.01+4558.15+389.7+294+1034.1+1335.61+882+1170.75+1170.75+294 -> 15164.07 | AC11: =16598.81+20212.5+294+1129.8+7700.7+1080 -> 47015.81 | AF11: =26190.01+1336.05+8327.3+1239.7 -> 37093.06 | AG11: =24981.84+284.29+882+1704.3 -> 27852.43 | AI11: =SUM(D11:AG11) -> 489544.97
C12: Receitas Diversas | D12: 0.61 | E12: 2.6 | F12: =4555.68+2.19 -> 4557.87 | H12: 2.36 | K12: 3.88 | L12: 4.06 | M12: 2.52 | N12: 3.48 | O12: 4.22 | R12: 2.29 | S12: 4.16 | T12: 3.28 | U12: 4.26 | V12: 1 | Y12: 1.06 | Z12: 2.9 | AB12: 1.14 | AF12: 5.29 | AG12: 2.35 | AI12: =SUM(D12:AG12) -> 4609.33
C13: Amex | D13: 1690.49 | E13: 324.14 | F13: 2863.41 | H13: 7158.93 | K13: 13039.77 | L13: 1673.59 | M13: 1780.14 | N13: 2316.71 | O13: 646.44 | R13: 7197.48 | T13: 3094.08 | U13: 3619.18 | V13: 1493.43 | Y13: 957.54 | Z13: 641.14 | AB13: =3208.56+11851.96 -> 15060.52 | AC13: 1047.68 | AF13: 2703.67 | AG13: 1685.81 | AI13: =SUM(D13:AG13) -> 68994.15
C14: Visa Electron | D14: 7064.51 | E14: 389.39 | F14: 579.16 | H14: 3870.73 | K14: 3184.52 | L14: 917.17 | M14: 665.59 | N14: 283.66 | O14: 3169.53 | R14: 4931.71 | S14: 685.66 | T14: 1432.41 | U14: 725.5 | V14: 2255.1 | Y14: 4826.79 | Z14: 91.25 | AB14: =485.35+1048.1 -> 1533.45 | AC14: 2235.01 | AF14: 3195.84 | AG14: 2173.12 | AI14: =SUM(D14:AG14) -> 44210.1
C15: Master Débito | D15: =4356.33+324.08 -> 4680.41 | F15: 1115.19 | H15: 1493.84 | K15: =2043.2+384.92 -> 2428.12 | L15: =296.28+24.09 -> 320.37 | M15: =1047.72+288.47 -> 1336.19 | N15: 1391.49 | O15: 1505.65 | R15: =1542.6+151.21 -> 1693.81 | T15: 920.28 | U15: 310.89 | V15: 1399.62 | Y15: =1767+593 -> 2360 | Z15: =28.45+849.96+1962.4 -> 2840.81 | AB15: =1161+219.89 -> 1380.89 | AC15: =615.35 -> 615.35 | AF15: =1972.71+1544.63 -> 3517.34 | AG15: 42 | AI15: =SUM(D15:AG15) -> 29352.25
C16: Visa Crédito | D16: 27164.25 | E16: 3809.75 | F16: =14898.44 -> 14898.44 | H16: =9178.07+746.7 -> 9924.77 | K16: 18930.56 | L16: 4549.43 | M16: 14944.56 | N16: 19969.45 | O16: 6576.3 | R16: 26726.32 | S16: 11408.9 | T16: 10986.2 | U16: 10663.76 | V16: 4945.96 | Y16: 27794.27 | Z16: 3529.66 | AB16: =6934.14+4435.42 -> 11369.56 | AC16: =21827.42 -> 21827.42 | AF16: 32674.07 | AG16: =8148.62 -> 8148.62 | AI16: =SUM(D16:AG16) -> 290842.25
C17: Master Crédito | D17: 16261.83 | E17: 6076.03 | F17: 1962.07 | H17: 10825.28 | K17: =15203.87+66.61 -> 15270.48 | L17: 1292.08 | M17: 142.85 | N17: 4944.83 | O17: 995.98 | R17: 11617.24 | S17: 7311.84 | T17: 1043.69 | U17: 1390.19 | V17: 5584.74 | Y17: 7099.52 | Z17: 1719.62 | AB17: =124.61+1520.73+979.16+4813.57 -> 7438.07 | AC17: 5548.02 | AF17: 21412.4 | AG17: =121.77+2785.82 -> 2907.59 | AI17: =SUM(D17:AG17) -> 130844.35
C18: TOTAL DAS ENTRADAS | D18: =SUM(D7:D17) -> 85124.98 | E18: =SUM(E7:E17) -> 41147.85 | F18: =SUM(F7:F17) -> 33428.35 | G18: =SUM(G7:G17) -> 0 | H18: =SUM(H7:H17) -> 52521.16 | I18: =SUM(I7:I17) -> 0 | J18: =SUM(J7:J17) -> 0 | K18: =SUM(K7:K17) -> 83499.71 | ... AH18: =SUM(AH7:AH17) -> 0 | AI18: =SUM(D18:AG18) -> 1176193.9
C19: Repasse Salários e Encargos | H19: =6306.47 -> 6306.47 | AI19: =SUM(D19:AF19) -> 6306.47
B20: SAIDAS | C20: Repasse Aluguel de Salas e Equipamentos | AI20: =SUM(D20:AG20) -> 0
C21: Repasse A&B | F21: =4555.68 -> 4555.68 | R21: =(354.8+48985.77+43530+591.8+947.76)-192.05 -> 94218.08 | Y21: 22087.8 | AF21: =39525.7+565.95+1738 -> 41829.65 | AG21: 70857.87 | AI21: =SUM(D21:AG21) -> 233549.08
C22: Repasse Telefonia | AI22: =SUM(D22:AG22) -> 0
C23: Repasse Internet | AI23: =SUM(D23:AG23) -> 0
C24: Repasse Diversos | AI24: =SUM(D24:AG24) -> 0
C25: Repasse ao Condomínio | D25: =-SUM(D19:D24) -> 0 | E25: =-SUM(E19:E24) -> 0 | F25: =-SUM(F19:F24) -> -4555.68 | G25: =-SUM(G19:G24) -> 0 | H25: =-SUM(H19:H24) -> -6306.47 | I25: =-SUM(I19:I24) -> 0 | J25: =-SUM(J19:J24) -> 0 | K25: =-SUM(K19:K24) -> 0 | ... AI25: =-SUM(AI19:AI24) -> -239855.55
C26: Impostos Lei 10.833 | AI26: =SUM(D26:AG26) -> 0
C27: IRRF | T27: =17.27+54.49+13.18+56.25+215.99 -> 357.18 | AI27: =SUM(D27:AG27) -> 357.18
C28: ISS a Recolher | M28: =44726.78 -> 44726.78 | AI28: =SUM(D28:AG28) -> 44726.78
C29: ISS Retido a Recolher | AI29: =SUM(D29:AG29) -> 0
C30: INSS Retido a Recolher | AI30: =SUM(D30:AG30) -> 0
C31: IPTU a Pagar | L31: 10954.19 | M31: =76.84+13381.47 -> 13458.31 | AI31: =SUM(D31:AG31) -> 24412.5
C32: PIS a Recolher | AB32: 4709.7 | AI32: =SUM(D32:AG32) -> 4709.7
C33: COFINS a Recolher | AB33: 21737.2 | AI33: =SUM(D33:AG33) -> 21737.2
C34: IRPJ a Recolher | AI34: =SUM(D34:AG34) -> 0
C35: CSLL a Recolher | AI35: =SUM(D35:AG35) -> 0
C36: Total de Impostos | D36: =-SUM(D26:D35) -> 0 | E36: =-SUM(E26:E35) -> 0 | F36: =-SUM(F26:F35) -> 0 | G36: =-SUM(G26:G35) -> 0 | H36: =-SUM(H26:H35) -> 0 | I36: =-SUM(I26:I35) -> 0 | J36: =-SUM(J26:J35) -> 0 | K36: =-SUM(K26:K35) -> 0 | ... AI36: =-SUM(AI26:AI35) -> -95943.36
C37: Água e Esgoto | AI37: =SUM(D37:AG37) -> 0
C38: Energia Elétrica | H38: 23107.33 | K38: 14.62 | AI38: =SUM(D38:AG38) -> 23121.95
C39: Telefone | AI39: =SUM(D39:AG39) -> 0
C40: Total de Contas de Consumo | D40: =-SUM(D37:D39) -> 0 | E40: =-SUM(E37:E39) -> 0 | F40: =-SUM(F37:F39) -> 0 | G40: =-SUM(G37:G39) -> 0 | H40: =-SUM(H37:H39) -> -23107.33 | I40: =-SUM(I37:I39) -> 0 | J40: =-SUM(J37:J39) -> 0 | K40: =-SUM(K37:K39) -> -14.62 | ... AI40: =-SUM(AI37:AI39) -> -23121.95
C41: Adiantamento Dividendos | V41: =214905.18-14377.38 -> 200527.8 | Y41: =22062.62+14377.38 -> 36440 | AI41: =SUM(D41:AG41) -> 236967.8
C42: Fundo de Reserva | AI42: =SUM(D42:AF42) -> 0
...

Sheet Julho
B2: Fluxo de Caixa de Julho de 2015
B4: ÍTEM / DESCRIÇÃO | D4: Realizado | E4: Realizado | F4: Realizado | G4: PREVISTO | H4: PREVISTO | I4: Realizado | J4: Realizado | K4: Realizado | L4: Realizado | M4: Realizado | N4: PREVISTO | O4: PREVISTO | P4: Realizado | Q4: Realizado | R4: Realizado | S4: Realizado | T4: Realizado | U4: PREVISTO | V4: PREVISTO | W4: Realizado | X4: Realizado | Y4: Realizado | Z4: Realizado | AA4: Realizado | AB4: PREVISTO | AC4: PREVISTO | AD4: Realizado | AE4: Realizado | AF4: Realizado | AG4: Realizado | AH4: Realizado
D5: 42186 | E5: =D5+1 -> 42187 | F5: =E5+1 -> 42188 | G5: =F5+1 -> 42189 | H5: =G5+1 -> 42190 | I5: =H5+1 -> 42191 | J5: =I5+1 -> 42192 | K5: =J5+1 -> 42193 | L5: =K5+1 -> 42194 | ... AH5: =AG5+1 -> 42216 | AI5: ACUMULADO
C6: SALDO ANTERIOR DA CONTA CORRENTE | D6: =Junho!AG77 -> 118497.17 | E6: =D77 -> 154858.27 | F6: =E77 -> 163119.87 | G6: =F77 -> 171165.14 | H6: =G77 -> 171165.14 | I6: =H77 -> 171165.14 | J6: =I77 -> 200277.03 | K6: =J77 -> 237625.77 | L6: =K77 -> 310121.76 | ... AH6: =AG77 -> 86930.679 | AI6: =D6 -> 118497.17
B7: ENTRADAS | C7: Adiantamento de Clientes | D7: =404.7+441 -> 845.7 | F7: 294 | I7: =271.76+1980 -> 2251.76 | J7: 172 | K7: =299.25+1120+460 -> 1879.25 | L7: =58.65+850.5 -> 909.15 | M7: =56+263 -> 319 | P7: =1006.95 -> 1006.95 | Q7: =266+588 -> 854 | R7: =588+2500+315 -> 3403 | T7: =12848+507 -> 13355 | W7: =4215.98+220.5 -> 4436.48 | AA7: =873.6+35+882 -> 1790.6 | AD7: =250 -> 250 | AE7: =588 -> 588 | AF7: =23.1 -> 23.1 | AG7: =1500+346+487.3 -> 2333.3 | AH7: =262.5+960+262.5 -> 1485 | AI7: =SUM(D7:AH7) -> 36196.29
C8: Depósito RDS | M8: =152.95+249.96+403+460.85+634.93+1063.3+2219.05 -> 5184.04 | AD8: =102.3+133.85+137.36+203.61+244.13+383.15+418.2+432.2+785.4+985.7+993.74+1066.17+1126+1144.85+2314.5 -> 10471.16 | AH8: =495.39+649.39+743+873.69+966.23+1065.8+2091.85+2763.1 -> 9648.45 | AI8: =SUM(D8:AH8) -> 25303.65
C9: Crédito Não Identificado | AI9: =SUM(D9:AH9) -> 0
C10: Fundo de Reserva | AI10: =SUM(D10:AH10) -> 0
C11: Faturas | D11: =23428.95+309.75+288.75 -> 24027.45 | E11: =3881.85+1470+299.25+1164.98+668.34+2199.12+6762 -> 16445.54 | F11: =13573.55+267.75+798+1307.54 -> 15946.84 | I11: =294+273+927.08+294+4319.38+306.95 -> 6414.41 | J11: =18381.93+1681.59+220.5 -> 20284.02 | K11: =3411.31+7818.85+588+1249.6+799.7+3929.87+3105.77+1030+1424+11396.99+900.88+220.5+676.2+4678.68+2090 -> 43320.35 | L11: 16338.98 | M11: =2118+4267.2+1764+876.75+2380.12+4899.77+2791.75+267.75+162.52 -> 19527.86 | P11: =36315.15+294+522.5+532+743.6+1431.72 -> 39838.97 | Q11: =39652.86+120+985.6+307.65+532+1239+2461.8 -> 45298.91 | R11: =15954.02+1321.5+531.05 -> 17806.57 | T11: =2728.32+3140.7+882+3897.6+2662.8+1500+9032.24+1533.95+4359.98+713+288.75 -> 30739.34 | W11: =2491.5 -> 2491.5 | X11: =44925.98+294+294+474.04 -> 45988.02 | Y11: =2951.98+7879.2+234.68 -> 11065.86 | Z11: =2156.4+299.25+474.9+1606.5+525+546+1575+220.5+1420.02 -> 8823.57 | AA11: =6910.6+3483.9+1220.1 -> 11614.6 | AD11: =7195.6+1293.5+588+294+535.5+7029.48+646.8 -> 17582.88 | AE11: =20104.35+882+1640.15+263+2047.5+769.5+940.5 -> 26647 | AF11: =3911.95+532+1327.2+3675+2000+1254+211.68+646.8+211.68+862.4+679.14 -> 15311.85 | AG11: =4887+194.25+3034.5+661.5+1675.82 -> 10453.07 | AH11: =18646.25+294+588+3209.85+2583+1764+819+770.7+1050+1478.88 -> 31203.68 | AI11: =SUM(D11:AH11) -> 477171.27
C12: Receitas Diversas | D12: 3.03 | E12: 3.86 | F12: 3.38 | I12: 3.9 | J12: 4.66 | K12: 5.97 | M12: 13.11 | P12: 7.36 | Q12: 8.66 | R12: 14.19 | T12: 7.94 | W12: 2.34 | X12: 3.4 | Y12: 4.1 | Z12: 3.35 | AA12: 3.67 | AD12: 5.19 | AE12: 5.85 | AF12: 1.08 | AG12: 1.65 | AH12: 0.21 | AI12: =SUM(D12:AH12) -> 106.9
C13: Amex | D13: 883.74 | E13: 2082.69 | F13: 277.24 | I13: 5372.65 | J13: 1724.6 | K13: 3367 | M13: 4703.83 | P13: 3558.87 | Q13: 6490.5 | R13: 2368.38 | T13: =1870.08+2333.18 -> 4203.26 | W13: 5033.72 | X13: 1704.02 | Y13: 5152.64 | Z13: 1331.34 | AA13: 866.21 | AD13: 4173.32 | AE13: 1670.92 | AF13: 7763.46 | AG13: 1689.98 | AH13: =343.99+2747.59 -> 3091.58 | AI13: =SUM(D13:AH13) -> 67509.95
C14: Visa Electron | D14: 852.17 | E14: 24.73 | F14: 2543.65 | I14: 4198.08 | J14: 2991.24 | K14: 1683.84 | L14: 205.37 | M14: 734.42 | P14: 2480.23 | Q14: 1931.54 | R14: 872.48 | T14: =769.55+844.91 -> 1614.46 | W14: 7106.81 | X14: 1817.23 | Y14: 316.33 | Z14: 1112.44 | AA14: 525.73 | AD14: 4330.49 | AE14: 1394.58 | AF14: 428.35 | AG14: 1558.34 | AH14: =170.82 -> 170.82 | AI14: =SUM(D14:AH14) -> 38893.33
C15: Master Débito | D15: 370.11 | E15: 104.1 | F15: 195.06 | I15: =296.71+2578.09+714.71 -> 3589.51 | J15: =458.02+245.8 -> 703.82 | K15: 3466.1 | L15: 1466.41 | M15: 367.46 | P15: =4576.37+183.78 -> 4760.15 | Q15: 448.9 | R15: 687.77 | T15: =58.77+701.1 -> 759.87 | W15: =1080+172.89 -> 1252.89 | X15: 633.95 | Y15: 147.19 | Z15: 292.01 | AA15: =1447.47+13.74 -> 1461.21 | AD15: =4601.23+217.34 -> 4818.57 | AE15: =1208.64+400.58 -> 1609.22 | AF15: 1135.24 | AG15: 285.14 | AH15: =908.6+430.67 -> 1339.27 | AI15: =SUM(D15:AH15) -> 29893.95
C16: Visa Crédito | D16: 14584.89 | E16: 5592.81 | F16: 16056.89 | I16: 42035.83 | J16: 10157.99 | K16: 16108.86 | L16: 8281.59 | M16: 11506.61 | P16: 32562.39 | Q16: =3671 -> 3671 | R16: 12248.18 | T16: =9284.31+9861.15 -> 19145.46 | W16: 20515.64 | X16: 3769.6 | Y16: 15580.14 | Z16: 5189.79 | AA16: 3072.15 | AD16: 30734.53 | AE16: 5430.75 | AF16: 14061.16 | AG16: 11540.52 | AH16: 11163.04 | AI16: =SUM(D16:AH16) -> 313009.82
C17: Master Crédito | D17: 3781.44 | E17: 3415.27 | F17: =266.84+1281.3 -> 1548.14 | I17: 17949.76 | J17: 1434.19 | K17: 4005.4 | L17: 7122.8 | M17: 2047.23 | P17: =11902.91+119.61 -> 12022.52 | Q17: 3629.22 | R17: 2563.1 | T17: =2488.13+3519.94 -> 6008.07 | W17: =11651+457.56 -> 12108.56 | X17: 1144.06 | Y17: 1820.24 | Z17: 1722.6 | AA17: 3039.41 | AD17: 20377.01 | AE17: 1031.14 | AF17: 844.84 | AG17: 4606.07 | AH17: =3444.97 -> 3444.97 | AI17: =SUM(D17:AH17) -> 115666.04
C18: TOTAL DAS ENTRADAS | D18: =SUM(D7:D17) -> 45348.53 | E18: =SUM(E7:E17) -> 27669 | F18: =SUM(F7:F17) -> 36865.2 | G18: =SUM(G7:G17) -> 0 | H18: =SUM(H7:H17) -> 0 | I18: =SUM(I7:I17) -> 81815.9 | J18: =SUM(J7:J17) -> 37472.52 | K18: =SUM(K7:K17) -> 73836.77 | ... AH18: =SUM(AH7:AH17) -> 61547.02 | AI18: =SUM(D18:AH18) -> 1103751.2
C19: Repasse Salários e Encargos | W19: =4750+42000 -> 46750 | Z19: 20000 | AD19: 16500 | AF19: 25500 | AH19: 13100 | AI19: =SUM(D19:AH19) -> 121850
B20: SAIDAS | C20: Repasse Aluguel de Salas e Equipamentos | AI20: =SUM(D20:AH20) -> 0
C21: Repasse A&B | R21: =(35042.5+1435.36+79.2)-(830.5+130+237.5) -> 35359.06 | W21: 47812.29 | AH21: =(60901.96+39254)-391.8 -> 99764.16 | AI21: =SUM(D21:AH21) -> 182935.51
C22: Repasse Telefonia | AI22: =SUM(D22:AH22) -> 0
C23: Repasse Internet | AI23: =SUM(D23:AH23) -> 0
C24: Repasse Diversos | AI24: =SUM(D24:AH24) -> 0
C25: Repasse ao Condomínio | D25: =-SUM(D19:D24) -> 0 | E25: =-SUM(E19:E24) -> 0 | F25: =-SUM(F19:F24) -> 0 | G25: =-SUM(G19:G24) -> 0 | H25: =-SUM(H19:H24) -> 0 | I25: =-SUM(I19:I24) -> 0 | J25: =-SUM(J19:J24) -> 0 | K25: =-SUM(K19:K24) -> 0 | ... AI25: =-SUM(AI19:AI24) -> -304785.51
C26: Impostos Lei 10.833 | AI26: =SUM(D26:AH26) -> 0
C27: IRRF | T27: =25.8+78.8+56.25+221.05 -> 381.9 | AI27: =SUM(D27:AH27) -> 381.9
C28: ISS a Recolher | AI28: =SUM(D28:AH28) -> 0
C29: ISS Retido a Recolher | M29: 37530.84 | AI29: =SUM(D29:AH29) -> 37530.84
C30: INSS Retido a Recolher | AI30: =SUM(D30:AH30) -> 0
C31: IPTU a Pagar | M31: =13445.45+10481.58 -> 23927.03 | AI31: =SUM(D31:AH31) -> 23927.03
C32: PIS a Recolher | Z32: 5717.52 | AI32: =SUM(D32:AH32) -> 5717.52
C33: COFINS a Recolher | Z33: 26424.54 | AI33: =SUM(D33:AH33) -> 26424.54
C34: IRPJ a Recolher | AF34: 171979.91 | AI34: =SUM(D34:AH34) -> 171979.91
C35: CSLL a Recolher | AF35: 76650.27 | AI35: =SUM(D35:AH35) -> 76650.27
C36: Total de Impostos | D36: =-SUM(D26:D35) -> 0 | E36: =-SUM(E26:E35) -> 0 | F36: =-SUM(F26:F35) -> 0 | G36: =-SUM(G26:G35) -> 0 | H36: =-SUM(H26:H35) -> 0 | I36: =-SUM(I26:I35) -> 0 | J36: =-SUM(J26:J35) -> 0 | K36: =-SUM(K26:K35) -> 0 | ... AI36: =-SUM(AI26:AI35) -> -342612.01
C37: Água e Esgoto | AI37: =SUM(D37:AH37) -> 0
C38: Energia Elétrica | E38: 19304.6 | M38: 46.55 | AH38: 16112.16 | AI38: =SUM(D38:AH38) -> 35463.31
C39: Telefone | AI39: =SUM(D39:AH39) -> 0
