Workbook

Sheet Início
A1: GERENCIAMENTO DE COMPRAS - INÍCIO

Sheet Cadastramento
A1: GERENCIAMENTO DE COMPRAS - CADASTRAMENTO
B5: Materiais | D5: Fornecedores
B6: Relação de Materiais | D6: Nome | E6: Telefone | F6: e-mail | G6: Materiais

Sheet Compras
A1: GERENCIAMENTO DE COMPRAS - COMPRAS
C4: Materiais
C5: =Cadastramento!B7 -> 0 | D5: =Cadastramento!B8 -> 0 | E5: =Cadastramento!B9 -> 0 | F5: =Cadastramento!B10 -> 0 | G5: =Cadastramento!B11 -> 0 | H5: =Cadastramento!B12 -> 0 | I5: =Cadastramento!B13 -> 0 | J5: =Cadastramento!B14 -> 0 | K5: =Cadastramento!B15 -> 0 | L5: =Cadastramento!B16 -> 0 | M5: =Cadastramento!B17 -> 0 | N5: =Cadastramento!B18 -> 0 | O5: =Cadastramento!B19 -> 0 | P5: =Cadastramento!B20 -> 0 | Q5: =Cadastramento!B21 -> 0 | R5: =Cadastramento!B22 -> 0 | S5: =Cadastramento!B23 -> 0 | T5: =Cadastramento!B24 -> 0 | U5: =Cadastramento!B25 -> 0 | V5: =Cadastramento!B26 -> 0
A6: Janeiro | B6: Fornecedor
B7: Quantidade
B8: Preço
B9: Total | C9: =C8*C7 -> 0 | D9: =D8*D7 -> 0 | E9: =E8*E7 -> 0 | F9: =F8*F7 -> 0 | G9: =G8*G7 -> 0 | H9: =H8*H7 -> 0 | I9: =I8*I7 -> 0 | J9: =J8*J7 -> 0 | ... V9: =V8*V7 -> 0
A10: Fevereiro | B10: Fornecedor
B11: Quantidade
B12: Preço
B13: Total | C13: =C12*C11 -> 0 | D13: =D12*D11 -> 0 | E13: =E12*E11 -> 0 | F13: =F12*F11 -> 0 | G13: =G12*G11 -> 0 | H13: =H12*H11 -> 0 | I13: =I12*I11 -> 0 | J13: =J12*J11 -> 0 | ... V13: =V12*V11 -> 0
A14: Março | B14: Fornecedor
B15: Quantidade
B16: Preço
B17: Total | C17: =C16*C15 -> 0 | D17: =D16*D15 -> 0 | E17: =E16*E15 -> 0 | F17: =F16*F15 -> 0 | G17: =G16*G15 -> 0 | H17: =H16*H15 -> 0 | I17: =I16*I15 -> 0 | J17: =J16*J15 -> 0 | ... V17: =V16*V15 -> 0
A18: Abril | B18: Fornecedor
B19: Quantidade
B20: Preço
B21: Total | C21: =C20*C19 -> 0 | D21: =D20*D19 -> 0 | E21: =E20*E19 -> 0 | F21: =F20*F19 -> 0 | G21: =G20*G19 -> 0 | H21: =H20*H19 -> 0 | I21: =I20*I19 -> 0 | J21: =J20*J19 -> 0 | ... V21: =V20*V19 -> 0
A22: Maio | B22: Fornecedor
B23: Quantidade
B24: Preço
B25: Total | C25: =C24*C23 -> 0 | D25: =D24*D23 -> 0 | E25: =E24*E23 -> 0 | F25: =F24*F23 -> 0 | G25: =G24*G23 -> 0 | H25: =H24*H23 -> 0 | I25: =I24*I23 -> 0 | J25: =J24*J23 -> 0 | ... V25: =V24*V23 -> 0
A26: Junho | B26: Fornecedor
B27: Quantidade
B28: Preço
B29: Total | C29: =C28*C27 -> 0 | D29: =D28*D27 -> 0 | E29: =E28*E27 -> 0 | F29: =F28*F27 -> 0 | G29: =G28*G27 -> 0 | H29: =H28*H27 -> 0 | I29: =I28*I27 -> 0 | J29: =J28*J27 -> 0 | ... V29: =V28*V27 -> 0
A30: Julho | B30: Fornecedor
B31: Quantidade
B32: Preço
B33: Total | C33: =C32*C31 -> 0 | D33: =D32*D31 -> 0 | E33: =E32*E31 -> 0 | F33: =F32*F31 -> 0 | G33: =G32*G31 -> 0 | H33: =H32*H31 -> 0 | I33: =I32*I31 -> 0 | J33: =J32*J31 -> 0 | ... V33: =V32*V31 -> 0
A34: Agosto | B34: Fornecedor
B35: Quantidade
B36: Preço
B37: Total | C37: =C36*C35 -> 0 | D37: =D36*D35 -> 0 | E37: =E36*E35 -> 0 | F37: =F36*F35 -> 0 | G37: =G36*G35 -> 0 | H37: =H36*H35 -> 0 | I37: =I36*I35 -> 0 | J37: =J36*J35 -> 0 | ... V37: =V36*V35 -> 0
A38: Setembro | B38: Fornecedor
B39: Quantidade
B40: Preço
B41: Total | C41: =C40*C39 -> 0 | D41: =D40*D39 -> 0 | E41: =E40*E39 -> 0 | F41: =F40*F39 -> 0 | G41: =G40*G39 -> 0 | H41: =H40*H39 -> 0 | I41: =I40*I39 -> 0 | J41: =J40*J39 -> 0 | ... V41: =V40*V39 -> 0
A42: Outubro | B42: Fornecedor
...

Sheet Referências de Cálculo
B1: Gasto Por Mês | F1: Gasto por Fornecedor
B2: Janeiro | C2: =SUM(Compras!C9:V9) -> 0 | F2: =Cadastramento!D7 -> 0 | G2: =SUM(SUMIF(Compras!$C$6:$V$6,F2,Compras!$C$9:$V$9),SUMIF(Compras!$C$10:$V$10,F2,Compras!$C$13:$V$13),SUMIF(Compras!C14:V14,F2,Compras!$C$17:$V$17),SUMIF(Compras!$C$18:$V$18,F2,Compras!$C$21:$V$21),SUMIF(Compras!$C$22:$V$22,F2,Compras!$C$25:$V$25),SUMIF(Compras!$C$26:$V$26,F2,Compras!$C$29:$V$29),SUMIF(Compras!$C$30:$V$30,F2,Compras!$C$33:$V$33),SUMIF(Compras!$C$34:$V$34,F2,Compras!$C$37:$V$37),SUMIF(Compras!$C$38:$V$38,F2,Compras!$C$41:$V$41),SUMIF(Compras!$C$42:$V$42,F2,Compras!$C$45:$V$45),SUMIF(Compras!$C$46:$V$46,F2,Compras!$C$49:$V$49),SUMIF(Compras!$C$50:$V$50,F2,Compras!$C$53:$V$53),) -> 0
B3: Fevereiro | C3: =SUM(Compras!C13:V13) -> 0 | F3: =Cadastramento!D8 -> 0 | G3: =SUM(SUMIF(Compras!$C$6:$V$6,F3,Compras!$C$9:$V$9),SUMIF(Compras!$C$10:$V$10,F3,Compras!$C$13:$V$13),SUMIF(Compras!C15:V15,F3,Compras!$C$17:$V$17),SUMIF(Compras!$C$18:$V$18,F3,Compras!$C$21:$V$21),SUMIF(Compras!$C$22:$V$22,F3,Compras!$C$25:$V$25),SUMIF(Compras!$C$26:$V$26,F3,Compras!$C$29:$V$29),SUMIF(Compras!$C$30:$V$30,F3,Compras!$C$33:$V$33),SUMIF(Compras!$C$34:$V$34,F3,Compras!$C$37:$V$37),SUMIF(Compras!$C$38:$V$38,F3,Compras!$C$41:$V$41),SUMIF(Compras!$C$42:$V$42,F3,Compras!$C$45:$V$45),SUMIF(Compras!$C$46:$V$46,F3,Compras!$C$49:$V$49),SUMIF(Compras!$C$50:$V$50,F3,Compras!$C$53:$V$53),) -> 0
B4: Março | C4: =SUM(Compras!C17:V17) -> 0 | F4: =Cadastramento!D9 -> 0 | G4: =SUM(SUMIF(Compras!$C$6:$V$6,F4,Compras!$C$9:$V$9),SUMIF(Compras!$C$10:$V$10,F4,Compras!$C$13:$V$13),SUMIF(Compras!C17:V17,F4,Compras!$C$17:$V$17),SUMIF(Compras!$C$18:$V$18,F4,Compras!$C$21:$V$21),SUMIF(Compras!$C$22:$V$22,F4,Compras!$C$25:$V$25),SUMIF(Compras!$C$26:$V$26,F4,Compras!$C$29:$V$29),SUMIF(Compras!$C$30:$V$30,F4,Compras!$C$33:$V$33),SUMIF(Compras!$C$34:$V$34,F4,Compras!$C$37:$V$37),SUMIF(Compras!$C$38:$V$38,F4,Compras!$C$41:$V$41),SUMIF(Compras!$C$42:$V$42,F4,Compras!$C$45:$V$45),SUMIF(Compras!$C$46:$V$46,F4,Compras!$C$49:$V$49),SUMIF(Compras!$C$50:$V$50,F4,Compras!$C$53:$V$53),) -> 0
B5: Abril | C5: =SUM(Compras!C21:V21) -> 0 | F5: =Cadastramento!D10 -> 0 | G5: =SUM(SUMIF(Compras!$C$6:$V$6,F5,Compras!$C$9:$V$9),SUMIF(Compras!$C$10:$V$10,F5,Compras!$C$13:$V$13),SUMIF(Compras!C18:V18,F5,Compras!$C$17:$V$17),SUMIF(Compras!$C$18:$V$18,F5,Compras!$C$21:$V$21),SUMIF(Compras!$C$22:$V$22,F5,Compras!$C$25:$V$25),SUMIF(Compras!$C$26:$V$26,F5,Compras!$C$29:$V$29),SUMIF(Compras!$C$30:$V$30,F5,Compras!$C$33:$V$33),SUMIF(Compras!$C$34:$V$34,F5,Compras!$C$37:$V$37),SUMIF(Compras!$C$38:$V$38,F5,Compras!$C$41:$V$41),SUMIF(Compras!$C$42:$V$42,F5,Compras!$C$45:$V$45),SUMIF(Compras!$C$46:$V$46,F5,Compras!$C$49:$V$49),SUMIF(Compras!$C$50:$V$50,F5,Compras!$C$53:$V$53),) -> 0
B6: Maio | C6: =SUM(Compras!C25:V25) -> 0 | F6: =Cadastramento!D11 -> 0 | G6: =SUM(SUMIF(Compras!$C$6:$V$6,F6,Compras!$C$9:$V$9),SUMIF(Compras!$C$10:$V$10,F6,Compras!$C$13:$V$13),SUMIF(Compras!C19:V19,F6,Compras!$C$17:$V$17),SUMIF(Compras!$C$18:$V$18,F6,Compras!$C$21:$V$21),SUMIF(Compras!$C$22:$V$22,F6,Compras!$C$25:$V$25),SUMIF(Compras!$C$26:$V$26,F6,Compras!$C$29:$V$29),SUMIF(Compras!$C$30:$V$30,F6,Compras!$C$33:$V$33),SUMIF(Compras!$C$34:$V$34,F6,Compras!$C$37:$V$37),SUMIF(Compras!$C$38:$V$38,F6,Compras!$C$41:$V$41),SUMIF(Compras!$C$42:$V$42,F6,Compras!$C$45:$V$45),SUMIF(Compras!$C$46:$V$46,F6,Compras!$C$49:$V$49),SUMIF(Compras!$C$50:$V$50,F6,Compras!$C$53:$V$53),) -> 0
B7: Junho | C7: =SUM(Compras!C29:V29) -> 0 | F7: =Cadastramento!D12 -> 0 | G7: =SUM(SUMIF(Compras!$C$6:$V$6,F7,Compras!$C$9:$V$9),SUMIF(Compras!$C$10:$V$10,F7,Compras!$C$13:$V$13),SUMIF(Compras!C21:V21,F7,Compras!$C$17:$V$17),SUMIF(Compras!$C$18:$V$18,F7,Compras!$C$21:$V$21),SUMIF(Compras!$C$22:$V$22,F7,Compras!$C$25:$V$25),SUMIF(Compras!$C$26:$V$26,F7,Compras!$C$29:$V$29),SUMIF(Compras!$C$30:$V$30,F7,Compras!$C$33:$V$33),SUMIF(Compras!$C$34:$V$34,F7,Compras!$C$37:$V$37),SUMIF(Compras!$C$38:$V$38,F7,Compras!$C$41:$V$41),SUMIF(Compras!$C$42:$V$42,F7,Compras!$C$45:$V$45),SUMIF(Compras!$C$46:$V$46,F7,Compras!$C$49:$V$49),SUMIF(Compras!$C$50:$V$50,F7,Compras!$C$53:$V$53),) -> 0
B8: Julho | C8: =SUM(Compras!C33:V33) -> 0 | F8: =Cadastramento!D13 -> 0 | G8: =SUM(SUMIF(Compras!$C$6:$V$6,F8,Compras!$C$9:$V$9),SUMIF(Compras!$C$10:$V$10,F8,Compras!$C$13:$V$13),SUMIF(Compras!C22:V22,F8,Compras!$C$17:$V$17),SUMIF(Compras!$C$18:$V$18,F8,Compras!$C$21:$V$21),SUMIF(Compras!$C$22:$V$22,F8,Compras!$C$25:$V$25),SUMIF(Compras!$C$26:$V$26,F8,Compras!$C$29:$V$29),SUMIF(Compras!$C$30:$V$30,F8,Compras!$C$33:$V$33),SUMIF(Compras!$C$34:$V$34,F8,Compras!$C$37:$V$37),SUMIF(Compras!$C$38:$V$38,F8,Compras!$C$41:$V$41),SUMIF(Compras!$C$42:$V$42,F8,Compras!$C$45:$V$45),SUMIF(Compras!$C$46:$V$46,F8,Compras!$C$49:$V$49),SUMIF(Compras!$C$50:$V$50,F8,Compras!$C$53:$V$53),) -> 0
B9: Agosto | C9: =SUM(Compras!C37:V37) -> 0 | F9: =Cadastramento!D14 -> 0 | G9: =SUM(SUMIF(Compras!$C$6:$V$6,F9,Compras!$C$9:$V$9),SUMIF(Compras!$C$10:$V$10,F9,Compras!$C$13:$V$13),SUMIF(Compras!C23:V23,F9,Compras!$C$17:$V$17),SUMIF(Compras!$C$18:$V$18,F9,Compras!$C$21:$V$21),SUMIF(Compras!$C$22:$V$22,F9,Compras!$C$25:$V$25),SUMIF(Compras!$C$26:$V$26,F9,Compras!$C$29:$V$29),SUMIF(Compras!$C$30:$V$30,F9,Compras!$C$33:$V$33),SUMIF(Compras!$C$34:$V$34,F9,Compras!$C$37:$V$37),SUMIF(Compras!$C$38:$V$38,F9,Compras!$C$41:$V$41),SUMIF(Compras!$C$42:$V$42,F9,Compras!$C$45:$V$45),SUMIF(Compras!$C$46:$V$46,F9,Compras!$C$49:$V$49),SUMIF(Compras!$C$50:$V$50,F9,Compras!$C$53:$V$53),) -> 0
B10: Setembro | C10: =SUM(Compras!C41:V41) -> 0 | F10: =Cadastramento!D15 -> 0 | G10: =SUM(SUMIF(Compras!$C$6:$V$6,F10,Compras!$C$9:$V$9),SUMIF(Compras!$C$10:$V$10,F10,Compras!$C$13:$V$13),SUMIF(Compras!C25:V25,F10,Compras!$C$17:$V$17),SUMIF(Compras!$C$18:$V$18,F10,Compras!$C$21:$V$21),SUMIF(Compras!$C$22:$V$22,F10,Compras!$C$25:$V$25),SUMIF(Compras!$C$26:$V$26,F10,Compras!$C$29:$V$29),SUMIF(Compras!$C$30:$V$30,F10,Compras!$C$33:$V$33),SUMIF(Compras!$C$34:$V$34,F10,Compras!$C$37:$V$37),SUMIF(Compras!$C$38:$V$38,F10,Compras!$C$41:$V$41),SUMIF(Compras!$C$42:$V$42,F10,Compras!$C$45:$V$45),SUMIF(Compras!$C$46:$V$46,F10,Compras!$C$49:$V$49),SUMIF(Compras!$C$50:$V$50,F10,Compras!$C$53:$V$53),) -> 0
B11: Outubro | C11: =SUM(Compras!C45:V45) -> 0 | F11: =Cadastramento!D16 -> 0 | G11: =SUM(SUMIF(Compras!$C$6:$V$6,F11,Compras!$C$9:$V$9),SUMIF(Compras!$C$10:$V$10,F11,Compras!$C$13:$V$13),SUMIF(Compras!C26:V26,F11,Compras!$C$17:$V$17),SUMIF(Compras!$C$18:$V$18,F11,Compras!$C$21:$V$21),SUMIF(Compras!$C$22:$V$22,F11,Compras!$C$25:$V$25),SUMIF(Compras!$C$26:$V$26,F11,Compras!$C$29:$V$29),SUMIF(Compras!$C$30:$V$30,F11,Compras!$C$33:$V$33),SUMIF(Compras!$C$34:$V$34,F11,Compras!$C$37:$V$37),SUMIF(Compras!$C$38:$V$38,F11,Compras!$C$41:$V$41),SUMIF(Compras!$C$42:$V$42,F11,Compras!$C$45:$V$45),SUMIF(Compras!$C$46:$V$46,F11,Compras!$C$49:$V$49),SUMIF(Compras!$C$50:$V$50,F11,Compras!$C$53:$V$53),) -> 0
B12: Novembro | C12: =SUM(Compras!C49:V49) -> 0 | F12: =Cadastramento!D17 -> 0 | G12: =SUM(SUMIF(Compras!$C$6:$V$6,F12,Compras!$C$9:$V$9),SUMIF(Compras!$C$10:$V$10,F12,Compras!$C$13:$V$13),SUMIF(Compras!C27:V27,F12,Compras!$C$17:$V$17),SUMIF(Compras!$C$18:$V$18,F12,Compras!$C$21:$V$21),SUMIF(Compras!$C$22:$V$22,F12,Compras!$C$25:$V$25),SUMIF(Compras!$C$26:$V$26,F12,Compras!$C$29:$V$29),SUMIF(Compras!$C$30:$V$30,F12,Compras!$C$33:$V$33),SUMIF(Compras!$C$34:$V$34,F12,Compras!$C$37:$V$37),SUMIF(Compras!$C$38:$V$38,F12,Compras!$C$41:$V$41),SUMIF(Compras!$C$42:$V$42,F12,Compras!$C$45:$V$45),SUMIF(Compras!$C$46:$V$46,F12,Compras!$C$49:$V$49),SUMIF(Compras!$C$50:$V$50,F12,Compras!$C$53:$V$53),) -> 0
B13: Dezembro | C13: =SUM(Compras!C53:V53) -> 0 | F13: =Cadastramento!D18 -> 0 | G13: =SUM(SUMIF(Compras!$C$6:$V$6,F13,Compras!$C$9:$V$9),SUMIF(Compras!$C$10:$V$10,F13,Compras!$C$13:$V$13),SUMIF(Compras!C29:V29,F13,Compras!$C$17:$V$17),SUMIF(Compras!$C$18:$V$18,F13,Compras!$C$21:$V$21),SUMIF(Compras!$C$22:$V$22,F13,Compras!$C$25:$V$25),SUMIF(Compras!$C$26:$V$26,F13,Compras!$C$29:$V$29),SUMIF(Compras!$C$30:$V$30,F13,Compras!$C$33:$V$33),SUMIF(Compras!$C$34:$V$34,F13,Compras!$C$37:$V$37),SUMIF(Compras!$C$38:$V$38,F13,Compras!$C$41:$V$41),SUMIF(Compras!$C$42:$V$42,F13,Compras!$C$45:$V$45),SUMIF(Compras!$C$46:$V$46,F13,Compras!$C$49:$V$49),SUMIF(Compras!$C$50:$V$50,F13,Compras!$C$53:$V$53),) -> 0
B14: Total | C14: =SUM(C2:C13) -> 0 | F14: =Cadastramento!D19 -> 0 | G14: =SUM(SUMIF(Compras!$C$6:$V$6,F14,Compras!$C$9:$V$9),SUMIF(Compras!$C$10:$V$10,F14,Compras!$C$13:$V$13),SUMIF(Compras!C30:V30,F14,Compras!$C$17:$V$17),SUMIF(Compras!$C$18:$V$18,F14,Compras!$C$21:$V$21),SUMIF(Compras!$C$22:$V$22,F14,Compras!$C$25:$V$25),SUMIF(Compras!$C$26:$V$26,F14,Compras!$C$29:$V$29),SUMIF(Compras!$C$30:$V$30,F14,Compras!$C$33:$V$33),SUMIF(Compras!$C$34:$V$34,F14,Compras!$C$37:$V$37),SUMIF(Compras!$C$38:$V$38,F14,Compras!$C$41:$V$41),SUMIF(Compras!$C$42:$V$42,F14,Compras!$C$45:$V$45),SUMIF(Compras!$C$46:$V$46,F14,Compras!$C$49:$V$49),SUMIF(Compras!$C$50:$V$50,F14,Compras!$C$53:$V$53),) -> 0
F15: =Cadastramento!D20 -> 0 | G15: =SUM(SUMIF(Compras!$C$6:$V$6,F15,Compras!$C$9:$V$9),SUMIF(Compras!$C$10:$V$10,F15,Compras!$C$13:$V$13),SUMIF(Compras!C31:V31,F15,Compras!$C$17:$V$17),SUMIF(Compras!$C$18:$V$18,F15,Compras!$C$21:$V$21),SUMIF(Compras!$C$22:$V$22,F15,Compras!$C$25:$V$25),SUMIF(Compras!$C$26:$V$26,F15,Compras!$C$29:$V$29),SUMIF(Compras!$C$30:$V$30,F15,Compras!$C$33:$V$33),SUMIF(Compras!$C$34:$V$34,F15,Compras!$C$37:$V$37),SUMIF(Compras!$C$38:$V$38,F15,Compras!$C$41:$V$41),SUMIF(Compras!$C$42:$V$42,F15,Compras!$C$45:$V$45),SUMIF(Compras!$C$46:$V$46,F15,Compras!$C$49:$V$49),SUMIF(Compras!$C$50:$V$50,F15,Compras!$C$53:$V$53),) -> 0
F16: =Cadastramento!D21 -> 0 | G16: =SUM(SUMIF(Compras!$C$6:$V$6,F16,Compras!$C$9:$V$9),SUMIF(Compras!$C$10:$V$10,F16,Compras!$C$13:$V$13),SUMIF(Compras!C33:V33,F16,Compras!$C$17:$V$17),SUMIF(Compras!$C$18:$V$18,F16,Compras!$C$21:$V$21),SUMIF(Compras!$C$22:$V$22,F16,Compras!$C$25:$V$25),SUMIF(Compras!$C$26:$V$26,F16,Compras!$C$29:$V$29),SUMIF(Compras!$C$30:$V$30,F16,Compras!$C$33:$V$33),SUMIF(Compras!$C$34:$V$34,F16,Compras!$C$37:$V$37),SUMIF(Compras!$C$38:$V$38,F16,Compras!$C$41:$V$41),SUMIF(Compras!$C$42:$V$42,F16,Compras!$C$45:$V$45),SUMIF(Compras!$C$46:$V$46,F16,Compras!$C$49:$V$49),SUMIF(Compras!$C$50:$V$50,F16,Compras!$C$53:$V$53),) -> 0
F17: =Cadastramento!D22 -> 0 | G17: =SUM(SUMIF(Compras!$C$6:$V$6,F17,Compras!$C$9:$V$9),SUMIF(Compras!$C$10:$V$10,F17,Compras!$C$13:$V$13),SUMIF(Compras!C34:V34,F17,Compras!$C$17:$V$17),SUMIF(Compras!$C$18:$V$18,F17,Compras!$C$21:$V$21),SUMIF(Compras!$C$22:$V$22,F17,Compras!$C$25:$V$25),SUMIF(Compras!$C$26:$V$26,F17,Compras!$C$29:$V$29),SUMIF(Compras!$C$30:$V$30,F17,Compras!$C$33:$V$33),SUMIF(Compras!$C$34:$V$34,F17,Compras!$C$37:$V$37),SUMIF(Compras!$C$38:$V$38,F17,Compras!$C$41:$V$41),SUMIF(Compras!$C$42:$V$42,F17,Compras!$C$45:$V$45),SUMIF(Compras!$C$46:$V$46,F17,Compras!$C$49:$V$49),SUMIF(Compras!$C$50:$V$50,F17,Compras!$C$53:$V$53),) -> 0
F18: =Cadastramento!D23 -> 0 | G18: =SUM(SUMIF(Compras!$C$6:$V$6,F18,Compras!$C$9:$V$9),SUMIF(Compras!$C$10:$V$10,F18,Compras!$C$13:$V$13),SUMIF(Compras!C35:V35,F18,Compras!$C$17:$V$17),SUMIF(Compras!$C$18:$V$18,F18,Compras!$C$21:$V$21),SUMIF(Compras!$C$22:$V$22,F18,Compras!$C$25:$V$25),SUMIF(Compras!$C$26:$V$26,F18,Compras!$C$29:$V$29),SUMIF(Compras!$C$30:$V$30,F18,Compras!$C$33:$V$33),SUMIF(Compras!$C$34:$V$34,F18,Compras!$C$37:$V$37),SUMIF(Compras!$C$38:$V$38,F18,Compras!$C$41:$V$41),SUMIF(Compras!$C$42:$V$42,F18,Compras!$C$45:$V$45),SUMIF(Compras!$C$46:$V$46,F18,Compras!$C$49:$V$49),SUMIF(Compras!$C$50:$V$50,F18,Compras!$C$53:$V$53),) -> 0
F19: =Cadastramento!D24 -> 0 | G19: =SUM(SUMIF(Compras!$C$6:$V$6,F19,Compras!$C$9:$V$9),SUMIF(Compras!$C$10:$V$10,F19,Compras!$C$13:$V$13),SUMIF(Compras!C37:V37,F19,Compras!$C$17:$V$17),SUMIF(Compras!$C$18:$V$18,F19,Compras!$C$21:$V$21),SUMIF(Compras!$C$22:$V$22,F19,Compras!$C$25:$V$25),SUMIF(Compras!$C$26:$V$26,F19,Compras!$C$29:$V$29),SUMIF(Compras!$C$30:$V$30,F19,Compras!$C$33:$V$33),SUMIF(Compras!$C$34:$V$34,F19,Compras!$C$37:$V$37),SUMIF(Compras!$C$38:$V$38,F19,Compras!$C$41:$V$41),SUMIF(Compras!$C$42:$V$42,F19,Compras!$C$45:$V$45),SUMIF(Compras!$C$46:$V$46,F19,Compras!$C$49:$V$49),SUMIF(Compras!$C$50:$V$50,F19,Compras!$C$53:$V$53),) -> 0
F20: =Cadastramento!D25 -> 0 | G20: =SUM(SUMIF(Compras!$C$6:$V$6,F20,Compras!$C$9:$V$9),SUMIF(Compras!$C$10:$V$10,F20,Compras!$C$13:$V$13),SUMIF(Compras!C38:V38,F20,Compras!$C$17:$V$17),SUMIF(Compras!$C$18:$V$18,F20,Compras!$C$21:$V$21),SUMIF(Compras!$C$22:$V$22,F20,Compras!$C$25:$V$25),SUMIF(Compras!$C$26:$V$26,F20,Compras!$C$29:$V$29),SUMIF(Compras!$C$30:$V$30,F20,Compras!$C$33:$V$33),SUMIF(Compras!$C$34:$V$34,F20,Compras!$C$37:$V$37),SUMIF(Compras!$C$38:$V$38,F20,Compras!$C$41:$V$41),SUMIF(Compras!$C$42:$V$42,F20,Compras!$C$45:$V$45),SUMIF(Compras!$C$46:$V$46,F20,Compras!$C$49:$V$49),SUMIF(Compras!$C$50:$V$50,F20,Compras!$C$53:$V$53),) -> 0
F21: =Cadastramento!D26 -> 0 | G21: =SUM(SUMIF(Compras!$C$6:$V$6,F21,Compras!$C$9:$V$9),SUMIF(Compras!$C$10:$V$10,F21,Compras!$C$13:$V$13),SUMIF(Compras!C39:V39,F21,Compras!$C$17:$V$17),SUMIF(Compras!$C$18:$V$18,F21,Compras!$C$21:$V$21),SUMIF(Compras!$C$22:$V$22,F21,Compras!$C$25:$V$25),SUMIF(Compras!$C$26:$V$26,F21,Compras!$C$29:$V$29),SUMIF(Compras!$C$30:$V$30,F21,Compras!$C$33:$V$33),SUMIF(Compras!$C$34:$V$34,F21,Compras!$C$37:$V$37),SUMIF(Compras!$C$38:$V$38,F21,Compras!$C$41:$V$41),SUMIF(Compras!$C$42:$V$42,F21,Compras!$C$45:$V$45),SUMIF(Compras!$C$46:$V$46,F21,Compras!$C$49:$V$49),SUMIF(Compras!$C$50:$V$50,F21,Compras!$C$53:$V$53),) -> 0
F22: Total | G22: =SUM(G2:G21) -> 0

Sheet Gráfico Mensal
A1: GERENCIAMENTO DE COMPRAS - GRÁFICO MENSAL

Sheet Gráfico por Fornecedor
A1: GERENCIAMENTO DE COMPRAS - GRÁFICO
