Workbook

Sheet RESCISÓRIAS
K4: ADMISSÃO:
K5: AFASTAMENTO:
C6: PROCESSO: | G6: DEFINIDO COMO: | H6: =IF(L61>40*VLOOKUP(L6,DADOS!A:B,2),"01","47") -> #VALUE! | K6: INICIAL:
C7: SALÁRIO: | G7: COMISSÃO: | K7: REMUNERAÇÃO: | L7: =D7+H7 -> 0
A8: X | C8: Aviso Prévio Integrativo | L8: =IF(A8="X",IF(AND(F18=0,F19=0),L7+D7/H23*((1+D21/100)*D23+(D20/100)*F20+(D21/100)*F24+(H7/H23*(D25/100))*H25)*(1+F26/100),IF(AND(F18<>0,F19<>0),"Periculosidade ou Insalubridade?",IF(AND(F18<>0,F19=0),L7+L18/F18+(D7+L18/F18)/H23*((1+D21/100)*D23+(D20/100)*F20+(D21/100)*F24+(H7/H23*(D25/100))*H25)*(1+F26/100),IF(AND(F18=0,F19<>0),L7+L19/F19+(D7+L19/F19)/H23*((1+D21/100)*D23+(D20/100)*F20+(D21/100)*F24+(H7/H23*(D25/100))*H25)*(1+F26/100),0)))),0) -> 0
A9: X | C9: Férias Proporcionais + 1/3 | F9: =IF(VALUE(CONCATENATE(LEFT(TEXT(L4,"dd/mm/aa"),5),RIGHT(TEXT(L5,"dd/mm/aa"),3)))>L5,IF(L8<>0,IF(VALUE(RIGHT(TEXT(L5,"dd/mm/aa"),2))=0,ROUND(DAYS360(CONCATENATE(LEFT(TEXT(L4,"dd/mm/aa"),6),99),L5+1)/30,0)+1,ROUND(DAYS360(CONCATENATE(LEFT(TEXT(L4,"dd/mm/aa"),6),RIGHT(TEXT(L5,"dd/mm/aa"),2)-1),L5+1)/30,0)+1),IF(VALUE(RIGHT(TEXT(L5,"dd/mm/aa"),2))=0,ROUND(DAYS360(CONCATENATE(LEFT(TEXT(L4,"dd/mm/aa"),6),99),L5+1)/30,0),ROUND(DAYS360(CONCATENATE(LEFT(TEXT(L4,"dd/mm/aa"),6),RIGHT(TEXT(L5,"dd/mm/aa"),2)-1),L5+1)/30,0))),IF(L8<>0,ROUND(DAYS360(VALUE(CONCATENATE(LEFT(TEXT(L4,"dd/mm/aa"),6),RIGHT(TEXT(L5,"dd/mm/aa"),2))),L5+1)/30,0)+1,ROUND(DAYS360(VALUE(CONCATENATE(LEFT(TEXT(L4,"dd/mm/aa"),6),RIGHT(TEXT(L5,"dd/mm/aa"),2))),L5+1)/30,0))) -> #VALUE! | G9: /12 | L9: =IF(A9="X",IF(AND(F18<>0,F19=0),(L7+L18/F18+(D7+L18/F18)/H23*((1+D21/100)*D23+(D20/100)*F20+(D21/100)*F24+(H7/H23*(D25/100))*H25)*(1+F26/100))/12*ROUND(F9,0)*4/3,IF(AND(F18=0,F19<>0),(L7+L19/F19+(D7+L19/F19)/H23*((1+D21/100)*D23+(D20/100)*F20+(D21/100)*F24+(H7/H23*(D25/100))*H25)*(1+F26/100))/12*ROUND(F9,0)*4/3,(L7+D7/H23*((1+D21/100)*D23+(D20/100)*F20+(D21/100)*F24+(H7/H23*(D25/100))*H25)*(1+F26/100))/12*ROUND(F9,0)*4/3)),0) -> #VALUE!
A10: X | C10: 13º Salário Proporcional | F10: =IF(YEAR(L4)<YEAR(L5),IF(L8<>0,ROUND(DAYS360(VALUE(CONCATENATE("1/1",RIGHT(TEXT(L5,"dd/mm/aa"),3))),L5+1)/30,0)+1,ROUND(DAYS360(VALUE(CONCATENATE("1/1",RIGHT(TEXT(L5,"dd/mm/aa"),3))),L5+1)/30,0)),IF(L8<>0,ROUND(DAYS360(L4,L5+1)/30,0)+1,ROUND(DAYS360(L4,L5+1)/30,0))) -> 0 | G10: /12 | L10: =IF(A10="X",IF(AND(F18<>0,F19=0),(L7+L18/F18+(D7+L18/F18)/H23*((1+D21/100)*D23+(D20/100)*F20+(D21/100)*F24+(H7/H23*(D25/100))*H25)*(1+F26/100))/12*ROUND(F10,0),IF(AND(F18=0,F19<>0),(L7+L19/F19+(D7+L19/F19)/H23*((1+D21/100)*D23+(D20/100)*F20+(D21/100)*F24+(H7/H23*(D25/100))*H25)*(1+F26/100))/12*ROUND(F10,0),(L7+D7/H23*((1+D21/100)*D23+(D20/100)*F20+(D21/100)*F24+(H7/H23*(D25/100))*H25)*(1+F26/100))/12*ROUND(F10,0))),0) -> 0
A11: X | C11: F.G.T.S. da Rescisão + 40% | F11: 40 | G11: % | L11: =IF(A11="X",(L8+L10+L13)*0.08*(1+F11/100),0) -> 0
A12: X | C12: 40% do F.G.T.S. | F12: =(DAYS360(L4,L5)/30) -> 0 | G12: meses | L12: =IF(A12="X",IF(F12<>0,(L7*0.08*(F12+F12/12))*0.4,0),0) -> 0
A13: X | C13: Saldo de Salário em dobro | F13: =DAYS360(VALUE(CONCATENATE(1,RIGHT(TEXT(L5,"dd/mm/aa"),6))),L5+1) -> -36000 | G13: nº dias | L13: =IF(A13="X",(D7+H7)*F13/30*2,0) -> 0
A14: X | C14: Multa do §8º, art. 477 da CLT | L14: =IF(A14="X",(D7+H7),0) -> 0
A15: X | C15: Férias Simples + 1/3 | F15: 1 | G15: período | L15: =IF(A15="X",IF(AND(F18<>0,F19=0),(L7+L18/F18+(D7+L18/F18)/H23*((1+D21/100)*D23+(D20/100)*F20+(D21/100)*F24+(H7/H23*(D25/100))*H25)*(1+F26/100))*4/3*F15,IF(AND(F18=0,F19<>0),(L7+L19/F19+(D7+L19/F19)/H23*((1+D21/100)*D23+(D20/100)*F20+(D21/100)*F24+(H7/H23*(D25/100))*H25)*(1+F26/100))*4/3*F15,(L7+D7/H23*((1+D21/100)*D23+(D20/100)*F20+(D21/100)*F24+(H7/H23*(D25/100))*H25)*(1+F26/100))*4/3*F15)),0) -> 0
A16: X | C16: Férias em Dobro + 1/3 | F16: 0 | G16: períodos | L16: =IF(A16="X",IF(AND(F18<>0,F19=0),(L7+L18/F18+(D7+L18/F18)/H23*((1+D21/100)*D23+(D20/100)*F20+(D21/100)*F24+(H7/H23*(D25/100))*H25)*(1+F26/100))*4/3*F16*2,IF(AND(F18=0,F19<>0),(L7+L19/F19+(D7+L19/F19)/220*((1+D21/100)*D23+(D20/100)*F20+(D21/100)*F24+(H7/H23*(D25/100))*H25)*(1+F26/100))*4/3*F16*2,(L7+D7/H23*((1+D21/100)*D23+(D20/100)*F20+(D21/100)*F24+(H7/H23*(D25/100))*H25)*(1+F26/100))*4/3*F16*2)),0) -> 0
A17: X | C17: 13º Salário Integral dos anos => | F17: 0 | G17: nº anos | L17: =IF(A17="X",IF(AND(F18<>0,F19=0),(L7+L18/F18+(D7+L18/F18)/H23*((1+D21/100)*D23+(D20/100)*F20+(D21/100)*F24+(H7/H23*(D25/100))*H25)*(1+F26/100))*F17,IF(AND(F18=0,F19<>0),(L7+L19/F19+(D7+L19/F19)/H23*((1+D21/100)*D23+(D20/100)*F20+(D21/100)*F24+(H7/H23*(D25/100))*H25)*(1+F26/100))*F17,(L7+D7/220*((1+D21/100)*D23+(D20/100)*F20+(D21/100)*F24+(H7/H23*(D25/100))*H25)*(1+F26/100))*F17)),0) -> 0
A18: X | C18: Adicional de Periculosidade | F18: 0 | G18: nº meses | L18: =IF(A18="X",(D7+H7)*30%*F18,0) -> 0
A19: X | C19: Adicional de Insalubridade | F19: 0 | G19: nº meses | H19: 40 | I19: grau percentual | L19: =IF(A19="X",VLOOKUP(L5,DADOS!A:B,2)*H19/100*F19,0) -> #N/A | N19: Fórmula antiga => | P19: =IF(A21="X",IF(F21=25,IF((E22-D22-(G22-F22))*24*6>J21,((E22-D22-(G22-F22))*24*6-J21)/6*F21,0),IF(F21=21,IF((E22-D22-(G22-F22))*24*5>J21,((E22-D22-(G22-F22))*24*5-J21)/5*F21,0),IF(F21=30,IF((E22-D22-(G22-F22))*24*6>J21,((E22-D22-(G22-F22))*24*6-J21)/6*25+((E22-D22-(G22-F22))*24-H21)*5,0),0))),0) -> 0
A20: X | C20: Adicional Noturno | D20: 20 | E20: % | F20: 0 | G20: hs noturnas devidas p/ mês | H20: 0 | I20: hs noturnas pagas p/ mês | J20: =DAYS360(L4,L5+1)/30 -> 0.033333333 | K20: nº meses | L20: =IF(A20="X",IF(AND(F18<>0,F19=0),(D7+L18/F18)/H23*D20/100*(F20-H20)*J20,IF(AND(F18=0,F19<>0),(D7+L19/F19)/H23*D20/100*(F20-H20)*J20,D7/H23*D20/100*(F20-H20)*J20)),0) -> 0 | N20: Dias Trab | P20: HEsemana | Q20: Hemês
A21: X | C21: Horas Extras | D21: 50 | E21: % do adicional | F21: 25 | G21: dias trab p/ mês | H21: 8 | I21: jornada diária | J21: 44 | K21: jornada semanal | N21: 21 | O21: =(E22-D22-(G22-F22))*24 -> 0 | P21: =IF(O21>$H$21,IF($H$21*5>$J$21,(O21-$H$21)*5+$H$21*5-$J$21,(O21-$H$21)*5),IF(O21*5>$J$21,O21*5-$J$21,0)) -> 0 | Q21: =P21/5*N21 -> 0
A22: X | C22: jornada: | D22: 0 | E22: 0 | F22: 0 | G22: 0 | H22: =DAYS360(L4,L5+1)/30 -> 0.033333333 | I22: nº meses | L22: =IF(A21="X",IF(AND(F18<>0,F19=0),(D7+L18/F18)/H23*(1+D21/100)*(D23-F23)*H22,IF(AND(F18=0,F19<>0),(D7+L19/F19)/H23*(1+D21/100)*(D23-F23)*H22,D7/H23*(1+D21/100)*(D23-F23)*H22)),0) -> 0 | N22: 25 | O22: =(E22-D22-(G22-F22))*24 -> 0 | P22: =IF(O22>$H$21,IF($H$21*6>$J$21,(O22-$H$21)*6+$H$21*6-$J$21,(O22-$H$21)*6),IF(O22*6>$J$21,O22*6-$J$21,0)) -> 0 | Q22: =P22/6*N22 -> 0
A23: X | D23: =IF(A21="X",IF(F21=25,Q22,IF(F21=21,Q21,IF(AND(F21>25,F21<=30),Q23,0))),0) -> 0 | E23: HE devidas p/ mês | F23: 0 | G23: HE pagas p/ mês | H23: =IF(H21=6,180,220) -> 220 | I23: divisor mensal | N23: =IF(AND(F21>25,F21<=30),F21,0) -> 0 | O23: =(E22-D22-(G22-F22))*24 -> 0 | P23: =IF(O23>$H$21,IF($H$21*6>$J$21,(O23-$H$21)*6+$H$21*6-$J$21,(O23-$H$21)*6),IF(O23*6>$J$21,O23*6-$J$21,0)) -> 0 | Q23: =IF(AND(N23>25,N23<=30),IF(O23>$H$21,P23/6*25+(O23-$H$21)*(N23-25),P23/6*25),0) -> 0
A24: X | C24: Adicional de Horas Extras face o repouso diário não concedido | F24: 0 | G24: intervalo em horas p/ mês | H24: =DAYS360(L4,L5+1)/30 -> 0.033333333 | I24: nº meses | L24: =IF(A24="X",IF(AND(F18<>0,F19=0),(D7+L18/F18)/H23*(D21/100)*F24*H24,IF(AND(F18=0,F19<>0),(D7+L19/F19)/H23*(D21/100)*F24*H24,D7/H23*(D21/100)*F24*H24)),0) -> 0
A25: X | C25: Adicional de Horas Extras face as comissões | D25: 50 | E25: % de adicional | F25: =DAYS360(L4,L5+1)/30 -> 0.033333333 | G25: nº meses | H25: =IF(A21="X",IF(F21=25,IF((E22-D22-(G22-F22))*24*6>J21,((E22-D22-(G22-F22))*24*6-J21)/6*F21,0),IF(F21=21,IF((E22-D22-(G22-F22))*24*5>J21,((E22-D22-(G22-F22))*24*5-J21)/5*F21,0),IF(F21=30,IF((E22-D22-(G22-F22))*24*6>J21,((E22-D22-(G22-F22))*24*6-J21)/6*25+((E22-D22-(G22-F22))*24-H21)*5,0),0))),0) -> 0 | I25: hs p/ mês | L25: =IF(A25="X",H7/H23*D25/100*H25*F25,0) -> 0
A26: X | C26: Repouso Semanal Remunerado | F26: =IF(F21=25,20,IF(F21=30,16.67,20)) -> 20 | G26: percentual | L26: =IF(A26="X",(L20+L22+L24+L25+L30+L31)*F26/100,0) -> 0
A27: X | C27: Dobras Domingos e Feriados | F27: 0 | G27: dias p/mês | H27: =DAYS360(L4,L5+1)/30 -> 0.033333333 | I27: nº meses | L27: =IF(A27="X",IF(AND(F18<>0,F19=0),(L7+L18/F18)/30*F27*H27,IF(AND(F18=0,F19<>0),(L7+L19/F19)/30*F27*H27,L7/30*F27*H27)),0) -> 0
A28: X | C28: Diferença Salarial em dobro | F28: 0 | G28: salário devido | H28: 0 | I28: salário pago | J28: =DAYS360(L4,L5+1)/30 -> 0.033333333 | K28: nº meses | L28: =IF(A28="X",(F28-H28)*J28*2,0) -> 0
A29: X | C29: Repouso Semanal Remunerado para Horista ou Diarista | F29: 0 | G29: salário por hora | H29: 0 | I29: salário por dia | J29: =DAYS360(L4,L5+1)/30 -> 0.033333333 | K29: nº meses | L29: =IF(A29="X",IF(AND(F29<>0,H29=0),F29*8/(7*30)*J29,IF(AND(F29=0,H29<>0),H29/(7*30)*J29,0)),0) -> 0
A30: X | C30: Comissão Retida | L30: 0
A31: X | C31: Diferença de Comissão | F31: 0 | G31: comissão devida | H31: 0 | I31: comissão paga | J31: =DAYS360(L4,L5+1)/30 -> 0.033333333 | K31: nº meses | L31: =IF(A31="X",(F31-H31)*J31*2,0) -> 0
A32: X | C32: Diferença de FGTS + 40% das Parcelas Salariais Pedidas | H32: 40 | I32: % | L32: =IF(A32="X",(L17+L18+L19+L20+L22+L24+L25+L26+L27+L28+L29+L30+L31)*0.08*(1+H32/100),0) -> #N/A
A33: X | C33: Indenização Decorrente da Estabilidade da Gestante | H33: 0 | I33: nº meses entre a despedida e o parto | L33: =IF(A33="X",IF(H33>0,IF(AND(F18<>0,F19=0),(L7+L18/F18+(D7+L18/F18)/H23*((1+D21/100)*D23+(D20/100)*F20+(D21/100)*F24+(H7/H23*(D25/100))*H25)*(1+F26/100))*(H33+5),IF(AND(F18=0,F19<>0),(L7+L19/F19+(D7+L19/F19)/H23*((1+D21/100)*D23+(D20/100)*F20+(D21/100)*F24+(H7/H23*(D25/100))*H25)*(1+F26/100))*(H33+5),(L7+D7/H23*((1+D21/100)*D23+(D20/100)*F20+(D21/100)*F24+(H7/H23*(D25/100))*H25)*(1+F26/100))*(H33+5))),0),0) -> 0
A34: X | C34: Salário Maternidade (120 dias) | L34: =IF(A34="X",IF(AND(F18<>0,F19=0),(L7+L18/F18+(D7+L18/F18)/H23*((1+D21/100)*D23+(D20/100)*F20+(D21/100)*F24+(H7/H23*(D25/100))*H25)*(1+F26/100))/30*120,IF(AND(F18=0,F19<>0),(L7+L19/F19+(D7+L19/F19)/H23*((1+D21/100)*D23+(D20/100)*F20+(D21/100)*F24+(H7/H23*(D25/100))*H25)*(1+F26/100))/30*120,(L7+D7/H23*((1+D21/100)*D23+(D20/100)*F20+(D21/100)*F24+(H7/220*(D25/100))*H25)*(1+F26/100))/30*120)),0) -> 0
A35: X | C35: Vale Transporte | F35: 0 | G35: vales p/ mês | H35: 1.3 | I35: valor da passagem | J35: =DAYS360(L4,L5+1)/30 -> 0.033333333 | K35: nº meses | L35: =IF(A35="X",IF(OR(F35=0,H35=0),0,F35*H35*J35),0) -> 0
A36: X | C36: Salário Família | F36: 0 | G36: nº dependentes | J36: =DAYS360(L4,L5+1)/30 -> 0.033333333 | K36: nº meses | L36: =IF(A36="X",IF(AND(F18<>0,F19=0),IF((L7+L18/F18+(D7+L18/F18)/H23*((1+D21/100)*D23+(D20/100)*F20)*(1+F26/100))<=VLOOKUP(L5,DADOS!A:C,3),VLOOKUP(L5,DADOS!A:D,4)*F36*J36,VLOOKUP(L5,DADOS!A:E,5)*F36*J36),IF(AND(F18=0,F19<>0),IF((L7+L19/F19+(D7+L19/F19)/H23*((1+D21/100)*D23+(D20/100)*F20)*(1+F26/100))<=VLOOKUP(L5,DADOS!A:C,3),VLOOKUP(L5,DADOS!A:D,4)*F36*J36,VLOOKUP(L5,DADOS!A:E,5)*F36*J36),IF((L7+D7/220*((1+D21/100)*D23+(D20/100)*F20)*(1+F26/100))<=VLOOKUP(L5,DADOS!A:C,3),VLOOKUP(L5,DADOS!A:D,4)*F36*J36,VLOOKUP(L5,DADOS!A:E,5)*F36*J36))),0) -> #N/A
A37: X | C37: Indenização Decorrente do não Cadastramento no PIS | H37: 0 | I37: anos | L37: =IF(A37="X",IF(L7<=VLOOKUP(L5,DADOS!A:B,2)*2,VLOOKUP(L5,DADOS!A:B,2)*H37,0),0) -> #N/A
A38: X | C38: Outros | L38: 0
A39: X | C39: Outros | L39: 0
A40: X | C40: Outros | L40: 0
A41: X | C41: ( - ) VALOR PAGO | L41: 0
A42: X | C42: Débito na data da despedida: | G42: = | H42: R$ | L42: =SUM(L8:L40)-L41 -> #VALUE!
A43: X
...

Sheet INDICES
A1: Data | B1: Índice | C1: Moeda
A2: 33273 | B2: 1.0028741 | C2: Cr$
A3: 33274 | B3: 1.0057565 | C3: Cr$
A4: 33275 | B4: 1.0086472 | C4: Cr$
A5: 33276 | B5: 1.0115462 | C5: Cr$
A6: 33277 | B6: 1.0144535 | C6: Cr$
A7: 33278 | B7: 1.0144535 | C7: Cr$
A8: 33279 | B8: 1.0144535 | C8: Cr$
A9: 33280 | B9: 1.0144535 | C9: Cr$
A10: 33281 | B10: 1.0144535 | C10: Cr$
A11: 33282 | B11: 1.0181731 | C11: Cr$
A12: 33283 | B12: 1.0219063 | C12: Cr$
A13: 33284 | B13: 1.0266168 | C13: Cr$
... A758: 34029 | B758: 88.546562 | C758: Cr$
A759: =A758+1 -> 34030 | B759: 89.442335 | C759: Cr$
A760: =A759+1 -> 34031 | B760: 90.347171 | C760: Cr$
A761: =A760+1 -> 34032 | B761: 91.26116 | C761: Cr$
A762: =A761+1 -> 34033 | B762: 91.26116 | C762: Cr$
A763: =A762+1 -> 34034 | B763: 91.26116 | C763: Cr$
A764: =A763+1 -> 34035 | B764: 91.26116 | C764: Cr$
A765: =A764+1 -> 34036 | B765: 92.184395 | C765: Cr$
A766: =A765+1 -> 34037 | B766: 93.11697 | C766: Cr$
A767: =A766+1 -> 34038 | B767: 94.058979 | C767: Cr$
A768: =A767+1 -> 34039 | B768: 94.998448 | C768: Cr$
A769: =A768+1 -> 34040 | B769: 95.9473 | C769: Cr$
A770: =A769+1 -> 34041 | B770: 95.9473 | C770: Cr$
... A1640: =A1639+1 -> 34911 | B1640: 0.0064911635 | C1640: R$
A1641: 34912 | B1641: 0.0064998636 | C1641: R$
A1642: 34913 | B1642: 0.0065071338 | C1642: R$
A1643: 34914 | B1643: 0.0065144122 | C1643: R$
A1644: 34915 | B1644: 0.0065216987 | C1644: R$
A1645: 34916 | B1645: 0.0065216987 | C1645: R$
A1646: 34917 | B1646: 0.0065216987 | C1646: R$
A1647: 34918 | B1647: 0.0065289933 | C1647: R$
A1648: 34919 | B1648: 0.0065362961 | C1648: R$
A1649: 34920 | B1649: 0.0065436071 | C1649: R$
A1650: 34921 | B1650: 0.0065509263 | C1650: R$
A1651: 34922 | B1651: 0.0065582536 | C1651: R$
A1652: 34923 | B1652: 0.0065582536 | C1652: R$
... A5052: 38353 | B5052: 0.011142412 | C5052: R$

Sheet DADOS
A1: Época | B1: Salário Mínimo | C1: Faixa | D1: Salário Família 1 | E1: Salário Família 2 | G1: Época | H1: Seguro Desemprego
A2: 34335 | B2: 32882 | C2: 50625.57 | D2: 2366.33 | E2: 295.74 | G2: 34335 | H2: =128.3*458.16 -> 58781.928 | I2: =213.84*458.16 -> 97972.934 | J2: =145.41*458.16 -> 66621.046
A3: 34366 | B3: 42829 | C3: 115582.02 | D3: 3082.15 | E3: 385.19 | G3: 34366 | H3: =128.3*637.64 -> 81809.212 | I3: =213.84*637.64 -> 136352.94 | J3: =145.41*637.64 -> 92719.232
A4: 34394 | B4: 60322.72 | C4: 162803.4 | D4: 4338.69 | E4: 540 | G4: 34394 | H4: =128.3*931.05 -> 119453.72 | I4: =213.84*931.05 -> 199095.73 | J4: =145.41*931.05 -> 135383.98
A5: 34425 | B5: 85776.77 | C5: 231500.65 | D5: 6169.46 | E5: 767.87 | G5: 34425 | H5: =128.3*1323.92 -> 169858.94 | I5: =213.84*1323.92 -> 283107.05 | J5: =145.41*1323.92 -> 192511.21
A6: 34455 | B6: 121527.89 | C6: 328023.37 | D6: 8740.85 | E6: 1087.91 | G6: 34455 | H6: =128.3*1875.72 -> 240654.88 | I6: =213.84*1875.72 -> 401103.96 | J6: =145.41*1875.72 -> 272748.45
A7: 34486 | B7: 178172.5 | C7: 480865 | D7: 12815 | E7: 1595 | G7: 34486 | H7: =128.3*2750 -> 352825 | I7: =213.84*2750 -> 588060 | J7: =145.41*2750 -> 399877.5
A8: 34516 | B8: 64.79 | C8: 174.86 | D8: 4.66 | E8: 0.58 | G8: 34516 | H8: 128.3 | I8: 213.84 | J8: 145.41
A9: 34547 | B9: 64.79 | C9: 174.86 | D9: 4.66 | E9: 0.58 | G9: 34547 | H9: 128.3 | I9: 213.84 | J9: 145.41
A10: 34578 | B10: 70 | C10: 174.86 | D10: 4.66 | E10: 0.58 | G10: 34578 | H10: 128.3 | I10: 213.84 | J10: 145.41
A11: 34608 | B11: 70 | C11: 174.86 | D11: 4.66 | E11: 0.58 | G11: 34608 | H11: 128.3 | I11: 213.84 | J11: 145.41
A12: 34639 | B12: 70 | C12: 174.86 | D12: 4.66 | E12: 0.58 | G12: 34639 | H12: 128.3 | I12: 213.84 | J12: 145.41
A13: 34669 | B13: 70 | C13: 174.86 | D13: 4.66 | E13: 0.58 | G13: 34669 | H13: 128.3 | I13: 213.84 | J13: 145.41
A14: 34700 | B14: 70 | C14: 174.86 | D14: 4.66 | E14: 0.58 | G14: 34700 | H14: 128.3 | I14: 213.84 | J14: 145.41
A15: 34731 | B15: 70 | C15: 174.86 | D15: 4.66 | E15: 0.58 | G15: 34731 | H15: 128.3 | I15: 213.84 | J15: 145.41
A16: 34759 | B16: 70 | C16: 174.86 | D16: 4.66 | E16: 0.58 | G16: 34759 | H16: 128.3 | I16: 213.84 | J16: 145.41
A17: 34790 | B17: 70 | C17: 174.86 | D17: 4.66 | E17: 0.58 | G17: 34790 | H17: 128.3 | I17: 213.84 | J17: 145.41
A18: 34820 | B18: 100 | C18: 249.8 | D18: 6.66 | E18: 0.83 | G18: 34820 | H18: 166.21 | I18: 277.03 | J18: 188.38
A19: 34851 | B19: 100 | C19: 249.8 | D19: 6.66 | E19: 0.83 | G19: 34851 | H19: 166.21 | I19: 277.03 | J19: 188.38
... A134: 38353 | B134: 260 | C134: 586.19 | D134: 20 | E134: 14.09 | G134: 38353 | H134: 429.2 | I134: 715.4 | J134: 486.46
