Workbook
Name anexo1: ANEXOS!$D$12:$D$17
Name anexo2: ANEXOS!$D$21:$D$26
Name anexo3: ANEXOS!$D$30:$D$35
Name anexo4: ANEXOS!$D$39:$D$44
Name anexo5: ANEXOS!$D$48:$D$53

Sheet Cálculo
C2: UMARIZAL CONSULTING
C3: Trav. Manoel Evaristo, 449 - Umarizal
C4: Cep 66.050-290 - Belém - Pará - Brasil
C5: Tel: +55 (091) 3277-7050 / (91) 98128-7982
C6: www.umarizaloffice.com.br
A8: Dúvidas e/ou Desbloqueio da planilha???
A9: Clique aqui e contrate nossa consultoria online
A11: PLANILHA PARA CÁLCULO DO SIMPLES NACIONAL 2018
B13: Obs: Preencha apenas as células em cinza
B15: Faturamento dos últimos 12 meses: | E15: 350000
B17: Faturamento dos últimos 12 meses (Cálculo): | E17: =IF(E15<480001,E15,0) -> 350000
B19: Atividade | C19: Faturamento do mês | D19: Alíquota efetiva | E19: Valor do DAS | F19: Percentual do ISS
B20: Anexo 1 (Comércio) | D20: =IF(E17>3600000,ANEXOS!F17,IF(ANEXOS!E8>1800000,ANEXOS!F16,IF(ANEXOS!E8>720000,ANEXOS!F15,IF(ANEXOS!E8>360000,ANEXOS!F14,IF(ANEXOS!E8>180000,ANEXOS!F13,IF(ANEXOS!E8<180000,ANEXOS!F12)))))) -> 0.056028571 | E20: =C20*D20 -> 0
B21: Anexo 2 (Indústria) | D21: =IF(Cálculo!E17>3600000,ANEXOS!F26,IF(E17>1800000,ANEXOS!F25,IF(Cálculo!E17>720000,ANEXOS!F24,IF(Cálculo!E17>360000,ANEXOS!F23,IF(Cálculo!E17>180000,ANEXOS!F22,IF(Cálculo!E17<180000,ANEXOS!F21)))))) -> 0.061028571 | E21: =C21*D21 -> 0
B22: Anexo 3 (Serviço) | D22: =IF(E17>3600000,ANEXOS!F35,IF(ANEXOS!E8>1800000,ANEXOS!F34,IF(ANEXOS!E8>720000,ANEXOS!F33,IF(ANEXOS!E8>360000,ANEXOS!F32,IF(ANEXOS!E8>180000,ANEXOS!F31,IF(ANEXOS!E8<180000,ANEXOS!F30)))))) -> 0.085257143 | E22: =C22*D22 -> 0 | F22: =IF(E17>3600000,ANEXOS!G35,IF(ANEXOS!E8>1800000,ANEXOS!G34,IF(ANEXOS!E8>720000,ANEXOS!G33,IF(ANEXOS!E8>360000,ANEXOS!G32,IF(ANEXOS!E8>180000,ANEXOS!G31,IF(ANEXOS!E8<180000,ANEXOS!G30)))))) -> 0.027282286
B23: Anexo 4 (Serviço) | D23: =IF(E17>3600000,ANEXOS!F44,IF(ANEXOS!E8>1800000,ANEXOS!F43,IF(ANEXOS!E8>720000,ANEXOS!F42,IF(ANEXOS!E8>360000,ANEXOS!F41,IF(ANEXOS!E8>180000,ANEXOS!F40,IF(ANEXOS!E8<180000,ANEXOS!F39)))))) -> 0.066857143 | E23: =C23*D23 -> 0 | F23: =IF(E17>3600000,ANEXOS!G44,IF(ANEXOS!E8>1800000,ANEXOS!G43,IF(ANEXOS!E8>720000,ANEXOS!G42,IF(ANEXOS!E8>360000,ANEXOS!G41,IF(ANEXOS!E8>180000,ANEXOS!G40,IF(ANEXOS!E8<180000,ANEXOS!G39)))))) -> 0.026742857
B24: Anexo 5 (Serviço) | D24: =IF(E17>3600000,ANEXOS!F53,IF(ANEXOS!E8>1800000,ANEXOS!F52,IF(ANEXOS!E8>720000,ANEXOS!F51,IF(ANEXOS!E8>360000,ANEXOS!F50,IF(ANEXOS!E8>180000,ANEXOS!F49,IF(ANEXOS!E8<180000,ANEXOS!F48)))))) -> 0.16714286 | E24: =C24*D24 -> 0 | F24: =IF(E17>3600000,ANEXOS!G53,IF(ANEXOS!E8>1800000,ANEXOS!G52,IF(ANEXOS!E8>720000,ANEXOS!G51,IF(ANEXOS!E8>360000,ANEXOS!G50,IF(ANEXOS!E8>180000,ANEXOS!G49,IF(ANEXOS!E8<180000,ANEXOS!G48)))))) -> 0.028414286
B25: Total do Faturamento | C25: =SUM(C20:C24) -> 0 | E25: =SUM(E20:E24) -> 0

Sheet ANEXOS
B1: UMARIZAL CONSULTING
B2: Trav. Manoel Evaristo, 449 - Umarizal
B3: Cep 66.050-290 - Belém - Pará - Brasil
B4: Tel: +55 (091) 3277-7050 / (91) 98128-7982
B5: www.umarizaloffice.com.br
A7: ANEXOS DO SIMPLES NACIONAL
C8: Faturamento dos últimos 12 meses | E8: =Cálculo!E17 -> 350000
B10: Anexo 1
B11: Faixa | C11: Faturamento dos últimos 12 meses | D11: Alíquota nominal | E11: Valor a Deduzir (em R$) | F11: Alíquota efetiva
B12: 1a Faixa | C12: Até 180.000,00 | D12: 0.04 | E12: 0 | F12: =(($E$8*D12)-E12)/$E$8 -> 0.04
B13: 2a Faixa | C13: De 180.000,01 a 360.000,00 | D13: 0.073 | E13: 5940 | F13: =(($E$8*D13)-E13)/$E$8 -> 0.056028571
B14: 3a Faixa | C14: De 360.000,01 a 720.000,00 | D14: 0.095 | E14: 13860 | F14: =(($E$8*D14)-E14)/$E$8 -> 0.0554
B15: 4a Faixa | C15: De 720.000,01 a 1.800.000,00 | D15: 0.107 | E15: 22500 | F15: =(($E$8*D15)-E15)/$E$8 -> 0.042714286
B16: 5a Faixa | C16: De 1.800.000,01 a 3.600.000,00 | D16: 0.143 | E16: 87300 | F16: =(($E$8*D16)-E16)/$E$8 -> -0.10642857
B17: 6a Faixa | C17: De 3.600.000,01 a 4.800.000,00 | D17: 0.19 | E17: 378000 | F17: =(($E$8*D17)-E17)/$E$8 -> -0.89
B19: Anexo 2
D20: Alíquota | E20: Valor a Deduzir (em R$) | F20: Alíquota efetiva
B21: 1a Faixa | C21: Até 180.000,00 | D21: 0.045 | E21: 0 | F21: =(($E$8*D21)-E21)/$E$8 -> 0.045
B22: 2a Faixa | C22: De 180.000,01 a 360.000,00 | D22: 0.078 | E22: 5940 | F22: =(($E$8*D22)-E22)/$E$8 -> 0.061028571
B23: 3a Faixa | C23: De 360.000,01 a 720.000,00 | D23: 0.1 | E23: 13860 | F23: =(($E$8*D23)-E23)/$E$8 -> 0.0604
B24: 4a Faixa | C24: De 720.000,01 a 1.800.000,00 | D24: 0.112 | E24: 22500 | F24: =(($E$8*D24)-E24)/$E$8 -> 0.047714286
B25: 5a Faixa | C25: De 1.800.000,01 a 3.600.000,00 | D25: 0.147 | E25: 85500 | F25: =(($E$8*D25)-E25)/$E$8 -> -0.097285714
B26: 6a Faixa | C26: De 3.600.000,01 a 4.800.000,00 | D26: 0.3 | E26: 720000 | F26: =(($E$8*D26)-E26)/$E$8 -> -1.7571429
B28: Anexo 3
B29: Receita Bruta em 12 Meses (em R$) | D29: Alíquota | E29: Valor a Deduzir (em R$) | F29: Alíquota efetiva | G29: ISS
B30: 1a Faixa | C30: Até 180.000,00 | D30: 0.06 | E30: 0 | F30: =(($E$8*D30)-E30)/$E$8 -> 0.06 | G30: =(33.5%*F30) -> 0.0201
B31: 2a Faixa | C31: De 180.000,01 a 360.000,00 | D31: 0.112 | E31: 9360 | F31: =(($E$8*D31)-E31)/$E$8 -> 0.085257143 | G31: =(32%*F31) -> 0.027282286
B32: 3a Faixa | C32: De 360.000,01 a 720.000,00 | D32: 0.135 | E32: 17640 | F32: =(($E$8*D32)-E32)/$E$8 -> 0.0846 | G32: =(32.5%*F32) -> 0.027495
B33: 4a Faixa | C33: De 720.000,01 a 1.800.000,00 | D33: 0.16 | E33: 35640 | F33: =(($E$8*D33)-E33)/$E$8 -> 0.058171429 | G33: =(32.5%*F33) -> 0.018905714
B34: 5a Faixa | C34: De 1.800.000,01 a 3.600.000,00 | D34: 0.21 | E34: 125640 | F34: =(($E$8*D34)-E34)/$E$8 -> -0.14897143 | G34: =IF((F34*33.5%)>5%,5%,F34*33.5%) -> -0.049905429
B35: 6a Faixa | C35: De 3.600.000,01 a 4.800.000,00 | D35: 0.33 | E35: 648000 | F35: =(($E$8*D35)-E35)/$E$8 -> -1.5214286 | G35: 0.05
B37: Anexo 4
B38: Receita Bruta em 12 Meses (em R$) | D38: Alíquota | E38: Valor a Deduzir (em R$) | F38: Alíquota efetiva | G38: ISS
B39: 1a Faixa | C39: Até 180.000,00 | D39: 0.045 | E39: 0 | F39: =(($E$8*D39)-E39)/$E$8 -> 0.045 | G39: =(44.5%*F39) -> 0.020025
B40: 2a Faixa | C40: De 180.000,01 a 360.000,00 | D40: 0.09 | E40: 8100 | F40: =(($E$8*D40)-E40)/$E$8 -> 0.066857143 | G40: =(40%*F40) -> 0.026742857
B41: 3a Faixa | C41: De 360.000,01 a 720.000,00 | D41: 0.102 | E41: 12420 | F41: =(($E$8*D41)-E41)/$E$8 -> 0.066514286 | G41: =(40%*F41) -> 0.026605714
B42: 4a Faixa | C42: De 720.000,01 a 1.800.000,00 | D42: 0.14 | E42: 39780 | F42: =(($E$8*D42)-E42)/$E$8 -> 0.026342857 | G42: =(40%*F42) -> 0.010537143
B43: 5a Faixa | C43: De 1.800.000,01 a 3.600.000,00 | D43: 0.22 | E43: 183780 | F43: =(($E$8*D43)-E43)/$E$8 -> -0.30508571 | G43: =IF((F43*40%)>5%,5%,F43*40%) -> -0.12203429
B44: 6a Faixa | C44: De 3.600.000,01 a 4.800.000,00 | D44: 0.33 | E44: 828000 | F44: =(($E$8*D44)-E44)/$E$8 -> -2.0357143 | G44: 0.05
B46: Anexo 5
...
