Workbook

Sheet CADASTRO
A1: INFORME AQUI A QUANTIDADE DE HORAS TRABALHADAS POR DIA EM JANEIRO | B1: 0.33333333 | D1: INFORME O ANO CALENDÁRIO QUE DESEJA | E1: 01/01/2017 | G1: FERIADO
G2: ABONADO
A3: INFORME AQUI A QUANTIDADE DE HORAS TRABALHADAS POR DIA EM FEVEREIRO | B3: 0.33333333 | G3: ATESTADO
A5: INFORME AQUI A QUANTIDADE DE HORAS TRABALHADAS POR DIA EM MARÇO | B5: =B3 -> 0.33333333
A7: INFORME AQUI A QUANTIDADE DE HORAS TRABALHADAS POR DIA EM ABRIL | B7: =B5 -> 0.33333333
A9: INFORME AQUI A QUANTIDADE DE HORAS TRABALHADAS POR DIA EM MAIO | B9: =B7 -> 0.33333333
A11: INFORME AQUI A QUANTIDADE DE HORAS TRABALHADAS POR DIA EM JUNHO | B11: =B9 -> 0.33333333
A13: INFORME AQUI A QUANTIDADE DE HORAS TRABALHADAS POR DIA EM JULHO | B13: =B11 -> 0.33333333
A15: INFORME AQUI A QUANTIDADE DE HORAS TRABALHADAS POR DIA EM AGOSTO | B15: =B13 -> 0.33333333
A17: INFORME AQUI A QUANTIDADE DE HORAS TRABALHADAS POR DIA EM SETEMBRO | B17: =B15 -> 0.33333333
A19: INFORME AQUI A QUANTIDADE DE HORAS TRABALHADAS POR DIA EM OUTUBRO | B19: =B17 -> 0.33333333
A21: INFORME AQUI A QUANTIDADE DE HORAS TRABALHADAS POR DIA EM NOVEMBRO | B21: =B19 -> 0.33333333
A23: INFORME AQUI A QUANTIDADE DE HORAS TRABALHADAS POR DIA EM DEZEMBRO | B23: =B21 -> 0.33333333

Sheet JANEIRO
A1: OBSERVAÇÃO | B1: DIA DA SEMANA | C1: DIA DO MÊS | D1: HORAS NORMAIS | H1: HORA EXTRA | J1: TOTAL DE HORAS NO DIA | L1: EXTRA X ATRASO | M1: HORAS DIÁRIAS | N1: HORA NOTURNA | O1: ACUMULADO DIÁRIO | P1: ADICIONAL NOTURNO (NORMAL) | Q1: ADICIONAL NOTURNO (EXTRA) | R1: TOTAL ADICIONAL NOTURNO
D2: ENTRADA | E2: SAÍDA | F2: ENTRADA | G2: SAÍDA | H2: ENTRADA | I2: SAÍDA | T2: DATA ATUAL | U2: =TODAY() -> 41466 | V2: =TEXT(U2,"DDDD") -> quarta-feira | W2: =NOW() -> 41466.536
B3: =TEXT(C3,"DDDD") -> domingo | C3: =CADASTRO!$E$1 -> 01/01/2017 | J3: =E3-D3+G3-F3+I3-H3 -> 0 | K3: =IF(B3="SÁBADO",0,IF(B3="DOMINGO",0,IF(A3="FERIADO",0,IF(A3="ABONADO",0,IF(A3="ATESTADO",0,M3))))) -> 0 | L3: =J3-K3 -> 0 | M3: =CADASTRO!B1 -> 0.33333333 | N3: 0.91666667 | O3: =L3 -> 0 | P3: =IF(G3>N3,G3-N3,0) -> 0 | Q3: =IF(I3>N3,I3-N3,0) -> 0 | R3: =P3+Q3 -> 0
B4: =TEXT(C4,"DDDD") -> segunda-feira | C4: =C3+1 -> 41275 | D4: 0.375 | E4: 0.5 | F4: 0.54166667 | G4: 0.75 | H4: 0.75 | I4: 0.95833333 | J4: =E4-D4+G4-F4+I4-H4 -> 0.54166667 | K4: =IF(B4="SÁBADO",0,IF(B4="DOMINGO",0,IF(A4="FERIADO",0,IF(A4="ABONADO",0,IF(A4="ATESTADO",0,M4))))) -> 0.33333333 | L4: =J4-K4 -> 0.20833333 | M4: =M3 -> 0.33333333 | N4: =N3 -> 0.91666667 | O4: =O3+L4 -> 0.20833333 | P4: =IF(G4>N4,G4-N4,0) -> 0 | Q4: =IF(I4>N4,I4-N4,0) -> 0.041666667 | R4: =P4+Q4 -> 0.041666667
B5: =TEXT(C5,"DDDD") -> terça-feira | C5: =C4+1 -> 41276 | D5: 0.375 | E5: 0.5 | F5: 0.54166667 | G5: 0.9375 | H5: 0 | I5: 0 | J5: =E5-D5+G5-F5+I5-H5 -> 0.52083333 | K5: =IF(B5="SÁBADO",0,IF(B5="DOMINGO",0,IF(A5="FERIADO",0,IF(A5="ABONADO",0,IF(A5="ATESTADO",0,M5))))) -> 0.33333333 | L5: =J5-K5 -> 0.1875 | M5: =M4 -> 0.33333333 | N5: =N4 -> 0.91666667 | O5: =O4+L5 -> 0.39583333 | P5: =IF(G5>N5,G5-N5,0) -> 0.020833333 | Q5: =IF(I5>N5,I5-N5,0) -> 0 | R5: =P5+Q5 -> 0.020833333
B6: =TEXT(C6,"DDDD") -> quarta-feira | C6: =C5+1 -> 41277 | J6: =E6-D6+G6-F6+I6-H6 -> 0 | K6: =IF(B6="SÁBADO",0,IF(B6="DOMINGO",0,IF(A6="FERIADO",0,IF(A6="ABONADO",0,IF(A6="ATESTADO",0,M6))))) -> 0.33333333 | L6: =J6-K6 -> -0.33333333 | M6: =M5 -> 0.33333333 | N6: =N5 -> 0.91666667 | O6: =O5+L6 -> 0.0625 | P6: =IF(G6>N6,G6-N6,0) -> 0 | Q6: =IF(I6>N6,I6-N6,0) -> 0 | R6: =P6+Q6 -> 0
B7: =TEXT(C7,"DDDD") -> quinta-feira | C7: =C6+1 -> 41278 | J7: =E7-D7+G7-F7+I7-H7 -> 0 | K7: =IF(B7="SÁBADO",0,IF(B7="DOMINGO",0,IF(A7="FERIADO",0,IF(A7="ABONADO",0,IF(A7="ATESTADO",0,M7))))) -> 0.33333333 | L7: =J7-K7 -> -0.33333333 | M7: =M6 -> 0.33333333 | N7: =N6 -> 0.91666667 | O7: =O6+L7 -> -0.27083333 | P7: =IF(G7>N7,G7-N7,0) -> 0 | Q7: =IF(I7>N7,I7-N7,0) -> 0 | R7: =P7+Q7 -> 0
B8: =TEXT(C8,"DDDD") -> sexta-feira | C8: =C7+1 -> 41279 | J8: =E8-D8+G8-F8+I8-H8 -> 0 | K8: =IF(B8="SÁBADO",0,IF(B8="DOMINGO",0,IF(A8="FERIADO",0,IF(A8="ABONADO",0,IF(A8="ATESTADO",0,M8))))) -> 0.33333333 | L8: =J8-K8 -> -0.33333333 | M8: =M7 -> 0.33333333 | N8: =N7 -> 0.91666667 | O8: =O7+L8 -> -0.60416667 | P8: =IF(G8>N8,G8-N8,0) -> 0 | Q8: =IF(I8>N8,I8-N8,0) -> 0 | R8: =P8+Q8 -> 0
B9: =TEXT(C9,"DDDD") -> sábado | C9: =C8+1 -> 41280 | J9: =E9-D9+G9-F9+I9-H9 -> 0 | K9: =IF(B9="SÁBADO",0,IF(B9="DOMINGO",0,IF(A9="FERIADO",0,IF(A9="ABONADO",0,IF(A9="ATESTADO",0,M9))))) -> 0 | L9: =J9-K9 -> 0 | M9: =M8 -> 0.33333333 | N9: =N8 -> 0.91666667 | O9: =O8+L9 -> -0.60416667 | P9: =IF(G9>N9,G9-N9,0) -> 0 | Q9: =IF(I9>N9,I9-N9,0) -> 0 | R9: =P9+Q9 -> 0
B10: =TEXT(C10,"DDDD") -> domingo | C10: =C9+1 -> 41281 | J10: =E10-D10+G10-F10+I10-H10 -> 0 | K10: =IF(B10="SÁBADO",0,IF(B10="DOMINGO",0,IF(A10="FERIADO",0,IF(A10="ABONADO",0,IF(A10="ATESTADO",0,M10))))) -> 0 | L10: =J10-K10 -> 0 | M10: =M9 -> 0.33333333 | N10: =N9 -> 0.91666667 | O10: =O9+L10 -> -0.60416667 | P10: =IF(G10>N10,G10-N10,0) -> 0 | Q10: =IF(I10>N10,I10-N10,0) -> 0 | R10: =P10+Q10 -> 0
B11: =TEXT(C11,"DDDD") -> segunda-feira | C11: =C10+1 -> 41282 | J11: =E11-D11+G11-F11+I11-H11 -> 0 | K11: =IF(B11="SÁBADO",0,IF(B11="DOMINGO",0,IF(A11="FERIADO",0,IF(A11="ABONADO",0,IF(A11="ATESTADO",0,M11))))) -> 0.33333333 | L11: =J11-K11 -> -0.33333333 | M11: =M10 -> 0.33333333 | N11: =N10 -> 0.91666667 | O11: =O10+L11 -> -0.9375 | P11: =IF(G11>N11,G11-N11,0) -> 0 | Q11: =IF(I11>N11,I11-N11,0) -> 0 | R11: =P11+Q11 -> 0
B12: =TEXT(C12,"DDDD") -> terça-feira | C12: =C11+1 -> 41283 | J12: =E12-D12+G12-F12+I12-H12 -> 0 | K12: =IF(B12="SÁBADO",0,IF(B12="DOMINGO",0,IF(A12="FERIADO",0,IF(A12="ABONADO",0,IF(A12="ATESTADO",0,M12))))) -> 0.33333333 | L12: =J12-K12 -> -0.33333333 | M12: =M11 -> 0.33333333 | N12: =N11 -> 0.91666667 | O12: =O11+L12 -> -1.2708333 | P12: =IF(G12>N12,G12-N12,0) -> 0 | Q12: =IF(I12>N12,I12-N12,0) -> 0 | R12: =P12+Q12 -> 0
B13: =TEXT(C13,"DDDD") -> quarta-feira | C13: =C12+1 -> 41284 | J13: =E13-D13+G13-F13+I13-H13 -> 0 | K13: =IF(B13="SÁBADO",0,IF(B13="DOMINGO",0,IF(A13="FERIADO",0,IF(A13="ABONADO",0,IF(A13="ATESTADO",0,M13))))) -> 0.33333333 | L13: =J13-K13 -> -0.33333333 | M13: =M12 -> 0.33333333 | N13: =N12 -> 0.91666667 | O13: =O12+L13 -> -1.6041667 | P13: =IF(G13>N13,G13-N13,0) -> 0 | Q13: =IF(I13>N13,I13-N13,0) -> 0 | R13: =P13+Q13 -> 0
B14: =TEXT(C14,"DDDD") -> quinta-feira | C14: =C13+1 -> 41285 | J14: =E14-D14+G14-F14+I14-H14 -> 0 | K14: =IF(B14="SÁBADO",0,IF(B14="DOMINGO",0,IF(A14="FERIADO",0,IF(A14="ABONADO",0,IF(A14="ATESTADO",0,M14))))) -> 0.33333333 | L14: =J14-K14 -> -0.33333333 | M14: =M13 -> 0.33333333 | N14: =N13 -> 0.91666667 | O14: =O13+L14 -> -1.9375 | P14: =IF(G14>N14,G14-N14,0) -> 0 | Q14: =IF(I14>N14,I14-N14,0) -> 0 | R14: =P14+Q14 -> 0
B15: =TEXT(C15,"DDDD") -> sexta-feira | C15: =C14+1 -> 41286 | J15: =E15-D15+G15-F15+I15-H15 -> 0 | K15: =IF(B15="SÁBADO",0,IF(B15="DOMINGO",0,IF(A15="FERIADO",0,IF(A15="ABONADO",0,IF(A15="ATESTADO",0,M15))))) -> 0.33333333 | L15: =J15-K15 -> -0.33333333 | M15: =M14 -> 0.33333333 | N15: =N14 -> 0.91666667 | O15: =O14+L15 -> -2.2708333 | P15: =IF(G15>N15,G15-N15,0) -> 0 | Q15: =IF(I15>N15,I15-N15,0) -> 0 | R15: =P15+Q15 -> 0
B16: =TEXT(C16,"DDDD") -> sábado | C16: =C15+1 -> 41287 | J16: =E16-D16+G16-F16+I16-H16 -> 0 | K16: =IF(B16="SÁBADO",0,IF(B16="DOMINGO",0,IF(A16="FERIADO",0,IF(A16="ABONADO",0,IF(A16="ATESTADO",0,M16))))) -> 0 | L16: =J16-K16 -> 0 | M16: =M15 -> 0.33333333 | N16: =N15 -> 0.91666667 | O16: =O15+L16 -> -2.2708333 | P16: =IF(G16>N16,G16-N16,0) -> 0 | Q16: =IF(I16>N16,I16-N16,0) -> 0 | R16: =P16+Q16 -> 0
B17: =TEXT(C17,"DDDD") -> domingo | C17: =C16+1 -> 41288 | J17: =E17-D17+G17-F17+I17-H17 -> 0 | K17: =IF(B17="SÁBADO",0,IF(B17="DOMINGO",0,IF(A17="FERIADO",0,IF(A17="ABONADO",0,IF(A17="ATESTADO",0,M17))))) -> 0 | L17: =J17-K17 -> 0 | M17: =M16 -> 0.33333333 | N17: =N16 -> 0.91666667 | O17: =O16+L17 -> -2.2708333 | P17: =IF(G17>N17,G17-N17,0) -> 0 | Q17: =IF(I17>N17,I17-N17,0) -> 0 | R17: =P17+Q17 -> 0
... B33: =TEXT(C33,"DDDD") -> terça-feira | C33: =C32+1 -> 41304 | J33: =E33-D33+G33-F33+I33-H33 -> 0 | K33: =IF(B33="SÁBADO",0,IF(B33="DOMINGO",0,IF(A33="FERIADO",0,IF(A33="ABONADO",0,IF(A33="ATESTADO",0,M33))))) -> 0.33333333 | L33: =J33-K33 -> -0.33333333 | M33: =M32 -> 0.33333333 | N33: =N32 -> 0.91666667 | O33: =O32+L33 -> -6.2708333 | P33: =IF(G33>N33,G33-N33,0) -> 0 | Q33: =IF(I33>N33,I33-N33,0) -> 0 | R33: =P33+Q33 -> 0
L34: =SUM(L3:L33) -> -6.2708333

Sheet FEVEREIRO
A1: OBSERVAÇÃO | B1: DIA DA SEMANA | C1: DIA DO MÊS | D1: ENTRADA | E1: SAÍDA | F1: ENTRADA | G1: SAÍDA | H1: TOTAL DE HORAS NO DIA | J1: EXTRA X ATRASO | L1: ACUMULADO DIÁRIO | N1: DATA ATUAL | O1: =TODAY() -> 41466 | P1: =TEXT(O1,"DDDD") -> quarta-feira | Q1: =NOW() -> 41466.536
B2: =TEXT(C2,"DDDD") -> quarta-feira | C2: =JANEIRO!C33+1 -> 41305 | H2: =E2-D2+G2-F2 -> 0 | I2: =IF(B2="SÁBADO",0,IF(B2="DOMINGO",0,IF(A2="FERIADO",0,IF(A2="ABONADO",0,IF(A2="ATESTADO",0,K2))))) -> 0.33333333 | J2: =H2-I2 -> -0.33333333 | K2: =CADASTRO!B3 -> 0.33333333 | L2: =J2 -> -0.33333333
B3: =TEXT(C3,"DDDD") -> quinta-feira | C3: =C2+1 -> 41306 | H3: =E3-D3+G3-F3 -> 0 | I3: =IF(B3="SÁBADO",0,IF(B3="DOMINGO",0,IF(A3="FERIADO",0,IF(A3="ABONADO",0,IF(A3="ATESTADO",0,K3))))) -> 0.33333333 | J3: =H3-I3 -> -0.33333333 | K3: =K2 -> 0.33333333 | L3: =L2+J3 -> -0.66666667
B4: =TEXT(C4,"DDDD") -> sexta-feira | C4: =C3+1 -> 41307 | H4: =E4-D4+G4-F4 -> 0 | I4: =IF(B4="SÁBADO",0,IF(B4="DOMINGO",0,IF(A4="FERIADO",0,IF(A4="ABONADO",0,IF(A4="ATESTADO",0,K4))))) -> 0.33333333 | J4: =H4-I4 -> -0.33333333 | K4: =K3 -> 0.33333333 | L4: =L3+J4 -> -1
B5: =TEXT(C5,"DDDD") -> sábado | C5: =C4+1 -> 41308 | H5: =E5-D5+G5-F5 -> 0 | I5: =IF(B5="SÁBADO",0,IF(B5="DOMINGO",0,IF(A5="FERIADO",0,IF(A5="ABONADO",0,IF(A5="ATESTADO",0,K5))))) -> 0 | J5: =H5-I5 -> 0 | K5: =K4 -> 0.33333333 | L5: =L4+J5 -> -1
B6: =TEXT(C6,"DDDD") -> domingo | C6: =C5+1 -> 41309 | H6: =E6-D6+G6-F6 -> 0 | I6: =IF(B6="SÁBADO",0,IF(B6="DOMINGO",0,IF(A6="FERIADO",0,IF(A6="ABONADO",0,IF(A6="ATESTADO",0,K6))))) -> 0 | J6: =H6-I6 -> 0 | K6: =K5 -> 0.33333333 | L6: =L5+J6 -> -1
B7: =TEXT(C7,"DDDD") -> segunda-feira | C7: =C6+1 -> 41310 | H7: =E7-D7+G7-F7 -> 0 | I7: =IF(B7="SÁBADO",0,IF(B7="DOMINGO",0,IF(A7="FERIADO",0,IF(A7="ABONADO",0,IF(A7="ATESTADO",0,K7))))) -> 0.33333333 | J7: =H7-I7 -> -0.33333333 | K7: =K6 -> 0.33333333 | L7: =L6+J7 -> -1.3333333
B8: =TEXT(C8,"DDDD") -> terça-feira | C8: =C7+1 -> 41311 | H8: =E8-D8+G8-F8 -> 0 | I8: =IF(B8="SÁBADO",0,IF(B8="DOMINGO",0,IF(A8="FERIADO",0,IF(A8="ABONADO",0,IF(A8="ATESTADO",0,K8))))) -> 0.33333333 | J8: =H8-I8 -> -0.33333333 | K8: =K7 -> 0.33333333 | L8: =L7+J8 -> -1.6666667
B9: =TEXT(C9,"DDDD") -> quarta-feira | C9: =C8+1 -> 41312 | H9: =E9-D9+G9-F9 -> 0 | I9: =IF(B9="SÁBADO",0,IF(B9="DOMINGO",0,IF(A9="FERIADO",0,IF(A9="ABONADO",0,IF(A9="ATESTADO",0,K9))))) -> 0.33333333 | J9: =H9-I9 -> -0.33333333 | K9: =K8 -> 0.33333333 | L9: =L8+J9 -> -2
B10: =TEXT(C10,"DDDD") -> quinta-feira | C10: =C9+1 -> 41313 | H10: =E10-D10+G10-F10 -> 0 | I10: =IF(B10="SÁBADO",0,IF(B10="DOMINGO",0,IF(A10="FERIADO",0,IF(A10="ABONADO",0,IF(A10="ATESTADO",0,K10))))) -> 0.33333333 | J10: =H10-I10 -> -0.33333333 | K10: =K9 -> 0.33333333 | L10: =L9+J10 -> -2.3333333
B11: =TEXT(C11,"DDDD") -> sexta-feira | C11: =C10+1 -> 41314 | H11: =E11-D11+G11-F11 -> 0 | I11: =IF(B11="SÁBADO",0,IF(B11="DOMINGO",0,IF(A11="FERIADO",0,IF(A11="ABONADO",0,IF(A11="ATESTADO",0,K11))))) -> 0.33333333 | J11: =H11-I11 -> -0.33333333 | K11: =K10 -> 0.33333333 | L11: =L10+J11 -> -2.6666667
B12: =TEXT(C12,"DDDD") -> sábado | C12: =C11+1 -> 41315 | H12: =E12-D12+G12-F12 -> 0 | I12: =IF(B12="SÁBADO",0,IF(B12="DOMINGO",0,IF(A12="FERIADO",0,IF(A12="ABONADO",0,IF(A12="ATESTADO",0,K12))))) -> 0 | J12: =H12-I12 -> 0 | K12: =K11 -> 0.33333333 | L12: =L11+J12 -> -2.6666667
B13: =TEXT(C13,"DDDD") -> domingo | C13: =C12+1 -> 41316 | H13: =E13-D13+G13-F13 -> 0 | I13: =IF(B13="SÁBADO",0,IF(B13="DOMINGO",0,IF(A13="FERIADO",0,IF(A13="ABONADO",0,IF(A13="ATESTADO",0,K13))))) -> 0 | J13: =H13-I13 -> 0 | K13: =K12 -> 0.33333333 | L13: =L12+J13 -> -2.6666667
B14: =TEXT(C14,"DDDD") -> segunda-feira | C14: =C13+1 -> 41317 | H14: =E14-D14+G14-F14 -> 0 | I14: =IF(B14="SÁBADO",0,IF(B14="DOMINGO",0,IF(A14="FERIADO",0,IF(A14="ABONADO",0,IF(A14="ATESTADO",0,K14))))) -> 0.33333333 | J14: =H14-I14 -> -0.33333333 | K14: =K13 -> 0.33333333 | L14: =L13+J14 -> -3
... B29: =TEXT(C29,"DDDD") -> terça-feira | C29: =C28+1 -> 41332 | H29: =E29-D29+G29-F29 -> 0 | I29: =IF(B29="SÁBADO",0,IF(B29="DOMINGO",0,IF(A29="FERIADO",0,IF(A29="ABONADO",0,IF(A29="ATESTADO",0,K29))))) -> 0.33333333 | J29: =H29-I29 -> -0.33333333 | K29: =K28 -> 0.33333333 | L29: =L28+J29 -> -6.6666667
B30: =TEXT(C30,"DDDD") -> quarta-feira | C30: =C29+1 -> 41333 | H30: =E30-D30+G30-F30 -> 0 | I30: =IF(B30="SÁBADO",0,IF(B30="DOMINGO",0,IF(A30="FERIADO",0,IF(A30="ABONADO",0,IF(A30="ATESTADO",0,K30))))) -> 0.33333333 | J30: =IF(C30=MARÇO!C2,0,H30-I30) -> 0 | K30: =K29 -> 0.33333333 | L30: =L29+J30 -> -6.6666667
B31: EM CASO DE ANO BISSEXTO CLIQUE NO [+] | J31: =SUM(J2:J30) -> -6.6666667

Sheet MARÇO
A1: OBSERVAÇÃO | B1: DIA DA SEMANA | C1: DIA DO MÊS | D1: ENTRADA | E1: SAÍDA | F1: ENTRADA | G1: SAÍDA | H1: TOTAL DE HORAS NO DIA | J1: EXTRA X ATRASO | L1: ACUMULADO DIÁRIO | N1: DATA ATUAL | O1: =TODAY() -> 41466 | P1: =TEXT(O1,"DDDD") -> quarta-feira | Q1: =NOW() -> 41466.536
B2: =TEXT(C2,"DDDD") -> quarta-feira | C2: 41333 | H2: =E2-D2+G2-F2 -> 0 | I2: =IF(B2="SÁBADO",0,IF(B2="DOMINGO",0,IF(A2="FERIADO",0,IF(A2="ABONADO",0,IF(A2="ATESTADO",0,K2))))) -> 0.33333333 | J2: =H2-I2 -> -0.33333333 | K2: =CADASTRO!B5 -> 0.33333333 | L2: =J2 -> -0.33333333
B3: =TEXT(C3,"DDDD") -> quinta-feira | C3: =C2+1 -> 41334 | H3: =E3-D3+G3-F3 -> 0 | I3: =IF(B3="SÁBADO",0,IF(B3="DOMINGO",0,IF(A3="FERIADO",0,IF(A3="ABONADO",0,IF(A3="ATESTADO",0,K3))))) -> 0.33333333 | J3: =H3-I3 -> -0.33333333 | K3: =K2 -> 0.33333333 | L3: =L2+J3 -> -0.66666667
B4: =TEXT(C4,"DDDD") -> sexta-feira | C4: =C3+1 -> 41335 | H4: =E4-D4+G4-F4 -> 0 | I4: =IF(B4="SÁBADO",0,IF(B4="DOMINGO",0,IF(A4="FERIADO",0,IF(A4="ABONADO",0,IF(A4="ATESTADO",0,K4))))) -> 0.33333333 | J4: =H4-I4 -> -0.33333333 | K4: =K3 -> 0.33333333 | L4: =L3+J4 -> -1
B5: =TEXT(C5,"DDDD") -> sábado | C5: =C4+1 -> 41336 | H5: =E5-D5+G5-F5 -> 0 | I5: =IF(B5="SÁBADO",0,IF(B5="DOMINGO",0,IF(A5="FERIADO",0,IF(A5="ABONADO",0,IF(A5="ATESTADO",0,K5))))) -> 0 | J5: =H5-I5 -> 0 | K5: =K4 -> 0.33333333 | L5: =L4+J5 -> -1
B6: =TEXT(C6,"DDDD") -> domingo | C6: =C5+1 -> 41337 | H6: =E6-D6+G6-F6 -> 0 | I6: =IF(B6="SÁBADO",0,IF(B6="DOMINGO",0,IF(A6="FERIADO",0,IF(A6="ABONADO",0,IF(A6="ATESTADO",0,K6))))) -> 0 | J6: =H6-I6 -> 0 | K6: =K5 -> 0.33333333 | L6: =L5+J6 -> -1
B7: =TEXT(C7,"DDDD") -> segunda-feira | C7: =C6+1 -> 41338 | H7: =E7-D7+G7-F7 -> 0 | I7: =IF(B7="SÁBADO",0,IF(B7="DOMINGO",0,IF(A7="FERIADO",0,IF(A7="ABONADO",0,IF(A7="ATESTADO",0,K7))))) -> 0.33333333 | J7: =H7-I7 -> -0.33333333 | K7: =K6 -> 0.33333333 | L7: =L6+J7 -> -1.3333333
B8: =TEXT(C8,"DDDD") -> terça-feira | C8: =C7+1 -> 41339 | H8: =E8-D8+G8-F8 -> 0 | I8: =IF(B8="SÁBADO",0,IF(B8="DOMINGO",0,IF(A8="FERIADO",0,IF(A8="ABONADO",0,IF(A8="ATESTADO",0,K8))))) -> 0.33333333 | J8: =H8-I8 -> -0.33333333 | K8: =K7 -> 0.33333333 | L8: =L7+J8 -> -1.6666667
B9: =TEXT(C9,"DDDD") -> quarta-feira | C9: =C8+1 -> 41340 | H9: =E9-D9+G9-F9 -> 0 | I9: =IF(B9="SÁBADO",0,IF(B9="DOMINGO",0,IF(A9="FERIADO",0,IF(A9="ABONADO",0,IF(A9="ATESTADO",0,K9))))) -> 0.33333333 | J9: =H9-I9 -> -0.33333333 | K9: =K8 -> 0.33333333 | L9: =L8+J9 -> -2
B10: =TEXT(C10,"DDDD") -> quinta-feira | C10: =C9+1 -> 41341 | H10: =E10-D10+G10-F10 -> 0 | I10: =IF(B10="SÁBADO",0,IF(B10="DOMINGO",0,IF(A10="FERIADO",0,IF(A10="ABONADO",0,IF(A10="ATESTADO",0,K10))))) -> 0.33333333 | J10: =H10-I10 -> -0.33333333 | K10: =K9 -> 0.33333333 | L10: =L9+J10 -> -2.3333333
B11: =TEXT(C11,"DDDD") -> sexta-feira | C11: =C10+1 -> 41342 | H11: =E11-D11+G11-F11 -> 0 | I11: =IF(B11="SÁBADO",0,IF(B11="DOMINGO",0,IF(A11="FERIADO",0,IF(A11="ABONADO",0,IF(A11="ATESTADO",0,K11))))) -> 0.33333333 | J11: =H11-I11 -> -0.33333333 | K11: =K10 -> 0.33333333 | L11: =L10+J11 -> -2.6666667
B12: =TEXT(C12,"DDDD") -> sábado | C12: =C11+1 -> 41343 | H12: =E12-D12+G12-F12 -> 0 | I12: =IF(B12="SÁBADO",0,IF(B12="DOMINGO",0,IF(A12="FERIADO",0,IF(A12="ABONADO",0,IF(A12="ATESTADO",0,K12))))) -> 0 | J12: =H12-I12 -> 0 | K12: =K11 -> 0.33333333 | L12: =L11+J12 -> -2.6666667
B13: =TEXT(C13,"DDDD") -> domingo | C13: =C12+1 -> 41344 | H13: =E13-D13+G13-F13 -> 0 | I13: =IF(B13="SÁBADO",0,IF(B13="DOMINGO",0,IF(A13="FERIADO",0,IF(A13="ABONADO",0,IF(A13="ATESTADO",0,K13))))) -> 0 | J13: =H13-I13 -> 0 | K13: =K12 -> 0.33333333 | L13: =L12+J13 -> -2.6666667
B14: =TEXT(C14,"DDDD") -> segunda-feira | C14: =C13+1 -> 41345 | H14: =E14-D14+G14-F14 -> 0 | I14: =IF(B14="SÁBADO",0,IF(B14="DOMINGO",0,IF(A14="FERIADO",0,IF(A14="ABONADO",0,IF(A14="ATESTADO",0,K14))))) -> 0.33333333 | J14: =H14-I14 -> -0.33333333 | K14: =K13 -> 0.33333333 | L14: =L13+J14 -> -3
... B32: =TEXT(C32,"DDDD") -> sexta-feira | C32: =C31+1 -> 41363 | H32: =E32-D32+G32-F32 -> 0 | I32: =IF(B32="SÁBADO",0,IF(B32="DOMINGO",0,IF(A32="FERIADO",0,IF(A32="ABONADO",0,IF(A32="ATESTADO",0,K32))))) -> 0.33333333 | J32: =H32-I32 -> -0.33333333 | K32: =K31 -> 0.33333333 | L32: =L31+J32 -> -7.6666667
J33: =SUM(J2:J32) -> -7.6666667

Sheet ABRIL
A1: OBSERVAÇÃO | B1: DIA DA SEMANA | C1: DIA DO MÊS | D1: ENTRADA | E1: SAÍDA | F1: ENTRADA | G1: SAÍDA | H1: TOTAL DE HORAS NO DIA | J1: EXTRA X ATRASO | L1: ACUMULADO DIÁRIO | N1: DATA ATUAL | O1: =TODAY() -> 41466 | P1: =TEXT(O1,"DDDD") -> quarta-feira | Q1: =NOW() -> 41466.536
B2: =TEXT(C2,"DDDD") -> sábado | C2: =MARÇO!C32+1 -> 41364 | H2: =E2-D2+G2-F2 -> 0 | I2: =IF(B2="SÁBADO",0,IF(B2="DOMINGO",0,IF(A2="FERIADO",0,IF(A2="ABONADO",0,IF(A2="ATESTADO",0,K2))))) -> 0 | J2: =H2-I2 -> 0 | K2: =CADASTRO!B7 -> 0.33333333 | L2: =J2 -> 0
B3: =TEXT(C3,"DDDD") -> domingo | C3: =C2+1 -> 41365 | H3: =E3-D3+G3-F3 -> 0 | I3: =IF(B3="SÁBADO",0,IF(B3="DOMINGO",0,IF(A3="FERIADO",0,IF(A3="ABONADO",0,IF(A3="ATESTADO",0,K3))))) -> 0 | J3: =H3-I3 -> 0 | K3: =K2 -> 0.33333333 | L3: =L2+J3 -> 0
B4: =TEXT(C4,"DDDD") -> segunda-feira | C4: =C3+1 -> 41366 | H4: =E4-D4+G4-F4 -> 0 | I4: =IF(B4="SÁBADO",0,IF(B4="DOMINGO",0,IF(A4="FERIADO",0,IF(A4="ABONADO",0,IF(A4="ATESTADO",0,K4))))) -> 0.33333333 | J4: =H4-I4 -> -0.33333333 | K4: =K3 -> 0.33333333 | L4: =L3+J4 -> -0.33333333
B5: FERIADO | C5: =C4+1 -> 41367 | H5: =E5-D5+G5-F5 -> 0 | I5: =IF(B5="SÁBADO",0,IF(B5="DOMINGO",0,IF(A5="FERIADO",0,IF(A5="ABONADO",0,IF(A5="ATESTADO",0,K5))))) -> 0.33333333 | J5: =H5-I5 -> -0.33333333 | K5: =K4 -> 0.33333333 | L5: =L4+J5 -> -0.66666667
B6: =TEXT(C6,"DDDD") -> quarta-feira | C6: =C5+1 -> 41368 | H6: =E6-D6+G6-F6 -> 0 | I6: =IF(B6="SÁBADO",0,IF(B6="DOMINGO",0,IF(A6="FERIADO",0,IF(A6="ABONADO",0,IF(A6="ATESTADO",0,K6))))) -> 0.33333333 | J6: =H6-I6 -> -0.33333333 | K6: =K5 -> 0.33333333 | L6: =L5+J6 -> -1
B7: =TEXT(C7,"DDDD") -> quinta-feira | C7: =C6+1 -> 41369 | H7: =E7-D7+G7-F7 -> 0 | I7: =IF(B7="SÁBADO",0,IF(B7="DOMINGO",0,IF(A7="FERIADO",0,IF(A7="ABONADO",0,IF(A7="ATESTADO",0,K7))))) -> 0.33333333 | J7: =H7-I7 -> -0.33333333 | K7: =K6 -> 0.33333333 | L7: =L6+J7 -> -1.3333333
B8: =TEXT(C8,"DDDD") -> sexta-feira | C8: =C7+1 -> 41370 | H8: =E8-D8+G8-F8 -> 0 | I8: =IF(B8="SÁBADO",0,IF(B8="DOMINGO",0,IF(A8="FERIADO",0,IF(A8="ABONADO",0,IF(A8="ATESTADO",0,K8))))) -> 0.33333333 | J8: =H8-I8 -> -0.33333333 | K8: =K7 -> 0.33333333 | L8: =L7+J8 -> -1.6666667
B9: =TEXT(C9,"DDDD") -> sábado | C9: =C8+1 -> 41371 | H9: =E9-D9+G9-F9 -> 0 | I9: =IF(B9="SÁBADO",0,IF(B9="DOMINGO",0,IF(A9="FERIADO",0,IF(A9="ABONADO",0,IF(A9="ATESTADO",0,K9))))) -> 0 | J9: =H9-I9 -> 0 | K9: =K8 -> 0.33333333 | L9: =L8+J9 -> -1.6666667
B10: =TEXT(C10,"DDDD") -> domingo | C10: =C9+1 -> 41372 | H10: =E10-D10+G10-F10 -> 0 | I10: =IF(B10="SÁBADO",0,IF(B10="DOMINGO",0,IF(A10="FERIADO",0,IF(A10="ABONADO",0,IF(A10="ATESTADO",0,K10))))) -> 0 | J10: =H10-I10 -> 0 | K10: =K9 -> 0.33333333 | L10: =L9+J10 -> -1.6666667
B11: =TEXT(C11,"DDDD") -> segunda-feira | C11: =C10+1 -> 41373 | H11: =E11-D11+G11-F11 -> 0 | I11: =IF(B11="SÁBADO",0,IF(B11="DOMINGO",0,IF(A11="FERIADO",0,IF(A11="ABONADO",0,IF(A11="ATESTADO",0,K11))))) -> 0.33333333 | J11: =H11-I11 -> -0.33333333 | K11: =K10 -> 0.33333333 | L11: =L10+J11 -> -2
B12: =TEXT(C12,"DDDD") -> terça-feira | C12: =C11+1 -> 41374 | H12: =E12-D12+G12-F12 -> 0 | I12: =IF(B12="SÁBADO",0,IF(B12="DOMINGO",0,IF(A12="FERIADO",0,IF(A12="ABONADO",0,IF(A12="ATESTADO",0,K12))))) -> 0.33333333 | J12: =H12-I12 -> -0.33333333 | K12: =K11 -> 0.33333333 | L12: =L11+J12 -> -2.3333333
B13: =TEXT(C13,"DDDD") -> quarta-feira | C13: =C12+1 -> 41375 | H13: =E13-D13+G13-F13 -> 0 | I13: =IF(B13="SÁBADO",0,IF(B13="DOMINGO",0,IF(A13="FERIADO",0,IF(A13="ABONADO",0,IF(A13="ATESTADO",0,K13))))) -> 0.33333333 | J13: =H13-I13 -> -0.33333333 | K13: =K12 -> 0.33333333 | L13: =L12+J13 -> -2.6666667
B14: =TEXT(C14,"DDDD") -> quinta-feira | C14: =C13+1 -> 41376 | H14: =E14-D14+G14-F14 -> 0 | I14: =IF(B14="SÁBADO",0,IF(B14="DOMINGO",0,IF(A14="FERIADO",0,IF(A14="ABONADO",0,IF(A14="ATESTADO",0,K14))))) -> 0.33333333 | J14: =H14-I14 -> -0.33333333 | K14: =K13 -> 0.33333333 | L14: =L13+J14 -> -3
B15: =TEXT(C15,"DDDD") -> sexta-feira | C15: =C14+1 -> 41377 | H15: =E15-D15+G15-F15 -> 0 | I15: =IF(B15="SÁBADO",0,IF(B15="DOMINGO",0,IF(A15="FERIADO",0,IF(A15="ABONADO",0,IF(A15="ATESTADO",0,K15))))) -> 0.33333333 | J15: =H15-I15 -> -0.33333333 | K15: =K14 -> 0.33333333 | L15: =L14+J15 -> -3.3333333
B16: =TEXT(C16,"DDDD") -> sábado | C16: =C15+1 -> 41378 | H16: =E16-D16+G16-F16 -> 0 | I16: =IF(B16="SÁBADO",0,IF(B16="DOMINGO",0,IF(A16="FERIADO",0,IF(A16="ABONADO",0,IF(A16="ATESTADO",0,K16))))) -> 0 | J16: =H16-I16 -> 0 | K16: =K15 -> 0.33333333 | L16: =L15+J16 -> -3.3333333
B17: =TEXT(C17,"DDDD") -> domingo | C17: =C16+1 -> 41379 | H17: =E17-D17+G17-F17 -> 0 | I17: =IF(B17="SÁBADO",0,IF(B17="DOMINGO",0,IF(A17="FERIADO",0,IF(A17="ABONADO",0,IF(A17="ATESTADO",0,K17))))) -> 0 | J17: =H17-I17 -> 0 | K17: =K16 -> 0.33333333 | L17: =L16+J17 -> -3.3333333
... B21: =TEXT(C21,"DDDD") -> quinta-feira | C21: =C20+1 -> 41383 | H21: =E21-D21+G21-F21 -> 0 | I21: =IF(B21="SÁBADO",0,IF(B21="DOMINGO",0,IF(A21="FERIADO",0,IF(A21="ABONADO",0,IF(A21="ATESTADO",0,K21))))) -> 0.33333333 | J21: =H21-I21 -> -0.33333333 | K21: =K20 -> 0.33333333 | L21: =L20+J21 -> -4.6666667
B22: FERIADO | C22: =C21+1 -> 41384 | H22: =E22-D22+G22-F22 -> 0 | I22: =IF(B22="SÁBADO",0,IF(B22="DOMINGO",0,IF(A22="FERIADO",0,IF(A22="ABONADO",0,IF(A22="ATESTADO",0,K22))))) -> 0.33333333 | J22: =H22-I22 -> -0.33333333 | K22: =K21 -> 0.33333333 | L22: =L21+J22 -> -5
B23: =TEXT(C23,"DDDD") -> sábado | C23: =C22+1 -> 41385 | H23: =E23-D23+G23-F23 -> 0 | I23: =IF(B23="SÁBADO",0,IF(B23="DOMINGO",0,IF(A23="FERIADO",0,IF(A23="ABONADO",0,IF(A23="ATESTADO",0,K23))))) -> 0 | J23: =H23-I23 -> 0 | K23: =K22 -> 0.33333333 | L23: =L22+J23 -> -5
B24: =TEXT(C24,"DDDD") -> domingo | C24: =C23+1 -> 41386 | H24: =E24-D24+G24-F24 -> 0 | I24: =IF(B24="SÁBADO",0,IF(B24="DOMINGO",0,IF(A24="FERIADO",0,IF(A24="ABONADO",0,IF(A24="ATESTADO",0,K24))))) -> 0 | J24: =H24-I24 -> 0 | K24: =K23 -> 0.33333333 | L24: =L23+J24 -> -5
B25: =TEXT(C25,"DDDD") -> segunda-feira | C25: =C24+1 -> 41387 | H25: =E25-D25+G25-F25 -> 0 | I25: =IF(B25="SÁBADO",0,IF(B25="DOMINGO",0,IF(A25="FERIADO",0,IF(A25="ABONADO",0,IF(A25="ATESTADO",0,K25))))) -> 0.33333333 | J25: =H25-I25 -> -0.33333333 | K25: =K24 -> 0.33333333 | L25: =L24+J25 -> -5.3333333
B26: =TEXT(C26,"DDDD") -> terça-feira | C26: =C25+1 -> 41388 | H26: =E26-D26+G26-F26 -> 0 | I26: =IF(B26="SÁBADO",0,IF(B26="DOMINGO",0,IF(A26="FERIADO",0,IF(A26="ABONADO",0,IF(A26="ATESTADO",0,K26))))) -> 0.33333333 | J26: =H26-I26 -> -0.33333333 | K26: =K25 -> 0.33333333 | L26: =L25+J26 -> -5.6666667
B27: =TEXT(C27,"DDDD") -> quarta-feira | C27: =C26+1 -> 41389 | H27: =E27-D27+G27-F27 -> 0 | I27: =IF(B27="SÁBADO",0,IF(B27="DOMINGO",0,IF(A27="FERIADO",0,IF(A27="ABONADO",0,IF(A27="ATESTADO",0,K27))))) -> 0.33333333 | J27: =H27-I27 -> -0.33333333 | K27: =K26 -> 0.33333333 | L27: =L26+J27 -> -6
B28: =TEXT(C28,"DDDD") -> quinta-feira | C28: =C27+1 -> 41390 | H28: =E28-D28+G28-F28 -> 0 | I28: =IF(B28="SÁBADO",0,IF(B28="DOMINGO",0,IF(A28="FERIADO",0,IF(A28="ABONADO",0,IF(A28="ATESTADO",0,K28))))) -> 0.33333333 | J28: =H28-I28 -> -0.33333333 | K28: =K27 -> 0.33333333 | L28: =L27+J28 -> -6.3333333
B29: =TEXT(C29,"DDDD") -> sexta-feira | C29: =C28+1 -> 41391 | H29: =E29-D29+G29-F29 -> 0 | I29: =IF(B29="SÁBADO",0,IF(B29="DOMINGO",0,IF(A29="FERIADO",0,IF(A29="ABONADO",0,IF(A29="ATESTADO",0,K29))))) -> 0.33333333 | J29: =H29-I29 -> -0.33333333 | K29: =K28 -> 0.33333333 | L29: =L28+J29 -> -6.6666667
B30: =TEXT(C30,"DDDD") -> sábado | C30: =C29+1 -> 41392 | H30: =E30-D30+G30-F30 -> 0 | I30: =IF(B30="SÁBADO",0,IF(B30="DOMINGO",0,IF(A30="FERIADO",0,IF(A30="ABONADO",0,IF(A30="ATESTADO",0,K30))))) -> 0 | J30: =H30-I30 -> 0 | K30: =K29 -> 0.33333333 | L30: =L29+J30 -> -6.6666667
B31: =TEXT(C31,"DDDD") -> domingo | C31: =C30+1 -> 41393 | H31: =E31-D31+G31-F31 -> 0 | I31: =IF(B31="SÁBADO",0,IF(B31="DOMINGO",0,IF(A31="FERIADO",0,IF(A31="ABONADO",0,IF(A31="ATESTADO",0,K31))))) -> 0 | J31: =H31-I31 -> 0 | K31: =K30 -> 0.33333333 | L31: =L30+J31 -> -6.6666667
J32: =SUM(J2:J31) -> -6.6666667

Sheet MAIO
A1: OBSERVAÇÃO | B1: DIA DA SEMANA | C1: DIA DO MÊS | D1: ENTRADA | E1: SAÍDA | F1: ENTRADA | G1: SAÍDA | H1: TOTAL DE HORAS NO DIA | J1: EXTRA X ATRASO | L1: ACUMULADO DIÁRIO | O1: DATA ATUAL | P1: =TODAY() -> 41466 | Q1: =TEXT(P1,"DDDD") -> quarta-feira | R1: =NOW() -> 41466.536
B2: =TEXT(C2,"DDDD") -> segunda-feira | C2: =ABRIL!C31+1 -> 41394 | H2: =E2-D2+G2-F2 -> 0 | I2: =IF(B2="SÁBADO",0,IF(B2="DOMINGO",0,IF(A2="FERIADO",0,IF(A2="ABONADO",0,IF(A2="ATESTADO",0,K2))))) -> 0.33333333 | J2: =H2-I2 -> -0.33333333 | K2: =CADASTRO!B9 -> 0.33333333 | L2: =J2 -> -0.33333333
B3: =TEXT(C3,"DDDD") -> terça-feira | C3: =C2+1 -> 41395 | H3: =E3-D3+G3-F3 -> 0 | I3: =IF(B3="SÁBADO",0,IF(B3="DOMINGO",0,IF(A3="FERIADO",0,IF(A3="ABONADO",0,IF(A3="ATESTADO",0,K3))))) -> 0.33333333 | J3: =H3-I3 -> -0.33333333 | K3: =K2 -> 0.33333333 | L3: =L2+J3 -> -0.66666667
B4: =TEXT(C4,"DDDD") -> quarta-feira | C4: =C3+1 -> 41396 | H4: =E4-D4+G4-F4 -> 0 | I4: =IF(B4="SÁBADO",0,IF(B4="DOMINGO",0,IF(A4="FERIADO",0,IF(A4="ABONADO",0,IF(A4="ATESTADO",0,K4))))) -> 0.33333333 | J4: =H4-I4 -> -0.33333333 | K4: =K3 -> 0.33333333 | L4: =L3+J4 -> -1
B5: =TEXT(C5,"DDDD") -> quinta-feira | C5: =C4+1 -> 41397 | H5: =E5-D5+G5-F5 -> 0 | I5: =IF(B5="SÁBADO",0,IF(B5="DOMINGO",0,IF(A5="FERIADO",0,IF(A5="ABONADO",0,IF(A5="ATESTADO",0,K5))))) -> 0.33333333 | J5: =H5-I5 -> -0.33333333 | K5: =K4 -> 0.33333333 | L5: =L4+J5 -> -1.3333333
B6: =TEXT(C6,"DDDD") -> sexta-feira | C6: =C5+1 -> 41398 | H6: =E6-D6+G6-F6 -> 0 | I6: =IF(B6="SÁBADO",0,IF(B6="DOMINGO",0,IF(A6="FERIADO",0,IF(A6="ABONADO",0,IF(A6="ATESTADO",0,K6))))) -> 0.33333333 | J6: =H6-I6 -> -0.33333333 | K6: =K5 -> 0.33333333 | L6: =L5+J6 -> -1.6666667
B7: =TEXT(C7,"DDDD") -> sábado | C7: =C6+1 -> 41399 | H7: =E7-D7+G7-F7 -> 0 | I7: =IF(B7="SÁBADO",0,IF(B7="DOMINGO",0,IF(A7="FERIADO",0,IF(A7="ABONADO",0,IF(A7="ATESTADO",0,K7))))) -> 0 | J7: =H7-I7 -> 0 | K7: =K6 -> 0.33333333 | L7: =L6+J7 -> -1.6666667
B8: =TEXT(C8,"DDDD") -> domingo | C8: =C7+1 -> 41400 | H8: =E8-D8+G8-F8 -> 0 | I8: =IF(B8="SÁBADO",0,IF(B8="DOMINGO",0,IF(A8="FERIADO",0,IF(A8="ABONADO",0,IF(A8="ATESTADO",0,K8))))) -> 0 | J8: =H8-I8 -> 0 | K8: =K7 -> 0.33333333 | L8: =L7+J8 -> -1.6666667
B9: =TEXT(C9,"DDDD") -> segunda-feira | C9: =C8+1 -> 41401 | H9: =E9-D9+G9-F9 -> 0 | I9: =IF(B9="SÁBADO",0,IF(B9="DOMINGO",0,IF(A9="FERIADO",0,IF(A9="ABONADO",0,IF(A9="ATESTADO",0,K9))))) -> 0.33333333 | J9: =H9-I9 -> -0.33333333 | K9: =K8 -> 0.33333333 | L9: =L8+J9 -> -2
B10: =TEXT(C10,"DDDD") -> terça-feira | C10: =C9+1 -> 41402 | H10: =E10-D10+G10-F10 -> 0 | I10: =IF(B10="SÁBADO",0,IF(B10="DOMINGO",0,IF(A10="FERIADO",0,IF(A10="ABONADO",0,IF(A10="ATESTADO",0,K10))))) -> 0.33333333 | J10: =H10-I10 -> -0.33333333 | K10: =K9 -> 0.33333333 | L10: =L9+J10 -> -2.3333333
B11: =TEXT(C11,"DDDD") -> quarta-feira | C11: =C10+1 -> 41403 | H11: =E11-D11+G11-F11 -> 0 | I11: =IF(B11="SÁBADO",0,IF(B11="DOMINGO",0,IF(A11="FERIADO",0,IF(A11="ABONADO",0,IF(A11="ATESTADO",0,K11))))) -> 0.33333333 | J11: =H11-I11 -> -0.33333333 | K11: =K10 -> 0.33333333 | L11: =L10+J11 -> -2.6666667
B12: =TEXT(C12,"DDDD") -> quinta-feira | C12: =C11+1 -> 41404 | H12: =E12-D12+G12-F12 -> 0 | I12: =IF(B12="SÁBADO",0,IF(B12="DOMINGO",0,IF(A12="FERIADO",0,IF(A12="ABONADO",0,IF(A12="ATESTADO",0,K12))))) -> 0.33333333 | J12: =H12-I12 -> -0.33333333 | K12: =K11 -> 0.33333333 | L12: =L11+J12 -> -3
B13: =TEXT(C13,"DDDD") -> sexta-feira | C13: =C12+1 -> 41405 | H13: =E13-D13+G13-F13 -> 0 | I13: =IF(B13="SÁBADO",0,IF(B13="DOMINGO",0,IF(A13="FERIADO",0,IF(A13="ABONADO",0,IF(A13="ATESTADO",0,K13))))) -> 0.33333333 | J13: =H13-I13 -> -0.33333333 | K13: =K12 -> 0.33333333 | L13: =L12+J13 -> -3.3333333
B14: =TEXT(C14,"DDDD") -> sábado | C14: =C13+1 -> 41406 | H14: =E14-D14+G14-F14 -> 0 | I14: =IF(B14="SÁBADO",0,IF(B14="DOMINGO",0,IF(A14="FERIADO",0,IF(A14="ABONADO",0,IF(A14="ATESTADO",0,K14))))) -> 0 | J14: =H14-I14 -> 0 | K14: =K13 -> 0.33333333 | L14: =L13+J14 -> -3.3333333
... B26: =TEXT(C26,"DDDD") -> quinta-feira | C26: =C25+1 -> 41418 | H26: =E26-D26+G26-F26 -> 0 | I26: =IF(B26="SÁBADO",0,IF(B26="DOMINGO",0,IF(A26="FERIADO",0,IF(A26="ABONADO",0,IF(A26="ATESTADO",0,K26))))) -> 0.33333333 | J26: =H26-I26 -> -0.33333333 | K26: =K25 -> 0.33333333 | L26: =L25+J26 -> -6.3333333
B27: FERIADO | C27: =C26+1 -> 41419 | H27: =E27-D27+G27-F27 -> 0 | I27: =IF(B27="SÁBADO",0,IF(B27="DOMINGO",0,IF(A27="FERIADO",0,IF(A27="ABONADO",0,IF(A27="ATESTADO",0,K27))))) -> 0.33333333 | J27: =H27-I27 -> -0.33333333 | K27: =K26 -> 0.33333333 | L27: =L26+J27 -> -6.6666667
B28: FERIADO | C28: =C27+1 -> 41420 | H28: =E28-D28+G28-F28 -> 0 | I28: =IF(B28="SÁBADO",0,IF(B28="DOMINGO",0,IF(A28="FERIADO",0,IF(A28="ABONADO",0,IF(A28="ATESTADO",0,K28))))) -> 0.33333333 | J28: =H28-I28 -> -0.33333333 | K28: =K27 -> 0.33333333 | L28: =L27+J28 -> -7
B29: =TEXT(C29,"DDDD") -> domingo | C29: =C28+1 -> 41421 | H29: =E29-D29+G29-F29 -> 0 | I29: =IF(B29="SÁBADO",0,IF(B29="DOMINGO",0,IF(A29="FERIADO",0,IF(A29="ABONADO",0,IF(A29="ATESTADO",0,K29))))) -> 0 | J29: =H29-I29 -> 0 | K29: =K28 -> 0.33333333 | L29: =L28+J29 -> -7
B30: =TEXT(C30,"DDDD") -> segunda-feira | C30: =C29+1 -> 41422 | H30: =E30-D30+G30-F30 -> 0 | I30: =IF(B30="SÁBADO",0,IF(B30="DOMINGO",0,IF(A30="FERIADO",0,IF(A30="ABONADO",0,IF(A30="ATESTADO",0,K30))))) -> 0.33333333 | J30: =H30-I30 -> -0.33333333 | K30: =K29 -> 0.33333333 | L30: =L29+J30 -> -7.3333333
B31: =TEXT(C31,"DDDD") -> terça-feira | C31: =C30+1 -> 41423 | H31: =E31-D31+G31-F31 -> 0 | I31: =IF(B31="SÁBADO",0,IF(B31="DOMINGO",0,IF(A31="FERIADO",0,IF(A31="ABONADO",0,IF(A31="ATESTADO",0,K31))))) -> 0.33333333 | J31: =H31-I31 -> -0.33333333 | K31: =K30 -> 0.33333333 | L31: =L30+J31 -> -7.6666667
B32: =TEXT(C32,"DDDD") -> quarta-feira | C32: =C31+1 -> 41424 | H32: =E32-D32+G32-F32 -> 0 | I32: =IF(B32="SÁBADO",0,IF(B32="DOMINGO",0,IF(A32="FERIADO",0,IF(A32="ABONADO",0,IF(A32="ATESTADO",0,K32))))) -> 0.33333333 | J32: =H32-I32 -> -0.33333333 | K32: =K31 -> 0.33333333 | L32: =L31+J32 -> -8
J33: =SUM(J2:J32) -> -8

Sheet JUNHO
A1: OBSERVAÇÃO | B1: DIA DA SEMANA | C1: DIA DO MÊS | D1: ENTRADA | E1: SAÍDA | F1: ENTRADA | G1: SAÍDA | H1: TOTAL DE HORAS NO DIA | J1: EXTRA X ATRASO | L1: ACUMULADO DIÁRIO | N1: DATA ATUAL | O1: =TODAY() -> 41466 | P1: =TEXT(O1,"DDDD") -> quarta-feira | Q1: =NOW() -> 41466.536
B2: =TEXT(C2,"DDDD") -> quinta-feira | C2: =MAIO!C32+1 -> 41425 | H2: =E2-D2+G2-F2 -> 0 | I2: =IF(B2="SÁBADO",0,IF(B2="DOMINGO",0,IF(A2="FERIADO",0,IF(A2="ABONADO",0,IF(A2="ATESTADO",0,K2))))) -> 0.33333333 | J2: =H2-I2 -> -0.33333333 | K2: =CADASTRO!B11 -> 0.33333333 | L2: =J2 -> -0.33333333
B3: =TEXT(C3,"DDDD") -> sexta-feira | C3: =C2+1 -> 41426 | H3: =E3-D3+G3-F3 -> 0 | I3: =IF(B3="SÁBADO",0,IF(B3="DOMINGO",0,IF(A3="FERIADO",0,IF(A3="ABONADO",0,IF(A3="ATESTADO",0,K3))))) -> 0.33333333 | J3: =H3-I3 -> -0.33333333 | K3: =K2 -> 0.33333333 | L3: =L2+J3 -> -0.66666667
B4: =TEXT(C4,"DDDD") -> sábado | C4: =C3+1 -> 41427 | H4: =E4-D4+G4-F4 -> 0 | I4: =IF(B4="SÁBADO",0,IF(B4="DOMINGO",0,IF(A4="FERIADO",0,IF(A4="ABONADO",0,IF(A4="ATESTADO",0,K4))))) -> 0 | J4: =H4-I4 -> 0 | K4: =K3 -> 0.33333333 | L4: =L3+J4 -> -0.66666667
B5: =TEXT(C5,"DDDD") -> domingo | C5: =C4+1 -> 41428 | H5: =E5-D5+G5-F5 -> 0 | I5: =IF(B5="SÁBADO",0,IF(B5="DOMINGO",0,IF(A5="FERIADO",0,IF(A5="ABONADO",0,IF(A5="ATESTADO",0,K5))))) -> 0 | J5: =H5-I5 -> 0 | K5: =K4 -> 0.33333333 | L5: =L4+J5 -> -0.66666667
B6: =TEXT(C6,"DDDD") -> segunda-feira | C6: =C5+1 -> 41429 | H6: =E6-D6+G6-F6 -> 0 | I6: =IF(B6="SÁBADO",0,IF(B6="DOMINGO",0,IF(A6="FERIADO",0,IF(A6="ABONADO",0,IF(A6="ATESTADO",0,K6))))) -> 0.33333333 | J6: =H6-I6 -> -0.33333333 | K6: =K5 -> 0.33333333 | L6: =L5+J6 -> -1
B7: =TEXT(C7,"DDDD") -> terça-feira | C7: =C6+1 -> 41430 | H7: =E7-D7+G7-F7 -> 0 | I7: =IF(B7="SÁBADO",0,IF(B7="DOMINGO",0,IF(A7="FERIADO",0,IF(A7="ABONADO",0,IF(A7="ATESTADO",0,K7))))) -> 0.33333333 | J7: =H7-I7 -> -0.33333333 | K7: =K6 -> 0.33333333 | L7: =L6+J7 -> -1.3333333
B8: =TEXT(C8,"DDDD") -> quarta-feira | C8: =C7+1 -> 41431 | H8: =E8-D8+G8-F8 -> 0 | I8: =IF(B8="SÁBADO",0,IF(B8="DOMINGO",0,IF(A8="FERIADO",0,IF(A8="ABONADO",0,IF(A8="ATESTADO",0,K8))))) -> 0.33333333 | J8: =H8-I8 -> -0.33333333 | K8: =K7 -> 0.33333333 | L8: =L7+J8 -> -1.6666667
B9: =TEXT(C9,"DDDD") -> quinta-feira | C9: =C8+1 -> 41432 | H9: =E9-D9+G9-F9 -> 0 | I9: =IF(B9="SÁBADO",0,IF(B9="DOMINGO",0,IF(A9="FERIADO",0,IF(A9="ABONADO",0,IF(A9="ATESTADO",0,K9))))) -> 0.33333333 | J9: =H9-I9 -> -0.33333333 | K9: =K8 -> 0.33333333 | L9: =L8+J9 -> -2
B10: =TEXT(C10,"DDDD") -> sexta-feira | C10: =C9+1 -> 41433 | H10: =E10-D10+G10-F10 -> 0 | I10: =IF(B10="SÁBADO",0,IF(B10="DOMINGO",0,IF(A10="FERIADO",0,IF(A10="ABONADO",0,IF(A10="ATESTADO",0,K10))))) -> 0.33333333 | J10: =H10-I10 -> -0.33333333 | K10: =K9 -> 0.33333333 | L10: =L9+J10 -> -2.3333333
B11: =TEXT(C11,"DDDD") -> sábado | C11: =C10+1 -> 41434 | H11: =E11-D11+G11-F11 -> 0 | I11: =IF(B11="SÁBADO",0,IF(B11="DOMINGO",0,IF(A11="FERIADO",0,IF(A11="ABONADO",0,IF(A11="ATESTADO",0,K11))))) -> 0 | J11: =H11-I11 -> 0 | K11: =K10 -> 0.33333333 | L11: =L10+J11 -> -2.3333333
B12: =TEXT(C12,"DDDD") -> domingo | C12: =C11+1 -> 41435 | H12: =E12-D12+G12-F12 -> 0 | I12: =IF(B12="SÁBADO",0,IF(B12="DOMINGO",0,IF(A12="FERIADO",0,IF(A12="ABONADO",0,IF(A12="ATESTADO",0,K12))))) -> 0 | J12: =H12-I12 -> 0 | K12: =K11 -> 0.33333333 | L12: =L11+J12 -> -2.3333333
B13: =TEXT(C13,"DDDD") -> segunda-feira | C13: =C12+1 -> 41436 | H13: =E13-D13+G13-F13 -> 0 | I13: =IF(B13="SÁBADO",0,IF(B13="DOMINGO",0,IF(A13="FERIADO",0,IF(A13="ABONADO",0,IF(A13="ATESTADO",0,K13))))) -> 0.33333333 | J13: =H13-I13 -> -0.33333333 | K13: =K12 -> 0.33333333 | L13: =L12+J13 -> -2.6666667
B14: =TEXT(C14,"DDDD") -> terça-feira | C14: =C13+1 -> 41437 | H14: =E14-D14+G14-F14 -> 0 | I14: =IF(B14="SÁBADO",0,IF(B14="DOMINGO",0,IF(A14="FERIADO",0,IF(A14="ABONADO",0,IF(A14="ATESTADO",0,K14))))) -> 0.33333333 | J14: =H14-I14 -> -0.33333333 | K14: =K13 -> 0.33333333 | L14: =L13+J14 -> -3
... B31: =TEXT(C31,"DDDD") -> sexta-feira | C31: =C30+1 -> 41454 | H31: =E31-D31+G31-F31 -> 0 | I31: =IF(B31="SÁBADO",0,IF(B31="DOMINGO",0,IF(A31="FERIADO",0,IF(A31="ABONADO",0,IF(A31="ATESTADO",0,K31))))) -> 0.33333333 | J31: =H31-I31 -> -0.33333333 | K31: =K30 -> 0.33333333 | L31: =L30+J31 -> -7.3333333
J32: =SUM(J2:J31) -> -7.3333333

Sheet JULHO
A1: OBSERVAÇÃO | B1: DIA DA SEMANA | C1: DIA DO MÊS | D1: ENTRADA | E1: SAÍDA | F1: ENTRADA | G1: SAÍDA | H1: TOTAL DE HORAS NO DIA | J1: EXTRA X ATRASO | L1: ACUMULADO DIÁRIO | N1: DATA ATUAL | O1: =TODAY() -> 41466 | P1: =TEXT(O1,"DDDD") -> quarta-feira | Q1: =NOW() -> 41466.536
B2: =TEXT(C2,"DDDD") -> sábado | C2: =JUNHO!C31+1 -> 41455 | H2: =E2-D2+G2-F2 -> 0 | I2: =IF(B2="SÁBADO",0,IF(B2="DOMINGO",0,IF(A2="FERIADO",0,IF(A2="ABONADO",0,IF(A2="ATESTADO",0,K2))))) -> 0 | J2: =H2-I2 -> 0 | K2: =CADASTRO!B13 -> 0.33333333 | L2: =J2 -> 0
B3: =TEXT(C3,"DDDD") -> domingo | C3: =C2+1 -> 41456 | H3: =E3-D3+G3-F3 -> 0 | I3: =IF(B3="SÁBADO",0,IF(B3="DOMINGO",0,IF(A3="FERIADO",0,IF(A3="ABONADO",0,IF(A3="ATESTADO",0,K3))))) -> 0 | J3: =H3-I3 -> 0 | K3: =K2 -> 0.33333333 | L3: =L2+J3 -> 0
B4: =TEXT(C4,"DDDD") -> segunda-feira | C4: =C3+1 -> 41457 | H4: =E4-D4+G4-F4 -> 0 | I4: =IF(B4="SÁBADO",0,IF(B4="DOMINGO",0,IF(A4="FERIADO",0,IF(A4="ABONADO",0,IF(A4="ATESTADO",0,K4))))) -> 0.33333333 | J4: =H4-I4 -> -0.33333333 | K4: =K3 -> 0.33333333 | L4: =L3+J4 -> -0.33333333
B5: =TEXT(C5,"DDDD") -> terça-feira | C5: =C4+1 -> 41458 | H5: =E5-D5+G5-F5 -> 0 | I5: =IF(B5="SÁBADO",0,IF(B5="DOMINGO",0,IF(A5="FERIADO",0,IF(A5="ABONADO",0,IF(A5="ATESTADO",0,K5))))) -> 0.33333333 | J5: =H5-I5 -> -0.33333333 | K5: =K4 -> 0.33333333 | L5: =L4+J5 -> -0.66666667
B6: =TEXT(C6,"DDDD") -> quarta-feira | C6: =C5+1 -> 41459 | H6: =E6-D6+G6-F6 -> 0 | I6: =IF(B6="SÁBADO",0,IF(B6="DOMINGO",0,IF(A6="FERIADO",0,IF(A6="ABONADO",0,IF(A6="ATESTADO",0,K6))))) -> 0.33333333 | J6: =H6-I6 -> -0.33333333 | K6: =K5 -> 0.33333333 | L6: =L5+J6 -> -1
B7: =TEXT(C7,"DDDD") -> quinta-feira | C7: =C6+1 -> 41460 | H7: =E7-D7+G7-F7 -> 0 | I7: =IF(B7="SÁBADO",0,IF(B7="DOMINGO",0,IF(A7="FERIADO",0,IF(A7="ABONADO",0,IF(A7="ATESTADO",0,K7))))) -> 0.33333333 | J7: =H7-I7 -> -0.33333333 | K7: =K6 -> 0.33333333 | L7: =L6+J7 -> -1.3333333
B8: =TEXT(C8,"DDDD") -> sexta-feira | C8: =C7+1 -> 41461 | H8: =E8-D8+G8-F8 -> 0 | I8: =IF(B8="SÁBADO",0,IF(B8="DOMINGO",0,IF(A8="FERIADO",0,IF(A8="ABONADO",0,IF(A8="ATESTADO",0,K8))))) -> 0.33333333 | J8: =H8-I8 -> -0.33333333 | K8: =K7 -> 0.33333333 | L8: =L7+J8 -> -1.6666667
B9: =TEXT(C9,"DDDD") -> sábado | C9: =C8+1 -> 41462 | H9: =E9-D9+G9-F9 -> 0 | I9: =IF(B9="SÁBADO",0,IF(B9="DOMINGO",0,IF(A9="FERIADO",0,IF(A9="ABONADO",0,IF(A9="ATESTADO",0,K9))))) -> 0 | J9: =H9-I9 -> 0 | K9: =K8 -> 0.33333333 | L9: =L8+J9 -> -1.6666667
B10: =TEXT(C10,"DDDD") -> domingo | C10: =C9+1 -> 41463 | H10: =E10-D10+G10-F10 -> 0 | I10: =IF(B10="SÁBADO",0,IF(B10="DOMINGO",0,IF(A10="FERIADO",0,IF(A10="ABONADO",0,IF(A10="ATESTADO",0,K10))))) -> 0 | J10: =H10-I10 -> 0 | K10: =K9 -> 0.33333333 | L10: =L9+J10 -> -1.6666667
B11: =TEXT(C11,"DDDD") -> segunda-feira | C11: =C10+1 -> 41464 | H11: =E11-D11+G11-F11 -> 0 | I11: =IF(B11="SÁBADO",0,IF(B11="DOMINGO",0,IF(A11="FERIADO",0,IF(A11="ABONADO",0,IF(A11="ATESTADO",0,K11))))) -> 0.33333333 | J11: =H11-I11 -> -0.33333333 | K11: =K10 -> 0.33333333 | L11: =L10+J11 -> -2
B12: =TEXT(C12,"DDDD") -> terça-feira | C12: =C11+1 -> 41465 | H12: =E12-D12+G12-F12 -> 0 | I12: =IF(B12="SÁBADO",0,IF(B12="DOMINGO",0,IF(A12="FERIADO",0,IF(A12="ABONADO",0,IF(A12="ATESTADO",0,K12))))) -> 0.33333333 | J12: =H12-I12 -> -0.33333333 | K12: =K11 -> 0.33333333 | L12: =L11+J12 -> -2.3333333
B13: =TEXT(C13,"DDDD") -> quarta-feira | C13: =C12+1 -> 41466 | H13: =E13-D13+G13-F13 -> 0 | I13: =IF(B13="SÁBADO",0,IF(B13="DOMINGO",0,IF(A13="FERIADO",0,IF(A13="ABONADO",0,IF(A13="ATESTADO",0,K13))))) -> 0.33333333 | J13: =H13-I13 -> -0.33333333 | K13: =K12 -> 0.33333333 | L13: =L12+J13 -> -2.6666667
B14: =TEXT(C14,"DDDD") -> quinta-feira | C14: =C13+1 -> 41467 | H14: =E14-D14+G14-F14 -> 0 | I14: =IF(B14="SÁBADO",0,IF(B14="DOMINGO",0,IF(A14="FERIADO",0,IF(A14="ABONADO",0,IF(A14="ATESTADO",0,K14))))) -> 0.33333333 | J14: =H14-I14 -> -0.33333333 | K14: =K13 -> 0.33333333 | L14: =L13+J14 -> -3
... B32: =TEXT(C32,"DDDD") -> segunda-feira | C32: =C31+1 -> 41485 | H32: =E32-D32+G32-F32 -> 0 | I32: =IF(B32="SÁBADO",0,IF(B32="DOMINGO",0,IF(A32="FERIADO",0,IF(A32="ABONADO",0,IF(A32="ATESTADO",0,K32))))) -> 0.33333333 | J32: =H32-I32 -> -0.33333333 | K32: =K31 -> 0.33333333 | L32: =L31+J32 -> -7
J33: =SUM(J2:J32) -> -7

Sheet AGOSTO
A1: OBSERVAÇÃO | B1: DIA DA SEMANA | C1: DIA DO MÊS | D1: ENTRADA | E1: SAÍDA | F1: ENTRADA | G1: SAÍDA | H1: TOTAL DE HORAS NO DIA | J1: EXTRA X ATRASO | L1: ACUMULADO DIÁRIO | N1: DATA ATUAL | O1: =TODAY() -> 41466 | P1: =TEXT(O1,"DDDD") -> quarta-feira | Q1: =NOW() -> 41466.536
B2: =TEXT(C2,"DDDD") -> terça-feira | C2: =JULHO!C32+1 -> 41486 | H2: =E2-D2+G2-F2 -> 0 | I2: =IF(B2="SÁBADO",0,IF(B2="DOMINGO",0,IF(A2="FERIADO",0,IF(A2="ABONADO",0,IF(A2="ATESTADO",0,K2))))) -> 0.33333333 | J2: =H2-I2 -> -0.33333333 | K2: =CADASTRO!B15 -> 0.33333333 | L2: =J2 -> -0.33333333
B3: =TEXT(C3,"DDDD") -> quarta-feira | C3: =C2+1 -> 41487 | H3: =E3-D3+G3-F3 -> 0 | I3: =IF(B3="SÁBADO",0,IF(B3="DOMINGO",0,IF(A3="FERIADO",0,IF(A3="ABONADO",0,IF(A3="ATESTADO",0,K3))))) -> 0.33333333 | J3: =H3-I3 -> -0.33333333 | K3: =K2 -> 0.33333333 | L3: =L2+J3 -> -0.66666667
B4: =TEXT(C4,"DDDD") -> quinta-feira | C4: =C3+1 -> 41488 | H4: =E4-D4+G4-F4 -> 0 | I4: =IF(B4="SÁBADO",0,IF(B4="DOMINGO",0,IF(A4="FERIADO",0,IF(A4="ABONADO",0,IF(A4="ATESTADO",0,K4))))) -> 0.33333333 | J4: =H4-I4 -> -0.33333333 | K4: =K3 -> 0.33333333 | L4: =L3+J4 -> -1
B5: =TEXT(C5,"DDDD") -> sexta-feira | C5: =C4+1 -> 41489 | H5: =E5-D5+G5-F5 -> 0 | I5: =IF(B5="SÁBADO",0,IF(B5="DOMINGO",0,IF(A5="FERIADO",0,IF(A5="ABONADO",0,IF(A5="ATESTADO",0,K5))))) -> 0.33333333 | J5: =H5-I5 -> -0.33333333 | K5: =K4 -> 0.33333333 | L5: =L4+J5 -> -1.3333333
B6: =TEXT(C6,"DDDD") -> sábado | C6: =C5+1 -> 41490 | H6: =E6-D6+G6-F6 -> 0 | I6: =IF(B6="SÁBADO",0,IF(B6="DOMINGO",0,IF(A6="FERIADO",0,IF(A6="ABONADO",0,IF(A6="ATESTADO",0,K6))))) -> 0 | J6: =H6-I6 -> 0 | K6: =K5 -> 0.33333333 | L6: =L5+J6 -> -1.3333333
B7: =TEXT(C7,"DDDD") -> domingo | C7: =C6+1 -> 41491 | H7: =E7-D7+G7-F7 -> 0 | I7: =IF(B7="SÁBADO",0,IF(B7="DOMINGO",0,IF(A7="FERIADO",0,IF(A7="ABONADO",0,IF(A7="ATESTADO",0,K7))))) -> 0 | J7: =H7-I7 -> 0 | K7: =K6 -> 0.33333333 | L7: =L6+J7 -> -1.3333333
B8: =TEXT(C8,"DDDD") -> segunda-feira | C8: =C7+1 -> 41492 | H8: =E8-D8+G8-F8 -> 0 | I8: =IF(B8="SÁBADO",0,IF(B8="DOMINGO",0,IF(A8="FERIADO",0,IF(A8="ABONADO",0,IF(A8="ATESTADO",0,K8))))) -> 0.33333333 | J8: =H8-I8 -> -0.33333333 | K8: =K7 -> 0.33333333 | L8: =L7+J8 -> -1.6666667
B9: =TEXT(C9,"DDDD") -> terça-feira | C9: =C8+1 -> 41493 | H9: =E9-D9+G9-F9 -> 0 | I9: =IF(B9="SÁBADO",0,IF(B9="DOMINGO",0,IF(A9="FERIADO",0,IF(A9="ABONADO",0,IF(A9="ATESTADO",0,K9))))) -> 0.33333333 | J9: =H9-I9 -> -0.33333333 | K9: =K8 -> 0.33333333 | L9: =L8+J9 -> -2
B10: =TEXT(C10,"DDDD") -> quarta-feira | C10: =C9+1 -> 41494 | H10: =E10-D10+G10-F10 -> 0 | I10: =IF(B10="SÁBADO",0,IF(B10="DOMINGO",0,IF(A10="FERIADO",0,IF(A10="ABONADO",0,IF(A10="ATESTADO",0,K10))))) -> 0.33333333 | J10: =H10-I10 -> -0.33333333 | K10: =K9 -> 0.33333333 | L10: =L9+J10 -> -2.3333333
B11: =TEXT(C11,"DDDD") -> quinta-feira | C11: =C10+1 -> 41495 | H11: =E11-D11+G11-F11 -> 0 | I11: =IF(B11="SÁBADO",0,IF(B11="DOMINGO",0,IF(A11="FERIADO",0,IF(A11="ABONADO",0,IF(A11="ATESTADO",0,K11))))) -> 0.33333333 | J11: =H11-I11 -> -0.33333333 | K11: =K10 -> 0.33333333 | L11: =L10+J11 -> -2.6666667
B12: =TEXT(C12,"DDDD") -> sexta-feira | C12: =C11+1 -> 41496 | H12: =E12-D12+G12-F12 -> 0 | I12: =IF(B12="SÁBADO",0,IF(B12="DOMINGO",0,IF(A12="FERIADO",0,IF(A12="ABONADO",0,IF(A12="ATESTADO",0,K12))))) -> 0.33333333 | J12: =H12-I12 -> -0.33333333 | K12: =K11 -> 0.33333333 | L12: =L11+J12 -> -3
B13: =TEXT(C13,"DDDD") -> sábado | C13: =C12+1 -> 41497 | H13: =E13-D13+G13-F13 -> 0 | I13: =IF(B13="SÁBADO",0,IF(B13="DOMINGO",0,IF(A13="FERIADO",0,IF(A13="ABONADO",0,IF(A13="ATESTADO",0,K13))))) -> 0 | J13: =H13-I13 -> 0 | K13: =K12 -> 0.33333333 | L13: =L12+J13 -> -3
B14: =TEXT(C14,"DDDD") -> domingo | C14: =C13+1 -> 41498 | H14: =E14-D14+G14-F14 -> 0 | I14: =IF(B14="SÁBADO",0,IF(B14="DOMINGO",0,IF(A14="FERIADO",0,IF(A14="ABONADO",0,IF(A14="ATESTADO",0,K14))))) -> 0 | J14: =H14-I14 -> 0 | K14: =K13 -> 0.33333333 | L14: =L13+J14 -> -3
... B32: =TEXT(C32,"DDDD") -> quinta-feira | C32: =C31+1 -> 41516 | H32: =E32-D32+G32-F32 -> 0 | I32: =IF(B32="SÁBADO",0,IF(B32="DOMINGO",0,IF(A32="FERIADO",0,IF(A32="ABONADO",0,IF(A32="ATESTADO",0,K32))))) -> 0.33333333 | J32: =H32-I32 -> -0.33333333 | K32: =K31 -> 0.33333333 | L32: =L31+J32 -> -7.6666667
J33: =SUM(J2:J32) -> -7.6666667

Sheet SETEMBRO
A1: OBSERVAÇÃO | B1: DIA DA SEMANA | C1: DIA DO MÊS | D1: ENTRADA | E1: SAÍDA | F1: ENTRADA | G1: SAÍDA | H1: TOTAL DE HORAS NO DIA | J1: EXTRA X ATRASO | L1: ACUMULADO DIÁRIO | N1: DATA ATUAL | O1: =TODAY() -> 41466 | P1: =TEXT(O1,"DDDD") -> quarta-feira | Q1: =NOW() -> 41466.536
B2: =TEXT(C2,"DDDD") -> sexta-feira | C2: =AGOSTO!C32+1 -> 41517 | H2: =E2-D2+G2-F2 -> 0 | I2: =IF(B2="SÁBADO",0,IF(B2="DOMINGO",0,IF(A2="FERIADO",0,IF(A2="ABONADO",0,IF(A2="ATESTADO",0,K2))))) -> 0.33333333 | J2: =H2-I2 -> -0.33333333 | K2: =CADASTRO!B17 -> 0.33333333 | L2: =J2 -> -0.33333333
B3: =TEXT(C3,"DDDD") -> sábado | C3: =C2+1 -> 41518 | H3: =E3-D3+G3-F3 -> 0 | I3: =IF(B3="SÁBADO",0,IF(B3="DOMINGO",0,IF(A3="FERIADO",0,IF(A3="ABONADO",0,IF(A3="ATESTADO",0,K3))))) -> 0 | J3: =H3-I3 -> 0 | K3: =K2 -> 0.33333333 | L3: =L2+J3 -> -0.33333333
B4: =TEXT(C4,"DDDD") -> domingo | C4: =C3+1 -> 41519 | H4: =E4-D4+G4-F4 -> 0 | I4: =IF(B4="SÁBADO",0,IF(B4="DOMINGO",0,IF(A4="FERIADO",0,IF(A4="ABONADO",0,IF(A4="ATESTADO",0,K4))))) -> 0 | J4: =H4-I4 -> 0 | K4: =K3 -> 0.33333333 | L4: =L3+J4 -> -0.33333333
B5: =TEXT(C5,"DDDD") -> segunda-feira | C5: =C4+1 -> 41520 | H5: =E5-D5+G5-F5 -> 0 | I5: =IF(B5="SÁBADO",0,IF(B5="DOMINGO",0,IF(A5="FERIADO",0,IF(A5="ABONADO",0,IF(A5="ATESTADO",0,K5))))) -> 0.33333333 | J5: =H5-I5 -> -0.33333333 | K5: =K4 -> 0.33333333 | L5: =L4+J5 -> -0.66666667
B6: =TEXT(C6,"DDDD") -> terça-feira | C6: =C5+1 -> 41521 | H6: =E6-D6+G6-F6 -> 0 | I6: =IF(B6="SÁBADO",0,IF(B6="DOMINGO",0,IF(A6="FERIADO",0,IF(A6="ABONADO",0,IF(A6="ATESTADO",0,K6))))) -> 0.33333333 | J6: =H6-I6 -> -0.33333333 | K6: =K5 -> 0.33333333 | L6: =L5+J6 -> -1
B7: =TEXT(C7,"DDDD") -> quarta-feira | C7: =C6+1 -> 41522 | H7: =E7-D7+G7-F7 -> 0 | I7: =IF(B7="SÁBADO",0,IF(B7="DOMINGO",0,IF(A7="FERIADO",0,IF(A7="ABONADO",0,IF(A7="ATESTADO",0,K7))))) -> 0.33333333 | J7: =H7-I7 -> -0.33333333 | K7: =K6 -> 0.33333333 | L7: =L6+J7 -> -1.3333333
B8: =TEXT(C8,"DDDD") -> quinta-feira | C8: =C7+1 -> 41523 | H8: =E8-D8+G8-F8 -> 0 | I8: =IF(B8="SÁBADO",0,IF(B8="DOMINGO",0,IF(A8="FERIADO",0,IF(A8="ABONADO",0,IF(A8="ATESTADO",0,K8))))) -> 0.33333333 | J8: =H8-I8 -> -0.33333333 | K8: =K7 -> 0.33333333 | L8: =L7+J8 -> -1.6666667
B9: =TEXT(C9,"DDDD") -> sexta-feira | C9: =C8+1 -> 41524 | H9: =E9-D9+G9-F9 -> 0 | I9: =IF(B9="SÁBADO",0,IF(B9="DOMINGO",0,IF(A9="FERIADO",0,IF(A9="ABONADO",0,IF(A9="ATESTADO",0,K9))))) -> 0.33333333 | J9: =H9-I9 -> -0.33333333 | K9: =K8 -> 0.33333333 | L9: =L8+J9 -> -2
B10: =TEXT(C10,"DDDD") -> sábado | C10: =C9+1 -> 41525 | H10: =E10-D10+G10-F10 -> 0 | I10: =IF(B10="SÁBADO",0,IF(B10="DOMINGO",0,IF(A10="FERIADO",0,IF(A10="ABONADO",0,IF(A10="ATESTADO",0,K10))))) -> 0 | J10: =H10-I10 -> 0 | K10: =K9 -> 0.33333333 | L10: =L9+J10 -> -2
B11: =TEXT(C11,"DDDD") -> domingo | C11: =C10+1 -> 41526 | H11: =E11-D11+G11-F11 -> 0 | I11: =IF(B11="SÁBADO",0,IF(B11="DOMINGO",0,IF(A11="FERIADO",0,IF(A11="ABONADO",0,IF(A11="ATESTADO",0,K11))))) -> 0 | J11: =H11-I11 -> 0 | K11: =K10 -> 0.33333333 | L11: =L10+J11 -> -2
B12: =TEXT(C12,"DDDD") -> segunda-feira | C12: =C11+1 -> 41527 | H12: =E12-D12+G12-F12 -> 0 | I12: =IF(B12="SÁBADO",0,IF(B12="DOMINGO",0,IF(A12="FERIADO",0,IF(A12="ABONADO",0,IF(A12="ATESTADO",0,K12))))) -> 0.33333333 | J12: =H12-I12 -> -0.33333333 | K12: =K11 -> 0.33333333 | L12: =L11+J12 -> -2.3333333
B13: =TEXT(C13,"DDDD") -> terça-feira | C13: =C12+1 -> 41528 | H13: =E13-D13+G13-F13 -> 0 | I13: =IF(B13="SÁBADO",0,IF(B13="DOMINGO",0,IF(A13="FERIADO",0,IF(A13="ABONADO",0,IF(A13="ATESTADO",0,K13))))) -> 0.33333333 | J13: =H13-I13 -> -0.33333333 | K13: =K12 -> 0.33333333 | L13: =L12+J13 -> -2.6666667
B14: =TEXT(C14,"DDDD") -> quarta-feira | C14: =C13+1 -> 41529 | H14: =E14-D14+G14-F14 -> 0 | I14: =IF(B14="SÁBADO",0,IF(B14="DOMINGO",0,IF(A14="FERIADO",0,IF(A14="ABONADO",0,IF(A14="ATESTADO",0,K14))))) -> 0.33333333 | J14: =H14-I14 -> -0.33333333 | K14: =K13 -> 0.33333333 | L14: =L13+J14 -> -3
... B31: =TEXT(C31,"DDDD") -> sábado | C31: =C30+1 -> 41546 | H31: =E31-D31+G31-F31 -> 0 | I31: =IF(B31="SÁBADO",0,IF(B31="DOMINGO",0,IF(A31="FERIADO",0,IF(A31="ABONADO",0,IF(A31="ATESTADO",0,K31))))) -> 0 | J31: =H31-I31 -> 0 | K31: =K30 -> 0.33333333 | L31: =L30+J31 -> -7
J32: =SUM(J2:J31) -> -7

Sheet OUTUBRO
A1: OBSERVAÇÃO | B1: DIA DA SEMANA | C1: DIA DO MÊS | D1: ENTRADA | E1: SAÍDA | F1: ENTRADA | G1: SAÍDA | H1: TOTAL DE HORAS NO DIA | J1: EXTRA X ATRASO | L1: ACUMULADO DIÁRIO | N1: DATA ATUAL | O1: =TODAY() -> 41466 | P1: =TEXT(O1,"DDDD") -> quarta-feira | Q1: =NOW() -> 41466.536
B2: =TEXT(C2,"DDDD") -> domingo | C2: =SETEMBRO!C31+1 -> 41547 | H2: =E2-D2+G2-F2 -> 0 | I2: =IF(B2="SÁBADO",0,IF(B2="DOMINGO",0,IF(A2="FERIADO",0,IF(A2="ABONADO",0,IF(A2="ATESTADO",0,K2))))) -> 0 | J2: =H2-I2 -> 0 | K2: =CADASTRO!B19 -> 0.33333333 | L2: =J2 -> 0
B3: =TEXT(C3,"DDDD") -> segunda-feira | C3: =C2+1 -> 41548 | H3: =E3-D3+G3-F3 -> 0 | I3: =IF(B3="SÁBADO",0,IF(B3="DOMINGO",0,IF(A3="FERIADO",0,IF(A3="ABONADO",0,IF(A3="ATESTADO",0,K3))))) -> 0.33333333 | J3: =H3-I3 -> -0.33333333 | K3: =K2 -> 0.33333333 | L3: =L2+J3 -> -0.33333333
B4: =TEXT(C4,"DDDD") -> terça-feira | C4: =C3+1 -> 41549 | H4: =E4-D4+G4-F4 -> 0 | I4: =IF(B4="SÁBADO",0,IF(B4="DOMINGO",0,IF(A4="FERIADO",0,IF(A4="ABONADO",0,IF(A4="ATESTADO",0,K4))))) -> 0.33333333 | J4: =H4-I4 -> -0.33333333 | K4: =K3 -> 0.33333333 | L4: =L3+J4 -> -0.66666667
B5: =TEXT(C5,"DDDD") -> quarta-feira | C5: =C4+1 -> 41550 | H5: =E5-D5+G5-F5 -> 0 | I5: =IF(B5="SÁBADO",0,IF(B5="DOMINGO",0,IF(A5="FERIADO",0,IF(A5="ABONADO",0,IF(A5="ATESTADO",0,K5))))) -> 0.33333333 | J5: =H5-I5 -> -0.33333333 | K5: =K4 -> 0.33333333 | L5: =L4+J5 -> -1
B6: =TEXT(C6,"DDDD") -> quinta-feira | C6: =C5+1 -> 41551 | H6: =E6-D6+G6-F6 -> 0 | I6: =IF(B6="SÁBADO",0,IF(B6="DOMINGO",0,IF(A6="FERIADO",0,IF(A6="ABONADO",0,IF(A6="ATESTADO",0,K6))))) -> 0.33333333 | J6: =H6-I6 -> -0.33333333 | K6: =K5 -> 0.33333333 | L6: =L5+J6 -> -1.3333333
B7: =TEXT(C7,"DDDD") -> sexta-feira | C7: =C6+1 -> 41552 | H7: =E7-D7+G7-F7 -> 0 | I7: =IF(B7="SÁBADO",0,IF(B7="DOMINGO",0,IF(A7="FERIADO",0,IF(A7="ABONADO",0,IF(A7="ATESTADO",0,K7))))) -> 0.33333333 | J7: =H7-I7 -> -0.33333333 | K7: =K6 -> 0.33333333 | L7: =L6+J7 -> -1.6666667
B8: =TEXT(C8,"DDDD") -> sábado | C8: =C7+1 -> 41553 | H8: =E8-D8+G8-F8 -> 0 | I8: =IF(B8="SÁBADO",0,IF(B8="DOMINGO",0,IF(A8="FERIADO",0,IF(A8="ABONADO",0,IF(A8="ATESTADO",0,K8))))) -> 0 | J8: =H8-I8 -> 0 | K8: =K7 -> 0.33333333 | L8: =L7+J8 -> -1.6666667
B9: =TEXT(C9,"DDDD") -> domingo | C9: =C8+1 -> 41554 | H9: =E9-D9+G9-F9 -> 0 | I9: =IF(B9="SÁBADO",0,IF(B9="DOMINGO",0,IF(A9="FERIADO",0,IF(A9="ABONADO",0,IF(A9="ATESTADO",0,K9))))) -> 0 | J9: =H9-I9 -> 0 | K9: =K8 -> 0.33333333 | L9: =L8+J9 -> -1.6666667
B10: =TEXT(C10,"DDDD") -> segunda-feira | C10: =C9+1 -> 41555 | H10: =E10-D10+G10-F10 -> 0 | I10: =IF(B10="SÁBADO",0,IF(B10="DOMINGO",0,IF(A10="FERIADO",0,IF(A10="ABONADO",0,IF(A10="ATESTADO",0,K10))))) -> 0.33333333 | J10: =H10-I10 -> -0.33333333 | K10: =K9 -> 0.33333333 | L10: =L9+J10 -> -2
B11: =TEXT(C11,"DDDD") -> terça-feira | C11: =C10+1 -> 41556 | H11: =E11-D11+G11-F11 -> 0 | I11: =IF(B11="SÁBADO",0,IF(B11="DOMINGO",0,IF(A11="FERIADO",0,IF(A11="ABONADO",0,IF(A11="ATESTADO",0,K11))))) -> 0.33333333 | J11: =H11-I11 -> -0.33333333 | K11: =K10 -> 0.33333333 | L11: =L10+J11 -> -2.3333333
B12: =TEXT(C12,"DDDD") -> quarta-feira | C12: =C11+1 -> 41557 | H12: =E12-D12+G12-F12 -> 0 | I12: =IF(B12="SÁBADO",0,IF(B12="DOMINGO",0,IF(A12="FERIADO",0,IF(A12="ABONADO",0,IF(A12="ATESTADO",0,K12))))) -> 0.33333333 | J12: =H12-I12 -> -0.33333333 | K12: =K11 -> 0.33333333 | L12: =L11+J12 -> -2.6666667
B13: =TEXT(C13,"DDDD") -> quinta-feira | C13: =C12+1 -> 41558 | H13: =E13-D13+G13-F13 -> 0 | I13: =IF(B13="SÁBADO",0,IF(B13="DOMINGO",0,IF(A13="FERIADO",0,IF(A13="ABONADO",0,IF(A13="ATESTADO",0,K13))))) -> 0.33333333 | J13: =H13-I13 -> -0.33333333 | K13: =K12 -> 0.33333333 | L13: =L12+J13 -> -3
B14: =TEXT(C14,"DDDD") -> sexta-feira | C14: =C13+1 -> 41559 | H14: =E14-D14+G14-F14 -> 0 | I14: =IF(B14="SÁBADO",0,IF(B14="DOMINGO",0,IF(A14="FERIADO",0,IF(A14="ABONADO",0,IF(A14="ATESTADO",0,K14))))) -> 0.33333333 | J14: =H14-I14 -> -0.33333333 | K14: =K13 -> 0.33333333 | L14: =L13+J14 -> -3.3333333
... B32: =TEXT(C32,"DDDD") -> terça-feira | C32: =C31+1 -> 41577 | H32: =E32-D32+G32-F32 -> 0 | I32: =IF(B32="SÁBADO",0,IF(B32="DOMINGO",0,IF(A32="FERIADO",0,IF(A32="ABONADO",0,IF(A32="ATESTADO",0,K32))))) -> 0.33333333 | J32: =H32-I32 -> -0.33333333 | K32: =K31 -> 0.33333333 | L32: =L31+J32 -> -7.3333333
J33: =SUM(J2:J32) -> -7.3333333

Sheet NOVEMBRO
A1: OBSERVAÇÃO | B1: DIA DA SEMANA | C1: DIA DO MÊS | D1: ENTRADA | E1: SAÍDA | F1: ENTRADA | G1: SAÍDA | H1: TOTAL DE HORAS NO DIA | J1: EXTRA X ATRASO | L1: ACUMULADO DIÁRIO | N1: DATA ATUAL | O1: =TODAY() -> 41466 | P1: =TEXT(O1,"DDDD") -> quarta-feira | Q1: =NOW() -> 41466.536
B2: =TEXT(C2,"DDDD") -> quarta-feira | C2: =OUTUBRO!C32+1 -> 41578 | H2: =E2-D2+G2-F2 -> 0 | I2: =IF(B2="SÁBADO",0,IF(B2="DOMINGO",0,IF(A2="FERIADO",0,IF(A2="ABONADO",0,IF(A2="ATESTADO",0,K2))))) -> 0.33333333 | J2: =H2-I2 -> -0.33333333 | K2: =CADASTRO!B21 -> 0.33333333 | L2: =J2 -> -0.33333333
B3: =TEXT(C3,"DDDD") -> quinta-feira | C3: =C2+1 -> 41579 | H3: =E3-D3+G3-F3 -> 0 | I3: =IF(B3="SÁBADO",0,IF(B3="DOMINGO",0,IF(A3="FERIADO",0,IF(A3="ABONADO",0,IF(A3="ATESTADO",0,K3))))) -> 0.33333333 | J3: =H3-I3 -> -0.33333333 | K3: =K2 -> 0.33333333 | L3: =L2+J3 -> -0.66666667
B4: =TEXT(C4,"DDDD") -> sexta-feira | C4: =C3+1 -> 41580 | H4: =E4-D4+G4-F4 -> 0 | I4: =IF(B4="SÁBADO",0,IF(B4="DOMINGO",0,IF(A4="FERIADO",0,IF(A4="ABONADO",0,IF(A4="ATESTADO",0,K4))))) -> 0.33333333 | J4: =H4-I4 -> -0.33333333 | K4: =K3 -> 0.33333333 | L4: =L3+J4 -> -1
B5: =TEXT(C5,"DDDD") -> sábado | C5: =C4+1 -> 41581 | H5: =E5-D5+G5-F5 -> 0 | I5: =IF(B5="SÁBADO",0,IF(B5="DOMINGO",0,IF(A5="FERIADO",0,IF(A5="ABONADO",0,IF(A5="ATESTADO",0,K5))))) -> 0 | J5: =H5-I5 -> 0 | K5: =K4 -> 0.33333333 | L5: =L4+J5 -> -1
B6: =TEXT(C6,"DDDD") -> domingo | C6: =C5+1 -> 41582 | H6: =E6-D6+G6-F6 -> 0 | I6: =IF(B6="SÁBADO",0,IF(B6="DOMINGO",0,IF(A6="FERIADO",0,IF(A6="ABONADO",0,IF(A6="ATESTADO",0,K6))))) -> 0 | J6: =H6-I6 -> 0 | K6: =K5 -> 0.33333333 | L6: =L5+J6 -> -1
B7: =TEXT(C7,"DDDD") -> segunda-feira | C7: =C6+1 -> 41583 | H7: =E7-D7+G7-F7 -> 0 | I7: =IF(B7="SÁBADO",0,IF(B7="DOMINGO",0,IF(A7="FERIADO",0,IF(A7="ABONADO",0,IF(A7="ATESTADO",0,K7))))) -> 0.33333333 | J7: =H7-I7 -> -0.33333333 | K7: =K6 -> 0.33333333 | L7: =L6+J7 -> -1.3333333
B8: =TEXT(C8,"DDDD") -> terça-feira | C8: =C7+1 -> 41584 | H8: =E8-D8+G8-F8 -> 0 | I8: =IF(B8="SÁBADO",0,IF(B8="DOMINGO",0,IF(A8="FERIADO",0,IF(A8="ABONADO",0,IF(A8="ATESTADO",0,K8))))) -> 0.33333333 | J8: =H8-I8 -> -0.33333333 | K8: =K7 -> 0.33333333 | L8: =L7+J8 -> -1.6666667
B9: =TEXT(C9,"DDDD") -> quarta-feira | C9: =C8+1 -> 41585 | H9: =E9-D9+G9-F9 -> 0 | I9: =IF(B9="SÁBADO",0,IF(B9="DOMINGO",0,IF(A9="FERIADO",0,IF(A9="ABONADO",0,IF(A9="ATESTADO",0,K9))))) -> 0.33333333 | J9: =H9-I9 -> -0.33333333 | K9: =K8 -> 0.33333333 | L9: =L8+J9 -> -2
B10: =TEXT(C10,"DDDD") -> quinta-feira | C10: =C9+1 -> 41586 | H10: =E10-D10+G10-F10 -> 0 | I10: =IF(B10="SÁBADO",0,IF(B10="DOMINGO",0,IF(A10="FERIADO",0,IF(A10="ABONADO",0,IF(A10="ATESTADO",0,K10))))) -> 0.33333333 | J10: =H10-I10 -> -0.33333333 | K10: =K9 -> 0.33333333 | L10: =L9+J10 -> -2.3333333
B11: =TEXT(C11,"DDDD") -> sexta-feira | C11: =C10+1 -> 41587 | H11: =E11-D11+G11-F11 -> 0 | I11: =IF(B11="SÁBADO",0,IF(B11="DOMINGO",0,IF(A11="FERIADO",0,IF(A11="ABONADO",0,IF(A11="ATESTADO",0,K11))))) -> 0.33333333 | J11: =H11-I11 -> -0.33333333 | K11: =K10 -> 0.33333333 | L11: =L10+J11 -> -2.6666667
B12: =TEXT(C12,"DDDD") -> sábado | C12: =C11+1 -> 41588 | H12: =E12-D12+G12-F12 -> 0 | I12: =IF(B12="SÁBADO",0,IF(B12="DOMINGO",0,IF(A12="FERIADO",0,IF(A12="ABONADO",0,IF(A12="ATESTADO",0,K12))))) -> 0 | J12: =H12-I12 -> 0 | K12: =K11 -> 0.33333333 | L12: =L11+J12 -> -2.6666667
B13: =TEXT(C13,"DDDD") -> domingo | C13: =C12+1 -> 41589 | H13: =E13-D13+G13-F13 -> 0 | I13: =IF(B13="SÁBADO",0,IF(B13="DOMINGO",0,IF(A13="FERIADO",0,IF(A13="ABONADO",0,IF(A13="ATESTADO",0,K13))))) -> 0 | J13: =H13-I13 -> 0 | K13: =K12 -> 0.33333333 | L13: =L12+J13 -> -2.6666667
B14: =TEXT(C14,"DDDD") -> segunda-feira | C14: =C13+1 -> 41590 | H14: =E14-D14+G14-F14 -> 0 | I14: =IF(B14="SÁBADO",0,IF(B14="DOMINGO",0,IF(A14="FERIADO",0,IF(A14="ABONADO",0,IF(A14="ATESTADO",0,K14))))) -> 0.33333333 | J14: =H14-I14 -> -0.33333333 | K14: =K13 -> 0.33333333 | L14: =L13+J14 -> -3
... B31: =TEXT(C31,"DDDD") -> quinta-feira | C31: =C30+1 -> 41607 | H31: =E31-D31+G31-F31 -> 0 | I31: =IF(B31="SÁBADO",0,IF(B31="DOMINGO",0,IF(A31="FERIADO",0,IF(A31="ABONADO",0,IF(A31="ATESTADO",0,K31))))) -> 0.33333333 | J31: =H31-I31 -> -0.33333333 | K31: =K30 -> 0.33333333 | L31: =L30+J31 -> -7.3333333
J32: =SUM(J2:J31) -> -7.3333333

Sheet DEZEMBRO
A1: OBSERVAÇÃO | B1: DIA DA SEMANA | C1: DIA DO MÊS | D1: ENTRADA | E1: SAÍDA | F1: ENTRADA | G1: SAÍDA | H1: TOTAL DE HORAS NO DIA | J1: EXTRA X ATRASO | L1: ACUMULADO DIÁRIO | N1: DATA ATUAL | O1: =TODAY() -> 41466 | P1: =TEXT(O1,"DDDD") -> quarta-feira | Q1: =NOW() -> 41466.536
B2: =TEXT(C2,"DDDD") -> sexta-feira | C2: =NOVEMBRO!C31+1 -> 41608 | H2: =E2-D2+G2-F2 -> 0 | I2: =IF(B2="SÁBADO",0,IF(B2="DOMINGO",0,IF(A2="FERIADO",0,IF(A2="ABONADO",0,IF(A2="ATESTADO",0,K2))))) -> 0.33333333 | J2: =H2-I2 -> -0.33333333 | K2: =CADASTRO!B23 -> 0.33333333 | L2: =J2 -> -0.33333333
B3: =TEXT(C3,"DDDD") -> sábado | C3: =C2+1 -> 41609 | H3: =E3-D3+G3-F3 -> 0 | I3: =IF(B3="SÁBADO",0,IF(B3="DOMINGO",0,IF(A3="FERIADO",0,IF(A3="ABONADO",0,IF(A3="ATESTADO",0,K3))))) -> 0 | J3: =H3-I3 -> 0 | K3: =K2 -> 0.33333333 | L3: =L2+J3 -> -0.33333333
B4: =TEXT(C4,"DDDD") -> domingo | C4: =C3+1 -> 41610 | H4: =E4-D4+G4-F4 -> 0 | I4: =IF(B4="SÁBADO",0,IF(B4="DOMINGO",0,IF(A4="FERIADO",0,IF(A4="ABONADO",0,IF(A4="ATESTADO",0,K4))))) -> 0 | J4: =H4-I4 -> 0 | K4: =K3 -> 0.33333333 | L4: =L3+J4 -> -0.33333333
B5: =TEXT(C5,"DDDD") -> segunda-feira | C5: =C4+1 -> 41611 | H5: =E5-D5+G5-F5 -> 0 | I5: =IF(B5="SÁBADO",0,IF(B5="DOMINGO",0,IF(A5="FERIADO",0,IF(A5="ABONADO",0,IF(A5="ATESTADO",0,K5))))) -> 0.33333333 | J5: =H5-I5 -> -0.33333333 | K5: =K4 -> 0.33333333 | L5: =L4+J5 -> -0.66666667
B6: =TEXT(C6,"DDDD") -> terça-feira | C6: =C5+1 -> 41612 | H6: =E6-D6+G6-F6 -> 0 | I6: =IF(B6="SÁBADO",0,IF(B6="DOMINGO",0,IF(A6="FERIADO",0,IF(A6="ABONADO",0,IF(A6="ATESTADO",0,K6))))) -> 0.33333333 | J6: =H6-I6 -> -0.33333333 | K6: =K5 -> 0.33333333 | L6: =L5+J6 -> -1
B7: =TEXT(C7,"DDDD") -> quarta-feira | C7: =C6+1 -> 41613 | H7: =E7-D7+G7-F7 -> 0 | I7: =IF(B7="SÁBADO",0,IF(B7="DOMINGO",0,IF(A7="FERIADO",0,IF(A7="ABONADO",0,IF(A7="ATESTADO",0,K7))))) -> 0.33333333 | J7: =H7-I7 -> -0.33333333 | K7: =K6 -> 0.33333333 | L7: =L6+J7 -> -1.3333333
B8: =TEXT(C8,"DDDD") -> quinta-feira | C8: =C7+1 -> 41614 | H8: =E8-D8+G8-F8 -> 0 | I8: =IF(B8="SÁBADO",0,IF(B8="DOMINGO",0,IF(A8="FERIADO",0,IF(A8="ABONADO",0,IF(A8="ATESTADO",0,K8))))) -> 0.33333333 | J8: =H8-I8 -> -0.33333333 | K8: =K7 -> 0.33333333 | L8: =L7+J8 -> -1.6666667
B9: =TEXT(C9,"DDDD") -> sexta-feira | C9: =C8+1 -> 41615 | H9: =E9-D9+G9-F9 -> 0 | I9: =IF(B9="SÁBADO",0,IF(B9="DOMINGO",0,IF(A9="FERIADO",0,IF(A9="ABONADO",0,IF(A9="ATESTADO",0,K9))))) -> 0.33333333 | J9: =H9-I9 -> -0.33333333 | K9: =K8 -> 0.33333333 | L9: =L8+J9 -> -2
B10: =TEXT(C10,"DDDD") -> sábado | C10: =C9+1 -> 41616 | H10: =E10-D10+G10-F10 -> 0 | I10: =IF(B10="SÁBADO",0,IF(B10="DOMINGO",0,IF(A10="FERIADO",0,IF(A10="ABONADO",0,IF(A10="ATESTADO",0,K10))))) -> 0 | J10: =H10-I10 -> 0 | K10: =K9 -> 0.33333333 | L10: =L9+J10 -> -2
B11: =TEXT(C11,"DDDD") -> domingo | C11: =C10+1 -> 41617 | H11: =E11-D11+G11-F11 -> 0 | I11: =IF(B11="SÁBADO",0,IF(B11="DOMINGO",0,IF(A11="FERIADO",0,IF(A11="ABONADO",0,IF(A11="ATESTADO",0,K11))))) -> 0 | J11: =H11-I11 -> 0 | K11: =K10 -> 0.33333333 | L11: =L10+J11 -> -2
