Workbook

Sheet Ini
A1: 3.0.1 | C1: PLANILHA DE CÁLCULO DE
C2: HORA EXTRA (BANCO DE HORAS) 3.0
C3: Seja bem-vindo(a). Com esta planilha você poderá analisar toda a folha de ponto do se funcionário. Invista suas energias em idéias que você sabe que serão viáveis!
B4: IMPORTANTE: LEIA OS PASSOS E ENTENDA A PLANILHA
C6: Passo 1 | E6: PREMISSAS GERAIS
C7: Este é o começo de tudo. É a parte de definição de todas as premissas que formaçãodo perfil do funcionário.Contribui com todas bases de cálculo usadas adiante.
C9: Passo 2 | E9: LANÇAMENTOS
C10: Os Lançamentos são os locais onde você vai preencher o dia a dia do seu funcionário. Dia a Dia, durante todo o ano.
C12: Passo 3 | E12: RESULTADOS CONSOLIDADOS
C13: A hora de retirar um relátório conciso e direto sobre os dados lançados mês a mês. Nos resultados consolidados você têm um panorama dde todo o ano e também mês a mês sendo uma indispensável ferramenta para tomada dde decisões.
C15: Passo 4 | E15: GRÁFICOS
C16: Os gráficos são importantes para que sejam feitas avaliações sobre a situação do seu funcionário de uma forma simples e mais visual. Você poderá ver os gráficos de cada tipo de horário de maneira separada. Além da análise por mês.
C18: Passo 5 | E18: ALERTAS E DICAS
C19: Esta planilha avaliará todos os dados preenchidos por você e retornará com dicas importantes para o seu segmento. Avaliando seu dia a dia, será mais fácil identificar se está fluindo da maneira correta, Isso servirá para alertá-lo sobre possíveis problemas.
C21: Passo 6 | E21: RELATÓRIO PARA IMPRESSÃO
C22: Imprima somente o que importa. Esta parte gera um relatório formatado para impressão em 8 páginas A4 com seu relatório mês a mês e o panorama geral. Acompanha gráficos e as dicas importantes que a planilha fornece para cada mês.
C24: Passo 7 | E24: FOLHA DE PONTO
C25: Imprima a folha de ponto mensal do seu funcionário de maneira prática e econômica com apenas um clique. É rápido, é simples e é tudo que você precisava para adiantar seu dia a dia.

Sheet P Gerais
A1: 3.0.1 | C1: 1. PREMISSAS GERAIS
C5: Ano de Vigência | G5: Horas Mensais
C6: 2015 | G6: 220
C8: Cadastro do Funcionário
C9: Nome Completo
C10: Data de Admissão
C11: Departamento
C12: Seção
C13: Cargo
C15: Salário Base
E16: JAN | H16: MAI | K16: SET
E17: FEV | H17: JUN | K17: OUT
E18: MAR | H18: JUL | K18: NOV
E19: ABR | H19: AGO | K19: DEZ
C21: Defina a Jornada de Trabalho do Funcionário
E22: Início | F22: Intervalo | I22: Término | M22: Carga Horária do Dia | N22: Horas de Intervalo
C23: SEG | M23: =IF(ABS(((E23-1)-F23)+(H23-I23))>=1,ABS(((E23-1)-F23)+(H23-I23))-1,ABS(((E23-1)-F23)+(H23-I23))) -> 0 | N23: =H23-F23 -> 0
C24: TER | M24: =IF(ABS(((E24-1)-F24)+(H24-I24))>=1,ABS(((E24-1)-F24)+(H24-I24))-1,ABS(((E24-1)-F24)+(H24-I24))) -> 0 | N24: =H24-F24 -> 0
C25: QUA | M25: =IF(ABS(((E25-1)-F25)+(H25-I25))>=1,ABS(((E25-1)-F25)+(H25-I25))-1,ABS(((E25-1)-F25)+(H25-I25))) -> 0 | N25: =H25-F25 -> 0
C26: QUI | M26: =IF(ABS(((E26-1)-F26)+(H26-I26))>=1,ABS(((E26-1)-F26)+(H26-I26))-1,ABS(((E26-1)-F26)+(H26-I26))) -> 0 | N26: =H26-F26 -> 0
C27: SEX | M27: =IF(ABS(((E27-1)-F27)+(H27-I27))>=1,ABS(((E27-1)-F27)+(H27-I27))-1,ABS(((E27-1)-F27)+(H27-I27))) -> 0 | N27: =H27-F27 -> 0
C28: SÁB | M28: =IF(ABS(((E28-1)-F28)+(H28-I28))>=1,ABS(((E28-1)-F28)+(H28-I28))-1,ABS(((E28-1)-F28)+(H28-I28))) -> 0 | N28: =H28-F28 -> 0
C29: DOM | M29: =IF(ABS(((E29-1)-F29)+(H29-I29))>=1,ABS(((E29-1)-F29)+(H29-I29))-1,ABS(((E29-1)-F29)+(H29-I29))) -> 0 | N29: =H29-F29 -> 0
C31: Modelo de pagamento das horas extras
C32: Essas horas extras estão sendo pagas ou fará banco de horas?
C34: Acréscimo por cada hora extra (%)
C35: Dia de Semana | E35: Sábado | F35: Domingo | H35: Noturno | I35: DSR | K35: Feriados | L35: Periculosidade
C38: Interjornada (Iniciada antes das 11 horas de descanso) | H38: Intrajornada (Trabalho na hora de descanso/almoço)

Sheet Lanc
A1: 3.0.1 | C1: 2. LANÇAMENTOS MENSAIS
C5: Quantas horas acumuladas ou devidas esse funcionário já têm no banco de horas | I5: 0 | K5: Horas extras | S5: =S13+S11 -> 0
C7: Dia | E7: Classificação | F7: Início | G7: Intervalo | I7: Término | K7: Horas Dia | M7: Horas Devidas | O7: Horas Extras | P7: 0.083333333 | Q7: Resumo do Mês | W7: 1 | AD7: intervalo | AF7: 0 | AG7: 1 | AH7: 0.45833333 | AI7: 0.20833333 | AJ7: 0.75 | AK7: 0.91666667
C8: 1 | D8: =VLOOKUP(X8,$AB$8:$AC$14,2,0) -> QUI | E8: Feriado | K8: =IF(ABS(((F8-1)-G8)+(H8-I8))>=1,ABS(((F8-1)-G8)+(H8-I8))-1,ABS(((F8-1)-G8)+(H8-I8))) -> 0 | M8: =IF(E8="Falta Justificada",0,IF(E8="Feriado",0,IF(E8="Folga(DSR)",0,IF(VLOOKUP(D8,'P Gerais'!$C$23:$M$29,11,0)-Lanc!K8>0,VLOOKUP(D8,'P Gerais'!$C$23:$M$29,11,0)-Lanc!K8,0)))) -> 0 | O8: =IF(E8="Feriado",IF(F8>I8,(I8+1-F8)-(H8-G8),(I8-F8)-(H8-G8)),IF(E8="Folga(DSR)",IF(F8>I8,(I8+1-F8)-(H8-G8),(I8-F8)-(H8-G8)),IF(E8="Falta Justificada",IF(F8>I8,(I8+1-F8)-(H8-G8),(I8-F8)-(H8-G8)),IF(VLOOKUP(D8,'P Gerais'!$C$23:$M$29,11,0)-Lanc!K8<0,ABS(VLOOKUP(D8,'P Gerais'!$C$23:$M$29,11,0)-Lanc!K8),0)))) -> 0 | P8: =IF(O8>$P$7,1,0) -> 0 | W8: =DATE('P Gerais'!$C$6,$W$7,Lanc!C8) -> 42005 | X8: =WEEKDAY(W8) -> 5 | AB8: 1 | AC8: DOM | AD8: =H8-G8 -> 0 | AE8: =VLOOKUP(D8,'P Gerais'!$C$23:$N$29,12,0) -> 0 | AF8: =IF(AE8-AD8<0,0,IF(OR(G8="",G8=0),0,AE8-AD8)) -> 0 | AG8: =($AG$7-I8)+F8 -> 1 | AH8: =IF(AG8<$AH$7,$AH$7-AG8,$AF$7) -> 0 | AI8: =IF(F8=I8,$AF$7,IF(F8<$AI$7,$AI$7-F8,$AF$7)) -> 0 | AJ8: =IF(F8=I8,$AF$7,IF(F8>=$AJ$7,O8,$AF$7)) -> 0 | AK8: =IF(AND(I8>$AK$7,I8>AL8),I8-AL8,$AF$7) -> 0 | AL8: =VLOOKUP(D8,'P Gerais'!$C$23:$I$29,7,FALSE) -> 0
C9: 2 | D9: =VLOOKUP(X9,$AB$8:$AC$14,2,0) -> SEX | E9: Feriado | K9: =IF(ABS(((F9-1)-G9)+(H9-I9))>=1,ABS(((F9-1)-G9)+(H9-I9))-1,ABS(((F9-1)-G9)+(H9-I9))) -> 0 | M9: =IF(E9="Falta Justificada",0,IF(E9="Feriado",0,IF(E9="Folga(DSR)",0,IF(VLOOKUP(D9,'P Gerais'!$C$23:$M$29,11,0)-Lanc!K9>0,VLOOKUP(D9,'P Gerais'!$C$23:$M$29,11,0)-Lanc!K9,0)))) -> 0 | O9: =IF(E9="Feriado",IF(F9>I9,(I9+1-F9)-(H9-G9),(I9-F9)-(H9-G9)),IF(E9="Folga(DSR)",IF(F9>I9,(I9+1-F9)-(H9-G9),(I9-F9)-(H9-G9)),IF(E9="Falta Justificada",IF(F9>I9,(I9+1-F9)-(H9-G9),(I9-F9)-(H9-G9)),IF(VLOOKUP(D9,'P Gerais'!$C$23:$M$29,11,0)-Lanc!K9<0,ABS(VLOOKUP(D9,'P Gerais'!$C$23:$M$29,11,0)-Lanc!K9),0)))) -> 0 | P9: =IF(O9>$P$7,1,0) -> 0 | Q9: Horas trabalhadas no mês | S9: =SUM(K8:K38) -> 0 | W9: =DATE('P Gerais'!$C$6,$W$7,Lanc!C9) -> 42006 | X9: =WEEKDAY(W9) -> 6 | AB9: 2 | AC9: SEG | AD9: =H9-G9 -> 0 | AE9: =VLOOKUP(D9,'P Gerais'!$C$23:$N$29,12,0) -> 0 | AF9: =IF(AE9-AD9<0,0,IF(OR(G9="",G9=0),0,AE9-AD9)) -> 0 | AG9: =($AG$7-I9)+F9 -> 1 | AH9: =IF(AG9<$AH$7,$AH$7-AG9,$AF$7) -> 0 | AI9: =IF(F9=I9,$AF$7,IF(F9<$AI$7,$AI$7-F9,$AF$7)) -> 0 | AJ9: =IF(F9=I9,$AF$7,IF(F9>=$AJ$7,O9,$AF$7)) -> 0 | AK9: =IF(AND(I9>$AK$7,I9>AL9),I9-AL9,$AF$7) -> 0 | AL9: =VLOOKUP(D9,'P Gerais'!$C$23:$I$29,7,FALSE) -> 0
C10: 3 | D10: =VLOOKUP(X10,$AB$8:$AC$14,2,0) -> SÁB | E10: Feriado | K10: =IF(ABS(((F10-1)-G10)+(H10-I10))>=1,ABS(((F10-1)-G10)+(H10-I10))-1,ABS(((F10-1)-G10)+(H10-I10))) -> 0 | M10: =IF(E10="Falta Justificada",0,IF(E10="Feriado",0,IF(E10="Folga(DSR)",0,IF(VLOOKUP(D10,'P Gerais'!$C$23:$M$29,11,0)-Lanc!K10>0,VLOOKUP(D10,'P Gerais'!$C$23:$M$29,11,0)-Lanc!K10,0)))) -> 0 | O10: =IF(E10="Feriado",IF(F10>I10,(I10+1-F10)-(H10-G10),(I10-F10)-(H10-G10)),IF(E10="Folga(DSR)",IF(F10>I10,(I10+1-F10)-(H10-G10),(I10-F10)-(H10-G10)),IF(E10="Falta Justificada",IF(F10>I10,(I10+1-F10)-(H10-G10),(I10-F10)-(H10-G10)),IF(VLOOKUP(D10,'P Gerais'!$C$23:$M$29,11,0)-Lanc!K10<0,ABS(VLOOKUP(D10,'P Gerais'!$C$23:$M$29,11,0)-Lanc!K10),0)))) -> 0 | P10: =IF(O10>$P$7,1,0) -> 0 | W10: =DATE('P Gerais'!$C$6,$W$7,Lanc!C10) -> 42007 | X10: =WEEKDAY(W10) -> 7 | AB10: 3 | AC10: TER | AD10: =H10-G10 -> 0 | AE10: =VLOOKUP(D10,'P Gerais'!$C$23:$N$29,12,0) -> 0 | AF10: =IF(AE10-AD10<0,0,IF(OR(G10="",G10=0),0,AE10-AD10)) -> 0 | AG10: =($AG$7-I10)+F10 -> 1 | AH10: =IF(AG10<$AH$7,$AH$7-AG10,$AF$7) -> 0 | AI10: =IF(F10=I10,$AF$7,IF(F10<$AI$7,$AI$7-F10,$AF$7)) -> 0 | AJ10: =IF(F10=I10,$AF$7,IF(F10>=$AJ$7,O10,$AF$7)) -> 0 | AK10: =IF(AND(I10>$AK$7,I10>AL10),I10-AL10,$AF$7) -> 0 | AL10: =VLOOKUP(D10,'P Gerais'!$C$23:$I$29,7,FALSE) -> 0
C11: 4 | D11: =VLOOKUP(X11,$AB$8:$AC$14,2,0) -> DOM | E11: Feriado | K11: =IF(ABS(((F11-1)-G11)+(H11-I11))>=1,ABS(((F11-1)-G11)+(H11-I11))-1,ABS(((F11-1)-G11)+(H11-I11))) -> 0 | M11: =IF(E11="Falta Justificada",0,IF(E11="Feriado",0,IF(E11="Folga(DSR)",0,IF(VLOOKUP(D11,'P Gerais'!$C$23:$M$29,11,0)-Lanc!K11>0,VLOOKUP(D11,'P Gerais'!$C$23:$M$29,11,0)-Lanc!K11,0)))) -> 0 | O11: =IF(E11="Feriado",IF(F11>I11,(I11+1-F11)-(H11-G11),(I11-F11)-(H11-G11)),IF(E11="Folga(DSR)",IF(F11>I11,(I11+1-F11)-(H11-G11),(I11-F11)-(H11-G11)),IF(E11="Falta Justificada",IF(F11>I11,(I11+1-F11)-(H11-G11),(I11-F11)-(H11-G11)),IF(VLOOKUP(D11,'P Gerais'!$C$23:$M$29,11,0)-Lanc!K11<0,ABS(VLOOKUP(D11,'P Gerais'!$C$23:$M$29,11,0)-Lanc!K11),0)))) -> 0 | P11: =IF(O11>$P$7,1,0) -> 0 | Q11: Acumulado no banco de horas | S11: =IF(K5="Horas devidas",ABS(-I5+S17-S15),ABS(I5+S17-S15)) -> 0 | T11: =IF(AND(K5="horas extras",T13="positivo"),"positivo",IF(AND(K5="horas devidas",T13="Negativo"),"Negativo",IF(AND(T13="positivo",K5="horas devidas",S13>I5),"Positivo","Negativo"))) -> positivo | W11: =DATE('P Gerais'!$C$6,$W$7,Lanc!C11) -> 42008 | X11: =WEEKDAY(W11) -> 1 | AB11: 4 | AC11: QUA | AD11: =H11-G11 -> 0 | AE11: =VLOOKUP(D11,'P Gerais'!$C$23:$N$29,12,0) -> 0 | AF11: =IF(AE11-AD11<0,0,IF(OR(G11="",G11=0),0,AE11-AD11)) -> 0 | AG11: =($AG$7-I11)+F11 -> 1 | AH11: =IF(AG11<$AH$7,$AH$7-AG11,$AF$7) -> 0 | AI11: =IF(F11=I11,$AF$7,IF(F11<$AI$7,$AI$7-F11,$AF$7)) -> 0 | AJ11: =IF(F11=I11,$AF$7,IF(F11>=$AJ$7,O11,$AF$7)) -> 0 | AK11: =IF(AND(I11>$AK$7,I11>AL11),I11-AL11,$AF$7) -> 0 | AL11: =VLOOKUP(D11,'P Gerais'!$C$23:$I$29,7,FALSE) -> 0
C12: 5 | D12: =VLOOKUP(X12,$AB$8:$AC$14,2,0) -> SEG | E12: Feriado | K12: =IF(ABS(((F12-1)-G12)+(H12-I12))>=1,ABS(((F12-1)-G12)+(H12-I12))-1,ABS(((F12-1)-G12)+(H12-I12))) -> 0 | M12: =IF(E12="Falta Justificada",0,IF(E12="Feriado",0,IF(E12="Folga(DSR)",0,IF(VLOOKUP(D12,'P Gerais'!$C$23:$M$29,11,0)-Lanc!K12>0,VLOOKUP(D12,'P Gerais'!$C$23:$M$29,11,0)-Lanc!K12,0)))) -> 0 | O12: =IF(E12="Feriado",IF(F12>I12,(I12+1-F12)-(H12-G12),(I12-F12)-(H12-G12)),IF(E12="Folga(DSR)",IF(F12>I12,(I12+1-F12)-(H12-G12),(I12-F12)-(H12-G12)),IF(E12="Falta Justificada",IF(F12>I12,(I12+1-F12)-(H12-G12),(I12-F12)-(H12-G12)),IF(VLOOKUP(D12,'P Gerais'!$C$23:$M$29,11,0)-Lanc!K12<0,ABS(VLOOKUP(D12,'P Gerais'!$C$23:$M$29,11,0)-Lanc!K12),0)))) -> 0 | P12: =IF(O12>$P$7,1,0) -> 0 | W12: =DATE('P Gerais'!$C$6,$W$7,Lanc!C12) -> 42009 | X12: =WEEKDAY(W12) -> 2 | AB12: 5 | AC12: QUI | AD12: =H12-G12 -> 0 | AE12: =VLOOKUP(D12,'P Gerais'!$C$23:$N$29,12,0) -> 0 | AF12: =IF(AE12-AD12<0,0,IF(OR(G12="",G12=0),0,AE12-AD12)) -> 0 | AG12: =($AG$7-I12)+F12 -> 1 | AH12: =IF(AG12<$AH$7,$AH$7-AG12,$AF$7) -> 0 | AI12: =IF(F12=I12,$AF$7,IF(F12<$AI$7,$AI$7-F12,$AF$7)) -> 0 | AJ12: =IF(F12=I12,$AF$7,IF(F12>=$AJ$7,O12,$AF$7)) -> 0 | AK12: =IF(AND(I12>$AK$7,I12>AL12),I12-AL12,$AF$7) -> 0 | AL12: =VLOOKUP(D12,'P Gerais'!$C$23:$I$29,7,FALSE) -> 0
C13: 6 | D13: =VLOOKUP(X13,$AB$8:$AC$14,2,0) -> TER | E13: Feriado | K13: =IF(ABS(((F13-1)-G13)+(H13-I13))>=1,ABS(((F13-1)-G13)+(H13-I13))-1,ABS(((F13-1)-G13)+(H13-I13))) -> 0 | M13: =IF(E13="Falta Justificada",0,IF(E13="Feriado",0,IF(E13="Folga(DSR)",0,IF(VLOOKUP(D13,'P Gerais'!$C$23:$M$29,11,0)-Lanc!K13>0,VLOOKUP(D13,'P Gerais'!$C$23:$M$29,11,0)-Lanc!K13,0)))) -> 0 | O13: =IF(E13="Feriado",IF(F13>I13,(I13+1-F13)-(H13-G13),(I13-F13)-(H13-G13)),IF(E13="Folga(DSR)",IF(F13>I13,(I13+1-F13)-(H13-G13),(I13-F13)-(H13-G13)),IF(E13="Falta Justificada",IF(F13>I13,(I13+1-F13)-(H13-G13),(I13-F13)-(H13-G13)),IF(VLOOKUP(D13,'P Gerais'!$C$23:$M$29,11,0)-Lanc!K13<0,ABS(VLOOKUP(D13,'P Gerais'!$C$23:$M$29,11,0)-Lanc!K13),0)))) -> 0 | P13: =IF(O13>$P$7,1,0) -> 0 | Q13: Horas somados/subtraídas ao banco | S13: =IF(S15>=S17,(S15)-S17,(S17-S15)) -> 0 | T13: =IF(S15>S17,"Negativo","Positivo") -> Positivo | W13: =DATE('P Gerais'!$C$6,$W$7,Lanc!C13) -> 42010 | X13: =WEEKDAY(W13) -> 3 | AB13: 6 | AC13: SEX | AD13: =H13-G13 -> 0 | AE13: =VLOOKUP(D13,'P Gerais'!$C$23:$N$29,12,0) -> 0 | AF13: =IF(AE13-AD13<0,0,IF(OR(G13="",G13=0),0,AE13-AD13)) -> 0 | AG13: =($AG$7-I13)+F13 -> 1 | AH13: =IF(AG13<$AH$7,$AH$7-AG13,$AF$7) -> 0 | AI13: =IF(F13=I13,$AF$7,IF(F13<$AI$7,$AI$7-F13,$AF$7)) -> 0 | AJ13: =IF(F13=I13,$AF$7,IF(F13>=$AJ$7,O13,$AF$7)) -> 0 | AK13: =IF(AND(I13>$AK$7,I13>AL13),I13-AL13,$AF$7) -> 0 | AL13: =VLOOKUP(D13,'P Gerais'!$C$23:$I$29,7,FALSE) -> 0
C14: 7 | D14: =VLOOKUP(X14,$AB$8:$AC$14,2,0) -> QUA | E14: Feriado | K14: =IF(ABS(((F14-1)-G14)+(H14-I14))>=1,ABS(((F14-1)-G14)+(H14-I14))-1,ABS(((F14-1)-G14)+(H14-I14))) -> 0 | M14: =IF(E14="Falta Justificada",0,IF(E14="Feriado",0,IF(E14="Folga(DSR)",0,IF(VLOOKUP(D14,'P Gerais'!$C$23:$M$29,11,0)-Lanc!K14>0,VLOOKUP(D14,'P Gerais'!$C$23:$M$29,11,0)-Lanc!K14,0)))) -> 0 | O14: =IF(E14="Feriado",IF(F14>I14,(I14+1-F14)-(H14-G14),(I14-F14)-(H14-G14)),IF(E14="Folga(DSR)",IF(F14>I14,(I14+1-F14)-(H14-G14),(I14-F14)-(H14-G14)),IF(E14="Falta Justificada",IF(F14>I14,(I14+1-F14)-(H14-G14),(I14-F14)-(H14-G14)),IF(VLOOKUP(D14,'P Gerais'!$C$23:$M$29,11,0)-Lanc!K14<0,ABS(VLOOKUP(D14,'P Gerais'!$C$23:$M$29,11,0)-Lanc!K14),0)))) -> 0 | P14: =IF(O14>$P$7,1,0) -> 0 | W14: =DATE('P Gerais'!$C$6,$W$7,Lanc!C14) -> 42011 | X14: =WEEKDAY(W14) -> 4 | AB14: 7 | AC14: SÁB | AD14: =H14-G14 -> 0 | AE14: =VLOOKUP(D14,'P Gerais'!$C$23:$N$29,12,0) -> 0 | AF14: =IF(AE14-AD14<0,0,IF(OR(G14="",G14=0),0,AE14-AD14)) -> 0 | AG14: =($AG$7-I14)+F14 -> 1 | AH14: =IF(AG14<$AH$7,$AH$7-AG14,$AF$7) -> 0 | AI14: =IF(F14=I14,$AF$7,IF(F14<$AI$7,$AI$7-F14,$AF$7)) -> 0 | AJ14: =IF(F14=I14,$AF$7,IF(F14>=$AJ$7,O14,$AF$7)) -> 0 | AK14: =IF(AND(I14>$AK$7,I14>AL14),I14-AL14,$AF$7) -> 0 | AL14: =VLOOKUP(D14,'P Gerais'!$C$23:$I$29,7,FALSE) -> 0
C15: 8 | D15: =VLOOKUP(X15,$AB$8:$AC$14,2,0) -> QUI | E15: Feriado | K15: =IF(ABS(((F15-1)-G15)+(H15-I15))>=1,ABS(((F15-1)-G15)+(H15-I15))-1,ABS(((F15-1)-G15)+(H15-I15))) -> 0 | M15: =IF(E15="Falta Justificada",0,IF(E15="Feriado",0,IF(E15="Folga(DSR)",0,IF(VLOOKUP(D15,'P Gerais'!$C$23:$M$29,11,0)-Lanc!K15>0,VLOOKUP(D15,'P Gerais'!$C$23:$M$29,11,0)-Lanc!K15,0)))) -> 0 | O15: =IF(E15="Feriado",IF(F15>I15,(I15+1-F15)-(H15-G15),(I15-F15)-(H15-G15)),IF(E15="Folga(DSR)",IF(F15>I15,(I15+1-F15)-(H15-G15),(I15-F15)-(H15-G15)),IF(E15="Falta Justificada",IF(F15>I15,(I15+1-F15)-(H15-G15),(I15-F15)-(H15-G15)),IF(VLOOKUP(D15,'P Gerais'!$C$23:$M$29,11,0)-Lanc!K15<0,ABS(VLOOKUP(D15,'P Gerais'!$C$23:$M$29,11,0)-Lanc!K15),0)))) -> 0 | P15: =IF(O15>$P$7,1,0) -> 0 | Q15: Total de horas devidas | S15: =SUM(M8:M38) -> 0 | W15: =DATE('P Gerais'!$C$6,$W$7,Lanc!C15) -> 42012 | X15: =WEEKDAY(W15) -> 5 | AD15: =H15-G15 -> 0 | AE15: =VLOOKUP(D15,'P Gerais'!$C$23:$N$29,12,0) -> 0 | AF15: =IF(AE15-AD15<0,0,IF(OR(G15="",G15=0),0,AE15-AD15)) -> 0 | AG15: =($AG$7-I15)+F15 -> 1 | AH15: =IF(AG15<$AH$7,$AH$7-AG15,$AF$7) -> 0 | AI15: =IF(F15=I15,$AF$7,IF(F15<$AI$7,$AI$7-F15,$AF$7)) -> 0 | AJ15: =IF(F15=I15,$AF$7,IF(F15>=$AJ$7,O15,$AF$7)) -> 0 | AK15: =IF(AND(I15>$AK$7,I15>AL15),I15-AL15,$AF$7) -> 0 | AL15: =VLOOKUP(D15,'P Gerais'!$C$23:$I$29,7,FALSE) -> 0
C16: 9 | D16: =VLOOKUP(X16,$AB$8:$AC$14,2,0) -> SEX | E16: Feriado | K16: =IF(ABS(((F16-1)-G16)+(H16-I16))>=1,ABS(((F16-1)-G16)+(H16-I16))-1,ABS(((F16-1)-G16)+(H16-I16))) -> 0 | M16: =IF(E16="Falta Justificada",0,IF(E16="Feriado",0,IF(E16="Folga(DSR)",0,IF(VLOOKUP(D16,'P Gerais'!$C$23:$M$29,11,0)-Lanc!K16>0,VLOOKUP(D16,'P Gerais'!$C$23:$M$29,11,0)-Lanc!K16,0)))) -> 0 | O16: =IF(E16="Feriado",IF(F16>I16,(I16+1-F16)-(H16-G16),(I16-F16)-(H16-G16)),IF(E16="Folga(DSR)",IF(F16>I16,(I16+1-F16)-(H16-G16),(I16-F16)-(H16-G16)),IF(E16="Falta Justificada",IF(F16>I16,(I16+1-F16)-(H16-G16),(I16-F16)-(H16-G16)),IF(VLOOKUP(D16,'P Gerais'!$C$23:$M$29,11,0)-Lanc!K16<0,ABS(VLOOKUP(D16,'P Gerais'!$C$23:$M$29,11,0)-Lanc!K16),0)))) -> 0 | P16: =IF(O16>$P$7,1,0) -> 0 | W16: =DATE('P Gerais'!$C$6,$W$7,Lanc!C16) -> 42013 | X16: =WEEKDAY(W16) -> 6 | AD16: =H16-G16 -> 0 | AE16: =VLOOKUP(D16,'P Gerais'!$C$23:$N$29,12,0) -> 0 | AF16: =IF(AE16-AD16<0,0,IF(OR(G16="",G16=0),0,AE16-AD16)) -> 0 | AG16: =($AG$7-I16)+F16 -> 1 | AH16: =IF(AG16<$AH$7,$AH$7-AG16,$AF$7) -> 0 | AI16: =IF(F16=I16,$AF$7,IF(F16<$AI$7,$AI$7-F16,$AF$7)) -> 0 | AJ16: =IF(F16=I16,$AF$7,IF(F16>=$AJ$7,O16,$AF$7)) -> 0 | AK16: =IF(AND(I16>$AK$7,I16>AL16),I16-AL16,$AF$7) -> 0 | AL16: =VLOOKUP(D16,'P Gerais'!$C$23:$I$29,7,FALSE) -> 0
C17: 10 | D17: =VLOOKUP(X17,$AB$8:$AC$14,2,0) -> SÁB | E17: Feriado | K17: =IF(ABS(((F17-1)-G17)+(H17-I17))>=1,ABS(((F17-1)-G17)+(H17-I17))-1,ABS(((F17-1)-G17)+(H17-I17))) -> 0 | M17: =IF(E17="Falta Justificada",0,IF(E17="Feriado",0,IF(E17="Folga(DSR)",0,IF(VLOOKUP(D17,'P Gerais'!$C$23:$M$29,11,0)-Lanc!K17>0,VLOOKUP(D17,'P Gerais'!$C$23:$M$29,11,0)-Lanc!K17,0)))) -> 0 | O17: =IF(E17="Feriado",IF(F17>I17,(I17+1-F17)-(H17-G17),(I17-F17)-(H17-G17)),IF(E17="Folga(DSR)",IF(F17>I17,(I17+1-F17)-(H17-G17),(I17-F17)-(H17-G17)),IF(E17="Falta Justificada",IF(F17>I17,(I17+1-F17)-(H17-G17),(I17-F17)-(H17-G17)),IF(VLOOKUP(D17,'P Gerais'!$C$23:$M$29,11,0)-Lanc!K17<0,ABS(VLOOKUP(D17,'P Gerais'!$C$23:$M$29,11,0)-Lanc!K17),0)))) -> 0 | P17: =IF(O17>$P$7,1,0) -> 0 | Q17: Total de horas extras | S17: =SUM(O8:O38) -> 0 | W17: =DATE('P Gerais'!$C$6,$W$7,Lanc!C17) -> 42014 | X17: =WEEKDAY(W17) -> 7 | AD17: =H17-G17 -> 0 | AE17: =VLOOKUP(D17,'P Gerais'!$C$23:$N$29,12,0) -> 0 | AF17: =IF(AE17-AD17<0,0,IF(OR(G17="",G17=0),0,AE17-AD17)) -> 0 | AG17: =($AG$7-I17)+F17 -> 1 | AH17: =IF(AG17<$AH$7,$AH$7-AG17,$AF$7) -> 0 | AI17: =IF(F17=I17,$AF$7,IF(F17<$AI$7,$AI$7-F17,$AF$7)) -> 0 | AJ17: =IF(F17=I17,$AF$7,IF(F17>=$AJ$7,O17,$AF$7)) -> 0 | AK17: =IF(AND(I17>$AK$7,I17>AL17),I17-AL17,$AF$7) -> 0 | AL17: =VLOOKUP(D17,'P Gerais'!$C$23:$I$29,7,FALSE) -> 0
C18: 11 | D18: =VLOOKUP(X18,$AB$8:$AC$14,2,0) -> DOM | E18: Feriado | K18: =IF(ABS(((F18-1)-G18)+(H18-I18))>=1,ABS(((F18-1)-G18)+(H18-I18))-1,ABS(((F18-1)-G18)+(H18-I18))) -> 0 | M18: =IF(E18="Falta Justificada",0,IF(E18="Feriado",0,IF(E18="Folga(DSR)",0,IF(VLOOKUP(D18,'P Gerais'!$C$23:$M$29,11,0)-Lanc!K18>0,VLOOKUP(D18,'P Gerais'!$C$23:$M$29,11,0)-Lanc!K18,0)))) -> 0 | O18: =IF(E18="Feriado",IF(F18>I18,(I18+1-F18)-(H18-G18),(I18-F18)-(H18-G18)),IF(E18="Folga(DSR)",IF(F18>I18,(I18+1-F18)-(H18-G18),(I18-F18)-(H18-G18)),IF(E18="Falta Justificada",IF(F18>I18,(I18+1-F18)-(H18-G18),(I18-F18)-(H18-G18)),IF(VLOOKUP(D18,'P Gerais'!$C$23:$M$29,11,0)-Lanc!K18<0,ABS(VLOOKUP(D18,'P Gerais'!$C$23:$M$29,11,0)-Lanc!K18),0)))) -> 0 | P18: =IF(O18>$P$7,1,0) -> 0 | W18: =DATE('P Gerais'!$C$6,$W$7,Lanc!C18) -> 42015 | X18: =WEEKDAY(W18) -> 1 | AD18: =H18-G18 -> 0 | AE18: =VLOOKUP(D18,'P Gerais'!$C$23:$N$29,12,0) -> 0 | AF18: =IF(AE18-AD18<0,0,IF(OR(G18="",G18=0),0,AE18-AD18)) -> 0 | AG18: =($AG$7-I18)+F18 -> 1 | AH18: =IF(AG18<$AH$7,$AH$7-AG18,$AF$7) -> 0 | AI18: =IF(F18=I18,$AF$7,IF(F18<$AI$7,$AI$7-F18,$AF$7)) -> 0 | AJ18: =IF(F18=I18,$AF$7,IF(F18>=$AJ$7,O18,$AF$7)) -> 0 | AK18: =IF(AND(I18>$AK$7,I18>AL18),I18-AL18,$AF$7) -> 0 | AL18: =VLOOKUP(D18,'P Gerais'!$C$23:$I$29,7,FALSE) -> 0
C19: 12 | D19: =VLOOKUP(X19,$AB$8:$AC$14,2,0) -> SEG | E19: Feriado | K19: =IF(ABS(((F19-1)-G19)+(H19-I19))>=1,ABS(((F19-1)-G19)+(H19-I19))-1,ABS(((F19-1)-G19)+(H19-I19))) -> 0 | M19: =IF(E19="Falta Justificada",0,IF(E19="Feriado",0,IF(E19="Folga(DSR)",0,IF(VLOOKUP(D19,'P Gerais'!$C$23:$M$29,11,0)-Lanc!K19>0,VLOOKUP(D19,'P Gerais'!$C$23:$M$29,11,0)-Lanc!K19,0)))) -> 0 | O19: =IF(E19="Feriado",IF(F19>I19,(I19+1-F19)-(H19-G19),(I19-F19)-(H19-G19)),IF(E19="Folga(DSR)",IF(F19>I19,(I19+1-F19)-(H19-G19),(I19-F19)-(H19-G19)),IF(E19="Falta Justificada",IF(F19>I19,(I19+1-F19)-(H19-G19),(I19-F19)-(H19-G19)),IF(VLOOKUP(D19,'P Gerais'!$C$23:$M$29,11,0)-Lanc!K19<0,ABS(VLOOKUP(D19,'P Gerais'!$C$23:$M$29,11,0)-Lanc!K19),0)))) -> 0 | P19: =IF(O19>$P$7,1,0) -> 0 | Q19: Total de hora extra a pagar | S19: =F54 -> 0 | W19: =DATE('P Gerais'!$C$6,$W$7,Lanc!C19) -> 42016 | X19: =WEEKDAY(W19) -> 2 | AD19: =H19-G19 -> 0 | AE19: =VLOOKUP(D19,'P Gerais'!$C$23:$N$29,12,0) -> 0 | AF19: =IF(AE19-AD19<0,0,IF(OR(G19="",G19=0),0,AE19-AD19)) -> 0 | AG19: =($AG$7-I19)+F19 -> 1 | AH19: =IF(AG19<$AH$7,$AH$7-AG19,$AF$7) -> 0 | AI19: =IF(F19=I19,$AF$7,IF(F19<$AI$7,$AI$7-F19,$AF$7)) -> 0 | AJ19: =IF(F19=I19,$AF$7,IF(F19>=$AJ$7,O19,$AF$7)) -> 0 | AK19: =IF(AND(I19>$AK$7,I19>AL19),I19-AL19,$AF$7) -> 0 | AL19: =VLOOKUP(D19,'P Gerais'!$C$23:$I$29,7,FALSE) -> 0
C20: 13 | D20: =VLOOKUP(X20,$AB$8:$AC$14,2,0) -> TER | E20: Feriado | K20: =IF(ABS(((F20-1)-G20)+(H20-I20))>=1,ABS(((F20-1)-G20)+(H20-I20))-1,ABS(((F20-1)-G20)+(H20-I20))) -> 0 | M20: =IF(E20="Falta Justificada",0,IF(E20="Feriado",0,IF(E20="Folga(DSR)",0,IF(VLOOKUP(D20,'P Gerais'!$C$23:$M$29,11,0)-Lanc!K20>0,VLOOKUP(D20,'P Gerais'!$C$23:$M$29,11,0)-Lanc!K20,0)))) -> 0 | O20: =IF(E20="Feriado",IF(F20>I20,(I20+1-F20)-(H20-G20),(I20-F20)-(H20-G20)),IF(E20="Folga(DSR)",IF(F20>I20,(I20+1-F20)-(H20-G20),(I20-F20)-(H20-G20)),IF(E20="Falta Justificada",IF(F20>I20,(I20+1-F20)-(H20-G20),(I20-F20)-(H20-G20)),IF(VLOOKUP(D20,'P Gerais'!$C$23:$M$29,11,0)-Lanc!K20<0,ABS(VLOOKUP(D20,'P Gerais'!$C$23:$M$29,11,0)-Lanc!K20),0)))) -> 0 | P20: =IF(O20>$P$7,1,0) -> 0 | W20: =DATE('P Gerais'!$C$6,$W$7,Lanc!C20) -> 42017 | X20: =WEEKDAY(W20) -> 3 | AD20: =H20-G20 -> 0 | AE20: =VLOOKUP(D20,'P Gerais'!$C$23:$N$29,12,0) -> 0 | AF20: =IF(AE20-AD20<0,0,IF(OR(G20="",G20=0),0,AE20-AD20)) -> 0 | AG20: =($AG$7-I20)+F20 -> 1 | AH20: =IF(AG20<$AH$7,$AH$7-AG20,$AF$7) -> 0 | AI20: =IF(F20=I20,$AF$7,IF(F20<$AI$7,$AI$7-F20,$AF$7)) -> 0 | AJ20: =IF(F20=I20,$AF$7,IF(F20>=$AJ$7,O20,$AF$7)) -> 0 | AK20: =IF(AND(I20>$AK$7,I20>AL20),I20-AL20,$AF$7) -> 0 | AL20: =VLOOKUP(D20,'P Gerais'!$C$23:$I$29,7,FALSE) -> 0
C21: 14 | D21: =VLOOKUP(X21,$AB$8:$AC$14,2,0) -> QUA | E21: Feriado | K21: =IF(ABS(((F21-1)-G21)+(H21-I21))>=1,ABS(((F21-1)-G21)+(H21-I21))-1,ABS(((F21-1)-G21)+(H21-I21))) -> 0 | M21: =IF(E21="Falta Justificada",0,IF(E21="Feriado",0,IF(E21="Folga(DSR)",0,IF(VLOOKUP(D21,'P Gerais'!$C$23:$M$29,11,0)-Lanc!K21>0,VLOOKUP(D21,'P Gerais'!$C$23:$M$29,11,0)-Lanc!K21,0)))) -> 0 | O21: =IF(E21="Feriado",IF(F21>I21,(I21+1-F21)-(H21-G21),(I21-F21)-(H21-G21)),IF(E21="Folga(DSR)",IF(F21>I21,(I21+1-F21)-(H21-G21),(I21-F21)-(H21-G21)),IF(E21="Falta Justificada",IF(F21>I21,(I21+1-F21)-(H21-G21),(I21-F21)-(H21-G21)),IF(VLOOKUP(D21,'P Gerais'!$C$23:$M$29,11,0)-Lanc!K21<0,ABS(VLOOKUP(D21,'P Gerais'!$C$23:$M$29,11,0)-Lanc!K21),0)))) -> 0 | P21: =IF(O21>$P$7,1,0) -> 0 | W21: =DATE('P Gerais'!$C$6,$W$7,Lanc!C21) -> 42018 | X21: =WEEKDAY(W21) -> 4 | AD21: =H21-G21 -> 0 | AE21: =VLOOKUP(D21,'P Gerais'!$C$23:$N$29,12,0) -> 0 | AF21: =IF(AE21-AD21<0,0,IF(OR(G21="",G21=0),0,AE21-AD21)) -> 0 | AG21: =($AG$7-I21)+F21 -> 1 | AH21: =IF(AG21<$AH$7,$AH$7-AG21,$AF$7) -> 0 | AI21: =IF(F21=I21,$AF$7,IF(F21<$AI$7,$AI$7-F21,$AF$7)) -> 0 | AJ21: =IF(F21=I21,$AF$7,IF(F21>=$AJ$7,O21,$AF$7)) -> 0 | AK21: =IF(AND(I21>$AK$7,I21>AL21),I21-AL21,$AF$7) -> 0 | AL21: =VLOOKUP(D21,'P Gerais'!$C$23:$I$29,7,FALSE) -> 0
C22: 15 | D22: =VLOOKUP(X22,$AB$8:$AC$14,2,0) -> QUI | E22: Feriado | K22: =IF(ABS(((F22-1)-G22)+(H22-I22))>=1,ABS(((F22-1)-G22)+(H22-I22))-1,ABS(((F22-1)-G22)+(H22-I22))) -> 0 | M22: =IF(E22="Falta Justificada",0,IF(E22="Feriado",0,IF(E22="Folga(DSR)",0,IF(VLOOKUP(D22,'P Gerais'!$C$23:$M$29,11,0)-Lanc!K22>0,VLOOKUP(D22,'P Gerais'!$C$23:$M$29,11,0)-Lanc!K22,0)))) -> 0 | O22: =IF(E22="Feriado",IF(F22>I22,(I22+1-F22)-(H22-G22),(I22-F22)-(H22-G22)),IF(E22="Folga(DSR)",IF(F22>I22,(I22+1-F22)-(H22-G22),(I22-F22)-(H22-G22)),IF(E22="Falta Justificada",IF(F22>I22,(I22+1-F22)-(H22-G22),(I22-F22)-(H22-G22)),IF(VLOOKUP(D22,'P Gerais'!$C$23:$M$29,11,0)-Lanc!K22<0,ABS(VLOOKUP(D22,'P Gerais'!$C$23:$M$29,11,0)-Lanc!K22),0)))) -> 0 | P22: =IF(O22>$P$7,1,0) -> 0 | W22: =DATE('P Gerais'!$C$6,$W$7,Lanc!C22) -> 42019 | X22: =WEEKDAY(W22) -> 5 | AD22: =H22-G22 -> 0 | AE22: =VLOOKUP(D22,'P Gerais'!$C$23:$N$29,12,0) -> 0 | AF22: =IF(AE22-AD22<0,0,IF(OR(G22="",G22=0),0,AE22-AD22)) -> 0 | AG22: =($AG$7-I22)+F22 -> 1 | AH22: =IF(AG22<$AH$7,$AH$7-AG22,$AF$7) -> 0 | AI22: =IF(F22=I22,$AF$7,IF(F22<$AI$7,$AI$7-F22,$AF$7)) -> 0 | AJ22: =IF(F22=I22,$AF$7,IF(F22>=$AJ$7,O22,$AF$7)) -> 0 | AK22: =IF(AND(I22>$AK$7,I22>AL22),I22-AL22,$AF$7) -> 0 | AL22: =VLOOKUP(D22,'P Gerais'!$C$23:$I$29,7,FALSE) -> 0
C23: 16 | D23: =VLOOKUP(X23,$AB$8:$AC$14,2,0) -> SEX | E23: Feriado | K23: =IF(ABS(((F23-1)-G23)+(H23-I23))>=1,ABS(((F23-1)-G23)+(H23-I23))-1,ABS(((F23-1)-G23)+(H23-I23))) -> 0 | M23: =IF(E23="Falta Justificada",0,IF(E23="Feriado",0,IF(E23="Folga(DSR)",0,IF(VLOOKUP(D23,'P Gerais'!$C$23:$M$29,11,0)-Lanc!K23>0,VLOOKUP(D23,'P Gerais'!$C$23:$M$29,11,0)-Lanc!K23,0)))) -> 0 | O23: =IF(E23="Feriado",IF(F23>I23,(I23+1-F23)-(H23-G23),(I23-F23)-(H23-G23)),IF(E23="Folga(DSR)",IF(F23>I23,(I23+1-F23)-(H23-G23),(I23-F23)-(H23-G23)),IF(E23="Falta Justificada",IF(F23>I23,(I23+1-F23)-(H23-G23),(I23-F23)-(H23-G23)),IF(VLOOKUP(D23,'P Gerais'!$C$23:$M$29,11,0)-Lanc!K23<0,ABS(VLOOKUP(D23,'P Gerais'!$C$23:$M$29,11,0)-Lanc!K23),0)))) -> 0 | P23: =IF(O23>$P$7,1,0) -> 0 | Q23: Horas Extras | W23: =DATE('P Gerais'!$C$6,$W$7,Lanc!C23) -> 42020 | X23: =WEEKDAY(W23) -> 6 | AD23: =H23-G23 -> 0 | AE23: =VLOOKUP(D23,'P Gerais'!$C$23:$N$29,12,0) -> 0 | AF23: =IF(AE23-AD23<0,0,IF(OR(G23="",G23=0),0,AE23-AD23)) -> 0 | AG23: =($AG$7-I23)+F23 -> 1 | AH23: =IF(AG23<$AH$7,$AH$7-AG23,$AF$7) -> 0 | AI23: =IF(F23=I23,$AF$7,IF(F23<$AI$7,$AI$7-F23,$AF$7)) -> 0 | AJ23: =IF(F23=I23,$AF$7,IF(F23>=$AJ$7,O23,$AF$7)) -> 0 | AK23: =IF(AND(I23>$AK$7,I23>AL23),I23-AL23,$AF$7) -> 0 | AL23: =VLOOKUP(D23,'P Gerais'!$C$23:$I$29,7,FALSE) -> 0
C24: 17 | D24: =VLOOKUP(X24,$AB$8:$AC$14,2,0) -> SÁB | E24: Feriado | K24: =IF(ABS(((F24-1)-G24)+(H24-I24))>=1,ABS(((F24-1)-G24)+(H24-I24))-1,ABS(((F24-1)-G24)+(H24-I24))) -> 0 | M24: =IF(E24="Falta Justificada",0,IF(E24="Feriado",0,IF(E24="Folga(DSR)",0,IF(VLOOKUP(D24,'P Gerais'!$C$23:$M$29,11,0)-Lanc!K24>0,VLOOKUP(D24,'P Gerais'!$C$23:$M$29,11,0)-Lanc!K24,0)))) -> 0 | O24: =IF(E24="Feriado",IF(F24>I24,(I24+1-F24)-(H24-G24),(I24-F24)-(H24-G24)),IF(E24="Folga(DSR)",IF(F24>I24,(I24+1-F24)-(H24-G24),(I24-F24)-(H24-G24)),IF(E24="Falta Justificada",IF(F24>I24,(I24+1-F24)-(H24-G24),(I24-F24)-(H24-G24)),IF(VLOOKUP(D24,'P Gerais'!$C$23:$M$29,11,0)-Lanc!K24<0,ABS(VLOOKUP(D24,'P Gerais'!$C$23:$M$29,11,0)-Lanc!K24),0)))) -> 0 | P24: =IF(O24>$P$7,1,0) -> 0 | W24: =DATE('P Gerais'!$C$6,$W$7,Lanc!C24) -> 42021 | X24: =WEEKDAY(W24) -> 7 | AD24: =H24-G24 -> 0 | AE24: =VLOOKUP(D24,'P Gerais'!$C$23:$N$29,12,0) -> 0 | AF24: =IF(AE24-AD24<0,0,IF(OR(G24="",G24=0),0,AE24-AD24)) -> 0 | AG24: =($AG$7-I24)+F24 -> 1 | AH24: =IF(AG24<$AH$7,$AH$7-AG24,$AF$7) -> 0 | AI24: =IF(F24=I24,$AF$7,IF(F24<$AI$7,$AI$7-F24,$AF$7)) -> 0 | AJ24: =IF(F24=I24,$AF$7,IF(F24>=$AJ$7,O24,$AF$7)) -> 0 | AK24: =IF(AND(I24>$AK$7,I24>AL24),I24-AL24,$AF$7) -> 0 | AL24: =VLOOKUP(D24,'P Gerais'!$C$23:$I$29,7,FALSE) -> 0
C25: 18 | D25: =VLOOKUP(X25,$AB$8:$AC$14,2,0) -> DOM | E25: Feriado | K25: =IF(ABS(((F25-1)-G25)+(H25-I25))>=1,ABS(((F25-1)-G25)+(H25-I25))-1,ABS(((F25-1)-G25)+(H25-I25))) -> 0 | M25: =IF(E25="Falta Justificada",0,IF(E25="Feriado",0,IF(E25="Folga(DSR)",0,IF(VLOOKUP(D25,'P Gerais'!$C$23:$M$29,11,0)-Lanc!K25>0,VLOOKUP(D25,'P Gerais'!$C$23:$M$29,11,0)-Lanc!K25,0)))) -> 0 | O25: =IF(E25="Feriado",IF(F25>I25,(I25+1-F25)-(H25-G25),(I25-F25)-(H25-G25)),IF(E25="Folga(DSR)",IF(F25>I25,(I25+1-F25)-(H25-G25),(I25-F25)-(H25-G25)),IF(E25="Falta Justificada",IF(F25>I25,(I25+1-F25)-(H25-G25),(I25-F25)-(H25-G25)),IF(VLOOKUP(D25,'P Gerais'!$C$23:$M$29,11,0)-Lanc!K25<0,ABS(VLOOKUP(D25,'P Gerais'!$C$23:$M$29,11,0)-Lanc!K25),0)))) -> 0 | P25: =IF(O25>$P$7,1,0) -> 0 | Q25: =IF(SUM(P8:P38)>0,"Segundo o art 59 da CLT, o máximo de horas extras permitidas por dia são 2(duas). Reveja as horas lançadas se deseja estar de acordo com as leis trabalhistas em vigor no Brasil.","Parabéns!! Todas os dias estão dentro do limite de duas horas extras estipuladas pela CLT.") -> Parabéns!! Todas os dias estão dentro do limite de duas horas extras estipuladas pela CLT. | T25: =IF(SUM(P8:P38)>0,1,0) -> 0 | W25: =DATE('P Gerais'!$C$6,$W$7,Lanc!C25) -> 42022 | X25: =WEEKDAY(W25) -> 1 | AD25: =H25-G25 -> 0 | AE25: =VLOOKUP(D25,'P Gerais'!$C$23:$N$29,12,0) -> 0 | AF25: =IF(AE25-AD25<0,0,IF(OR(G25="",G25=0),0,AE25-AD25)) -> 0 | AG25: =($AG$7-I25)+F25 -> 1 | AH25: =IF(AG25<$AH$7,$AH$7-AG25,$AF$7) -> 0 | AI25: =IF(F25=I25,$AF$7,IF(F25<$AI$7,$AI$7-F25,$AF$7)) -> 0 | AJ25: =IF(F25=I25,$AF$7,IF(F25>=$AJ$7,O25,$AF$7)) -> 0 | AK25: =IF(AND(I25>$AK$7,I25>AL25),I25-AL25,$AF$7) -> 0 | AL25: =VLOOKUP(D25,'P Gerais'!$C$23:$I$29,7,FALSE) -> 0
C26: 19 | D26: =VLOOKUP(X26,$AB$8:$AC$14,2,0) -> SEG | E26: Feriado | K26: =IF(ABS(((F26-1)-G26)+(H26-I26))>=1,ABS(((F26-1)-G26)+(H26-I26))-1,ABS(((F26-1)-G26)+(H26-I26))) -> 0 | M26: =IF(E26="Falta Justificada",0,IF(E26="Feriado",0,IF(E26="Folga(DSR)",0,IF(VLOOKUP(D26,'P Gerais'!$C$23:$M$29,11,0)-Lanc!K26>0,VLOOKUP(D26,'P Gerais'!$C$23:$M$29,11,0)-Lanc!K26,0)))) -> 0 | O26: =IF(E26="Feriado",IF(F26>I26,(I26+1-F26)-(H26-G26),(I26-F26)-(H26-G26)),IF(E26="Folga(DSR)",IF(F26>I26,(I26+1-F26)-(H26-G26),(I26-F26)-(H26-G26)),IF(E26="Falta Justificada",IF(F26>I26,(I26+1-F26)-(H26-G26),(I26-F26)-(H26-G26)),IF(VLOOKUP(D26,'P Gerais'!$C$23:$M$29,11,0)-Lanc!K26<0,ABS(VLOOKUP(D26,'P Gerais'!$C$23:$M$29,11,0)-Lanc!K26),0)))) -> 0 | P26: =IF(O26>$P$7,1,0) -> 0 | W26: =DATE('P Gerais'!$C$6,$W$7,Lanc!C26) -> 42023 | X26: =WEEKDAY(W26) -> 2 | AD26: =H26-G26 -> 0 | AE26: =VLOOKUP(D26,'P Gerais'!$C$23:$N$29,12,0) -> 0 | AF26: =IF(AE26-AD26<0,0,IF(OR(G26="",G26=0),0,AE26-AD26)) -> 0 | AG26: =($AG$7-I26)+F26 -> 1 | AH26: =IF(AG26<$AH$7,$AH$7-AG26,$AF$7) -> 0 | AI26: =IF(F26=I26,$AF$7,IF(F26<$AI$7,$AI$7-F26,$AF$7)) -> 0 | AJ26: =IF(F26=I26,$AF$7,IF(F26>=$AJ$7,O26,$AF$7)) -> 0 | AK26: =IF(AND(I26>$AK$7,I26>AL26),I26-AL26,$AF$7) -> 0 | AL26: =VLOOKUP(D26,'P Gerais'!$C$23:$I$29,7,FALSE) -> 0
C27: 20 | D27: =VLOOKUP(X27,$AB$8:$AC$14,2,0) -> TER | E27: Feriado | K27: =IF(ABS(((F27-1)-G27)+(H27-I27))>=1,ABS(((F27-1)-G27)+(H27-I27))-1,ABS(((F27-1)-G27)+(H27-I27))) -> 0 | M27: =IF(E27="Falta Justificada",0,IF(E27="Feriado",0,IF(E27="Folga(DSR)",0,IF(VLOOKUP(D27,'P Gerais'!$C$23:$M$29,11,0)-Lanc!K27>0,VLOOKUP(D27,'P Gerais'!$C$23:$M$29,11,0)-Lanc!K27,0)))) -> 0 | O27: =IF(E27="Feriado",IF(F27>I27,(I27+1-F27)-(H27-G27),(I27-F27)-(H27-G27)),IF(E27="Folga(DSR)",IF(F27>I27,(I27+1-F27)-(H27-G27),(I27-F27)-(H27-G27)),IF(E27="Falta Justificada",IF(F27>I27,(I27+1-F27)-(H27-G27),(I27-F27)-(H27-G27)),IF(VLOOKUP(D27,'P Gerais'!$C$23:$M$29,11,0)-Lanc!K27<0,ABS(VLOOKUP(D27,'P Gerais'!$C$23:$M$29,11,0)-Lanc!K27),0)))) -> 0 | P27: =IF(O27>$P$7,1,0) -> 0 | W27: =DATE('P Gerais'!$C$6,$W$7,Lanc!C27) -> 42024 | X27: =WEEKDAY(W27) -> 3 | AD27: =H27-G27 -> 0 | AE27: =VLOOKUP(D27,'P Gerais'!$C$23:$N$29,12,0) -> 0 | AF27: =IF(AE27-AD27<0,0,IF(OR(G27="",G27=0),0,AE27-AD27)) -> 0 | AG27: =($AG$7-I27)+F27 -> 1 | AH27: =IF(AG27<$AH$7,$AH$7-AG27,$AF$7) -> 0 | AI27: =IF(F27=I27,$AF$7,IF(F27<$AI$7,$AI$7-F27,$AF$7)) -> 0 | AJ27: =IF(F27=I27,$AF$7,IF(F27>=$AJ$7,O27,$AF$7)) -> 0 | AK27: =IF(AND(I27>$AK$7,I27>AL27),I27-AL27,$AF$7) -> 0 | AL27: =VLOOKUP(D27,'P Gerais'!$C$23:$I$29,7,FALSE) -> 0
C28: 21 | D28: =VLOOKUP(X28,$AB$8:$AC$14,2,0) -> QUA | E28: Feriado | K28: =IF(ABS(((F28-1)-G28)+(H28-I28))>=1,ABS(((F28-1)-G28)+(H28-I28))-1,ABS(((F28-1)-G28)+(H28-I28))) -> 0 | M28: =IF(E28="Falta Justificada",0,IF(E28="Feriado",0,IF(E28="Folga(DSR)",0,IF(VLOOKUP(D28,'P Gerais'!$C$23:$M$29,11,0)-Lanc!K28>0,VLOOKUP(D28,'P Gerais'!$C$23:$M$29,11,0)-Lanc!K28,0)))) -> 0 | O28: =IF(E28="Feriado",IF(F28>I28,(I28+1-F28)-(H28-G28),(I28-F28)-(H28-G28)),IF(E28="Folga(DSR)",IF(F28>I28,(I28+1-F28)-(H28-G28),(I28-F28)-(H28-G28)),IF(E28="Falta Justificada",IF(F28>I28,(I28+1-F28)-(H28-G28),(I28-F28)-(H28-G28)),IF(VLOOKUP(D28,'P Gerais'!$C$23:$M$29,11,0)-Lanc!K28<0,ABS(VLOOKUP(D28,'P Gerais'!$C$23:$M$29,11,0)-Lanc!K28),0)))) -> 0 | P28: =IF(O28>$P$7,1,0) -> 0 | W28: =DATE('P Gerais'!$C$6,$W$7,Lanc!C28) -> 42025 | X28: =WEEKDAY(W28) -> 4 | AD28: =H28-G28 -> 0 | AE28: =VLOOKUP(D28,'P Gerais'!$C$23:$N$29,12,0) -> 0 | AF28: =IF(AE28-AD28<0,0,IF(OR(G28="",G28=0),0,AE28-AD28)) -> 0 | AG28: =($AG$7-I28)+F28 -> 1 | AH28: =IF(AG28<$AH$7,$AH$7-AG28,$AF$7) -> 0 | AI28: =IF(F28=I28,$AF$7,IF(F28<$AI$7,$AI$7-F28,$AF$7)) -> 0 | AJ28: =IF(F28=I28,$AF$7,IF(F28>=$AJ$7,O28,$AF$7)) -> 0 | AK28: =IF(AND(I28>$AK$7,I28>AL28),I28-AL28,$AF$7) -> 0 | AL28: =VLOOKUP(D28,'P Gerais'!$C$23:$I$29,7,FALSE) -> 0
C29: 22 | D29: =VLOOKUP(X29,$AB$8:$AC$14,2,0) -> QUI | E29: Feriado | K29: =IF(ABS(((F29-1)-G29)+(H29-I29))>=1,ABS(((F29-1)-G29)+(H29-I29))-1,ABS(((F29-1)-G29)+(H29-I29))) -> 0 | M29: =IF(E29="Falta Justificada",0,IF(E29="Feriado",0,IF(E29="Folga(DSR)",0,IF(VLOOKUP(D29,'P Gerais'!$C$23:$M$29,11,0)-Lanc!K29>0,VLOOKUP(D29,'P Gerais'!$C$23:$M$29,11,0)-Lanc!K29,0)))) -> 0 | O29: =IF(E29="Feriado",IF(F29>I29,(I29+1-F29)-(H29-G29),(I29-F29)-(H29-G29)),IF(E29="Folga(DSR)",IF(F29>I29,(I29+1-F29)-(H29-G29),(I29-F29)-(H29-G29)),IF(E29="Falta Justificada",IF(F29>I29,(I29+1-F29)-(H29-G29),(I29-F29)-(H29-G29)),IF(VLOOKUP(D29,'P Gerais'!$C$23:$M$29,11,0)-Lanc!K29<0,ABS(VLOOKUP(D29,'P Gerais'!$C$23:$M$29,11,0)-Lanc!K29),0)))) -> 0 | P29: =IF(O29>$P$7,1,0) -> 0 | W29: =DATE('P Gerais'!$C$6,$W$7,Lanc!C29) -> 42026 | X29: =WEEKDAY(W29) -> 5 | AD29: =H29-G29 -> 0 | AE29: =VLOOKUP(D29,'P Gerais'!$C$23:$N$29,12,0) -> 0 | AF29: =IF(AE29-AD29<0,0,IF(OR(G29="",G29=0),0,AE29-AD29)) -> 0 | AG29: =($AG$7-I29)+F29 -> 1 | AH29: =IF(AG29<$AH$7,$AH$7-AG29,$AF$7) -> 0 | AI29: =IF(F29=I29,$AF$7,IF(F29<$AI$7,$AI$7-F29,$AF$7)) -> 0 | AJ29: =IF(F29=I29,$AF$7,IF(F29>=$AJ$7,O29,$AF$7)) -> 0 | AK29: =IF(AND(I29>$AK$7,I29>AL29),I29-AL29,$AF$7) -> 0 | AL29: =VLOOKUP(D29,'P Gerais'!$C$23:$I$29,7,FALSE) -> 0
C30: 23 | D30: =VLOOKUP(X30,$AB$8:$AC$14,2,0) -> SEX | E30: Feriado | K30: =IF(ABS(((F30-1)-G30)+(H30-I30))>=1,ABS(((F30-1)-G30)+(H30-I30))-1,ABS(((F30-1)-G30)+(H30-I30))) -> 0 | M30: =IF(E30="Falta Justificada",0,IF(E30="Feriado",0,IF(E30="Folga(DSR)",0,IF(VLOOKUP(D30,'P Gerais'!$C$23:$M$29,11,0)-Lanc!K30>0,VLOOKUP(D30,'P Gerais'!$C$23:$M$29,11,0)-Lanc!K30,0)))) -> 0 | O30: =IF(E30="Feriado",IF(F30>I30,(I30+1-F30)-(H30-G30),(I30-F30)-(H30-G30)),IF(E30="Folga(DSR)",IF(F30>I30,(I30+1-F30)-(H30-G30),(I30-F30)-(H30-G30)),IF(E30="Falta Justificada",IF(F30>I30,(I30+1-F30)-(H30-G30),(I30-F30)-(H30-G30)),IF(VLOOKUP(D30,'P Gerais'!$C$23:$M$29,11,0)-Lanc!K30<0,ABS(VLOOKUP(D30,'P Gerais'!$C$23:$M$29,11,0)-Lanc!K30),0)))) -> 0 | P30: =IF(O30>$P$7,1,0) -> 0 | W30: =DATE('P Gerais'!$C$6,$W$7,Lanc!C30) -> 42027 | X30: =WEEKDAY(W30) -> 6 | AD30: =H30-G30 -> 0 | AE30: =VLOOKUP(D30,'P Gerais'!$C$23:$N$29,12,0) -> 0 | AF30: =IF(AE30-AD30<0,0,IF(OR(G30="",G30=0),0,AE30-AD30)) -> 0 | AG30: =($AG$7-I30)+F30 -> 1 | AH30: =IF(AG30<$AH$7,$AH$7-AG30,$AF$7) -> 0 | AI30: =IF(F30=I30,$AF$7,IF(F30<$AI$7,$AI$7-F30,$AF$7)) -> 0 | AJ30: =IF(F30=I30,$AF$7,IF(F30>=$AJ$7,O30,$AF$7)) -> 0 | AK30: =IF(AND(I30>$AK$7,I30>AL30),I30-AL30,$AF$7) -> 0 | AL30: =VLOOKUP(D30,'P Gerais'!$C$23:$I$29,7,FALSE) -> 0
C31: 24 | D31: =VLOOKUP(X31,$AB$8:$AC$14,2,0) -> SÁB | E31: Feriado | K31: =IF(ABS(((F31-1)-G31)+(H31-I31))>=1,ABS(((F31-1)-G31)+(H31-I31))-1,ABS(((F31-1)-G31)+(H31-I31))) -> 0 | M31: =IF(E31="Falta Justificada",0,IF(E31="Feriado",0,IF(E31="Folga(DSR)",0,IF(VLOOKUP(D31,'P Gerais'!$C$23:$M$29,11,0)-Lanc!K31>0,VLOOKUP(D31,'P Gerais'!$C$23:$M$29,11,0)-Lanc!K31,0)))) -> 0 | O31: =IF(E31="Feriado",IF(F31>I31,(I31+1-F31)-(H31-G31),(I31-F31)-(H31-G31)),IF(E31="Folga(DSR)",IF(F31>I31,(I31+1-F31)-(H31-G31),(I31-F31)-(H31-G31)),IF(E31="Falta Justificada",IF(F31>I31,(I31+1-F31)-(H31-G31),(I31-F31)-(H31-G31)),IF(VLOOKUP(D31,'P Gerais'!$C$23:$M$29,11,0)-Lanc!K31<0,ABS(VLOOKUP(D31,'P Gerais'!$C$23:$M$29,11,0)-Lanc!K31),0)))) -> 0 | P31: =IF(O31>$P$7,1,0) -> 0 | Q31: =IF(COUNTIF(E8:E38,"Folga(DSR)")<MAX(C8:C38)/7,"O mês não está contemplando um DSR(Descanso Semanal Remunerado) por semana. Isso pode se configurar uma irregularidade segundo as leis trabalhistas.","Parabéns!! Sua folha de pagamento contempla uma DSR por semana conforme a lei trabalhista.") -> O mês não está contemplando um DSR(Descanso Semanal Remunerado) por semana. Isso pode se configurar uma irregularidade segundo as leis trabalhistas. | W31: =DATE('P Gerais'!$C$6,$W$7,Lanc!C31) -> 42028 | X31: =WEEKDAY(W31) -> 7 | AD31: =H31-G31 -> 0 | AE31: =VLOOKUP(D31,'P Gerais'!$C$23:$N$29,12,0) -> 0 | AF31: =IF(AE31-AD31<0,0,IF(OR(G31="",G31=0),0,AE31-AD31)) -> 0 | AG31: =($AG$7-I31)+F31 -> 1 | AH31: =IF(AG31<$AH$7,$AH$7-AG31,$AF$7) -> 0 | AI31: =IF(F31=I31,$AF$7,IF(F31<$AI$7,$AI$7-F31,$AF$7)) -> 0 | AJ31: =IF(F31=I31,$AF$7,IF(F31>=$AJ$7,O31,$AF$7)) -> 0 | AK31: =IF(AND(I31>$AK$7,I31>AL31),I31-AL31,$AF$7) -> 0 | AL31: =VLOOKUP(D31,'P Gerais'!$C$23:$I$29,7,FALSE) -> 0
C32: 25 | D32: =VLOOKUP(X32,$AB$8:$AC$14,2,0) -> DOM | E32: Feriado | K32: =IF(ABS(((F32-1)-G32)+(H32-I32))>=1,ABS(((F32-1)-G32)+(H32-I32))-1,ABS(((F32-1)-G32)+(H32-I32))) -> 0 | M32: =IF(E32="Falta Justificada",0,IF(E32="Feriado",0,IF(E32="Folga(DSR)",0,IF(VLOOKUP(D32,'P Gerais'!$C$23:$M$29,11,0)-Lanc!K32>0,VLOOKUP(D32,'P Gerais'!$C$23:$M$29,11,0)-Lanc!K32,0)))) -> 0 | O32: =IF(E32="Feriado",IF(F32>I32,(I32+1-F32)-(H32-G32),(I32-F32)-(H32-G32)),IF(E32="Folga(DSR)",IF(F32>I32,(I32+1-F32)-(H32-G32),(I32-F32)-(H32-G32)),IF(E32="Falta Justificada",IF(F32>I32,(I32+1-F32)-(H32-G32),(I32-F32)-(H32-G32)),IF(VLOOKUP(D32,'P Gerais'!$C$23:$M$29,11,0)-Lanc!K32<0,ABS(VLOOKUP(D32,'P Gerais'!$C$23:$M$29,11,0)-Lanc!K32),0)))) -> 0 | P32: =IF(O32>$P$7,1,0) -> 0 | W32: =DATE('P Gerais'!$C$6,$W$7,Lanc!C32) -> 42029 | X32: =WEEKDAY(W32) -> 1 | AD32: =H32-G32 -> 0 | AE32: =VLOOKUP(D32,'P Gerais'!$C$23:$N$29,12,0) -> 0 | AF32: =IF(AE32-AD32<0,0,IF(OR(G32="",G32=0),0,AE32-AD32)) -> 0 | AG32: =($AG$7-I32)+F32 -> 1 | AH32: =IF(AG32<$AH$7,$AH$7-AG32,$AF$7) -> 0 | AI32: =IF(F32=I32,$AF$7,IF(F32<$AI$7,$AI$7-F32,$AF$7)) -> 0 | AJ32: =IF(F32=I32,$AF$7,IF(F32>=$AJ$7,O32,$AF$7)) -> 0 | AK32: =IF(AND(I32>$AK$7,I32>AL32),I32-AL32,$AF$7) -> 0 | AL32: =VLOOKUP(D32,'P Gerais'!$C$23:$I$29,7,FALSE) -> 0
C33: 26 | D33: =VLOOKUP(X33,$AB$8:$AC$14,2,0) -> SEG | E33: Feriado | K33: =IF(ABS(((F33-1)-G33)+(H33-I33))>=1,ABS(((F33-1)-G33)+(H33-I33))-1,ABS(((F33-1)-G33)+(H33-I33))) -> 0 | M33: =IF(E33="Falta Justificada",0,IF(E33="Feriado",0,IF(E33="Folga(DSR)",0,IF(VLOOKUP(D33,'P Gerais'!$C$23:$M$29,11,0)-Lanc!K33>0,VLOOKUP(D33,'P Gerais'!$C$23:$M$29,11,0)-Lanc!K33,0)))) -> 0 | O33: =IF(E33="Feriado",IF(F33>I33,(I33+1-F33)-(H33-G33),(I33-F33)-(H33-G33)),IF(E33="Folga(DSR)",IF(F33>I33,(I33+1-F33)-(H33-G33),(I33-F33)-(H33-G33)),IF(E33="Falta Justificada",IF(F33>I33,(I33+1-F33)-(H33-G33),(I33-F33)-(H33-G33)),IF(VLOOKUP(D33,'P Gerais'!$C$23:$M$29,11,0)-Lanc!K33<0,ABS(VLOOKUP(D33,'P Gerais'!$C$23:$M$29,11,0)-Lanc!K33),0)))) -> 0 | P33: =IF(O33>$P$7,1,0) -> 0 | W33: =DATE('P Gerais'!$C$6,$W$7,Lanc!C33) -> 42030 | X33: =WEEKDAY(W33) -> 2 | AD33: =H33-G33 -> 0 | AE33: =VLOOKUP(D33,'P Gerais'!$C$23:$N$29,12,0) -> 0 | AF33: =IF(AE33-AD33<0,0,IF(OR(G33="",G33=0),0,AE33-AD33)) -> 0 | AG33: =($AG$7-I33)+F33 -> 1 | AH33: =IF(AG33<$AH$7,$AH$7-AG33,$AF$7) -> 0 | AI33: =IF(F33=I33,$AF$7,IF(F33<$AI$7,$AI$7-F33,$AF$7)) -> 0 | AJ33: =IF(F33=I33,$AF$7,IF(F33>=$AJ$7,O33,$AF$7)) -> 0 | AK33: =IF(AND(I33>$AK$7,I33>AL33),I33-AL33,$AF$7) -> 0 | AL33: =VLOOKUP(D33,'P Gerais'!$C$23:$I$29,7,FALSE) -> 0
C34: 27 | D34: =VLOOKUP(X34,$AB$8:$AC$14,2,0) -> TER | E34: Feriado | K34: =IF(ABS(((F34-1)-G34)+(H34-I34))>=1,ABS(((F34-1)-G34)+(H34-I34))-1,ABS(((F34-1)-G34)+(H34-I34))) -> 0 | M34: =IF(E34="Falta Justificada",0,IF(E34="Feriado",0,IF(E34="Folga(DSR)",0,IF(VLOOKUP(D34,'P Gerais'!$C$23:$M$29,11,0)-Lanc!K34>0,VLOOKUP(D34,'P Gerais'!$C$23:$M$29,11,0)-Lanc!K34,0)))) -> 0 | O34: =IF(E34="Feriado",IF(F34>I34,(I34+1-F34)-(H34-G34),(I34-F34)-(H34-G34)),IF(E34="Folga(DSR)",IF(F34>I34,(I34+1-F34)-(H34-G34),(I34-F34)-(H34-G34)),IF(E34="Falta Justificada",IF(F34>I34,(I34+1-F34)-(H34-G34),(I34-F34)-(H34-G34)),IF(VLOOKUP(D34,'P Gerais'!$C$23:$M$29,11,0)-Lanc!K34<0,ABS(VLOOKUP(D34,'P Gerais'!$C$23:$M$29,11,0)-Lanc!K34),0)))) -> 0 | P34: =IF(O34>$P$7,1,0) -> 0 | W34: =DATE('P Gerais'!$C$6,$W$7,Lanc!C34) -> 42031 | X34: =WEEKDAY(W34) -> 3 | AD34: =H34-G34 -> 0 | AE34: =VLOOKUP(D34,'P Gerais'!$C$23:$N$29,12,0) -> 0 | AF34: =IF(AE34-AD34<0,0,IF(OR(G34="",G34=0),0,AE34-AD34)) -> 0 | AG34: =($AG$7-I34)+F34 -> 1 | AH34: =IF(AG34<$AH$7,$AH$7-AG34,$AF$7) -> 0 | AI34: =IF(F34=I34,$AF$7,IF(F34<$AI$7,$AI$7-F34,$AF$7)) -> 0 | AJ34: =IF(F34=I34,$AF$7,IF(F34>=$AJ$7,O34,$AF$7)) -> 0 | AK34: =IF(AND(I34>$AK$7,I34>AL34),I34-AL34,$AF$7) -> 0 | AL34: =VLOOKUP(D34,'P Gerais'!$C$23:$I$29,7,FALSE) -> 0
C35: 28 | D35: =VLOOKUP(X35,$AB$8:$AC$14,2,0) -> QUA | E35: Feriado | K35: =IF(ABS(((F35-1)-G35)+(H35-I35))>=1,ABS(((F35-1)-G35)+(H35-I35))-1,ABS(((F35-1)-G35)+(H35-I35))) -> 0 | M35: =IF(E35="Falta Justificada",0,IF(E35="Feriado",0,IF(E35="Folga(DSR)",0,IF(VLOOKUP(D35,'P Gerais'!$C$23:$M$29,11,0)-Lanc!K35>0,VLOOKUP(D35,'P Gerais'!$C$23:$M$29,11,0)-Lanc!K35,0)))) -> 0 | O35: =IF(E35="Feriado",IF(F35>I35,(I35+1-F35)-(H35-G35),(I35-F35)-(H35-G35)),IF(E35="Folga(DSR)",IF(F35>I35,(I35+1-F35)-(H35-G35),(I35-F35)-(H35-G35)),IF(E35="Falta Justificada",IF(F35>I35,(I35+1-F35)-(H35-G35),(I35-F35)-(H35-G35)),IF(VLOOKUP(D35,'P Gerais'!$C$23:$M$29,11,0)-Lanc!K35<0,ABS(VLOOKUP(D35,'P Gerais'!$C$23:$M$29,11,0)-Lanc!K35),0)))) -> 0 | P35: =IF(O35>$P$7,1,0) -> 0 | W35: =DATE('P Gerais'!$C$6,$W$7,Lanc!C35) -> 42032 | X35: =WEEKDAY(W35) -> 4 | AD35: =H35-G35 -> 0 | AE35: =VLOOKUP(D35,'P Gerais'!$C$23:$N$29,12,0) -> 0 | AF35: =IF(AE35-AD35<0,0,IF(OR(G35="",G35=0),0,AE35-AD35)) -> 0 | AG35: =($AG$7-I35)+F35 -> 1 | AH35: =IF(AG35<$AH$7,$AH$7-AG35,$AF$7) -> 0 | AI35: =IF(F35=I35,$AF$7,IF(F35<$AI$7,$AI$7-F35,$AF$7)) -> 0 | AJ35: =IF(F35=I35,$AF$7,IF(F35>=$AJ$7,O35,$AF$7)) -> 0 | AK35: =IF(AND(I35>$AK$7,I35>AL35),I35-AL35,$AF$7) -> 0 | AL35: =VLOOKUP(D35,'P Gerais'!$C$23:$I$29,7,FALSE) -> 0
C36: 29 | D36: =VLOOKUP(X36,$AB$8:$AC$14,2,0) -> QUI | E36: Feriado | K36: =IF(ABS(((F36-1)-G36)+(H36-I36))>=1,ABS(((F36-1)-G36)+(H36-I36))-1,ABS(((F36-1)-G36)+(H36-I36))) -> 0 | M36: =IF(E36="Falta Justificada",0,IF(E36="Feriado",0,IF(E36="Folga(DSR)",0,IF(VLOOKUP(D36,'P Gerais'!$C$23:$M$29,11,0)-Lanc!K36>0,VLOOKUP(D36,'P Gerais'!$C$23:$M$29,11,0)-Lanc!K36,0)))) -> 0 | O36: =IF(E36="Feriado",IF(F36>I36,(I36+1-F36)-(H36-G36),(I36-F36)-(H36-G36)),IF(E36="Folga(DSR)",IF(F36>I36,(I36+1-F36)-(H36-G36),(I36-F36)-(H36-G36)),IF(E36="Falta Justificada",IF(F36>I36,(I36+1-F36)-(H36-G36),(I36-F36)-(H36-G36)),IF(VLOOKUP(D36,'P Gerais'!$C$23:$M$29,11,0)-Lanc!K36<0,ABS(VLOOKUP(D36,'P Gerais'!$C$23:$M$29,11,0)-Lanc!K36),0)))) -> 0 | P36: =IF(O36>$P$7,1,0) -> 0 | W36: =DATE('P Gerais'!$C$6,$W$7,Lanc!C36) -> 42033 | X36: =WEEKDAY(W36) -> 5 | AD36: =H36-G36 -> 0 | AE36: =VLOOKUP(D36,'P Gerais'!$C$23:$N$29,12,0) -> 0 | AF36: =IF(AE36-AD36<0,0,IF(OR(G36="",G36=0),0,AE36-AD36)) -> 0 | AG36: =($AG$7-I36)+F36 -> 1 | AH36: =IF(AG36<$AH$7,$AH$7-AG36,$AF$7) -> 0 | AI36: =IF(F36=I36,$AF$7,IF(F36<$AI$7,$AI$7-F36,$AF$7)) -> 0 | AJ36: =IF(F36=I36,$AF$7,IF(F36>=$AJ$7,O36,$AF$7)) -> 0 | AK36: =IF(AND(I36>$AK$7,I36>AL36),I36-AL36,$AF$7) -> 0 | AL36: =VLOOKUP(D36,'P Gerais'!$C$23:$I$29,7,FALSE) -> 0
C37: 30 | D37: =VLOOKUP(X37,$AB$8:$AC$14,2,0) -> SEX | E37: Feriado | K37: =IF(ABS(((F37-1)-G37)+(H37-I37))>=1,ABS(((F37-1)-G37)+(H37-I37))-1,ABS(((F37-1)-G37)+(H37-I37))) -> 0 | M37: =IF(E37="Falta Justificada",0,IF(E37="Feriado",0,IF(E37="Folga(DSR)",0,IF(VLOOKUP(D37,'P Gerais'!$C$23:$M$29,11,0)-Lanc!K37>0,VLOOKUP(D37,'P Gerais'!$C$23:$M$29,11,0)-Lanc!K37,0)))) -> 0 | O37: =IF(E37="Feriado",IF(F37>I37,(I37+1-F37)-(H37-G37),(I37-F37)-(H37-G37)),IF(E37="Folga(DSR)",IF(F37>I37,(I37+1-F37)-(H37-G37),(I37-F37)-(H37-G37)),IF(E37="Falta Justificada",IF(F37>I37,(I37+1-F37)-(H37-G37),(I37-F37)-(H37-G37)),IF(VLOOKUP(D37,'P Gerais'!$C$23:$M$29,11,0)-Lanc!K37<0,ABS(VLOOKUP(D37,'P Gerais'!$C$23:$M$29,11,0)-Lanc!K37),0)))) -> 0 | P37: =IF(O37>$P$7,1,0) -> 0 | W37: =DATE('P Gerais'!$C$6,$W$7,Lanc!C37) -> 42034 | X37: =WEEKDAY(W37) -> 6 | AD37: =H37-G37 -> 0 | AE37: =VLOOKUP(D37,'P Gerais'!$C$23:$N$29,12,0) -> 0 | AF37: =IF(AE37-AD37<0,0,IF(OR(G37="",G37=0),0,AE37-AD37)) -> 0 | AG37: =($AG$7-I37)+F37 -> 1 | AH37: =IF(AG37<$AH$7,$AH$7-AG37,$AF$7) -> 0 | AI37: =IF(F37=I37,$AF$7,IF(F37<$AI$7,$AI$7-F37,$AF$7)) -> 0 | AJ37: =IF(F37=I37,$AF$7,IF(F37>=$AJ$7,O37,$AF$7)) -> 0 | AK37: =IF(AND(I37>$AK$7,I37>AL37),I37-AL37,$AF$7) -> 0 | AL37: =VLOOKUP(D37,'P Gerais'!$C$23:$I$29,7,FALSE) -> 0
C38: 31 | D38: =VLOOKUP(X38,$AB$8:$AC$14,2,0) -> SÁB | E38: Feriado | K38: =IF(ABS(((F38-1)-G38)+(H38-I38))>=1,ABS(((F38-1)-G38)+(H38-I38))-1,ABS(((F38-1)-G38)+(H38-I38))) -> 0 | M38: =IF(E38="Falta Justificada",0,IF(E38="Feriado",0,IF(E38="Folga(DSR)",0,IF(VLOOKUP(D38,'P Gerais'!$C$23:$M$29,11,0)-Lanc!K38>0,VLOOKUP(D38,'P Gerais'!$C$23:$M$29,11,0)-Lanc!K38,0)))) -> 0 | O38: =IF(E38="Feriado",IF(F38>I38,(I38+1-F38)-(H38-G38),(I38-F38)-(H38-G38)),IF(E38="Folga(DSR)",IF(F38>I38,(I38+1-F38)-(H38-G38),(I38-F38)-(H38-G38)),IF(E38="Falta Justificada",IF(F38>I38,(I38+1-F38)-(H38-G38),(I38-F38)-(H38-G38)),IF(VLOOKUP(D38,'P Gerais'!$C$23:$M$29,11,0)-Lanc!K38<0,ABS(VLOOKUP(D38,'P Gerais'!$C$23:$M$29,11,0)-Lanc!K38),0)))) -> 0 | P38: =IF(O38>$P$7,1,0) -> 0 | W38: =DATE('P Gerais'!$C$6,$W$7,Lanc!C38) -> 42035 | X38: =WEEKDAY(W38) -> 7 | AF38: =IF(AE38-AD38<0,0,IF(OR(G38="",G38=0),0,AE38-AD38)) -> 0 | AI38: =IF(F38=I38,$AF$7,IF(F38<$AI$7,$AI$7-F38,$AF$7)) -> 0 | AK38: =IF(AND(I38>$AK$7,I38>AL38),I38-AL38,$AF$7) -> 0 | AL38: =VLOOKUP(D38,'P Gerais'!$C$23:$I$29,7,FALSE) -> 0
G40: 0.041666667 | H40: ='P Gerais'!F16+'P Gerais'!F16*'P Gerais'!L36 -> 0 | I40: ='P Gerais'!G6 -> 220 | K40: =H40/I40 -> 0
B41: Seg | C41: Horas Extras às Segundas | F41: =SUMIF($D$8:$D$38,B41,$O$8:$O$38)-SUMIFS($K$8:$K$38,$D$8:$D$38,B41,$E$8:$E$38,"Feriado")-SUMIFS($K$8:$K$38,$D$8:$D$38,B41,$E$8:$E$38,"Folga(DSR)")-SUMIFS($K$8:$K$38,$D$8:$D$38,B41,$E$8:$E$38,"Falta Justificada")-SUMIFS($AJ$8:$AJ$38,$D$8:$D$38,B41,$E$8:$E$38,"Normal") -> 0 | G41: ='P Gerais'!$C$36 -> 0 | H41: =$K$40*(1+G41)*(F41*24) -> 0
B42: Ter | C42: Horas Extras às Terças | F42: =SUMIF($D$8:$D$38,B42,$O$8:$O$38)-SUMIFS($K$8:$K$38,$D$8:$D$38,B42,$E$8:$E$38,"Feriado")-SUMIFS($K$8:$K$38,$D$8:$D$38,B42,$E$8:$E$38,"Folga(DSR)")-SUMIFS($K$8:$K$38,$D$8:$D$38,B42,$E$8:$E$38,"Falta Justificada")-SUMIFS($AJ$8:$AJ$38,$D$8:$D$38,B42,$E$8:$E$38,"Normal") -> 0 | G42: ='P Gerais'!$C$36 -> 0 | H42: =$K$40*(1+G42)*(F42*24) -> 0
B43: Qua | C43: Horas Extras às Quartas | F43: =SUMIF($D$8:$D$38,B43,$O$8:$O$38)-SUMIFS($K$8:$K$38,$D$8:$D$38,B43,$E$8:$E$38,"Feriado")-SUMIFS($K$8:$K$38,$D$8:$D$38,B43,$E$8:$E$38,"Folga(DSR)")-SUMIFS($K$8:$K$38,$D$8:$D$38,B43,$E$8:$E$38,"Falta Justificada")-SUMIFS($AJ$8:$AJ$38,$D$8:$D$38,B43,$E$8:$E$38,"Normal") -> 0 | G43: ='P Gerais'!$C$36 -> 0 | H43: =$K$40*(1+G43)*(F43*24) -> 0
B44: Qui | C44: Horas Extras às Quintas | F44: =SUMIF($D$8:$D$38,B44,$O$8:$O$38)-SUMIFS($K$8:$K$38,$D$8:$D$38,B44,$E$8:$E$38,"Feriado")-SUMIFS($K$8:$K$38,$D$8:$D$38,B44,$E$8:$E$38,"Folga(DSR)")-SUMIFS($K$8:$K$38,$D$8:$D$38,B44,$E$8:$E$38,"Falta Justificada")-SUMIFS($AJ$8:$AJ$38,$D$8:$D$38,B44,$E$8:$E$38,"Normal") -> 0 | G44: ='P Gerais'!$C$36 -> 0 | H44: =$K$40*(1+G44)*(F44*24) -> 0
B45: Sex | C45: Horas Extras às Sextas | F45: =SUMIF($D$8:$D$38,B45,$O$8:$O$38)-SUMIFS($K$8:$K$38,$D$8:$D$38,B45,$E$8:$E$38,"Feriado")-SUMIFS($K$8:$K$38,$D$8:$D$38,B45,$E$8:$E$38,"Folga(DSR)")-SUMIFS($K$8:$K$38,$D$8:$D$38,B45,$E$8:$E$38,"Falta Justificada")-SUMIFS($AJ$8:$AJ$38,$D$8:$D$38,B45,$E$8:$E$38,"Normal") -> 0 | G45: ='P Gerais'!$C$36 -> 0 | H45: =$K$40*(1+G45)*(F45*24) -> 0
...

Sheet Fev
A1: 3.0.1 | C1: 2. LANÇAMENTOS MENSAIS
C5: Acumulado mês anterior | I5: =Lanc!S11 -> 0 | K5: =IF(Lanc!T11="Negativo","Negativo","Positivo") -> Positivo | S5: =IF(S17>'P Gerais'!G6/10,1,0) -> 0
M6: =VLOOKUP(D11,'P Gerais'!$C$23:$M$29,11,0) -> 0 | O6: =M6-K11 -> 0
C7: Dia | E7: Classificação | F7: Início | G7: Intervalo | I7: Término | K7: Horas Dia | M7: Horas Devidas | O7: Horas Extras | P7: 0.083333333 | Q7: Resumo do Mês | W7: 2 | AD7: intervalo | AF7: 0 | AG7: 1 | AH7: 0.45833333 | AI7: 0.20833333 | AJ7: 0.75 | AK7: 0.91666667
C8: 1 | D8: =VLOOKUP(X8,$AB$8:$AC$14,2,0) -> DOM | E8: Feriado | K8: =IF(ABS(((F8-1)-G8)+(H8-I8))>=1,ABS(((F8-1)-G8)+(H8-I8))-1,ABS(((F8-1)-G8)+(H8-I8))) -> 0 | M8: =IF(E8="Falta Justificada",0,IF(E8="Feriado",0,IF(E8="Folga(DSR)",0,IF(VLOOKUP(D8,'P Gerais'!$C$23:$M$29,11,0)-K8>0,VLOOKUP(D8,'P Gerais'!$C$23:$M$29,11,0)-K8,0)))) -> 0 | O8: =IF(E8="Feriado",IF(F8>I8,(I8+1-F8)-(H8-G8),(I8-F8)-(H8-G8)),IF(E8="Folga(DSR)",IF(F8>I8,(I8+1-F8)-(H8-G8),(I8-F8)-(H8-G8)),IF(E8="Falta Justificada",IF(F8>I8,(I8+1-F8)-(H8-G8),(I8-F8)-(H8-G8)),IF(VLOOKUP(D8,'P Gerais'!$C$23:$M$29,11,0)-K8<0,ABS(VLOOKUP(D8,'P Gerais'!$C$23:$M$29,11,0)-K8),0)))) -> 0 | P8: =IF(O8>$P$7,1,0) -> 0 | W8: =DATE('P Gerais'!$C$6,$W$7,Fev!C8) -> 42036 | X8: =WEEKDAY(W8) -> 1 | AB8: 1 | AC8: DOM | AD8: =H8-G8 -> 0 | AE8: =VLOOKUP(D8,'P Gerais'!$C$23:$N$29,12,0) -> 0 | AF8: =IF(AE8-AD8<0,0,IF(OR(G8="",G8=0),0,AE8-AD8)) -> 0 | AG8: =($AG$7-I8)+F8 -> 1 | AH8: =IF(AG8<$AH$7,$AH$7-AG8,$AF$7) -> 0 | AI8: =IF(F8=I8,$AF$7,IF(F8<$AI$7,$AI$7-F8,$AF$7)) -> 0 | AJ8: =IF(F8=I8,$AF$7,IF(F8>=$AJ$7,O8,$AF$7)) -> 0 | AK8: =IF(AND(I8>$AK$7,I8>AL8),I8-AL8,$AF$7) -> 0 | AL8: =VLOOKUP(D8,'P Gerais'!$C$23:$I$29,7,FALSE) -> 0
C9: 2 | D9: =VLOOKUP(X9,$AB$8:$AC$14,2,0) -> SEG | E9: Feriado | K9: =IF(ABS(((F9-1)-G9)+(H9-I9))>=1,ABS(((F9-1)-G9)+(H9-I9))-1,ABS(((F9-1)-G9)+(H9-I9))) -> 0 | M9: =IF(E9="Falta Justificada",0,IF(E9="Feriado",0,IF(E9="Folga(DSR)",0,IF(VLOOKUP(D9,'P Gerais'!$C$23:$M$29,11,0)-K9>0,VLOOKUP(D9,'P Gerais'!$C$23:$M$29,11,0)-K9,0)))) -> 0 | O9: =IF(E9="Feriado",IF(F9>I9,(I9+1-F9)-(H9-G9),(I9-F9)-(H9-G9)),IF(E9="Folga(DSR)",IF(F9>I9,(I9+1-F9)-(H9-G9),(I9-F9)-(H9-G9)),IF(E9="Falta Justificada",IF(F9>I9,(I9+1-F9)-(H9-G9),(I9-F9)-(H9-G9)),IF(VLOOKUP(D9,'P Gerais'!$C$23:$M$29,11,0)-K9<0,ABS(VLOOKUP(D9,'P Gerais'!$C$23:$M$29,11,0)-K9),0)))) -> 0 | P9: =IF(O9>$P$7,1,0) -> 0 | Q9: Horas trabalhadas no mês | S9: =SUM(K8:K38) -> 0 | W9: =DATE('P Gerais'!$C$6,$W$7,Fev!C9) -> 42037 | X9: =WEEKDAY(W9) -> 2 | AB9: 2 | AC9: SEG | AD9: =H9-G9 -> 0 | AE9: =VLOOKUP(D9,'P Gerais'!$C$23:$N$29,12,0) -> 0 | AF9: =IF(AE9-AD9<0,0,IF(OR(G9="",G9=0),0,AE9-AD9)) -> 0 | AG9: =($AG$7-I9)+F9 -> 1 | AH9: =IF(AG9<$AH$7,$AH$7-AG9,$AF$7) -> 0 | AI9: =IF(F9=I9,$AF$7,IF(F9<$AI$7,$AI$7-F9,$AF$7)) -> 0 | AJ9: =IF(F9=I9,$AF$7,IF(F9>=$AJ$7,O9,$AF$7)) -> 0 | AK9: =IF(AND(I9>$AK$7,I9>AL9),I9-AL9,$AF$7) -> 0 | AL9: =VLOOKUP(D9,'P Gerais'!$C$23:$I$29,7,FALSE) -> 0
C10: 3 | D10: =VLOOKUP(X10,$AB$8:$AC$14,2,0) -> TER | E10: Feriado | K10: =IF(ABS(((F10-1)-G10)+(H10-I10))>=1,ABS(((F10-1)-G10)+(H10-I10))-1,ABS(((F10-1)-G10)+(H10-I10))) -> 0 | M10: =IF(E10="Falta Justificada",0,IF(E10="Feriado",0,IF(E10="Folga(DSR)",0,IF(VLOOKUP(D10,'P Gerais'!$C$23:$M$29,11,0)-K10>0,VLOOKUP(D10,'P Gerais'!$C$23:$M$29,11,0)-K10,0)))) -> 0 | O10: =IF(E10="Feriado",IF(F10>I10,(I10+1-F10)-(H10-G10),(I10-F10)-(H10-G10)),IF(E10="Folga(DSR)",IF(F10>I10,(I10+1-F10)-(H10-G10),(I10-F10)-(H10-G10)),IF(E10="Falta Justificada",IF(F10>I10,(I10+1-F10)-(H10-G10),(I10-F10)-(H10-G10)),IF(VLOOKUP(D10,'P Gerais'!$C$23:$M$29,11,0)-K10<0,ABS(VLOOKUP(D10,'P Gerais'!$C$23:$M$29,11,0)-K10),0)))) -> 0 | P10: =IF(O10>$P$7,1,0) -> 0 | W10: =DATE('P Gerais'!$C$6,$W$7,Fev!C10) -> 42038 | X10: =WEEKDAY(W10) -> 3 | AB10: 3 | AC10: TER | AD10: =H10-G10 -> 0 | AE10: =VLOOKUP(D10,'P Gerais'!$C$23:$N$29,12,0) -> 0 | AF10: =IF(AE10-AD10<0,0,IF(OR(G10="",G10=0),0,AE10-AD10)) -> 0 | AG10: =($AG$7-I10)+F10 -> 1 | AH10: =IF(AG10<$AH$7,$AH$7-AG10,$AF$7) -> 0 | AI10: =IF(F10=I10,$AF$7,IF(F10<$AI$7,$AI$7-F10,$AF$7)) -> 0 | AJ10: =IF(F10=I10,$AF$7,IF(F10>=$AJ$7,O10,$AF$7)) -> 0 | AK10: =IF(AND(I10>$AK$7,I10>AL10),I10-AL10,$AF$7) -> 0 | AL10: =VLOOKUP(D10,'P Gerais'!$C$23:$I$29,7,FALSE) -> 0
C11: 4 | D11: =VLOOKUP(X11,$AB$8:$AC$14,2,0) -> QUA | E11: Feriado | K11: =IF(ABS(((F11-1)-G11)+(H11-I11))>=1,ABS(((F11-1)-G11)+(H11-I11))-1,ABS(((F11-1)-G11)+(H11-I11))) -> 0 | M11: =IF(E11="Falta Justificada",0,IF(E11="Feriado",0,IF(E11="Folga(DSR)",0,IF(VLOOKUP(D11,'P Gerais'!$C$23:$M$29,11,0)-K11>0,VLOOKUP(D11,'P Gerais'!$C$23:$M$29,11,0)-K11,0)))) -> 0 | O11: =IF(E11="Feriado",IF(F11>I11,(I11+1-F11)-(H11-G11),(I11-F11)-(H11-G11)),IF(E11="Folga(DSR)",IF(F11>I11,(I11+1-F11)-(H11-G11),(I11-F11)-(H11-G11)),IF(E11="Falta Justificada",IF(F11>I11,(I11+1-F11)-(H11-G11),(I11-F11)-(H11-G11)),IF(VLOOKUP(D11,'P Gerais'!$C$23:$M$29,11,0)-K11<0,ABS(VLOOKUP(D11,'P Gerais'!$C$23:$M$29,11,0)-K11),0)))) -> 0 | P11: =IF(O11>$P$7,1,0) -> 0 | Q11: Acumulado no banco de horas | S11: =IF(K5="Negativo",ABS(-I5+S17-S15),ABS(I5+S17-S15)) -> 0 | T11: =IF(S15>S17+IF(K5="Negativo",-I5,I5),"Negativo","Positivo") -> Positivo | W11: =DATE('P Gerais'!$C$6,$W$7,Fev!C11) -> 42039 | X11: =WEEKDAY(W11) -> 4 | AB11: 4 | AC11: QUA | AD11: =H11-G11 -> 0 | AE11: =VLOOKUP(D11,'P Gerais'!$C$23:$N$29,12,0) -> 0 | AF11: =IF(AE11-AD11<0,0,IF(OR(G11="",G11=0),0,AE11-AD11)) -> 0 | AG11: =($AG$7-I11)+F11 -> 1 | AH11: =IF(AG11<$AH$7,$AH$7-AG11,$AF$7) -> 0 | AI11: =IF(F11=I11,$AF$7,IF(F11<$AI$7,$AI$7-F11,$AF$7)) -> 0 | AJ11: =IF(F11=I11,$AF$7,IF(F11>=$AJ$7,O11,$AF$7)) -> 0 | AK11: =IF(AND(I11>$AK$7,I11>AL11),I11-AL11,$AF$7) -> 0 | AL11: =VLOOKUP(D11,'P Gerais'!$C$23:$I$29,7,FALSE) -> 0
C12: 5 | D12: =VLOOKUP(X12,$AB$8:$AC$14,2,0) -> QUI | E12: Feriado | K12: =IF(ABS(((F12-1)-G12)+(H12-I12))>=1,ABS(((F12-1)-G12)+(H12-I12))-1,ABS(((F12-1)-G12)+(H12-I12))) -> 0 | M12: =IF(E12="Falta Justificada",0,IF(E12="Feriado",0,IF(E12="Folga(DSR)",0,IF(VLOOKUP(D12,'P Gerais'!$C$23:$M$29,11,0)-K12>0,VLOOKUP(D12,'P Gerais'!$C$23:$M$29,11,0)-K12,0)))) -> 0 | O12: =IF(E12="Feriado",IF(F12>I12,(I12+1-F12)-(H12-G12),(I12-F12)-(H12-G12)),IF(E12="Folga(DSR)",IF(F12>I12,(I12+1-F12)-(H12-G12),(I12-F12)-(H12-G12)),IF(E12="Falta Justificada",IF(F12>I12,(I12+1-F12)-(H12-G12),(I12-F12)-(H12-G12)),IF(VLOOKUP(D12,'P Gerais'!$C$23:$M$29,11,0)-K12<0,ABS(VLOOKUP(D12,'P Gerais'!$C$23:$M$29,11,0)-K12),0)))) -> 0 | P12: =IF(O12>$P$7,1,0) -> 0 | W12: =DATE('P Gerais'!$C$6,$W$7,Fev!C12) -> 42040 | X12: =WEEKDAY(W12) -> 5 | AB12: 5 | AC12: QUI | AD12: =H12-G12 -> 0 | AE12: =VLOOKUP(D12,'P Gerais'!$C$23:$N$29,12,0) -> 0 | AF12: =IF(AE12-AD12<0,0,IF(OR(G12="",G12=0),0,AE12-AD12)) -> 0 | AG12: =($AG$7-I12)+F12 -> 1 | AH12: =IF(AG12<$AH$7,$AH$7-AG12,$AF$7) -> 0 | AI12: =IF(F12=I12,$AF$7,IF(F12<$AI$7,$AI$7-F12,$AF$7)) -> 0 | AJ12: =IF(F12=I12,$AF$7,IF(F12>=$AJ$7,O12,$AF$7)) -> 0 | AK12: =IF(AND(I12>$AK$7,I12>AL12),I12-AL12,$AF$7) -> 0 | AL12: =VLOOKUP(D12,'P Gerais'!$C$23:$I$29,7,FALSE) -> 0
C13: 6 | D13: =VLOOKUP(X13,$AB$8:$AC$14,2,0) -> SEX | E13: Feriado | K13: =IF(ABS(((F13-1)-G13)+(H13-I13))>=1,ABS(((F13-1)-G13)+(H13-I13))-1,ABS(((F13-1)-G13)+(H13-I13))) -> 0 | M13: =IF(E13="Falta Justificada",0,IF(E13="Feriado",0,IF(E13="Folga(DSR)",0,IF(VLOOKUP(D13,'P Gerais'!$C$23:$M$29,11,0)-K13>0,VLOOKUP(D13,'P Gerais'!$C$23:$M$29,11,0)-K13,0)))) -> 0 | O13: =IF(E13="Feriado",IF(F13>I13,(I13+1-F13)-(H13-G13),(I13-F13)-(H13-G13)),IF(E13="Folga(DSR)",IF(F13>I13,(I13+1-F13)-(H13-G13),(I13-F13)-(H13-G13)),IF(E13="Falta Justificada",IF(F13>I13,(I13+1-F13)-(H13-G13),(I13-F13)-(H13-G13)),IF(VLOOKUP(D13,'P Gerais'!$C$23:$M$29,11,0)-K13<0,ABS(VLOOKUP(D13,'P Gerais'!$C$23:$M$29,11,0)-K13),0)))) -> 0 | P13: =IF(O13>$P$7,1,0) -> 0 | Q13: Horas somados/subtraídas ao banco | S13: =IF(S15>=S17,(S15)-S17,(S17-S15)) -> 0 | T13: =IF(S15>S17,"Negativo","Positivo") -> Positivo | W13: =DATE('P Gerais'!$C$6,$W$7,Fev!C13) -> 42041 | X13: =WEEKDAY(W13) -> 6 | AB13: 6 | AC13: SEX | AD13: =H13-G13 -> 0 | AE13: =VLOOKUP(D13,'P Gerais'!$C$23:$N$29,12,0) -> 0 | AF13: =IF(AE13-AD13<0,0,IF(OR(G13="",G13=0),0,AE13-AD13)) -> 0 | AG13: =($AG$7-I13)+F13 -> 1 | AH13: =IF(AG13<$AH$7,$AH$7-AG13,$AF$7) -> 0 | AI13: =IF(F13=I13,$AF$7,IF(F13<$AI$7,$AI$7-F13,$AF$7)) -> 0 | AJ13: =IF(F13=I13,$AF$7,IF(F13>=$AJ$7,O13,$AF$7)) -> 0 | AK13: =IF(AND(I13>$AK$7,I13>AL13),I13-AL13,$AF$7) -> 0 | AL13: =VLOOKUP(D13,'P Gerais'!$C$23:$I$29,7,FALSE) -> 0
C14: 7 | D14: =VLOOKUP(X14,$AB$8:$AC$14,2,0) -> SÁB | E14: Feriado | K14: =IF(ABS(((F14-1)-G14)+(H14-I14))>=1,ABS(((F14-1)-G14)+(H14-I14))-1,ABS(((F14-1)-G14)+(H14-I14))) -> 0 | M14: =IF(E14="Falta Justificada",0,IF(E14="Feriado",0,IF(E14="Folga(DSR)",0,IF(VLOOKUP(D14,'P Gerais'!$C$23:$M$29,11,0)-K14>0,VLOOKUP(D14,'P Gerais'!$C$23:$M$29,11,0)-K14,0)))) -> 0 | O14: =IF(E14="Feriado",IF(F14>I14,(I14+1-F14)-(H14-G14),(I14-F14)-(H14-G14)),IF(E14="Folga(DSR)",IF(F14>I14,(I14+1-F14)-(H14-G14),(I14-F14)-(H14-G14)),IF(E14="Falta Justificada",IF(F14>I14,(I14+1-F14)-(H14-G14),(I14-F14)-(H14-G14)),IF(VLOOKUP(D14,'P Gerais'!$C$23:$M$29,11,0)-K14<0,ABS(VLOOKUP(D14,'P Gerais'!$C$23:$M$29,11,0)-K14),0)))) -> 0 | P14: =IF(O14>$P$7,1,0) -> 0 | W14: =DATE('P Gerais'!$C$6,$W$7,Fev!C14) -> 42042 | X14: =WEEKDAY(W14) -> 7 | AB14: 7 | AC14: SÁB | AD14: =H14-G14 -> 0 | AE14: =VLOOKUP(D14,'P Gerais'!$C$23:$N$29,12,0) -> 0 | AF14: =IF(AE14-AD14<0,0,IF(OR(G14="",G14=0),0,AE14-AD14)) -> 0 | AG14: =($AG$7-I14)+F14 -> 1 | AH14: =IF(AG14<$AH$7,$AH$7-AG14,$AF$7) -> 0 | AI14: =IF(F14=I14,$AF$7,IF(F14<$AI$7,$AI$7-F14,$AF$7)) -> 0 | AJ14: =IF(F14=I14,$AF$7,IF(F14>=$AJ$7,O14,$AF$7)) -> 0 | AK14: =IF(AND(I14>$AK$7,I14>AL14),I14-AL14,$AF$7) -> 0 | AL14: =VLOOKUP(D14,'P Gerais'!$C$23:$I$29,7,FALSE) -> 0
C15: 8 | D15: =VLOOKUP(X15,$AB$8:$AC$14,2,0) -> DOM | E15: Feriado | K15: =IF(ABS(((F15-1)-G15)+(H15-I15))>=1,ABS(((F15-1)-G15)+(H15-I15))-1,ABS(((F15-1)-G15)+(H15-I15))) -> 0 | M15: =IF(E15="Falta Justificada",0,IF(E15="Feriado",0,IF(E15="Folga(DSR)",0,IF(VLOOKUP(D15,'P Gerais'!$C$23:$M$29,11,0)-K15>0,VLOOKUP(D15,'P Gerais'!$C$23:$M$29,11,0)-K15,0)))) -> 0 | O15: =IF(E15="Feriado",IF(F15>I15,(I15+1-F15)-(H15-G15),(I15-F15)-(H15-G15)),IF(E15="Folga(DSR)",IF(F15>I15,(I15+1-F15)-(H15-G15),(I15-F15)-(H15-G15)),IF(E15="Falta Justificada",IF(F15>I15,(I15+1-F15)-(H15-G15),(I15-F15)-(H15-G15)),IF(VLOOKUP(D15,'P Gerais'!$C$23:$M$29,11,0)-K15<0,ABS(VLOOKUP(D15,'P Gerais'!$C$23:$M$29,11,0)-K15),0)))) -> 0 | P15: =IF(O15>$P$7,1,0) -> 0 | Q15: Total de horas devidas | S15: =SUM(M8:M38) -> 0 | W15: =DATE('P Gerais'!$C$6,$W$7,Fev!C15) -> 42043 | X15: =WEEKDAY(W15) -> 1 | AD15: =H15-G15 -> 0 | AE15: =VLOOKUP(D15,'P Gerais'!$C$23:$N$29,12,0) -> 0 | AF15: =IF(AE15-AD15<0,0,IF(OR(G15="",G15=0),0,AE15-AD15)) -> 0 | AG15: =($AG$7-I15)+F15 -> 1 | AH15: =IF(AG15<$AH$7,$AH$7-AG15,$AF$7) -> 0 | AI15: =IF(F15=I15,$AF$7,IF(F15<$AI$7,$AI$7-F15,$AF$7)) -> 0 | AJ15: =IF(F15=I15,$AF$7,IF(F15>=$AJ$7,O15,$AF$7)) -> 0 | AK15: =IF(AND(I15>$AK$7,I15>AL15),I15-AL15,$AF$7) -> 0 | AL15: =VLOOKUP(D15,'P Gerais'!$C$23:$I$29,7,FALSE) -> 0
C16: 9 | D16: =VLOOKUP(X16,$AB$8:$AC$14,2,0) -> SEG | E16: Feriado | K16: =IF(ABS(((F16-1)-G16)+(H16-I16))>=1,ABS(((F16-1)-G16)+(H16-I16))-1,ABS(((F16-1)-G16)+(H16-I16))) -> 0 | M16: =IF(E16="Falta Justificada",0,IF(E16="Feriado",0,IF(E16="Folga(DSR)",0,IF(VLOOKUP(D16,'P Gerais'!$C$23:$M$29,11,0)-K16>0,VLOOKUP(D16,'P Gerais'!$C$23:$M$29,11,0)-K16,0)))) -> 0 | O16: =IF(E16="Feriado",IF(F16>I16,(I16+1-F16)-(H16-G16),(I16-F16)-(H16-G16)),IF(E16="Folga(DSR)",IF(F16>I16,(I16+1-F16)-(H16-G16),(I16-F16)-(H16-G16)),IF(E16="Falta Justificada",IF(F16>I16,(I16+1-F16)-(H16-G16),(I16-F16)-(H16-G16)),IF(VLOOKUP(D16,'P Gerais'!$C$23:$M$29,11,0)-K16<0,ABS(VLOOKUP(D16,'P Gerais'!$C$23:$M$29,11,0)-K16),0)))) -> 0 | P16: =IF(O16>$P$7,1,0) -> 0 | W16: =DATE('P Gerais'!$C$6,$W$7,Fev!C16) -> 42044 | X16: =WEEKDAY(W16) -> 2 | AD16: =H16-G16 -> 0 | AE16: =VLOOKUP(D16,'P Gerais'!$C$23:$N$29,12,0) -> 0 | AF16: =IF(AE16-AD16<0,0,IF(OR(G16="",G16=0),0,AE16-AD16)) -> 0 | AG16: =($AG$7-I16)+F16 -> 1 | AH16: =IF(AG16<$AH$7,$AH$7-AG16,$AF$7) -> 0 | AI16: =IF(F16=I16,$AF$7,IF(F16<$AI$7,$AI$7-F16,$AF$7)) -> 0 | AJ16: =IF(F16=I16,$AF$7,IF(F16>=$AJ$7,O16,$AF$7)) -> 0 | AK16: =IF(AND(I16>$AK$7,I16>AL16),I16-AL16,$AF$7) -> 0 | AL16: =VLOOKUP(D16,'P Gerais'!$C$23:$I$29,7,FALSE) -> 0
