Workbook

Sheet Ini
C2: PLANILHA DE
C3: PLANILHA DE AVALIAÇÃO ECONÔMICO-FINANCEIRA DE EMPRESA
C4: BALANÇO
C5: Seja bem-vindo(a). Com esta planilha você terá o controle das finanças da empresa e poderá tomar decisões importantes com base em números
C6: Instruções sobre como você deve começar
C8: 1 | E8: Balanço Patrimonial
E9: Os valores devem ser registrados aqui. Você irá relacionar isso de acordo com e a uma categoria das contas do Ativo (circulante e não circulante) e do Passivo (circulante, não circulante e Patrimôni Líquido.
C12: 2 | E12: Demonstração de Resultado de Exercício (DRE)
E13: A Demonstração do Resultado do Exercício tem como objetivo principal apresentarr esumida o resultado apurado em relação ao conjunto de operações realizadas num determinado período, normalmente, de doze meses.
C16: 3 | E16: Veja os resultados através de gráficos
E17: Aqui você verá os gráficos a partir de todos os dados que você cadastrou em “Balanço Patromônial” e “DRE” . É uma forma rápida e agradável para visualizar seus resultados de forma prática.
C20: 4 | E20: Faça uma Análise de Balanço
E21: Identifique os fatores positivos ou negativos sobre a saúde financeira e administrativa das empresas nos números divulgados em seus balanços patrimoniais
C24: 5 | E24: Imprima um relatório financeiro completo
E25: Já separamos uma aba exclusiva com suas principais informações financeiras prontas para impressão. Basta entrar no relatório e imprimir!

Sheet Bal
C1: 1. BALANÇO PATRIMÔNIAL
C6: 1000 | D6: Ativo Circulante (Bens e Direitos) | E6: =IF(ISERROR($E$7+$E$17+$E$27+$E$37+$E$47+$E$57+$E$67+$E$77+$E$87),"",$E$7+$E$17+$E$27+$E$37+$E$47+$E$57+$E$67+$E$77+$E$87) -> 153280 | H6: 1000 | I6: Contas do Ativo Circulante - Resultado
C7: 1110 | D7: Disponibilidades | E7: =IF(ISERROR(SUM(E8:E16)),"",SUM(E8:E16)) -> 57560 | H7: 1110 | I7: Disponibilidades | J7: 57560 | K7: 0.37552192 | L7: =IF(ISERROR(SUM($J$7:$J$15)),"",SUM($J$7:$J$15)) -> 153280
C8: 1111 | D8: Caixa | E8: 5850 | F8: =IF(ISERROR(E8/$E$7),"",E8/$E$7) -> 0.10163308 | H8: 1120 | I8: Aplicações em Instrumentos Financeiros | J8: 0 | K8: 0
C9: 1112 | D9: Recurso de Caixa Pequena | F9: =IF(ISERROR(E9/$E$7),"",E9/$E$7) -> 0 | H9: 1130 | I9: Estoque | J9: 46320 | K9: 0.30219207
C10: 1113 | D10: Bancos - Conta movimento no País | E10: 51710 | F10: =IF(ISERROR(E10/$E$7),"",E10/$E$7) -> 0.89836692 | H10: 1140 | I10: Créditos Tributários | J10: 0 | K10: 0
C11: 1114 | D11: Bancos no Exterior | F11: =IF(ISERROR(E11/$E$7),"",E11/$E$7) -> 0 | H11: 1150 | I11: Clientes Créditos a Receber | J11: 49400 | K11: 0.32228601
C12: 1115 | D12: Bancos Contas Vinculadas | F12: =IF(ISERROR(E12/$E$7),"",E12/$E$7) -> 0 | H12: 1160 | I12: Clientes Vencidos a Liquidar | J12: 0 | K12: 0
C13: 1116 | D13: Depósitos em Garantias e Cauções em Dinheiro | F13: =IF(ISERROR(E13/$E$7),"",E13/$E$7) -> 0 | H13: 1170 | I13: Outros Créditos | J13: 0 | K13: 0
C14: 1117 | D14: Disponibilidades em Moedas Estrangeiras | F14: =IF(ISERROR(E14/$E$7),"",E14/$E$7) -> 0 | H14: 1180 | I14: Outros Valores e Bens | J14: 0 | K14: 0
C15: 1118 | D15: Aplicações em Ouro | F15: =IF(ISERROR(E15/$E$7),"",E15/$E$7) -> 0 | H15: 1190 | I15: Despesas Antecipadas | J15: 0 | K15: 0
C16: 1119 | D16: Outras Disponibilidades - Valores Mobiliários | F16: =IF(ISERROR(E16/$E$7),"",E16/$E$7) -> 0
C17: 1120 | D17: Aplicações em Instrumentos Financeiros | E17: =IF(ISERROR(SUM(E18:E26)),"",SUM(E18:E26)) -> 0 | H17: Direitos Realizáveis a Curto Prazo
C18: 1121 | D18: Aplicações Compromissadas por Revenda | F18: =IF(ISERROR(E18/$E$17),"",E18/$E$17) | H18: 1120 | I18: Aplicações em Instrumentos Financeiros | J18: 0 | K18: 0
C19: 1122 | D19: Aplicações de Renda Fixa | F19: =IF(ISERROR(E19/$E$17),"",E19/$E$17) | H19: 1150 | I19: Clientes Créditos a Receber | J19: 49400 | K19: 1
C20: 1123 | D20: Aplicações de Renda Variável | F20: =IF(ISERROR(E20/$E$17),"",E20/$E$17) | H20: 1160 | I20: Clientes Vencidos a Liquidar | J20: 0 | K20: 0
C21: 1124 | D21: Títulos e Aplicações Vinculados | F21: =IF(ISERROR(E21/$E$17),"",E21/$E$17) | H21: Resultado | J21: 49400
C22: 1125 | D22: Devedores por Empréstimos de Títulos e Valores Mobiliários | F22: =IF(ISERROR(E22/$E$17),"",E22/$E$17)
C23: 1126 | D23: Box de Aplicação | F23: =IF(ISERROR(E23/$E$17),"",E23/$E$17) | H23: Valor Total do Ativo Circulante
C24: 1127 | D24: Valores Mobiliários em Moedas Estrangeiras | F24: =IF(ISERROR(E24/$E$17),"",E24/$E$17) | H24: Resultado | J24: 153280
C25: 1128 | D25: Valores Mobiliários Sujeitas a Restrições | F25: =IF(ISERROR(E25/$E$17),"",E25/$E$17)
C26: 1129 | D26: Outros Títulos e Valores Mobiliários a Receber | F26: =IF(ISERROR(E26/$E$17),"",E26/$E$17)
C27: 1130 | D27: Estoque | E27: =IF(ISERROR(SUM(E28:E36)),"",SUM(E28:E36)) -> 46320
C28: 1131 | D28: Estoque de Matéria Prima (insumos) | F28: =IF(ISERROR(E28/$E$27),"",E28/$E$27) -> 0
C29: 1132 | D29: Estoque de Produção em Elaboração | F29: =IF(ISERROR(E29/$E$27),"",E29/$E$27) -> 0
C30: 1133 | D30: Estoque de Produtos Acabados | F30: =IF(ISERROR(E30/$E$27),"",E30/$E$27) -> 0
C31: 1134 | D31: Estoque de Mercadorias para Revenda | E31: 46320 | F31: =IF(ISERROR(E31/$E$27),"",E31/$E$27) -> 1
C32: 1135 | D32: Mercadoria de Reposição na Prestação de Serviços | F32: =IF(ISERROR(E32/$E$27),"",E32/$E$27) -> 0
C33: 1136 | D33: Devedores por Estoques Remetidos para a Industrialização | F33: =IF(ISERROR(E33/$E$27),"",E33/$E$27) -> 0
C34: 1137 | D34: Devedores por Mercadorias Remetidas em Consignação ou Comodato | F34: =IF(ISERROR(E34/$E$27),"",E34/$E$27) -> 0
C35: 1138 | D35: Mercadorias Recebidas em Consignação ou Comodato | F35: =IF(ISERROR(E35/$E$27),"",E35/$E$27) -> 0
C36: 1139 | D36: Outros Estoques | F36: =IF(ISERROR(E36/$E$27),"",E36/$E$27) -> 0
C37: 1140 | D37: Créditos Tributários | E37: =IF(ISERROR(SUM(E38:E46)),"",SUM(E38:E46)) -> 0
C38: 1141 | D38: IRPJ - Imposto de Renda de Pessoa Jurídica | F38: =IF(ISERROR(E38/$E$37),"",E38/$E$37)
C39: 1142 | D39: CSLL - Contribuição Social sobre o Lucro Líquido | F39: =IF(ISERROR(E39/$E$37),"",E39/$E$37)
C40: 1143 | D40: ICMS - Imposto sobre Circulação de Mercadorias e Serviços e Outros Tributos Estaduais | F40: =IF(ISERROR(E40/$E$37),"",E40/$E$37)
C41: 1144 | D41: IPI - Imposto sobre Produtos Industrializados | F41: =IF(ISERROR(E41/$E$37),"",E41/$E$37)
C42: 1145 | D42: ISS - Imposto sobre Serviços e outros Tributos Municipais a Recuperar | F42: =IF(ISERROR(E42/$E$37),"",E42/$E$37)
C43: 1146 | D43: Contribuições Sociais - PIS e COFINS a Recuperar | F43: =IF(ISERROR(E43/$E$37),"",E43/$E$37)
C44: 1147 | D44: Crédito Fiscal do ICMS sobre o Imobilizado de Uso | F44: =IF(ISERROR(E44/$E$37),"",E44/$E$37)
...

Sheet Atin
C1: 1. BALANÇO PATRIMÔNIAL
C6: 2000 | D6: Ativo Não Circulante (Bens e Direitos) | E6: =IF(ISERROR($E$7+$E$17+$E$27+$E$37+$E$47+$E$57+$E$67+$E$77+$E$87+$E$97+$E$107+$E$117+$E$127+$E$137+$E$147),"",$E$7+$E$17+$E$27+$E$37+$E$47+$E$57+$E$67+$E$77+$E$87+$E$97+$E$107+$E$117+$E$127+$E$137+$E$147) -> 141500 | H6: 2000 | I6: Contas do Ativo Não Circulante - Resultado
C7: 2200 | D7: Valores e Bens | E7: =IF(ISERROR(SUM(E8:E16)),"",SUM(E8:E16)) -> 65000 | H7: 2200 | I7: Valores e Bens | J7: =IF(ISERROR($E$7),"",$E$7) -> 65000 | K7: =IF(ISERROR(J7/$L$7),"",J7/$L$7) -> 0.45936396 | L7: =IF(ISERROR(SUM($J$7:$J$21)),"",SUM($J$7:$J$21)) -> 141500
C8: 2211 | D8: Adiantamentos por Conta de Imobilizações | F8: =IF(ISERROR(E8/$E$7),"",E8/$E$7) -> 0 | H8: 2220 | I8: Garantias e Cauções | J8: =IF(ISERROR($E$17),"",$E$17) -> 0 | K8: =IF(ISERROR(J8/$L$7),"",J8/$L$7) -> 0
C9: 2212 | D9: Clientes - Devedores de Longo Prazo | E9: 65000 | F9: =IF(ISERROR(E9/$E$7),"",E9/$E$7) -> 1 | H9: 2230 | I9: Aplicações em Instrumentos Financeiros a Longo Prazo | J9: =IF(ISERROR($E$27),"",$E$27) -> 0 | K9: =IF(ISERROR(J9/$L$7),"",J9/$L$7) -> 0
C10: 2213 | D10: Imóveis em Construção | F10: =IF(ISERROR(E10/$E$7),"",E10/$E$7) -> 0 | H10: 2240 | I10: Depósitos Judiciais | J10: =IF(ISERROR($E$37),"",$E$37) -> 0 | K10: =IF(ISERROR(J10/$L$7),"",J10/$L$7) -> 0
C11: 2214 | D11: Estoque de Reposição Permanente | F11: =IF(ISERROR(E11/$E$7),"",E11/$E$7) -> 0 | H11: 2250 | I11: Imóveis para Locação ou Venda | J11: =IF(ISERROR($E$47),"",$E$47) -> 0 | K11: =IF(ISERROR(J11/$L$7),"",J11/$L$7) -> 0
C12: 2215 | D12: Antecipação de Valores Residuais de Arrendamento Mercantil | F12: =IF(ISERROR(E12/$E$7),"",E12/$E$7) -> 0 | H12: 2290 | I12: Outras Contas do Realizável | J12: =IF(ISERROR($E$57),"",$E$57) -> 0 | K12: =IF(ISERROR(J12/$L$7),"",J12/$L$7) -> 0
C13: 2216 | F13: =IF(ISERROR(E13/$E$7),"",E13/$E$7) -> 0 | H13: 2310 | I13: Investimentos | J13: =IF(ISERROR($E$67),"",$E$67) -> 0 | K13: =IF(ISERROR(J13/$L$7),"",J13/$L$7) -> 0
C14: 2217 | D14: Créditos Fiscais e Tributários de Longo Prazo | F14: =IF(ISERROR(E14/$E$7),"",E14/$E$7) -> 0 | H14: 2320 | I14: Imobilizado de Uso | J14: =IF(ISERROR($E$77),"",$E$77) -> 50000 | K14: =IF(ISERROR(J14/$L$7),"",J14/$L$7) -> 0.35335689
C15: 2218 | F15: =IF(ISERROR(E15/$E$7),"",E15/$E$7) -> 0 | H15: 2330 | I15: Ativo Diferido | J15: =IF(ISERROR($E$87),"",$E$87) -> 18500 | K15: =IF(ISERROR(J15/$L$7),"",J15/$L$7) -> 0.13074205
C16: 2219 | D16: Outros Valores e Bens a Longo Prazo | F16: =IF(ISERROR(E16/$E$7),"",E16/$E$7) -> 0 | H16: 2340 | I16: Intangível | J16: =IF(ISERROR($E$97),"",$E$97) -> 20000 | K16: =IF(ISERROR(J16/$L$7),"",J16/$L$7) -> 0.14134276
C17: 2220 | D17: Garantias e Cauções | E17: =IF(ISERROR(SUM(E18:E26)),"",SUM(E18:E26)) -> 0 | H17: 2350 | I17: Imobilizado de Arrendamento (Leaseback) | J17: =IF(ISERROR($E$107),"",$E$107) -> 0 | K17: =IF(ISERROR(J17/$L$7),"",J17/$L$7) -> 0
C18: 2221 | D18: Garantias e Cauções em Títulos | F18: =IF(ISERROR(E18/$E$17),"",E18/$E$17) | H18: 2360 | I18: Imobilizado Para Locação | J18: =IF(ISERROR($E$117),"",$E$117) -> 0 | K18: =IF(ISERROR(J18/$L$7),"",J18/$L$7) -> 0
C19: 2222 | D19: Garantias e Cauções em Bens Móveis | F19: =IF(ISERROR(E19/$E$17),"",E19/$E$17) | H19: 2370 | I19: Ativo Biológico e Produto Agrícola | J19: =IF(ISERROR($E$127),"",$E$127) -> 0 | K19: =IF(ISERROR(J19/$L$7),"",J19/$L$7) -> 0
C20: 2223 | D20: Garantias e Cauções em Imóveis | F20: =IF(ISERROR(E20/$E$17),"",E20/$E$17) | H20: 2380 | I20: Imobilzado Recebido em Comodato | J20: =IF(ISERROR($E$137),"",$E$137) -> 0 | K20: =IF(ISERROR(J20/$L$7),"",J20/$L$7) -> 0
C21: 2224 | D21: Garantias e Cauções em Dinheiro | F21: =IF(ISERROR(E21/$E$17),"",E21/$E$17) | H21: 2390 | I21: Outros | J21: =IF(ISERROR($E$147),"",$E$147) -> -12000 | K21: =IF(ISERROR(J21/$L$7),"",J21/$L$7) -> -0.084805654
C22: 2225 | F22: =IF(ISERROR(E22/$E$17),"",E22/$E$17)
C23: 2226 | F23: =IF(ISERROR(E23/$E$17),"",E23/$E$17) | H23: 2200 | I23: Direitos Realizáveis a Longo Prazo
C24: 2227 | F24: =IF(ISERROR(E24/$E$17),"",E24/$E$17) | H24: 2210 | I24: Valores e Bens | J24: =IF(ISERROR($E$7),"",$E$7) -> 65000 | K24: =IF(ISERROR(J24/$J$30),"",J24/$J$30) -> 1
C25: 2228 | F25: =IF(ISERROR(E25/$E$17),"",E25/$E$17) | H25: 2220 | I25: Garantias e Cauções | J25: =IF(ISERROR($E$17),"",$E$17) -> 0 | K25: =IF(ISERROR(J25/$J$30),"",J25/$J$30) -> 0
C26: 2229 | D26: Outras Garantias e Cauções | F26: =IF(ISERROR(E26/$E$17),"",E26/$E$17) | H26: 2230 | I26: Aplicações em Instrumentos Financeiros a Longo Prazo | J26: =IF(ISERROR($E$27),"",$E$27) -> 0 | K26: =IF(ISERROR(J26/$J$30),"",J26/$J$30) -> 0
C27: 2230 | D27: Aplicações em Instrumentos Financeiros a Longo Prazo | E27: =IF(ISERROR(SUM(E28:E36)),"",SUM(E28:E36)) -> 0 | H27: 2240 | I27: Depósitos Judiciais | J27: =IF(ISERROR($E$37),"",$E$37) -> 0 | K27: =IF(ISERROR(J27/$J$30),"",J27/$J$30) -> 0
C28: 2231 | D28: TVM de Sociedades em Regime Especial | F28: =IF(ISERROR(E28/$E$27),"",E28/$E$27) | H28: 2250 | I28: Imóveis para Locação ou Venda | J28: =IF(ISERROR($E$47),"",$E$47) -> 0 | K28: =IF(ISERROR(J28/$J$30),"",J28/$J$30) -> 0
C29: 2232 | D29: Participações em Sociedades em Regime Especial | F29: =IF(ISERROR(E29/$E$27),"",E29/$E$27) | H29: 2290 | I29: Outras Contas do Realizável | J29: =IF(ISERROR($E$57),"",$E$57) -> 0 | K29: =IF(ISERROR(J29/$J$30),"",J29/$J$30) -> 0
C30: 2233 | D30: Opções por Incentivos Fiscais | F30: =IF(ISERROR(E30/$E$27),"",E30/$E$27) | H30: Resultado | J30: =IF(ISERROR(SUM($J$24:$J$29)),"",SUM($J$24:$J$29)) -> 65000
C31: 2234 | F31: =IF(ISERROR(E31/$E$27),"",E31/$E$27)
C32: 2235 | F32: =IF(ISERROR(E32/$E$27),"",E32/$E$27) | H32: 2300 | I32: Ativo Permanente
C33: 2236 | F33: =IF(ISERROR(E33/$E$27),"",E33/$E$27) | H33: 2310 | I33: Investimentos | J33: =IF(ISERROR($E$67),"",$E$67) -> 0 | K33: =IF(ISERROR(J33/$J$42),"",J33/$J$42) -> 0
C34: 2237 | F34: =IF(ISERROR(E34/$E$27),"",E34/$E$27) | H34: 2320 | I34: Imobilizado de Uso | J34: =IF(ISERROR($E$77),"",$E$77) -> 50000 | K34: =IF(ISERROR(J34/$J$42),"",J34/$J$42) -> 0.65359477
C35: 2238 | F35: =IF(ISERROR(E35/$E$27),"",E35/$E$27) | H35: 2330 | I35: Ativo Diferido | J35: =IF(ISERROR($E$87),"",$E$87) -> 18500 | K35: =IF(ISERROR(J35/$J$42),"",J35/$J$42) -> 0.24183007
C36: 2239 | D36: Outros Títulos e Valores Mobiliários de Longo Prazo | F36: =IF(ISERROR(E36/$E$27),"",E36/$E$27) | H36: 2340 | I36: Intangível | J36: =IF(ISERROR($E$97),"",$E$97) -> 20000 | K36: =IF(ISERROR(J36/$J$42),"",J36/$J$42) -> 0.26143791
C37: 2240 | D37: Depósitos Judiciais | E37: =IF(ISERROR(SUM(E38:E46)),"",SUM(E38:E46)) -> 0 | H37: 2350 | I37: Imobilizado de Arrendamento (Leaseback) | J37: =IF(ISERROR($E$107),"",$E$107) -> 0 | K37: =IF(ISERROR(J37/$J$42),"",J37/$J$42) -> 0
C38: 2241 | D38: Depósitos Judiciais - Trabalhistas | F38: =IF(ISERROR(E38/$E$37),"",E38/$E$37) | H38: 2360 | I38: Imobilizado Para Locação | J38: =IF(ISERROR($E$117),"",$E$117) -> 0 | K38: =IF(ISERROR(J38/$J$42),"",J38/$J$42) -> 0
C39: 2242 | D39: Depósitos Judiciais - Fiscais e Tributários | F39: =IF(ISERROR(E39/$E$37),"",E39/$E$37) | H39: 2370 | I39: Ativo Biológico e Produto Agrícola | J39: =IF(ISERROR($E$127),"",$E$127) -> 0 | K39: =IF(ISERROR(J39/$J$42),"",J39/$J$42) -> 0
C40: 2243 | F40: =IF(ISERROR(E40/$E$37),"",E40/$E$37) | H40: 2380 | I40: Imobilzado Recebido em Comodato | J40: =IF(ISERROR($E$137),"",$E$137) -> 0 | K40: =IF(ISERROR(J40/$J$42),"",J40/$J$42) -> 0
C41: 2244 | F41: =IF(ISERROR(E41/$E$37),"",E41/$E$37) | H41: 2390 | I41: Outros | J41: =IF(ISERROR($E$147),"",$E$147) -> -12000 | K41: =IF(ISERROR(J41/$J$42),"",J41/$J$42) -> -0.15686275
C42: 2245 | F42: =IF(ISERROR(E42/$E$37),"",E42/$E$37) | H42: Resultado | J42: =IF(ISERROR(SUM($J$33:$J$41)),"",SUM($J$33:$J$41)) -> 76500
C43: 2246 | F43: =IF(ISERROR(E43/$E$37),"",E43/$E$37)
C44: 2247 | F44: =IF(ISERROR(E44/$E$37),"",E44/$E$37) | H44: Valor Total do Ativo Circulante
...

Sheet Pas
C1: 1. BALANÇO PATRIMÔNIAL
C6: 3400 | D6: Passivo Circulante (Deveres e Obrigações) | E6: =IF(ISERROR($E$7+$E$17+$E$27+$E$37+$E$47+$E$57+$E$67+$E$77+$E$87),"",$E$7+$E$17+$E$27+$E$37+$E$47+$E$57+$E$67+$E$77+$E$87) -> 58958 | H6: 3400 | I6: Contas do Passivo Circulante - Resultado
C7: 3410 | D7: Fornecedores | E7: =IF(ISERROR(SUM(E8:E16)),"",SUM(E8:E16)) -> 31840 | H7: 3410 | I7: Fornecedores | J7: =IF(ISERROR($E$7),"",$E$7) -> 31840 | K7: =IF(ISERROR(J7/$L$7),"",J7/$L$7) -> 0.54004546 | L7: =IF(ISERROR(SUM($J$7:$J$15)),"",SUM($J$7:$J$15)) -> 58958
C8: 3411 | D8: Fornecedores de Mercadorias para Revenda | E8: 31840 | F8: =IF(ISERROR(E8/$E$7),"",E8/$E$7) -> 1 | H8: 3410 | I8: Obrigações Financeiras a Curto Prazo | J8: =IF(ISERROR($E$17),"",$E$17) -> 0 | K8: =IF(ISERROR(J8/$L$7),"",J8/$L$7) -> 0
C9: 3412 | D9: Fornecedores de Bens para o Permanente | F9: =IF(ISERROR(E9/$E$7),"",E9/$E$7) -> 0 | H9: 3410 | I9: Obrigações Fiscais e Tributárias | J9: =IF(ISERROR($E$27),"",$E$27) -> 0 | K9: =IF(ISERROR(J9/$L$7),"",J9/$L$7) -> 0
C10: 3413 | D10: Fornecedores de Matérias Primas para a Industrialização | F10: =IF(ISERROR(E10/$E$7),"",E10/$E$7) -> 0 | H10: 3410 | I10: Obrigações Trabalhistas e Previdenciárias | J10: =IF(ISERROR($E$37),"",$E$37) -> 12750 | K10: =IF(ISERROR(J10/$L$7),"",J10/$L$7) -> 0.21625564
C11: 3414 | D11: Fornecedores de Peças de Reposição | F11: =IF(ISERROR(E11/$E$7),"",E11/$E$7) -> 0 | H11: 3410 | I11: Obrigações Sociais e Estatutárias | J11: =IF(ISERROR($E$47),"",$E$47) -> 8874 | K11: =IF(ISERROR(J11/$L$7),"",J11/$L$7) -> 0.15051393
C12: 3415 | D12: Fornecedores de Bens em Consignação ou Comodato | F12: =IF(ISERROR(E12/$E$7),"",E12/$E$7) -> 0 | H12: 3410 | I12: Obrigações Administrativas e Operacionais | J12: =IF(ISERROR($E$57),"",$E$57) -> 5494 | K12: =IF(ISERROR(J12/$L$7),"",J12/$L$7) -> 0.093184979
C13: 3416 | D13: Forncedores de Material de Expediente | F13: =IF(ISERROR(E13/$E$7),"",E13/$E$7) -> 0 | H13: 3410 | I13: Provisões para Contingências | J13: =IF(ISERROR($E$67),"",$E$67) -> 0 | K13: =IF(ISERROR(J13/$L$7),"",J13/$L$7) -> 0
C14: 3417 | F14: =IF(ISERROR(E14/$E$7),"",E14/$E$7) -> 0 | H14: 3410 | I14: Relações Interfinanceiras | J14: =IF(ISERROR($E$77),"",$E$77) -> 0 | K14: =IF(ISERROR(J14/$L$7),"",J14/$L$7) -> 0
C15: 3418 | D15: Fornecedores no Exterior | F15: =IF(ISERROR(E15/$E$7),"",E15/$E$7) -> 0 | H15: 3410 | I15: Outras Obrigações | J15: =IF(ISERROR($E$87),"",$E$87) -> 0 | K15: =IF(ISERROR(J15/$L$7),"",J15/$L$7) -> 0
C16: 3419 | D16: Outros Fornecedores | F16: =IF(ISERROR(E16/$E$7),"",E16/$E$7) -> 0
C17: 3420 | D17: Obrigações Financeiras de Curto Prazo | E17: =IF(ISERROR(SUM(E18:E26)),"",SUM(E18:E26)) -> 0 | H17: 3400 | I17: Obrigações Realizáveis a Curto Prazo
C18: 3421 | D18: Bancos Oficiais Federais | F18: =IF(ISERROR(E18/$E$17),"",E18/$E$17) | H18: 3410 | I18: Fornecedores | J18: =IF(ISERROR($E$7),"",$E$7) -> 31840 | K18: =IF(ISERROR(J18/$J$21),"",J18/$J$21) -> 2.4972549
C19: 3422 | D19: Bancos Oficiais Estaduais | F19: =IF(ISERROR(E19/$E$17),"",E19/$E$17) | H19: 3410 | I19: Obrigações Financeiras a Curto Prazo | J19: =IF(ISERROR($E$17),"",$E$17) -> 0 | K19: =IF(ISERROR(J19/$J$21),"",J19/$J$21) -> 0
C20: 3423 | D20: Bancos Privados no Brasil | F20: =IF(ISERROR(E20/$E$17),"",E20/$E$17) | H20: 3410 | I20: Obrigações Fiscais e Tributárias | J20: =IF(ISERROR($E$27),"",$E$27) -> 0 | K20: =IF(ISERROR(J20/$J$21),"",J20/$J$21) -> 0
C21: 3424 | D21: Bancos Oficiais no Exterior | F21: =IF(ISERROR(E21/$E$17),"",E21/$E$17) | H21: 3410 | I21: Obrigações Trabalhistas e Previdenciárias | J21: =IF(ISERROR($E$37),"",$E$37) -> 12750 | K21: =IF(ISERROR(J21/$J$21),"",J21/$J$21) -> 1
C22: 3425 | D22: Outros Bancos no Exterior | F22: =IF(ISERROR(E22/$E$17),"",E22/$E$17) | H22: 3410 | I22: Obrigações Sociais e Estatutárias | J22: =IF(ISERROR($E$47),"",$E$47) -> 8874 | K22: =IF(ISERROR(J22/$J$21),"",J22/$J$21) -> 0.696
C23: 3426 | D23: Empresas de Factoring / Forfaiting | F23: =IF(ISERROR(E23/$E$17),"",E23/$E$17) | H23: 3410 | I23: Provisões para Contingências | J23: =IF(ISERROR($E$67),"",$E$67) -> 0 | K23: =IF(ISERROR(J23/$J$21),"",J23/$J$21) -> 0
C24: 3427 | F24: =IF(ISERROR(E24/$E$17),"",E24/$E$17) | H24: Resultado | J24: =IF(ISERROR(SUM($J$18:$J$23)),"",SUM($J$18:$J$23)) -> 53464
C25: 3428 | D25: Box de Captação | F25: =IF(ISERROR(E25/$E$17),"",E25/$E$17)
C26: 3429 | D26: Outros Financiamentos de Curto Prazo | F26: =IF(ISERROR(E26/$E$17),"",E26/$E$17) | H26: Valor Total do Passivo Circulante
C27: 3430 | D27: Obrigações Fiscais e Tributárias | E27: =IF(ISERROR(SUM(E28:E36)),"",SUM(E28:E36)) -> 0 | H27: Resultado | J27: =IF(ISERROR(SUM($J$7:$J$15)),"",SUM($J$7:$J$15)) -> 58958
C28: 3431 | D28: Imposto de Renda Retido na Fonte | F28: =IF(ISERROR(E28/$E$27),"",E28/$E$27)
C29: 3432 | D29: Imposto de Renda e Contribuição Social a Pagar | F29: =IF(ISERROR(E29/$E$27),"",E29/$E$27)
C30: 3433 | D30: Outros Impostos Federais | F30: =IF(ISERROR(E30/$E$27),"",E30/$E$27)
C31: 3434 | D31: Impostos Estaduais | F31: =IF(ISERROR(E31/$E$27),"",E31/$E$27)
C32: 3435 | D32: Impostos Municipais | F32: =IF(ISERROR(E32/$E$27),"",E32/$E$27)
C33: 3436 | F33: =IF(ISERROR(E33/$E$27),"",E33/$E$27)
C34: 3437 | F34: =IF(ISERROR(E34/$E$27),"",E34/$E$27)
C35: 3438 | F35: =IF(ISERROR(E35/$E$27),"",E35/$E$27)
C36: 3439 | D36: Outras Obrigações Fiscais e Tributárias | F36: =IF(ISERROR(E36/$E$27),"",E36/$E$27)
C37: 3440 | D37: Obrigações Trabalhistas e Previdenciárias | E37: =IF(ISERROR(SUM(E38:E46)),"",SUM(E38:E46)) -> 12750
C38: 3441 | D38: Ordenados e Salários a Pagar | E38: 12750 | F38: =IF(ISERROR(E38/$E$37),"",E38/$E$37) -> 1
C39: 3442 | D39: Autonômos - Pessoas Físicas | F39: =IF(ISERROR(E39/$E$37),"",E39/$E$37) -> 0
C40: 3443 | D40: Terceirizados - Pessoas Jurídicas | F40: =IF(ISERROR(E40/$E$37),"",E40/$E$37) -> 0
C41: 3444 | D41: Contribuição ao INSS | F41: =IF(ISERROR(E41/$E$37),"",E41/$E$37) -> 0
C42: 3445 | D42: FGTS | F42: =IF(ISERROR(E42/$E$37),"",E42/$E$37) -> 0
C43: 3446 | D43: Contribuição Sindical | F43: =IF(ISERROR(E43/$E$37),"",E43/$E$37) -> 0
C44: 3447 | D44: Indenizações Trabalhistas a Pagar | F44: =IF(ISERROR(E44/$E$37),"",E44/$E$37) -> 0
...

Sheet Pasn
C1: 1. BALANÇO PATRIMÔNIAL
C6: 4000 | D6: Passivo Não Circulante (Deveres e Obrigações) | E6: =IF(ISERROR($E$7+$E$17+$E$27+$E$37+$E$47+$E$57+$E$67+$E$77+$E$87+$E$97+$E$107+$E$117+$E$127+$E$137+$E$147+$E$157+$E$167+$E$177+$E$187+$E$197),"",$E$7+$E$17+$E$27+$E$37+$E$47+$E$57+$E$67+$E$77+$E$87+$E$97+$E$107+$E$117+$E$127+$E$137+$E$147+$E$157+$E$167+$E$177+$E$187+$E$197) -> 235822 | H6: 4000 | I6: Contas do Passivo Não Circulante - Resultado
C7: 4510 | D7: Fornecedores | E7: =IF(ISERROR(SUM(E8:E16)),"",SUM(E8:E16)) -> 50000 | H7: 4510 | I7: Fornecedores | J7: =IF(ISERROR($E$7),"",$E$7) -> 50000 | K7: =IF(ISERROR(J7/$L$7),"",J7/$L$7) -> 0.21202432 | L7: =IF(ISERROR(SUM($J$7:$J$26)),"",SUM($J$7:$J$26)) -> 235822
C8: 4511 | D8: Fornecedores de Bens do Ativo Permanente | E8: 50000 | F8: =IF(ISERROR(E8/$E$7),"",E8/$E$7) -> 1 | H8: 4520 | I8: Obrigações Financeiras a Longo Prazo | J8: =IF(ISERROR($E$17),"",$E$17) -> 0 | K8: =IF(ISERROR(J8/$L$7),"",J8/$L$7) -> 0
C9: 4512 | F9: =IF(ISERROR(E9/$E$7),"",E9/$E$7) -> 0 | H9: 4530 | I9: Obrigações Fiscais e Tributárias | J9: =IF(ISERROR($E$27),"",$E$27) -> 0 | K9: =IF(ISERROR(J9/$L$7),"",J9/$L$7) -> 0
C10: 4513 | F10: =IF(ISERROR(E10/$E$7),"",E10/$E$7) -> 0 | H10: 4540 | I10: Obrigações Trabalhistas e Previdenciárias | J10: =IF(ISERROR($E$37),"",$E$37) -> 0 | K10: =IF(ISERROR(J10/$L$7),"",J10/$L$7) -> 0
C11: 4514 | F11: =IF(ISERROR(E11/$E$7),"",E11/$E$7) -> 0 | H11: 4550 | I11: Obrigações Sociais e Estatutárias | J11: =IF(ISERROR($E$47),"",$E$47) -> 0 | K11: =IF(ISERROR(J11/$L$7),"",J11/$L$7) -> 0
C12: 4515 | F12: =IF(ISERROR(E12/$E$7),"",E12/$E$7) -> 0 | H12: 4560 | I12: Créditos de Coligadas e Controladas | J12: =IF(ISERROR($E$57),"",$E$57) -> 0 | K12: =IF(ISERROR(J12/$L$7),"",J12/$L$7) -> 0
C13: 4516 | F13: =IF(ISERROR(E13/$E$7),"",E13/$E$7) -> 0 | H13: 4570 | I13: Provisões para Contingências | J13: =IF(ISERROR($E$67),"",$E$67) -> 0 | K13: =IF(ISERROR(J13/$L$7),"",J13/$L$7) -> 0
C14: 4517 | F14: =IF(ISERROR(E14/$E$7),"",E14/$E$7) -> 0 | H14: 4580 | I14: Receitas Diferidas | J14: =IF(ISERROR($E$77),"",$E$77) -> 0 | K14: =IF(ISERROR(J14/$L$7),"",J14/$L$7) -> 0
C15: 4518 | F15: =IF(ISERROR(E15/$E$7),"",E15/$E$7) -> 0 | H15: 4590 | I15: Outras Obrigações | J15: =IF(ISERROR($E$87),"",$E$87) -> 0 | K15: =IF(ISERROR(J15/$L$7),"",J15/$L$7) -> 0
C16: 4519 | D16: Outros Fornecedores do Longo Prazo | F16: =IF(ISERROR(E16/$E$7),"",E16/$E$7) -> 0 | H16: 4610 | I16: Resultados de Exercícios Futuros - Receitas Diferidas | J16: =IF(ISERROR($E$97),"",$E$97) -> 0 | K16: =IF(ISERROR(J16/$L$7),"",J16/$L$7) -> 0
C17: 4520 | D17: Obrigações Financeiras de Longo Prazo | E17: =IF(ISERROR(SUM(E18:E26)),"",SUM(E18:E26)) -> 0 | H17: 4620 | I17: Custos e Despesas de Exercícios Futuros | J17: =IF(ISERROR($E$107),"",$E$107) -> 0 | K17: =IF(ISERROR(J17/$L$7),"",J17/$L$7) -> 0
C18: 4521 | D18: Bancos Oficiais Federais | F18: =IF(ISERROR(E18/$E$17),"",E18/$E$17) | H18: 5710 | I18: Capital / Capital Social / Patrimônio Social | J18: =IF(ISERROR($E$117),"",$E$117) -> 120000 | K18: =IF(ISERROR(J18/$L$7),"",J18/$L$7) -> 0.50885838
C19: 4522 | D19: Bancos Oficiais Estaduais | F19: =IF(ISERROR(E19/$E$17),"",E19/$E$17) | H19: 5720 | I19: Reserva de Capital | J19: =IF(ISERROR($E$127),"",$E$127) -> 1556 | K19: =IF(ISERROR(J19/$L$7),"",J19/$L$7) -> 0.0065981969
C20: 4523 | D20: Bancos Privados no Brasil | F20: =IF(ISERROR(E20/$E$17),"",E20/$E$17) | H20: 5730 | I20: Ações em Tesouraria | J20: =IF(ISERROR($E$137),"",$E$137) -> 0 | K20: =IF(ISERROR(J20/$L$7),"",J20/$L$7) -> 0
C21: 4524 | D21: Bancos Privados no Exterior | F21: =IF(ISERROR(E21/$E$17),"",E21/$E$17) | H21: 5740 | I21: Ajustes de Avaliação Patrimônial | J21: =IF(ISERROR($E$147),"",$E$147) -> 0 | K21: =IF(ISERROR(J21/$L$7),"",J21/$L$7) -> 0
C22: 4525 | D22: Outros Bancos no Exterior | F22: =IF(ISERROR(E22/$E$17),"",E22/$E$17) | H22: 5750 | I22: Reservas de Lucros | J22: =IF(ISERROR($E$157),"",$E$157) -> 64266 | K22: =IF(ISERROR(J22/$L$7),"",J22/$L$7) -> 0.2725191
C23: 4526 | D23: Empresas de Factoring / Forfaiting | F23: =IF(ISERROR(E23/$E$17),"",E23/$E$17) | H23: 5760 | I23: Reservas de Reavaliação | J23: =IF(ISERROR($E$167),"",$E$167) -> 0 | K23: =IF(ISERROR(J23/$L$7),"",J23/$L$7) -> 0
C24: 4527 | D24: Box de Captção | F24: =IF(ISERROR(E24/$E$17),"",E24/$E$17) | H24: 5770 | I24: Outras Reservas | J24: =IF(ISERROR($E$177),"",$E$177) -> 0 | K24: =IF(ISERROR(J24/$L$7),"",J24/$L$7) -> 0
C25: 4528 | F25: =IF(ISERROR(E25/$E$17),"",E25/$E$17) | H25: 5780 | I25: Lucros Acumulados / Sobras / Superávits | J25: =IF(ISERROR($E$187),"",$E$187) -> 0 | K25: =IF(ISERROR(J25/$L$7),"",J25/$L$7) -> 0
C26: 4529 | D26: Outros Financiamentos de Longo Prazo | F26: =IF(ISERROR(E26/$E$17),"",E26/$E$17) | H26: 5790 | I26: Prejuízos, Perdas e Déficits Acumulados | J26: =IF(ISERROR($E$197),"",$E$197) -> 0 | K26: =IF(ISERROR(J26/$L$7),"",J26/$L$7) -> 0
C27: 4530 | D27: Obrigações Fiscais e Tributárias | E27: =IF(ISERROR(SUM(E28:E36)),"",SUM(E28:E36)) -> 0
C28: 4531 | D28: Imposto de Renda Diferido | F28: =IF(ISERROR(E28/$E$27),"",E28/$E$27) | H28: 4500 | I28: Obrigações Realizáveis a Longo Prazo
C29: 4532 | D29: Parcelamentos de Débitos Tributários e Federais | F29: =IF(ISERROR(E29/$E$27),"",E29/$E$27) | H29: 4510 | I29: Fornecedores | J29: =IF(ISERROR($E$7),"",$E$7) -> 50000 | K29: =IF(ISERROR(J29/$J$38),"",J29/$J$38) -> 1
C30: 4533 | D30: Parcelamentos de Débitos Tributários e Estaduais | F30: =IF(ISERROR(E30/$E$27),"",E30/$E$27) | H30: 4520 | I30: Obrigações Financeiras a Longo Prazo | J30: =IF(ISERROR($E$17),"",$E$17) -> 0 | K30: =IF(ISERROR(J30/$J$38),"",J30/$J$38) -> 0
C31: 4534 | D31: Parcelamentos de Débitos Tributários e Municipais | F31: =IF(ISERROR(E31/$E$27),"",E31/$E$27) | H31: 4530 | I31: Obrigações Fiscais e Tributárias | J31: =IF(ISERROR($E$27),"",$E$27) -> 0 | K31: =IF(ISERROR(J31/$J$38),"",J31/$J$38) -> 0
C32: 4535 | D32: Contribuição Social Diferida | F32: =IF(ISERROR(E32/$E$27),"",E32/$E$27) | H32: 4540 | I32: Obrigações Trabalhistas e Previdenciárias | J32: =IF(ISERROR($E$37),"",$E$37) -> 0 | K32: =IF(ISERROR(J32/$J$38),"",J32/$J$38) -> 0
C33: 4536 | D33: Outras Provisões para Impostos Diferidos | F33: =IF(ISERROR(E33/$E$27),"",E33/$E$27) | H33: 4550 | I33: Obrigações Sociais e Estatutárias | J33: =IF(ISERROR($E$47),"",$E$47) -> 0 | K33: =IF(ISERROR(J33/$J$38),"",J33/$J$38) -> 0
C34: 4537 | F34: =IF(ISERROR(E34/$E$27),"",E34/$E$27) | H34: 4560 | I34: Créditos de Coligadas e Controladas | J34: =IF(ISERROR($E$57),"",$E$57) -> 0 | K34: =IF(ISERROR(J34/$J$38),"",J34/$J$38) -> 0
C35: 4538 | F35: =IF(ISERROR(E35/$E$27),"",E35/$E$27) | H35: 4570 | I35: Provisões para Contingências | J35: =IF(ISERROR($E$67),"",$E$67) -> 0 | K35: =IF(ISERROR(J35/$J$38),"",J35/$J$38) -> 0
C36: 4539 | D36: Outras Obrigações Fiscais e Tributárias | F36: =IF(ISERROR(E36/$E$27),"",E36/$E$27) | H36: 4580 | I36: Receitas Diferidas | J36: =IF(ISERROR($E$77),"",$E$77) -> 0 | K36: =IF(ISERROR(J36/$J$38),"",J36/$J$38) -> 0
C37: 4540 | D37: Obrigações Trabalhistas e Previdenciárias | E37: =IF(ISERROR(SUM(E38:E46)),"",SUM(E38:E46)) -> 0 | H37: 4590 | I37: Outras Obrigações | J37: =IF(ISERROR($E$87),"",$E$87) -> 0 | K37: =IF(ISERROR(J37/$J$38),"",J37/$J$38) -> 0
C38: 4541 | D38: Ações Judiciais Trabalhistas | F38: =IF(ISERROR(E38/$E$37),"",E38/$E$37) | H38: Resultado | J38: =IF(ISERROR(SUM($J$29:$J$37)),"",SUM($J$29:$J$37)) -> 50000
C39: 4542 | D39: Ações Judiciais Previdenciárias | F39: =IF(ISERROR(E39/$E$37),"",E39/$E$37)
C40: 4543 | D40: Parcelamento de Débitos Trabalhistas | F40: =IF(ISERROR(E40/$E$37),"",E40/$E$37) | H40: 4600 | I40: Resultado de Exercícios Futuros
C41: 4544 | D41: Parcelamento de Débitos Previdenciários | F41: =IF(ISERROR(E41/$E$37),"",E41/$E$37) | H41: 4610 | I41: Resultados de Exercícios Futuros - Receitas Diferidas | J41: =IF(ISERROR($E$97),"",$E$97) -> 0 | K41: =IF(ISERROR(J41/$J$43),"",J41/$J$43)
C42: 4545 | F42: =IF(ISERROR(E42/$E$37),"",E42/$E$37) | H42: 4620 | I42: Custos e Despesas de Exercícios Futuros | J42: =IF(ISERROR($E$107),"",$E$107) -> 0 | K42: =IF(ISERROR(J42/$J$43),"",J42/$J$43)
C43: 4546 | F43: =IF(ISERROR(E43/$E$37),"",E43/$E$37) | H43: Resultado | J43: =IF(ISERROR(SUM($J$41:$J$42)),"",SUM($J$41:$J$42)) -> 0
C44: 4547 | F44: =IF(ISERROR(E44/$E$37),"",E44/$E$37)
...

Sheet Res Bp
C1: 1. BALANÇO PATRIMÔNIAL
C6: 1000 | D6: Contas do Ativo Circulante - Resultado | H6: 3400 | I6: Contas do Passivo Circulante - Resultado
C7: 1110 | D7: Disponibilidades | E7: =IF(ISERROR(Bal!J7),"",Bal!J7) -> 57560 | F7: =IF(ISERROR(Bal!K7),"",Bal!K7) -> 0.37552192 | H7: 3410 | I7: Fornecedores | J7: =IF(ISERROR(Pas!J7),"",Pas!J7) -> 31840 | K7: =IF(ISERROR(Pas!K7),"",Pas!K7) -> 0.54004546 | L7: =IF(ISERROR(SUM($E$7:$E$15)),"",SUM($E$7:$E$15)) -> 153280
C8: 1120 | D8: Aplicações em Instrumentos Financeiros | E8: =IF(ISERROR(Bal!J8),"",Bal!J8) -> 0 | F8: =IF(ISERROR(Bal!K8),"",Bal!K8) -> 0 | H8: 3410 | I8: Obrigações Financeiras a Curto Prazo | J8: =IF(ISERROR(Pas!J8),"",Pas!J8) -> 0 | K8: =IF(ISERROR(Pas!K8),"",Pas!K8) -> 0
C9: 1130 | D9: Estoque | E9: =IF(ISERROR(Bal!J9),"",Bal!J9) -> 46320 | F9: =IF(ISERROR(Bal!K9),"",Bal!K9) -> 0.30219207 | H9: 3410 | I9: Obrigações Fiscais e Tributárias | J9: =IF(ISERROR(Pas!J9),"",Pas!J9) -> 0 | K9: =IF(ISERROR(Pas!K9),"",Pas!K9) -> 0
C10: 1140 | D10: Créditos Tributários | E10: =IF(ISERROR(Bal!J10),"",Bal!J10) -> 0 | F10: =IF(ISERROR(Bal!K10),"",Bal!K10) -> 0 | H10: 3410 | I10: Obrigações Trabalhistas e Previdenciárias | J10: =IF(ISERROR(Pas!J10),"",Pas!J10) -> 12750 | K10: =IF(ISERROR(Pas!K10),"",Pas!K10) -> 0.21625564
C11: 1150 | D11: Clientes Créditos a Receber | E11: =IF(ISERROR(Bal!J11),"",Bal!J11) -> 49400 | F11: =IF(ISERROR(Bal!K11),"",Bal!K11) -> 0.32228601 | H11: 3410 | I11: Obrigações Sociais e Estatutárias | J11: =IF(ISERROR(Pas!J11),"",Pas!J11) -> 8874 | K11: =IF(ISERROR(Pas!K11),"",Pas!K11) -> 0.15051393
C12: 1160 | D12: Clientes Vencidos a Liquidar | E12: =IF(ISERROR(Bal!J12),"",Bal!J12) -> 0 | F12: =IF(ISERROR(Bal!K12),"",Bal!K12) -> 0 | H12: 3410 | I12: Obrigações Administrativas e Operacionais | J12: =IF(ISERROR(Pas!J12),"",Pas!J12) -> 5494 | K12: =IF(ISERROR(Pas!K12),"",Pas!K12) -> 0.093184979
C13: 1170 | D13: Outros Créditos | E13: =IF(ISERROR(Bal!J13),"",Bal!J13) -> 0 | F13: =IF(ISERROR(Bal!K13),"",Bal!K13) -> 0 | H13: 3410 | I13: Provisões para Contingências | J13: =IF(ISERROR(Pas!J13),"",Pas!J13) -> 0 | K13: =IF(ISERROR(Pas!K13),"",Pas!K13) -> 0
C14: 1180 | D14: Outros Valores e Bens | E14: =IF(ISERROR(Bal!J14),"",Bal!J14) -> 0 | F14: =IF(ISERROR(Bal!K14),"",Bal!K14) -> 0 | H14: 3410 | I14: Relações Interfinanceiras | J14: =IF(ISERROR(Pas!J14),"",Pas!J14) -> 0 | K14: =IF(ISERROR(Pas!K14),"",Pas!K14) -> 0
C15: 1190 | D15: Despesas Antecipadas | E15: =IF(ISERROR(Bal!J15),"",Bal!J15) -> 0 | F15: =IF(ISERROR(Bal!K15),"",Bal!K15) -> 0 | H15: 3410 | I15: Outras Obrigações | J15: =IF(ISERROR(Pas!J15),"",Pas!J15) -> 0 | K15: =IF(ISERROR(Pas!K15),"",Pas!K15) -> 0
C16: Resultado | E16: =IF(ISERROR(SUM(E7:E15)),"",SUM(E7:E15)) -> 153280 | H16: Resultado | J16: =IF(ISERROR(SUM(J7:J15)),"",SUM(J7:J15)) -> 58958
C18: 2000 | D18: Contas do Ativo Não Circulante - Resultado | H18: 4000 | I18: Contas do Passivo Não Circulante - Resultado
C19: 2200 | D19: Valores e Bens | E19: =IF(ISERROR(Atin!J7),"",Atin!J7) -> 65000 | F19: =IF(ISERROR(Atin!K7),"",Atin!K7) -> 0.45936396 | H19: 4510 | I19: Fornecedores | J19: =IF(ISERROR(Pasn!J7),"",Pasn!J7) -> 50000 | K19: =IF(ISERROR(Pasn!K7),"",Pasn!K7) -> 0.21202432
C20: 2220 | D20: Garantias e Cauções | E20: =IF(ISERROR(Atin!J8),"",Atin!J8) -> 0 | F20: =IF(ISERROR(Atin!K8),"",Atin!K8) -> 0 | H20: 4520 | I20: Obrigações Financeiras a Longo Prazo | J20: =IF(ISERROR(Pasn!J8),"",Pasn!J8) -> 0 | K20: =IF(ISERROR(Pasn!K8),"",Pasn!K8) -> 0
C21: 2230 | D21: Aplicações em Instrumentos Financeiros a Longo Prazo | E21: =IF(ISERROR(Atin!J9),"",Atin!J9) -> 0 | F21: =IF(ISERROR(Atin!K9),"",Atin!K9) -> 0 | H21: 4530 | I21: Obrigações Fiscais e Tributárias | J21: =IF(ISERROR(Pasn!J9),"",Pasn!J9) -> 0 | K21: =IF(ISERROR(Pasn!K9),"",Pasn!K9) -> 0
C22: 2240 | D22: Depósitos Judiciais | E22: =IF(ISERROR(Atin!J10),"",Atin!J10) -> 0 | F22: =IF(ISERROR(Atin!K10),"",Atin!K10) -> 0 | H22: 4540 | I22: Obrigações Trabalhistas e Previdenciárias | J22: =IF(ISERROR(Pasn!J10),"",Pasn!J10) -> 0 | K22: =IF(ISERROR(Pasn!K10),"",Pasn!K10) -> 0
C23: 2250 | D23: Imóveis para Locação ou Venda | E23: =IF(ISERROR(Atin!J11),"",Atin!J11) -> 0 | F23: =IF(ISERROR(Atin!K11),"",Atin!K11) -> 0 | H23: 4550 | I23: Obrigações Sociais e Estatutárias | J23: =IF(ISERROR(Pasn!J11),"",Pasn!J11) -> 0 | K23: =IF(ISERROR(Pasn!K11),"",Pasn!K11) -> 0
C24: 2290 | D24: Outras Contas do Realizável | E24: =IF(ISERROR(Atin!J12),"",Atin!J12) -> 0 | F24: =IF(ISERROR(Atin!K12),"",Atin!K12) -> 0 | H24: 4560 | I24: Créditos de Coligadas e Controladas | J24: =IF(ISERROR(Pasn!J12),"",Pasn!J12) -> 0 | K24: =IF(ISERROR(Pasn!K12),"",Pasn!K12) -> 0
C25: 2310 | D25: Investimentos | E25: =IF(ISERROR(Atin!J13),"",Atin!J13) -> 0 | F25: =IF(ISERROR(Atin!K13),"",Atin!K13) -> 0 | H25: 4570 | I25: Provisões para Contingências | J25: =IF(ISERROR(Pasn!J13),"",Pasn!J13) -> 0 | K25: =IF(ISERROR(Pasn!K13),"",Pasn!K13) -> 0
C26: 2320 | D26: Imobilizado de Uso | E26: =IF(ISERROR(Atin!J14),"",Atin!J14) -> 50000 | F26: =IF(ISERROR(Atin!K14),"",Atin!K14) -> 0.35335689 | H26: 4580 | I26: Receitas Diferidas | J26: =IF(ISERROR(Pasn!J14),"",Pasn!J14) -> 0 | K26: =IF(ISERROR(Pasn!K14),"",Pasn!K14) -> 0
C27: 2330 | D27: Ativo Diferido | E27: =IF(ISERROR(Atin!J15),"",Atin!J15) -> 18500 | F27: =IF(ISERROR(Atin!K15),"",Atin!K15) -> 0.13074205 | H27: 4590 | I27: Outras Obrigações | J27: =IF(ISERROR(Pasn!J15),"",Pasn!J15) -> 0 | K27: =IF(ISERROR(Pasn!K15),"",Pasn!K15) -> 0
C28: 2340 | D28: Intangível | E28: =IF(ISERROR(Atin!J16),"",Atin!J16) -> 20000 | F28: =IF(ISERROR(Atin!K16),"",Atin!K16) -> 0.14134276 | H28: 4610 | I28: Resultados de Exercícios Futuros - Receitas Diferidas | J28: =IF(ISERROR(Pasn!J16),"",Pasn!J16) -> 0 | K28: =IF(ISERROR(Pasn!K16),"",Pasn!K16) -> 0
C29: 2350 | D29: Imobilizado de Arrendamento (Leaseback) | E29: =IF(ISERROR(Atin!J17),"",Atin!J17) -> 0 | F29: =IF(ISERROR(Atin!K17),"",Atin!K17) -> 0 | H29: 4620 | I29: Custos e Despesas de Exercícios Futuros | J29: =IF(ISERROR(Pasn!J17),"",Pasn!J17) -> 0 | K29: =IF(ISERROR(Pasn!K17),"",Pasn!K17) -> 0
C30: 2360 | D30: Imobilizado Para Locação | E30: =IF(ISERROR(Atin!J18),"",Atin!J18) -> 0 | F30: =IF(ISERROR(Atin!K18),"",Atin!K18) -> 0 | H30: 5710 | I30: Capital / Capital Social / Patrimônio Social | J30: =IF(ISERROR(Pasn!J18),"",Pasn!J18) -> 120000 | K30: =IF(ISERROR(Pasn!K18),"",Pasn!K18) -> 0.50885838
... C33: 2390 | D33: Outros | E33: =IF(ISERROR(Atin!J21),"",Atin!J21) -> -12000 | F33: =IF(ISERROR(Atin!K21),"",Atin!K21) -> -0.084805654 | H33: 5740 | I33: Ajustes de Avaliação Patrimônial | J33: =IF(ISERROR(Pasn!J21),"",Pasn!J21) -> 0 | K33: =IF(ISERROR(Pasn!K21),"",Pasn!K21) -> 0
C34: Resultado | E34: =IF(ISERROR(SUM(E19:E33)),"",SUM(E19:E33)) -> 141500 | H34: 5750 | I34: Reservas de Lucros | J34: =IF(ISERROR(Pasn!J22),"",Pasn!J22) -> 64266 | K34: =IF(ISERROR(Pasn!K22),"",Pasn!K22) -> 0.2725191
H35: 5760 | I35: Reservas de Reavaliação | J35: =IF(ISERROR(Pasn!J23),"",Pasn!J23) -> 0 | K35: =IF(ISERROR(Pasn!K23),"",Pasn!K23) -> 0
C36: Resultado Total | H36: 5770 | I36: Outras Reservas | J36: =IF(ISERROR(Pasn!J24),"",Pasn!J24) -> 0 | K36: =IF(ISERROR(Pasn!K24),"",Pasn!K24) -> 0
C37: Ativo | E37: =IF(ISERROR(E34+E16),"",E34+E16) -> 294780 | H37: 5780 | I37: Lucros Acumulados / Sobras / Superávits | J37: =IF(ISERROR(Pasn!J25),"",Pasn!J25) -> 0 | K37: =IF(ISERROR(Pasn!K25),"",Pasn!K25) -> 0
C38: Passivo | E38: =IF(ISERROR(J16+J39),"",J16+J39) -> 294780 | H38: 5790 | I38: Prejuízos, Perdas e Déficits Acumulados | J38: =IF(ISERROR(Pasn!J26),"",Pasn!J26) -> 0 | K38: =IF(ISERROR(Pasn!K26),"",Pasn!K26) -> 0
C39: Resultado | E39: =IF(ISERROR(E37-E38),"",E37-E38) -> 0 | H39: Resultado | J39: =IF(ISERROR(SUM(J19:J38)),"",SUM(J19:J38)) -> 235822

Sheet Dre
C1: 2. DRE
C6: 6800 | D6: Contas de Resultado Credora (Receitas) | E6: =IF(ISERROR($E$7+$E$17+$E$27+$E$37+$E$47+$E$57+$E$67+$E$77+$E$87),"",$E$7+$E$17+$E$27+$E$37+$E$47+$E$57+$E$67+$E$77+$E$87) -> 408670 | H6: 6800 | I6: Contas de Resultado Credora (Receitas) - Resultado
C7: 6810 | D7: Receitas de Exportação | E7: =IF(ISERROR(SUM(E8:E16)),"",SUM(E8:E16)) -> 0 | H7: 6810 | I7: Receitas de Exportação | J7: =IF(ISERROR($E$7),"",$E$7) -> 0 | K7: =IF(ISERROR(J7/$L$7),"",J7/$L$7) -> 0 | L7: =IF(ISERROR(SUM($J$7:$J$15)),"",SUM($J$7:$J$15)) -> 408670
C8: 6811 | D8: Receita Bruta de Exportação | F8: =IF(ISERROR(E8/$E$7),"",E8/$E$7) | H8: 6820 | I8: Receita da Venda de Produtos | J8: =IF(ISERROR($E$17),"",$E$17) -> 408670 | K8: =IF(ISERROR(J8/$L$7),"",J8/$L$7) -> 1
C9: 6812 | D9: Deduções da Receita Bruta | F9: =IF(ISERROR(E9/$E$7),"",E9/$E$7) | H9: 6830 | I9: Receitas da Revenda de Mercadorias | J9: =IF(ISERROR($E$27),"",$E$27) -> 0 | K9: =IF(ISERROR(J9/$L$7),"",J9/$L$7) -> 0
C10: 6813 | F10: =IF(ISERROR(E10/$E$7),"",E10/$E$7) | H10: 6840 | I10: Receitas da Prestação de Serviços | J10: =IF(ISERROR($E$37),"",$E$37) -> 0 | K10: =IF(ISERROR(J10/$L$7),"",J10/$L$7) -> 0
C11: 6814 | F11: =IF(ISERROR(E11/$E$7),"",E11/$E$7) | H11: 6850 | I11: Receitas da Atividade Rural | J11: =IF(ISERROR($E$47),"",$E$47) -> 0 | K11: =IF(ISERROR(J11/$L$7),"",J11/$L$7) -> 0
C12: 6815 | D12: Outras Receitas Operacionais | F12: =IF(ISERROR(E12/$E$7),"",E12/$E$7) | H12: 6860 | I12: Receitas das Atividades de Educação e Saúde | J12: =IF(ISERROR($E$57),"",$E$57) -> 0 | K12: =IF(ISERROR(J12/$L$7),"",J12/$L$7) -> 0
C13: 6816 | D13: Receitas Não Operacionais | F13: =IF(ISERROR(E13/$E$7),"",E13/$E$7) | H13: 6870 | I13: Receitas das Atividades de Assistência Social | J13: =IF(ISERROR($E$67),"",$E$67) -> 0 | K13: =IF(ISERROR(J13/$L$7),"",J13/$L$7) -> 0
C14: 6817 | F14: =IF(ISERROR(E14/$E$7),"",E14/$E$7) | H14: 6880 | I14: Receitas das Atividades Imobiliárias | J14: =IF(ISERROR($E$77),"",$E$77) -> 0 | K14: =IF(ISERROR(J14/$L$7),"",J14/$L$7) -> 0
C15: 6818 | F15: =IF(ISERROR(E15/$E$7),"",E15/$E$7) | H15: 6890 | I15: Receitas das Atividades em Geral | J15: =IF(ISERROR($E$87),"",$E$87) -> 0 | K15: =IF(ISERROR(J15/$L$7),"",J15/$L$7) -> 0
C16: 6819 | F16: =IF(ISERROR(E16/$E$7),"",E16/$E$7)
C17: 6820 | D17: Receita da Venda de Produtos | E17: =IF(ISERROR(SUM(E18:E26)),"",SUM(E18:E26)) -> 408670 | H17: Valor Total das Contas de Resultado Credora (Receitas)
C18: 6821 | D18: Receita Bruta da Venda de Produtos | E18: 420120 | F18: =IF(ISERROR(E18/$E$17),"",E18/$E$17) -> 1.0280177 | H18: Resultado | J18: =IF(ISERROR(SUM($J$7:$J$15)),"",SUM($J$7:$J$15)) -> 408670
C19: 6822 | D19: Deduções da Receita Bruta | F19: =IF(ISERROR(E19/$E$17),"",E19/$E$17) -> 0
C20: 6823 | D20: (-) Abatimentos | E20: -6580 | F20: =IF(ISERROR(E20/$E$17),"",E20/$E$17) -> -0.016101011
C21: 6824 | D21: (-) Devolução de Vendas | E21: -4870 | F21: =IF(ISERROR(E21/$E$17),"",E21/$E$17) -> -0.011916705
C22: 6825 | F22: =IF(ISERROR(E22/$E$17),"",E22/$E$17) -> 0
C23: 6826 | F23: =IF(ISERROR(E23/$E$17),"",E23/$E$17) -> 0
C24: 6827 | F24: =IF(ISERROR(E24/$E$17),"",E24/$E$17) -> 0
C25: 6828 | D25: Outras Receitas Operacionais | F25: =IF(ISERROR(E25/$E$17),"",E25/$E$17) -> 0
C26: 6829 | D26: Receitas Não Operacionais | F26: =IF(ISERROR(E26/$E$17),"",E26/$E$17) -> 0
C27: 6830 | D27: Receitas da Revenda de Mercadorias | E27: =IF(ISERROR(SUM(E28:E36)),"",SUM(E28:E36)) -> 0
C28: 6831 | D28: Receita Bruta da Venda de Mercadorias | F28: =IF(ISERROR(E28/$E$27),"",E28/$E$27)
C29: 6832 | F29: =IF(ISERROR(E29/$E$27),"",E29/$E$27)
C30: 6833 | D30: Deduções da Receita Bruta | F30: =IF(ISERROR(E30/$E$27),"",E30/$E$27)
C31: 6834 | F31: =IF(ISERROR(E31/$E$27),"",E31/$E$27)
C32: 6835 | F32: =IF(ISERROR(E32/$E$27),"",E32/$E$27)
C33: 6836 | D33: Outras Receitas Operacionais | F33: =IF(ISERROR(E33/$E$27),"",E33/$E$27)
C34: 6837 | F34: =IF(ISERROR(E34/$E$27),"",E34/$E$27)
C35: 6838 | F35: =IF(ISERROR(E35/$E$27),"",E35/$E$27)
C36: 6839 | D36: Receitas Não Operacionais | F36: =IF(ISERROR(E36/$E$27),"",E36/$E$27)
C37: 6840 | D37: Receitas da Prestação de Serviços | E37: =IF(ISERROR(SUM(E38:E46)),"",SUM(E38:E46)) -> 0
C38: 6841 | D38: Receita Bruta de Serviços Prestados | F38: =IF(ISERROR(E38/$E$37),"",E38/$E$37)
C39: 6842 | F39: =IF(ISERROR(E39/$E$37),"",E39/$E$37)
C40: 6843 | F40: =IF(ISERROR(E40/$E$37),"",E40/$E$37)
C41: 6844 | F41: =IF(ISERROR(E41/$E$37),"",E41/$E$37)
C42: 6845 | F42: =IF(ISERROR(E42/$E$37),"",E42/$E$37)
C43: 6846 | F43: =IF(ISERROR(E43/$E$37),"",E43/$E$37)
C44: 6847 | D44: Deduções da Receita Bruta | F44: =IF(ISERROR(E44/$E$37),"",E44/$E$37)
...

Sheet Des
C1: 2. DRE
C6: 6900 | D6: Contas de Resultado Devedoras (Custos e Despesas) | E6: =IF(ISERROR($E$7+$E$17+$E$27+$E$37+$E$47+$E$57+$E$67+$E$77+$E$87),"",$E$7+$E$17+$E$27+$E$37+$E$47+$E$57+$E$67+$E$77+$E$87) -> 377534 | H6: 6900 | I6: Contas de Resultado Devedoras (Custos e Despesas) - Resultado
C7: 6910 | D7: Custos | E7: =IF(ISERROR(SUM(E8:E16)),"",SUM(E8:E16)) -> 350640 | H7: 6910 | I7: Custo | J7: =IF(ISERROR($E$7),"",$E$7) -> 350640 | K7: =IF(ISERROR(J7/$L$7),"",J7/$L$7) -> 0.92876403 | L7: =IF(ISERROR(SUM($J$7:$J$15)),"",SUM($J$7:$J$15)) -> 377534
C8: 6191 | D8: Custos dos Produtos de Fabricação Própria (Produzidos e Vendidos) | E8: 350640 | F8: =IF(ISERROR(E8/$E$7),"",E8/$E$7) -> 1 | H8: 6920 | I8: Despesa da Venda de Produtos | J8: =IF(ISERROR($E$17),"",$E$17) -> 10500 | K8: =IF(ISERROR(J8/$L$7),"",J8/$L$7) -> 0.027812065
C9: 6912 | F9: =IF(ISERROR(E9/$E$7),"",E9/$E$7) -> 0 | H9: 6930 | I9: Despesas da Revenda de Mercadorias | J9: =IF(ISERROR($E$27),"",$E$27) -> 0 | K9: =IF(ISERROR(J9/$L$7),"",J9/$L$7) -> 0
C10: 6913 | D10: Custo de Mercadorias Revendidades | F10: =IF(ISERROR(E10/$E$7),"",E10/$E$7) -> 0 | H10: 6940 | I10: Despesas da Prestação de Serviços | J10: =IF(ISERROR($E$37),"",$E$37) -> 0 | K10: =IF(ISERROR(J10/$L$7),"",J10/$L$7) -> 0
C11: 6914 | D11: Custo dos Serviços Prestados | F11: =IF(ISERROR(E11/$E$7),"",E11/$E$7) -> 0 | H11: 6950 | I11: Despesas da Atividade Rural | J11: =IF(ISERROR($E$47),"",$E$47) -> 0 | K11: =IF(ISERROR(J11/$L$7),"",J11/$L$7) -> 0
C12: 6915 | D12: Custa da Atividade Rural | F12: =IF(ISERROR(E12/$E$7),"",E12/$E$7) -> 0 | H12: 6960 | I12: Despesas das Atividades Ligadas à Educação e Saúde | J12: =IF(ISERROR($E$57),"",$E$57) -> 0 | K12: =IF(ISERROR(J12/$L$7),"",J12/$L$7) -> 0
C13: 6916 | D13: Custo dos Bens e Serviços para Educação e Saúde | F13: =IF(ISERROR(E13/$E$7),"",E13/$E$7) -> 0 | H13: 6970 | I13: Despesas de Atividades de Assistência Social | J13: =IF(ISERROR($E$67),"",$E$67) -> 0 | K13: =IF(ISERROR(J13/$L$7),"",J13/$L$7) -> 0
C14: 6917 | D14: Custo dos Bens e Serviços para Assisntência Social | F14: =IF(ISERROR(E14/$E$7),"",E14/$E$7) -> 0 | H14: 6980 | I14: Despesas das Atividades Imobiliárias | J14: =IF(ISERROR($E$77),"",$E$77) -> 0 | K14: =IF(ISERROR(J14/$L$7),"",J14/$L$7) -> 0
C15: 6918 | D15: Custo das Unidades Imobiliárias Vendidas | F15: =IF(ISERROR(E15/$E$7),"",E15/$E$7) -> 0 | H15: 6990 | I15: Despesas das Atividades em Geral | J15: =IF(ISERROR($E$87),"",$E$87) -> 16394 | K15: =IF(ISERROR(J15/$L$7),"",J15/$L$7) -> 0.043423904
C16: 6919 | D16: Custo dos Bens e Serviços para Demais Atividades | F16: =IF(ISERROR(E16/$E$7),"",E16/$E$7) -> 0
C17: 6920 | D17: Despesa da Venda de Produtos | E17: =IF(ISERROR(SUM(E18:E26)),"",SUM(E18:E26)) -> 10500 | H17: Contas de Resultado Devedoras (Custos e Despesas)
C18: 6921 | D18: Despesas Operacionais | E18: 10500 | F18: =IF(ISERROR(E18/$E$17),"",E18/$E$17) -> 1 | H18: Resultado | J18: =IF(ISERROR(SUM($J$7:$J$15)),"",SUM($J$7:$J$15)) -> 377534
C19: 6922 | F19: =IF(ISERROR(E19/$E$17),"",E19/$E$17) -> 0
C20: 6923 | F20: =IF(ISERROR(E20/$E$17),"",E20/$E$17) -> 0
C21: 6924 | D21: Outras Despesas Operacionais | F21: =IF(ISERROR(E21/$E$17),"",E21/$E$17) -> 0
C22: 6925 | D22: Despesas Não Operacionais | F22: =IF(ISERROR(E22/$E$17),"",E22/$E$17) -> 0
C23: 6926 | D23: Participações de Empregados | F23: =IF(ISERROR(E23/$E$17),"",E23/$E$17) -> 0
C24: 6927 | D24: Outras Participações | F24: =IF(ISERROR(E24/$E$17),"",E24/$E$17) -> 0
C25: 6928 | F25: =IF(ISERROR(E25/$E$17),"",E25/$E$17) -> 0
C26: 6929 | D26: Provisão para CSLL e IRPJ | F26: =IF(ISERROR(E26/$E$17),"",E26/$E$17) -> 0
C27: 6930 | D27: Despesas da Revenda de Mercadorias | E27: =IF(ISERROR(SUM(E28:E36)),"",SUM(E28:E36)) -> 0
C28: 6931 | D28: Despesas Operacionais | F28: =IF(ISERROR(E28/$E$27),"",E28/$E$27)
C29: 6932 | F29: =IF(ISERROR(E29/$E$27),"",E29/$E$27)
C30: 6933 | D30: Outras Despesas Operacionais | F30: =IF(ISERROR(E30/$E$27),"",E30/$E$27)
C31: 6934 | D31: Despesas Não Operacionais | F31: =IF(ISERROR(E31/$E$27),"",E31/$E$27)
C32: 6935 | F32: =IF(ISERROR(E32/$E$27),"",E32/$E$27)
C33: 6936 | D33: Participações de Empregados | F33: =IF(ISERROR(E33/$E$27),"",E33/$E$27)
C34: 6937 | D34: Outras Participações | F34: =IF(ISERROR(E34/$E$27),"",E34/$E$27)
C35: 6938 | F35: =IF(ISERROR(E35/$E$27),"",E35/$E$27)
C36: 6939 | D36: Provisão para CSLL e IRPJ | F36: =IF(ISERROR(E36/$E$27),"",E36/$E$27)
C37: 6940 | D37: Despesas da Prestação de Serviços | E37: =IF(ISERROR(SUM(E38:E46)),"",SUM(E38:E46)) -> 0
C38: 6941 | D38: Despesas Operacionais | F38: =IF(ISERROR(E38/$E$37),"",E38/$E$37)
C39: 6942 | F39: =IF(ISERROR(E39/$E$37),"",E39/$E$37)
C40: 6943 | D40: Outras Despesas Operacionais | F40: =IF(ISERROR(E40/$E$37),"",E40/$E$37)
C41: 6944 | F41: =IF(ISERROR(E41/$E$37),"",E41/$E$37)
C42: 6945 | D42: Despesas Não Operacionais | F42: =IF(ISERROR(E42/$E$37),"",E42/$E$37)
C43: 6946 | D43: Participações de Empregados | F43: =IF(ISERROR(E43/$E$37),"",E43/$E$37)
C44: 6947 | D44: Outras Participações | F44: =IF(ISERROR(E44/$E$37),"",E44/$E$37)
...

Sheet Res
C1: 2. DRE
C6: 6800 | D6: Contas de Resultado Credora (Receitas) - Resultado | H6: 6900 | I6: Contas de Resultado Devedoras (Custos e Despesas) - Resultado
C7: 6810 | D7: Receitas de Exportação | E7: =IF(ISERROR(Dre!J7),"",Dre!J7) -> 0 | F7: =IF(ISERROR(E7/$E$16),"",E7/$E$16) -> 0 | H7: 6910 | I7: Custo | J7: =IF(ISERROR(Des!J7),"",Des!J7) -> 350640 | K7: =IF(ISERROR(J7/$J$16),"",J7/$J$16) -> 0.92876403
C8: 6820 | D8: Receita da Venda de Produtos | E8: =IF(ISERROR(Dre!J8),"",Dre!J8) -> 408670 | F8: =IF(ISERROR(E8/$E$16),"",E8/$E$16) -> 1 | H8: 6920 | I8: Despesa da Venda de Produtos | J8: =IF(ISERROR(Des!J8),"",Des!J8) -> 10500 | K8: =IF(ISERROR(J8/$J$16),"",J8/$J$16) -> 0.027812065
C9: 6830 | D9: Receitas da Revenda de Mercadorias | E9: =IF(ISERROR(Dre!J9),"",Dre!J9) -> 0 | F9: =IF(ISERROR(E9/$E$16),"",E9/$E$16) -> 0 | H9: 6930 | I9: Despesas da Revenda de Mercadorias | J9: =IF(ISERROR(Des!J9),"",Des!J9) -> 0 | K9: =IF(ISERROR(J9/$J$16),"",J9/$J$16) -> 0
C10: 6840 | D10: Receitas da Prestação de Serviços | E10: =IF(ISERROR(Dre!J10),"",Dre!J10) -> 0 | F10: =IF(ISERROR(E10/$E$16),"",E10/$E$16) -> 0 | H10: 6940 | I10: Despesas da Prestação de Serviços | J10: =IF(ISERROR(Des!J10),"",Des!J10) -> 0 | K10: =IF(ISERROR(J10/$J$16),"",J10/$J$16) -> 0
C11: 6850 | D11: Receitas da Atividade Rural | E11: =IF(ISERROR(Dre!J11),"",Dre!J11) -> 0 | F11: =IF(ISERROR(E11/$E$16),"",E11/$E$16) -> 0 | H11: 6950 | I11: Despesas da Atividade Rural | J11: =IF(ISERROR(Des!J11),"",Des!J11) -> 0 | K11: =IF(ISERROR(J11/$J$16),"",J11/$J$16) -> 0
C12: 6860 | D12: Receitas das Atividades de Educação e Saúde | E12: =IF(ISERROR(Dre!J12),"",Dre!J12) -> 0 | F12: =IF(ISERROR(E12/$E$16),"",E12/$E$16) -> 0 | H12: 6960 | I12: Despesas das Atividades Ligadas à Educação e Saúde | J12: =IF(ISERROR(Des!J12),"",Des!J12) -> 0 | K12: =IF(ISERROR(J12/$J$16),"",J12/$J$16) -> 0
C13: 6870 | D13: Receitas das Atividades de Assistência Social | E13: =IF(ISERROR(Dre!J13),"",Dre!J13) -> 0 | F13: =IF(ISERROR(E13/$E$16),"",E13/$E$16) -> 0 | H13: 6970 | I13: Despesas de Atividades de Assistência Social | J13: =IF(ISERROR(Des!J13),"",Des!J13) -> 0 | K13: =IF(ISERROR(J13/$J$16),"",J13/$J$16) -> 0
C14: 6880 | D14: Receitas das Atividades Imobiliárias | E14: =IF(ISERROR(Dre!J14),"",Dre!J14) -> 0 | F14: =IF(ISERROR(E14/$E$16),"",E14/$E$16) -> 0 | H14: 6980 | I14: Despesas das Atividades Imobiliárias | J14: =IF(ISERROR(Des!J14),"",Des!J14) -> 0 | K14: =IF(ISERROR(J14/$J$16),"",J14/$J$16) -> 0
C15: 6890 | D15: Receitas das Atividades em Geral | E15: =IF(ISERROR(Dre!J15),"",Dre!J15) -> 0 | F15: =IF(ISERROR(E15/$E$16),"",E15/$E$16) -> 0 | H15: 6990 | I15: Despesas das Atividades em Geral | J15: =IF(ISERROR(Des!J15),"",Des!J15) -> 16394 | K15: =IF(ISERROR(J15/$J$16),"",J15/$J$16) -> 0.043423904
C16: Contas de Resultado Credora (Receitas) - Resultado | E16: =IF(ISERROR(SUM(E7:E15)),"",SUM(E7:E15)) -> 408670 | H16: Contas de Resultado Devedoras (Custos e Despesas) - Resultado | J16: =IF(ISERROR(SUM(J7:J15)),"",SUM(J7:J15)) -> 377534
C18: Demonstração do Resultado do Exercício (DRE)
C19: Contas de Resultado Credora (Receitas) | E19: =IF(ISERROR($E$16),"",$E$16) -> 408670 | F19: =IF(ISERROR($E$19/$G$19),"",$E$19/$G$19) -> 0.51980148 | G19: =IF(ISERROR(SUM(E19:E20)),"",SUM(E19:E20)) -> 786204
C20: Contas de Resultado Devedoras (Custos e Despesas) | E20: =IF(ISERROR($J$16),"",$J$16) -> 377534 | F20: =IF(ISERROR($E$19/$G$19),"",$E$19/$G$19) -> 0.51980148
C21: Resultado do Exercício | E21: =IF(ISERROR(E19-E20),"",E19-E20) -> 31136

Sheet Gra
C1: 4. GRÁFICOS
C6: 1 - ATIVO CIRCULANTE
C16: 1.1 - ATIVO NÃO CIRCULANTE
C26: 1.2 - PASSIVO CIRCULANTE
C36: 1.3 - PASSIVO NÃO CIRCULANTE
L37: Balanço Patrimônial
L38: =IF(ISERROR(Bal!$D$6),"",Bal!$D$6) -> Ativo Circulante (Bens e Direitos) | M38: =IF(ISERROR(Bal!$E$6),"",Bal!$E$6) -> 153280 | N38: =IF(ISERROR($M$38/$M$42),"",$M$38/$M$42) -> 0.2599905
L39: =IF(ISERROR(Atin!$D$6),"",Atin!$D$6) -> Ativo Não Circulante (Bens e Direitos) | M39: =IF(ISERROR(Atin!$E$6),"",Atin!$E$6) -> 141500 | N39: =IF(ISERROR($M$39/$M$42),"",$M$39/$M$42) -> 0.2400095
L40: =IF(ISERROR(Pas!$D$6),"",Pas!$D$6) -> Passivo Circulante (Deveres e Obrigações) | M40: =IF(ISERROR(Pas!$E$6),"",Pas!$E$6) -> 58958 | N40: =IF(ISERROR($M$40/$M$42),"",$M$40/$M$42) -> 0.10000339
L41: =IF(ISERROR(Pasn!$D$6),"",Pasn!$D$6) -> Passivo Não Circulante (Deveres e Obrigações) | M41: =IF(ISERROR(Pasn!$E$6),"",Pasn!$E$6) -> 235822 | N41: =IF(ISERROR($M$41/$M$42),"",$M$41/$M$42) -> 0.39999661
M42: =IF(ISERROR(SUM($M$38:$M$41)),"",SUM($M$38:$M$41)) -> 589560
C46: 1.4 - BALANÇO PATRIMÔNIAL
C56: 2 - RECEITAS - DRE
C66: 2.1 - DESPESAS (DRE)
C76: 2.2 - DEMONSTRAÇÃO DE RESULTADO DE EXERCÍCIO (DRE)

Sheet Ana
C1: 4. ALERTAS E DICAS
C6: Endividamento Geral ou Nível de Alavancagem | F6: =IF(ISERROR(SUM(F7:F9)),"",SUM(F7:F9)) -> 294780 | G6: Interpretação do índice | V6: =IF(ISERROR(SUM(V7:V8)),"",SUM(V7:V8)) -> 244780
C7: Passivo Circulante | D7: =IF(ISERROR(Pas!$E$6),"",Pas!$E$6) -> 58958 | E7: =IF(ISERROR($D$7/$F$6),"",$D$7/$F$6) -> 0.20000678 | F7: =IF(ISERROR(D7),"",D7) -> 58958 | G7: =IF($D$10<=1,"O PATRIMÔNIO LÍQUIDO será suficiente para a liquidação do Passivo","O PATRIMÔNIO LÍQUIDO não será suficiente para pagamento ou liquidação do Passivo") -> O PATRIMÔNIO LÍQUIDO será suficiente para a liquidação do Passivo | V7: =IF(ISERROR(D19),"",D19) -> 58958
C8: Exigível a Longo Prazo | D8: =IF(ISERROR(Pasn!$J$38),"",Pasn!$J$38) -> 50000 | E8: =IF(ISERROR($D$8/$F$6),"",$D$8/$F$6) -> 0.16961802 | F8: =IF(ISERROR(D8),"",D8) -> 50000 | V8: =IF(ISERROR(D20),"",D20) -> 185822
C9: Patrimônio Liquido | D9: =IF(ISERROR(Pasn!$J$55),"",Pasn!$J$55) -> 185822 | E9: =IF(ISERROR($D$9/$F$6),"",$D$9/$F$6) -> 0.6303752 | F9: =IF(ISERROR(D9),"",D9) -> 185822
C10: Resultado | D10: =IF(ISERROR(ROUND($F$10/$F$9,2)),"",ROUND($F$10/$F$9,2)) -> 0.59 | F10: =IF(ISERROR(SUM(F7:F8)),"",SUM(F7:F8)) -> 108958
C12: Endividamento Financeiro Versus Total | F12: =IF(ISERROR(SUM(F13:F15)),"",SUM(F13:F15)) -> 217916 | G12: Interpretação do índice
C13: Obrigações Financeiras | D13: =IF(ISERROR(Pas!$E$6+Pasn!$J$38),"",Pas!$E$6+Pasn!$J$38) -> 108958 | E13: =IF(ISERROR(D13/$F$12),"",D13/$F$12) -> 0.5 | F13: =IF(ISERROR($D$13),"",$D$13) -> 108958 | G13: =IF(ISERROR("Seu percentual de Passivo referente a dívidadas com estabelecimentos bancários no país e no exterior é de " & ($D$16)),"","Seu percentual de Passivo referente a dívidadas com estabelecimentos bancários no país e no exterior é de " & ($D$16)) -> Seu percentual de Passivo referente a dívidadas com estabelecimentos bancários no país e no exterior é de 1%
C14: Passivo Circulante | D14: =IF(ISERROR(Pas!$E$6),"",Pas!$E$6) -> 58958 | E14: =IF(ISERROR(D14/$F$12),"",D14/$F$12) -> 0.27055379 | F14: =IF(ISERROR($D$14),"",$D$14) -> 58958
C15: Exigível a Longo Prazo | D15: =IF(ISERROR(Pasn!$J$38),"",Pasn!$J$38) -> 50000 | E15: =IF(ISERROR(D15/$F$12),"",D15/$F$12) -> 0.22944621 | F15: =IF(ISERROR($D$15),"",$D$15) -> 50000
C16: Resultado | D16: =IF(ISERROR(ROUND($F$13/$F$16,2)&"%"),"",ROUND($F$13/$F$16,2)&"%") -> 1% | F16: =IF(ISERROR(SUM($F$14:$F$15)),"",SUM($F$14:$F$15)) -> 108958
C18: Endividamento de Curto Prazo | G18: Interpretação do índice
C19: Passivo Circulante | D19: =IF(ISERROR(Pas!$E$6),"",Pas!$E$6) -> 58958 | E19: =IF(ISERROR($D$19/$V$6),"",$D$19/$V$6) -> 0.24086118 | F19: =IF(ISERROR($D$19),"",$D$19) -> 58958 | G19: =IF($D$21<=1,"O PATRIMÔNIO LÍQUIDO será suficiente para a liquidação do Passivo Circulante; mediante o índice de ENDIVIDAMENTO GERAL poderá será apurada como ficará o nível de endividamento se houver saldo a pagar no grupamento EXIGÍVEL DE LONGO PRAZO","O PATRIMÔNIO LÍQUIDO será suficiente para pagamento ou liquidação do Passivo Circulante, ficando parte dele a descoberto; o eventual EXIGÍVEL DE LONGO PRAZO existente também ficará sem pagamento") -> O PATRIMÔNIO LÍQUIDO será suficiente para a liquidação do Passivo Circulante; mediante o índice de ENDIVIDAMENTO GERAL poderá será apurada como ficará o nível de endividamento se houver saldo a pagar no grupamento EXIGÍVEL DE LONGO PRAZO
C20: Patrimônio Líquido | D20: =IF(ISERROR(Pasn!$J$55),"",Pasn!$J$55) -> 185822 | E20: =IF(ISERROR($D$20/$V$6),"",$D$20/$V$6) -> 0.75913882 | F20: =IF(ISERROR($D$20),"",$D$20) -> 185822
C21: Resultado | D21: =IF(ISERROR(ROUND($F$19/$F$20,2)),"",ROUND($F$19/$F$20,2)) -> 0.32
C23: Endividamento Financeiro Versus Capital Próprio | F23: =IF(ISERROR(SUM(F24:F25)),"",SUM(F24:F25)) -> 294780 | G23: Interpretação do índice
C24: Obrigações Financeiras | D24: =IF(ISERROR(Pas!$E$6+Pasn!$J$38),"",Pas!$E$6+Pasn!$J$38) -> 108958 | E24: =IF(ISERROR($D$24/$F$23),"",$D$24/$F$23) -> 0.3696248 | F24: =IF(ISERROR($D$24),"",$D$24) -> 108958 | G24: =IF($D$26<=1,"O PATRIMÔNIO LÍQUIDO será suficiente para pagamento ou liquidação das Obrigações Financeiras","O PATRIMÔNIO LÍQUIDO (capital próprio) não será suficiente para pagamento ou liquidação das Obrigações Financeiras") -> O PATRIMÔNIO LÍQUIDO será suficiente para pagamento ou liquidação das Obrigações Financeiras
C25: Patrimônio Líquido | D25: =IF(ISERROR(Pasn!$J$55),"",Pasn!$J$55) -> 185822 | E25: =IF(ISERROR($D$25/$F$23),"",$D$25/$F$23) -> 0.6303752 | F25: =IF(ISERROR($D$25),"",$D$25) -> 185822
C26: Resultado | D26: =IF(ISERROR(ROUND($F$24/$F$25,2)),"",ROUND($F$24/$F$25,2)) -> 0.59
C28: Endividamento Financeiro de Curto Prazo Versus Ativo Circulante | F28: =IF(ISERROR(SUM(F29:F30)),"",SUM(F29:F30)) -> 212238 | G28: Interpretação do índice
C29: Obrigações Financeiras (Passivo Circulante) | D29: =IF(ISERROR(Pas!$E$6),"",Pas!$E$6) -> 58958 | E29: =IF(ISERROR($D$29/$F$28),"",$D$29/$F$28) -> 0.27779191 | F29: =IF(ISERROR($D$29),"",$D$29) -> 58958 | G29: =IF($D$31<=1,"O ATIVO CIRCULANTE será suficiente para pagamento ou liquidação das Obrigações Financeiras","O ATIVO CIRCULANTE (recebíveis de curto prazo) não será suficiente para pagamento ou liquidação das Obrigações Financeiras") -> O ATIVO CIRCULANTE será suficiente para pagamento ou liquidação das Obrigações Financeiras
C30: Ativo Circulante | D30: =IF(ISERROR(Bal!$E$6),"",Bal!$E$6) -> 153280 | E30: =IF(ISERROR($D$30/$F$28),"",$D$30/$F$28) -> 0.72220809 | F30: =IF(ISERROR($D$30),"",$D$30) -> 153280
C31: Resultado | D31: =IF(ISERROR(ROUND($F$29/$F$30,2)),"",ROUND($F$29/$F$30,2)) -> 0.38
C33: Nível de Desconto de Duplicatas | F33: =IF(ISERROR(SUM(F34:F35)),"",SUM(F34:F35)) -> 81240 | G33: Interpretação do índice
C34: Duplicatas Descontadas | D34: =IF(ISERROR(Pas!$J$7),"",(Pas!$J$7)) -> 31840 | E34: =IF(ISERROR(D34/$F$33),"",D34/$F$33) -> 0.39192516 | F34: =IF(ISERROR(D34),"",D34) -> 31840 | G34: =IF($D$31<=1,"O ATIVO CIRCULANTE será suficiente para pagamento ou liquidação das Obrigações Financeiras","O ATIVO CIRCULANTE (recebíveis de curto prazo) não será suficiente para pagamento ou liquidação das Obrigações Financeiras") -> O ATIVO CIRCULANTE será suficiente para pagamento ou liquidação das Obrigações Financeiras
C35: Duplicatas a Receber | D35: =IF(ISERROR(Bal!J11),"",Bal!J11) -> 49400 | E35: =IF(ISERROR(D35/$F$33),"",D35/$F$33) -> 0.60807484 | F35: =IF(ISERROR(D35),"",D35) -> 49400
C36: Resultado | D36: =IF(ISERROR(ROUND(F34/F35,2)),"",ROUND(F34/F35,2)) -> 0.64
C38: Imobilização do Patrimônio Líquido | F38: =IF(ISERROR(SUM($F$39:$F$40)),"",SUM($F$39:$F$40)) -> 262322 | G38: Interpretação do índice
C39: Ativo Permanente | D39: =IF(ISERROR(Atin!$J$42),"",Atin!$J$42) -> 76500 | E39: =IF(ISERROR($D$39/$F$38),"",$D$39/$F$38) -> 0.29162632 | F39: =IF(ISERROR($D$39),"",$D$39) -> 76500 | G39: =IF(ISERROR("O percentual do Patrimônio Líquido que se encontra aplicado no Ativo Permanente é de " & ($D$41)),"","O percentual do Patrimônio Líquido que se encontra aplicado no Ativo Permanente é de " & ($D$41)) -> O percentual do Patrimônio Líquido que se encontra aplicado no Ativo Permanente é de 0,41%
C40: Patrimônio Líquido | D40: =IF(ISERROR(Pasn!$J$55),"",Pasn!$J$55) -> 185822 | E40: =IF(ISERROR($D$40/$F$38),"",$D$40/$F$38) -> 0.70837368 | F40: =IF(ISERROR($D$40),"",$D$40) -> 185822
C41: Resultado | D41: =IF(ISERROR(ROUND($F$39/$F$40,2) &"%"),"",ROUND($F$39/$F$40,2) &"%") -> 0,41%

Sheet Cpd
C1: 4. ALERTAS E DICAS
C6: Liquidez Corrente | F6: =IF(ISERROR(SUM(F7:F8)),"",SUM(F7:F8)) -> 212238 | G6: Interpretação do índice
C7: Ativo Circulante | D7: =IF(ISERROR(Bal!$J$24),"",Bal!$J$24) -> 153280 | E7: =IF(ISERROR(F7/$F$6),"",F7/$F$6) -> 0.72220809 | F7: =IF(ISERROR(D7),"",D7) -> 153280 | G7: =IF($D$9>=1,"Significa que a entidade tem ou terá recursos financeiros suficientes para honrar seus compromissos de curto prazo (até um ano)","Significa que a entidade não tem ou não terá recursos financeiros para honrar seus compromissos de curto prazo (até um ano)") -> Significa que a entidade tem ou terá recursos financeiros suficientes para honrar seus compromissos de curto prazo (até um ano)
C8: Passivo Circulante | D8: =IF(ISERROR(Pas!$J$27),"",Pas!$J$27) -> 58958 | E8: =IF(ISERROR(F8/$F$6),"",F8/$F$6) -> 0.27779191 | F8: =IF(ISERROR(D8),"",D8) -> 58958
C9: Total de Liquidez Corrente | D9: =IF(ISERROR(ROUND(F7/F8,2)),"",ROUND(F7/F8,2)) -> 2.6
C11: Liquidez Imediata | F11: =IF(ISERROR(SUM(F12:F13)),"",SUM(F12:F13)) -> 116518 | G11: Interpretação do índice
