Workbook

Sheet ANEXO I
A6: CALCULO DO SIMPLES NACIONAL PARA 2018 - ANEXO I - COMÉRCIO
A8: ANEXO I - COMERCIO | B8: Receita Bruta em 12 Meses | E8: Alíquota | F8: Dedução | H8: RBM | I8: 67
B9: 1 | C9: 0 | D9: 180000 | E9: 0.04 | F9: 0 | H9: RBT12 | I9: 3005256.2
B10: 2 | C10: =D9+0.01 -> 180000.01 | D10: 360000 | E10: 0.073 | F10: 5940 | H10: Alíq nominal | I10: =IFERROR(VLOOKUP(I9,$C$9:$E14,3),"ISENTO") -> 0.143 | K10: Cálculo até 2017
B11: 3 | C11: =D10+0.01 -> 360000.01 | D11: 720000 | E11: 0.095 | F11: 13860 | H11: Dedução | I11: =IFERROR(VLOOKUP(I9,$C$9:$F$14,4),0) -> 87300 | K11: Aliquota | L11: Simples | M11: Variação
B12: 4 | C12: =D11+0.01 -> 720000.01 | D12: 1800000 | E12: 0.107 | F12: 22500 | H12: Alíq efetiva | I12: =IFERROR(ROUND((I9*I10-I11)/I9,4),"") -> 0.114 | K12: =IFERROR(VLOOKUP(I9,'Tabelas 2017'!$B$2:$M$21,4),"ISENTO") -> 0.1132 | L12: =I8*K12 -> 7.5844 | M12: =IFERROR(I13/L12-1,0) -> 0.0070671378
B13: 5 | C13: =D12+0.01 -> 1800000 | D13: 3600000 | E13: 0.143 | F13: 87300 | H13: Simples | I13: =IFERROR(I8*I12,"") -> 7.638
B14: 6 | C14: =D13+0.01 -> 3600000 | D14: 4800000 | E14: 0.19 | F14: 378000
B16: Percentual de Repartição dos Tributos (Anexo I)
B17: Faixa | C17: IRPJ | D17: CSLL | E17: Cofins | F17: PIS/Pasep | G17: CPP | H17: ICMS | I17: Total
B18: =IF($I$10=E9,1,0) -> 0 | C18: =IFERROR(IF(B18=1,$I$12*C27,0),"") -> 0 | D18: =IFERROR(IF(B18=1,$I$12*D27,0),"") -> 0 | E18: =IFERROR(IF(B18=1,$I$12*E27,0),"") -> 0 | F18: =IFERROR(IF(B18=1,$I$12*F27,0),"") -> 0 | G18: =IFERROR(IF(B18=1,$I$12*G27,0),0) -> 0 | H18: =IFERROR(IF(B18=1,$I$12*H27,0),"") -> 0 | I18: =SUM(C18:H18) -> 0
B19: =IF($I$10=E10,2,0) -> 0 | C19: =IF(B19=2,$I$12*C28,0) -> 0 | D19: =IF(B19=2,$I$12*D28,0) -> 0 | E19: =IF(B19=2,$I$12*E28,0) -> 0 | F19: =IF(B19=2,$I$12*F28,0) -> 0 | G19: =IF(B19=2,$I$12*G28,0) -> 0 | H19: =IF(B19=2,$I$12*H28,0) -> 0 | I19: =SUM(C19:H19) -> 0
B20: =IF($I$10=E11,3,0) -> 0 | C20: =IF(B20=3,$I$12*C29,0) -> 0 | D20: =IF(B20=3,$I$12*D29,0) -> 0 | E20: =IF(B20=3,$I$12*E29,0) -> 0 | F20: =IF(B20=3,$I$12*F29,0) -> 0 | G20: =IF(B20=3,$I$12*G29,0) -> 0 | H20: =IF(B20=3,$I$12*H29,0) -> 0 | I20: =SUM(C20:H20) -> 0
B21: =IF($I$10=E12,4,0) -> 0 | C21: =IF(B21=4,$I$12*C30,0) -> 0 | D21: =IF(B21=4,$I$12*D30,0) -> 0 | E21: =IF(B21=4,$I$12*E30,0) -> 0 | F21: =IF(B21=4,$I$12*F30,0) -> 0 | G21: =IF(B21=4,$I$12*G30,0) -> 0 | H21: =IF(B21=4,$I$12*H30,0) -> 0 | I21: =SUM(C21:H21) -> 0
B22: =IF($I$10=E13,5,0) -> 5 | C22: =IF(B22=5,$I$12*C31,0) -> 0.00627 | D22: =IF(B22=5,$I$12*D31,0) -> 0.00399 | E22: =IF(B22=5,$I$12*E31,0) -> 0.0145236 | F22: =IF(B22=5,$I$12*F31,0) -> 0.0031464 | G22: =IF(B22=5,$I$12*G31,0) -> 0.04788 | H22: =IF(B22=5,$I$12*H31,0) -> 0.03819 | I22: =SUM(C22:H22) -> 0.114
B23: =IF($I$10=E14,6,0) -> 0 | C23: =IF(B23=6,$I$12*C32,0) -> 0 | D23: =IF(B23=6,$I$12*D32,0) -> 0 | E23: =IF(B23=6,$I$12*E32,0) -> 0 | F23: =IF(B23=6,$I$12*F32,0) -> 0 | G23: =IF(B23=6,$I$12*G32,0) -> 0 | H23: =IF(B23=6,$I$12*H32,0) -> 0 | I23: =SUM(C23:H23) -> 0
C25: Percentual de Repartição dos Tributos (Anexo I)
C26: IRPJ | D26: CSLL | E26: Cofins | F26: PIS/Pasep | G26: CPP | H26: ICMS
C27: 0.055 | D27: 0.035 | E27: 0.1274 | F27: 0.0276 | G27: 0.415 | H27: 0.34
C28: 0.055 | D28: 0.035 | E28: 0.1274 | F28: 0.0276 | G28: 0.415 | H28: 0.34
C29: 0.055 | D29: 0.035 | E29: 0.1274 | F29: 0.0276 | G29: 0.42 | H29: 0.335
C30: 0.055 | D30: 0.035 | E30: 0.1274 | F30: 0.0276 | G30: 0.42 | H30: 0.335
C31: 0.055 | D31: 0.035 | E31: 0.1274 | F31: 0.0276 | G31: 0.42 | H31: 0.335
C32: 0.135 | D32: 0.1 | E32: 0.2827 | F32: 0.0613 | G32: 0.421 | H32: 0

Sheet ANEXO II
A6: CALCULO DO SIMPLES NACIONAL PARA 2018 - ANEXO II - INDUSTRIA
A8: ANEXO II - INDUSTRIA | B8: Receita Bruta em 12 Meses | E8: Alíquota | F8: Dedução | H8: RBM | I8: 0
B9: 1 | C9: 0 | D9: 180000 | E9: 0.045 | F9: 0 | H9: RBT12 | I9: 624708.32
B10: 2 | C10: =D9+0.01 -> 180000.01 | D10: 360000 | E10: 0.078 | F10: 5940 | H10: Alíq nominal | I10: =IFERROR(VLOOKUP(I9,$C$9:$E14,3),"ISENTO") -> 0.1 | K10: Cálculo até 2017
B11: 3 | C11: =D10+0.01 -> 360000.01 | D11: 720000 | E11: 0.1 | F11: 13860 | H11: Dedução | I11: =IFERROR(VLOOKUP(I9,$C$9:$F$14,4),0) -> 13860 | K11: Aliquota | L11: Simples | M11: Variação
B12: 4 | C12: =D11+0.01 -> 720000.01 | D12: 1800000 | E12: 0.112 | F12: 22500 | H12: Alíq efetiva | I12: =IFERROR(ROUND((I9*I10-I11)/I9,4),"") -> 0.0778 | K12: =IFERROR(VLOOKUP(I9,'Tabelas 2017'!$B$2:$M$21,6),"ISENTO") -> 0.0804 | L12: =I8*K12 -> 0 | M12: =IFERROR(I13/L12-1,0) -> 0
B13: 5 | C13: =D12+0.01 -> 1800000 | D13: 3600000 | E13: 0.147 | F13: 85500 | H13: Simples | I13: =IFERROR(I8*I12,"") -> 0
B14: 6 | C14: =D13+0.01 -> 3600000 | D14: 4800000 | E14: 0.3 | F14: 720000
B16: Percentual de Repartição dos Tributos (Anexo II)
B17: Faixa | C17: IRPJ | D17: CSLL | E17: Cofins | F17: PIS/Pasep | G17: CPP | H17: IPI | I17: ICMS | J17: Total
B18: =IF($I$10=E9,1,0) -> 0 | C18: =IFERROR(IF(B18=1,$I$12*C27,0),"") -> 0 | D18: =IFERROR(IF(B18=1,$I$12*D27,0),"") -> 0 | E18: =IFERROR(IF(B18=1,$I$12*E27,0),"") -> 0 | F18: =IFERROR(IF(B18=1,$I$12*F27,0),"") -> 0 | G18: =IFERROR(IF(B18=1,$I$12*G27,0),0) -> 0 | H18: =IFERROR(IF(B18=1,$I$12*H27,0),0) -> 0 | I18: =IFERROR(IF(B18=1,$I$12*I27,0),"") -> 0 | J18: =SUM(C18:I18) -> 0
B19: =IF($I$10=E10,2,0) -> 0 | C19: =IF(B19=2,$I$12*C28,0) -> 0 | D19: =IF(B19=2,$I$12*D28,0) -> 0 | E19: =IF(B19=2,$I$12*E28,0) -> 0 | F19: =IF(B19=2,$I$12*F28,0) -> 0 | G19: =IF(B19=2,$I$12*G28,0) -> 0 | H19: =IFERROR(IF(B19=2,$I$12*H28,0),0) -> 0 | I19: =IF(B19=2,$I$12*I28,0) -> 0 | J19: =SUM(C19:I19) -> 0
B20: =IF($I$10=E11,3,0) -> 3 | C20: =IF(B20=3,$I$12*C29,0) -> 0.004279 | D20: =IF(B20=3,$I$12*D29,0) -> 0.002723 | E20: =IF(B20=3,$I$12*E29,0) -> 0.00895478 | F20: =IF(B20=3,$I$12*F29,0) -> 0.00193722 | G20: =IF(B20=3,$I$12*G29,0) -> 0.029175 | H20: =IFERROR(IF(B20=3,$I$12*H29,0),0) -> 0.005835 | I20: =IF(B20=3,$I$12*I29,0) -> 0.024896 | J20: =SUM(C20:I20) -> 0.0778
B21: =IF($I$10=E12,4,0) -> 0 | C21: =IF(B21=4,$I$12*C30,0) -> 0 | D21: =IF(B21=4,$I$12*D30,0) -> 0 | E21: =IF(B21=4,$I$12*E30,0) -> 0 | F21: =IF(B21=4,$I$12*F30,0) -> 0 | G21: =IF(B21=4,$I$12*G30,0) -> 0 | H21: =IFERROR(IF(B21=4,$I$12*H30,0),0) -> 0 | I21: =IF(B21=4,$I$12*I30,0) -> 0 | J21: =SUM(C21:I21) -> 0
B22: =IF($I$10=E13,5,0) -> 0 | C22: =IF(B22=5,$I$12*C31,0) -> 0 | D22: =IF(B22=5,$I$12*D31,0) -> 0 | E22: =IF(B22=5,$I$12*E31,0) -> 0 | F22: =IF(B22=5,$I$12*F31,0) -> 0 | G22: =IF(B22=5,$I$12*G31,0) -> 0 | H22: =IFERROR(IF(B22=5,$I$12*H31,0),0) -> 0 | I22: =IF(B22=5,$I$12*I31,0) -> 0 | J22: =SUM(C22:I22) -> 0
B23: =IF($I$10=E14,6,0) -> 0 | C23: =IF(B23=6,$I$12*C32,0) -> 0 | D23: =IF(B23=6,$I$12*D32,0) -> 0 | E23: =IF(B23=6,$I$12*E32,0) -> 0 | F23: =IF(B23=6,$I$12*F32,0) -> 0 | G23: =IF(B23=6,$I$12*G32,0) -> 0 | H23: =IFERROR(IF(B23=6,$I$12*H32,0),0) -> 0 | I23: =IF(B23=6,$I$12*I32,0) -> 0 | J23: =SUM(C23:I23) -> 0
C25: Percentual de Repartição dos Tributos (Anexo II)
C26: IRPJ | D26: CSLL | E26: Cofins | F26: PIS/Pasep | G26: CPP | H26: IPI | I26: ICMS
C27: 0.055 | D27: 0.035 | E27: 0.1151 | F27: 0.0249 | G27: 0.375 | H27: 0.075 | I27: 0.32
C28: 0.055 | D28: 0.035 | E28: 0.1151 | F28: 0.0249 | G28: 0.375 | H28: 0.075 | I28: 0.32
C29: 0.055 | D29: 0.035 | E29: 0.1151 | F29: 0.0249 | G29: 0.375 | H29: 0.075 | I29: 0.32
C30: 0.055 | D30: 0.035 | E30: 0.1151 | F30: 0.0249 | G30: 0.375 | H30: 0.075 | I30: 0.32
C31: 0.055 | D31: 0.035 | E31: 0.1151 | F31: 0.0249 | G31: 0.375 | H31: 0.075 | I31: 0.32
C32: 0.085 | D32: 0.075 | E32: 0.2096 | F32: 0.0454 | G32: 0.235 | H32: 0.35 | I32: 0

Sheet ANEXO III
A6: CALCULO DO SIMPLES NACIONAL PARA 2018 - ANEXO III - SERVIÇOS
A8: ANEXO III - SERV não relacionados § 5º C art 18 LC 123. | B8: Receita Bruta em 12 Meses | E8: Alíquota | F8: Dedução | K8: RBM | L8: 0
B9: 1 | C9: 0 | D9: 180000 | E9: 0.06 | F9: 0 | H9: FS AC 12 | I9: 0 | K9: RBT12 | L9: 318042.26
B10: 2 | C10: =D9+0.01 -> 180000.01 | D10: 360000 | E10: 0.112 | F10: 9360 | H10: % RBT12 | I10: 28 | K10: Alíq nominal | L10: =IFERROR(IF(I10>=28,VLOOKUP(L9,$C$9:$E$14,3),VLOOKUP(L9,'ANEXO V'!$C$9:$E$14,3)),"") -> 0.112
B11: 3 | C11: =D10+0.01 -> 360000.01 | D11: 720000 | E11: 0.135 | F11: 17640 | H11: =IF(I10<28,"FS<28%","FS>=28%") -> FS>=28% | K11: Dedução | L11: =IF(I10>=28,VLOOKUP(L9,$C$9:$F$14,4),VLOOKUP(L9,'ANEXO V'!$C$9:$F$14,4)) -> 9360
B12: 4 | C12: =D11+0.01 -> 720000.01 | D12: 1800000 | E12: 0.16 | F12: 35640 | G12: =IF(I12="V", "(**)","") | H12: Anexo | I12: =IF(I10<28,"V","III") -> III | K12: Alíq efetiva | L12: =IFERROR(ROUND((L9*L10-L11)/L9,4),"") -> 0.0826
B13: 5 | C13: =D12+0.01 -> 1800000 | D13: 3600000 | E13: 0.21 | F13: 125640 | K13: Simples | L13: =IFERROR(L8*L12,"") -> 0
B14: 6 | C14: =D13+0.01 -> 3600000 | D14: 4800000 | E14: 0.33 | F14: 648000
K15: 225136.36
B16: Percentual de Repartição dos Tributos (Anexo III)
B17: Faixa | C17: IRPJ | D17: CSLL | E17: Cofins | F17: PIS/Pasep | G17: CPP | H17: ISS | I17: Total
B18: =IF(AND($L$10=E9,$I$12="III"),1,0) -> 0 | C18: =IFERROR(IF(B18=1,$L$12*C27,0),"") -> 0 | D18: =IFERROR(IF(B18=1,$L$12*D27,0),"") -> 0 | E18: =IFERROR(IF(B18=1,$L$12*E27,O),"") | F18: =IFERROR(IF(B18=1,$L$12*F27,0),"") -> 0 | G18: =IFERROR(IF(B18=1,$L$12*G27,0),"") -> 0 | H18: =IFERROR(IF(B18=1,$L$12*H27,0),"") -> 0 | I18: =SUM(C18:H18) -> 0
B19: =IF(AND($L$10=E10,$I$12="III"),2,0) -> 2 | C19: =IF(B19=2,$L$12*C28,0) -> 0.003304 | D19: =IF(B19=2,$L$12*D28,0) -> 0.002891 | E19: =IF(B19=2,$L$12*E28,0) -> 0.0116053 | F19: =IF(B19=2,$L$12*F28,0) -> 0.0025193 | G19: =IF(B19=2,$L$12*G28,0) -> 0.0358484 | H19: =IF(B19=2,$L$12*H28,0) -> 0.026432 | I19: =SUM(C19:H19) -> 0.0826
B20: =IF(AND($L$10=E11,$I$12="III"),3,0) -> 0 | C20: =IF(B20=3,$L$12*C29,0) -> 0 | D20: =IF(B20=3,$L$12*D29,0) -> 0 | E20: =IF(B20=3,$L$12*E29,0) -> 0 | F20: =IF(B20=3,$L$12*F29,0) -> 0 | G20: =IF(B20=3,$L$12*G29,0) -> 0 | H20: =IF(B20=3,$L$12*H29,0) -> 0 | I20: =SUM(C20:H20) -> 0
B21: =IF(AND($L$10=E12,$I$12="III"),4,0) -> 0 | C21: =IF(B21=4,$L$12*C30,0) -> 0 | D21: =IF(B21=4,$L$12*D30,0) -> 0 | E21: =IF(B21=4,$L$12*E30,0) -> 0 | F21: =IF(B21=4,$L$12*F30,0) -> 0 | G21: =IF(B21=4,$L$12*G30,0) -> 0 | H21: =IF(B21=4,$L$12*H30,0) -> 0 | I21: =SUM(C21:H21) -> 0
B22: =IF(AND($L$10=E13,$I$12="III"),5,0) -> 0 | C22: =IF(AND($B$22=5,$L$12<=14.92537%),$L$12*C31,($L$12-5%)*6.02%) -> 0.00196252 | D22: =IF(AND($B$22=5,$L$12<=14.92537%),$L$12*D31,($L$12-5%)*5.26%) -> 0.00171476 | E22: =IF(AND($B$22=5,$L$12<=14.92537%),$L$12*E31,($L$12-5%)*19.28%) -> 0.00628528 | F22: =IF(AND($B$22=5,$L$12<=14.92537%),$L$12*F31,($L$12-5%)*4.18%) -> 0.00136268 | G22: =IF(AND($B$22=5,$L$12<=14.92537%),$L$12*G31,($L$12-5%)*65.26%) -> 0.02127476 | H22: =IF(AND($B$22=5,$L$12<=14.92537%),$L$12*H31,5%) -> 0.05 | I22: =SUM(C22:H22) -> 0.0826
B23: =IF(AND($L$10=E14,$I$12="III"),6,0) -> 0 | C23: =IF(B23=6,$L$12*C32,0) -> 0 | D23: =IF(B23=6,$L$12*D32,0) -> 0 | E23: =IF(B23=6,$L$12*E32,0) -> 0 | F23: =IF(B23=6,$L$12*F32,0) -> 0 | G23: =IF(B23=6,$L$12*G32,0) -> 0 | H23: =IF(B23=6,$L$12*H32,0) -> 0 | I23: =SUM(C23:H23) -> 0
C25: Percentual de Repartição dos Tributos (Anexo III)
C26: IRPJ | D26: CSLL | E26: Cofins | F26: PIS/Pasep | G26: CPP | H26: ISS
C27: 0.04 | D27: 0.035 | E27: 0.1282 | F27: 0.0278 | G27: 0.434 | H27: 0.335
C28: 0.04 | D28: 0.035 | E28: 0.1405 | F28: 0.0305 | G28: 0.434 | H28: 0.32
C29: 0.04 | D29: 0.035 | E29: 0.1364 | F29: 0.0296 | G29: 0.434 | H29: 0.325
C30: 0.04 | D30: 0.035 | E30: 0.1364 | F30: 0.0296 | G30: 0.434 | H30: 0.325
C31: 0.04 | D31: 0.035 | E31: 0.1282 | F31: 0.0278 | G31: 0.434 | H31: 0.335 | I31: (*)
C32: 0.35 | D32: 0.15 | E32: 0.1603 | F32: 0.0347 | G32: 0.305 | H32: 0
B34: (*) O percentual efetivo máximo devido ao ISS será de 5%, transferindo-se a diferença, de forma proporcional, aos tributos federais da mesma faixa de receita bruta anual. Sendo assim, na 5a faixa, quando a alíquota efetiva for superior a 14,92537%, a repartição será:
B35: Faixa | C35: IRPJ | D35: CSLL | E35: Cofins | F35: PIS | G35: CPP | H35: ISS
B36: 5a Faixa, com alíquota efetiva superior a 14,92537% | C36: (Alíquota efetiva – 5%) x 6,02% | D36: (Alíquota efetiva – 5%) x 5,26% | E36: (Alíquota efetiva – 5%) x 19,28% | F36: Alíquota efetiva – 5%) x 4,18% | G36: Alíquota efetiva – 5%) x 65,26% | H36: fixo em 5%

Sheet ANEXO IV
A6: CALCULO DO SIMPLES NACIONAL PARA 2018 - ANEXO IV - SERVIÇOS COM CESSÃO DE MÃO DE OBRA
A8: ANEXO IV - SERV relacionados § 5º C art 18 LC 123. | B8: Receita Bruta em 12 Meses | E8: Alíquota | F8: Dedução | H8: RBM | I8: 0
B9: 1 | C9: 0 | D9: 180000 | E9: 0.045 | F9: 0 | H9: RBT12 | I9: 207252.16
B10: 2 | C10: =D9+0.01 -> 180000.01 | D10: 360000 | E10: 0.09 | F10: 8100 | H10: Alíq nominal | I10: =IFERROR(VLOOKUP(I9,$C$9:$E$14,3),"ISENTO") -> 0.09 | K10: Cálculo até 2017
B11: 3 | C11: =D10+0.01 -> 360000.01 | D11: 720000 | E11: 0.102 | F11: 12420 | H11: Dedução | I11: =IFERROR(VLOOKUP(I9,$C$9:$F$14,4),"ISENTO") -> 8100 | K11: Aliquota | L11: Simples | M11: Variação
B12: 4 | C12: =D11+0.01 -> 720000.01 | D12: 1800000 | E12: 0.14 | F12: 39780 | H12: Alíq efetiva | I12: =IFERROR(ROUND((I9*I10-I11)/I9,4),"") -> 0.0509 | K12: =IFERROR(VLOOKUP(I9,'Tabelas 2017'!$B$2:$M$21,10),"ISENTO") -> 0.0654 | L12: =I8*K12 -> 0 | M12: =IFERROR(I13/L12-1,"")
B13: 5 | C13: =D12+0.01 -> 1800000 | D13: 3600000 | E13: 0.22 | F13: 183780 | H13: Simples | I13: =IFERROR(I8*I12,"") -> 0
B14: 6 | C14: =D13+0.01 -> 3600000 | D14: 4800000 | E14: 0.33 | F14: 828000
B16: Percentual de Repartição dos Tributos (Anexo IV)
B17: Faixa | C17: IRPJ | D17: CSLL | E17: Cofins | F17: PIS/Pasep | G17: ISS | H17: Total
B18: =IF($I$10=E9,1,0) -> 0 | C18: =IFERROR(IF(B18=1,$I$12*C27,0),"") -> 0 | D18: =IFERROR(IF(B18=1,$I$12*D27,0),"") -> 0 | E18: =IFERROR(IF(B18=1,$I$12*E27,0),"") -> 0 | F18: =IFERROR(IF(B18=1,$I$12*F27,0),"") -> 0 | G18: =IFERROR(IF(B18=1,$I$12*G27,0),0) -> 0 | H18: =SUM(C18:G18) -> 0
B19: =IF($I$10=E10,2,0) -> 2 | C19: =IF(B19=2,$I$12*C28,0) -> 0.0100782 | D19: =IF(B19=2,$I$12*D28,0) -> 0.0077368 | E19: =IF(B19=2,$I$12*E28,0) -> 0.01045995 | F19: =IF(B19=2,$I$12*F28,0) -> 0.00226505 | G19: =IF(B19=2,$I$12*G28,0) -> 0.02036 | H19: =SUM(C19:G19) -> 0.0509
B20: =IF($I$10=E11,3,0) -> 0 | C20: =IF(B20=3,$I$12*C29,0) -> 0 | D20: =IF(B20=3,$I$12*D29,0) -> 0 | E20: =IF(B20=3,$I$12*E29,0) -> 0 | F20: =IF(B20=3,$I$12*F29,0) -> 0 | G20: =IF(B20=3,$I$12*G29,0) -> 0 | H20: =SUM(C20:G20) -> 0
B21: =IF($I$10=E12,4,0) -> 0 | C21: =IF(B21=4,$I$12*C30,0) -> 0 | D21: =IF(B21=4,$I$12*D30,0) -> 0 | E21: =IF(B21=4,$I$12*E30,0) -> 0 | F21: =IF(B21=4,$I$12*F30,0) -> 0 | G21: =IF(B21=4,$I$12*G30,0) -> 0 | H21: =SUM(C21:G21) -> 0
B22: =IF($I$10=E13,5,0) -> 0 | C22: =IF(AND($B$22=5,$I$12<=12.5%),$I$12*C31,($I$12-5%)*31.33%) -> 0.00028197 | D22: =IF(AND($B$22=5,$I$12<=12.5%),$I$12*D31,($I$12-5%)*32%) -> 0.000288 | E22: =IF(AND($B$22=5,$I$12<=12.5%),$I$12*E31,($I$12-5%)*30.13%) -> 0.00027117 | F22: =IF(AND($B$22=5,$I$12<=12.5%),$I$12*F31,($I$12-5%)*6.54%) -> 5.886e-05 | G22: =IF(AND($B$22=5,$I$12<=12.5%),$I$12*G31,5%) -> 0.05 | H22: =SUM(C22:G22) -> 0.0509
B23: =IF($I$10=E14,6,0) -> 0 | C23: =IF(B23=6,$I$12*C32,0) -> 0 | D23: =IF(B23=6,$I$12*D32,0) -> 0 | E23: =IF(B23=6,$I$12*E32,0) -> 0 | F23: =IF(B23=6,$I$12*F32,0) -> 0 | G23: =IF(B23=6,$I$12*G32,0) -> 0 | H23: =SUM(C23:G23) -> 0
C25: Percentual de Repartição dos Tributos (Anexo IV)
C26: IRPJ | D26: CSLL | E26: Cofins | F26: PIS/Pasep | G26: ISS
C27: 0.188 | D27: 0.152 | E27: 0.1767 | F27: 0.0383 | G27: 0.445
C28: 0.198 | D28: 0.152 | E28: 0.2055 | F28: 0.0445 | G28: 0.4
C29: 0.208 | D29: 0.152 | E29: 0.1973 | F29: 0.0427 | G29: 0.4
C30: 0.178 | D30: 0.192 | E30: 0.189 | F30: 0.041 | G30: 0.4
C31: 0.188 | D31: 0.192 | E31: 0.1808 | F31: 0.0392 | G31: 0.4 | H31: (*)
C32: 0.535 | D32: 0.215 | E32: 0.2055 | F32: 0.0445 | G32: 0
C34: (*) O percentual efetivo máximo devido ao ISS será de 5%, transferindo-se a diferença, de forma proporcional, aos tributos federais da mesma faixa de receita bruta anual. Sendo assim, na 5a faixa, quando a alíquota efetiva for superior a 12,5%, a repartição será:
C35: Faixa | D35: IRPJ | E35: CSLL | F35: Cofins | G35: PIS | H35: ISS
C36: 5a Faixa, com alíquota efetiva superior a 12,5% | D36: (Alíquota efetiva – 5%) x 31,33% | E36: (Alíquota efetiva – 5%) x 32% | F36: (Alíquota efetiva – 5%) x 30,13% | G36: Alíquota efetiva – 5%) x 6,54% | H36: fixo em 5%

Sheet ANEXO V
A6: CALCULO DO SIMPLES NACIONAL PARA 2018 - ANEXO V - SERVIÇOS PROFISSIONAIS
A8: ANEXO V - SERV relacionados § 5º I art 18 LC 123. | B8: Receita Bruta em 12 Meses | E8: Alíquota | F8: Dedução | K8: RBM | L8: 0
B9: 1 | C9: 0 | D9: 180000 | E9: 0.155 | F9: 0 | H9: FS 12 | I9: 0 | K9: RBT12 | L9: 150000
B10: 2 | C10: =D9+0.01 -> 180000.01 | D10: 360000 | E10: 0.18 | F10: 4500 | H10: % RBT12 | I10: =IFERROR(I9/L9%,"") -> 0 | K10: Alíq nominal | L10: =IF(I10>=28,VLOOKUP(L9,'ANEXO III'!$C$9:$E$14,3),VLOOKUP(L9,$C$9:$E$14,3)) -> 0.155
B11: 3 | C11: =D10+0.01 -> 360000.01 | D11: 720000 | E11: 0.195 | F11: 9900 | H11: =IF(I10<28,"FS<28%","FS>=28%") -> FS<28% | K11: Dedução | L11: =IF(I10>=28,VLOOKUP(L9,'ANEXO III'!$C$9:$F$14,4),VLOOKUP(L9,$C$9:$F$14,4)) -> 0
B12: 4 | C12: =D11+0.01 -> 720000.01 | D12: 1800000 | E12: 0.205 | F12: 17100 | G12: =IF(I12="III", "(**)","") | H12: Anexo | I12: =IF(I10<28,"V","III") -> V | K12: Alíq efetiva | L12: =IFERROR(ROUND((L9*L10-L11)/L9,4),) -> 0.155
B13: 5 | C13: =D12+0.01 -> 1800000 | D13: 3600000 | E13: 0.23 | F13: 62100 | K13: Simples | L13: =L8*L12 -> 0
B14: 6 | C14: =D13+0.01 -> 3600000 | D14: 4800000 | E14: 0.305 | F14: 540000
B16: Percentual de Repartição dos Tributos (Anexo V)
B17: Faixa | C17: IRPJ | D17: CSLL | E17: Cofins | F17: PIS/Pasep | G17: CPP | H17: ISS | I17: Total
B18: =IF(AND($L$10=E9,$I$12="V"),1,0) -> 1 | C18: =IFERROR(IF(B18=1,$L$12*C27,0),"") -> 0.03875 | D18: =IFERROR(IF(B18=1,$L$12*D27,0),"") -> 0.02325 | E18: =IFERROR(IF(B18=1,$L$12*E27,0),"") -> 0.021855 | F18: =IFERROR(IF(B18=1,$L$12*F27,0),"") -> 0.0047275 | G18: =IFERROR(IF(B18=1,$L$12*G27,0),"") -> 0.0447175 | H18: =IFERROR(IF(B18=1,$L$12*H27,0),"") -> 0.0217 | I18: =SUM(C18:H18) -> 0.155
B19: =IF(AND($L$10=E10,$I$12="V"),2,0) -> 0 | C19: =IF(B19=2,$L$12*C28,0) -> 0 | D19: =IF(B19=2,$L$12*D28,0) -> 0 | E19: =IF(B19=2,$L$12*E28,0) -> 0 | F19: =IF(B19=2,$L$12*F28,0) -> 0 | G19: =IF(B19=2,$L$12*G28,0) -> 0 | H19: =IF(B19=2,$L$12*H28,0) -> 0 | I19: =SUM(C19:H19) -> 0
B20: =IF(AND($L$10=E11,$I$12="V"),3,0) -> 0 | C20: =IF(B20=3,$L$12*C29,0) -> 0 | D20: =IF(B20=3,$L$12*D29,0) -> 0 | E20: =IF(B20=3,$L$12*E29,0) -> 0 | F20: =IF(B20=3,$L$12*F29,0) -> 0 | G20: =IF(B20=3,$L$12*G29,0) -> 0 | H20: =IF(B20=3,$L$12*H29,0) -> 0 | I20: =SUM(C20:H20) -> 0
B21: =IF(AND($L$10=E12,$I$12="V"),4,0) -> 0 | C21: =IF(B21=4,$L$12*C30,0) -> 0 | D21: =IF(B21=4,$L$12*D30,0) -> 0 | E21: =IF(B21=4,$L$12*E30,0) -> 0 | F21: =IF(B21=4,$L$12*F30,0) -> 0 | G21: =IF(B21=4,$L$12*G30,0) -> 0 | H21: =IF(B21=4,$L$12*H30,0) -> 0 | I21: =SUM(C21:H21) -> 0
B22: =IF(AND($L$10=E13,$I$12="V"),5,0) -> 0 | C22: =IF(B22=5,$L$12*C31,0) -> 0 | D22: =IF(B22=5,$L$12*D31,0) -> 0 | E22: =IF(B22=5,$L$12*E31,0) -> 0 | F22: =IF(B22=5,$L$12*F31,0) -> 0 | G22: =IF(B22=5,$L$12*G31,0) -> 0 | H22: =IF(B22=5,$L$12*H31,0) -> 0 | I22: =SUM(C22:H22) -> 0
B23: =IF(AND($L$10=E14,$I$12="V"),6,0) -> 0 | C23: =IF(B23=6,$L$12*C32,0) -> 0 | D23: =IF(B23=6,$L$12*D32,0) -> 0 | E23: =IF(B23=6,$L$12*E32,0) -> 0 | F23: =IF(B23=6,$L$12*F32,0) -> 0 | G23: =IF(B23=6,$L$12*G32,0) -> 0 | H23: =IF(B23=6,$L$12*H32,0) -> 0 | I23: =SUM(C23:H23) -> 0
C25: Percentual de Repartição dos Tributos (Anexo III)
C26: IRPJ | D26: CSLL | E26: Cofins | F26: PIS/Pasep | G26: CPP | H26: ISS
C27: 0.25 | D27: 0.15 | E27: 0.141 | F27: 0.0305 | G27: 0.2885 | H27: 0.14
C28: 0.23 | D28: 0.15 | E28: 0.141 | F28: 0.0305 | G28: 0.2785 | H28: 0.17
C29: 0.24 | D29: 0.15 | E29: 0.1492 | F29: 0.0323 | G29: 0.2385 | H29: 0.19
C30: 0.21 | D30: 0.15 | E30: 0.1574 | F30: 0.0341 | G30: 0.2385 | H30: 0.21
C31: 0.23 | D31: 0.125 | E31: 0.141 | F31: 0.0305 | G31: 0.2385 | H31: 0.235
C32: 0.35 | D32: 0.155 | E32: 0.1644 | F32: 0.0356 | G32: 0.295 | H32: 0

Sheet SUBLIMITES PARA ICMS E ISS
G1: 1
G2: 2
G3: 3
G4: 4
G5: 5
B6: FORMULA CONFORME ITEM 2 LETRA b INCISO I ARTIGO 24 DA RESOLUÇÃO CGSN 94/11
B7: Quando ultrapassa os R$ 3.600.000,00 no ano, mas não ultrapassa os R$ 4.800.000,00
B9: Sublimite | C9: 3600000
B10: Alíquota nominal 5º Faixa | C10: =IF(E10=1,'ANEXO I'!E13,IF(E10=2,'ANEXO II'!E13,IF(E10=3,'ANEXO III'!E13,IF(E10=4,'ANEXO IV'!E13,IF(E10=5,'ANEXO V'!E13,0))))) -> 0.22 | D10: Opção do anexo => | E10: 4
B11: Multiplicação | C11: =C9*C10 -> 792000
B12: Parcela a deduzir da 5º Faixa | C12: =IF(E10=1,'ANEXO I'!F13,IF(E10=2,'ANEXO II'!F13,IF(E10=3,'ANEXO III'!F13,IF(E10=4,'ANEXO IV'!F13,IF(E10=5,'ANEXO V'!F13,0))))) -> 183780
B13: Subtração | C13: =C11-C12 -> 608220
B14: Sublimite | C14: =C9 -> 3600000
B15: Divisão | C15: =C13/C14 -> 0.16895
B16: Percentual de distribuição da 5º Faixa ICMS ou ISS | C16: 0.335
B17: Aliquota efetiva | C17: =C15*C16 -> 0.05659825
B18: Receita Bruta total mensal que ultrapassou o limite | C18: 0
B19: ICMS a recolher do excesso | C19: =C18*C17 -> 0
B21: OBS 1: Será feito 2 calculos o primeiro quanto ao método convencional tributando o valor total da receita na 6º faixa com os 19%
B22: e o segundo método é o demonstrado acima, somente referente ao ICMS ou ISS
B24: OBS 2: Quando o percentual efetivo do ISS for superior a 5%, o resultado limitar-se-á a 5%, transferindo-se a diferença
B25: para os tributos federais, de forma proporcional aos percentuais de cada tributo.
B29: FORMULA CONFORME LETRA "A" INCISO II ARTIGO 24 DA RESOLUÇÃO CGSN 94/11
B30: Quando ultrapassar os R$ 4.800.000,00 Tributos Federais
B32: Sublimite | C32: 4800000
B33: Alíquota nominal 6º Faixa | C33: =IF(E33=1,'ANEXO I'!E14,IF(E33=2,'ANEXO II'!E14,IF(E33=3,'ANEXO III'!E14,IF(E33=4,'ANEXO IV'!E14,IF(E33=5,'ANEXO V'!E14,0))))) -> 0.19 | D33: Opção do anexo => | E33: 1
B34: Multiplicação | C34: =C32*C33 -> 912000
B35: Parcela a deduzir da 6º Faixa | C35: =IF(E33=1,'ANEXO I'!F14,IF(E33=2,'ANEXO II'!F14,IF(E33=3,'ANEXO III'!F14,IF(E33=4,'ANEXO IV'!F14,IF(E33=5,'ANEXO V'!F14,0))))) -> 378000
B36: Subtração | C36: =C34-C35 -> 534000
B37: Sublimite | C37: =C32 -> 4800000 | D37: Receita Bruta total mensal que ultrapassou o limite
B38: Divisão | C38: =C36/C37 -> 0.11125 | D38: 0
B39: Percentual de distribuição da 6º Faixa - IRPJ | C39: =IF(E33=1,'ANEXO I'!C32,IF(E33=2,'ANEXO II'!C32,IF(E33=3,'ANEXO III'!C32,IF(E33=4,'ANEXO IV'!C32,IF(E33=5,'ANEXO V'!C32,0))))) -> 0.135
B40: Aliquota efetiva | C40: =$C$38*C39 -> 0.01501875 | D40: =$D$38*C40 -> 0 | E40: IRPJ
B41: Percentual de distribuição da 6º Faixa - CSLL | C41: =IF(E33=1,'ANEXO I'!D32,IF(E33=2,'ANEXO II'!D32,IF(E33=3,'ANEXO III'!D32,IF(E33=4,'ANEXO IV'!D32,IF(E33=5,'ANEXO V'!D32,0))))) -> 0.1
B42: Aliquota efetiva | C42: =$C$38*C41 -> 0.011125 | D42: =$D$38*C42 -> 0 | E42: CSLL
B43: Percentual de distribuição da 6º Faixa - COFINS | C43: =IF(E33=1,'ANEXO I'!E32,IF(E33=2,'ANEXO II'!E32,IF(E33=3,'ANEXO III'!E32,IF(E33=4,'ANEXO IV'!E32,IF(E33=5,'ANEXO V'!E32,0))))) -> 0.2827
B44: Aliquota efetiva | C44: =$C$38*C43 -> 0.031450375 | D44: =$D$38*C44 -> 0 | E44: COFINS
B45: Percentual de distribuição da 6º Faixa - PIS | C45: =IF(E33=1,'ANEXO I'!F32,IF(E33=2,'ANEXO II'!F32,IF(E33=3,'ANEXO III'!F32,IF(E33=4,'ANEXO IV'!F32,IF(E33=5,'ANEXO V'!F32,0))))) -> 0.0613
B46: Aliquota efetiva | C46: =$C$38*C45 -> 0.006819625 | D46: =$D$38*C46 -> 0 | E46: PIS
B47: Percentual de distribuição da 6º Faixa - CPP | C47: =IF(E33=1,'ANEXO I'!G32,IF(E33=2,'ANEXO II'!G32,IF(E33=3,'ANEXO III'!G32,IF(E33=4,'ANEXO IV'!G32,IF(E33=5,'ANEXO V'!G32,0))))) -> 0.421
...

Sheet Tabelas 2017
A1: Faixa | B1: Receita bruta 12 meses anteriores | E1: Anexo I Comércio | G1: Anexo II Indústria | I1: Anexo III Serviços | K1: Anexo IV Serviços | M1: Anexo VI Serviços
A2: 1 | B2: 0 | C2: 180000 | E2: ='[1]LC123 2007'!D3 -> 0.04 | G2: ='[1]LC123 2007'!M3 -> 0.045 | I2: ='[1]LC123 2007'!D26 -> 0.06 | K2: ='[1]LC123 2007'!M26 -> 0.045 | M2: 0.1693
A3: =A2+1 -> 2 | B3: =C2+0.01 -> 180000.01 | C3: =C$2*2 -> 360000 | E3: ='[1]LC123 2007'!D4 -> 0.0547 | G3: ='[1]LC123 2007'!M4 -> 0.0597 | I3: ='[1]LC123 2007'!D27 -> 0.0821 | K3: ='[1]LC123 2007'!M27 -> 0.0654 | M3: 0.1772
A4: =A3+1 -> 3 | B4: =C3+0.01 -> 360000.01 | C4: =C3+C$2 -> 540000 | E4: ='[1]LC123 2007'!D5 -> 0.0684 | G4: ='[1]LC123 2007'!M5 -> 0.0734 | I4: ='[1]LC123 2007'!D28 -> 0.1026 | K4: ='[1]LC123 2007'!M28 -> 0.077 | M4: 0.1843
A5: =A4+1 -> 4 | B5: =C4+0.01 -> 540000.01 | C5: =C4+C$2 -> 720000 | E5: ='[1]LC123 2007'!D6 -> 0.0754 | G5: ='[1]LC123 2007'!M6 -> 0.0804 | I5: ='[1]LC123 2007'!D29 -> 0.1131 | K5: ='[1]LC123 2007'!M29 -> 0.0849 | M5: 0.1877
A6: =A5+1 -> 5 | B6: =C5+0.01 -> 720000.01 | C6: =C5+C$2 -> 900000 | E6: ='[1]LC123 2007'!D7 -> 0.076 | G6: ='[1]LC123 2007'!M7 -> 0.081 | I6: ='[1]LC123 2007'!D30 -> 0.114 | K6: ='[1]LC123 2007'!M30 -> 0.0897 | M6: 0.1904
A7: =A6+1 -> 6 | B7: =C6+0.01 -> 900000.01 | C7: =C6+C$2 -> 1080000 | E7: ='[1]LC123 2007'!D8 -> 0.0828 | G7: ='[1]LC123 2007'!M8 -> 0.0878 | I7: ='[1]LC123 2007'!D31 -> 0.1242 | K7: ='[1]LC123 2007'!M31 -> 0.0978 | M7: 0.1994
A8: =A7+1 -> 7 | B8: =C7+0.01 -> 1080000 | C8: =C7+C$2 -> 1260000 | E8: ='[1]LC123 2007'!D9 -> 0.0836 | G8: ='[1]LC123 2007'!M9 -> 0.0886 | I8: ='[1]LC123 2007'!D32 -> 0.1254 | K8: ='[1]LC123 2007'!M32 -> 0.1026 | M8: 0.2034
A9: =A8+1 -> 8 | B9: =C8+0.01 -> 1260000 | C9: =C8+C$2 -> 1440000 | E9: ='[1]LC123 2007'!D10 -> 0.0845 | G9: ='[1]LC123 2007'!M10 -> 0.0895 | I9: ='[1]LC123 2007'!D33 -> 0.1268 | K9: ='[1]LC123 2007'!M33 -> 0.1076 | M9: 0.2066
A10: =A9+1 -> 9 | B10: =C9+0.01 -> 1440000 | C10: =C9+C$2 -> 1620000 | E10: ='[1]LC123 2007'!D11 -> 0.0903 | G10: ='[1]LC123 2007'!M11 -> 0.0953 | I10: ='[1]LC123 2007'!D34 -> 0.1355 | K10: ='[1]LC123 2007'!M34 -> 0.1151 | M10: 0.2117
A11: =A10+1 -> 10 | B11: =C10+0.01 -> 1620000 | C11: =C10+C$2 -> 1800000 | E11: ='[1]LC123 2007'!D12 -> 0.0912 | G11: ='[1]LC123 2007'!M12 -> 0.0962 | I11: ='[1]LC123 2007'!D35 -> 0.1368 | K11: ='[1]LC123 2007'!M35 -> 0.12 | M11: 0.2138
A12: =A11+1 -> 11 | B12: =C11+0.01 -> 1800000 | C12: =C11+C$2 -> 1980000 | E12: ='[1]LC123 2007'!D13 -> 0.0995 | G12: ='[1]LC123 2007'!M13 -> 0.1045 | I12: ='[1]LC123 2007'!D36 -> 0.1493 | K12: ='[1]LC123 2007'!M36 -> 0.128 | M12: 0.2186
A13: =A12+1 -> 12 | B13: =C12+0.01 -> 1980000 | C13: =C12+C$2 -> 2160000 | E13: ='[1]LC123 2007'!D14 -> 0.1004 | G13: ='[1]LC123 2007'!M14 -> 0.1054 | I13: ='[1]LC123 2007'!D37 -> 0.1506 | K13: ='[1]LC123 2007'!M37 -> 0.1325 | M13: 0.2197
A14: =A13+1 -> 13 | B14: =C13+0.01 -> 2160000 | C14: =C13+C$2 -> 2340000 | E14: ='[1]LC123 2007'!D15 -> 0.1013 | G14: ='[1]LC123 2007'!M15 -> 0.1063 | I14: ='[1]LC123 2007'!D38 -> 0.152 | K14: ='[1]LC123 2007'!M38 -> 0.137 | M14: 0.2206
A15: =A14+1 -> 14 | B15: =C14+0.01 -> 2340000 | C15: =C14+C$2 -> 2520000 | E15: ='[1]LC123 2007'!D16 -> 0.1023 | G15: ='[1]LC123 2007'!M16 -> 0.1073 | I15: ='[1]LC123 2007'!D39 -> 0.1535 | K15: ='[1]LC123 2007'!M39 -> 0.1415 | M15: 0.2214
... A21: =A20+1 -> 20 | B21: =C20+0.01 -> 3420000 | C21: =C20+C$2 -> 3600000 | E21: ='[1]LC123 2007'!D22 -> 0.1161 | G21: ='[1]LC123 2007'!M22 -> 0.1211 | I21: ='[1]LC123 2007'!D45 -> 0.1742 | K21: ='[1]LC123 2007'!M45 -> 0.1685 | M21: 0.2245
A23: Faixa | B23: Receita bruta 12 meses anteriores | E23: Anexo V Serviços (r)<0,10 | G23: Anexo V 0,10=< (r) e (r)<0,15 | I23: Anexo V 0,15=< (r) e (r)<0,20 | K23: Anexo V 0,20=< (r) e (r)<0,25 | M23: Anexo V 0,25=<(r) e (r)<0,30 | O23: Anexo V 0,30=< (r) e (r)<0,35 | Q23: Anexo V 0,35=< (r) e (r)<0,40 | S23: Anexo V Serviços (r)>=0,40
A24: 1 | B24: Até | C24: 180000 | E24: 0.175 | G24: 0.157 | I24: 0.137 | K24: 0.1182 | M24: 0.1047 | O24: 0.0997 | Q24: 0.088 | S24: 0.08
A25: =A24+1 -> 2 | B25: =C24+0.01 -> 180000.01 | C25: =C$2*2 -> 360000 | E25: 0.1752 | G25: 0.1575 | I25: 0.139 | K25: 0.126 | M25: 0.1233 | O25: 0.1072 | Q25: 0.091 | S25: 0.0848
A26: =A25+1 -> 3 | B26: =C25+0.01 -> 360000.01 | C26: =C25+C$2 -> 540000 | E26: 0.1755 | G26: 0.1595 | I26: 0.142 | K26: 0.129 | M26: 0.1264 | O26: 0.1111 | Q26: 0.0958 | S26: 0.0903
A27: =A26+1 -> 4 | B27: =C26+0.01 -> 540000.01 | C27: =C26+C$2 -> 720000 | E27: 0.1795 | G27: 0.167 | I27: 0.15 | K27: 0.137 | M27: 0.1345 | O27: 0.12 | Q27: 0.1056 | S27: 0.0934
A28: =A27+1 -> 5 | B28: =C27+0.01 -> 720000.01 | C28: =C27+C$2 -> 900000 | E28: 0.1815 | G28: 0.1695 | I28: 0.153 | K28: 0.1403 | M28: 0.1353 | O28: 0.124 | Q28: 0.1104 | S28: 0.1006
A29: =A28+1 -> 6 | B29: =C28+0.01 -> 900000.01 | C29: =C28+C$2 -> 1080000 | E29: 0.1845 | G29: 0.172 | I29: 0.154 | K29: 0.141 | M29: 0.136 | O29: 0.126 | Q29: 0.116 | S29: 0.106
A30: =A29+1 -> 7 | B30: =C29+0.01 -> 1080000 | C30: =C29+C$2 -> 1260000 | E30: 0.1855 | G30: 0.173 | I30: 0.155 | K30: 0.1411 | M30: 0.1368 | O30: 0.1268 | Q30: 0.1168 | S30: 0.1068
A31: =A30+1 -> 8 | B31: =C30+0.01 -> 1260000 | C31: =C30+C$2 -> 1440000 | E31: 0.1862 | G31: 0.1732 | I31: 0.156 | K31: 0.1412 | M31: 0.1369 | O31: 0.1269 | Q31: 0.1169 | S31: 0.1069
A32: =A31+1 -> 9 | B32: =C31+0.01 -> 1440000 | C32: =C31+C$2 -> 1620000 | E32: 0.1872 | G32: 0.1742 | I32: 0.157 | K32: 0.1413 | M32: 0.1408 | O32: 0.1308 | Q32: 0.1208 | S32: 0.1108
A33: =A32+1 -> 10 | B33: =C32+0.01 -> 1620000 | C33: =C32+C$2 -> 1800000 | E33: 0.1886 | G33: 0.1756 | I33: 0.158 | K33: 0.1414 | M33: 0.1409 | O33: 0.1309 | Q33: 0.1209 | S33: 0.1109
A34: =A33+1 -> 11 | B34: =C33+0.01 -> 1800000 | C34: =C33+C$2 -> 1980000 | E34: 0.1896 | G34: 0.1766 | I34: 0.159 | K34: 0.1449 | M34: 0.1445 | O34: 0.1361 | Q34: 0.1278 | S34: 0.1187
A35: =A34+1 -> 12 | B35: =C34+0.01 -> 1980000 | C35: =C34+C$2 -> 2160000 | E35: 0.1906 | G35: 0.1776 | I35: 0.16 | K35: 0.1467 | M35: 0.1464 | O35: 0.1389 | Q35: 0.1315 | S35: 0.1228
A36: =A35+1 -> 13 | B36: =C35+0.01 -> 2160000 | C36: =C35+C$2 -> 2340000 | E36: 0.1926 | G36: 0.1796 | I36: 0.162 | K36: 0.1486 | M36: 0.1482 | O36: 0.1417 | Q36: 0.1351 | S36: 0.1268
A37: =A36+1 -> 14 | B37: =C36+0.01 -> 2340000 | C37: =C36+C$2 -> 2520000 | E37: 0.1956 | G37: 0.183 | I37: 0.165 | K37: 0.1546 | M37: 0.1518 | O37: 0.1461 | Q37: 0.1404 | S37: 0.1326
... A43: =A42+1 -> 20 | B43: =C42+0.01 -> 3420000 | C43: =C42+C$2 -> 3600000 | E43: 0.229 | G43: 0.218 | I43: 0.2 | K43: 0.186 | M43: 0.184 | O43: 0.1785 | Q43: 0.176 | S43: 0.1718
A44: r = Folha de salários + encargos nos 12 meses anteriores / Receita bruta total acumulada nos 12 meses anteriores
A45: Somar-se-á a alíquota do Simples Nacional relativa ao IRPJ, PIS/Pasep, CSLL, Cofins e CPP apurada na forma acima a parcela correspondente ao ISS prevista no Anexo IV.
A46: Sublimites até faixa 10 (AC, AP, RO e RR) até faixa 14 (MA, PA e TO), Resolução CGSN 130/2016, 06/12/2016.

Sheet Cálculo 2018
S1: 800000
S2: 0.112
S3: =S1*S2 -> 89600
S4: 22500
S5: =S3-S4 -> 67100
S6: 800000
S7: =S5/S6 -> 0.083875
S8: 30000
S9: =S8*S7 -> 2516.25
