Workbook

Sheet Ini
C1: PLANILHA DE CÁLCULO DE
C2: HORAS EXTRAS 3.5
C3: Seja bem-vindo(a). Com esta planilha você poderá analisar toda a folha de ponto do se funcionário. Invista suas energias em idéias que você sabe que serão viáveis!
C4: IMPORTANTE: LEIA OS PASSOS E ENTENDA A PLANILHA
C6: Passo 1 | E6: PREMISSAS GERAIS
C7: Este é o começo de tudo. É a parte de definição de todas as premissas de decadastro e perfis do funcionário.Contribui com todas bases de cálculo usadas adiante.
C9: Passo 2 | E9: LANÇAMENTOS
C10: Os Lançamentos são os locais onde você vai preencher o dia a dia do seu funcionário durante o mês.
C12: Passo 3 | E12: RESULTADOS CONSOLIDADOS
C13: A hora de retirar um relátório conciso e direto sobre os dados lançados. Nos resultados consolidados você têm um panorama de todo o mês. Uma indispensável ferramenta para tomada de decisões.
C15: Passo 4 | E15: GRÁFICOS
C16: Os gráficos são importantes para que sejam feitas avaliações sobre a situação do seu funcionário de uma forma simples e mais visual. Você poderá ver os gráficos de cada tipo de hora extra de maneira separada. Além de outras análises.
C18: Passo 5 | E18: ALERTAS E DICAS
C19: Esta planilha avaliará todos os dados preenchidos por você e retornará com dicas importantes para o seu segmento. Avaliando seu dia a dia, será mais fácil identificar se está fluindo da maneira correta, isso servirá para alertá-lo sobre possíveis problemas.
C21: Passo 6 | E21: RELATÓRIO PARA IMPRESSÃO
C22: Imprima somente o que importa. Esta parte gera um relatório formatado para impressão em páginas tamanho A4 com seu relatório e o panorama geral. Acompanha gráficos e as dicas importantes que a planilha fornece.
C24: Passo 7 | E24: FOLHA DE PONTO
C25: Imprima a folha de ponto mensal dos seus funcionários de maneira prática e econômica com apenas um clique. É rápido, é simples e é tudo que você precisava para adiantar seu dia a dia.

Sheet P Gerais
C1: 1. PREMISSAS GERAIS
C5: Configuração do período da planilha
C6: Ano corrente | I6: Mês corrente
C8: Salário mínimo vigente para esta categoria de funcionários
C9: Modelo de pagamento das horas extras
C10: Essas horas extras estão sendo pagas ou fará banco de horas?
C12: Acréscimo por cada hora extra (%)
C13: Dia de Semana | E13: Sábado | F13: Domingo | H13: DSR | I13: Feriados | K13: Periculosidade | L13: Insalubridade
C14: 0.5 | E14: 0.5 | F14: 1 | H14: 1 | I14: 1 | K14: 0.3 | L14: 1
C16: Interjornada (Iniciada antes das 11 horas de descanso) | I16: Intrajornada (Trabalho na hora de descanso/almoço)
C17: 1 | I17: 0.5
C19: Descrição dos funcionários

Sheet Departamentos
A1: 3.0.1 | C1: 1. PREMISSAS GERAIS
C5: Cadastro de departamentos

Sheet Funcionários
A1: 3.0.1 | C1: 1. PREMISSAS GERAIS
C5: Cadastro de funcionários | L5: Menu
C6: Funcionário | D6: Área | E6: Salário | F6: insalubridade | G6: periculosidade | L6: =IF(Departamentos!C6=0,"",Departamentos!C6)
F7: =IF(ISERROR(VLOOKUP($C7,Jornada!$C$8:$E$37,2,FALSE)),"",VLOOKUP($C7,Jornada!$C$8:$E$37,2,FALSE)) | G7: =IF(ISERROR(VLOOKUP($C7,Jornada!$C$8:$E$37,3,FALSE)),"",VLOOKUP($C7,Jornada!$C$8:$E$37,3,FALSE)) | H7: =IF(F7="Sim",E7*'P Gerais'!$L$14,0)+IF(G7="Sim",E7*'P Gerais'!$K$14,0) -> 0 | I7: =E7+H7 -> 0 | L7: =IF(Departamentos!C7=0,"",Departamentos!C7)
F8: =IF(ISERROR(VLOOKUP($C8,Jornada!$C$8:$E$37,2,FALSE)),"",VLOOKUP($C8,Jornada!$C$8:$E$37,2,FALSE)) | G8: =IF(ISERROR(VLOOKUP($C8,Jornada!$C$8:$E$37,3,FALSE)),"",VLOOKUP($C8,Jornada!$C$8:$E$37,3,FALSE)) | H8: =IF(F8="Sim",E8*'P Gerais'!$L$14,0)+IF(G8="Sim",E8*'P Gerais'!$K$14,0) -> 0 | I8: =E8+H8 -> 0 | L8: =IF(Departamentos!C8=0,"",Departamentos!C8)
F9: =IF(ISERROR(VLOOKUP($C9,Jornada!$C$8:$E$37,2,FALSE)),"",VLOOKUP($C9,Jornada!$C$8:$E$37,2,FALSE)) | G9: =IF(ISERROR(VLOOKUP($C9,Jornada!$C$8:$E$37,3,FALSE)),"",VLOOKUP($C9,Jornada!$C$8:$E$37,3,FALSE)) | H9: =IF(F9="Sim",E9*'P Gerais'!$L$14,0)+IF(G9="Sim",E9*'P Gerais'!$K$14,0) -> 0 | I9: =E9+H9 -> 0 | L9: =IF(Departamentos!C9=0,"",Departamentos!C9)
F10: =IF(ISERROR(VLOOKUP($C10,Jornada!$C$8:$E$37,2,FALSE)),"",VLOOKUP($C10,Jornada!$C$8:$E$37,2,FALSE)) | G10: =IF(ISERROR(VLOOKUP($C10,Jornada!$C$8:$E$37,3,FALSE)),"",VLOOKUP($C10,Jornada!$C$8:$E$37,3,FALSE)) | H10: =IF(F10="Sim",E10*'P Gerais'!$L$14,0)+IF(G10="Sim",E10*'P Gerais'!$K$14,0) -> 0 | I10: =E10+H10 -> 0 | L10: =IF(Departamentos!C10=0,"",Departamentos!C10)
F11: =IF(ISERROR(VLOOKUP($C11,Jornada!$C$8:$E$37,2,FALSE)),"",VLOOKUP($C11,Jornada!$C$8:$E$37,2,FALSE)) | G11: =IF(ISERROR(VLOOKUP($C11,Jornada!$C$8:$E$37,3,FALSE)),"",VLOOKUP($C11,Jornada!$C$8:$E$37,3,FALSE)) | H11: =IF(F11="Sim",E11*'P Gerais'!$L$14,0)+IF(G11="Sim",E11*'P Gerais'!$K$14,0) -> 0 | I11: =E11+H11 -> 0 | L11: =IF(Departamentos!C11=0,"",Departamentos!C11)
F12: =IF(ISERROR(VLOOKUP($C12,Jornada!$C$8:$E$37,2,FALSE)),"",VLOOKUP($C12,Jornada!$C$8:$E$37,2,FALSE)) | H12: =IF(F12="Sim",E12*'P Gerais'!$L$14,0)+IF(L13="Sim",E12*'P Gerais'!$K$14,0) -> 0 | I12: =E12+H12 -> 0 | L12: =IF(Departamentos!C12=0,"",Departamentos!C12)
F13: =IF(ISERROR(VLOOKUP($C13,Jornada!$C$8:$E$37,2,FALSE)),"",VLOOKUP($C13,Jornada!$C$8:$E$37,2,FALSE)) | H13: =IF(F13="Sim",E13*'P Gerais'!$L$14,0)+IF(L14="Sim",E13*'P Gerais'!$K$14,0) -> 0 | I13: =E13+H13 -> 0 | L13: =IF(Departamentos!C13=0,"",Departamentos!C13)
F14: =IF(ISERROR(VLOOKUP($C14,Jornada!$C$8:$E$37,2,FALSE)),"",VLOOKUP($C14,Jornada!$C$8:$E$37,2,FALSE)) | H14: =IF(F14="Sim",E14*'P Gerais'!$L$14,0)+IF(L15="Sim",E14*'P Gerais'!$K$14,0) -> 0 | I14: =E14+H14 -> 0 | L14: =IF(Departamentos!C14=0,"",Departamentos!C14)
F15: =IF(ISERROR(VLOOKUP($C15,Jornada!$C$8:$E$37,2,FALSE)),"",VLOOKUP($C15,Jornada!$C$8:$E$37,2,FALSE)) | H15: =IF(F15="Sim",E15*'P Gerais'!$L$14,0)+IF(L16="Sim",E15*'P Gerais'!$K$14,0) -> 0 | I15: =E15+H15 -> 0
F16: =IF(ISERROR(VLOOKUP($C16,Jornada!$C$8:$E$37,2,FALSE)),"",VLOOKUP($C16,Jornada!$C$8:$E$37,2,FALSE)) | H16: =IF(F16="Sim",E16*'P Gerais'!$L$14,0)+IF(L17="Sim",E16*'P Gerais'!$K$14,0) -> 0 | I16: =E16+H16 -> 0
F17: =IF(ISERROR(VLOOKUP($C17,Jornada!$C$8:$E$37,2,FALSE)),"",VLOOKUP($C17,Jornada!$C$8:$E$37,2,FALSE)) | H17: =IF(F17="Sim",E17*'P Gerais'!$L$14,0)+IF(L18="Sim",E17*'P Gerais'!$K$14,0) -> 0 | I17: =E17+H17 -> 0
F18: =IF(ISERROR(VLOOKUP($C18,Jornada!$C$8:$E$37,2,FALSE)),"",VLOOKUP($C18,Jornada!$C$8:$E$37,2,FALSE)) | H18: =IF(F18="Sim",E18*'P Gerais'!$L$14,0)+IF(L19="Sim",E18*'P Gerais'!$K$14,0) -> 0 | I18: =E18+H18 -> 0
F19: =IF(ISERROR(VLOOKUP($C19,Jornada!$C$8:$E$37,2,FALSE)),"",VLOOKUP($C19,Jornada!$C$8:$E$37,2,FALSE)) | H19: =IF(F19="Sim",E19*'P Gerais'!$L$14,0)+IF(L20="Sim",E19*'P Gerais'!$K$14,0) -> 0 | I19: =E19+H19 -> 0
F20: =IF(ISERROR(VLOOKUP($C20,Jornada!$C$8:$E$37,2,FALSE)),"",VLOOKUP($C20,Jornada!$C$8:$E$37,2,FALSE)) | H20: =IF(F20="Sim",E20*'P Gerais'!$L$14,0)+IF(L21="Sim",E20*'P Gerais'!$K$14,0) -> 0 | I20: =E20+H20 -> 0
F21: =IF(ISERROR(VLOOKUP($C21,Jornada!$C$8:$E$37,2,FALSE)),"",VLOOKUP($C21,Jornada!$C$8:$E$37,2,FALSE)) | H21: =IF(F21="Sim",E21*'P Gerais'!$L$14,0)+IF(L22="Sim",E21*'P Gerais'!$K$14,0) -> 0 | I21: =E21+H21 -> 0
F22: =IF(ISERROR(VLOOKUP($C22,Jornada!$C$8:$E$37,2,FALSE)),"",VLOOKUP($C22,Jornada!$C$8:$E$37,2,FALSE)) | H22: =IF(F22="Sim",E22*'P Gerais'!$L$14,0)+IF(L23="Sim",E22*'P Gerais'!$K$14,0) -> 0 | I22: =E22+H22 -> 0
F23: =IF(ISERROR(VLOOKUP($C23,Jornada!$C$8:$E$37,2,FALSE)),"",VLOOKUP($C23,Jornada!$C$8:$E$37,2,FALSE)) | H23: =IF(F23="Sim",E23*'P Gerais'!$L$14,0)+IF(L24="Sim",E23*'P Gerais'!$K$14,0) -> 0 | I23: =E23+H23 -> 0
F24: =IF(ISERROR(VLOOKUP($C24,Jornada!$C$8:$E$37,2,FALSE)),"",VLOOKUP($C24,Jornada!$C$8:$E$37,2,FALSE)) | H24: =IF(F24="Sim",E24*'P Gerais'!$L$14,0)+IF(L25="Sim",E24*'P Gerais'!$K$14,0) -> 0 | I24: =E24+H24 -> 0
F25: =IF(ISERROR(VLOOKUP($C25,Jornada!$C$8:$E$37,2,FALSE)),"",VLOOKUP($C25,Jornada!$C$8:$E$37,2,FALSE)) | H25: =IF(F25="Sim",E25*'P Gerais'!$L$14,0)+IF(L26="Sim",E25*'P Gerais'!$K$14,0) -> 0 | I25: =E25+H25 -> 0
F26: =IF(ISERROR(VLOOKUP($C26,Jornada!$C$8:$E$37,2,FALSE)),"",VLOOKUP($C26,Jornada!$C$8:$E$37,2,FALSE)) | H26: =IF(F26="Sim",E26*'P Gerais'!$L$14,0)+IF(L27="Sim",E26*'P Gerais'!$K$14,0) -> 0 | I26: =E26+H26 -> 0
... F36: =IF(ISERROR(VLOOKUP($C36,Jornada!$C$8:$E$37,2,FALSE)),"",VLOOKUP($C36,Jornada!$C$8:$E$37,2,FALSE)) | H36: =IF(F36="Sim",E36*'P Gerais'!$L$14,0)+IF(L37="Sim",E36*'P Gerais'!$K$14,0) -> 0 | I36: =E36+H36 -> 0

Sheet Jornada
C1: 1. PREMISSAS GERAIS
J4: Seg | L4: Ter | N4: Qua | P4: Qui | R4: Sex | T4: Sáb | V4: Dom
I5: Seg | K5: Ter | M5: Qua | O5: Qui | Q5: Sex | S5: Sáb | U5: Dom
I6: Segunda | K6: Terça | M6: Quarta | O6: Quinta | Q6: Sexta | S6: Sábado | U6: Domingo | X6: 0.25 | Z6: Jornada de trabalho | AN6: JORNADA
C7: Funcionário | D7: Insalubridade | E7: Periculosidade | F7: Horas acumuladas no banco de horas | G7: Extras ou Devidas | H7: Tempo de intervalo diário | I7: Início | J7: Fim | K7: Início | L7: Fim | M7: Início | N7: Fim | O7: Início | P7: Fim | Q7: Início | R7: Fim | S7: Início | T7: Fim | U7: Início | V7: Fim | X7: Seg | Y7: Ter | Z7: Qua | AA7: Qui | AB7: Sex | AC7: Sáb | AD7: Dom | AE7: Semanal | AF7: Mensal | AJ7: 0.25 | AK7: 0.625 | AN7: Seg | AO7: Ter | AP7: Qua | AQ7: Qui | AR7: Sex | AS7: Sáb | AT7: Dom
C8: =IF(Funcionários!C7=0,"",Funcionários!C7) | W8: 2 | X8: =IF(I8-J8=0,0,IF(I8>J8,"-",J8-I8-$H8)) -> 0 | Y8: =IF(K8-L8=0,0,IF(K8>L8,"-",L8-K8-$H8)) -> 0 | Z8: =IF(M8-N8=0,0,IF(M8>N8,"-",N8-M8-$H8)) -> 0 | AA8: =IF(O8-P8=0,0,IF(O8>P8,"-",P8-O8-$H8)) -> 0 | AB8: =IF(Q8-R8=0,0,IF(Q8>R8,"-",R8-Q8-$H8)) -> 0 | AC8: =IF(S8-T8=0,0,IF(S8>T8,"-",T8-S8-$H8)) -> 0 | AD8: =IF(U8-V8=0,0,IF(U8>V8,"-",V8-U8-$H8)) -> 0 | AE8: =ROUNDUP(24*(SUM(X8:AD8)),0) -> 0 | AF8: =AE8*5 -> 0 | AG8: =IF(C8="","",VLOOKUP(C8,Funcionários!$C$7:$D$36,2,0)) | AJ8: 0.29166667 | AK8: 0.66666667 | AN8: =IF(I8-J8=0,"",IF(I8>J8,"Erro","Ok")) | AO8: =IF(K8-L8=0,"",IF(K8>L8,"Erro","Ok")) | AP8: =IF(M8-N8=0,"",IF(M8>N8,"Erro","Ok")) | AQ8: =IF(O8-P8=0,"",IF(O8>P8,"Erro","Ok")) | AR8: =IF(Q8-R8=0,"",IF(Q8>R8,"Erro","Ok")) | AS8: =IF(S8-T8=0,"",IF(S8>T8,"Erro","Ok")) | AT8: =IF(U8-V8=0,"",IF(U8>V8,"Erro","Ok"))
C9: =IF(Funcionários!C8=0,"",Funcionários!C8) | W9: 3 | X9: =IF(I9-J9=0,0,IF(I9>J9,"-",J9-I9-$H9)) -> 0 | Y9: =IF(K9-L9=0,0,IF(K9>L9,"-",L9-K9-$H9)) -> 0 | Z9: =IF(M9-N9=0,0,IF(M9>N9,"-",N9-M9-$H9)) -> 0 | AA9: =IF(O9-P9=0,0,IF(O9>P9,"-",P9-O9-$H9)) -> 0 | AB9: =IF(Q9-R9=0,0,IF(Q9>R9,"-",R9-Q9-$H9)) -> 0 | AC9: =IF(S9-T9=0,0,IF(S9>T9,"-",T9-S9-$H9)) -> 0 | AD9: =IF(U9-V9=0,0,IF(U9>V9,"-",V9-U9-$H9)) -> 0 | AE9: =ROUNDUP(24*(SUM(X9:AD9)),0) -> 0 | AF9: =AE9*5 -> 0 | AG9: =IF(C9="","",VLOOKUP(C9,Funcionários!$C$7:$D$36,2,0)) | AJ9: 0.33333333 | AK9: 0.70833333 | AN9: =IF(I9-J9=0,"",IF(I9>J9,"Erro","Ok")) | AO9: =IF(K9-L9=0,"",IF(K9>L9,"Erro","Ok")) | AP9: =IF(M9-N9=0,"",IF(M9>N9,"Erro","Ok")) | AQ9: =IF(O9-P9=0,"",IF(O9>P9,"Erro","Ok")) | AR9: =IF(Q9-R9=0,"",IF(Q9>R9,"Erro","Ok")) | AS9: =IF(S9-T9=0,"",IF(S9>T9,"Erro","Ok")) | AT9: =IF(U9-V9=0,"",IF(U9>V9,"Erro","Ok"))
C10: =IF(Funcionários!C9=0,"",Funcionários!C9) | W10: 4 | X10: =IF(I10-J10=0,0,IF(I10>J10,"-",J10-I10-$H10)) -> 0 | Y10: =IF(K10-L10=0,0,IF(K10>L10,"-",L10-K10-$H10)) -> 0 | Z10: =IF(M10-N10=0,0,IF(M10>N10,"-",N10-M10-$H10)) -> 0 | AA10: =IF(O10-P10=0,0,IF(O10>P10,"-",P10-O10-$H10)) -> 0 | AB10: =IF(Q10-R10=0,0,IF(Q10>R10,"-",R10-Q10-$H10)) -> 0 | AC10: =IF(S10-T10=0,0,IF(S10>T10,"-",T10-S10-$H10)) -> 0 | AD10: =IF(U10-V10=0,0,IF(U10>V10,"-",V10-U10-$H10)) -> 0 | AE10: =ROUNDUP(24*(SUM(X10:AD10)),0) -> 0 | AF10: =AE10*5 -> 0 | AG10: =IF(C10="","",VLOOKUP(C10,Funcionários!$C$7:$D$36,2,0)) | AJ10: 0.375 | AK10: 0.75 | AN10: =IF(I10-J10=0,"",IF(I10>J10,"Erro","Ok")) | AO10: =IF(K10-L10=0,"",IF(K10>L10,"Erro","Ok")) | AP10: =IF(M10-N10=0,"",IF(M10>N10,"Erro","Ok")) | AQ10: =IF(O10-P10=0,"",IF(O10>P10,"Erro","Ok")) | AR10: =IF(Q10-R10=0,"",IF(Q10>R10,"Erro","Ok")) | AS10: =IF(S10-T10=0,"",IF(S10>T10,"Erro","Ok")) | AT10: =IF(U10-V10=0,"",IF(U10>V10,"Erro","Ok"))
C11: =IF(Funcionários!C10=0,"",Funcionários!C10) | W11: 5 | X11: =IF(I11-J11=0,0,IF(I11>J11,"-",J11-I11-$H11)) -> 0 | Y11: =IF(K11-L11=0,0,IF(K11>L11,"-",L11-K11-$H11)) -> 0 | Z11: =IF(M11-N11=0,0,IF(M11>N11,"-",N11-M11-$H11)) -> 0 | AA11: =IF(O11-P11=0,0,IF(O11>P11,"-",P11-O11-$H11)) -> 0 | AB11: =IF(Q11-R11=0,0,IF(Q11>R11,"-",R11-Q11-$H11)) -> 0 | AC11: =IF(S11-T11=0,0,IF(S11>T11,"-",T11-S11-$H11)) -> 0 | AD11: =IF(U11-V11=0,0,IF(U11>V11,"-",V11-U11-$H11)) -> 0 | AE11: =ROUNDUP(24*(SUM(X11:AD11)),0) -> 0 | AF11: =AE11*5 -> 0 | AG11: =IF(C11="","",VLOOKUP(C11,Funcionários!$C$7:$D$36,2,0)) | AJ11: 0.41666667 | AN11: =IF(I11-J11=0,"",IF(I11>J11,"Erro","Ok")) | AO11: =IF(K11-L11=0,"",IF(K11>L11,"Erro","Ok")) | AP11: =IF(M11-N11=0,"",IF(M11>N11,"Erro","Ok")) | AQ11: =IF(O11-P11=0,"",IF(O11>P11,"Erro","Ok")) | AR11: =IF(Q11-R11=0,"",IF(Q11>R11,"Erro","Ok")) | AS11: =IF(S11-T11=0,"",IF(S11>T11,"Erro","Ok")) | AT11: =IF(U11-V11=0,"",IF(U11>V11,"Erro","Ok"))
C12: =IF(Funcionários!C11=0,"",Funcionários!C11) | W12: 6 | X12: =IF(I12-J12=0,0,IF(I12>J12,"-",J12-I12-$H12)) -> 0 | Y12: =IF(K12-L12=0,0,IF(K12>L12,"-",L12-K12-$H12)) -> 0 | Z12: =IF(M12-N12=0,0,IF(M12>N12,"-",N12-M12-$H12)) -> 0 | AA12: =IF(O12-P12=0,0,IF(O12>P12,"-",P12-O12-$H12)) -> 0 | AB12: =IF(Q12-R12=0,0,IF(Q12>R12,"-",R12-Q12-$H12)) -> 0 | AC12: =IF(S12-T12=0,0,IF(S12>T12,"-",T12-S12-$H12)) -> 0 | AD12: =IF(U12-V12=0,0,IF(U12>V12,"-",V12-U12-$H12)) -> 0 | AE12: =ROUNDUP(24*(SUM(X12:AD12)),0) -> 0 | AF12: =AE12*5 -> 0 | AG12: =IF(C12="","",VLOOKUP(C12,Funcionários!$C$7:$D$36,2,0)) | AJ12: 0.45833333 | AN12: =IF(I12-J12=0,"",IF(I12>J12,"Erro","Ok")) | AO12: =IF(K12-L12=0,"",IF(K12>L12,"Erro","Ok")) | AP12: =IF(M12-N12=0,"",IF(M12>N12,"Erro","Ok")) | AQ12: =IF(O12-P12=0,"",IF(O12>P12,"Erro","Ok")) | AR12: =IF(Q12-R12=0,"",IF(Q12>R12,"Erro","Ok")) | AS12: =IF(S12-T12=0,"",IF(S12>T12,"Erro","Ok")) | AT12: =IF(U12-V12=0,"",IF(U12>V12,"Erro","Ok"))
C13: =IF(Funcionários!C12=0,"",Funcionários!C12) | W13: 7 | X13: =IF(I13-J13=0,0,IF(I13>J13,"-",J13-I13-$H13)) -> 0 | Y13: =IF(K13-L13=0,0,IF(K13>L13,"-",L13-K13-$H13)) -> 0 | Z13: =IF(M13-N13=0,0,IF(M13>N13,"-",N13-M13-$H13)) -> 0 | AA13: =IF(O13-P13=0,0,IF(O13>P13,"-",P13-O13-$H13)) -> 0 | AB13: =IF(Q13-R13=0,0,IF(Q13>R13,"-",R13-Q13-$H13)) -> 0 | AC13: =IF(S13-T13=0,0,IF(S13>T13,"-",T13-S13-$H13)) -> 0 | AD13: =IF(U13-V13=0,0,IF(U13>V13,"-",V13-U13-$H13)) -> 0 | AE13: =ROUNDUP(24*(SUM(X13:AD13)),0) -> 0 | AF13: =AE13*5 -> 0 | AG13: =IF(C13="","",VLOOKUP(C13,Funcionários!$C$7:$D$36,2,0)) | AJ13: 0.5 | AN13: =IF(I13-J13=0,"",IF(I13>J13,"Erro","Ok")) | AO13: =IF(K13-L13=0,"",IF(K13>L13,"Erro","Ok")) | AP13: =IF(M13-N13=0,"",IF(M13>N13,"Erro","Ok")) | AQ13: =IF(O13-P13=0,"",IF(O13>P13,"Erro","Ok")) | AR13: =IF(Q13-R13=0,"",IF(Q13>R13,"Erro","Ok")) | AS13: =IF(S13-T13=0,"",IF(S13>T13,"Erro","Ok")) | AT13: =IF(U13-V13=0,"",IF(U13>V13,"Erro","Ok"))
C14: =IF(Funcionários!C13=0,"",Funcionários!C13) | W14: 8 | X14: =IF(I14-J14=0,0,IF(I14>J14,"-",J14-I14-$H14)) -> 0 | Y14: =IF(K14-L14=0,0,IF(K14>L14,"-",L14-K14-$H14)) -> 0 | Z14: =IF(M14-N14=0,0,IF(M14>N14,"-",N14-M14-$H14)) -> 0 | AA14: =IF(O14-P14=0,0,IF(O14>P14,"-",P14-O14-$H14)) -> 0 | AB14: =IF(Q14-R14=0,0,IF(Q14>R14,"-",R14-Q14-$H14)) -> 0 | AC14: =IF(S14-T14=0,0,IF(S14>T14,"-",T14-S14-$H14)) -> 0 | AD14: =IF(U14-V14=0,0,IF(U14>V14,"-",V14-U14-$H14)) -> 0 | AE14: =ROUNDUP(24*(SUM(X14:AD14)),0) -> 0 | AF14: =AE14*5 -> 0 | AG14: =IF(C14="","",VLOOKUP(C14,Funcionários!$C$7:$D$36,2,0)) | AN14: =IF(I14-J14=0,"",IF(I14>J14,"Erro","Ok")) | AO14: =IF(K14-L14=0,"",IF(K14>L14,"Erro","Ok")) | AP14: =IF(M14-N14=0,"",IF(M14>N14,"Erro","Ok")) | AQ14: =IF(O14-P14=0,"",IF(O14>P14,"Erro","Ok")) | AR14: =IF(Q14-R14=0,"",IF(Q14>R14,"Erro","Ok")) | AS14: =IF(S14-T14=0,"",IF(S14>T14,"Erro","Ok")) | AT14: =IF(U14-V14=0,"",IF(U14>V14,"Erro","Ok"))
C15: =IF(Funcionários!C14=0,"",Funcionários!C14) | W15: 9 | X15: =IF(I15-J15=0,0,IF(I15>J15,"-",J15-I15-$H15)) -> 0 | Y15: =IF(K15-L15=0,0,IF(K15>L15,"-",L15-K15-$H15)) -> 0 | Z15: =IF(M15-N15=0,0,IF(M15>N15,"-",N15-M15-$H15)) -> 0 | AA15: =IF(O15-P15=0,0,IF(O15>P15,"-",P15-O15-$H15)) -> 0 | AB15: =IF(Q15-R15=0,0,IF(Q15>R15,"-",R15-Q15-$H15)) -> 0 | AC15: =IF(S15-T15=0,0,IF(S15>T15,"-",T15-S15-$H15)) -> 0 | AD15: =IF(U15-V15=0,0,IF(U15>V15,"-",V15-U15-$H15)) -> 0 | AE15: =ROUNDUP(24*(SUM(X15:AD15)),0) -> 0 | AF15: =AE15*5 -> 0 | AG15: =IF(C15="","",VLOOKUP(C15,Funcionários!$C$7:$D$36,2,0)) | AN15: =IF(I15-J15=0,"",IF(I15>J15,"Erro","Ok")) | AO15: =IF(K15-L15=0,"",IF(K15>L15,"Erro","Ok")) | AP15: =IF(M15-N15=0,"",IF(M15>N15,"Erro","Ok")) | AQ15: =IF(O15-P15=0,"",IF(O15>P15,"Erro","Ok")) | AR15: =IF(Q15-R15=0,"",IF(Q15>R15,"Erro","Ok")) | AS15: =IF(S15-T15=0,"",IF(S15>T15,"Erro","Ok")) | AT15: =IF(U15-V15=0,"",IF(U15>V15,"Erro","Ok"))
C16: =IF(Funcionários!C15=0,"",Funcionários!C15) | W16: 10 | X16: =IF(I16-J16=0,0,IF(I16>J16,"-",J16-I16-$H16)) -> 0 | Y16: =IF(K16-L16=0,0,IF(K16>L16,"-",L16-K16-$H16)) -> 0 | Z16: =IF(M16-N16=0,0,IF(M16>N16,"-",N16-M16-$H16)) -> 0 | AA16: =IF(O16-P16=0,0,IF(O16>P16,"-",P16-O16-$H16)) -> 0 | AB16: =IF(Q16-R16=0,0,IF(Q16>R16,"-",R16-Q16-$H16)) -> 0 | AC16: =IF(S16-T16=0,0,IF(S16>T16,"-",T16-S16-$H16)) -> 0 | AD16: =IF(U16-V16=0,0,IF(U16>V16,"-",V16-U16-$H16)) -> 0 | AE16: =ROUNDUP(24*(SUM(X16:AD16)),0) -> 0 | AF16: =AE16*5 -> 0 | AG16: =IF(C16="","",VLOOKUP(C16,Funcionários!$C$7:$D$36,2,0)) | AN16: =IF(I16-J16=0,"",IF(I16>J16,"Erro","Ok")) | AO16: =IF(K16-L16=0,"",IF(K16>L16,"Erro","Ok")) | AP16: =IF(M16-N16=0,"",IF(M16>N16,"Erro","Ok")) | AQ16: =IF(O16-P16=0,"",IF(O16>P16,"Erro","Ok")) | AR16: =IF(Q16-R16=0,"",IF(Q16>R16,"Erro","Ok")) | AS16: =IF(S16-T16=0,"",IF(S16>T16,"Erro","Ok")) | AT16: =IF(U16-V16=0,"",IF(U16>V16,"Erro","Ok"))
C17: =IF(Funcionários!C16=0,"",Funcionários!C16) | W17: 11 | X17: =IF(I17-J17=0,0,IF(I17>J17,"-",J17-I17-$H17)) -> 0 | Y17: =IF(K17-L17=0,0,IF(K17>L17,"-",L17-K17-$H17)) -> 0 | Z17: =IF(M17-N17=0,0,IF(M17>N17,"-",N17-M17-$H17)) -> 0 | AA17: =IF(O17-P17=0,0,IF(O17>P17,"-",P17-O17-$H17)) -> 0 | AB17: =IF(Q17-R17=0,0,IF(Q17>R17,"-",R17-Q17-$H17)) -> 0 | AC17: =IF(S17-T17=0,0,IF(S17>T17,"-",T17-S17-$H17)) -> 0 | AD17: =IF(U17-V17=0,0,IF(U17>V17,"-",V17-U17-$H17)) -> 0 | AE17: =ROUNDUP(24*(SUM(X17:AD17)),0) -> 0 | AF17: =AE17*5 -> 0 | AG17: =IF(C17="","",VLOOKUP(C17,Funcionários!$C$7:$D$36,2,0)) | AN17: =IF(I17-J17=0,"",IF(I17>J17,"Erro","Ok")) | AO17: =IF(K17-L17=0,"",IF(K17>L17,"Erro","Ok")) | AP17: =IF(M17-N17=0,"",IF(M17>N17,"Erro","Ok")) | AQ17: =IF(O17-P17=0,"",IF(O17>P17,"Erro","Ok")) | AR17: =IF(Q17-R17=0,"",IF(Q17>R17,"Erro","Ok")) | AS17: =IF(S17-T17=0,"",IF(S17>T17,"Erro","Ok")) | AT17: =IF(U17-V17=0,"",IF(U17>V17,"Erro","Ok"))
C18: =IF(Funcionários!C17=0,"",Funcionários!C17) | W18: 12 | X18: =IF(I18-J18=0,0,IF(I18>J18,"-",J18-I18-$H18)) -> 0 | Y18: =IF(K18-L18=0,0,IF(K18>L18,"-",L18-K18-$H18)) -> 0 | Z18: =IF(M18-N18=0,0,IF(M18>N18,"-",N18-M18-$H18)) -> 0 | AA18: =IF(O18-P18=0,0,IF(O18>P18,"-",P18-O18-$H18)) -> 0 | AB18: =IF(Q18-R18=0,0,IF(Q18>R18,"-",R18-Q18-$H18)) -> 0 | AC18: =IF(S18-T18=0,0,IF(S18>T18,"-",T18-S18-$H18)) -> 0 | AD18: =IF(U18-V18=0,0,IF(U18>V18,"-",V18-U18-$H18)) -> 0 | AE18: =ROUNDUP(24*(SUM(X18:AD18)),0) -> 0 | AF18: =AE18*5 -> 0 | AG18: =IF(C18="","",VLOOKUP(C18,Funcionários!$C$7:$D$36,2,0)) | AN18: =IF(I18-J18=0,"",IF(I18>J18,"Erro","Ok")) | AO18: =IF(K18-L18=0,"",IF(K18>L18,"Erro","Ok")) | AP18: =IF(M18-N18=0,"",IF(M18>N18,"Erro","Ok")) | AQ18: =IF(O18-P18=0,"",IF(O18>P18,"Erro","Ok")) | AR18: =IF(Q18-R18=0,"",IF(Q18>R18,"Erro","Ok")) | AS18: =IF(S18-T18=0,"",IF(S18>T18,"Erro","Ok")) | AT18: =IF(U18-V18=0,"",IF(U18>V18,"Erro","Ok"))
C19: =IF(Funcionários!C18=0,"",Funcionários!C18) | W19: 13 | X19: =IF(I19-J19=0,0,IF(I19>J19,"-",J19-I19-$H19)) -> 0 | Y19: =IF(K19-L19=0,0,IF(K19>L19,"-",L19-K19-$H19)) -> 0 | Z19: =IF(M19-N19=0,0,IF(M19>N19,"-",N19-M19-$H19)) -> 0 | AA19: =IF(O19-P19=0,0,IF(O19>P19,"-",P19-O19-$H19)) -> 0 | AB19: =IF(Q19-R19=0,0,IF(Q19>R19,"-",R19-Q19-$H19)) -> 0 | AC19: =IF(S19-T19=0,0,IF(S19>T19,"-",T19-S19-$H19)) -> 0 | AD19: =IF(U19-V19=0,0,IF(U19>V19,"-",V19-U19-$H19)) -> 0 | AE19: =ROUNDUP(24*(SUM(X19:AD19)),0) -> 0 | AF19: =AE19*5 -> 0 | AG19: =IF(C19="","",VLOOKUP(C19,Funcionários!$C$7:$D$36,2,0)) | AN19: =IF(I19-J19=0,"",IF(I19>J19,"Erro","Ok")) | AO19: =IF(K19-L19=0,"",IF(K19>L19,"Erro","Ok")) | AP19: =IF(M19-N19=0,"",IF(M19>N19,"Erro","Ok")) | AQ19: =IF(O19-P19=0,"",IF(O19>P19,"Erro","Ok")) | AR19: =IF(Q19-R19=0,"",IF(Q19>R19,"Erro","Ok")) | AS19: =IF(S19-T19=0,"",IF(S19>T19,"Erro","Ok")) | AT19: =IF(U19-V19=0,"",IF(U19>V19,"Erro","Ok"))
C20: =IF(Funcionários!C19=0,"",Funcionários!C19) | W20: 14 | X20: =IF(I20-J20=0,0,IF(I20>J20,"-",J20-I20-$H20)) -> 0 | Y20: =IF(K20-L20=0,0,IF(K20>L20,"-",L20-K20-$H20)) -> 0 | Z20: =IF(M20-N20=0,0,IF(M20>N20,"-",N20-M20-$H20)) -> 0 | AA20: =IF(O20-P20=0,0,IF(O20>P20,"-",P20-O20-$H20)) -> 0 | AB20: =IF(Q20-R20=0,0,IF(Q20>R20,"-",R20-Q20-$H20)) -> 0 | AC20: =IF(S20-T20=0,0,IF(S20>T20,"-",T20-S20-$H20)) -> 0 | AD20: =IF(U20-V20=0,0,IF(U20>V20,"-",V20-U20-$H20)) -> 0 | AE20: =ROUNDUP(24*(SUM(X20:AD20)),0) -> 0 | AF20: =AE20*5 -> 0 | AG20: =IF(C20="","",VLOOKUP(C20,Funcionários!$C$7:$D$36,2,0)) | AN20: =IF(I20-J20=0,"",IF(I20>J20,"Erro","Ok")) | AO20: =IF(K20-L20=0,"",IF(K20>L20,"Erro","Ok")) | AP20: =IF(M20-N20=0,"",IF(M20>N20,"Erro","Ok")) | AQ20: =IF(O20-P20=0,"",IF(O20>P20,"Erro","Ok")) | AR20: =IF(Q20-R20=0,"",IF(Q20>R20,"Erro","Ok")) | AS20: =IF(S20-T20=0,"",IF(S20>T20,"Erro","Ok")) | AT20: =IF(U20-V20=0,"",IF(U20>V20,"Erro","Ok"))
C21: =IF(Funcionários!C20=0,"",Funcionários!C20) | W21: 15 | X21: =IF(I21-J21=0,0,IF(I21>J21,"-",J21-I21-$H21)) -> 0 | Y21: =IF(K21-L21=0,0,IF(K21>L21,"-",L21-K21-$H21)) -> 0 | Z21: =IF(M21-N21=0,0,IF(M21>N21,"-",N21-M21-$H21)) -> 0 | AA21: =IF(O21-P21=0,0,IF(O21>P21,"-",P21-O21-$H21)) -> 0 | AB21: =IF(Q21-R21=0,0,IF(Q21>R21,"-",R21-Q21-$H21)) -> 0 | AC21: =IF(S21-T21=0,0,IF(S21>T21,"-",T21-S21-$H21)) -> 0 | AD21: =IF(U21-V21=0,0,IF(U21>V21,"-",V21-U21-$H21)) -> 0 | AE21: =ROUNDUP(24*(SUM(X21:AD21)),0) -> 0 | AF21: =AE21*5 -> 0 | AG21: =IF(C21="","",VLOOKUP(C21,Funcionários!$C$7:$D$36,2,0)) | AN21: =IF(I21-J21=0,"",IF(I21>J21,"Erro","Ok")) | AO21: =IF(K21-L21=0,"",IF(K21>L21,"Erro","Ok")) | AP21: =IF(M21-N21=0,"",IF(M21>N21,"Erro","Ok")) | AQ21: =IF(O21-P21=0,"",IF(O21>P21,"Erro","Ok")) | AR21: =IF(Q21-R21=0,"",IF(Q21>R21,"Erro","Ok")) | AS21: =IF(S21-T21=0,"",IF(S21>T21,"Erro","Ok")) | AT21: =IF(U21-V21=0,"",IF(U21>V21,"Erro","Ok"))
C22: =IF(Funcionários!C21=0,"",Funcionários!C21) | W22: 16 | X22: =IF(I22-J22=0,0,IF(I22>J22,"-",J22-I22-$H22)) -> 0 | Y22: =IF(K22-L22=0,0,IF(K22>L22,"-",L22-K22-$H22)) -> 0 | Z22: =IF(M22-N22=0,0,IF(M22>N22,"-",N22-M22-$H22)) -> 0 | AA22: =IF(O22-P22=0,0,IF(O22>P22,"-",P22-O22-$H22)) -> 0 | AB22: =IF(Q22-R22=0,0,IF(Q22>R22,"-",R22-Q22-$H22)) -> 0 | AC22: =IF(S22-T22=0,0,IF(S22>T22,"-",T22-S22-$H22)) -> 0 | AD22: =IF(U22-V22=0,0,IF(U22>V22,"-",V22-U22-$H22)) -> 0 | AE22: =ROUNDUP(24*(SUM(X22:AD22)),0) -> 0 | AF22: =AE22*5 -> 0 | AG22: =IF(C22="","",VLOOKUP(C22,Funcionários!$C$7:$D$36,2,0)) | AN22: =IF(I22-J22=0,"",IF(I22>J22,"Erro","Ok")) | AO22: =IF(K22-L22=0,"",IF(K22>L22,"Erro","Ok")) | AP22: =IF(M22-N22=0,"",IF(M22>N22,"Erro","Ok")) | AQ22: =IF(O22-P22=0,"",IF(O22>P22,"Erro","Ok")) | AR22: =IF(Q22-R22=0,"",IF(Q22>R22,"Erro","Ok")) | AS22: =IF(S22-T22=0,"",IF(S22>T22,"Erro","Ok")) | AT22: =IF(U22-V22=0,"",IF(U22>V22,"Erro","Ok"))
C23: =IF(Funcionários!C22=0,"",Funcionários!C22) | W23: 17 | X23: =IF(I23-J23=0,0,IF(I23>J23,"-",J23-I23-$H23)) -> 0 | Y23: =IF(K23-L23=0,0,IF(K23>L23,"-",L23-K23-$H23)) -> 0 | Z23: =IF(M23-N23=0,0,IF(M23>N23,"-",N23-M23-$H23)) -> 0 | AA23: =IF(O23-P23=0,0,IF(O23>P23,"-",P23-O23-$H23)) -> 0 | AB23: =IF(Q23-R23=0,0,IF(Q23>R23,"-",R23-Q23-$H23)) -> 0 | AC23: =IF(S23-T23=0,0,IF(S23>T23,"-",T23-S23-$H23)) -> 0 | AD23: =IF(U23-V23=0,0,IF(U23>V23,"-",V23-U23-$H23)) -> 0 | AE23: =ROUNDUP(24*(SUM(X23:AD23)),0) -> 0 | AF23: =AE23*5 -> 0 | AG23: =IF(C23="","",VLOOKUP(C23,Funcionários!$C$7:$D$36,2,0)) | AN23: =IF(I23-J23=0,"",IF(I23>J23,"Erro","Ok")) | AO23: =IF(K23-L23=0,"",IF(K23>L23,"Erro","Ok")) | AP23: =IF(M23-N23=0,"",IF(M23>N23,"Erro","Ok")) | AQ23: =IF(O23-P23=0,"",IF(O23>P23,"Erro","Ok")) | AR23: =IF(Q23-R23=0,"",IF(Q23>R23,"Erro","Ok")) | AS23: =IF(S23-T23=0,"",IF(S23>T23,"Erro","Ok")) | AT23: =IF(U23-V23=0,"",IF(U23>V23,"Erro","Ok"))
C24: =IF(Funcionários!C23=0,"",Funcionários!C23) | W24: 18 | X24: =IF(I24-J24=0,0,IF(I24>J24,"-",J24-I24-$H24)) -> 0 | Y24: =IF(K24-L24=0,0,IF(K24>L24,"-",L24-K24-$H24)) -> 0 | Z24: =IF(M24-N24=0,0,IF(M24>N24,"-",N24-M24-$H24)) -> 0 | AA24: =IF(O24-P24=0,0,IF(O24>P24,"-",P24-O24-$H24)) -> 0 | AB24: =IF(Q24-R24=0,0,IF(Q24>R24,"-",R24-Q24-$H24)) -> 0 | AC24: =IF(S24-T24=0,0,IF(S24>T24,"-",T24-S24-$H24)) -> 0 | AD24: =IF(U24-V24=0,0,IF(U24>V24,"-",V24-U24-$H24)) -> 0 | AE24: =ROUNDUP(24*(SUM(X24:AD24)),0) -> 0 | AF24: =AE24*5 -> 0 | AG24: =IF(C24="","",VLOOKUP(C24,Funcionários!$C$7:$D$36,2,0)) | AN24: =IF(I24-J24=0,"",IF(I24>J24,"Erro","Ok")) | AO24: =IF(K24-L24=0,"",IF(K24>L24,"Erro","Ok")) | AP24: =IF(M24-N24=0,"",IF(M24>N24,"Erro","Ok")) | AQ24: =IF(O24-P24=0,"",IF(O24>P24,"Erro","Ok")) | AR24: =IF(Q24-R24=0,"",IF(Q24>R24,"Erro","Ok")) | AS24: =IF(S24-T24=0,"",IF(S24>T24,"Erro","Ok")) | AT24: =IF(U24-V24=0,"",IF(U24>V24,"Erro","Ok"))
C25: =IF(Funcionários!C24=0,"",Funcionários!C24) | W25: 19 | X25: =IF(I25-J25=0,0,IF(I25>J25,"-",J25-I25-$H25)) -> 0 | Y25: =IF(K25-L25=0,0,IF(K25>L25,"-",L25-K25-$H25)) -> 0 | Z25: =IF(M25-N25=0,0,IF(M25>N25,"-",N25-M25-$H25)) -> 0 | AA25: =IF(O25-P25=0,0,IF(O25>P25,"-",P25-O25-$H25)) -> 0 | AB25: =IF(Q25-R25=0,0,IF(Q25>R25,"-",R25-Q25-$H25)) -> 0 | AC25: =IF(S25-T25=0,0,IF(S25>T25,"-",T25-S25-$H25)) -> 0 | AD25: =IF(U25-V25=0,0,IF(U25>V25,"-",V25-U25-$H25)) -> 0 | AE25: =ROUNDUP(24*(SUM(X25:AD25)),0) -> 0 | AF25: =AE25*5 -> 0 | AG25: =IF(C25="","",VLOOKUP(C25,Funcionários!$C$7:$D$36,2,0)) | AN25: =IF(I25-J25=0,"",IF(I25>J25,"Erro","Ok")) | AO25: =IF(K25-L25=0,"",IF(K25>L25,"Erro","Ok")) | AP25: =IF(M25-N25=0,"",IF(M25>N25,"Erro","Ok")) | AQ25: =IF(O25-P25=0,"",IF(O25>P25,"Erro","Ok")) | AR25: =IF(Q25-R25=0,"",IF(Q25>R25,"Erro","Ok")) | AS25: =IF(S25-T25=0,"",IF(S25>T25,"Erro","Ok")) | AT25: =IF(U25-V25=0,"",IF(U25>V25,"Erro","Ok"))
... C37: =IF(Funcionários!C36=0,"",Funcionários!C36) | W37: 31 | X37: =IF(I37-J37=0,0,IF(I37>J37,"-",J37-I37-$H37)) -> 0 | Y37: =IF(K37-L37=0,0,IF(K37>L37,"-",L37-K37-$H37)) -> 0 | Z37: =IF(M37-N37=0,0,IF(M37>N37,"-",N37-M37-$H37)) -> 0 | AA37: =IF(O37-P37=0,0,IF(O37>P37,"-",P37-O37-$H37)) -> 0 | AB37: =IF(Q37-R37=0,0,IF(Q37>R37,"-",R37-Q37-$H37)) -> 0 | AC37: =IF(S37-T37=0,0,IF(S37>T37,"-",T37-S37-$H37)) -> 0 | AD37: =IF(U37-V37=0,0,IF(U37>V37,"-",V37-U37-$H37)) -> 0 | AE37: =ROUNDUP(24*(SUM(X37:AD37)),0) -> 0 | AF37: =AE37*5 -> 0 | AG37: =IF(C37="","",VLOOKUP(C37,Funcionários!$C$7:$D$36,2,0)) | AN37: =IF(I37-J37=0,"",IF(I37>J37,"Erro","Ok")) | AO37: =IF(K37-L37=0,"",IF(K37>L37,"Erro","Ok")) | AP37: =IF(M37-N37=0,"",IF(M37>N37,"Erro","Ok")) | AQ37: =IF(O37-P37=0,"",IF(O37>P37,"Erro","Ok")) | AR37: =IF(Q37-R37=0,"",IF(Q37>R37,"Erro","Ok")) | AS37: =IF(S37-T37=0,"",IF(S37>T37,"Erro","Ok")) | AT37: =IF(U37-V37=0,"",IF(U37>V37,"Erro","Ok"))
I38: a | J38: a | K38: a | L38: a | M38: a | N38: a | O38: a | P38: a | Q38: a | R38: a | S38: a | T38: a | U38: a | V38: a | W38: a

Sheet Lanç
C1: 2. LANÇAMENTOS MENSAIS
C5: Lanç!$C$8 | K5: =IF(ISERROR(VLOOKUP(INDIRECT($C$5),Jornada!$C$8:$F$37,4,0)),0,VLOOKUP(INDIRECT($C$5),Jornada!$C$8:$F$37,4,0)) -> 0 | M5: =IF(ISERROR(VLOOKUP(INDIRECT($C$5),Jornada!$C$8:$G$37,5,0)),0,VLOOKUP(INDIRECT($C$5),Jornada!$C$8:$G$37,5,0)) -> 0 | AK5: 0.25 | AL5: 0.91666667 | AM5: 0.20833333 | AN5: 1 | AO5: 0.70833333
M6: 1
C7: Lista de funcionários | E7: =IF('P Gerais'!J6=0,"Janeiro",'P Gerais'!J6) -> Janeiro | G7: Classificação | H7: Início | I7: Intervalo | K7: Término | M7: Horas Dia | O7: Horas Devidas | Q7: Horas Extras | R7: 0.083333333 | S7: Resumo do Mês | W7: Janeiro | X7: 1 | AB7: =VLOOKUP($E$7,$W$7:$X$18,2,0) -> 1 | AG7: intervalo real | AH7: intervalo devido | AI7: 0 | AJ7: 1 | AK7: 0.45833333 | AL7: Início | AM7: Fim | AN7: Hora Extra Noturna Início
C8: =IF(Funcionários!C7=0,"",Funcionários!C7) | D8: =WEEKDAY(DATE('P Gerais'!$D$6,VLOOKUP(Lanç!$E$7,$W$7:$X$18,2,FALSE),E8)) -> 1 | E8: 1 | F8: =VLOOKUP(D8,$AE$8:$AF$14,2,FALSE) -> Dom | M8: =IF(AND(H8=K8,H8<>0),$M$6-IF(J8<I8,$AJ$7+J8-I8,J8-I8),IF(H8>K8,(K8+1-H8)-IF(J8<I8,$AJ$7+J8-I8,J8-I8),(K8-H8)-IF(J8<I8,$AJ$7+J8-I8,J8-I8))) -> 0 | O8: =IF(OR(G8=0,G8="Férias",G8="Falta Justificada",G8="Feriado",G8="Folga (DSR)"),0,IF(G8="Falta Injustificada",HLOOKUP($F8,Jornada!$X$7:$AD$37,VLOOKUP(INDIRECT($C$5),Jornada!$C$8:$W$37,21,0),0),IF(HLOOKUP($F8,Jornada!$X$7:$AD$37,VLOOKUP(INDIRECT($C$5),Jornada!$C$8:$W$37,21,0),0)-M8>0,HLOOKUP($F8,Jornada!$X$7:$AD$37,VLOOKUP(INDIRECT($C$5),Jornada!$C$8:$W$37,21,0),0)-M8,0))) -> 0 | P8: =IF(HLOOKUP($F8,Jornada!$X$7:$AD$37,VLOOKUP(INDIRECT($C$5),Jornada!$C$8:$W$37,21,0),0)-M8<0,ABS(HLOOKUP($F8,Jornada!$X$7:$AD$37,VLOOKUP(INDIRECT($C$5),Jornada!$C$8:$W$37,21,0),0)-M8),0) -> 0 | Q8: =IF(G8="Normal",P8,IF(G8=0,0,IF(OR(G8="Feriado",G8="Férias"),IF(H8>K8,(K8+1-H8)-IF(J8<I8,$AJ$7+J8-I8,J8-I8),(K8-H8)-IF(J8<I8,$AJ$7+J8-I8,J8-I8)),IF(G8="Folga (DSR)",IF(H8>K8,(K8+1-H8)-IF(J8<I8,$AJ$7+J8-I8,J8-I8),(K8-H8)-IF(J8<I8,$AJ$7+J8-I8,J8-I8)),IF(G8="Falta Justificada",IF(H8>K8,(K8+1-H8)-IF(J8<I8,$AJ$7+J8-I8,J8-I8),(K8-H8)-IF(J8<I8,$AJ$7+J8-I8,J8-I8)),0))))) -> 0 | R8: =IF(Q8>$R$7,1,0) -> 0 | S8: Horas trabalhadas no mês | U8: =SUM(M8:M38) -> 0 | W8: Fevereiro | X8: 2 | AB8: =DATE('P Gerais'!$D$6,AB7,1) -> 1 | AC8: =WEEKDAY(AB8) -> 1 | AE8: 1 | AF8: Dom | AG8: =IF(J8<I8,$AJ$7+J8-I8,J8-I8) -> 0 | AH8: =IF(HLOOKUP($F8,Jornada!$X$7:$AD$37,VLOOKUP(INDIRECT($C$5),Jornada!$C$8:$W$37,21,0),0)=0,0,VLOOKUP(INDIRECT($C$5),Jornada!$C$8:$H$37,4,0)) -> 0 | AI8: =IF(AND(I8=0,J8=0,OR(H8<>0,K8<>0),HLOOKUP($F8,Jornada!$X$7:$AD$37,VLOOKUP(INDIRECT($C$5),Jornada!$C$8:$W$37,21,0),0)>$AK$5,M8>$AK$5),VLOOKUP(INDIRECT($C$5),Jornada!$C$8:$H$37,6,0),IF(AG8>VLOOKUP(INDIRECT($C$5),Jornada!$C$8:$H$37,6,0),IF(VLOOKUP(INDIRECT($C$5),Jornada!$C$8:$H$37,6,0)<AG8,0,ABS(VLOOKUP(INDIRECT($C$5),Jornada!$C$8:$H$37,6,0))-AG8),0)) -> 0 | AJ8: =($AJ$7-K8)+H8 -> 1 | AK8: =IF(AJ8<$AK$7,$AK$7-AJ8,$AI$7) -> 0 | AL8: =HLOOKUP($F8,Jornada!$I$5:$V$37,VLOOKUP(INDIRECT($C$5),Jornada!$C$8:$W$37,21,0)+2,0) -> 0 | AM8: =HLOOKUP($F8,Jornada!$I$4:$V$37,VLOOKUP(INDIRECT($C$5),Jornada!$C$8:$W$37,21,0)+3,0) -> 0 | AN8: =IF(AND(AL8>=$AL$5,AL8<$AN$5,H8>=$AL$5,H8<AL8),AL8-H8,IF(AND(AL8>$AI$7,AL8<=$AM$5,H8>=$AL$5,H8<=$AN$5),$AN$5-H8+AL8,IF(AND(AL8>=$AI$7,AL8<=$AM$5,H8>=$AI$7,H8<=$AM$5,H8<AL8),H8-AL8,0))) -> 0 | AO8: =IF(AP8>Q8,0,AP8) -> 0 | AP8: =IF(Q8=0,0,IF(AND(AM8>=$AL$5,AM8<$AN$5,K8>=$AL$5,K8<$AM$5,K8>AM8),K8-AM8,IF(AND(AM8>=$AL$5,AM8<$AN$5,K8<$AN$5,K8>AM8),K8-$AL$5,IF(AND(AM8>=$AI$7,AM8<$AM$5,K8<$AM$5),K8-AM8,IF(AND(AM8<>AI7,AM8>=$AI$7,AM8<=$AM$5,K8>$AM$5,K8>AM8),$AM$5-AM8,IF(AND(K8>$AL$5,K8<$AN$5),K8-$AL$5,IF(AND(K8>$AI$7,K8<$AM$5),$AN$5-$AL$5+K8,IF(AND(OR(K8>$AL$5,H8>$AO$5),AM8>=$AI$7,AM8<$AM$5,K8>$AM$5),(1+$AM$5-$AL$5)-AG8,0)))))))) -> 0
C9: =IF(Funcionários!C8=0,"",Funcionários!C8) | D9: =IF(D8=7,1,D8+1) -> 2 | E9: =IF(DAY(DATE('P Gerais'!$D$6,VLOOKUP($E$7,$W$7:$X$18,2,0),E8+1))>DAY(EOMONTH(DATE('P Gerais'!$D$6,VLOOKUP($E$7,$W$7:$X$18,2,0),E8),0)),DAY(DATE('P Gerais'!$D$6,VLOOKUP($E$7,$W$7:$X$18,2,0)+1,1)),DAY(DATE('P Gerais'!$D$6,VLOOKUP($E$7,$W$7:$X$18,2,0),E8+1))) -> 2 | F9: =VLOOKUP(D9,$AE$8:$AF$14,2,FALSE) -> Seg | M9: =IF(AND(H9=K9,H9<>0),$M$6-IF(J9<I9,$AJ$7+J9-I9,J9-I9),IF(H9>K9,(K9+1-H9)-IF(J9<I9,$AJ$7+J9-I9,J9-I9),(K9-H9)-IF(J9<I9,$AJ$7+J9-I9,J9-I9))) -> 0 | O9: =IF(OR(G9=0,G9="Férias",G9="Falta Justificada",G9="Feriado",G9="Folga (DSR)"),0,IF(G9="Falta Injustificada",HLOOKUP($F9,Jornada!$X$7:$AD$37,VLOOKUP(INDIRECT($C$5),Jornada!$C$8:$W$37,21,0),0),IF(HLOOKUP($F9,Jornada!$X$7:$AD$37,VLOOKUP(INDIRECT($C$5),Jornada!$C$8:$W$37,21,0),0)-M9>0,HLOOKUP($F9,Jornada!$X$7:$AD$37,VLOOKUP(INDIRECT($C$5),Jornada!$C$8:$W$37,21,0),0)-M9,0))) -> 0 | P9: =IF(HLOOKUP($F9,Jornada!$X$7:$AD$37,VLOOKUP(INDIRECT($C$5),Jornada!$C$8:$W$37,21,0),0)-M9<0,ABS(HLOOKUP($F9,Jornada!$X$7:$AD$37,VLOOKUP(INDIRECT($C$5),Jornada!$C$8:$W$37,21,0),0)-M9),0) -> 0 | Q9: =IF(G9="Normal",P9,IF(G9=0,0,IF(OR(G9="Feriado",G9="Férias"),IF(H9>K9,(K9+1-H9)-IF(J9<I9,$AJ$7+J9-I9,J9-I9),(K9-H9)-IF(J9<I9,$AJ$7+J9-I9,J9-I9)),IF(G9="Folga (DSR)",IF(H9>K9,(K9+1-H9)-IF(J9<I9,$AJ$7+J9-I9,J9-I9),(K9-H9)-IF(J9<I9,$AJ$7+J9-I9,J9-I9)),IF(G9="Falta Justificada",IF(H9>K9,(K9+1-H9)-IF(J9<I9,$AJ$7+J9-I9,J9-I9),(K9-H9)-IF(J9<I9,$AJ$7+J9-I9,J9-I9)),0))))) -> 0 | R9: =IF(Q9>$R$7,1,0) -> 0 | W9: Março | X9: 3 | AB9: =AB8+1 -> 2 | AC9: =WEEKDAY(AB9) -> 2 | AE9: 2 | AF9: Seg | AG9: =IF(J9<I9,$AJ$7+J9-I9,J9-I9) -> 0 | AH9: =IF(HLOOKUP($F9,Jornada!$X$7:$AD$37,VLOOKUP(INDIRECT($C$5),Jornada!$C$8:$W$37,21,0),0)=0,0,VLOOKUP(INDIRECT($C$5),Jornada!$C$8:$H$37,4,0)) -> 0 | AI9: =IF(AND(I9=0,J9=0,OR(H9<>0,K9<>0),HLOOKUP($F9,Jornada!$X$7:$AD$37,VLOOKUP(INDIRECT($C$5),Jornada!$C$8:$W$37,21,0),0)>$AK$5,M9>$AK$5),VLOOKUP(INDIRECT($C$5),Jornada!$C$8:$H$37,6,0),IF(AG9>VLOOKUP(INDIRECT($C$5),Jornada!$C$8:$H$37,6,0),IF(VLOOKUP(INDIRECT($C$5),Jornada!$C$8:$H$37,6,0)<AG9,0,ABS(VLOOKUP(INDIRECT($C$5),Jornada!$C$8:$H$37,6,0))-AG9),0)) -> 0 | AJ9: =($AJ$7-K9)+H9 -> 1 | AK9: =IF(AJ9<$AK$7,$AK$7-AJ9,$AI$7) -> 0 | AL9: =HLOOKUP($F9,Jornada!$I$5:$V$37,VLOOKUP(INDIRECT($C$5),Jornada!$C$8:$W$37,21,0)+2,0) -> 0 | AM9: =HLOOKUP($F9,Jornada!$I$4:$V$37,VLOOKUP(INDIRECT($C$5),Jornada!$C$8:$W$37,21,0)+3,0) -> 0 | AN9: =IF(AND(AL9>=$AL$5,AL9<$AN$5,H9>=$AL$5,H9<AL9),AL9-H9,IF(AND(AL9>$AI$7,AL9<=$AM$5,H9>=$AL$5,H9<=$AN$5),$AN$5-H9+AL9,IF(AND(AL9>=$AI$7,AL9<=$AM$5,H9>=$AI$7,H9<=$AM$5,H9<AL9),H9-AL9,0))) -> 0 | AO9: =IF(AP9>Q9,0,AP9) -> 0 | AP9: =IF(Q9=0,0,IF(AND(AM9>=$AL$5,AM9<$AN$5,K9>=$AL$5,K9<$AM$5,K9>AM9),K9-AM9,IF(AND(AM9>=$AL$5,AM9<$AN$5,K9<$AN$5,K9>AM9),K9-$AL$5,IF(AND(AM9>=$AI$7,AM9<$AM$5,K9<$AM$5),K9-AM9,IF(AND(AM9<>AI8,AM9>=$AI$7,AM9<=$AM$5,K9>$AM$5,K9>AM9),$AM$5-AM9,IF(AND(K9>$AL$5,K9<$AN$5),K9-$AL$5,IF(AND(K9>$AI$7,K9<$AM$5),$AN$5-$AL$5+K9,IF(AND(OR(K9>$AL$5,H9>$AO$5),AM9>=$AI$7,AM9<$AM$5,K9>$AM$5),(1+$AM$5-$AL$5)-AG9,0)))))))) -> 0
C10: =IF(Funcionários!C9=0,"",Funcionários!C9) | D10: =IF(D9=7,1,D9+1) -> 3 | E10: =IF(DAY(DATE('P Gerais'!$D$6,VLOOKUP($E$7,$W$7:$X$18,2,0),E9+1))>DAY(EOMONTH(DATE('P Gerais'!$D$6,VLOOKUP($E$7,$W$7:$X$18,2,0),E9),0)),DAY(DATE('P Gerais'!$D$6,VLOOKUP($E$7,$W$7:$X$18,2,0)+1,1)),DAY(DATE('P Gerais'!$D$6,VLOOKUP($E$7,$W$7:$X$18,2,0),E9+1))) -> 3 | F10: =VLOOKUP(D10,$AE$8:$AF$14,2,FALSE) -> Ter | M10: =IF(AND(H10=K10,H10<>0),$M$6-IF(J10<I10,$AJ$7+J10-I10,J10-I10),IF(H10>K10,(K10+1-H10)-IF(J10<I10,$AJ$7+J10-I10,J10-I10),(K10-H10)-IF(J10<I10,$AJ$7+J10-I10,J10-I10))) -> 0 | O10: =IF(OR(G10=0,G10="Férias",G10="Falta Justificada",G10="Feriado",G10="Folga (DSR)"),0,IF(G10="Falta Injustificada",HLOOKUP($F10,Jornada!$X$7:$AD$37,VLOOKUP(INDIRECT($C$5),Jornada!$C$8:$W$37,21,0),0),IF(HLOOKUP($F10,Jornada!$X$7:$AD$37,VLOOKUP(INDIRECT($C$5),Jornada!$C$8:$W$37,21,0),0)-M10>0,HLOOKUP($F10,Jornada!$X$7:$AD$37,VLOOKUP(INDIRECT($C$5),Jornada!$C$8:$W$37,21,0),0)-M10,0))) -> 0 | P10: =IF(HLOOKUP($F10,Jornada!$X$7:$AD$37,VLOOKUP(INDIRECT($C$5),Jornada!$C$8:$W$37,21,0),0)-M10<0,ABS(HLOOKUP($F10,Jornada!$X$7:$AD$37,VLOOKUP(INDIRECT($C$5),Jornada!$C$8:$W$37,21,0),0)-M10),0) -> 0 | Q10: =IF(G10="Normal",P10,IF(G10=0,0,IF(OR(G10="Feriado",G10="Férias"),IF(H10>K10,(K10+1-H10)-IF(J10<I10,$AJ$7+J10-I10,J10-I10),(K10-H10)-IF(J10<I10,$AJ$7+J10-I10,J10-I10)),IF(G10="Folga (DSR)",IF(H10>K10,(K10+1-H10)-IF(J10<I10,$AJ$7+J10-I10,J10-I10),(K10-H10)-IF(J10<I10,$AJ$7+J10-I10,J10-I10)),IF(G10="Falta Justificada",IF(H10>K10,(K10+1-H10)-IF(J10<I10,$AJ$7+J10-I10,J10-I10),(K10-H10)-IF(J10<I10,$AJ$7+J10-I10,J10-I10)),0))))) -> 0 | R10: =IF(Q10>$R$7,1,0) -> 0 | S10: Acumulado no banco de horas | U10: =IF(M5="Horas devidas",ABS(-K5+F58-U14),ABS(K5+F58-U14)) -> 0 | W10: Abril | X10: 4 | AB10: =AB9+1 -> 3 | AC10: =WEEKDAY(AB10) -> 3 | AE10: 3 | AF10: Ter | AG10: =IF(J10<I10,$AJ$7+J10-I10,J10-I10) -> 0 | AH10: =IF(HLOOKUP($F10,Jornada!$X$7:$AD$37,VLOOKUP(INDIRECT($C$5),Jornada!$C$8:$W$37,21,0),0)=0,0,VLOOKUP(INDIRECT($C$5),Jornada!$C$8:$H$37,4,0)) -> 0 | AI10: =IF(AND(I10=0,J10=0,OR(H10<>0,K10<>0),HLOOKUP($F10,Jornada!$X$7:$AD$37,VLOOKUP(INDIRECT($C$5),Jornada!$C$8:$W$37,21,0),0)>$AK$5,M10>$AK$5),VLOOKUP(INDIRECT($C$5),Jornada!$C$8:$H$37,6,0),IF(AG10>VLOOKUP(INDIRECT($C$5),Jornada!$C$8:$H$37,6,0),IF(VLOOKUP(INDIRECT($C$5),Jornada!$C$8:$H$37,6,0)<AG10,0,ABS(VLOOKUP(INDIRECT($C$5),Jornada!$C$8:$H$37,6,0))-AG10),0)) -> 0 | AJ10: =($AJ$7-K10)+H10 -> 1 | AK10: =IF(AJ10<$AK$7,$AK$7-AJ10,$AI$7) -> 0 | AL10: =HLOOKUP($F10,Jornada!$I$5:$V$37,VLOOKUP(INDIRECT($C$5),Jornada!$C$8:$W$37,21,0)+2,0) -> 0 | AM10: =HLOOKUP($F10,Jornada!$I$4:$V$37,VLOOKUP(INDIRECT($C$5),Jornada!$C$8:$W$37,21,0)+3,0) -> 0 | AN10: =IF(AND(AL10>=$AL$5,AL10<$AN$5,H10>=$AL$5,H10<AL10),AL10-H10,IF(AND(AL10>$AI$7,AL10<=$AM$5,H10>=$AL$5,H10<=$AN$5),$AN$5-H10+AL10,IF(AND(AL10>=$AI$7,AL10<=$AM$5,H10>=$AI$7,H10<=$AM$5,H10<AL10),H10-AL10,0))) -> 0 | AO10: =IF(AP10>Q10,0,AP10) -> 0 | AP10: =IF(Q10=0,0,IF(AND(AM10>=$AL$5,AM10<$AN$5,K10>=$AL$5,K10<$AM$5,K10>AM10),K10-AM10,IF(AND(AM10>=$AL$5,AM10<$AN$5,K10<$AN$5,K10>AM10),K10-$AL$5,IF(AND(AM10>=$AI$7,AM10<$AM$5,K10<$AM$5),K10-AM10,IF(AND(AM10<>AI9,AM10>=$AI$7,AM10<=$AM$5,K10>$AM$5,K10>AM10),$AM$5-AM10,IF(AND(K10>$AL$5,K10<$AN$5),K10-$AL$5,IF(AND(K10>$AI$7,K10<$AM$5),$AN$5-$AL$5+K10,IF(AND(OR(K10>$AL$5,H10>$AO$5),AM10>=$AI$7,AM10<$AM$5,K10>$AM$5),(1+$AM$5-$AL$5)-AG10,0)))))))) -> 0
C11: =IF(Funcionários!C10=0,"",Funcionários!C10) | D11: =IF(D10=7,1,D10+1) -> 4 | E11: =IF(DAY(DATE('P Gerais'!$D$6,VLOOKUP($E$7,$W$7:$X$18,2,0),E10+1))>DAY(EOMONTH(DATE('P Gerais'!$D$6,VLOOKUP($E$7,$W$7:$X$18,2,0),E10),0)),DAY(DATE('P Gerais'!$D$6,VLOOKUP($E$7,$W$7:$X$18,2,0)+1,1)),DAY(DATE('P Gerais'!$D$6,VLOOKUP($E$7,$W$7:$X$18,2,0),E10+1))) -> 4 | F11: =VLOOKUP(D11,$AE$8:$AF$14,2,FALSE) -> Qua | M11: =IF(AND(H11=K11,H11<>0),$M$6-IF(J11<I11,$AJ$7+J11-I11,J11-I11),IF(H11>K11,(K11+1-H11)-IF(J11<I11,$AJ$7+J11-I11,J11-I11),(K11-H11)-IF(J11<I11,$AJ$7+J11-I11,J11-I11))) -> 0 | O11: =IF(OR(G11=0,G11="Férias",G11="Falta Justificada",G11="Feriado",G11="Folga (DSR)"),0,IF(G11="Falta Injustificada",HLOOKUP($F11,Jornada!$X$7:$AD$37,VLOOKUP(INDIRECT($C$5),Jornada!$C$8:$W$37,21,0),0),IF(HLOOKUP($F11,Jornada!$X$7:$AD$37,VLOOKUP(INDIRECT($C$5),Jornada!$C$8:$W$37,21,0),0)-M11>0,HLOOKUP($F11,Jornada!$X$7:$AD$37,VLOOKUP(INDIRECT($C$5),Jornada!$C$8:$W$37,21,0),0)-M11,0))) -> 0 | P11: =IF(HLOOKUP($F11,Jornada!$X$7:$AD$37,VLOOKUP(INDIRECT($C$5),Jornada!$C$8:$W$37,21,0),0)-M11<0,ABS(HLOOKUP($F11,Jornada!$X$7:$AD$37,VLOOKUP(INDIRECT($C$5),Jornada!$C$8:$W$37,21,0),0)-M11),0) -> 0 | Q11: =IF(G11="Normal",P11,IF(G11=0,0,IF(OR(G11="Feriado",G11="Férias"),IF(H11>K11,(K11+1-H11)-IF(J11<I11,$AJ$7+J11-I11,J11-I11),(K11-H11)-IF(J11<I11,$AJ$7+J11-I11,J11-I11)),IF(G11="Folga (DSR)",IF(H11>K11,(K11+1-H11)-IF(J11<I11,$AJ$7+J11-I11,J11-I11),(K11-H11)-IF(J11<I11,$AJ$7+J11-I11,J11-I11)),IF(G11="Falta Justificada",IF(H11>K11,(K11+1-H11)-IF(J11<I11,$AJ$7+J11-I11,J11-I11),(K11-H11)-IF(J11<I11,$AJ$7+J11-I11,J11-I11)),0))))) -> 0 | R11: =IF(Q11>$R$7,1,0) -> 0 | V11: =IF(AND(K5>U12,M5="Horas devidas"),"Negativo",IF(AND(U12>K5,U14>F58),"Negativo",0)) -> 0 | W11: Maio | X11: 5 | Z11: =IF(AND(M5="horas extras",Z13="positivo"),"positivo",IF(AND(M5="horas devidas",Z13="Negativo"),"Negativo",IF(AND(Z13="positivo",M5="horas devidas",U12>K5),"Positivo","Negativo"))) -> Negativo | AB11: =AB10+1 -> 4 | AC11: =WEEKDAY(AB11) -> 4 | AE11: 4 | AF11: Qua | AG11: =IF(J11<I11,$AJ$7+J11-I11,J11-I11) -> 0 | AH11: =IF(HLOOKUP($F11,Jornada!$X$7:$AD$37,VLOOKUP(INDIRECT($C$5),Jornada!$C$8:$W$37,21,0),0)=0,0,VLOOKUP(INDIRECT($C$5),Jornada!$C$8:$H$37,4,0)) -> 0 | AI11: =IF(AND(I11=0,J11=0,OR(H11<>0,K11<>0),HLOOKUP($F11,Jornada!$X$7:$AD$37,VLOOKUP(INDIRECT($C$5),Jornada!$C$8:$W$37,21,0),0)>$AK$5,M11>$AK$5),VLOOKUP(INDIRECT($C$5),Jornada!$C$8:$H$37,6,0),IF(AG11>VLOOKUP(INDIRECT($C$5),Jornada!$C$8:$H$37,6,0),IF(VLOOKUP(INDIRECT($C$5),Jornada!$C$8:$H$37,6,0)<AG11,0,ABS(VLOOKUP(INDIRECT($C$5),Jornada!$C$8:$H$37,6,0))-AG11),0)) -> 0 | AJ11: =($AJ$7-K11)+H11 -> 1 | AK11: =IF(AJ11<$AK$7,$AK$7-AJ11,$AI$7) -> 0 | AL11: =HLOOKUP($F11,Jornada!$I$5:$V$37,VLOOKUP(INDIRECT($C$5),Jornada!$C$8:$W$37,21,0)+2,0) -> 0 | AM11: =HLOOKUP($F11,Jornada!$I$4:$V$37,VLOOKUP(INDIRECT($C$5),Jornada!$C$8:$W$37,21,0)+3,0) -> 0 | AN11: =IF(AND(AL11>=$AL$5,AL11<$AN$5,H11>=$AL$5,H11<AL11),AL11-H11,IF(AND(AL11>$AI$7,AL11<=$AM$5,H11>=$AL$5,H11<=$AN$5),$AN$5-H11+AL11,IF(AND(AL11>=$AI$7,AL11<=$AM$5,H11>=$AI$7,H11<=$AM$5,H11<AL11),H11-AL11,0))) -> 0 | AO11: =IF(AP11>Q11,0,AP11) -> 0 | AP11: =IF(Q11=0,0,IF(AND(AM11>=$AL$5,AM11<$AN$5,K11>=$AL$5,K11<$AM$5,K11>AM11),K11-AM11,IF(AND(AM11>=$AL$5,AM11<$AN$5,K11<$AN$5,K11>AM11),K11-$AL$5,IF(AND(AM11>=$AI$7,AM11<$AM$5,K11<$AM$5),K11-AM11,IF(AND(AM11<>AI10,AM11>=$AI$7,AM11<=$AM$5,K11>$AM$5,K11>AM11),$AM$5-AM11,IF(AND(K11>$AL$5,K11<$AN$5),K11-$AL$5,IF(AND(K11>$AI$7,K11<$AM$5),$AN$5-$AL$5+K11,IF(AND(OR(K11>$AL$5,H11>$AO$5),AM11>=$AI$7,AM11<$AM$5,K11>$AM$5),(1+$AM$5-$AL$5)-AG11,0)))))))) -> 0
C12: =IF(Funcionários!C11=0,"",Funcionários!C11) | D12: =IF(D11=7,1,D11+1) -> 5 | E12: =IF(DAY(DATE('P Gerais'!$D$6,VLOOKUP($E$7,$W$7:$X$18,2,0),E11+1))>DAY(EOMONTH(DATE('P Gerais'!$D$6,VLOOKUP($E$7,$W$7:$X$18,2,0),E11),0)),DAY(DATE('P Gerais'!$D$6,VLOOKUP($E$7,$W$7:$X$18,2,0)+1,1)),DAY(DATE('P Gerais'!$D$6,VLOOKUP($E$7,$W$7:$X$18,2,0),E11+1))) -> 5 | F12: =VLOOKUP(D12,$AE$8:$AF$14,2,FALSE) -> Qui | M12: =IF(AND(H12=K12,H12<>0),$M$6-IF(J12<I12,$AJ$7+J12-I12,J12-I12),IF(H12>K12,(K12+1-H12)-IF(J12<I12,$AJ$7+J12-I12,J12-I12),(K12-H12)-IF(J12<I12,$AJ$7+J12-I12,J12-I12))) -> 0 | O12: =IF(OR(G12=0,G12="Férias",G12="Falta Justificada",G12="Feriado",G12="Folga (DSR)"),0,IF(G12="Falta Injustificada",HLOOKUP($F12,Jornada!$X$7:$AD$37,VLOOKUP(INDIRECT($C$5),Jornada!$C$8:$W$37,21,0),0),IF(HLOOKUP($F12,Jornada!$X$7:$AD$37,VLOOKUP(INDIRECT($C$5),Jornada!$C$8:$W$37,21,0),0)-M12>0,HLOOKUP($F12,Jornada!$X$7:$AD$37,VLOOKUP(INDIRECT($C$5),Jornada!$C$8:$W$37,21,0),0)-M12,0))) -> 0 | P12: =IF(HLOOKUP($F12,Jornada!$X$7:$AD$37,VLOOKUP(INDIRECT($C$5),Jornada!$C$8:$W$37,21,0),0)-M12<0,ABS(HLOOKUP($F12,Jornada!$X$7:$AD$37,VLOOKUP(INDIRECT($C$5),Jornada!$C$8:$W$37,21,0),0)-M12),0) -> 0 | Q12: =IF(G12="Normal",P12,IF(G12=0,0,IF(OR(G12="Feriado",G12="Férias"),IF(H12>K12,(K12+1-H12)-IF(J12<I12,$AJ$7+J12-I12,J12-I12),(K12-H12)-IF(J12<I12,$AJ$7+J12-I12,J12-I12)),IF(G12="Folga (DSR)",IF(H12>K12,(K12+1-H12)-IF(J12<I12,$AJ$7+J12-I12,J12-I12),(K12-H12)-IF(J12<I12,$AJ$7+J12-I12,J12-I12)),IF(G12="Falta Justificada",IF(H12>K12,(K12+1-H12)-IF(J12<I12,$AJ$7+J12-I12,J12-I12),(K12-H12)-IF(J12<I12,$AJ$7+J12-I12,J12-I12)),0))))) -> 0 | R12: =IF(Q12>$R$7,1,0) -> 0 | S12: Horas somados / subtraídas ao banco | U12: =IF(U14>=F58,(U14)-F58,(F58-U14)) -> 0 | W12: Junho | X12: 6 | AB12: =AB11+1 -> 5 | AC12: =WEEKDAY(AB12) -> 5 | AE12: 5 | AF12: Qui | AG12: =IF(J12<I12,$AJ$7+J12-I12,J12-I12) -> 0 | AH12: =IF(HLOOKUP($F12,Jornada!$X$7:$AD$37,VLOOKUP(INDIRECT($C$5),Jornada!$C$8:$W$37,21,0),0)=0,0,VLOOKUP(INDIRECT($C$5),Jornada!$C$8:$H$37,4,0)) -> 0 | AI12: =IF(AND(I12=0,J12=0,OR(H12<>0,K12<>0),HLOOKUP($F12,Jornada!$X$7:$AD$37,VLOOKUP(INDIRECT($C$5),Jornada!$C$8:$W$37,21,0),0)>$AK$5,M12>$AK$5),VLOOKUP(INDIRECT($C$5),Jornada!$C$8:$H$37,6,0),IF(AG12>VLOOKUP(INDIRECT($C$5),Jornada!$C$8:$H$37,6,0),IF(VLOOKUP(INDIRECT($C$5),Jornada!$C$8:$H$37,6,0)<AG12,0,ABS(VLOOKUP(INDIRECT($C$5),Jornada!$C$8:$H$37,6,0))-AG12),0)) -> 0 | AJ12: =($AJ$7-K12)+H12 -> 1 | AK12: =IF(AJ12<$AK$7,$AK$7-AJ12,$AI$7) -> 0 | AL12: =HLOOKUP($F12,Jornada!$I$5:$V$37,VLOOKUP(INDIRECT($C$5),Jornada!$C$8:$W$37,21,0)+2,0) -> 0 | AM12: =HLOOKUP($F12,Jornada!$I$4:$V$37,VLOOKUP(INDIRECT($C$5),Jornada!$C$8:$W$37,21,0)+3,0) -> 0 | AN12: =IF(AND(AL12>=$AL$5,AL12<$AN$5,H12>=$AL$5,H12<AL12),AL12-H12,IF(AND(AL12>$AI$7,AL12<=$AM$5,H12>=$AL$5,H12<=$AN$5),$AN$5-H12+AL12,IF(AND(AL12>=$AI$7,AL12<=$AM$5,H12>=$AI$7,H12<=$AM$5,H12<AL12),H12-AL12,0))) -> 0 | AO12: =IF(AP12>Q12,0,AP12) -> 0 | AP12: =IF(Q12=0,0,IF(AND(AM12>=$AL$5,AM12<$AN$5,K12>=$AL$5,K12<$AM$5,K12>AM12),K12-AM12,IF(AND(AM12>=$AL$5,AM12<$AN$5,K12<$AN$5,K12>AM12),K12-$AL$5,IF(AND(AM12>=$AI$7,AM12<$AM$5,K12<$AM$5),K12-AM12,IF(AND(AM12<>AI11,AM12>=$AI$7,AM12<=$AM$5,K12>$AM$5,K12>AM12),$AM$5-AM12,IF(AND(K12>$AL$5,K12<$AN$5),K12-$AL$5,IF(AND(K12>$AI$7,K12<$AM$5),$AN$5-$AL$5+K12,IF(AND(OR(K12>$AL$5,H12>$AO$5),AM12>=$AI$7,AM12<$AM$5,K12>$AM$5),(1+$AM$5-$AL$5)-AG12,0)))))))) -> 0
C13: =IF(Funcionários!C12=0,"",Funcionários!C12) | D13: =IF(D12=7,1,D12+1) -> 6 | E13: =IF(DAY(DATE('P Gerais'!$D$6,VLOOKUP($E$7,$W$7:$X$18,2,0),E12+1))>DAY(EOMONTH(DATE('P Gerais'!$D$6,VLOOKUP($E$7,$W$7:$X$18,2,0),E12),0)),DAY(DATE('P Gerais'!$D$6,VLOOKUP($E$7,$W$7:$X$18,2,0)+1,1)),DAY(DATE('P Gerais'!$D$6,VLOOKUP($E$7,$W$7:$X$18,2,0),E12+1))) -> 6 | F13: =VLOOKUP(D13,$AE$8:$AF$14,2,FALSE) -> Sex | M13: =IF(AND(H13=K13,H13<>0),$M$6-IF(J13<I13,$AJ$7+J13-I13,J13-I13),IF(H13>K13,(K13+1-H13)-IF(J13<I13,$AJ$7+J13-I13,J13-I13),(K13-H13)-IF(J13<I13,$AJ$7+J13-I13,J13-I13))) -> 0 | O13: =IF(OR(G13=0,G13="Férias",G13="Falta Justificada",G13="Feriado",G13="Folga (DSR)"),0,IF(G13="Falta Injustificada",HLOOKUP($F13,Jornada!$X$7:$AD$37,VLOOKUP(INDIRECT($C$5),Jornada!$C$8:$W$37,21,0),0),IF(HLOOKUP($F13,Jornada!$X$7:$AD$37,VLOOKUP(INDIRECT($C$5),Jornada!$C$8:$W$37,21,0),0)-M13>0,HLOOKUP($F13,Jornada!$X$7:$AD$37,VLOOKUP(INDIRECT($C$5),Jornada!$C$8:$W$37,21,0),0)-M13,0))) -> 0 | P13: =IF(HLOOKUP($F13,Jornada!$X$7:$AD$37,VLOOKUP(INDIRECT($C$5),Jornada!$C$8:$W$37,21,0),0)-M13<0,ABS(HLOOKUP($F13,Jornada!$X$7:$AD$37,VLOOKUP(INDIRECT($C$5),Jornada!$C$8:$W$37,21,0),0)-M13),0) -> 0 | Q13: =IF(G13="Normal",P13,IF(G13=0,0,IF(OR(G13="Feriado",G13="Férias"),IF(H13>K13,(K13+1-H13)-IF(J13<I13,$AJ$7+J13-I13,J13-I13),(K13-H13)-IF(J13<I13,$AJ$7+J13-I13,J13-I13)),IF(G13="Folga (DSR)",IF(H13>K13,(K13+1-H13)-IF(J13<I13,$AJ$7+J13-I13,J13-I13),(K13-H13)-IF(J13<I13,$AJ$7+J13-I13,J13-I13)),IF(G13="Falta Justificada",IF(H13>K13,(K13+1-H13)-IF(J13<I13,$AJ$7+J13-I13,J13-I13),(K13-H13)-IF(J13<I13,$AJ$7+J13-I13,J13-I13)),0))))) -> 0 | R13: =IF(Q13>$R$7,1,0) -> 0 | W13: Julho | X13: 7 | Z13: =IF(U14>F58,"Negativo","Positivo") -> Positivo | AB13: =AB12+1 -> 6 | AC13: =WEEKDAY(AB13) -> 6 | AE13: 6 | AF13: Sex | AG13: =IF(J13<I13,$AJ$7+J13-I13,J13-I13) -> 0 | AH13: =IF(HLOOKUP($F13,Jornada!$X$7:$AD$37,VLOOKUP(INDIRECT($C$5),Jornada!$C$8:$W$37,21,0),0)=0,0,VLOOKUP(INDIRECT($C$5),Jornada!$C$8:$H$37,4,0)) -> 0 | AI13: =IF(AND(I13=0,J13=0,OR(H13<>0,K13<>0),HLOOKUP($F13,Jornada!$X$7:$AD$37,VLOOKUP(INDIRECT($C$5),Jornada!$C$8:$W$37,21,0),0)>$AK$5,M13>$AK$5),VLOOKUP(INDIRECT($C$5),Jornada!$C$8:$H$37,6,0),IF(AG13>VLOOKUP(INDIRECT($C$5),Jornada!$C$8:$H$37,6,0),IF(VLOOKUP(INDIRECT($C$5),Jornada!$C$8:$H$37,6,0)<AG13,0,ABS(VLOOKUP(INDIRECT($C$5),Jornada!$C$8:$H$37,6,0))-AG13),0)) -> 0 | AJ13: =($AJ$7-K13)+H13 -> 1 | AK13: =IF(AJ13<$AK$7,$AK$7-AJ13,$AI$7) -> 0 | AL13: =HLOOKUP($F13,Jornada!$I$5:$V$37,VLOOKUP(INDIRECT($C$5),Jornada!$C$8:$W$37,21,0)+2,0) -> 0 | AM13: =HLOOKUP($F13,Jornada!$I$4:$V$37,VLOOKUP(INDIRECT($C$5),Jornada!$C$8:$W$37,21,0)+3,0) -> 0 | AN13: =IF(AND(AL13>=$AL$5,AL13<$AN$5,H13>=$AL$5,H13<AL13),AL13-H13,IF(AND(AL13>$AI$7,AL13<=$AM$5,H13>=$AL$5,H13<=$AN$5),$AN$5-H13+AL13,IF(AND(AL13>=$AI$7,AL13<=$AM$5,H13>=$AI$7,H13<=$AM$5,H13<AL13),H13-AL13,0))) -> 0 | AO13: =IF(AP13>Q13,0,AP13) -> 0 | AP13: =IF(Q13=0,0,IF(AND(AM13>=$AL$5,AM13<$AN$5,K13>=$AL$5,K13<$AM$5,K13>AM13),K13-AM13,IF(AND(AM13>=$AL$5,AM13<$AN$5,K13<$AN$5,K13>AM13),K13-$AL$5,IF(AND(AM13>=$AI$7,AM13<$AM$5,K13<$AM$5),K13-AM13,IF(AND(AM13<>AI12,AM13>=$AI$7,AM13<=$AM$5,K13>$AM$5,K13>AM13),$AM$5-AM13,IF(AND(K13>$AL$5,K13<$AN$5),K13-$AL$5,IF(AND(K13>$AI$7,K13<$AM$5),$AN$5-$AL$5+K13,IF(AND(OR(K13>$AL$5,H13>$AO$5),AM13>=$AI$7,AM13<$AM$5,K13>$AM$5),(1+$AM$5-$AL$5)-AG13,0)))))))) -> 0
C14: =IF(Funcionários!C13=0,"",Funcionários!C13) | D14: =IF(D13=7,1,D13+1) -> 7 | E14: =IF(DAY(DATE('P Gerais'!$D$6,VLOOKUP($E$7,$W$7:$X$18,2,0),E13+1))>DAY(EOMONTH(DATE('P Gerais'!$D$6,VLOOKUP($E$7,$W$7:$X$18,2,0),E13),0)),DAY(DATE('P Gerais'!$D$6,VLOOKUP($E$7,$W$7:$X$18,2,0)+1,1)),DAY(DATE('P Gerais'!$D$6,VLOOKUP($E$7,$W$7:$X$18,2,0),E13+1))) -> 7 | F14: =VLOOKUP(D14,$AE$8:$AF$14,2,FALSE) -> Sáb | M14: =IF(AND(H14=K14,H14<>0),$M$6-IF(J14<I14,$AJ$7+J14-I14,J14-I14),IF(H14>K14,(K14+1-H14)-IF(J14<I14,$AJ$7+J14-I14,J14-I14),(K14-H14)-IF(J14<I14,$AJ$7+J14-I14,J14-I14))) -> 0 | O14: =IF(OR(G14=0,G14="Férias",G14="Falta Justificada",G14="Feriado",G14="Folga (DSR)"),0,IF(G14="Falta Injustificada",HLOOKUP($F14,Jornada!$X$7:$AD$37,VLOOKUP(INDIRECT($C$5),Jornada!$C$8:$W$37,21,0),0),IF(HLOOKUP($F14,Jornada!$X$7:$AD$37,VLOOKUP(INDIRECT($C$5),Jornada!$C$8:$W$37,21,0),0)-M14>0,HLOOKUP($F14,Jornada!$X$7:$AD$37,VLOOKUP(INDIRECT($C$5),Jornada!$C$8:$W$37,21,0),0)-M14,0))) -> 0 | P14: =IF(HLOOKUP($F14,Jornada!$X$7:$AD$37,VLOOKUP(INDIRECT($C$5),Jornada!$C$8:$W$37,21,0),0)-M14<0,ABS(HLOOKUP($F14,Jornada!$X$7:$AD$37,VLOOKUP(INDIRECT($C$5),Jornada!$C$8:$W$37,21,0),0)-M14),0) -> 0 | Q14: =IF(G14="Normal",P14,IF(G14=0,0,IF(OR(G14="Feriado",G14="Férias"),IF(H14>K14,(K14+1-H14)-IF(J14<I14,$AJ$7+J14-I14,J14-I14),(K14-H14)-IF(J14<I14,$AJ$7+J14-I14,J14-I14)),IF(G14="Folga (DSR)",IF(H14>K14,(K14+1-H14)-IF(J14<I14,$AJ$7+J14-I14,J14-I14),(K14-H14)-IF(J14<I14,$AJ$7+J14-I14,J14-I14)),IF(G14="Falta Justificada",IF(H14>K14,(K14+1-H14)-IF(J14<I14,$AJ$7+J14-I14,J14-I14),(K14-H14)-IF(J14<I14,$AJ$7+J14-I14,J14-I14)),0))))) -> 0 | R14: =IF(Q14>$R$7,1,0) -> 0 | S14: Total de horas devidas | U14: =SUM(O8:O38) -> 0 | W14: Agosto | X14: 8 | AB14: =AB13+1 -> 7 | AC14: =WEEKDAY(AB14) -> 7 | AE14: 7 | AF14: Sáb | AG14: =IF(J14<I14,$AJ$7+J14-I14,J14-I14) -> 0 | AH14: =IF(HLOOKUP($F14,Jornada!$X$7:$AD$37,VLOOKUP(INDIRECT($C$5),Jornada!$C$8:$W$37,21,0),0)=0,0,VLOOKUP(INDIRECT($C$5),Jornada!$C$8:$H$37,4,0)) -> 0 | AI14: =IF(AND(I14=0,J14=0,OR(H14<>0,K14<>0),HLOOKUP($F14,Jornada!$X$7:$AD$37,VLOOKUP(INDIRECT($C$5),Jornada!$C$8:$W$37,21,0),0)>$AK$5,M14>$AK$5),VLOOKUP(INDIRECT($C$5),Jornada!$C$8:$H$37,6,0),IF(AG14>VLOOKUP(INDIRECT($C$5),Jornada!$C$8:$H$37,6,0),IF(VLOOKUP(INDIRECT($C$5),Jornada!$C$8:$H$37,6,0)<AG14,0,ABS(VLOOKUP(INDIRECT($C$5),Jornada!$C$8:$H$37,6,0))-AG14),0)) -> 0 | AJ14: =($AJ$7-K14)+H14 -> 1 | AK14: =IF(AJ14<$AK$7,$AK$7-AJ14,$AI$7) -> 0 | AL14: =HLOOKUP($F14,Jornada!$I$5:$V$37,VLOOKUP(INDIRECT($C$5),Jornada!$C$8:$W$37,21,0)+2,0) -> 0 | AM14: =HLOOKUP($F14,Jornada!$I$4:$V$37,VLOOKUP(INDIRECT($C$5),Jornada!$C$8:$W$37,21,0)+3,0) -> 0 | AN14: =IF(AND(AL14>=$AL$5,AL14<$AN$5,H14>=$AL$5,H14<AL14),AL14-H14,IF(AND(AL14>$AI$7,AL14<=$AM$5,H14>=$AL$5,H14<=$AN$5),$AN$5-H14+AL14,IF(AND(AL14>=$AI$7,AL14<=$AM$5,H14>=$AI$7,H14<=$AM$5,H14<AL14),H14-AL14,0))) -> 0 | AO14: =IF(AP14>Q14,0,AP14) -> 0 | AP14: =IF(Q14=0,0,IF(AND(AM14>=$AL$5,AM14<$AN$5,K14>=$AL$5,K14<$AM$5,K14>AM14),K14-AM14,IF(AND(AM14>=$AL$5,AM14<$AN$5,K14<$AN$5,K14>AM14),K14-$AL$5,IF(AND(AM14>=$AI$7,AM14<$AM$5,K14<$AM$5),K14-AM14,IF(AND(AM14<>AI13,AM14>=$AI$7,AM14<=$AM$5,K14>$AM$5,K14>AM14),$AM$5-AM14,IF(AND(K14>$AL$5,K14<$AN$5),K14-$AL$5,IF(AND(K14>$AI$7,K14<$AM$5),$AN$5-$AL$5+K14,IF(AND(OR(K14>$AL$5,H14>$AO$5),AM14>=$AI$7,AM14<$AM$5,K14>$AM$5),(1+$AM$5-$AL$5)-AG14,0)))))))) -> 0
C15: =IF(Funcionários!C14=0,"",Funcionários!C14) | D15: =IF(D14=7,1,D14+1) -> 1 | E15: =IF(DAY(DATE('P Gerais'!$D$6,VLOOKUP($E$7,$W$7:$X$18,2,0),E14+1))>DAY(EOMONTH(DATE('P Gerais'!$D$6,VLOOKUP($E$7,$W$7:$X$18,2,0),E14),0)),DAY(DATE('P Gerais'!$D$6,VLOOKUP($E$7,$W$7:$X$18,2,0)+1,1)),DAY(DATE('P Gerais'!$D$6,VLOOKUP($E$7,$W$7:$X$18,2,0),E14+1))) -> 8 | F15: =VLOOKUP(D15,$AE$8:$AF$14,2,FALSE) -> Dom | M15: =IF(AND(H15=K15,H15<>0),$M$6-IF(J15<I15,$AJ$7+J15-I15,J15-I15),IF(H15>K15,(K15+1-H15)-IF(J15<I15,$AJ$7+J15-I15,J15-I15),(K15-H15)-IF(J15<I15,$AJ$7+J15-I15,J15-I15))) -> 0 | O15: =IF(OR(G15=0,G15="Férias",G15="Falta Justificada",G15="Feriado",G15="Folga (DSR)"),0,IF(G15="Falta Injustificada",HLOOKUP($F15,Jornada!$X$7:$AD$37,VLOOKUP(INDIRECT($C$5),Jornada!$C$8:$W$37,21,0),0),IF(HLOOKUP($F15,Jornada!$X$7:$AD$37,VLOOKUP(INDIRECT($C$5),Jornada!$C$8:$W$37,21,0),0)-M15>0,HLOOKUP($F15,Jornada!$X$7:$AD$37,VLOOKUP(INDIRECT($C$5),Jornada!$C$8:$W$37,21,0),0)-M15,0))) -> 0 | P15: =IF(HLOOKUP($F15,Jornada!$X$7:$AD$37,VLOOKUP(INDIRECT($C$5),Jornada!$C$8:$W$37,21,0),0)-M15<0,ABS(HLOOKUP($F15,Jornada!$X$7:$AD$37,VLOOKUP(INDIRECT($C$5),Jornada!$C$8:$W$37,21,0),0)-M15),0) -> 0 | Q15: =IF(G15="Normal",P15,IF(G15=0,0,IF(OR(G15="Feriado",G15="Férias"),IF(H15>K15,(K15+1-H15)-IF(J15<I15,$AJ$7+J15-I15,J15-I15),(K15-H15)-IF(J15<I15,$AJ$7+J15-I15,J15-I15)),IF(G15="Folga (DSR)",IF(H15>K15,(K15+1-H15)-IF(J15<I15,$AJ$7+J15-I15,J15-I15),(K15-H15)-IF(J15<I15,$AJ$7+J15-I15,J15-I15)),IF(G15="Falta Justificada",IF(H15>K15,(K15+1-H15)-IF(J15<I15,$AJ$7+J15-I15,J15-I15),(K15-H15)-IF(J15<I15,$AJ$7+J15-I15,J15-I15)),0))))) -> 0 | R15: =IF(Q15>$R$7,1,0) -> 0 | W15: Setembro | X15: 9 | AB15: =AB14+1 -> 8 | AC15: =WEEKDAY(AB15) -> 1 | AG15: =IF(J15<I15,$AJ$7+J15-I15,J15-I15) -> 0 | AH15: =IF(HLOOKUP($F15,Jornada!$X$7:$AD$37,VLOOKUP(INDIRECT($C$5),Jornada!$C$8:$W$37,21,0),0)=0,0,VLOOKUP(INDIRECT($C$5),Jornada!$C$8:$H$37,4,0)) -> 0 | AI15: =IF(AND(I15=0,J15=0,OR(H15<>0,K15<>0),HLOOKUP($F15,Jornada!$X$7:$AD$37,VLOOKUP(INDIRECT($C$5),Jornada!$C$8:$W$37,21,0),0)>$AK$5,M15>$AK$5),VLOOKUP(INDIRECT($C$5),Jornada!$C$8:$H$37,6,0),IF(AG15>VLOOKUP(INDIRECT($C$5),Jornada!$C$8:$H$37,6,0),IF(VLOOKUP(INDIRECT($C$5),Jornada!$C$8:$H$37,6,0)<AG15,0,ABS(VLOOKUP(INDIRECT($C$5),Jornada!$C$8:$H$37,6,0))-AG15),0)) -> 0 | AJ15: =($AJ$7-K15)+H15 -> 1 | AK15: =IF(AJ15<$AK$7,$AK$7-AJ15,$AI$7) -> 0 | AL15: =HLOOKUP($F15,Jornada!$I$5:$V$37,VLOOKUP(INDIRECT($C$5),Jornada!$C$8:$W$37,21,0)+2,0) -> 0 | AM15: =HLOOKUP($F15,Jornada!$I$4:$V$37,VLOOKUP(INDIRECT($C$5),Jornada!$C$8:$W$37,21,0)+3,0) -> 0 | AN15: =IF(AND(AL15>=$AL$5,AL15<$AN$5,H15>=$AL$5,H15<AL15),AL15-H15,IF(AND(AL15>$AI$7,AL15<=$AM$5,H15>=$AL$5,H15<=$AN$5),$AN$5-H15+AL15,IF(AND(AL15>=$AI$7,AL15<=$AM$5,H15>=$AI$7,H15<=$AM$5,H15<AL15),H15-AL15,0))) -> 0 | AO15: =IF(AP15>Q15,0,AP15) -> 0 | AP15: =IF(Q15=0,0,IF(AND(AM15>=$AL$5,AM15<$AN$5,K15>=$AL$5,K15<$AM$5,K15>AM15),K15-AM15,IF(AND(AM15>=$AL$5,AM15<$AN$5,K15<$AN$5,K15>AM15),K15-$AL$5,IF(AND(AM15>=$AI$7,AM15<$AM$5,K15<$AM$5),K15-AM15,IF(AND(AM15<>AI14,AM15>=$AI$7,AM15<=$AM$5,K15>$AM$5,K15>AM15),$AM$5-AM15,IF(AND(K15>$AL$5,K15<$AN$5),K15-$AL$5,IF(AND(K15>$AI$7,K15<$AM$5),$AN$5-$AL$5+K15,IF(AND(OR(K15>$AL$5,H15>$AO$5),AM15>=$AI$7,AM15<$AM$5,K15>$AM$5),(1+$AM$5-$AL$5)-AG15,0)))))))) -> 0
C16: =IF(Funcionários!C15=0,"",Funcionários!C15) | D16: =IF(D15=7,1,D15+1) -> 2 | E16: =IF(DAY(DATE('P Gerais'!$D$6,VLOOKUP($E$7,$W$7:$X$18,2,0),E15+1))>DAY(EOMONTH(DATE('P Gerais'!$D$6,VLOOKUP($E$7,$W$7:$X$18,2,0),E15),0)),DAY(DATE('P Gerais'!$D$6,VLOOKUP($E$7,$W$7:$X$18,2,0)+1,1)),DAY(DATE('P Gerais'!$D$6,VLOOKUP($E$7,$W$7:$X$18,2,0),E15+1))) -> 9 | F16: =VLOOKUP(D16,$AE$8:$AF$14,2,FALSE) -> Seg | M16: =IF(AND(H16=K16,H16<>0),$M$6-IF(J16<I16,$AJ$7+J16-I16,J16-I16),IF(H16>K16,(K16+1-H16)-IF(J16<I16,$AJ$7+J16-I16,J16-I16),(K16-H16)-IF(J16<I16,$AJ$7+J16-I16,J16-I16))) -> 0 | O16: =IF(OR(G16=0,G16="Férias",G16="Falta Justificada",G16="Feriado",G16="Folga (DSR)"),0,IF(G16="Falta Injustificada",HLOOKUP($F16,Jornada!$X$7:$AD$37,VLOOKUP(INDIRECT($C$5),Jornada!$C$8:$W$37,21,0),0),IF(HLOOKUP($F16,Jornada!$X$7:$AD$37,VLOOKUP(INDIRECT($C$5),Jornada!$C$8:$W$37,21,0),0)-M16>0,HLOOKUP($F16,Jornada!$X$7:$AD$37,VLOOKUP(INDIRECT($C$5),Jornada!$C$8:$W$37,21,0),0)-M16,0))) -> 0 | P16: =IF(HLOOKUP($F16,Jornada!$X$7:$AD$37,VLOOKUP(INDIRECT($C$5),Jornada!$C$8:$W$37,21,0),0)-M16<0,ABS(HLOOKUP($F16,Jornada!$X$7:$AD$37,VLOOKUP(INDIRECT($C$5),Jornada!$C$8:$W$37,21,0),0)-M16),0) -> 0 | Q16: =IF(G16="Normal",P16,IF(G16=0,0,IF(OR(G16="Feriado",G16="Férias"),IF(H16>K16,(K16+1-H16)-IF(J16<I16,$AJ$7+J16-I16,J16-I16),(K16-H16)-IF(J16<I16,$AJ$7+J16-I16,J16-I16)),IF(G16="Folga (DSR)",IF(H16>K16,(K16+1-H16)-IF(J16<I16,$AJ$7+J16-I16,J16-I16),(K16-H16)-IF(J16<I16,$AJ$7+J16-I16,J16-I16)),IF(G16="Falta Justificada",IF(H16>K16,(K16+1-H16)-IF(J16<I16,$AJ$7+J16-I16,J16-I16),(K16-H16)-IF(J16<I16,$AJ$7+J16-I16,J16-I16)),0))))) -> 0 | R16: =IF(Q16>$R$7,1,0) -> 0 | S16: Total de horas extras | U16: =SUM(Q8:Q38) -> 0 | W16: Outubro | X16: 10 | AB16: =AB15+1 -> 9 | AC16: =WEEKDAY(AB16) -> 2 | AG16: =IF(J16<I16,$AJ$7+J16-I16,J16-I16) -> 0 | AH16: =IF(HLOOKUP($F16,Jornada!$X$7:$AD$37,VLOOKUP(INDIRECT($C$5),Jornada!$C$8:$W$37,21,0),0)=0,0,VLOOKUP(INDIRECT($C$5),Jornada!$C$8:$H$37,4,0)) -> 0 | AI16: =IF(AND(I16=0,J16=0,OR(H16<>0,K16<>0),HLOOKUP($F16,Jornada!$X$7:$AD$37,VLOOKUP(INDIRECT($C$5),Jornada!$C$8:$W$37,21,0),0)>$AK$5,M16>$AK$5),VLOOKUP(INDIRECT($C$5),Jornada!$C$8:$H$37,6,0),IF(AG16>VLOOKUP(INDIRECT($C$5),Jornada!$C$8:$H$37,6,0),IF(VLOOKUP(INDIRECT($C$5),Jornada!$C$8:$H$37,6,0)<AG16,0,ABS(VLOOKUP(INDIRECT($C$5),Jornada!$C$8:$H$37,6,0))-AG16),0)) -> 0 | AJ16: =($AJ$7-K16)+H16 -> 1 | AK16: =IF(AJ16<$AK$7,$AK$7-AJ16,$AI$7) -> 0 | AL16: =HLOOKUP($F16,Jornada!$I$5:$V$37,VLOOKUP(INDIRECT($C$5),Jornada!$C$8:$W$37,21,0)+2,0) -> 0 | AM16: =HLOOKUP($F16,Jornada!$I$4:$V$37,VLOOKUP(INDIRECT($C$5),Jornada!$C$8:$W$37,21,0)+3,0) -> 0 | AN16: =IF(AND(AL16>=$AL$5,AL16<$AN$5,H16>=$AL$5,H16<AL16),AL16-H16,IF(AND(AL16>$AI$7,AL16<=$AM$5,H16>=$AL$5,H16<=$AN$5),$AN$5-H16+AL16,IF(AND(AL16>=$AI$7,AL16<=$AM$5,H16>=$AI$7,H16<=$AM$5,H16<AL16),H16-AL16,0))) -> 0 | AO16: =IF(AP16>Q16,0,AP16) -> 0 | AP16: =IF(Q16=0,0,IF(AND(AM16>=$AL$5,AM16<$AN$5,K16>=$AL$5,K16<$AM$5,K16>AM16),K16-AM16,IF(AND(AM16>=$AL$5,AM16<$AN$5,K16<$AN$5,K16>AM16),K16-$AL$5,IF(AND(AM16>=$AI$7,AM16<$AM$5,K16<$AM$5),K16-AM16,IF(AND(AM16<>AI15,AM16>=$AI$7,AM16<=$AM$5,K16>$AM$5,K16>AM16),$AM$5-AM16,IF(AND(K16>$AL$5,K16<$AN$5),K16-$AL$5,IF(AND(K16>$AI$7,K16<$AM$5),$AN$5-$AL$5+K16,IF(AND(OR(K16>$AL$5,H16>$AO$5),AM16>=$AI$7,AM16<$AM$5,K16>$AM$5),(1+$AM$5-$AL$5)-AG16,0)))))))) -> 0
