Workbook

Sheet BD_Geral
U2: CRONOGRAMA
U3: STATUS | AI3: DATA | AJ3: EVOLUÇÃO | AK3: CONFORMIDADE | AM3: CICLO ONBOARDING | AS3: CICLO ONBOARDING | AU3: SUCESSO | AY3: CATEGORIA | BM3: CATEGORIA
B4: # | C4: CLIENTE | D4: NOME CONTABILIDADE | E4: NOME CONTADOR | F4: NOME CS | H4: 1 | I4: 2 | J4: 3 | K4: 4 | L4: 5 | M4: 6 | N4: 7 | O4: 8 | P4: 9 | Q4: 10 | R4: 11 | S4: 12 | T4: 13 | AM4: GERAL | AO4: Escolha das Empresas | AP4: Aprendizado com a Plataforma | AQ4: Contábil em dia | AR4: Subir balancetes pro Nucont | AS4: Visita aos Clientes | AU4: Contagem | AV4: Data Primeiro | AW4: Data Último | AY4: Ser valorizado/ receber elogio por parte do empresário | AZ4: Reposicionamento no mercado (jeito de conversar/ identidade) | BA4: Melhorar perfil da carteira de clientes | BB4: Reduzir inadimplência | BC4: Reajustar honorário contábil | BD4: =#REF! -> #REF! | BE4: Ter metas claras para a equipe do contábil/ rearranjo do setor/ direcionamento do setor | BF4: Diminuir atraso médio dos lançamentos contábeis | BG4: Clientes enviarem documentação mais organizada/ via tecnologia | BH4: Melhorar ambiente de trabalho do contábil por ter metas e processos claros | BI4: Identificar problemas de apuração contábil | BJ4: =#REF! -> #REF! | BK4: Conseguir indicação de novos clientes | BL4: Conseguir fechar um novo cliente vindo de indicação | BM4: Conseguir um novo cliente por proposta diferenciada | BO4: DATA | CI4: DATA
B5: 1 | C5: Contabilidade 1 | D5: =Cronograma!G6 -> Nome Empresa | E5: =Cronograma!G7 -> Nome Empresário | F5: =Cronograma!G8 -> Nome Contabilidade | H5: =Cronograma!D13 -> 0 | I5: =Cronograma!D14 -> 0 | J5: =Cronograma!D15 -> 0 | K5: =Cronograma!D16 -> 0 | L5: =Cronograma!D17 -> 0 | M5: =Cronograma!D18 -> 0 | N5: =Cronograma!D19 -> 0 | O5: =Cronograma!D20 -> 0 | P5: =Cronograma!D21 -> 0 | Q5: =Cronograma!D22 -> 0 | R5: =Cronograma!D23 -> 0 | S5: =Cronograma!D24 -> 0 | T5: =Cronograma!D25 -> 0 | V5: =Cronograma!K13 -> 42991 | W5: =Cronograma!K14 -> 42992 | X5: =Cronograma!K15 -> 42993 | Y5: =Cronograma!K16 -> 42994 | Z5: =Cronograma!K17 -> 42995 | AA5: =Cronograma!K18 -> 42996 | AB5: =Cronograma!K19 -> 42997 | AC5: =Cronograma!K20 -> 42998 | AD5: =Cronograma!K21 -> 42999 | AE5: =Cronograma!K22 -> 43000 | AF5: =Cronograma!K23 | AG5: =Cronograma!K24 | AH5: =Cronograma!K25 | AJ5: =Cronograma!R9 -> 0 | AK5: =Cronograma!T9 -> 0 | AM5: =Cronograma!AB9 -> 0 | AO5: =Cronograma!$AJ$30 -> 0 | AP5: =Cronograma!AJ31 -> 0 | AQ5: =Cronograma!AJ32 -> 0 | AR5: =Cronograma!AJ33 -> 0 | AS5: =Cronograma!AJ34 -> 0 | AU5: =Cronograma!$AA$47 -> 5 | AV5: =Cronograma!AF45 -> 42878 | AW5: =Cronograma!AF49 -> 42899 | AY5: =COUNTIF(Cronograma!$G$45:$L$87,BD_Geral!AY4) -> 0 | AZ5: =COUNTIF(Cronograma!$G$45:$L$87,BD_Geral!AZ4) -> 0 | BA5: =COUNTIF(Cronograma!$G$45:$L$87,BD_Geral!BA4) -> 0 | BB5: =COUNTIF(Cronograma!$G$45:$L$87,BD_Geral!BB4) -> 0 | BC5: =COUNTIF(Cronograma!$G$45:$L$87,BD_Geral!BC4) -> 0 | BE5: =COUNTIF(Cronograma!$G$45:$L$87,BD_Geral!BE4) -> 0 | BF5: =COUNTIF(Cronograma!$G$45:$L$87,BD_Geral!BF4) -> 0 | BG5: =COUNTIF(Cronograma!$G$45:$L$87,BD_Geral!BG4) -> 0 | BH5: =COUNTIF(Cronograma!$G$45:$L$87,BD_Geral!BH4) -> 0 | BI5: =COUNTIF(Cronograma!$G$45:$L$87,BD_Geral!BI4) -> 0 | BK5: =COUNTIF(Cronograma!$G$45:$L$87,BD_Geral!BK4) -> 0 | BL5: =COUNTIF(Cronograma!$G$45:$L$87,BD_Geral!BL4) -> 0 | BM5: =COUNTIF(Cronograma!$G$45:$L$87,BD_Geral!BM4) -> 0 | BO5: =Cronograma!E45 -> 42878 | BP5: =Cronograma!E47 -> 42879 | BQ5: =Cronograma!E49 -> 42881 | BR5: =Cronograma!E51 -> 42882 | BS5: =Cronograma!E53 -> 42883 | BT5: =Cronograma!E55 -> 42884 | BU5: =Cronograma!E57 -> 42885 | BV5: =Cronograma!E59 -> 42886 | BW5: =Cronograma!E61 -> 42887 | BX5: =Cronograma!E63 -> 42888 | BY5: =Cronograma!E65 -> 42889 | BZ5: =Cronograma!E67 -> 42890 | CA5: =Cronograma!E69 -> 42891 | CB5: =Cronograma!E71 -> 42892 | CC5: =Cronograma!E73 -> 42893 | CD5: =Cronograma!E75 -> 42894 | CE5: =Cronograma!E77 -> 42895 | CF5: =Cronograma!E79 -> 42896 | CG5: =Cronograma!E81 -> 42897 | CH5: =Cronograma!E83 -> 42898 | CI5: =Cronograma!E85 -> 42899
B6: 2 | C6: Contabilidade 2

Sheet Cronograma
B3: Cronograma de Onboarding
D6: Empresa | G6: Nome Empresa
D7: Empresário | G7: Nome Empresário | AM7: Onboarding | BL7: 1 | BN7: =BE8 -> GESTÃO E ESTRATÉGIA | CS7: =IF(BL7<>0,CONCATENATE(BM7,". ",BN7),CONCATENATE("------- ",BM7,". ",BN7)) -> . GESTÃO E ESTRATÉGIA
D8: Contabilidade | G8: Nome Contabilidade | T8: =TODAY() -> 43161 | U8: Evolução Esperada | AM8: Etapas do Cronograma ( | AN8: =COUNTIF(D13:D25,1) -> 0 | AO8: =AP8-AN8 -> 10 | AP8: =COUNTA(F13:H25) -> 10 | BE8: GESTÃO E ESTRATÉGIA | BM8: 1 | BN8: Receber recomendações para melhorar meu negócio | CR8: =COUNTIF($G$45:$L$86,CS8) -> 0 | CS8: =IF(BL8<>0,CONCATENATE(BM8,". ",BN8),CONCATENATE("------- ",BM8,". ",BN8)) -> ------- 1. Receber recomendações para melhorar meu negócio
AB9: =AN14 -> 0 | AM9: Documentos Prioritários ( | AN9: =R19*10 -> 0 | AO9: =AP9-AN9 -> 10 | AP9: 10 | BM9: 2 | BN9: Receber relatórios de desempenho e diagnósticos que me ajudam a tomar decisão | CR9: =COUNTIF($G$45:$L$86,CS9) -> 0 | CS9: =IF(BL9<>0,CONCATENATE(BM9,". ",BN9),CONCATENATE("------- ",BM9,". ",BN9)) -> ------- 2. Receber relatórios de desempenho e diagnósticos que me ajudam a tomar decisão
X10: =VLOOKUP(T8,K13:Q24,7,TRUE()) -> 0 | AM10: Demais Documentos ( | AN10: =V19*10 -> 0 | AO10: =AP10-AN10 -> 10 | AP10: 10 | BM10: 3 | BN10: Receber apoio na gestão financeira | CR10: =COUNTIF($G$45:$L$86,CS10) -> 0 | CS10: =IF(BL10<>0,CONCATENATE(BM10,". ",BN10),CONCATENATE("------- ",BM10,". ",BN10)) -> ------- 3. Receber apoio na gestão financeira
D11: Status | E11: # | F11: Etapa | I11: Etapa Crítica | J11: Responsável | K11: Data | M11: Duração | P11: DOCUMENTAÇÃO | AM11: Sucessos definidos ( | AN11: =IF(COUNTIF(BL8:BL27,1)>5,10,COUNTIF(BL8:BL27,1)*2) -> 0 | AO11: =AP11-AN11 -> 10 | AP11: 10 | BM11: 4 | BN11: Receber apoio para acessar linhas de crédito | CR11: =COUNTIF($G$45:$L$86,CS11) -> 0 | CS11: =IF(BL11<>0,CONCATENATE(BM11,". ",BN11),CONCATENATE("------- ",BM11,". ",BN11)) -> ------- 4. Receber apoio para acessar linhas de crédito
BM12: 5 | BN12: Receber ajuda na elaboração do meu Plano de Negócios | CR12: =COUNTIF($G$45:$L$86,CS12) -> 0 | CS12: =IF(BL12<>0,CONCATENATE(BM12,". ",BN12),CONCATENATE("------- ",BM12,". ",BN12)) -> ------- 5. Receber ajuda na elaboração do meu Plano de Negócios
C13: =WEEKDAY(L13) -> 4 | D13: 0 | E13: 1 | F13: Acordo entre contabilidade e empresa | J13: Ambos | K13: 42991 | L13: =K13 -> 42991 | M13: =IFERROR(K13-$K$13,"") -> 0 | O13: =E13 -> 1 | P13: Prioditários | T13: Demais | AN13: =SUM(AN8:AN12) -> 0 | AP13: =SUM(AP8:AP12) -> 40 | BN13: =BE14 -> PARTE LEGAL E TRIBUTÁRIA | CS13: =IF(BL13<>0,CONCATENATE(BM13,". ",BN13),CONCATENATE("------- ",BM13,". ",BN13)) -> ------- . PARTE LEGAL E TRIBUTÁRIA
C14: =WEEKDAY(L14) -> 5 | D14: 0 | E14: 2 | F14: Comunicação contabilidade anterior | I14: -1 | J14: Empresa | K14: 42992 | L14: =K14 -> 42992 | M14: =IFERROR(K14-$K$13,"") -> 1 | O14: =E14 -> 2 | AN14: =(AN13/(AP13)) -> 0 | BE14: PARTE LEGAL E TRIBUTÁRIA | BM14: 6 | BN14: Ter economia fiscal através de planejamento tributário | CR14: =COUNTIF($G$45:$L$86,CS14) -> 0 | CS14: =IF(BL14<>0,CONCATENATE(BM14,". ",BN14),CONCATENATE("------- ",BM14,". ",BN14)) -> ------- 6. Ter economia fiscal através de planejamento tributário
C15: =WEEKDAY(L15) -> 6 | D15: 0 | E15: 3 | F15: Assinatura do contrato | J15: Ambos | K15: 42993 | L15: =K15 -> 42993 | M15: =IFERROR(K15-$K$13,"") -> 2 | O15: =E15 -> 3 | P15: Entregue | R15: =Documentos!B5 -> 0 | T15: Entregue | V15: =Documentos!G5 -> 0 | BM15: 7 | BN15: Receber apoio para participar de licitações | CR15: =COUNTIF($G$45:$L$86,CS15) -> 0 | CS15: =IF(BL15<>0,CONCATENATE(BM15,". ",BN15),CONCATENATE("------- ",BM15,". ",BN15)) -> ------- 7. Receber apoio para participar de licitações
C16: =WEEKDAY(L16) -> 7 | D16: 0 | E16: 4 | F16: Assinatura do Termo de Transferência | I16: -1 | J16: Ambos | K16: 42994 | L16: =K16 -> 42994 | M16: =IFERROR(K16-$K$13,"") -> 3 | O16: =E16 -> 4 | AM16: =AM8 -> Etapas do Cronograma ( | AN16: =AN8 -> 0 | BM16: 8 | BN16: Solucionar dívidas / pagamentos fiscais em atraso | CR16: =COUNTIF($G$45:$L$86,CS16) -> 0 | CS16: =IF(BL16<>0,CONCATENATE(BM16,". ",BN16),CONCATENATE("------- ",BM16,". ",BN16)) -> ------- 8. Solucionar dívidas / pagamentos fiscais em atraso
C17: =WEEKDAY(L17) -> 1 | D17: 0 | E17: 5 | F17: Assinatura DBE de troca de contador | I17: -1 | J17: Ambos | K17: 42995 | L17: =K17 -> 42995 | M17: =IFERROR(K17-$K$13,"") -> 4 | O17: =E17 -> 5 | P17: Total | R17: =Documentos!C5 -> 8 | T17: Total | V17: =Documentos!H5 -> 21 | AM17: Falta | AN17: =AO8 -> 10 | BM17: 9 | BN17: Receber ajuda para a correta emissão de notas fiscais | CR17: =COUNTIF($G$45:$L$86,CS17) -> 0 | CS17: =IF(BL17<>0,CONCATENATE(BM17,". ",BN17),CONCATENATE("------- ",BM17,". ",BN17)) -> ------- 9. Receber ajuda para a correta emissão de notas fiscais
C18: =WEEKDAY(L18) -> 2 | D18: 0 | E18: 6 | F18: Envio dos Documentos Prioritários | J18: Empresa | K18: 42996 | L18: =K18 -> 42996 | M18: =IFERROR(K18-$K$13,"") -> 5 | O18: =E18 -> 6 | AM18: =AM9 -> Documentos Prioritários ( | AN18: =AN9 -> 0 | BM18: 10 | BN18: Ter riscos trabalhistas mitigados | CR18: =COUNTIF($G$45:$L$86,CS18) -> 0 | CS18: =IF(BL18<>0,CONCATENATE(BM18,". ",BN18),CONCATENATE("------- ",BM18,". ",BN18)) -> ------- 10. Ter riscos trabalhistas mitigados
C19: =WEEKDAY(L19) -> 3 | D19: 0 | E19: 7 | F19: Contato equipe da empresa | J19: Empresa | K19: 42997 | L19: =K19 -> 42997 | M19: =IFERROR(K19-$K$13,"") -> 6 | O19: =E19 -> 7 | P19: % Concuído | R19: =R15/R17 -> 0 | T19: % Concuído | V19: =V15/V17 -> 0 | AM19: Falta | AN19: =AO9 -> 10 | BN19: =BE20 -> COMUNICAÇÃO E RELACIONAMENTO | CS19: =IF(BL19<>0,CONCATENATE(BM19,". ",BN19),CONCATENATE("------- ",BM19,". ",BN19)) -> ------- . COMUNICAÇÃO E RELACIONAMENTO
C20: =WEEKDAY(L20) -> 4 | D20: 0 | E20: 8 | F20: Contato equipe da contabilidade | J20: Contabilidade | K20: 42998 | L20: =K20 -> 42998 | M20: =IFERROR(K20-$K$13,"") -> 7 | O20: =E20 -> 8 | AM20: =AM10 -> Demais Documentos ( | AN20: =AN10 -> 0 | BE20: COMUNICAÇÃO E RELACIONAMENTO | BM20: 11 | BN20: Receber todos os documentos através de e-mail ou canal do cliente | CR20: =COUNTIF($G$45:$L$86,CS20) -> 0 | CS20: =IF(BL20<>0,CONCATENATE(BM20,". ",BN20),CONCATENATE("------- ",BM20,". ",BN20)) -> ------- 11. Receber todos os documentos através de e-mail ou canal do cliente
C21: =WEEKDAY(L21) -> 5 | D21: 0 | E21: 9 | F21: Reunião de Boas-Vindas | I21: -1 | J21: Ambos | K21: 42999 | L21: =K21 -> 42999 | M21: =IFERROR(K21-$K$13,"") -> 8 | O21: =E21 -> 9 | R21: =ROUND(R19,2)*100 -> 0 | V21: =ROUND(V19,2)*100 -> 0 | AM21: Falta | AN21: =AO10 -> 10 | BM21: 12 | BN21: Ser atendido de forma ágil através de Skype, WhatsApp, etc. | CR21: =COUNTIF($G$45:$L$86,CS21) -> 0 | CS21: =IF(BL21<>0,CONCATENATE(BM21,". ",BN21),CONCATENATE("------- ",BM21,". ",BN21)) -> ------- 12. Ser atendido de forma ágil através de Skype, WhatsApp, etc.
C22: =WEEKDAY(L22) -> 6 | D22: 0 | E22: 10 | F22: Envio dos Demais Documentos | J22: Empresa | K22: 43000 | L22: =K22 -> 43000 | M22: =IFERROR(K22-$K$13,"") -> 9 | O22: =E22 -> 10 | AM22: =AM11 -> Sucessos definidos ( | AN22: =AN11 -> 0 | BM22: 13 | BN22: Ser atendido por uma única pessoa em cada setor | CR22: =COUNTIF($G$45:$L$86,CS22) -> 0 | CS22: =IF(BL22<>0,CONCATENATE(BM22,". ",BN22),CONCATENATE("------- ",BM22,". ",BN22)) -> ------- 13. Ser atendido por uma única pessoa em cada setor
C23: =WEEKDAY(L23) -> #VALUE! | D23: 0 | E23: 11 | L23: =K23 | M23: =IFERROR(K23-$K$13,"") | O23: =E23 -> 11 | AM23: Falta | AN23: =AO11 -> 10 | BM23: 14 | BN23: Receber conteúdo relevante e aplicável sobre assuntos contábeis / financeiros / gerenciais | CS23: =IF(BL23<>0,CONCATENATE(BM23,". ",BN23),CONCATENATE("------- ",BM23,". ",BN23)) -> ------- 14. Receber conteúdo relevante e aplicável sobre assuntos contábeis / financeiros / gerenciais
C24: =WEEKDAY(L24) -> #VALUE! | D24: 0 | E24: 12 | L24: =K24 | M24: =IFERROR(K24-$K$13,"") | O24: =E24 -> 12 | BN24: =BE25 -> ESPECÍFICOS | CR24: =COUNTIF($G$45:$L$86,CS24) -> 0 | CS24: =IF(BL24<>0,CONCATENATE(BM24,". ",BN24),CONCATENATE("------- ",BM24,". ",BN24)) -> ------- . ESPECÍFICOS
C25: =WEEKDAY(L25) -> #VALUE! | D25: 0 | E25: 13 | L25: =K25 | M25: =IFERROR(K25-$K$13,"") | O25: =E25 -> 13 | Q25: =E25/13 -> 1 | R25: =M25 | T25: =IF(D25=1,E25/13,0) -> 0 | BE25: ESPECÍFICOS | BM25: 15 | CR25: =COUNTIF($G$45:$L$86,CS25) -> 0 | CS25: =IF(BL25<>0,CONCATENATE(BM25,". ",BN25),CONCATENATE("------- ",BM25,". ",BN25)) -> ------- 15.
BM26: 16 | CR26: =COUNTIF($G$45:$L$86,CS26) -> 0 | CS26: =IF(BL26<>0,CONCATENATE(BM26,". ",BN26),CONCATENATE("------- ",BM26,". ",BN26)) -> ------- 16.
BM27: 17 | CS27: =IF(BL27<>0,CONCATENATE(BM27,". ",BN27),CONCATENATE("------- ",BM27,". ",BN27)) -> ------- 17.
D28: Quem faz parte da equipe | I28: Dados da equipe | O28: Interação com Equipe
D29: # | E29: Nome | G29: Setor | I29: Email | L29: Telefone | O29: Meio de contato (tligação/ email/ visita)
D30: 1 | E30: Regina | G30: Financeiro | I30: financeiro@empresa.com.br | L30: 98857-6351 | AB30: =CONCATENATE(AK30,AJ30,"/",AP8,")") -> Etapas do Cronograma (0/10) | AJ30: =AN8 -> 0 | AK30: Etapas do Cronograma (
D31: 2 | E31: Jussara | G31: Financeiro | I31: financeiro2@empresa.com.br | AB31: =CONCATENATE(AK31,R21,"%",")") -> Documentos Prioritários (0%) | AJ31: =AN9 -> 0 | AK31: Documentos Prioritários (
D32: 3 | E32: Gustavo | G32: Administrativo | I32: adm@empresa.com.br | AB32: =CONCATENATE(AK32,V21,"%",")") -> Demais Documentos (0%) | AJ32: =AN10 -> 0 | AK32: Demais Documentos (
D33: 4 | E33: Sócio Legal | G33: Sócio | I33: sociolegal@empresa.com.br | AB33: =CONCATENATE(AK33,AJ33,"/","5)") -> Sucessos definidos (0/5) | AJ33: =AN11/2 -> 0 | AK33: Sucessos definidos (
D34: 5 | E34: Sócio Mala | G34: Sócio | I34: sociomala@empresa.com.br
D43: # | E43: DATA | G43: CATEGORIA DO SUCESSO | M43: DESCRIÇÃO DO SUCESSO | V43: VALOR REF. | AA43: CONTAGEM DE SUCESSOS | AF43: Data primeiro sucesso
D45: 1 | E45: 42878 | G45: 2. Receber relatórios de desempenho e diagnósticos que me ajudam a tomar decisão | AF45: =IF(AA47=0,"",SMALL(E45:F86,1)) -> 42878
D47: =D45+1 -> 2 | E47: 42879 | G47: 6. Ter economia fiscal através de planejamento tributário | AA47: =COUNTA(G45:L86) -> 5 | AF47: Data último sucesso
D49: =D47+1 -> 3 | E49: 42881 | G49: 7. Receber apoio para participar de licitações | AF49: =IF(AA47=0,"",LARGE(E45:F86,1)) -> 42899
D51: =D49+1 -> 4 | E51: 42882 | G51: 10. Ter riscos trabalhistas mitigados
D53: =D51+1 -> 5 | E53: 42883 | G53: 14. Receber conteúdo relevante e aplicável sobre assuntos contábeis / financeiros / gerenciais
D55: =D53+1 -> 6 | E55: 42884
D57: =D55+1 -> 7 | E57: 42885
D59: =D57+1 -> 8 | E59: 42886
D61: =D59+1 -> 9 | E61: 42887
...

Sheet Documentos
A1: Sim
B2: RELAÇÃO DE DOCUMENTAÇÃO
A3: Não
B4: ENTREGUE | C4: DOCUMENTOS PRIORITÁRIOS | D4: FORMATO | E4: SETOR | G4: ENTREGUE | H4: DEMAIS DOCUMENTOS | I4: FORMATO | J4: SETOR
B5: =COUNTIF(B6:B62,"Sim") -> 0 | C5: =COUNTA(C6:C62) -> 8 | G5: =COUNTIF(G6:G62,"Sim") -> 0 | H5: =COUNTA(H6:H62) -> 21
C6: Certificado digital A1 ou A3 com senha | D6: arquivo pfx (A1) ou token (A3) | E6: LEGAL | H6: Balancete Analítico ano anterior + Balancete Analítico do ano corrente acumulado até o mês anterior | I6: PDF | J6: CONTÁBIL
C7: Contrato Social ou Última Alteração Contratual consolidada, registrado na JUNTA | D7: PDF | E7: LEGAL | H7: Livro Razão do ano anterior + Livro Razão do ano corrente até o mês anterior | I7: PDF ou XLS | J7: CONTÁBIL
C8: Folha de pagamento completa + GFIP entregue do mês anterior | D8: PDF | E8: PESSOAL | H8: Balanço patrimonial analítico do ano anterior atualizado | I8: PDF ou XLS | J8: CONTÁBIL
C9: Ficha de registro de todos os empregados ativos, atualizada | D9: PDF | E9: PESSOAL | H9: DRE do ano anterior atualizada | I9: PDF ou XLS | J9: CONTÁBIL
C10: Código de Acesso ao Simples Nacional | D10: - | E10: FISCAL | H10: Ficha de Relação de itens do ativo imobilizado | I10: PDF ou TXT | J10: CONTÁBIL
C11: Senha de Acesso à DEISSBH | D11: - | E11: FISCAL | H11: Última ECD entregue | I11: TXT | J11: CONTÁBIL
C12: Senha SIARE | D12: - | E12: FISCAL | H12: Última ECF entregue | I12: TXT | J12: CONTÁBIL
C13: RTRTH | H13: Última declaração de IRPF entregue dos sócios, com recibo de entrega | I13: PDF | J13: CONTÁBIL
H14: Relação de faturamento 12 últimos meses atualizada. | I14: PDF ou XLS | J14: FISCAL
H15: Última DEFIS entregue | I15: PDF | J15: FISCAL
H16: 12 últimas folhas de pagamento analíticas e resumo | I16: PDF | J16: PESSOAL
H17: Três últimas GFIP entregues | I17: PDF | J17: PESSOAL
H18: CCT atualizada | I18: PDF | J18: PESSOAL
H19: Relação de período aquisitivo de férias e últimas férias gozadas de todos os funcionários | I19: PDF | J19: PESSOAL
H20: Última RAIS entregue | I20: TXT ou PDF | J20: PESSOAL
H21: Último CAGED Entregue | I21: TXT ou PDF | J21: PESSOAL
H22: Última DIRF entregue | I22: TXT ou PDF | J22: PESSOAL
H23: Três últimas contribuições pagas para sindicato patronal e dos empregados. | I23: Impresso ou PDF | J23: PESSOAL
H24: Cópia do Alvará de Localização e Funcionamento | I24: PDF | J24: LEGAL
H25: Cópia autenticada (pelo menos três) do RG e CPF dos sócios | I25: Impresso | J25: LEGAL
H26: DBE troca de contabilidade assinado com firma reconhecida

Sheet Plano de Ação
