Workbook

Sheet Introdução
B2: Bem vindo a este material totalmente GRATUITO.
B6: O seu propósito é auxiliar você empresário a alcançar seus objetivos, e alavancar sua empresa, através de ferramentas auxiliares de gestão.
B9: Antes, uma pequena dica!
B11: Algumas colunas possuem dicas ou informações que auxiliam no seu entendimento. Basta parar o cursor do mouse sobre as células que possuem setinha vermelha no canto superior direito. Como este:
B17: Depois de ler as instruções, clique aqui para acessar a planilha na integra

Sheet Formulário
A1: FORMULÁRIO DE PESQUISA | M1: =$A$1 -> FORMULÁRIO DE PESQUISA
A2: Sua opinião e importante para nós! | M2: Sua opinião e importante para nós!
A4: Qualidade no Atendimento | D4: Sugestões:____________________________________________________________________________________________________________________________________________ | M4: =$A$4 -> Qualidade no Atendimento | P4: Sugestões:____________________________________________________________________________________________________________________________________________
A5: NOTA DE 0 A 10: | M5: NOTA DE 0 A 10:
A6: Qualidade dos Produtos | M6: =$A$6 -> Qualidade dos Produtos
A7: =A5 -> NOTA DE 0 A 10: | M7: =M5 -> NOTA DE 0 A 10:
A8: Valores Cobrados | M8: =$A$8 -> Valores Cobrados
A9: =A5 -> NOTA DE 0 A 10: | M9: =M5 -> NOTA DE 0 A 10:
A10: 8<------------------------------------------------------------------------------------------------
A11: =$A$1 -> FORMULÁRIO DE PESQUISA | M11: =$A$1 -> FORMULÁRIO DE PESQUISA
A12: Sua opinião e importante para nós! | M12: Sua opinião e importante para nós!
A14: =$A$4 -> Qualidade no Atendimento | D14: Sugestões:____________________________________________________________________________________________________________________________________________ | M14: =$A$4 -> Qualidade no Atendimento | P14: Sugestões:____________________________________________________________________________________________________________________________________________
A15: NOTA DE 0 A 10: | M15: NOTA DE 0 A 10:
A16: =$A$6 -> Qualidade dos Produtos | M16: =$A$6 -> Qualidade dos Produtos
A17: =A15 -> NOTA DE 0 A 10: | M17: =M15 -> NOTA DE 0 A 10:
A18: =$A$8 -> Valores Cobrados | M18: =$A$8 -> Valores Cobrados
A19: =A15 -> NOTA DE 0 A 10: | M19: =M15 -> NOTA DE 0 A 10:
A20: 8<------------------------------------------------------------------------------------------------
A21: =$A$1 -> FORMULÁRIO DE PESQUISA | M21: =$A$1 -> FORMULÁRIO DE PESQUISA
A22: Sua opinião e importante para nós! | M22: Sua opinião e importante para nós!
A24: =$A$4 -> Qualidade no Atendimento | D24: Sugestões:____________________________________________________________________________________________________________________________________________ | M24: =$A$4 -> Qualidade no Atendimento | P24: Sugestões:____________________________________________________________________________________________________________________________________________
A25: NOTA DE 0 A 10: | M25: NOTA DE 0 A 10:
A26: =$A$6 -> Qualidade dos Produtos | M26: =$A$6 -> Qualidade dos Produtos
A27: =A25 -> NOTA DE 0 A 10: | M27: =M25 -> NOTA DE 0 A 10:
A28: =$A$8 -> Valores Cobrados | M28: =$A$8 -> Valores Cobrados
A29: =A25 -> NOTA DE 0 A 10: | M29: =M25 -> NOTA DE 0 A 10:
A30: 8<------------------------------------------------------------------------------------------------
A31: =$A$1 -> FORMULÁRIO DE PESQUISA | M31: =$A$1 -> FORMULÁRIO DE PESQUISA
A32: Sua opinião e importante para nós! | M32: Sua opinião e importante para nós!
A34: =$A$4 -> Qualidade no Atendimento | D34: Sugestões:____________________________________________________________________________________________________________________________________________ | M34: =$A$4 -> Qualidade no Atendimento | P34: Sugestões:____________________________________________________________________________________________________________________________________________
A35: NOTA DE 0 A 10: | M35: NOTA DE 0 A 10:
A36: =$A$6 -> Qualidade dos Produtos | M36: =$A$6 -> Qualidade dos Produtos
A37: =A35 -> NOTA DE 0 A 10: | M37: =M35 -> NOTA DE 0 A 10:
A38: =$A$8 -> Valores Cobrados | M38: =$A$8 -> Valores Cobrados
A39: =A35 -> NOTA DE 0 A 10: | M39: =M35 -> NOTA DE 0 A 10:
A40: 8<------------------------------------------------------------------------------------------------
A41: =$A$1 -> FORMULÁRIO DE PESQUISA | M41: =$A$1 -> FORMULÁRIO DE PESQUISA
A42: Sua opinião e importante para nós! | M42: Sua opinião e importante para nós!
A44: =$A$4 -> Qualidade no Atendimento | D44: Sugestões:____________________________________________________________________________________________________________________________________________ | M44: =$A$4 -> Qualidade no Atendimento | P44: Sugestões:____________________________________________________________________________________________________________________________________________
A45: NOTA DE 0 A 10: | M45: NOTA DE 0 A 10:
...

Sheet Dados da Pesquisa
I3: Dados da Pesquisa
C8: Sumário | I8: Sugestões | J8: =Formulário!A4 -> Qualidade no Atendimento | K8: =Formulário!A6 -> Qualidade dos Produtos | L8: =Formulário!A8 -> Valores Cobrados
J10: 10 | K10: 5 | L10: 10
J12: 10 | K12: 10 | L12: 10
J14: 10 | K14: 10 | L14: 10
J16: 10 | K16: 10 | L16: 10
J18: 10 | K18: 10 | L18: 10

Sheet Apuração de Pesquisa
I3: Apuração de Pesquisas | N3: NPS (Net Promoter Score) | S3: =L16-J16 -> 0.86666667
C8: Sumário | I8: Período da pesquisa de: | J8: 43132 | K8: a | L8: 43133
I11: Perguntas | J11: Notas de 0 a 6 | K11: notas de 7 a 8 | L11: notas de 9 a 10 | N11: =IF(S3<-0.01,"Zona Crítica",IF(AND(S3>=0,S3<=0.49),"Zona de Aperfeiçoamento",IF(AND(S3>=0.5,S3<0.75),"Zona de Qualidade","Zona de Excelência"))) -> Zona de Excelência
I12: =Formulário!A4 -> Qualidade no Atendimento | J12: =COUNTIF('Dados da Pesquisa'!J:J,"<=6") -> 0 | K12: =COUNTIFS('Dados da Pesquisa'!J:J,">6",'Dados da Pesquisa'!J:J,"<9") -> 0 | L12: =COUNTIF('Dados da Pesquisa'!J:J,">=9") -> 5
I13: =Formulário!A6 -> Qualidade dos Produtos | J13: =COUNTIF('Dados da Pesquisa'!K:K,"<=6") -> 1 | K13: =COUNTIFS('Dados da Pesquisa'!K:K,">6",'Dados da Pesquisa'!K:K,"<9") -> 0 | L13: =COUNTIF('Dados da Pesquisa'!K:K,">=9") -> 4
I14: =Formulário!A8 -> Valores Cobrados | J14: =COUNTIF('Dados da Pesquisa'!L:L,"<=6") -> 0 | K14: =COUNTIFS('Dados da Pesquisa'!L:L,">6",'Dados da Pesquisa'!L:L,"<9") -> 0 | L14: =COUNTIF('Dados da Pesquisa'!L:L,">=9") -> 5
I15: Total por notas | J15: =SUM(J12:J14)/3 -> 0.33333333 | K15: =SUM(K12:K14)/3 -> 0 | L15: =SUM(L12:L14)/3 -> 4.6666667
I16: Percentual por nota | J16: =J15/$J$17 -> 0.066666667 | K16: =K15/$J$17 -> 0 | L16: =L15/$J$17 -> 0.93333333
I17: Total de Pesquisados | J17: =SUM(J15:L15) -> 5
I19: A pesquisa de satisfação é fundamnetal para que você saiba como o seu cliente se sente perante ao serviço/ produto que você está oferecendo. Notas de 0 a 6 - Clientes Detratores - Indicam que tiveram suas vidas afetadas negativamente depois de fazer negócios com a empresa. Não voltariam a fazer negócios jamais, a não ser em situações extremas. Notas 7 e 8 - Clientes Neutros - Cliente que só compram os produtos ou serviços por julgarem necessário. Não são leais e não indicariam para amigos ou parceiros. Notas 9 e 10 - Clientes Promotores - Indicam que tiveram suas vidas melhoradas após iniciar um relacionamento com a empresa/marca/serviço. São leais e indicariam para amigos e parceiros. | N19: O NPS é medido através da pergunta: "Em uma escada de 0 a 10, o quanto você indicaria nossa empresa para um amigo?" De acordo com a porcentagem obtida no Net Promoter Score, é possível classificar as empresas em 4 Zonas de Classificação, que inficam o quão bem estão as empresas em relação à satisfação de seus clientes. Elas são: Zona de Excelência - NPS entre 75 e 100% Zona de Qualidade - NPS entre 50 e 74% Zona de Aperfeiçoamento - NPS entre 0 e 49% Zona Crítica - NPS entre -100 e -1%

Sheet Gráficos
C8: Sumário
