Workbook

Sheet Orientações
C2: * ORIENTAÇÕES *
C4: Digitar somente nos campos abaixo:
C5: Chapa: Digitar o número da chapa ou registro do funcionário.
C6: Nome : Informar o nome do funcionário. Obs: Deixei a coluna pequena para poder visualisar toda a planilha, mas procure abreviar
C7: Periodo aquisitivo - DIGITAR SOMENTE A DATA INíCIO, do período aquisitivo que esta em aberto
C8: Faltas sem justificativas : Quando for lançar/programar o INíCIO DE GOZO, digite a quantidade de faltas sem justificativas
C9: Periodo de gozo - DIGITAR SOMENTE A DATA INÍCIO
C10: Abono Pecuniário - Selecionar "SIM" ou "NÃO"
C12: * ATENÇÃO * - CAMPOS ABAIXO MUITO IMPORTANTES - * ANALISAR SEMPRE *
C13: Data limite de gozo - Ficar atento para esta data, ela informa o dia limite de gozo, para não vencer o segundo periodo aquisitivo
C14: Situação após programação - Caso o início de gozo já estiver excedido o 2º período aqusitivo, a planilha dará um alerta em vermelho "Férias em dobro"
C15: Qtde dias para limite de gozo - Este campo é super importante, pois irá ALERTAR quando faltarem menos de 66 dias para o funcionário sair de férias, sob pena
... C24: feriado ou dia de repouso semanal remunerado.

Sheet Controle Vencimento Férias
B2: * PLANILHA PARA CONTROLE VENCIMENTO DE FÉRIAS *
B4: Chapa | C4: Nome | D4: Período aquisitivo | F4: Faltas sem | G4: Dias de | H4: Situação | I4: Data Limite | J4: Periodo de gozo | L4: Abono | M4: Dias de | N4: Situação | O4: Qtde dias para
D5: Início | E5: Fim | F5: justificativa | G5: direito | I5: de gozo | J5: Início | K5: Fim | L5: Pecuniário | M5: abono | N5: após programação | O5: limite de gozo
B6: 1 | C6: Beltrano de Tal Jr | D6: 42522 | E6: =IF(ISBLANK(D6),"",DATE(YEAR(D6)+1,MONTH(D6),DAY(D6))-1) -> 42886 | F6: 0 | G6: =IF(F6<Parâmetros!$E$3,Parâmetros!$F$3,VLOOKUP('Controle Vencimento Férias'!F6,Parâmetros!$C$3:$F$7,4,1)) -> 30 | H6: =IF(ISBLANK(D6),"",IF(E6<=Parâmetros!$B$10,"Vencidas",IF(E6>Parâmetros!$B$10,"Não vencidas"))) -> Vencidas | I6: =IF(ISBLANK(D6),"",E6+336) -> 43222 | J6: 42126 | K6: =IF(ISBLANK(J6),"",(J6+G6-1)-M6) -> 42155 | M6: =IF(Parâmetros!I4=1,G6/3,IF(Parâmetros!I4=2,0)) -> 0 | N6: =IF(ISBLANK(J6),"",IF(J6<=I6,"No prazo",IF(J6>I6,"Férias em dobro"))) -> No prazo | O6: =IF(ISBLANK(D6),"",IF(I6-Parâmetros!$B$10<=65,I6-Parâmetros!$B$10,IF(I6-Parâmetros!$B$10>65,I6-Parâmetros!$B$10))) -> 30.523911
B7: 2 | C7: Fulano de Tal | D7: 42557 | E7: =IF(ISBLANK(D7),"",DATE(YEAR(D7)+1,MONTH(D7),DAY(D7))-1) -> 42921 | F7: 0 | G7: =IF(F7<Parâmetros!$E$3,Parâmetros!$F$3,VLOOKUP('Controle Vencimento Férias'!F7,Parâmetros!$C$3:$F$7,4,1)) -> 30 | H7: =IF(ISBLANK(D7),"",IF(E7<=Parâmetros!$B$10,"Vencidas",IF(E7>Parâmetros!$B$10,"Não vencidas"))) -> Vencidas | I7: =IF(ISBLANK(D7),"",E7+336) -> 43257 | J7: 43215 | K7: =IF(ISBLANK(J7),"",(J7+G7-1)-M7) -> 43244 | M7: =IF(Parâmetros!I7=1,G7/3,IF(Parâmetros!I7=2,0)) -> 0 | N7: =IF(ISBLANK(J7),"",IF(J7<=I7,"No prazo",IF(J7>I7,"Férias em dobro"))) -> No prazo | O7: =IF(ISBLANK(D7),"",IF(I7-Parâmetros!$B$10<=65,I7-Parâmetros!$B$10,IF(I7-Parâmetros!$B$10>65,I7-Parâmetros!$B$10))) -> 65.523911
B8: 3 | C8: Sicrano de Tal e Tal | D8: 42949 | E8: =IF(ISBLANK(D8),"",DATE(YEAR(D8)+1,MONTH(D8),DAY(D8))-1) -> 43313 | F8: 0 | G8: =IF(F8<Parâmetros!$E$3,Parâmetros!$F$3,VLOOKUP('Controle Vencimento Férias'!F8,Parâmetros!$C$3:$F$7,4,1)) -> 30 | H8: =IF(ISBLANK(D8),"",IF(E8<=Parâmetros!$B$10,"Vencidas",IF(E8>Parâmetros!$B$10,"Não vencidas"))) -> Não vencidas | I8: =IF(ISBLANK(D8),"",E8+336) -> 43649 | K8: =IF(ISBLANK(J8),"",(J8+G8-1)-M8) | M8: =IF(Parâmetros!I10=1,G8/3,IF(Parâmetros!I10=2,0)) -> 0 | N8: =IF(ISBLANK(J8),"",IF(J8<=I8,"No prazo",IF(J8>I8,"Férias em dobro"))) | O8: =IF(ISBLANK(D8),"",IF(I8-Parâmetros!$B$10<=65,I8-Parâmetros!$B$10,IF(I8-Parâmetros!$B$10>65,I8-Parâmetros!$B$10))) -> 457.52391
B9: 4 | E9: =IF(ISBLANK(D9),"",DATE(YEAR(D9)+1,MONTH(D9),DAY(D9))-1) | F9: 0 | G9: =IF(F9<Parâmetros!$E$3,Parâmetros!$F$3,VLOOKUP('Controle Vencimento Férias'!F9,Parâmetros!$C$3:$F$7,4,1)) -> 30 | H9: =IF(ISBLANK(D9),"",IF(E9<=Parâmetros!$B$10,"Vencidas",IF(E9>Parâmetros!$B$10,"Não vencidas"))) | I9: =IF(ISBLANK(D9),"",E9+336) | K9: =IF(ISBLANK(J9),"",(J9+G9-1)-M9) | M9: =IF(Parâmetros!I13=1,G9/3,IF(Parâmetros!I13=2,0)) -> 0 | N9: =IF(ISBLANK(J9),"",IF(J9<=I9,"No prazo",IF(J9>I9,"Férias em dobro"))) | O9: =IF(ISBLANK(D9),"",IF(I9-Parâmetros!$B$10<=65,I9-Parâmetros!$B$10,IF(I9-Parâmetros!$B$10>65,I9-Parâmetros!$B$10)))
B10: 5 | E10: =IF(ISBLANK(D10),"",DATE(YEAR(D10)+1,MONTH(D10),DAY(D10))-1) | F10: 0 | G10: =IF(F10<Parâmetros!$E$3,Parâmetros!$F$3,VLOOKUP('Controle Vencimento Férias'!F10,Parâmetros!$C$3:$F$7,4,1)) -> 30 | H10: =IF(ISBLANK(D10),"",IF(E10<=Parâmetros!$B$10,"Vencidas",IF(E10>Parâmetros!$B$10,"Não vencidas"))) | I10: =IF(ISBLANK(D10),"",E10+336) | K10: =IF(ISBLANK(J10),"",(J10+G10-1)-M10) | M10: =IF(Parâmetros!I16=1,G10/3,IF(Parâmetros!I16=2,0)) -> 0 | N10: =IF(ISBLANK(J10),"",IF(J10<=I10,"No prazo",IF(J10>I10,"Férias em dobro"))) | O10: =IF(ISBLANK(D10),"",IF(I10-Parâmetros!$B$10<=65,I10-Parâmetros!$B$10,IF(I10-Parâmetros!$B$10>65,I10-Parâmetros!$B$10)))
B11: 6 | E11: =IF(ISBLANK(D11),"",DATE(YEAR(D11)+1,MONTH(D11),DAY(D11))-1) | F11: 0 | G11: =IF(F11<Parâmetros!$E$3,Parâmetros!$F$3,VLOOKUP('Controle Vencimento Férias'!F11,Parâmetros!$C$3:$F$7,4,1)) -> 30 | H11: =IF(ISBLANK(D11),"",IF(E11<=Parâmetros!$B$10,"Vencidas",IF(E11>Parâmetros!$B$10,"Não vencidas"))) | I11: =IF(ISBLANK(D11),"",E11+336) | K11: =IF(ISBLANK(J11),"",(J11+G11-1)-M11) | M11: =IF(Parâmetros!I19=1,G11/3,IF(Parâmetros!I19=2,0)) -> 0 | N11: =IF(ISBLANK(J11),"",IF(J11<=I11,"No prazo",IF(J11>I11,"Férias em dobro"))) | O11: =IF(ISBLANK(D11),"",IF(I11-Parâmetros!$B$10<=65,I11-Parâmetros!$B$10,IF(I11-Parâmetros!$B$10>65,I11-Parâmetros!$B$10)))
B12: 7 | E12: =IF(ISBLANK(D12),"",DATE(YEAR(D12)+1,MONTH(D12),DAY(D12))-1) | F12: 0 | G12: =IF(F12<Parâmetros!$E$3,Parâmetros!$F$3,VLOOKUP('Controle Vencimento Férias'!F12,Parâmetros!$C$3:$F$7,4,1)) -> 30 | H12: =IF(ISBLANK(D12),"",IF(E12<=Parâmetros!$B$10,"Vencidas",IF(E12>Parâmetros!$B$10,"Não vencidas"))) | I12: =IF(ISBLANK(D12),"",E12+336) | K12: =IF(ISBLANK(J12),"",(J12+G12-1)-M12) | M12: =IF(Parâmetros!I22=1,G12/3,IF(Parâmetros!I22=2,0)) -> 0 | N12: =IF(ISBLANK(J12),"",IF(J12<=I12,"No prazo",IF(J12>I12,"Férias em dobro"))) | O12: =IF(ISBLANK(D12),"",IF(I12-Parâmetros!$B$10<=65,I12-Parâmetros!$B$10,IF(I12-Parâmetros!$B$10>65,I12-Parâmetros!$B$10)))
B13: 8 | E13: =IF(ISBLANK(D13),"",DATE(YEAR(D13)+1,MONTH(D13),DAY(D13))-1) | F13: 0 | G13: =IF(F13<Parâmetros!$E$3,Parâmetros!$F$3,VLOOKUP('Controle Vencimento Férias'!F13,Parâmetros!$C$3:$F$7,4,1)) -> 30 | H13: =IF(ISBLANK(D13),"",IF(E13<=Parâmetros!$B$10,"Vencidas",IF(E13>Parâmetros!$B$10,"Não vencidas"))) | I13: =IF(ISBLANK(D13),"",E13+336) | K13: =IF(ISBLANK(J13),"",(J13+G13-1)-M13) | M13: =IF(Parâmetros!I25=1,G13/3,IF(Parâmetros!I25=2,0)) -> 0 | N13: =IF(ISBLANK(J13),"",IF(J13<=I13,"No prazo",IF(J13>I13,"Férias em dobro"))) | O13: =IF(ISBLANK(D13),"",IF(I13-Parâmetros!$B$10<=65,I13-Parâmetros!$B$10,IF(I13-Parâmetros!$B$10>65,I13-Parâmetros!$B$10)))
B14: 9 | E14: =IF(ISBLANK(D14),"",DATE(YEAR(D14)+1,MONTH(D14),DAY(D14))-1) | F14: 0 | G14: =IF(F14<Parâmetros!$E$3,Parâmetros!$F$3,VLOOKUP('Controle Vencimento Férias'!F14,Parâmetros!$C$3:$F$7,4,1)) -> 30 | H14: =IF(ISBLANK(D14),"",IF(E14<=Parâmetros!$B$10,"Vencidas",IF(E14>Parâmetros!$B$10,"Não vencidas"))) | I14: =IF(ISBLANK(D14),"",E14+336) | K14: =IF(ISBLANK(J14),"",(J14+G14-1)-M14) | M14: =IF(Parâmetros!L4=1,G14/3,IF(Parâmetros!L4=2,0)) -> 0 | N14: =IF(ISBLANK(J14),"",IF(J14<=I14,"No prazo",IF(J14>I14,"Férias em dobro"))) | O14: =IF(ISBLANK(D14),"",IF(I14-Parâmetros!$B$10<=65,I14-Parâmetros!$B$10,IF(I14-Parâmetros!$B$10>65,I14-Parâmetros!$B$10)))
B15: 10 | E15: =IF(ISBLANK(D15),"",DATE(YEAR(D15)+1,MONTH(D15),DAY(D15))-1) | F15: 0 | G15: =IF(F15<Parâmetros!$E$3,Parâmetros!$F$3,VLOOKUP('Controle Vencimento Férias'!F15,Parâmetros!$C$3:$F$7,4,1)) -> 30 | H15: =IF(ISBLANK(D15),"",IF(E15<=Parâmetros!$B$10,"Vencidas",IF(E15>Parâmetros!$B$10,"Não vencidas"))) | I15: =IF(ISBLANK(D15),"",E15+336) | K15: =IF(ISBLANK(J15),"",(J15+G15-1)-M15) | M15: =IF(Parâmetros!L7=1,G15/3,IF(Parâmetros!L7=2,0)) -> 0 | N15: =IF(ISBLANK(J15),"",IF(J15<=I15,"No prazo",IF(J15>I15,"Férias em dobro"))) | O15: =IF(ISBLANK(D15),"",IF(I15-Parâmetros!$B$10<=65,I15-Parâmetros!$B$10,IF(I15-Parâmetros!$B$10>65,I15-Parâmetros!$B$10)))
B16: 11 | E16: =IF(ISBLANK(D16),"",DATE(YEAR(D16)+1,MONTH(D16),DAY(D16))-1) | F16: 0 | G16: =IF(F16<Parâmetros!$E$3,Parâmetros!$F$3,VLOOKUP('Controle Vencimento Férias'!F16,Parâmetros!$C$3:$F$7,4,1)) -> 30 | H16: =IF(ISBLANK(D16),"",IF(E16<=Parâmetros!$B$10,"Vencidas",IF(E16>Parâmetros!$B$10,"Não vencidas"))) | I16: =IF(ISBLANK(D16),"",E16+336) | K16: =IF(ISBLANK(J16),"",(J16+G16-1)-M16) | M16: =IF(Parâmetros!L10=1,G16/3,IF(Parâmetros!L10=2,0)) -> 0 | N16: =IF(ISBLANK(J16),"",IF(J16<=I16,"No prazo",IF(J16>I16,"Férias em dobro"))) | O16: =IF(ISBLANK(D16),"",IF(I16-Parâmetros!$B$10<=65,I16-Parâmetros!$B$10,IF(I16-Parâmetros!$B$10>65,I16-Parâmetros!$B$10)))
B17: 12 | E17: =IF(ISBLANK(D17),"",DATE(YEAR(D17)+1,MONTH(D17),DAY(D17))-1) | F17: 0 | G17: =IF(F17<Parâmetros!$E$3,Parâmetros!$F$3,VLOOKUP('Controle Vencimento Férias'!F17,Parâmetros!$C$3:$F$7,4,1)) -> 30 | H17: =IF(ISBLANK(D17),"",IF(E17<=Parâmetros!$B$10,"Vencidas",IF(E17>Parâmetros!$B$10,"Não vencidas"))) | I17: =IF(ISBLANK(D17),"",E17+336) | K17: =IF(ISBLANK(J17),"",(J17+G17-1)-M17) | M17: =IF(Parâmetros!L13=1,G17/3,IF(Parâmetros!L13=2,0)) -> 0 | N17: =IF(ISBLANK(J17),"",IF(J17<=I17,"No prazo",IF(J17>I17,"Férias em dobro"))) | O17: =IF(ISBLANK(D17),"",IF(I17-Parâmetros!$B$10<=65,I17-Parâmetros!$B$10,IF(I17-Parâmetros!$B$10>65,I17-Parâmetros!$B$10)))
B18: 13 | E18: =IF(ISBLANK(D18),"",DATE(YEAR(D18)+1,MONTH(D18),DAY(D18))-1) | F18: 0 | G18: =IF(F18<Parâmetros!$E$3,Parâmetros!$F$3,VLOOKUP('Controle Vencimento Férias'!F18,Parâmetros!$C$3:$F$7,4,1)) -> 30 | H18: =IF(ISBLANK(D18),"",IF(E18<=Parâmetros!$B$10,"Vencidas",IF(E18>Parâmetros!$B$10,"Não vencidas"))) | I18: =IF(ISBLANK(D18),"",E18+336) | K18: =IF(ISBLANK(J18),"",(J18+G18-1)-M18) | M18: =IF(Parâmetros!L16=1,G18/3,IF(Parâmetros!L16=2,0)) -> 0 | N18: =IF(ISBLANK(J18),"",IF(J18<=I18,"No prazo",IF(J18>I18,"Férias em dobro"))) | O18: =IF(ISBLANK(D18),"",IF(I18-Parâmetros!$B$10<=65,I18-Parâmetros!$B$10,IF(I18-Parâmetros!$B$10>65,I18-Parâmetros!$B$10)))
B19: 14 | E19: =IF(ISBLANK(D19),"",DATE(YEAR(D19)+1,MONTH(D19),DAY(D19))-1) | F19: 0 | G19: =IF(F19<Parâmetros!$E$3,Parâmetros!$F$3,VLOOKUP('Controle Vencimento Férias'!F19,Parâmetros!$C$3:$F$7,4,1)) -> 30 | H19: =IF(ISBLANK(D19),"",IF(E19<=Parâmetros!$B$10,"Vencidas",IF(E19>Parâmetros!$B$10,"Não vencidas"))) | I19: =IF(ISBLANK(D19),"",E19+336) | K19: =IF(ISBLANK(J19),"",(J19+G19-1)-M19) | M19: =IF(Parâmetros!L19=1,G19/3,IF(Parâmetros!L19=2,0)) -> 0 | N19: =IF(ISBLANK(J19),"",IF(J19<=I19,"No prazo",IF(J19>I19,"Férias em dobro"))) | O19: =IF(ISBLANK(D19),"",IF(I19-Parâmetros!$B$10<=65,I19-Parâmetros!$B$10,IF(I19-Parâmetros!$B$10>65,I19-Parâmetros!$B$10)))
B20: 15 | E20: =IF(ISBLANK(D20),"",DATE(YEAR(D20)+1,MONTH(D20),DAY(D20))-1) | F20: 0 | G20: =IF(F20<Parâmetros!$E$3,Parâmetros!$F$3,VLOOKUP('Controle Vencimento Férias'!F20,Parâmetros!$C$3:$F$7,4,1)) -> 30 | H20: =IF(ISBLANK(D20),"",IF(E20<=Parâmetros!$B$10,"Vencidas",IF(E20>Parâmetros!$B$10,"Não vencidas"))) | I20: =IF(ISBLANK(D20),"",E20+336) | K20: =IF(ISBLANK(J20),"",(J20+G20-1)-M20) | M20: =IF(Parâmetros!L22=1,G20/3,IF(Parâmetros!L22=2,0)) -> 0 | N20: =IF(ISBLANK(J20),"",IF(J20<=I20,"No prazo",IF(J20>I20,"Férias em dobro"))) | O20: =IF(ISBLANK(D20),"",IF(I20-Parâmetros!$B$10<=65,I20-Parâmetros!$B$10,IF(I20-Parâmetros!$B$10>65,I20-Parâmetros!$B$10)))
B21: 16 | E21: =IF(ISBLANK(D21),"",DATE(YEAR(D21)+1,MONTH(D21),DAY(D21))-1) | F21: 0 | G21: =IF(F21<Parâmetros!$E$3,Parâmetros!$F$3,VLOOKUP('Controle Vencimento Férias'!F21,Parâmetros!$C$3:$F$7,4,1)) -> 30 | H21: =IF(ISBLANK(D21),"",IF(E21<=Parâmetros!$B$10,"Vencidas",IF(E21>Parâmetros!$B$10,"Não vencidas"))) | I21: =IF(ISBLANK(D21),"",E21+336) | K21: =IF(ISBLANK(J21),"",(J21+G21-1)-M21) | M21: =IF(Parâmetros!L25=1,G21/3,IF(Parâmetros!L25=2,0)) -> 0 | N21: =IF(ISBLANK(J21),"",IF(J21<=I21,"No prazo",IF(J21>I21,"Férias em dobro"))) | O21: =IF(ISBLANK(D21),"",IF(I21-Parâmetros!$B$10<=65,I21-Parâmetros!$B$10,IF(I21-Parâmetros!$B$10>65,I21-Parâmetros!$B$10)))
B22: 17 | E22: =IF(ISBLANK(D22),"",DATE(YEAR(D22)+1,MONTH(D22),DAY(D22))-1) | F22: 0 | G22: =IF(F22<Parâmetros!$E$3,Parâmetros!$F$3,VLOOKUP('Controle Vencimento Férias'!F22,Parâmetros!$C$3:$F$7,4,1)) -> 30 | H22: =IF(ISBLANK(D22),"",IF(E22<=Parâmetros!$B$10,"Vencidas",IF(E22>Parâmetros!$B$10,"Não vencidas"))) | I22: =IF(ISBLANK(D22),"",E22+336) | K22: =IF(ISBLANK(J22),"",(J22+G22-1)-M22) | M22: =IF(Parâmetros!O4=1,G22/3,IF(Parâmetros!O4=2,0)) -> 0 | N22: =IF(ISBLANK(J22),"",IF(J22<=I22,"No prazo",IF(J22>I22,"Férias em dobro"))) | O22: =IF(ISBLANK(D22),"",IF(I22-Parâmetros!$B$10<=65,I22-Parâmetros!$B$10,IF(I22-Parâmetros!$B$10>65,I22-Parâmetros!$B$10)))
B23: 18 | E23: =IF(ISBLANK(D23),"",DATE(YEAR(D23)+1,MONTH(D23),DAY(D23))-1) | F23: 0 | G23: =IF(F23<Parâmetros!$E$3,Parâmetros!$F$3,VLOOKUP('Controle Vencimento Férias'!F23,Parâmetros!$C$3:$F$7,4,1)) -> 30 | H23: =IF(ISBLANK(D23),"",IF(E23<=Parâmetros!$B$10,"Vencidas",IF(E23>Parâmetros!$B$10,"Não vencidas"))) | I23: =IF(ISBLANK(D23),"",E23+336) | K23: =IF(ISBLANK(J23),"",(J23+G23-1)-M23) | M23: =IF(Parâmetros!O7=1,G23/3,IF(Parâmetros!O7=2,0)) -> 0 | N23: =IF(ISBLANK(J23),"",IF(J23<=I23,"No prazo",IF(J23>I23,"Férias em dobro"))) | O23: =IF(ISBLANK(D23),"",IF(I23-Parâmetros!$B$10<=65,I23-Parâmetros!$B$10,IF(I23-Parâmetros!$B$10>65,I23-Parâmetros!$B$10)))
B24: 19 | E24: =IF(ISBLANK(D24),"",DATE(YEAR(D24)+1,MONTH(D24),DAY(D24))-1) | F24: 0 | G24: =IF(F24<Parâmetros!$E$3,Parâmetros!$F$3,VLOOKUP('Controle Vencimento Férias'!F24,Parâmetros!$C$3:$F$7,4,1)) -> 30 | H24: =IF(ISBLANK(D24),"",IF(E24<=Parâmetros!$B$10,"Vencidas",IF(E24>Parâmetros!$B$10,"Não vencidas"))) | I24: =IF(ISBLANK(D24),"",E24+336) | K24: =IF(ISBLANK(J24),"",(J24+G24-1)-M24) | M24: =IF(Parâmetros!O10=1,G24/3,IF(Parâmetros!O10=2,0)) -> 0 | N24: =IF(ISBLANK(J24),"",IF(J24<=I24,"No prazo",IF(J24>I24,"Férias em dobro"))) | O24: =IF(ISBLANK(D24),"",IF(I24-Parâmetros!$B$10<=65,I24-Parâmetros!$B$10,IF(I24-Parâmetros!$B$10>65,I24-Parâmetros!$B$10)))
B25: 20 | E25: =IF(ISBLANK(D25),"",DATE(YEAR(D25)+1,MONTH(D25),DAY(D25))-1) | F25: 0 | G25: =IF(F25<Parâmetros!$E$3,Parâmetros!$F$3,VLOOKUP('Controle Vencimento Férias'!F25,Parâmetros!$C$3:$F$7,4,1)) -> 30 | H25: =IF(ISBLANK(D25),"",IF(E25<=Parâmetros!$B$10,"Vencidas",IF(E25>Parâmetros!$B$10,"Não vencidas"))) | I25: =IF(ISBLANK(D25),"",E25+336) | K25: =IF(ISBLANK(J25),"",(J25+G25-1)-M25) | M25: =IF(Parâmetros!O13=1,G25/3,IF(Parâmetros!O13=2,0)) -> 0 | N25: =IF(ISBLANK(J25),"",IF(J25<=I25,"No prazo",IF(J25>I25,"Férias em dobro"))) | O25: =IF(ISBLANK(D25),"",IF(I25-Parâmetros!$B$10<=65,I25-Parâmetros!$B$10,IF(I25-Parâmetros!$B$10>65,I25-Parâmetros!$B$10)))
B26: 21 | E26: =IF(ISBLANK(D26),"",DATE(YEAR(D26)+1,MONTH(D26),DAY(D26))-1) | F26: 0 | G26: =IF(F26<Parâmetros!$E$3,Parâmetros!$F$3,VLOOKUP('Controle Vencimento Férias'!F26,Parâmetros!$C$3:$F$7,4,1)) -> 30 | H26: =IF(ISBLANK(D26),"",IF(E26<=Parâmetros!$B$10,"Vencidas",IF(E26>Parâmetros!$B$10,"Não vencidas"))) | I26: =IF(ISBLANK(D26),"",E26+336) | K26: =IF(ISBLANK(J26),"",(J26+G26-1)-M26) | M26: =IF(Parâmetros!O16=1,G26/3,IF(Parâmetros!O16=2,0)) -> 0 | N26: =IF(ISBLANK(J26),"",IF(J26<=I26,"No prazo",IF(J26>I26,"Férias em dobro"))) | O26: =IF(ISBLANK(D26),"",IF(I26-Parâmetros!$B$10<=65,I26-Parâmetros!$B$10,IF(I26-Parâmetros!$B$10>65,I26-Parâmetros!$B$10)))
B27: 22 | E27: =IF(ISBLANK(D27),"",DATE(YEAR(D27)+1,MONTH(D27),DAY(D27))-1) | F27: 0 | G27: =IF(F27<Parâmetros!$E$3,Parâmetros!$F$3,VLOOKUP('Controle Vencimento Férias'!F27,Parâmetros!$C$3:$F$7,4,1)) -> 30 | H27: =IF(ISBLANK(D27),"",IF(E27<=Parâmetros!$B$10,"Vencidas",IF(E27>Parâmetros!$B$10,"Não vencidas"))) | I27: =IF(ISBLANK(D27),"",E27+336) | K27: =IF(ISBLANK(J27),"",(J27+G27-1)-M27) | M27: =IF(Parâmetros!O19=1,G27/3,IF(Parâmetros!O19=2,0)) -> 0 | N27: =IF(ISBLANK(J27),"",IF(J27<=I27,"No prazo",IF(J27>I27,"Férias em dobro"))) | O27: =IF(ISBLANK(D27),"",IF(I27-Parâmetros!$B$10<=65,I27-Parâmetros!$B$10,IF(I27-Parâmetros!$B$10>65,I27-Parâmetros!$B$10)))
B28: 23 | E28: =IF(ISBLANK(D28),"",DATE(YEAR(D28)+1,MONTH(D28),DAY(D28))-1) | F28: 0 | G28: =IF(F28<Parâmetros!$E$3,Parâmetros!$F$3,VLOOKUP('Controle Vencimento Férias'!F28,Parâmetros!$C$3:$F$7,4,1)) -> 30 | H28: =IF(ISBLANK(D28),"",IF(E28<=Parâmetros!$B$10,"Vencidas",IF(E28>Parâmetros!$B$10,"Não vencidas"))) | I28: =IF(ISBLANK(D28),"",E28+336) | K28: =IF(ISBLANK(J28),"",(J28+G28-1)-M28) | M28: =IF(Parâmetros!O22=1,G28/3,IF(Parâmetros!O22=2,0)) -> 0 | N28: =IF(ISBLANK(J28),"",IF(J28<=I28,"No prazo",IF(J28>I28,"Férias em dobro"))) | O28: =IF(ISBLANK(D28),"",IF(I28-Parâmetros!$B$10<=65,I28-Parâmetros!$B$10,IF(I28-Parâmetros!$B$10>65,I28-Parâmetros!$B$10)))
B29: 24 | E29: =IF(ISBLANK(D29),"",DATE(YEAR(D29)+1,MONTH(D29),DAY(D29))-1) | F29: 0 | G29: =IF(F29<Parâmetros!$E$3,Parâmetros!$F$3,VLOOKUP('Controle Vencimento Férias'!F29,Parâmetros!$C$3:$F$7,4,1)) -> 30 | H29: =IF(ISBLANK(D29),"",IF(E29<=Parâmetros!$B$10,"Vencidas",IF(E29>Parâmetros!$B$10,"Não vencidas"))) | I29: =IF(ISBLANK(D29),"",E29+336) | K29: =IF(ISBLANK(J29),"",(J29+G29-1)-M29) | M29: =IF(Parâmetros!O25=1,G29/3,IF(Parâmetros!O25=2,0)) -> 0 | N29: =IF(ISBLANK(J29),"",IF(J29<=I29,"No prazo",IF(J29>I29,"Férias em dobro"))) | O29: =IF(ISBLANK(D29),"",IF(I29-Parâmetros!$B$10<=65,I29-Parâmetros!$B$10,IF(I29-Parâmetros!$B$10>65,I29-Parâmetros!$B$10)))
B30: 25 | E30: =IF(ISBLANK(D30),"",DATE(YEAR(D30)+1,MONTH(D30),DAY(D30))-1) | F30: 0 | G30: =IF(F30<Parâmetros!$E$3,Parâmetros!$F$3,VLOOKUP('Controle Vencimento Férias'!F30,Parâmetros!$C$3:$F$7,4,1)) -> 30 | H30: =IF(ISBLANK(D30),"",IF(E30<=Parâmetros!$B$10,"Vencidas",IF(E30>Parâmetros!$B$10,"Não vencidas"))) | I30: =IF(ISBLANK(D30),"",E30+336) | K30: =IF(ISBLANK(J30),"",(J30+G30-1)-M30) | M30: =IF(Parâmetros!R4=1,G30/3,IF(Parâmetros!R4=2,0)) -> 0 | N30: =IF(ISBLANK(J30),"",IF(J30<=I30,"No prazo",IF(J30>I30,"Férias em dobro"))) | O30: =IF(ISBLANK(D30),"",IF(I30-Parâmetros!$B$10<=65,I30-Parâmetros!$B$10,IF(I30-Parâmetros!$B$10>65,I30-Parâmetros!$B$10)))
B31: 26 | E31: =IF(ISBLANK(D31),"",DATE(YEAR(D31)+1,MONTH(D31),DAY(D31))-1) | F31: 0 | G31: =IF(F31<Parâmetros!$E$3,Parâmetros!$F$3,VLOOKUP('Controle Vencimento Férias'!F31,Parâmetros!$C$3:$F$7,4,1)) -> 30 | H31: =IF(ISBLANK(D31),"",IF(E31<=Parâmetros!$B$10,"Vencidas",IF(E31>Parâmetros!$B$10,"Não vencidas"))) | I31: =IF(ISBLANK(D31),"",E31+336) | K31: =IF(ISBLANK(J31),"",(J31+G31-1)-M31) | M31: =IF(Parâmetros!R7=1,G31/3,IF(Parâmetros!R7=2,0)) -> 0 | N31: =IF(ISBLANK(J31),"",IF(J31<=I31,"No prazo",IF(J31>I31,"Férias em dobro"))) | O31: =IF(ISBLANK(D31),"",IF(I31-Parâmetros!$B$10<=65,I31-Parâmetros!$B$10,IF(I31-Parâmetros!$B$10>65,I31-Parâmetros!$B$10)))
B32: 27 | E32: =IF(ISBLANK(D32),"",DATE(YEAR(D32)+1,MONTH(D32),DAY(D32))-1) | F32: 0 | G32: =IF(F32<Parâmetros!$E$3,Parâmetros!$F$3,VLOOKUP('Controle Vencimento Férias'!F32,Parâmetros!$C$3:$F$7,4,1)) -> 30 | H32: =IF(ISBLANK(D32),"",IF(E32<=Parâmetros!$B$10,"Vencidas",IF(E32>Parâmetros!$B$10,"Não vencidas"))) | I32: =IF(ISBLANK(D32),"",E32+336) | K32: =IF(ISBLANK(J32),"",(J32+G32-1)-M32) | M32: =IF(Parâmetros!R10=1,G32/3,IF(Parâmetros!R10=2,0)) -> 0 | N32: =IF(ISBLANK(J32),"",IF(J32<=I32,"No prazo",IF(J32>I32,"Férias em dobro"))) | O32: =IF(ISBLANK(D32),"",IF(I32-Parâmetros!$B$10<=65,I32-Parâmetros!$B$10,IF(I32-Parâmetros!$B$10>65,I32-Parâmetros!$B$10)))
B33: 28 | E33: =IF(ISBLANK(D33),"",DATE(YEAR(D33)+1,MONTH(D33),DAY(D33))-1) | F33: 0 | G33: =IF(F33<Parâmetros!$E$3,Parâmetros!$F$3,VLOOKUP('Controle Vencimento Férias'!F33,Parâmetros!$C$3:$F$7,4,1)) -> 30 | H33: =IF(ISBLANK(D33),"",IF(E33<=Parâmetros!$B$10,"Vencidas",IF(E33>Parâmetros!$B$10,"Não vencidas"))) | I33: =IF(ISBLANK(D33),"",E33+336) | K33: =IF(ISBLANK(J33),"",(J33+G33-1)-M33) | M33: =IF(Parâmetros!R13=1,G33/3,IF(Parâmetros!R13=2,0)) -> 0 | N33: =IF(ISBLANK(J33),"",IF(J33<=I33,"No prazo",IF(J33>I33,"Férias em dobro"))) | O33: =IF(ISBLANK(D33),"",IF(I33-Parâmetros!$B$10<=65,I33-Parâmetros!$B$10,IF(I33-Parâmetros!$B$10>65,I33-Parâmetros!$B$10)))
B34: 29 | E34: =IF(ISBLANK(D34),"",DATE(YEAR(D34)+1,MONTH(D34),DAY(D34))-1) | F34: 0 | G34: =IF(F34<Parâmetros!$E$3,Parâmetros!$F$3,VLOOKUP('Controle Vencimento Férias'!F34,Parâmetros!$C$3:$F$7,4,1)) -> 30 | H34: =IF(ISBLANK(D34),"",IF(E34<=Parâmetros!$B$10,"Vencidas",IF(E34>Parâmetros!$B$10,"Não vencidas"))) | I34: =IF(ISBLANK(D34),"",E34+336) | K34: =IF(ISBLANK(J34),"",(J34+G34-1)-M34) | M34: =IF(Parâmetros!R16=1,G34/3,IF(Parâmetros!R16=2,0)) -> 0 | N34: =IF(ISBLANK(J34),"",IF(J34<=I34,"No prazo",IF(J34>I34,"Férias em dobro"))) | O34: =IF(ISBLANK(D34),"",IF(I34-Parâmetros!$B$10<=65,I34-Parâmetros!$B$10,IF(I34-Parâmetros!$B$10>65,I34-Parâmetros!$B$10)))
B35: 30 | E35: =IF(ISBLANK(D35),"",DATE(YEAR(D35)+1,MONTH(D35),DAY(D35))-1) | F35: 0 | G35: =IF(F35<Parâmetros!$E$3,Parâmetros!$F$3,VLOOKUP('Controle Vencimento Férias'!F35,Parâmetros!$C$3:$F$7,4,1)) -> 30 | H35: =IF(ISBLANK(D35),"",IF(E35<=Parâmetros!$B$10,"Vencidas",IF(E35>Parâmetros!$B$10,"Não vencidas"))) | I35: =IF(ISBLANK(D35),"",E35+336) | K35: =IF(ISBLANK(J35),"",(J35+G35-1)-M35) | M35: =IF(Parâmetros!R19=1,G35/3,IF(Parâmetros!R19=2,0)) -> 0 | N35: =IF(ISBLANK(J35),"",IF(J35<=I35,"No prazo",IF(J35>I35,"Férias em dobro"))) | O35: =IF(ISBLANK(D35),"",IF(I35-Parâmetros!$B$10<=65,I35-Parâmetros!$B$10,IF(I35-Parâmetros!$B$10>65,I35-Parâmetros!$B$10)))
B36: 31 | E36: =IF(ISBLANK(D36),"",DATE(YEAR(D36)+1,MONTH(D36),DAY(D36))-1) | F36: 0 | G36: =IF(F36<Parâmetros!$E$3,Parâmetros!$F$3,VLOOKUP('Controle Vencimento Férias'!F36,Parâmetros!$C$3:$F$7,4,1)) -> 30 | H36: =IF(ISBLANK(D36),"",IF(E36<=Parâmetros!$B$10,"Vencidas",IF(E36>Parâmetros!$B$10,"Não vencidas"))) | I36: =IF(ISBLANK(D36),"",E36+336) | K36: =IF(ISBLANK(J36),"",(J36+G36-1)-M36) | M36: =IF(Parâmetros!R22=1,G36/3,IF(Parâmetros!R22=2,0)) -> 0 | N36: =IF(ISBLANK(J36),"",IF(J36<=I36,"No prazo",IF(J36>I36,"Férias em dobro"))) | O36: =IF(ISBLANK(D36),"",IF(I36-Parâmetros!$B$10<=65,I36-Parâmetros!$B$10,IF(I36-Parâmetros!$B$10>65,I36-Parâmetros!$B$10)))
B37: 32 | E37: =IF(ISBLANK(D37),"",DATE(YEAR(D37)+1,MONTH(D37),DAY(D37))-1) | F37: 0 | G37: =IF(F37<Parâmetros!$E$3,Parâmetros!$F$3,VLOOKUP('Controle Vencimento Férias'!F37,Parâmetros!$C$3:$F$7,4,1)) -> 30 | H37: =IF(ISBLANK(D37),"",IF(E37<=Parâmetros!$B$10,"Vencidas",IF(E37>Parâmetros!$B$10,"Não vencidas"))) | I37: =IF(ISBLANK(D37),"",E37+336) | K37: =IF(ISBLANK(J37),"",(J37+G37-1)-M37) | M37: =IF(Parâmetros!R25=1,G37/3,IF(Parâmetros!R25=2,0)) -> 0 | N37: =IF(ISBLANK(J37),"",IF(J37<=I37,"No prazo",IF(J37>I37,"Férias em dobro"))) | O37: =IF(ISBLANK(D37),"",IF(I37-Parâmetros!$B$10<=65,I37-Parâmetros!$B$10,IF(I37-Parâmetros!$B$10>65,I37-Parâmetros!$B$10)))
B38: 33 | E38: =IF(ISBLANK(D38),"",DATE(YEAR(D38)+1,MONTH(D38),DAY(D38))-1) | F38: 0 | G38: =IF(F38<Parâmetros!$E$3,Parâmetros!$F$3,VLOOKUP('Controle Vencimento Férias'!F38,Parâmetros!$C$3:$F$7,4,1)) -> 30 | H38: =IF(ISBLANK(D38),"",IF(E38<=Parâmetros!$B$10,"Vencidas",IF(E38>Parâmetros!$B$10,"Não vencidas"))) | I38: =IF(ISBLANK(D38),"",E38+336) | K38: =IF(ISBLANK(J38),"",(J38+G38-1)-M38) | M38: =IF(Parâmetros!U4=1,G38/3,IF(Parâmetros!U4=2,0)) -> 0 | N38: =IF(ISBLANK(J38),"",IF(J38<=I38,"No prazo",IF(J38>I38,"Férias em dobro"))) | O38: =IF(ISBLANK(D38),"",IF(I38-Parâmetros!$B$10<=65,I38-Parâmetros!$B$10,IF(I38-Parâmetros!$B$10>65,I38-Parâmetros!$B$10)))
B39: 34 | E39: =IF(ISBLANK(D39),"",DATE(YEAR(D39)+1,MONTH(D39),DAY(D39))-1) | F39: 0 | G39: =IF(F39<Parâmetros!$E$3,Parâmetros!$F$3,VLOOKUP('Controle Vencimento Férias'!F39,Parâmetros!$C$3:$F$7,4,1)) -> 30 | H39: =IF(ISBLANK(D39),"",IF(E39<=Parâmetros!$B$10,"Vencidas",IF(E39>Parâmetros!$B$10,"Não vencidas"))) | I39: =IF(ISBLANK(D39),"",E39+336) | K39: =IF(ISBLANK(J39),"",(J39+G39-1)-M39) | M39: =IF(Parâmetros!U7=1,G39/3,IF(Parâmetros!U7=2,0)) -> 0 | N39: =IF(ISBLANK(J39),"",IF(J39<=I39,"No prazo",IF(J39>I39,"Férias em dobro"))) | O39: =IF(ISBLANK(D39),"",IF(I39-Parâmetros!$B$10<=65,I39-Parâmetros!$B$10,IF(I39-Parâmetros!$B$10>65,I39-Parâmetros!$B$10)))
B40: 35 | E40: =IF(ISBLANK(D40),"",DATE(YEAR(D40)+1,MONTH(D40),DAY(D40))-1) | F40: 0 | G40: =IF(F40<Parâmetros!$E$3,Parâmetros!$F$3,VLOOKUP('Controle Vencimento Férias'!F40,Parâmetros!$C$3:$F$7,4,1)) -> 30 | H40: =IF(ISBLANK(D40),"",IF(E40<=Parâmetros!$B$10,"Vencidas",IF(E40>Parâmetros!$B$10,"Não vencidas"))) | I40: =IF(ISBLANK(D40),"",E40+336) | K40: =IF(ISBLANK(J40),"",(J40+G40-1)-M40) | M40: =IF(Parâmetros!U10=1,G40/3,IF(Parâmetros!U10=2,0)) -> 0 | N40: =IF(ISBLANK(J40),"",IF(J40<=I40,"No prazo",IF(J40>I40,"Férias em dobro"))) | O40: =IF(ISBLANK(D40),"",IF(I40-Parâmetros!$B$10<=65,I40-Parâmetros!$B$10,IF(I40-Parâmetros!$B$10>65,I40-Parâmetros!$B$10)))
B41: 36 | E41: =IF(ISBLANK(D41),"",DATE(YEAR(D41)+1,MONTH(D41),DAY(D41))-1) | F41: 0 | G41: =IF(F41<Parâmetros!$E$3,Parâmetros!$F$3,VLOOKUP('Controle Vencimento Férias'!F41,Parâmetros!$C$3:$F$7,4,1)) -> 30 | H41: =IF(ISBLANK(D41),"",IF(E41<=Parâmetros!$B$10,"Vencidas",IF(E41>Parâmetros!$B$10,"Não vencidas"))) | I41: =IF(ISBLANK(D41),"",E41+336) | K41: =IF(ISBLANK(J41),"",(J41+G41-1)-M41) | M41: =IF(Parâmetros!U13=1,G41/3,IF(Parâmetros!U13=2,0)) -> 0 | N41: =IF(ISBLANK(J41),"",IF(J41<=I41,"No prazo",IF(J41>I41,"Férias em dobro"))) | O41: =IF(ISBLANK(D41),"",IF(I41-Parâmetros!$B$10<=65,I41-Parâmetros!$B$10,IF(I41-Parâmetros!$B$10>65,I41-Parâmetros!$B$10)))
B42: 37 | E42: =IF(ISBLANK(D42),"",DATE(YEAR(D42)+1,MONTH(D42),DAY(D42))-1) | F42: 0 | G42: =IF(F42<Parâmetros!$E$3,Parâmetros!$F$3,VLOOKUP('Controle Vencimento Férias'!F42,Parâmetros!$C$3:$F$7,4,1)) -> 30 | H42: =IF(ISBLANK(D42),"",IF(E42<=Parâmetros!$B$10,"Vencidas",IF(E42>Parâmetros!$B$10,"Não vencidas"))) | I42: =IF(ISBLANK(D42),"",E42+336) | K42: =IF(ISBLANK(J42),"",(J42+G42-1)-M42) | M42: =IF(Parâmetros!U16=1,G42/3,IF(Parâmetros!U16=2,0)) -> 0 | N42: =IF(ISBLANK(J42),"",IF(J42<=I42,"No prazo",IF(J42>I42,"Férias em dobro"))) | O42: =IF(ISBLANK(D42),"",IF(I42-Parâmetros!$B$10<=65,I42-Parâmetros!$B$10,IF(I42-Parâmetros!$B$10>65,I42-Parâmetros!$B$10)))
...

Sheet Parâmetros
B2: Faltas no período aquisitivo | F2: Dias | H2: 1 | J2: Abono | K2: 9 | M2: Abono | N2: 17 | P2: Abono | Q2: 25 | S2: Abono | T2: 33 | V2: Abono | W2: 41 | Y2: Abono | Z2: 49 | AB2: Abono
B3: de | C3: 0 | D3: a | E3: 5 | F3: 30 | J3: SIM | M3: SIM | P3: SIM | S3: SIM | V3: SIM | Y3: SIM | AB3: SIM
B4: de | C4: 6 | D4: a | E4: 14 | F4: 24 | I4: 2 | J4: NÃO | L4: 2 | M4: NÃO | O4: 2 | P4: NÃO | R4: 2 | S4: NÃO | U4: 2 | V4: NÃO | X4: 2 | Y4: NÃO | AA4: 2 | AB4: NÃO
B5: de | C5: 15 | D5: a | E5: 23 | F5: 18 | H5: 2 | J5: Abono | K5: 10 | M5: Abono | N5: 18 | P5: Abono | Q5: 26 | S5: Abono | T5: 34 | V5: Abono | W5: 42 | Y5: Abono | Z5: 50 | AB5: Abono
B6: de | C6: 24 | D6: a | E6: 32 | F6: 12 | J6: SIM | M6: SIM | P6: SIM | S6: SIM | V6: SIM | Y6: SIM | AB6: SIM
B7: de | C7: 33 | D7: a | E7: 99 | F7: 0 | I7: 2 | J7: NÃO | L7: 2 | M7: NÃO | O7: 2 | P7: NÃO | R7: 2 | S7: NÃO | U7: 2 | V7: NÃO | X7: 2 | Y7: NÃO | AA7: 2 | AB7: NÃO
H8: 3 | J8: Abono | K8: 11 | M8: Abono | N8: 19 | P8: Abono | Q8: 27 | S8: Abono | T8: 35 | V8: Abono | W8: 43 | Y8: Abono
B9: data atual | J9: SIM | M9: SIM | P9: SIM | S9: SIM | V9: SIM | Y9: SIM
B10: =NOW() -> 43191.476 | I10: 2 | J10: NÃO | L10: 2 | M10: NÃO | O10: 2 | P10: NÃO | R10: 2 | S10: NÃO | U10: 2 | V10: NÃO | X10: 2 | Y10: NÃO
H11: 4 | J11: Abono | K11: 12 | M11: Abono | N11: 20 | P11: Abono | Q11: 28 | S11: Abono | T11: 36 | V11: Abono | W11: 44 | Y11: Abono
J12: SIM | M12: SIM | P12: SIM | S12: SIM | V12: SIM | Y12: SIM
I13: 2 | J13: NÃO | L13: 2 | M13: NÃO | O13: 2 | P13: NÃO | R13: 2 | S13: NÃO | U13: 2 | V13: NÃO | X13: 2 | Y13: NÃO
H14: 5 | J14: Abono | K14: 13 | M14: Abono | N14: 21 | P14: Abono | Q14: 29 | S14: Abono | T14: 37 | V14: Abono | W14: 45 | Y14: Abono
B15: cálculo dias abono | J15: SIM | M15: SIM | P15: SIM | S15: SIM | V15: SIM | Y15: SIM
B16: =IF('Controle Vencimento Férias'!F6<=Parâmetros!E3,Parâmetros!F3,VLOOKUP('Controle Vencimento Férias'!F6,Parâmetros!C3:F7,4,1)) -> 30 | C16: 24 | I16: 2 | J16: NÃO | L16: 2 | M16: NÃO | O16: 2 | P16: NÃO | R16: 2 | S16: NÃO | U16: 2 | V16: NÃO | X16: 2 | Y16: NÃO
B17: 8 | H17: 6 | J17: Abono | K17: 14 | M17: Abono | N17: 22 | P17: Abono | Q17: 30 | S17: Abono | T17: 38 | V17: Abono | W17: 46 | Y17: Abono
J18: SIM | M18: SIM | P18: SIM | S18: SIM | V18: SIM | Y18: SIM
I19: 2 | J19: NÃO | L19: 2 | M19: NÃO | O19: 2 | P19: NÃO | R19: 2 | S19: NÃO | U19: 2 | V19: NÃO | X19: 2 | Y19: NÃO
H20: 7 | J20: Abono | K20: 15 | M20: Abono | N20: 23 | P20: Abono | Q20: 31 | S20: Abono | T20: 39 | V20: Abono | W20: 47 | Y20: Abono
J21: SIM | M21: SIM | P21: SIM | S21: SIM | V21: SIM | Y21: SIM
I22: 2 | J22: NÃO | L22: 2 | M22: NÃO | O22: 2 | P22: NÃO | R22: 2 | S22: NÃO | U22: 2 | V22: NÃO | X22: 2 | Y22: NÃO
H23: 8 | J23: Abono | K23: 16 | M23: Abono | N23: 24 | P23: Abono | Q23: 32 | S23: Abono | T23: 40 | V23: Abono | W23: 48 | Y23: Abono
J24: SIM | M24: SIM | P24: SIM | S24: SIM | V24: SIM | Y24: SIM
I25: 2 | J25: NÃO | L25: 2 | M25: NÃO | O25: 2 | P25: NÃO | R25: 2 | S25: NÃO | U25: 2 | V25: NÃO | X25: 2 | Y25: NÃO
