Workbook

Sheet CPC 06 R2 - Árvore de Decisão
B2: FAQ CPC 06 (R2)
B4: 1) | C4: Existe um Ativo Identificado?
B6: 2) | C6: O cliente tem o direito de obter substancialmente todos os benefícios econômicos do uso do ativo durante todo o período de uso?
B9: 3) | C9: O cliente, o fornecedor, ou nenhuma das partes, tem o direito de direcionar como e para qual finalidade o ativo é usado durante todo o período de uso?
B12: 4) | C12: O cliente tem direito de operar o ativo durante todo o período de uso, sem o fornecedor ter o direito de alterar essas instruções operacionais?
B15: 5) | C15: O cliente projetou o ativo de modo que predetermina como e para qual finalidade o ativo será usado durante todo o período de uso?

Sheet Resumo Contratos
B2: Resumo Contratos de Alugueis
B4: # Identificação Contrato | C4: Conforme Contrato | O4: Utilizado para análise
C5: Tipo Contrato | D5: Locador | E5: Ativo Identificado | F5: Valor ao mês | G5: Reajuste | H5: Entrada / Antecipação | I5: Taxa Implícita (a.a.) | J5: Prazo (Meses) | K5: Data Início | L5: Data Final | M5: Observação | O5: Arrendamento conforme CPC 06 ? | P5: Justificativa | Q5: Reajuste Anual | R5: Taxa Incremental (a.a.) | S5: Prazo (Meses) | T5: Data Início | U5: Data Final | V5: Observação
B6: 1 | C6: Instrumento Particular de Contrato de Locação de Imóvel Urbano para fins comerciais | D6: Sandro G de Moraes ME | E6: Terreno urbano de nº 07-B-8, com 5.969m², com três edificações, sendo que a primeira refere-se a um barracão comercial em alvenaria, medindo 700m², a segunda refere-se a uma varanda de aproximadamente 180m², e a terceira trata-se de construção no andar superior mediindo 75m², melhor descrita e caracterizada na Matrícula de nº 1.615, do Cartório de Registro de Imóveis da Comarca de Paranatinga/MT | F6: 9540 | G6: Valor mensal referente a 10 salários mínimos + IPG-M, anualmente | H6: N/A | I6: N/A | J6: =6*12 -> 72 | K6: 43313 | L6: 45550 | O6: Sim | P6: O ativo atende todos os requisitos previstos no CPC 06 (R2) para ser considerado arrendamento | Q6: =Premissas!$F$19 -> 0.049636326 | R6: =Premissas!$N$19 -> 0.10384722 | S6: =5*12 -> 60 | T6: 43466 | U6: =DATE(YEAR(T6),(MONTH(T6)+S6),DAY(T6))-1 -> 45291 | V6: Prazo de 5 anos sugerido pela administração, baseado na expectativa de continuidade operacional da filial. Anualmente o prazo será revisado.
B7: 2 | C7: Instrumento Particular de Contrato de Locação de Imóvel Urbano para fins comerciais | D7: Edualdo Junior Simões | E7: Prédio Comercial com área de 400 m², a qual faz parte de um total da área construída de 800 m² edificada no lote 01, quadra 26, loteamento denominado "Villa Santiago do Norte", com área total de 2.512,35 m², melhor descrita e caracterizada na matrícula de nº 6.040, do Cartório de Registro de Imóveis da Comarca de Paranatinga/MT | F7: 2000 | G7: N/A | H7: N/A | I7: N/A | J7: 24 | K7: 43467 | L7: 44198 | O7: Sim | P7: O ativo atende todos os requisitos previstos no CPC 06 (R2) para ser considerado arrendamento | Q7: =Premissas!$F$19 -> 0.049636326 | R7: =Premissas!$N$19 -> 0.10384722 | S7: =5*12 -> 60 | T7: 43466 | U7: =DATE(YEAR(T7),(MONTH(T7)+S7),DAY(T7))-1 -> 45291 | V7: Prazo de 5 anos sugerido pela administração, baseado na expectativa de continuidade operacional da filial. Anualmente o prazo será revisado.
B8: 3 | C8: Instrumento Particular de Contrato de Locação de Imóvel Urbano para fins comerciais | D8: W.I. Construções e Serviços Ltda ME | E8: 01 Lote de Terreno urbano, constituído do membramento dos lotes 04 e 08, situado na cidade de Chapadão do Céu/GO, com área total de 2.975 m² de área de terreno e 794,23 m² de área construída, melhor descrito e caracterizado na matrícula de nº 2.264, do Cartório de Registro de Imóveis da Comarca de Serranópolis/GO | F8: 18000 | G8: IGP-M, anualmente | H8: R$ 100.000,00, correspondente a 06 meses de aluguel | I8: N/A | J8: =8*12 -> 96 | K8: 43617 | L8: 46537 | O8: Sim | P8: O ativo atende todos os requisitos previstos no CPC 06 (R2) para ser considerado arrendamento | Q8: =Premissas!$F$19 -> 0.049636326 | R8: =Premissas!$N$19 -> 0.10384722 | S8: =5*12 -> 60 | T8: 43466 | U8: =DATE(YEAR(T8),(MONTH(T8)+S8),DAY(T8))-1 -> 45291 | V8: Prazo de 5 anos sugerido pela administração, baseado na expectativa de continuidade operacional da filial. Anualmente o prazo será revisado.
B9: 4 | C9: Instrumento Particular de Contrato de Locação de Terreno | D9: Dirceu Antônio dos Santos | E9: Gleba de terras, denominada "Fazenda Nova Esperança", localizada no município de Chapadão do Sul/MS, com área de 252,939 ha, melhor descrita e caracterizada na matrícula de nº 14.484, do Cartório de Registro de Imóveis da Comarca de Chapadão do Sul/MS | F9: 1000 | G9: N/A | H9: N/A | I9: N/A | J9: 4 | K9: 43040 | L9: 43160 | O9: Sim | P9: O ativo atende todos os requisitos previstos no CPC 06 (R2) para ser considerado arrendamento | Q9: =Premissas!$F$19 -> 0.049636326 | R9: =Premissas!$N$19 -> 0.10384722 | S9: =5*12 -> 60 | T9: 43466 | U9: =DATE(YEAR(T9),(MONTH(T9)+S9),DAY(T9))-1 -> 45291 | V9: Prazo de 5 anos sugerido pela administração, baseado na expectativa de continuidade operacional da filial. Anualmente o prazo será revisado.
B10: 5 | C10: Instrumento Particular de Contrato de Locação de Imóvel Urbano para fins comerciais | D10: Valdir Fedrigo e Evalda Fedrigo | E10: 01 Prédio comercial de 62,15 m², com área total construída de 830,29 m², edificada no lote 10-A, quadra 05, com área total de 1.781,15 m², localizado na Rua Juscelino Kubitschek, 145, Polo Empresarial, CEP: 79.560-000, melhor descrita e caracterizada na matrícula de nº 8.252, do Cartório de Registro de Imóveis da Comarca de Chapadão do Sul/MS | F10: 13000 | G10: N/A | H10: N/A | I10: N/A | J10: =5*12 -> 60 | K10: 43497 | L10: 45323 | O10: Sim | P10: O ativo atende todos os requisitos previstos no CPC 06 (R2) para ser considerado arrendamento | Q10: =Premissas!$F$19 -> 0.049636326 | R10: =Premissas!$N$19 -> 0.10384722 | S10: =5*12 -> 60 | T10: 43466 | U10: =DATE(YEAR(T10),(MONTH(T10)+S10),DAY(T10))-1 -> 45291 | V10: Prazo de 5 anos sugerido pela administração, baseado na expectativa de continuidade operacional da filial. Anualmente o prazo será revisado.
B11: 6 | C11: Instrumento Particular de Contrato de Locação de Imóvel Urbano para fins comerciais | D11: Agro Baggio Máquinas Agrícolas Ltda | E11: 02 Imóveis comerciais, com total de 6.132,846 m² de área de terreno, com total de 1.466,20 m² de área construída, nas seguintes composições: a) - 01 lote de terras denominado 07-B-9, com 1.600 m², com 01 edificação de 1.025,63 m², situado no "Perímetro Urbano" da cidade de Paranatinga/MT, imóvel melhor descrito e caracterizado na matrícula de nº 1.742, do Cartório de Registro de Imóveis da Comarca de Paranatinga/MT; b) - 01 lote de terras denominado 07-B-10A, com 4.532,846 m², com 02 edificações , sendo que a primeira refere- se a um prédio aos fundos, para depósito de óleo, peças grandes, materiais recicláveis , com 149,29 m², e o segundo refere- se à uma rampa de lavagem com 291,28 m², melhor descrita e caracterizada na matrícula de nº 6.538, do Cartório de Registro de Imóveis da Comarca de Paranatinga/MT | F11: 9540 | G11: Valor mensal referente a 10 salários mínimos + IPG-M, anualmente | H11: N/A | I11: N/A | J11: =6*12 -> 72 | K11: 43313 | L11: 45565 | O11: Sim | P11: O ativo atende todos os requisitos previstos no CPC 06 (R2) para ser considerado arrendamento | Q11: =Premissas!$F$19 -> 0.049636326 | R11: =Premissas!$N$19 -> 0.10384722 | S11: =5*12 -> 60 | T11: 43466 | U11: =DATE(YEAR(T11),(MONTH(T11)+S11),DAY(T11))-1 -> 45291 | V11: Prazo de 5 anos sugerido pela administração, baseado na expectativa de continuidade operacional da filial. Anualmente o prazo será revisado.
B12: 7 | C12: Instrumento Particular de Contrato de Locação de Imóvel Urbano | D12: RS Pneus e Equipamentos Ltda | E12: 02 imóveis com total de 1.119 m² de área de terreno, e 800 m², localizado a Rua Juscelino Kubitschek, 344, Anexo A, Castelândia II, município de Primavera do Leste/MT, CEP: 78.850-000, nas seguintes composições: a) - 01 lote de terras nº 17, na quadra 01 do loteamento Parque Castelândia II, na cidade de Primavera do Leste/MS, com área de 559,50 m², melhor descrito e caracterizado na matrícula de nº 2.236, do Cartório de Registro de Imóveis da Comarca de Primavera do Leste/MT; b) - 01 lote de terras nº 18, na quadra 01 do loteamento Parque Castelândia II, na Cidade de Primavera do Leste/MS, com área de 559,50 m², melhor descrito e caracterizado na matrícula de nº 2.237, do Cartório de Registro de Imóveis da Comarca de Primavera do Leste/MT | F12: 3500 | G12: IGP-M, anualmente | H12: N/A | I12: N/A | J12: 24 | K12: 43497 | L12: 44228 | O12: Sim | P12: O ativo atende todos os requisitos previstos no CPC 06 (R2) para ser considerado arrendamento | Q12: =Premissas!$F$19 -> 0.049636326 | R12: =Premissas!$N$19 -> 0.10384722 | S12: =5*12 -> 60 | T12: 43466 | U12: =DATE(YEAR(T12),(MONTH(T12)+S12),DAY(T12))-1 -> 45291 | V12: Prazo de 5 anos sugerido pela administração, baseado na expectativa de continuidade operacional da filial. Anualmente o prazo será revisado.
B13: 8 | C13: Contrato de Locação de Veículos | D13: Ouro Verde Locação e Serviço S/A | E13: 20 Fiat Strada 1.4 CE Hard Working 2019 Manual 2P Flex 578/24F/0 | F13: =1384.05*20 -> 27681 | G13: IGP-M, anualmente | H13: N/A | I13: N/A | J13: 36 | K13: 43516 | L13: =DATE(YEAR(K13),(MONTH(K13)+J13),DAY(K13)) -> 44612 | O13: Não | P13: Possui cláusula prevendo a possibilidade de subtituição do ativo, a pedido do locador | Q13: N/A | R13: N/A | S13: N/A | T13: N/A | U13: N/A | V13: N/A
B14: 9 | C14: Contrato de Locação de Veículos | D14: Arval - BNP Paribas | E14: 01 Fiat Strada Pick-up 1.4 CE Hard Working 18/19 2019 2P | F14: 1303.21 | G14: IGP-M, anualmente | H14: N/A | I14: N/A | J14: 36 | K14: 43469 | L14: =DATE(YEAR(K14),(MONTH(K14)+J14),DAY(K14)) -> 44565 | O14: Não | P14: Possui cláusula prevendo a possibilidade de subtituição do ativo, a pedido do locador | Q14: N/A | R14: N/A | S14: N/A | T14: N/A | U14: N/A | V14: N/A
B15: 10 | C15: Contrato de Locação de Veículos | D15: Arval - BNP Paribas | E15: 01 Fiat Toro Pick-up 1.8 Endurance Auto 18/19 2019 4P | F15: 2117 | G15: IGP-M, anualmente | H15: N/A | I15: N/A | J15: 36 | K15: 43469 | L15: =DATE(YEAR(K15),(MONTH(K15)+J15),DAY(K15)) -> 44565 | O15: Não | P15: Possui cláusula prevendo a possibilidade de subtituição do ativo, a pedido do locador | Q15: N/A | R15: N/A | S15: N/A | T15: N/A | U15: N/A | V15: N/A
B16: 11 | C16: Contrato de Locação de Veículos | D16: Arval - BNP Paribas | E16: 01 Volkswagen Amarok Pick-up 2.0 CS S 4x4 18/19 2019 2P | F16: 2395 | G16: IGP-M, anualmente | H16: N/A | I16: N/A | J16: 36 | K16: 43469 | L16: =DATE(YEAR(K16),(MONTH(K16)+J16),DAY(K16)) -> 44565 | O16: Não | P16: Possui cláusula prevendo a possibilidade de subtituição do ativo, a pedido do locador | Q16: N/A | R16: N/A | S16: N/A | T16: N/A | U16: N/A | V16: N/A

Sheet Premissas
C2: IGP-M | K2: Taxas de Mercado - Financiamento Imobiliário PJ
C4: Data | D4: 189 - Índice geral de preços do mercado (IGP-M) - Var. % mensal | F4: Percentual a.m. % | K4: Data | L4: 20761 - Taxa média de juros das operações de crédito com recursos direcionados - Pessoas jurídicas - Financiamento imobiliário com taxas de mercado - % a.a. | M4: 20762 - Taxa média de juros das operações de crédito com recursos direcionados - Pessoas jurídicas - Financiamento imobiliário com taxas reguladas - % a.a. | N4: 20763 - Taxa média de juros das operações de crédito com recursos direcionados - Pessoas jurídicas - Financiamento imobiliário total - % a.a.
C5: 43344 | D5: 1.52 | F5: =D5% -> 0.0152 | K5: 43344 | L5: 10.64 | M5: 9.71 | N5: 10.33
C6: 43374 | D6: 0.89 | F6: =D6% -> 0.0089 | K6: 43374 | L6: 11.22 | M6: 10.41 | N6: 10.95
C7: 43405 | D7: -0.49 | F7: =D7% -> -0.0049 | K7: 43405 | L7: 10.72 | M7: 10.06 | N7: 10.5
C8: 43435 | D8: -1.08 | F8: =D8% -> -0.0108 | K8: 43435 | L8: 10.46 | M8: 9.6 | N8: 10.18
C9: 43466 | D9: 0.01 | F9: =D9% -> 0.0001 | K9: 43466 | L9: 11.19 | M9: 10.43 | N9: 10.94
C10: 43497 | D10: 0.88 | F10: =D10% -> 0.0088 | K10: 43497 | L10: 10.48 | M10: 10.09 | N10: 10.35
C11: 43525 | D11: 1.26 | F11: =D11% -> 0.0126 | K11: 43525 | L11: 11.01 | M11: 10.05 | N11: 10.72
C12: 43556 | D12: 0.92 | F12: =D12% -> 0.0092 | K12: 43556 | L12: 10.34 | M12: 10.06 | N12: 10.25
C13: 43586 | D13: 0.45 | F13: =D13% -> 0.0045 | K13: 43586 | L13: 10.79 | M13: 9.97 | N13: 10.54
C14: 43617 | D14: 0.8 | F14: =D14% -> 0.008 | K14: 43617 | L14: 10.8 | M14: 10.24 | N14: 10.63
C15: 43647 | D15: 0.4 | F15: =D15% -> 0.004 | K15: 43647 | L15: 10.39 | M15: 10.11 | N15: 10.3
C16: 43678 | D16: -0.67 | F16: =D16% -> -0.0067 | K16: 43678 | L16: 9.75 | M16: 9.86 | N16: 9.78
C17: Fonte: | D17: FGV | K17: Fonte | L17: BCB-DSTAT | M17: BCB-DSTAT | N17: BCB-DSTAT
C19: % IGP-M Médio a.a. - Últimos 12 Meses | F19: =FVSCHEDULE(1,F5:F16)-1 -> 0.049636326 | L19: % Taxa Média a.a. - Últimos 12 Meses | N19: =AVERAGE(L5:N16)% -> 0.10384722
L20: % Taxa Média a.m. - Últimos 12 Meses | N20: =(1+N19)^(1/12)-1 -> 0.0082674509
C27: Fonte: https://www.portalbrasil.net/igpm.htm

Sheet Contabilização
B2: Fluxo de Pagamentos - 5 Anos - Com expectativa de atualização anual pelo IGP-M
B4: # Identificação Contrato | C4: 43466 | D4: 43497 | E4: 43525 | F4: 43556 | G4: 43586 | H4: 43617 | I4: 43647 | J4: 43678 | K4: 43709 | L4: 43739 | M4: 43770 | N4: 43800 | O4: 43831 | P4: 43862 | Q4: 43891 | R4: 43922 | S4: 43952 | T4: 43983 | U4: 44013 | V4: 44044 | W4: 44075 | X4: 44105 | Y4: 44136 | Z4: 44166 | AA4: 44197 | AB4: 44228 | AC4: 44256 | AD4: 44287 | AE4: 44317 | AF4: 44348 | AG4: 44378 | AH4: 44409 | AI4: 44440 | AJ4: 44470 | AK4: 44501 | AL4: 44531 | AM4: 44562 | AN4: 44593 | AO4: 44621 | AP4: 44652 | AQ4: 44682 | AR4: 44713 | AS4: 44743 | AT4: 44774 | AU4: 44805 | AV4: 44835 | AW4: 44866 | AX4: 44896 | AY4: 44927 | AZ4: 44958 | BA4: 44986 | BB4: 45017 | BC4: 45047 | BD4: 45078 | BE4: 45108 | BF4: 45139 | BG4: 45170 | BH4: 45200 | BI4: 45231 | BJ4: 45261 | BK4: TOTAL
B5: 1 | C5: ='Resumo Contratos'!F6 -> 9540 | D5: =C5 -> 9540 | E5: =D5 -> 9540 | F5: =E5 -> 9540 | G5: =F5 -> 9540 | H5: =G5 -> 9540 | I5: =H5 -> 9540 | J5: =I5 -> 9540 | K5: =J5 -> 9540 | ... N5: =M5 -> 9540 | O5: =N5+(N5*Premissas!$F$19) -> 10013.531 | P5: =O5 -> 10013.531 | Q5: =P5 -> 10013.531 | R5: =Q5 -> 10013.531 | S5: =R5 -> 10013.531 | T5: =S5 -> 10013.531 | U5: =T5 -> 10013.531 | V5: =U5 -> 10013.531 | W5: =V5 -> 10013.531 | ... Z5: =Y5 -> 10013.531 | AA5: =Z5+(Z5*Premissas!$F$19) -> 10510.565 | AB5: =AA5 -> 10510.565 | AC5: =AB5 -> 10510.565 | AD5: =AC5 -> 10510.565 | AE5: =AD5 -> 10510.565 | AF5: =AE5 -> 10510.565 | AG5: =AF5 -> 10510.565 | AH5: =AG5 -> 10510.565 | AI5: =AH5 -> 10510.565 | ... AL5: =AK5 -> 10510.565 | AM5: =AL5+(AL5*Premissas!$F$19) -> 11032.271 | AN5: =AM5 -> 11032.271 | AO5: =AN5 -> 11032.271 | AP5: =AO5 -> 11032.271 | AQ5: =AP5 -> 11032.271 | AR5: =AQ5 -> 11032.271 | AS5: =AR5 -> 11032.271 | AT5: =AS5 -> 11032.271 | AU5: =AT5 -> 11032.271 | ... AX5: =AW5 -> 11032.271 | AY5: =AX5+(AX5*Premissas!$F$19) -> 11579.873 | AZ5: =AY5 -> 11579.873 | BA5: =AZ5 -> 11579.873 | BB5: =BA5 -> 11579.873 | BC5: =BB5 -> 11579.873 | BD5: =BC5 -> 11579.873 | BE5: =BD5 -> 11579.873 | BF5: =BE5 -> 11579.873 | BG5: =BF5 -> 11579.873 | ... BJ5: =BI5 -> 11579.873 | BK5: =SUM(C5:BJ5) -> 632114.88
B6: 2 | C6: ='Resumo Contratos'!F7 -> 2000 | D6: =C6 -> 2000 | E6: =D6 -> 2000 | F6: =E6 -> 2000 | G6: =F6 -> 2000 | H6: =G6 -> 2000 | I6: =H6 -> 2000 | J6: =I6 -> 2000 | K6: =J6 -> 2000 | ... N6: =M6 -> 2000 | O6: =N6+(N6*Premissas!$F$19) -> 2099.2727 | P6: =O6 -> 2099.2727 | Q6: =P6 -> 2099.2727 | R6: =Q6 -> 2099.2727 | S6: =R6 -> 2099.2727 | T6: =S6 -> 2099.2727 | U6: =T6 -> 2099.2727 | V6: =U6 -> 2099.2727 | W6: =V6 -> 2099.2727 | ... Z6: =Y6 -> 2099.2727 | AA6: =Z6+(Z6*Premissas!$F$19) -> 2203.4728 | AB6: =AA6 -> 2203.4728 | AC6: =AB6 -> 2203.4728 | AD6: =AC6 -> 2203.4728 | AE6: =AD6 -> 2203.4728 | AF6: =AE6 -> 2203.4728 | AG6: =AF6 -> 2203.4728 | AH6: =AG6 -> 2203.4728 | AI6: =AH6 -> 2203.4728 | ... AL6: =AK6 -> 2203.4728 | AM6: =AL6+(AL6*Premissas!$F$19) -> 2312.8451 | AN6: =AM6 -> 2312.8451 | AO6: =AN6 -> 2312.8451 | AP6: =AO6 -> 2312.8451 | AQ6: =AP6 -> 2312.8451 | AR6: =AQ6 -> 2312.8451 | AS6: =AR6 -> 2312.8451 | AT6: =AS6 -> 2312.8451 | AU6: =AT6 -> 2312.8451 | ... AX6: =AW6 -> 2312.8451 | AY6: =AX6+(AX6*Premissas!$F$19) -> 2427.6463 | AZ6: =AY6 -> 2427.6463 | BA6: =AZ6 -> 2427.6463 | BB6: =BA6 -> 2427.6463 | BC6: =BB6 -> 2427.6463 | BD6: =BC6 -> 2427.6463 | BE6: =BD6 -> 2427.6463 | BF6: =BE6 -> 2427.6463 | BG6: =BF6 -> 2427.6463 | ... BJ6: =BI6 -> 2427.6463 | BK6: =SUM(C6:BJ6) -> 132518.84
B7: 3 | C7: ='Resumo Contratos'!F8 -> 18000 | D7: =C7 -> 18000 | E7: =D7 -> 18000 | F7: =E7 -> 18000 | G7: =F7 -> 18000 | H7: =G7 -> 18000 | I7: =H7 -> 18000 | J7: =I7 -> 18000 | K7: =J7 -> 18000 | ... N7: =M7 -> 18000 | O7: =N7+(N7*Premissas!$F$19) -> 18893.454 | P7: =O7 -> 18893.454 | Q7: =P7 -> 18893.454 | R7: =Q7 -> 18893.454 | S7: =R7 -> 18893.454 | T7: =S7 -> 18893.454 | U7: =T7 -> 18893.454 | V7: =U7 -> 18893.454 | W7: =V7 -> 18893.454 | ... Z7: =Y7 -> 18893.454 | AA7: =Z7+(Z7*Premissas!$F$19) -> 19831.255 | AB7: =AA7 -> 19831.255 | AC7: =AB7 -> 19831.255 | AD7: =AC7 -> 19831.255 | AE7: =AD7 -> 19831.255 | AF7: =AE7 -> 19831.255 | AG7: =AF7 -> 19831.255 | AH7: =AG7 -> 19831.255 | AI7: =AH7 -> 19831.255 | ... AL7: =AK7 -> 19831.255 | AM7: =AL7+(AL7*Premissas!$F$19) -> 20815.606 | AN7: =AM7 -> 20815.606 | AO7: =AN7 -> 20815.606 | AP7: =AO7 -> 20815.606 | AQ7: =AP7 -> 20815.606 | AR7: =AQ7 -> 20815.606 | AS7: =AR7 -> 20815.606 | AT7: =AS7 -> 20815.606 | AU7: =AT7 -> 20815.606 | ... AX7: =AW7 -> 20815.606 | AY7: =AX7+(AX7*Premissas!$F$19) -> 21848.816 | AZ7: =AY7 -> 21848.816 | BA7: =AZ7 -> 21848.816 | BB7: =BA7 -> 21848.816 | BC7: =BB7 -> 21848.816 | BD7: =BC7 -> 21848.816 | BE7: =BD7 -> 21848.816 | BF7: =BE7 -> 21848.816 | BG7: =BF7 -> 21848.816 | ... BJ7: =BI7 -> 21848.816 | BK7: =SUM(C7:BJ7) -> 1192669.6
B8: 4 | C8: ='Resumo Contratos'!F9 -> 1000 | D8: =C8 -> 1000 | E8: =D8 -> 1000 | F8: =E8 -> 1000 | G8: =F8 -> 1000 | H8: =G8 -> 1000 | I8: =H8 -> 1000 | J8: =I8 -> 1000 | K8: =J8 -> 1000 | ... N8: =M8 -> 1000 | O8: =N8+(N8*Premissas!$F$19) -> 1049.6363 | P8: =O8 -> 1049.6363 | Q8: =P8 -> 1049.6363 | R8: =Q8 -> 1049.6363 | S8: =R8 -> 1049.6363 | T8: =S8 -> 1049.6363 | U8: =T8 -> 1049.6363 | V8: =U8 -> 1049.6363 | W8: =V8 -> 1049.6363 | ... Z8: =Y8 -> 1049.6363 | AA8: =Z8+(Z8*Premissas!$F$19) -> 1101.7364 | AB8: =AA8 -> 1101.7364 | AC8: =AB8 -> 1101.7364 | AD8: =AC8 -> 1101.7364 | AE8: =AD8 -> 1101.7364 | AF8: =AE8 -> 1101.7364 | AG8: =AF8 -> 1101.7364 | AH8: =AG8 -> 1101.7364 | AI8: =AH8 -> 1101.7364 | ... AL8: =AK8 -> 1101.7364 | AM8: =AL8+(AL8*Premissas!$F$19) -> 1156.4226 | AN8: =AM8 -> 1156.4226 | AO8: =AN8 -> 1156.4226 | AP8: =AO8 -> 1156.4226 | AQ8: =AP8 -> 1156.4226 | AR8: =AQ8 -> 1156.4226 | AS8: =AR8 -> 1156.4226 | AT8: =AS8 -> 1156.4226 | AU8: =AT8 -> 1156.4226 | ... AX8: =AW8 -> 1156.4226 | AY8: =AX8+(AX8*Premissas!$F$19) -> 1213.8231 | AZ8: =AY8 -> 1213.8231 | BA8: =AZ8 -> 1213.8231 | BB8: =BA8 -> 1213.8231 | BC8: =BB8 -> 1213.8231 | BD8: =BC8 -> 1213.8231 | BE8: =BD8 -> 1213.8231 | BF8: =BE8 -> 1213.8231 | BG8: =BF8 -> 1213.8231 | ... BJ8: =BI8 -> 1213.8231 | BK8: =SUM(C8:BJ8) -> 66259.421
B9: 5 | C9: ='Resumo Contratos'!F10 -> 13000 | D9: =C9 -> 13000 | E9: =D9 -> 13000 | F9: =E9 -> 13000 | G9: =F9 -> 13000 | H9: =G9 -> 13000 | I9: =H9 -> 13000 | J9: =I9 -> 13000 | K9: =J9 -> 13000 | ... N9: =M9 -> 13000 | O9: =N9+(N9*Premissas!$F$19) -> 13645.272 | P9: =O9 -> 13645.272 | Q9: =P9 -> 13645.272 | R9: =Q9 -> 13645.272 | S9: =R9 -> 13645.272 | T9: =S9 -> 13645.272 | U9: =T9 -> 13645.272 | V9: =U9 -> 13645.272 | W9: =V9 -> 13645.272 | ... Z9: =Y9 -> 13645.272 | AA9: =Z9+(Z9*Premissas!$F$19) -> 14322.573 | AB9: =AA9 -> 14322.573 | AC9: =AB9 -> 14322.573 | AD9: =AC9 -> 14322.573 | AE9: =AD9 -> 14322.573 | AF9: =AE9 -> 14322.573 | AG9: =AF9 -> 14322.573 | AH9: =AG9 -> 14322.573 | AI9: =AH9 -> 14322.573 | ... AL9: =AK9 -> 14322.573 | AM9: =AL9+(AL9*Premissas!$F$19) -> 15033.493 | AN9: =AM9 -> 15033.493 | AO9: =AN9 -> 15033.493 | AP9: =AO9 -> 15033.493 | AQ9: =AP9 -> 15033.493 | AR9: =AQ9 -> 15033.493 | AS9: =AR9 -> 15033.493 | AT9: =AS9 -> 15033.493 | AU9: =AT9 -> 15033.493 | ... AX9: =AW9 -> 15033.493 | AY9: =AX9+(AX9*Premissas!$F$19) -> 15779.701 | AZ9: =AY9 -> 15779.701 | BA9: =AZ9 -> 15779.701 | BB9: =BA9 -> 15779.701 | BC9: =BB9 -> 15779.701 | BD9: =BC9 -> 15779.701 | BE9: =BD9 -> 15779.701 | BF9: =BE9 -> 15779.701 | BG9: =BF9 -> 15779.701 | ... BJ9: =BI9 -> 15779.701 | BK9: =SUM(C9:BJ9) -> 861372.48
B10: 6 | C10: ='Resumo Contratos'!F11 -> 9540 | D10: =C10 -> 9540 | E10: =D10 -> 9540 | F10: =E10 -> 9540 | G10: =F10 -> 9540 | H10: =G10 -> 9540 | I10: =H10 -> 9540 | J10: =I10 -> 9540 | K10: =J10 -> 9540 | ... N10: =M10 -> 9540 | O10: =N10+(N10*Premissas!$F$19) -> 10013.531 | P10: =O10 -> 10013.531 | Q10: =P10 -> 10013.531 | R10: =Q10 -> 10013.531 | S10: =R10 -> 10013.531 | T10: =S10 -> 10013.531 | U10: =T10 -> 10013.531 | V10: =U10 -> 10013.531 | W10: =V10 -> 10013.531 | ... Z10: =Y10 -> 10013.531 | AA10: =Z10+(Z10*Premissas!$F$19) -> 10510.565 | AB10: =AA10 -> 10510.565 | AC10: =AB10 -> 10510.565 | AD10: =AC10 -> 10510.565 | AE10: =AD10 -> 10510.565 | AF10: =AE10 -> 10510.565 | AG10: =AF10 -> 10510.565 | AH10: =AG10 -> 10510.565 | AI10: =AH10 -> 10510.565 | ... AL10: =AK10 -> 10510.565 | AM10: =AL10+(AL10*Premissas!$F$19) -> 11032.271 | AN10: =AM10 -> 11032.271 | AO10: =AN10 -> 11032.271 | AP10: =AO10 -> 11032.271 | AQ10: =AP10 -> 11032.271 | AR10: =AQ10 -> 11032.271 | AS10: =AR10 -> 11032.271 | AT10: =AS10 -> 11032.271 | AU10: =AT10 -> 11032.271 | ... AX10: =AW10 -> 11032.271 | AY10: =AX10+(AX10*Premissas!$F$19) -> 11579.873 | AZ10: =AY10 -> 11579.873 | BA10: =AZ10 -> 11579.873 | BB10: =BA10 -> 11579.873 | BC10: =BB10 -> 11579.873 | BD10: =BC10 -> 11579.873 | BE10: =BD10 -> 11579.873 | BF10: =BE10 -> 11579.873 | BG10: =BF10 -> 11579.873 | ... BJ10: =BI10 -> 11579.873 | BK10: =SUM(C10:BJ10) -> 632114.88
B11: 7 | C11: ='Resumo Contratos'!F12 -> 3500 | D11: =C11 -> 3500 | E11: =D11 -> 3500 | F11: =E11 -> 3500 | G11: =F11 -> 3500 | H11: =G11 -> 3500 | I11: =H11 -> 3500 | J11: =I11 -> 3500 | K11: =J11 -> 3500 | ... N11: =M11 -> 3500 | O11: =N11+(N11*Premissas!$F$19) -> 3673.7271 | P11: =O11 -> 3673.7271 | Q11: =P11 -> 3673.7271 | R11: =Q11 -> 3673.7271 | S11: =R11 -> 3673.7271 | T11: =S11 -> 3673.7271 | U11: =T11 -> 3673.7271 | V11: =U11 -> 3673.7271 | W11: =V11 -> 3673.7271 | ... Z11: =Y11 -> 3673.7271 | AA11: =Z11+(Z11*Premissas!$F$19) -> 3856.0775 | AB11: =AA11 -> 3856.0775 | AC11: =AB11 -> 3856.0775 | AD11: =AC11 -> 3856.0775 | AE11: =AD11 -> 3856.0775 | AF11: =AE11 -> 3856.0775 | AG11: =AF11 -> 3856.0775 | AH11: =AG11 -> 3856.0775 | AI11: =AH11 -> 3856.0775 | ... AL11: =AK11 -> 3856.0775 | AM11: =AL11+(AL11*Premissas!$F$19) -> 4047.479 | AN11: =AM11 -> 4047.479 | AO11: =AN11 -> 4047.479 | AP11: =AO11 -> 4047.479 | AQ11: =AP11 -> 4047.479 | AR11: =AQ11 -> 4047.479 | AS11: =AR11 -> 4047.479 | AT11: =AS11 -> 4047.479 | AU11: =AT11 -> 4047.479 | ... AX11: =AW11 -> 4047.479 | AY11: =AX11+(AX11*Premissas!$F$19) -> 4248.381 | AZ11: =AY11 -> 4248.381 | BA11: =AZ11 -> 4248.381 | BB11: =BA11 -> 4248.381 | BC11: =BB11 -> 4248.381 | BD11: =BC11 -> 4248.381 | BE11: =BD11 -> 4248.381 | BF11: =BE11 -> 4248.381 | BG11: =BF11 -> 4248.381 | ... BJ11: =BI11 -> 4248.381 | BK11: =SUM(C11:BJ11) -> 231907.97
B15: TOTAL | C15: =SUM(C5:C14) -> 56580 | D15: =SUM(D5:D14) -> 56580 | E15: =SUM(E5:E14) -> 56580 | F15: =SUM(F5:F14) -> 56580 | G15: =SUM(G5:G14) -> 56580 | H15: =SUM(H5:H14) -> 56580 | I15: =SUM(I5:I14) -> 56580 | J15: =SUM(J5:J14) -> 56580 | ... BK15: =SUM(BK5:BK14) -> 3748958.1
B18: Atualização ao Valor Presente pelas Taxas Médias de Mercado - Financiamento Imobiliário PJ
C20: 1 | D20: 2 | E20: 3 | F20: 4 | G20: 5 | H20: 6 | I20: 7 | J20: 8 | K20: 9 | L20: 10 | M20: 11 | N20: 12 | O20: 13 | P20: 14 | Q20: 15 | R20: 16 | S20: 17 | T20: 18 | U20: 19 | V20: 20 | W20: 21 | X20: 22 | Y20: 23 | Z20: 24 | AA20: 25 | AB20: 26 | AC20: 27 | AD20: 28 | AE20: 29 | AF20: 30 | AG20: 31 | AH20: 32 | AI20: 33 | AJ20: 34 | AK20: 35 | AL20: 36 | AM20: 37 | AN20: 38 | AO20: 39 | AP20: 40 | AQ20: 41 | AR20: 42 | AS20: 43 | AT20: 44 | AU20: 45 | AV20: 46 | AW20: 47 | AX20: 48 | AY20: 49 | AZ20: 50 | BA20: 51 | BB20: 52 | BC20: 53 | BD20: 54 | BE20: 55 | BF20: 56 | BG20: 57 | BH20: 58 | BI20: 59 | BJ20: 60
B21: # Identificação Contrato | C21: 43466 | D21: 43497 | E21: 43525 | F21: 43556 | G21: 43586 | H21: 43617 | I21: 43647 | J21: 43678 | K21: 43709 | L21: 43739 | M21: 43770 | N21: 43800 | O21: 43831 | P21: 43862 | Q21: 43891 | R21: 43922 | S21: 43952 | T21: 43983 | U21: 44013 | V21: 44044 | W21: 44075 | X21: 44105 | Y21: 44136 | Z21: 44166 | AA21: 44197 | AB21: 44228 | AC21: 44256 | AD21: 44287 | AE21: 44317 | AF21: 44348 | AG21: 44378 | AH21: 44409 | AI21: 44440 | AJ21: 44470 | AK21: 44501 | AL21: 44531 | AM21: 44562 | AN21: 44593 | AO21: 44621 | AP21: 44652 | AQ21: 44682 | AR21: 44713 | AS21: 44743 | AT21: 44774 | AU21: 44805 | AV21: 44835 | AW21: 44866 | AX21: 44896 | AY21: 44927 | AZ21: 44958 | BA21: 44986 | BB21: 45017 | BC21: 45047 | BD21: 45078 | BE21: 45108 | BF21: 45139 | BG21: 45170 | BH21: 45200 | BI21: 45231 | BJ21: 45261 | BK21: TOTAL
B22: 1 | C22: =(C5/(1+Premissas!$N$20)^C$20) -> 9461.7752 | D22: =(D5/(1+Premissas!$N$20)^D$20) -> 9384.1919 | E22: =(E5/(1+Premissas!$N$20)^E$20) -> 9307.2447 | F22: =(F5/(1+Premissas!$N$20)^F$20) -> 9230.9285 | G22: =(G5/(1+Premissas!$N$20)^G$20) -> 9155.238 | H22: =(H5/(1+Premissas!$N$20)^H$20) -> 9080.1681 | I22: =(I5/(1+Premissas!$N$20)^I$20) -> 9005.7138 | J22: =(J5/(1+Premissas!$N$20)^J$20) -> 8931.87 | ... BJ22: =(BJ5/(1+Premissas!$N$20)^BJ$20) -> 7065.7609 | BK22: =SUM(C22:BJ22) -> 492031.79 | BM22: =NPV(Premissas!$N$20,Contabilização!C5:BJ5)-BK22 -> -4.6566129e-10
B23: 2 | C23: =(C6/(1+Premissas!$N$20)^C$20) -> 1983.6007 | D23: =(D6/(1+Premissas!$N$20)^D$20) -> 1967.3358 | E23: =(E6/(1+Premissas!$N$20)^E$20) -> 1951.2043 | F23: =(F6/(1+Premissas!$N$20)^F$20) -> 1935.2051 | G23: =(G6/(1+Premissas!$N$20)^G$20) -> 1919.3371 | H23: =(H6/(1+Premissas!$N$20)^H$20) -> 1903.5992 | I23: =(I6/(1+Premissas!$N$20)^I$20) -> 1887.9903 | J23: =(J6/(1+Premissas!$N$20)^J$20) -> 1872.5094 | ... BJ23: =(BJ6/(1+Premissas!$N$20)^BJ$20) -> 1481.2916 | BK23: =SUM(C23:BJ23) -> 103151.32 | BM23: =NPV(Premissas!$N$20,Contabilização!C6:BJ6)-BK23 -> -1.1641532e-10
B24: 3 | C24: =(C7/(1+Premissas!$N$20)^C$20) -> 17852.406 | D24: =(D7/(1+Premissas!$N$20)^D$20) -> 17706.022 | E24: =(E7/(1+Premissas!$N$20)^E$20) -> 17560.839 | F24: =(F7/(1+Premissas!$N$20)^F$20) -> 17416.846 | G24: =(G7/(1+Premissas!$N$20)^G$20) -> 17274.034 | H24: =(H7/(1+Premissas!$N$20)^H$20) -> 17132.393 | I24: =(I7/(1+Premissas!$N$20)^I$20) -> 16991.913 | J24: =(J7/(1+Premissas!$N$20)^J$20) -> 16852.585 | ... BJ24: =(BJ7/(1+Premissas!$N$20)^BJ$20) -> 13331.624 | BK24: =SUM(C24:BJ24) -> 928361.87 | BM24: =NPV(Premissas!$N$20,Contabilização!C7:BJ7)-BK24 -> 0
B25: 4 | C25: =(C8/(1+Premissas!$N$20)^C$20) -> 991.80034 | D25: =(D8/(1+Premissas!$N$20)^D$20) -> 983.66791 | E25: =(E8/(1+Premissas!$N$20)^E$20) -> 975.60217 | F25: =(F8/(1+Premissas!$N$20)^F$20) -> 967.60256 | G25: =(G8/(1+Premissas!$N$20)^G$20) -> 959.66855 | H25: =(H8/(1+Premissas!$N$20)^H$20) -> 951.79959 | I25: =(I8/(1+Premissas!$N$20)^I$20) -> 943.99516 | J25: =(J8/(1+Premissas!$N$20)^J$20) -> 936.25472 | ... BJ25: =(BJ8/(1+Premissas!$N$20)^BJ$20) -> 740.6458 | BK25: =SUM(C25:BJ25) -> 51575.659 | BM25: =NPV(Premissas!$N$20,Contabilização!C8:BJ8)-BK25 -> -5.8207661e-11
B26: 5 | C26: =(C9/(1+Premissas!$N$20)^C$20) -> 12893.404 | D26: =(D9/(1+Premissas!$N$20)^D$20) -> 12787.683 | E26: =(E9/(1+Premissas!$N$20)^E$20) -> 12682.828 | F26: =(F9/(1+Premissas!$N$20)^F$20) -> 12578.833 | G26: =(G9/(1+Premissas!$N$20)^G$20) -> 12475.691 | H26: =(H9/(1+Premissas!$N$20)^H$20) -> 12373.395 | I26: =(I9/(1+Premissas!$N$20)^I$20) -> 12271.937 | J26: =(J9/(1+Premissas!$N$20)^J$20) -> 12171.311 | ... BJ26: =(BJ9/(1+Premissas!$N$20)^BJ$20) -> 9628.3954 | BK26: =SUM(C26:BJ26) -> 670483.57 | BM26: =NPV(Premissas!$N$20,Contabilização!C9:BJ9)-BK26 -> 0
B27: 6 | C27: =(C10/(1+Premissas!$N$20)^C$20) -> 9461.7752 | D27: =(D10/(1+Premissas!$N$20)^D$20) -> 9384.1919 | E27: =(E10/(1+Premissas!$N$20)^E$20) -> 9307.2447 | F27: =(F10/(1+Premissas!$N$20)^F$20) -> 9230.9285 | G27: =(G10/(1+Premissas!$N$20)^G$20) -> 9155.238 | H27: =(H10/(1+Premissas!$N$20)^H$20) -> 9080.1681 | I27: =(I10/(1+Premissas!$N$20)^I$20) -> 9005.7138 | J27: =(J10/(1+Premissas!$N$20)^J$20) -> 8931.87 | ... BJ27: =(BJ10/(1+Premissas!$N$20)^BJ$20) -> 7065.7609 | BK27: =SUM(C27:BJ27) -> 492031.79 | BM27: =NPV(Premissas!$N$20,Contabilização!C10:BJ10)-BK27 -> -4.6566129e-10
B28: 7 | C28: =(C11/(1+Premissas!$N$20)^C$20) -> 3471.3012 | D28: =(D11/(1+Premissas!$N$20)^D$20) -> 3442.8377 | E28: =(E11/(1+Premissas!$N$20)^E$20) -> 3414.6076 | F28: =(F11/(1+Premissas!$N$20)^F$20) -> 3386.609 | G28: =(G11/(1+Premissas!$N$20)^G$20) -> 3358.8399 | H28: =(H11/(1+Premissas!$N$20)^H$20) -> 3331.2986 | I28: =(I11/(1+Premissas!$N$20)^I$20) -> 3303.9831 | J28: =(J11/(1+Premissas!$N$20)^J$20) -> 3276.8915 | ... BJ28: =(BJ11/(1+Premissas!$N$20)^BJ$20) -> 2592.2603 | BK28: =SUM(C28:BJ28) -> 180514.81 | BM28: =NPV(Premissas!$N$20,Contabilização!C11:BJ11)-BK28 -> 0
C29: =(C12/(1+Premissas!$N$20)^C$20) -> 0 | D29: =(D12/(1+Premissas!$N$20)^D$20) -> 0 | E29: =(E12/(1+Premissas!$N$20)^E$20) -> 0 | F29: =(F12/(1+Premissas!$N$20)^F$20) -> 0 | G29: =(G12/(1+Premissas!$N$20)^G$20) -> 0 | H29: =(H12/(1+Premissas!$N$20)^H$20) -> 0 | I29: =(I12/(1+Premissas!$N$20)^I$20) -> 0 | J29: =(J12/(1+Premissas!$N$20)^J$20) -> 0 | ... BJ29: =(BJ12/(1+Premissas!$N$20)^BJ$20) -> 0 | BK29: =SUM(C29:BJ29) -> 0 | BM29: =NPV(Premissas!$N$20,Contabilização!C12:BJ12)-BK29 -> 0
C30: =(C13/(1+Premissas!$N$20)^C$20) -> 0 | D30: =(D13/(1+Premissas!$N$20)^D$20) -> 0 | E30: =(E13/(1+Premissas!$N$20)^E$20) -> 0 | F30: =(F13/(1+Premissas!$N$20)^F$20) -> 0 | G30: =(G13/(1+Premissas!$N$20)^G$20) -> 0 | H30: =(H13/(1+Premissas!$N$20)^H$20) -> 0 | I30: =(I13/(1+Premissas!$N$20)^I$20) -> 0 | J30: =(J13/(1+Premissas!$N$20)^J$20) -> 0 | ... BJ30: =(BJ13/(1+Premissas!$N$20)^BJ$20) -> 0 | BK30: =SUM(C30:BJ30) -> 0 | BM30: =NPV(Premissas!$N$20,Contabilização!C13:BJ13)-BK30 -> 0
C31: =(C14/(1+Premissas!$N$20)^C$20) -> 0 | D31: =(D14/(1+Premissas!$N$20)^D$20) -> 0 | E31: =(E14/(1+Premissas!$N$20)^E$20) -> 0 | F31: =(F14/(1+Premissas!$N$20)^F$20) -> 0 | G31: =(G14/(1+Premissas!$N$20)^G$20) -> 0 | H31: =(H14/(1+Premissas!$N$20)^H$20) -> 0 | I31: =(I14/(1+Premissas!$N$20)^I$20) -> 0 | J31: =(J14/(1+Premissas!$N$20)^J$20) -> 0 | ... BJ31: =(BJ14/(1+Premissas!$N$20)^BJ$20) -> 0 | BK31: =SUM(C31:BJ31) -> 0 | BM31: =NPV(Premissas!$N$20,Contabilização!C14:BJ14)-BK31 -> 0
B32: TOTAL | C32: =SUM(C22:C31) -> 56116.063 | D32: =SUM(D22:D31) -> 55655.931 | E32: =SUM(E22:E31) -> 55199.571 | F32: =SUM(F22:F31) -> 54746.953 | G32: =SUM(G22:G31) -> 54298.047 | H32: =SUM(H22:H31) -> 53852.821 | I32: =SUM(I22:I31) -> 53411.246 | J32: =SUM(J22:J31) -> 52973.292 | ... BK32: =SUM(BK22:BK31) -> 2918150.8
B35: Lançamento de Depreciação Mensal
B37: # Identificação Contrato | C37: 43466 | D37: 43497 | E37: 43525 | F37: 43556 | G37: 43586 | H37: 43617 | I37: 43647 | J37: 43678 | K37: 43709 | L37: 43739 | M37: 43770 | N37: 43800 | O37: 43831 | P37: 43862 | Q37: 43891 | R37: 43922 | S37: 43952 | T37: 43983 | U37: 44013 | V37: 44044 | W37: 44075 | X37: 44105 | Y37: 44136 | Z37: 44166 | AA37: 44197 | AB37: 44228 | AC37: 44256 | AD37: 44287 | AE37: 44317 | AF37: 44348 | AG37: 44378 | AH37: 44409 | AI37: 44440 | AJ37: 44470 | AK37: 44501 | AL37: 44531 | AM37: 44562 | AN37: 44593 | AO37: 44621 | AP37: 44652 | AQ37: 44682 | AR37: 44713 | AS37: 44743 | AT37: 44774 | AU37: 44805 | AV37: 44835 | AW37: 44866 | AX37: 44896 | AY37: 44927 | AZ37: 44958 | BA37: 44986 | BB37: 45017 | BC37: 45047 | BD37: 45078 | BE37: 45108 | BF37: 45139 | BG37: 45170 | BH37: 45200 | BI37: 45231 | BJ37: 45261 | BK37: TOTAL
B38: 1 | C38: =$BK22/$BJ$20 -> 8200.5298 | D38: =$BK22/$BJ$20 -> 8200.5298 | E38: =$BK22/$BJ$20 -> 8200.5298 | F38: =$BK22/$BJ$20 -> 8200.5298 | G38: =$BK22/$BJ$20 -> 8200.5298 | H38: =$BK22/$BJ$20 -> 8200.5298 | I38: =$BK22/$BJ$20 -> 8200.5298 | J38: =$BK22/$BJ$20 -> 8200.5298 | ... BJ38: =$BK22/$BJ$20 -> 8200.5298 | BK38: =SUM(C38:BJ38) -> 492031.79
B39: 2 | C39: =$BK23/$BJ$20 -> 1719.1886 | D39: =$BK23/$BJ$20 -> 1719.1886 | E39: =$BK23/$BJ$20 -> 1719.1886 | F39: =$BK23/$BJ$20 -> 1719.1886 | G39: =$BK23/$BJ$20 -> 1719.1886 | H39: =$BK23/$BJ$20 -> 1719.1886 | I39: =$BK23/$BJ$20 -> 1719.1886 | J39: =$BK23/$BJ$20 -> 1719.1886 | ... BJ39: =$BK23/$BJ$20 -> 1719.1886 | BK39: =SUM(C39:BJ39) -> 103151.32
B40: 3 | C40: =$BK24/$BJ$20 -> 15472.698 | D40: =$BK24/$BJ$20 -> 15472.698 | E40: =$BK24/$BJ$20 -> 15472.698 | F40: =$BK24/$BJ$20 -> 15472.698 | G40: =$BK24/$BJ$20 -> 15472.698 | H40: =$BK24/$BJ$20 -> 15472.698 | I40: =$BK24/$BJ$20 -> 15472.698 | J40: =$BK24/$BJ$20 -> 15472.698 | ... BJ40: =$BK24/$BJ$20 -> 15472.698 | BK40: =SUM(C40:BJ40) -> 928361.87
B41: 4 | C41: =$BK25/$BJ$20 -> 859.59432 | D41: =$BK25/$BJ$20 -> 859.59432 | E41: =$BK25/$BJ$20 -> 859.59432 | F41: =$BK25/$BJ$20 -> 859.59432 | G41: =$BK25/$BJ$20 -> 859.59432 | H41: =$BK25/$BJ$20 -> 859.59432 | I41: =$BK25/$BJ$20 -> 859.59432 | J41: =$BK25/$BJ$20 -> 859.59432 | ... BJ41: =$BK25/$BJ$20 -> 859.59432 | BK41: =SUM(C41:BJ41) -> 51575.659
B42: 5 | C42: =$BK26/$BJ$20 -> 11174.726 | D42: =$BK26/$BJ$20 -> 11174.726 | E42: =$BK26/$BJ$20 -> 11174.726 | F42: =$BK26/$BJ$20 -> 11174.726 | G42: =$BK26/$BJ$20 -> 11174.726 | H42: =$BK26/$BJ$20 -> 11174.726 | I42: =$BK26/$BJ$20 -> 11174.726 | J42: =$BK26/$BJ$20 -> 11174.726 | ... BJ42: =$BK26/$BJ$20 -> 11174.726 | BK42: =SUM(C42:BJ42) -> 670483.57
B43: 6 | C43: =$BK27/$BJ$20 -> 8200.5298 | D43: =$BK27/$BJ$20 -> 8200.5298 | E43: =$BK27/$BJ$20 -> 8200.5298 | F43: =$BK27/$BJ$20 -> 8200.5298 | G43: =$BK27/$BJ$20 -> 8200.5298 | H43: =$BK27/$BJ$20 -> 8200.5298 | I43: =$BK27/$BJ$20 -> 8200.5298 | J43: =$BK27/$BJ$20 -> 8200.5298 | ... BJ43: =$BK27/$BJ$20 -> 8200.5298 | BK43: =SUM(C43:BJ43) -> 492031.79
B44: 7 | C44: =$BK28/$BJ$20 -> 3008.5801 | D44: =$BK28/$BJ$20 -> 3008.5801 | E44: =$BK28/$BJ$20 -> 3008.5801 | F44: =$BK28/$BJ$20 -> 3008.5801 | G44: =$BK28/$BJ$20 -> 3008.5801 | H44: =$BK28/$BJ$20 -> 3008.5801 | I44: =$BK28/$BJ$20 -> 3008.5801 | J44: =$BK28/$BJ$20 -> 3008.5801 | ... BJ44: =$BK28/$BJ$20 -> 3008.5801 | BK44: =SUM(C44:BJ44) -> 180514.81
C45: =$BK29/$BJ$20 -> 0 | D45: =$BK29/$BJ$20 -> 0 | E45: =$BK29/$BJ$20 -> 0 | F45: =$BK29/$BJ$20 -> 0 | G45: =$BK29/$BJ$20 -> 0 | H45: =$BK29/$BJ$20 -> 0 | I45: =$BK29/$BJ$20 -> 0 | J45: =$BK29/$BJ$20 -> 0 | ... BJ45: =$BK29/$BJ$20 -> 0 | BK45: =SUM(C45:BJ45) -> 0
C46: =$BK30/$BJ$20 -> 0 | D46: =$BK30/$BJ$20 -> 0 | E46: =$BK30/$BJ$20 -> 0 | F46: =$BK30/$BJ$20 -> 0 | G46: =$BK30/$BJ$20 -> 0 | H46: =$BK30/$BJ$20 -> 0 | I46: =$BK30/$BJ$20 -> 0 | J46: =$BK30/$BJ$20 -> 0 | ... BJ46: =$BK30/$BJ$20 -> 0 | BK46: =SUM(C46:BJ46) -> 0
C47: =$BK31/$BJ$20 -> 0 | D47: =$BK31/$BJ$20 -> 0 | E47: =$BK31/$BJ$20 -> 0 | F47: =$BK31/$BJ$20 -> 0 | G47: =$BK31/$BJ$20 -> 0 | H47: =$BK31/$BJ$20 -> 0 | I47: =$BK31/$BJ$20 -> 0 | J47: =$BK31/$BJ$20 -> 0 | ... BJ47: =$BK31/$BJ$20 -> 0 | BK47: =SUM(C47:BJ47) -> 0
B48: TOTAL | C48: =SUM(C38:C47) -> 48635.847 | D48: =SUM(D38:D47) -> 48635.847 | E48: =SUM(E38:E47) -> 48635.847 | F48: =SUM(F38:F47) -> 48635.847 | G48: =SUM(G38:G47) -> 48635.847 | H48: =SUM(H38:H47) -> 48635.847 | I48: =SUM(I38:I47) -> 48635.847 | J48: =SUM(J38:J47) -> 48635.847 | ... BK48: =SUM(BK38:BK47) -> 2918150.8
B51: Lançamento de Juros Mensal
B53: # Identificação Contrato | C53: 43466 | D53: 43497 | E53: 43525 | F53: 43556 | G53: 43586 | H53: 43617 | I53: 43647 | J53: 43678 | K53: 43709 | L53: 43739 | M53: 43770 | N53: 43800 | O53: 43831 | P53: 43862 | Q53: 43891 | R53: 43922 | S53: 43952 | T53: 43983 | U53: 44013 | V53: 44044 | W53: 44075 | X53: 44105 | Y53: 44136 | Z53: 44166 | AA53: 44197 | AB53: 44228 | AC53: 44256 | AD53: 44287 | AE53: 44317 | AF53: 44348 | AG53: 44378 | AH53: 44409 | AI53: 44440 | AJ53: 44470 | AK53: 44501 | AL53: 44531 | AM53: 44562 | AN53: 44593 | AO53: 44621 | AP53: 44652 | AQ53: 44682 | AR53: 44713 | AS53: 44743 | AT53: 44774 | AU53: 44805 | AV53: 44835 | AW53: 44866 | AX53: 44896 | AY53: 44927 | AZ53: 44958 | BA53: 44986 | BB53: 45017 | BC53: 45047 | BD53: 45078 | BE53: 45108 | BF53: 45139 | BG53: 45170 | BH53: 45200 | BI53: 45231 | BJ53: 45261 | BK53: TOTAL
B54: 1 | C54: =SUM($C22:$BJ22)*Premissas!$N$20 -> 4067.8487 | D54: =C150*Premissas!$N$20 -> 4022.6079 | E54: =D150*Premissas!$N$20 -> 3976.9931 | F54: =E150*Premissas!$N$20 -> 3931.0013 | G54: =F150*Premissas!$N$20 -> 3884.6291 | H54: =G150*Premissas!$N$20 -> 3837.8736 | I54: =H150*Premissas!$N$20 -> 3790.7316 | J54: =I150*Premissas!$N$20 -> 3743.1998 | K54: =J150*Premissas!$N$20 -> 3695.275 | ... BJ54: =BI150*Premissas!$N$20 -> 94.951026 | BK54: =SUM(C54:BJ54) -> 140083.09
...

Sheet Lançamentos Contábeis
C2: Pelo Lançamento Inicial
C4: Lançamento | D4: 43466 | E4: 43497 | F4: 43525 | G4: 43556 | H4: 43586 | I4: 43617 | J4: 43647 | K4: 43678 | L4: 43709 | M4: 43739 | N4: 43770 | O4: 43800 | P4: 43831 | Q4: 43862 | R4: 43891 | S4: 43922 | T4: 43952 | U4: 43983 | V4: 44013 | W4: 44044 | X4: 44075 | Y4: 44105 | Z4: 44136 | AA4: 44166 | AB4: 44197 | AC4: 44228 | AD4: 44256 | AE4: 44287 | AF4: 44317 | AG4: 44348 | AH4: 44378 | AI4: 44409 | AJ4: 44440 | AK4: 44470 | AL4: 44501 | AM4: 44531 | AN4: 44562 | AO4: 44593 | AP4: 44621 | AQ4: 44652 | AR4: 44682 | AS4: 44713 | AT4: 44743 | AU4: 44774 | AV4: 44805 | AW4: 44835 | AX4: 44866 | AY4: 44896 | AZ4: 44927 | BA4: 44958 | BB4: 44986 | BC4: 45017 | BD4: 45047 | BE4: 45078 | BF4: 45108 | BG4: 45139 | BH4: 45170 | BI4: 45200 | BJ4: 45231 | BK4: 45261
B5: D | C5: Direito de uso de Imóveis CPC 06 R2 (Ativo Não Circulante) | D5: =Contabilização!$C$80 -> 2918150.8 | E5: 0 | F5: 0 | G5: 0 | H5: 0 | I5: 0 | J5: 0 | K5: 0 | L5: 0 | M5: 0 | N5: 0 | O5: 0 | P5: 0 | Q5: 0 | R5: 0 | S5: 0 | T5: 0 | U5: 0 | V5: 0 | W5: 0 | X5: 0 | Y5: 0 | Z5: 0 | AA5: 0 | AB5: 0 | AC5: 0 | AD5: 0 | AE5: 0 | AF5: 0 | AG5: 0 | AH5: 0 | AI5: 0 | AJ5: 0 | AK5: 0 | AL5: 0 | AM5: 0 | AN5: 0 | AO5: 0 | AP5: 0 | AQ5: 0 | AR5: 0 | AS5: 0 | AT5: 0 | AU5: 0 | AV5: 0 | AW5: 0 | AX5: 0 | AY5: 0 | AZ5: 0 | BA5: 0 | BB5: 0 | BC5: 0 | BD5: 0 | BE5: 0 | BF5: 0 | BG5: 0 | BH5: 0 | BI5: 0 | BJ5: 0 | BK5: 0
B6: C | C6: Obrigações por arrendamento CPC 06 R2 (Passivo Circulante) | D6: =D5 -> 2918150.8 | E6: =E5 -> 0 | F6: =F5 -> 0 | G6: =G5 -> 0 | H6: =H5 -> 0 | I6: =I5 -> 0 | J6: =J5 -> 0 | K6: =K5 -> 0 | ... BK6: =BK5 -> 0
C9: Pelo Pagamento do Aluguel
C11: Lançamento | D11: 43466 | E11: 43497 | F11: 43525 | G11: 43556 | H11: 43586 | I11: 43617 | J11: 43647 | K11: 43678 | L11: 43709 | M11: 43739 | N11: 43770 | O11: 43800 | P11: 43831 | Q11: 43862 | R11: 43891 | S11: 43922 | T11: 43952 | U11: 43983 | V11: 44013 | W11: 44044 | X11: 44075 | Y11: 44105 | Z11: 44136 | AA11: 44166 | AB11: 44197 | AC11: 44228 | AD11: 44256 | AE11: 44287 | AF11: 44317 | AG11: 44348 | AH11: 44378 | AI11: 44409 | AJ11: 44440 | AK11: 44470 | AL11: 44501 | AM11: 44531 | AN11: 44562 | AO11: 44593 | AP11: 44621 | AQ11: 44652 | AR11: 44682 | AS11: 44713 | AT11: 44743 | AU11: 44774 | AV11: 44805 | AW11: 44835 | AX11: 44866 | AY11: 44896 | AZ11: 44927 | BA11: 44958 | BB11: 44986 | BC11: 45017 | BD11: 45047 | BE11: 45078 | BF11: 45108 | BG11: 45139 | BH11: 45170 | BI11: 45200 | BJ11: 45231 | BK11: 45261
B12: D | C12: Obrigações por arrendamento CPC 06 R2 (Passivo Circulante) | D12: =D13 -> 56580 | E12: =E13 -> 56580 | F12: =F13 -> 56580 | G12: =G13 -> 56580 | H12: =H13 -> 56580 | I12: =I13 -> 56580 | J12: =J13 -> 56580 | K12: =K13 -> 56580 | ... BK12: =BK13 -> 68678.113
B13: C | C13: Bancos (Ativo Circulante) | D13: =Contabilização!C15 -> 56580 | E13: =Contabilização!D15 -> 56580 | F13: =Contabilização!E15 -> 56580 | G13: =Contabilização!F15 -> 56580 | H13: =Contabilização!G15 -> 56580 | I13: =Contabilização!H15 -> 56580 | J13: =Contabilização!I15 -> 56580 | K13: =Contabilização!J15 -> 56580 | ... BK13: =Contabilização!BJ15 -> 68678.113
D14: =D13-Contabilização!C15 -> 0 | E14: =E13-Contabilização!D15 -> 0 | F14: =F13-Contabilização!E15 -> 0 | G14: =G13-Contabilização!F15 -> 0 | H14: =H13-Contabilização!G15 -> 0 | I14: =I13-Contabilização!H15 -> 0 | J14: =J13-Contabilização!I15 -> 0 | K14: =K13-Contabilização!J15 -> 0 | ... BK14: =BK13-Contabilização!BJ15 -> 0
C16: Pelo Lançamento de Juros
C18: Lançamento | D18: 43466 | E18: 43497 | F18: 43525 | G18: 43556 | H18: 43586 | I18: 43617 | J18: 43647 | K18: 43678 | L18: 43709 | M18: 43739 | N18: 43770 | O18: 43800 | P18: 43831 | Q18: 43862 | R18: 43891 | S18: 43922 | T18: 43952 | U18: 43983 | V18: 44013 | W18: 44044 | X18: 44075 | Y18: 44105 | Z18: 44136 | AA18: 44166 | AB18: 44197 | AC18: 44228 | AD18: 44256 | AE18: 44287 | AF18: 44317 | AG18: 44348 | AH18: 44378 | AI18: 44409 | AJ18: 44440 | AK18: 44470 | AL18: 44501 | AM18: 44531 | AN18: 44562 | AO18: 44593 | AP18: 44621 | AQ18: 44652 | AR18: 44682 | AS18: 44713 | AT18: 44743 | AU18: 44774 | AV18: 44805 | AW18: 44835 | AX18: 44866 | AY18: 44896 | AZ18: 44927 | BA18: 44958 | BB18: 44986 | BC18: 45017 | BD18: 45047 | BE18: 45078 | BF18: 45108 | BG18: 45139 | BH18: 45170 | BI18: 45200 | BJ18: 45231 | BK18: 45261
B19: D | C19: Despesa financeira (Resultado) | D19: =Contabilização!C64 -> 24125.668 | E19: =Contabilização!D64 -> 23857.354 | F19: =Contabilização!E64 -> 23586.821 | G19: =Contabilização!F64 -> 23314.052 | H19: =Contabilização!G64 -> 23039.027 | I19: =Contabilização!H64 -> 22761.729 | J19: =Contabilização!I64 -> 22482.138 | K19: =Contabilização!J64 -> 22200.235 | ... BK19: =Contabilização!BJ64 -> 563.13721
B20: C | C20: Obrigações por arrendamento CPC 06 R2 (Passivo Circulante) | D20: =D19 -> 24125.668 | E20: =E19 -> 23857.354 | F20: =F19 -> 23586.821 | G20: =G19 -> 23314.052 | H20: =H19 -> 23039.027 | I20: =I19 -> 22761.729 | J20: =J19 -> 22482.138 | K20: =K19 -> 22200.235 | ... BK20: =BK19 -> 563.13721
D21: =SUM($D6:D6)+SUM($D20:D20)-SUM($D12:D12)-Contabilização!C160 -> 0 | E21: =SUM($D6:E6)+SUM($D20:E20)-SUM($D12:E12)-Contabilização!D160 -> 0 | F21: =SUM($D6:F6)+SUM($D20:F20)-SUM($D12:F12)-Contabilização!E160 -> 0 | G21: =SUM($D6:G6)+SUM($D20:G20)-SUM($D12:G12)-Contabilização!F160 -> 0 | H21: =SUM($D6:H6)+SUM($D20:H20)-SUM($D12:H12)-Contabilização!G160 -> 0 | I21: =SUM($D6:I6)+SUM($D20:I20)-SUM($D12:I12)-Contabilização!H160 -> 0 | J21: =SUM($D6:J6)+SUM($D20:J20)-SUM($D12:J12)-Contabilização!I160 -> 0 | K21: =SUM($D6:K6)+SUM($D20:K20)-SUM($D12:K12)-Contabilização!J160 -> 0 | ... BK21: =SUM($D6:BK6)+SUM($D20:BK20)-SUM($D12:BK12)-Contabilização!BJ160 -> -5.8207661e-10
C23: Pela Segregação entre Curto e Longo Prazo
C25: Lançamento | D25: 43466 | E25: 43497 | F25: 43525 | G25: 43556 | H25: 43586 | I25: 43617 | J25: 43647 | K25: 43678 | L25: 43709 | M25: 43739 | N25: 43770 | O25: 43800 | P25: 43831 | Q25: 43862 | R25: 43891 | S25: 43922 | T25: 43952 | U25: 43983 | V25: 44013 | W25: 44044 | X25: 44075 | Y25: 44105 | Z25: 44136 | AA25: 44166 | AB25: 44197 | AC25: 44228 | AD25: 44256 | AE25: 44287 | AF25: 44317 | AG25: 44348 | AH25: 44378 | AI25: 44409 | AJ25: 44440 | AK25: 44470 | AL25: 44501 | AM25: 44531 | AN25: 44562 | AO25: 44593 | AP25: 44621 | AQ25: 44652 | AR25: 44682 | AS25: 44713 | AT25: 44743 | AU25: 44774 | AV25: 44805 | AW25: 44835 | AX25: 44866 | AY25: 44896 | AZ25: 44927 | BA25: 44958 | BB25: 44986 | BC25: 45017 | BD25: 45047 | BE25: 45078 | BF25: 45108 | BG25: 45139 | BH25: 45170 | BI25: 45200 | BJ25: 45231 | BK25: 45261
B26: D | C26: Obrigações por arrendamento CPC 06 R2 (Passivo Circulante) | D26: =D27 -> 2471859.8 | E26: 0 | F26: 0 | G26: 0 | H26: 0 | I26: 0 | J26: 0 | K26: 0 | L26: 0 | M26: 0 | N26: 0 | O26: 0 | P26: 0 | Q26: 0 | R26: 0 | S26: 0 | T26: 0 | U26: 0 | V26: 0 | W26: 0 | X26: 0 | Y26: 0 | Z26: 0 | AA26: 0 | AB26: 0 | AC26: 0 | AD26: 0 | AE26: 0 | AF26: 0 | AG26: 0 | AH26: 0 | AI26: 0 | AJ26: 0 | AK26: 0 | AL26: 0 | AM26: 0 | AN26: 0 | AO26: 0 | AP26: 0 | AQ26: 0 | AR26: 0 | AS26: 0 | AT26: 0 | AU26: 0 | AV26: 0 | AW26: 0 | AX26: 0 | AY26: 0 | AZ26: 0 | BA26: 0 | BB26: 0 | BC26: 0 | BD26: 0 | BE26: 0 | BF26: 0 | BG26: 0 | BH26: 0 | BI26: 0 | BJ26: 0 | BK26: 0
B27: C | C27: Obrigações por arrendamento CPC 06 R2 (Passivo Não Circulante) | D27: =Contabilização!C160-Contabilização!C128 -> 2471859.8 | E27: 0 | F27: 0 | G27: 0 | H27: 0 | I27: 0 | J27: 0 | K27: 0 | L27: 0 | M27: 0 | N27: 0 | O27: 0 | P27: 0 | Q27: 0 | R27: 0 | S27: 0 | T27: 0 | U27: 0 | V27: 0 | W27: 0 | X27: 0 | Y27: 0 | Z27: 0 | AA27: 0 | AB27: 0 | AC27: 0 | AD27: 0 | AE27: 0 | AF27: 0 | AG27: 0 | AH27: 0 | AI27: 0 | AJ27: 0 | AK27: 0 | AL27: 0 | AM27: 0 | AN27: 0 | AO27: 0 | AP27: 0 | AQ27: 0 | AR27: 0 | AS27: 0 | AT27: 0 | AU27: 0 | AV27: 0 | AW27: 0 | AX27: 0 | AY27: 0 | AZ27: 0 | BA27: 0 | BB27: 0 | BC27: 0 | BD27: 0 | BE27: 0 | BF27: 0 | BG27: 0 | BH27: 0 | BI27: 0 | BJ27: 0 | BK27: 0
B29: D | C29: Obrigações por arrendamento CPC 06 R2 (Passivo Não Circulante) | D29: 0 | E29: =-(Contabilização!D144-SUM('Lançamentos Contábeis'!$D27:D27)+SUM('Lançamentos Contábeis'!$D29:D29)) -> 38952.444 | F29: =-(Contabilização!E144-SUM('Lançamentos Contábeis'!$D27:E27)+SUM('Lançamentos Contábeis'!$D29:E29)) -> 39274.481 | G29: =-(Contabilização!F144-SUM('Lançamentos Contábeis'!$D27:F27)+SUM('Lançamentos Contábeis'!$D29:F29)) -> 39599.181 | H29: =-(Contabilização!G144-SUM('Lançamentos Contábeis'!$D27:G27)+SUM('Lançamentos Contábeis'!$D29:G29)) -> 39926.565 | I29: =-(Contabilização!H144-SUM('Lançamentos Contábeis'!$D27:H27)+SUM('Lançamentos Contábeis'!$D29:H29)) -> 40256.656 | J29: =-(Contabilização!I144-SUM('Lançamentos Contábeis'!$D27:I27)+SUM('Lançamentos Contábeis'!$D29:I29)) -> 40589.476 | K29: =-(Contabilização!J144-SUM('Lançamentos Contábeis'!$D27:J27)+SUM('Lançamentos Contábeis'!$D29:J29)) -> 40925.048 | L29: =-(Contabilização!K144-SUM('Lançamentos Contábeis'!$D27:K27)+SUM('Lançamentos Contábeis'!$D29:K29)) -> 41263.394 | ... BK29: =-(Contabilização!BJ144-SUM('Lançamentos Contábeis'!$D27:BJ27)+SUM('Lançamentos Contábeis'!$D29:BJ29)) -> 0
B30: C | C30: Obrigações por arrendamento CPC 06 R2 (Passivo Circulante) | D30: 0 | E30: =E29 -> 38952.444 | F30: =F29 -> 39274.481 | G30: =G29 -> 39599.181 | H30: =H29 -> 39926.565 | I30: =I29 -> 40256.656 | J30: =J29 -> 40589.476 | K30: =K29 -> 40925.048 | L30: =L29 -> 41263.394 | ... BK30: =BK29 -> 0
D31: =Contabilização!C128-(SUM($D6:D6)-SUM($D12:D12)+SUM($D20:D20)+SUM($D30:D30)-SUM($D26:D26)) -> 0 | E31: =Contabilização!D128-(SUM($D6:E6)-SUM($D12:E12)+SUM($D20:E20)+SUM($D30:E30)-SUM($D26:E26)) -> -7.2759576e-09 | F31: =Contabilização!E128-(SUM($D6:F6)-SUM($D12:F12)+SUM($D20:F20)+SUM($D30:F30)-SUM($D26:F26)) -> -7.1595423e-09 | G31: =Contabilização!F128-(SUM($D6:G6)-SUM($D12:G12)+SUM($D20:G20)+SUM($D30:G30)-SUM($D26:G26)) -> -7.1013346e-09 | H31: =Contabilização!G128-(SUM($D6:H6)-SUM($D12:H12)+SUM($D20:H20)+SUM($D30:H30)-SUM($D26:H26)) -> -7.043127e-09 | I31: =Contabilização!H128-(SUM($D6:I6)-SUM($D12:I12)+SUM($D20:I20)+SUM($D30:I30)-SUM($D26:I26)) -> -7.043127e-09 | J31: =Contabilização!I128-(SUM($D6:J6)-SUM($D12:J12)+SUM($D20:J20)+SUM($D30:J30)-SUM($D26:J26)) -> -6.693881e-09 | K31: =Contabilização!J128-(SUM($D6:K6)-SUM($D12:K12)+SUM($D20:K20)+SUM($D30:K30)-SUM($D26:K26)) -> -6.2864274e-09 | ... BK31: =Contabilização!BJ128-(SUM($D6:BK6)-SUM($D12:BK12)+SUM($D20:BK20)+SUM($D30:BK30)-SUM($D26:BK26)) -> -6.0535967e-09
D32: =Contabilização!C144+(-SUM($D27:D27)+SUM($D29:D29)) -> -6.519258e-09 | E32: =Contabilização!D144+(-SUM($D27:E27)+SUM($D29:E29)) -> 0 | F32: =Contabilização!E144+(-SUM($D27:F27)+SUM($D29:F29)) -> 0 | G32: =Contabilização!F144+(-SUM($D27:G27)+SUM($D29:G29)) -> 0 | H32: =Contabilização!G144+(-SUM($D27:H27)+SUM($D29:H29)) -> 0 | I32: =Contabilização!H144+(-SUM($D27:I27)+SUM($D29:I29)) -> 0 | J32: =Contabilização!I144+(-SUM($D27:J27)+SUM($D29:J29)) -> 0 | K32: =Contabilização!J144+(-SUM($D27:K27)+SUM($D29:K29)) -> 0 | ... BK32: =Contabilização!BJ144+(-SUM($D27:BK27)+SUM($D29:BK29)) -> 0
C34: Pelo Lançamento de Depreciação
C36: Lançamento | D36: 43466 | E36: 43497 | F36: 43525 | G36: 43556 | H36: 43586 | I36: 43617 | J36: 43647 | K36: 43678 | L36: 43709 | M36: 43739 | N36: 43770 | O36: 43800 | P36: 43831 | Q36: 43862 | R36: 43891 | S36: 43922 | T36: 43952 | U36: 43983 | V36: 44013 | W36: 44044 | X36: 44075 | Y36: 44105 | Z36: 44136 | AA36: 44166 | AB36: 44197 | AC36: 44228 | AD36: 44256 | AE36: 44287 | AF36: 44317 | AG36: 44348 | AH36: 44378 | AI36: 44409 | AJ36: 44440 | AK36: 44470 | AL36: 44501 | AM36: 44531 | AN36: 44562 | AO36: 44593 | AP36: 44621 | AQ36: 44652 | AR36: 44682 | AS36: 44713 | AT36: 44743 | AU36: 44774 | AV36: 44805 | AW36: 44835 | AX36: 44866 | AY36: 44896 | AZ36: 44927 | BA36: 44958 | BB36: 44986 | BC36: 45017 | BD36: 45047 | BE36: 45078 | BF36: 45108 | BG36: 45139 | BH36: 45170 | BI36: 45200 | BJ36: 45231 | BK36: 45261
B37: D | C37: Despesa com depreciação (Resultado) | D37: =Contabilização!C48 -> 48635.847 | E37: =Contabilização!D48 -> 48635.847 | F37: =Contabilização!E48 -> 48635.847 | G37: =Contabilização!F48 -> 48635.847 | H37: =Contabilização!G48 -> 48635.847 | I37: =Contabilização!H48 -> 48635.847 | J37: =Contabilização!I48 -> 48635.847 | K37: =Contabilização!J48 -> 48635.847 | ... BK37: =Contabilização!BJ48 -> 48635.847
B38: C | C38: (-) Dep. Acum. Direito de uso de Imóveis CPC 06 R2 (Ativo Não Circulante) | D38: =D37 -> 48635.847 | E38: =E37 -> 48635.847 | F38: =F37 -> 48635.847 | G38: =G37 -> 48635.847 | H38: =H37 -> 48635.847 | I38: =I37 -> 48635.847 | J38: =J37 -> 48635.847 | K38: =K37 -> 48635.847 | ... BK38: =BK37 -> 48635.847
D39: =Contabilização!C112-(SUM($D5:D5)-SUM($D38:D38)) -> 0 | E39: =Contabilização!D112-(SUM($D5:E5)-SUM($D38:E38)) -> 0 | F39: =Contabilização!E112-(SUM($D5:F5)-SUM($D38:F38)) -> 0 | G39: =Contabilização!F112-(SUM($D5:G5)-SUM($D38:G38)) -> 0 | H39: =Contabilização!G112-(SUM($D5:H5)-SUM($D38:H38)) -> 0 | I39: =Contabilização!H112-(SUM($D5:I5)-SUM($D38:I38)) -> 0 | J39: =Contabilização!I112-(SUM($D5:J5)-SUM($D38:J38)) -> 0 | K39: =Contabilização!J112-(SUM($D5:K5)-SUM($D38:K38)) -> 0 | ... BK39: =Contabilização!BJ112-(SUM($D5:BK5)-SUM($D38:BK38)) -> 1.4333636e-09
C41: Saldo Ativo conforme lançamentos | D41: =SUM($D5:D5)-SUM($D38:D38) -> 2869515 | E41: =SUM($D5:E5)-SUM($D38:E38) -> 2820879.1 | F41: =SUM($D5:F5)-SUM($D38:F38) -> 2772243.3 | G41: =SUM($D5:G5)-SUM($D38:G38) -> 2723607.4 | H41: =SUM($D5:H5)-SUM($D38:H38) -> 2674971.6 | I41: =SUM($D5:I5)-SUM($D38:I38) -> 2626335.7 | J41: =SUM($D5:J5)-SUM($D38:J38) -> 2577699.9 | K41: =SUM($D5:K5)-SUM($D38:K38) -> 2529064 | ... BK41: =SUM($D5:BK5)-SUM($D38:BK38) -> 0
C42: Saldo Passivo conforme lançamentos | D42: =SUM($D6:D6)-SUM($D12:D12)+SUM($D20:D20)-SUM($D26:D26)+SUM($D27:D27)-SUM($D29:D29)+SUM($D30:D30) -> 2885696.5 | E42: =SUM($D6:E6)-SUM($D12:E12)+SUM($D20:E20)-SUM($D26:E26)+SUM($D27:E27)-SUM($D29:E29)+SUM($D30:E30) -> 2852973.8 | F42: =SUM($D6:F6)-SUM($D12:F12)+SUM($D20:F20)-SUM($D26:F26)+SUM($D27:F27)-SUM($D29:F29)+SUM($D30:F30) -> 2819980.6 | G42: =SUM($D6:G6)-SUM($D12:G12)+SUM($D20:G20)-SUM($D26:G26)+SUM($D27:G27)-SUM($D29:G29)+SUM($D30:G30) -> 2786714.7 | H42: =SUM($D6:H6)-SUM($D12:H12)+SUM($D20:H20)-SUM($D26:H26)+SUM($D27:H27)-SUM($D29:H29)+SUM($D30:H30) -> 2753173.7 | I42: =SUM($D6:I6)-SUM($D12:I12)+SUM($D20:I20)-SUM($D26:I26)+SUM($D27:I27)-SUM($D29:I29)+SUM($D30:I30) -> 2719355.5 | J42: =SUM($D6:J6)-SUM($D12:J12)+SUM($D20:J20)-SUM($D26:J26)+SUM($D27:J27)-SUM($D29:J29)+SUM($D30:J30) -> 2685257.6 | K42: =SUM($D6:K6)-SUM($D12:K12)+SUM($D20:K20)-SUM($D26:K26)+SUM($D27:K27)-SUM($D29:K29)+SUM($D30:K30) -> 2650877.8 | ... BK42: =SUM($D6:BK6)-SUM($D12:BK12)+SUM($D20:BK20)-SUM($D26:BK26)+SUM($D27:BK27)-SUM($D29:BK29)+SUM($D30:BK30) -> 6.0535967e-09
C43: Check Saldo Ativo | D43: =D41-Contabilização!C112 -> 0 | E43: =E41-Contabilização!D112 -> 0 | F43: =F41-Contabilização!E112 -> 0 | G43: =G41-Contabilização!F112 -> 0 | H43: =H41-Contabilização!G112 -> 0 | I43: =I41-Contabilização!H112 -> 0 | J43: =J41-Contabilização!I112 -> 0 | K43: =K41-Contabilização!J112 -> 0 | ... BK43: =BK41-Contabilização!BJ112 -> -1.4333636e-09
C44: Check Saldo Passivo | D44: =D42-Contabilização!C160 -> 0 | E44: =E42-Contabilização!D160 -> 0 | F44: =F42-Contabilização!E160 -> 0 | G44: =G42-Contabilização!F160 -> 0 | H44: =H42-Contabilização!G160 -> 0 | I44: =I42-Contabilização!H160 -> 0 | J44: =J42-Contabilização!I160 -> 0 | K44: =K42-Contabilização!J160 -> 0 | ... BK44: =BK42-Contabilização!BJ160 -> -5.8207661e-10
