Workbook

Sheet Menu principal
B2: CONTROLE DE OBRIGAÇÕES ACESSÓRIAS | N2: CONSULTORIA
B4: ÂMBITO FEDERAL
B6: MENSAL | E6: ANUAL
B7: DCTF | C7: EFD CONT | E7: DIRF | F7: DIMOB | G7: DEFIS | H7: DMED | I7: DIPJ | J7: DSPJ | K7: ECD | L7: ECF
N8: RESPONSABILIDADE
A9: Atrasadas | B9: =COUNTBLANK(Tabela1[ENTREGA]) -> 20 | N9: FISCAL | O9: CONTÁBIL
A10: Atrasando | B10: =COUNTIF(DCTF!H:H,"<10") -> 35
A11: Vencendo hoje | B11: =COUNTIF(DCTF!E:E,TODAY()) -> 0
A12: Atrasado | B12: =SUM(DCTF!H:H) -> -853164
B14: ÂMBITO ESTADUAL
B16: MENSAL | G16: ANUAL | N16: AVISOS DE VENCIMENTO
B17: EFD ICMS/IPI | C17: GIA ST | D17: REDF | E17: GIA | G17: STDA | N17: DCTF | O17: 43242
N18: EFD CONT
N19: DIRF | O19: 43159
B20: ÂMBITO MUNICIPAL | N20: DIMOB
N21: DEFIS | O21: =DATE(2018,3,31) -> 43190
B22: MENSAL | G22: ANUAL | N22: DMED
B23: GISS | C23: DEISS | D23: ISS SP | E23: ISS BARUERI | G23: ALVARÁ | N23: DIPJ
N24: DSPJ
N25: ECD | O25: 43250
B26: OUTROS | N26: ECF
N27: EFD ICMS/IPI
B28: CERTIFICADO | C28: CND FED | D28: CND EST | E28: CND MUN | N28: GIA ST
N29: REDF
N30: GIA
N31: STDA
N32: GISS
N33: DEISS
N34: ISS SP
N35: ISS BARUERI
N36: ALVARÁ
N37: CERTIFICADO
N38: CND FED
N39: CND EST
N40: CND MUN

Sheet DCTF
A1: EMPRESA INATIVAS | B1: CNPJ | C1: REGIME | D1: SITUAÇÃO | E1: RESPONSÁVEL | F1: VENCIMENTO | G1: ENTREGA | H1: ATRASO | I1: Controle | J1: STATUS
A2: ACA COMERCIO | C2: SN | D2: INATIVA | F2: 43182 | G2: 43180 | H2: =DAYS360(F2,G2) -> -2 | I2: =IF(Tabela1[[#This Row],[ENTREGA]]="",Tabela1[[#This Row],[VENCIMENTO]]-TODAY( ),"") | J2: =IF(H2>0.99,"Vencida","No Prazo") -> No Prazo
A3: ADMINISTRADORA DE MOVEIS BAENA | C3: LP | D3: INATIVA | F3: 43242 | H3: =DAYS360(F3,G3) -> -42622 | I3: =IF(Tabela1[[#This Row],[ENTREGA]]="",Tabela1[[#This Row],[VENCIMENTO]]-TODAY( ),"") -> -1 | J3: =IF(H3>0.99,"Vencida","No Prazo") -> No Prazo
A4: AFAG REPRESSETNAÇÕES LTDA | C4: LP | D4: INATIVA | F4: 43242 | H4: =DAYS360(F4,G4) -> -42622 | I4: =IF(Tabela1[[#This Row],[ENTREGA]]="",Tabela1[[#This Row],[VENCIMENTO]]-TODAY( ),"") -> -1 | J4: =IF(H4>0.99,"Vencida","No Prazo") -> No Prazo
A5: BABY SAFE DO BRASIL | C5: LP | D5: INATIVA | F5: 43242 | H5: =DAYS360(F5,G5) -> -42622 | I5: =IF(Tabela1[[#This Row],[ENTREGA]]="",Tabela1[[#This Row],[VENCIMENTO]]-TODAY( ),"") -> -1 | J5: =IF(H5>0.99,"Vencida","No Prazo") -> No Prazo
A6: BAZAR GRACELAND DISCOS LTDA | C6: FORA | D6: INATIVA | F6: ='Menu principal'!O$17 -> 43242 | G6: 43172 | H6: =DAYS360(F6,G6) -> -69 | I6: =IF(Tabela1[[#This Row],[ENTREGA]]="",Tabela1[[#This Row],[VENCIMENTO]]-TODAY( ),"") | J6: =IF(H6>0.99,"Vencida","No Prazo") -> No Prazo
A7: DEPOSITO DE DOCES SANSIL LTDA ME | C7: FORA | D7: INATIVA | F7: ='Menu principal'!O$17 -> 43242 | G7: 43172 | H7: =DAYS360(F7,G7) -> -69 | I7: =IF(Tabela1[[#This Row],[ENTREGA]]="",Tabela1[[#This Row],[VENCIMENTO]]-TODAY( ),"") | J7: =IF(H7>0.99,"Vencida","No Prazo") -> No Prazo
A8: ELS CHAVES TREINAMENTO | C8: FORA | D8: INATIVA | F8: ='Menu principal'!O$17 -> 43242 | G8: 43172 | H8: =DAYS360(F8,G8) -> -69 | I8: =IF(Tabela1[[#This Row],[ENTREGA]]="",Tabela1[[#This Row],[VENCIMENTO]]-TODAY( ),"") | J8: =IF(H8>0.99,"Vencida","No Prazo") -> No Prazo
A9: ENGECORP CONSULT ASSES E PROJ ENGEN LT | C9: LP | D9: INATIVA | F9: 43242 | H9: =DAYS360(F9,G9) -> -42622 | I9: =IF(Tabela1[[#This Row],[ENTREGA]]="",Tabela1[[#This Row],[VENCIMENTO]]-TODAY( ),"") -> -1 | J9: =IF(H9>0.99,"Vencida","No Prazo") -> No Prazo
A10: FERBOR COM. REPRES. | C10: FORA | D10: INATIVA | F10: ='Menu principal'!O$17 -> 43242 | G10: 43172 | H10: =DAYS360(F10,G10) -> -69 | I10: =IF(Tabela1[[#This Row],[ENTREGA]]="",Tabela1[[#This Row],[VENCIMENTO]]-TODAY( ),"") | J10: =IF(H10>0.99,"Vencida","No Prazo") -> No Prazo
A11: FERGO SOLUÇÕES | C11: FORA | D11: INATIVA | F11: ='Menu principal'!O$17 -> 43242 | G11: 43172 | H11: =DAYS360(F11,G11) -> -69 | I11: =IF(Tabela1[[#This Row],[ENTREGA]]="",Tabela1[[#This Row],[VENCIMENTO]]-TODAY( ),"") | J11: =IF(H11>0.99,"Vencida","No Prazo") -> No Prazo
A12: FERNANDA CHAVES | C12: FORA | D12: INATIVA | F12: ='Menu principal'!O$17 -> 43242 | G12: 43172 | H12: =DAYS360(F12,G12) -> -69 | I12: =IF(Tabela1[[#This Row],[ENTREGA]]="",Tabela1[[#This Row],[VENCIMENTO]]-TODAY( ),"") | J12: =IF(H12>0.99,"Vencida","No Prazo") -> No Prazo
A13: FSW PLANEJAMENTO | C13: LP | D13: ATIVA | F13: 43242 | H13: =DAYS360(F13,G13) -> -42622 | I13: =IF(Tabela1[[#This Row],[ENTREGA]]="",Tabela1[[#This Row],[VENCIMENTO]]-TODAY( ),"") -> -1 | J13: =IF(H13>0.99,"Vencida","No Prazo") -> No Prazo
A14: GALETO DE RAMOS LANCHONETE | C14: SN | D14: INATIVA | F14: ='Menu principal'!O$17 -> 43242 | G14: 43172 | H14: =DAYS360(F14,G14) -> -69 | I14: =IF(Tabela1[[#This Row],[ENTREGA]]="",Tabela1[[#This Row],[VENCIMENTO]]-TODAY( ),"") | J14: =IF(H14>0.99,"Vencida","No Prazo") -> No Prazo
A15: GOLAN REFORMA E CONTRUÇÃO LTDA (dflash) | C15: SN | D15: ATIVA POSSUI CPRB | F15: 43182 | G15: 43174 | H15: =DAYS360(F15,G15) -> -8 | I15: =IF(Tabela1[[#This Row],[ENTREGA]]="",Tabela1[[#This Row],[VENCIMENTO]]-TODAY( ),"") | J15: =IF(H15>0.99,"Vencida","No Prazo") -> No Prazo
A16: GLOBAL RENTAL SERVICE COM. E SERV. DE MAQ E EQIP. | C16: SN | D16: INATIVA | F16: ='Menu principal'!O$17 -> 43242 | G16: 43172 | H16: =DAYS360(F16,G16) -> -69 | I16: =IF(Tabela1[[#This Row],[ENTREGA]]="",Tabela1[[#This Row],[VENCIMENTO]]-TODAY( ),"") | J16: =IF(H16>0.99,"Vencida","No Prazo") -> No Prazo
A17: JARDIM ESCOLA SOLAR DA CRIANÇA | C17: LP | D17: INATIVA | F17: 43242 | H17: =DAYS360(F17,G17) -> -42622 | I17: =IF(Tabela1[[#This Row],[ENTREGA]]="",Tabela1[[#This Row],[VENCIMENTO]]-TODAY( ),"") -> -1 | J17: =IF(H17>0.99,"Vencida","No Prazo") -> No Prazo
A18: LA BORQUEIREIE REPRESENTAÇÕES COM. LTDA | C18: LP | D18: INATIVA | F18: 43242 | H18: =DAYS360(F18,G18) -> -42622 | I18: =IF(Tabela1[[#This Row],[ENTREGA]]="",Tabela1[[#This Row],[VENCIMENTO]]-TODAY( ),"") -> -1 | J18: =IF(H18>0.99,"Vencida","No Prazo") -> No Prazo
A19: MENPHIS DISCOS LTDA | C19: SN | D19: INATIVA | F19: ='Menu principal'!O$17 -> 43242 | G19: 43172 | H19: =DAYS360(F19,G19) -> -69 | I19: =IF(Tabela1[[#This Row],[ENTREGA]]="",Tabela1[[#This Row],[VENCIMENTO]]-TODAY( ),"") | J19: =IF(H19>0.99,"Vencida","No Prazo") -> No Prazo
A20: MURALHÃO 2000 DOS VIDROS | C20: LP | D20: INATIVA | F20: 43242 | H20: =DAYS360(F20,G20) -> -42622 | I20: =IF(Tabela1[[#This Row],[ENTREGA]]="",Tabela1[[#This Row],[VENCIMENTO]]-TODAY( ),"") -> -1 | J20: =IF(H20>0.99,"Vencida","No Prazo") -> No Prazo
A21: NASCIMENTO REPRESENTAÇÕES | C21: LP | D21: ATIVA | F21: 43242 | H21: =DAYS360(F21,G21) -> -42622 | I21: =IF(Tabela1[[#This Row],[ENTREGA]]="",Tabela1[[#This Row],[VENCIMENTO]]-TODAY( ),"") -> -1 | J21: =IF(H21>0.99,"Vencida","No Prazo") -> No Prazo
A22: NEIMAR PLASTICOS INDUSTRIAIS LTDA | C22: LP | D22: INATIVA | F22: 43242 | H22: =DAYS360(F22,G22) -> -42622 | I22: =IF(Tabela1[[#This Row],[ENTREGA]]="",Tabela1[[#This Row],[VENCIMENTO]]-TODAY( ),"") -> -1 | J22: =IF(H22>0.99,"Vencida","No Prazo") -> No Prazo
A23: NOGUEIRA PINHO COM. | C23: LP | D23: INATIVA | F23: 43242 | H23: =DAYS360(F23,G23) -> -42622 | I23: =IF(Tabela1[[#This Row],[ENTREGA]]="",Tabela1[[#This Row],[VENCIMENTO]]-TODAY( ),"") -> -1 | J23: =IF(H23>0.99,"Vencida","No Prazo") -> No Prazo
A24: PONTO DAS BLUSAS COM. DE ROUPAS LTDA | C24: LP | D24: INATIVA | F24: 43242 | H24: =DAYS360(F24,G24) -> -42622 | I24: =IF(Tabela1[[#This Row],[ENTREGA]]="",Tabela1[[#This Row],[VENCIMENTO]]-TODAY( ),"") -> -1 | J24: =IF(H24>0.99,"Vencida","No Prazo") -> No Prazo
A25: QUITUNGO AUTO VIDROS E ACES DE AUTOM LT | C25: LP | D25: ATIVA | F25: 43242 | H25: =DAYS360(F25,G25) -> -42622 | I25: =IF(Tabela1[[#This Row],[ENTREGA]]="",Tabela1[[#This Row],[VENCIMENTO]]-TODAY( ),"") -> -1 | J25: =IF(H25>0.99,"Vencida","No Prazo") -> No Prazo
A26: REPRESENTAÇÕES GUIMARAES E ALMEIDA LTDA | C26: LP | D26: INATIVA | F26: 43242 | H26: =DAYS360(F26,G26) -> -42622 | I26: =IF(Tabela1[[#This Row],[ENTREGA]]="",Tabela1[[#This Row],[VENCIMENTO]]-TODAY( ),"") -> -1 | J26: =IF(H26>0.99,"Vencida","No Prazo") -> No Prazo
A27: RODMAN COM DE BORRACHAS | C27: LP | D27: INATIVA | F27: 43242 | H27: =DAYS360(F27,G27) -> -42622 | I27: =IF(Tabela1[[#This Row],[ENTREGA]]="",Tabela1[[#This Row],[VENCIMENTO]]-TODAY( ),"") -> -1 | J27: =IF(H27>0.99,"Vencida","No Prazo") -> No Prazo
A28: SIMOES IMOVEIS | C28: LP | D28: INATIVA | F28: 43242 | H28: =DAYS360(F28,G28) -> -42622 | I28: =IF(Tabela1[[#This Row],[ENTREGA]]="",Tabela1[[#This Row],[VENCIMENTO]]-TODAY( ),"") -> -1 | J28: =IF(H28>0.99,"Vencida","No Prazo") -> No Prazo
A29: TRANSPORTADORA P R RAFALSKI LTDA | C29: SN | D29: INATIVA | F29: ='Menu principal'!O$17 -> 43242 | G29: 43173 | H29: =DAYS360(F29,G29) -> -68 | I29: =IF(Tabela1[[#This Row],[ENTREGA]]="",Tabela1[[#This Row],[VENCIMENTO]]-TODAY( ),"") | J29: =IF(H29>0.99,"Vencida","No Prazo") -> No Prazo
A30: V SONIC COMERCIO EXTERIOR obs comentario | C30: LP (EXCLUIDA 01.2018) | D30: VERIFICAR | F30: 43242 | H30: =DAYS360(F30,G30) -> -42622 | I30: =IF(Tabela1[[#This Row],[ENTREGA]]="",Tabela1[[#This Row],[VENCIMENTO]]-TODAY( ),"") -> -1 | J30: =IF(H30>0.99,"Vencida","No Prazo") -> No Prazo
A31: BICHO FELIZ LTDA | C31: LP (EXCLUIDA 01.2018) | D31: ATIVA | F31: 43242 | H31: =DAYS360(F31,G31) -> -42622 | I31: =IF(Tabela1[[#This Row],[ENTREGA]]="",Tabela1[[#This Row],[VENCIMENTO]]-TODAY( ),"") -> -1 | J31: =IF(H31>0.99,"Vencida","No Prazo") -> No Prazo
A32: NR MEIRELLES DIST. DE DESC. LIMP. E PROTEÇÃO | C32: LP (EXCLUIDA 01.2018) | D32: ATIVA | F32: 43242 | H32: =DAYS360(F32,G32) -> -42622 | I32: =IF(Tabela1[[#This Row],[ENTREGA]]="",Tabela1[[#This Row],[VENCIMENTO]]-TODAY( ),"") -> -1 | J32: =IF(H32>0.99,"Vencida","No Prazo") -> No Prazo
A33: IMPRESSO PRODUTOS E SERVIÇOS GRAFICOS LTDA | C33: LP (EXCLUIDA 01.2018) | D33: ATIVA | F33: 43242 | H33: =DAYS360(F33,G33) -> -42622 | I33: =IF(Tabela1[[#This Row],[ENTREGA]]="",Tabela1[[#This Row],[VENCIMENTO]]-TODAY( ),"") -> -1 | J33: =IF(H33>0.99,"Vencida","No Prazo") -> No Prazo
A34: ORN ENTERTAINMENT AGENCIA DE TURISMO E VIAGENS | C34: SN | D34: ATIVA | F34: 43182 | G34: 43173 | H34: =DAYS360(F34,G34) -> -9 | I34: =IF(Tabela1[[#This Row],[ENTREGA]]="",Tabela1[[#This Row],[VENCIMENTO]]-TODAY( ),"") | J34: =IF(H34>0.99,"Vencida","No Prazo") -> No Prazo
A35: ALEGON COM. ATACADISTA | C35: SN | D35: INATIVA | F35: 43182 | G35: 43174 | H35: =DAYS360(F35,G35) -> -8 | I35: =IF(Tabela1[[#This Row],[ENTREGA]]="",Tabela1[[#This Row],[VENCIMENTO]]-TODAY( ),"") | J35: =IF(H35>0.99,"Vencida","No Prazo") -> No Prazo
A36: BOCA DE VAZ LOBO LANCHES LTDA | C36: SN | D36: INATIVA | F36: 43182 | G36: 43174 | H36: =DAYS360(F36,G36) -> -8 | I36: =IF(Tabela1[[#This Row],[ENTREGA]]="",Tabela1[[#This Row],[VENCIMENTO]]-TODAY( ),"") | J36: =IF(H36>0.99,"Vencida","No Prazo") -> No Prazo

Sheet EFD CONT
A1: EMPRESA | B1: CNPJ | C1: REGIME | D1: RESPONSÁVEL | E1: VENCIMENTO | F1: ENTREGA | G1: ATRASO | H1: Controle | I1: STATUS
A2: XXXXXXX | B2: XXXXXXX | C2: XXXXXXX | D2: MÁRCIO | E2: 43182 | F2: 43174 | G2: =DAYS360(E2,F2) -> -8 | H2: =IF(Tabela13[[#This Row],[ENTREGA]]="",Tabela13[[#This Row],[VENCIMENTO]]-TODAY(),"") | I2: =IF(G2>0.99,"Vencida","No Prazo") -> No Prazo
A3: XXXXXXX | B3: XXXXXXX | C3: XXXXXXX | D3: MÁRCIO | E3: 43182 | F3: 43174 | G3: =DAYS360(E3,F3) -> -8 | H3: =IF(Tabela13[[#This Row],[ENTREGA]]="",Tabela13[[#This Row],[VENCIMENTO]]-TODAY(),"") | I3: =IF(G3>0.99,"Vencida","No Prazo") -> No Prazo
A4: XXXXXXX | B4: XXXXXXX | C4: XXXXXXX | D4: MÁRCIO | E4: 43123 | F4: 43117 | G4: =DAYS360(E4,F4) -> -6 | H4: =IF(Tabela13[[#This Row],[ENTREGA]]="",Tabela13[[#This Row],[VENCIMENTO]]-TODAY(),"") | I4: =IF(G4>0.99,"Vencida","No Prazo") -> No Prazo

Sheet DIRF
A1: EMPRESA | B1: CNPJ | C1: REGIME | D1: RESPONSÁVEL | E1: VENCIMENTO | F1: ENTREGA | G1: ATRASO | H1: Controle | I1: STATUS
A2: XXXXXXX | B2: XXXXXXX | C2: XXXXXXX | E2: 43179 | G2: =DAYS360(E2,F2) -> -42560 | H2: =IF(Tabela14[[#This Row],[ENTREGA]]="",Tabela14[[#This Row],[VENCIMENTO]]-TODAY(),"") -> -64 | I2: =IF(G2>0.99,"Vencida","No Prazo") -> No Prazo
A3: XXXXXXX | B3: XXXXXXX | C3: XXXXXXX | E3: 43159 | F3: 43159 | G3: =DAYS360(E3,F3) -> -2 | H3: =IF(Tabela14[[#This Row],[ENTREGA]]="",Tabela14[[#This Row],[VENCIMENTO]]-TODAY(),"") | I3: =IF(G3>0.99,"Vencida","No Prazo") -> No Prazo
A4: XXXXXXX | B4: XXXXXXX | C4: XXXXXXX | E4: 42083 | G4: =DAYS360(E4,F4) -> -41480 | H4: =IF(Tabela14[[#This Row],[ENTREGA]]="",Tabela14[[#This Row],[VENCIMENTO]]-TODAY(),"") -> -1160 | I4: =IF(G4>0.99,"Vencida","No Prazo") -> No Prazo

Sheet DIMOB

Sheet DEFIS
A1: EMPRESA INATIVAS | B1: CNPJ | C1: REGIME | D1: COD ACESSO | E1: SITUAÇÃO | F1: CPF RESPONSAVE | G1: VENCIMENTO | H1: ENTREGA | I1: ATRASO | J1: Controle | K1: STATUS
A2: A L SANT'ANNA COM DE BORRACHAS ME | C2: SN | D2: 597567186278 | E2: ATIVA | F2: 110.075.407-53 | G2: ='Menu principal'!O$21 -> 43190 | I2: =DAYS360(DEFIS!G2,H2) -> -42570 | J2: =IF(Tabela5[[#This Row],[ENTREGA]]="",Tabela5[[#This Row],[VENCIMENTO]]-TODAY(),"") -> -53 | K2: =IF(I2>0.99,"Vencida","No Prazo") -> No Prazo
A3: ACA COMERCIO | C3: SN | D3: 402382268932 | E3: INATIVA | F3: 111.195.527-10 | G3: ='Menu principal'!O$21 -> 43190 | I3: =DAYS360(DEFIS!G3,H3) -> -42570 | J3: =IF(Tabela5[[#This Row],[ENTREGA]]="",Tabela5[[#This Row],[VENCIMENTO]]-TODAY(),"") -> -53 | K3: =IF(I3>0.99,"Vencida","No Prazo") -> No Prazo
A4: ACAPORI PRODUTOS DE MINAS LTDA ME | C4: SN | D4: 967968485127 | E4: ATIVA | F4: 537.394.007-06 | G4: ='Menu principal'!O$21 -> 43190 | I4: =DAYS360(DEFIS!G4,H4) -> -42570 | J4: =IF(Tabela5[[#This Row],[ENTREGA]]="",Tabela5[[#This Row],[VENCIMENTO]]-TODAY(),"") -> -53 | K4: =IF(I4>0.99,"Vencida","No Prazo") -> No Prazo
A5: ALEGON COM. ATACADISTA | C5: SN | D5: CERTIFICADO | E5: INATIVA | F5: 2426833718 | G5: ='Menu principal'!O$21 -> 43190 | I5: =DAYS360(DEFIS!G5,H5) -> -42570 | J5: =IF(Tabela5[[#This Row],[ENTREGA]]="",Tabela5[[#This Row],[VENCIMENTO]]-TODAY(),"") -> -53 | K5: =IF(I5>0.99,"Vencida","No Prazo") -> No Prazo
A6: ALL LABOR MAT MEDICO HOSP LTDA ME | C6: SN | D6: 029407792330 | E6: ATIVA | F6: 013.048.137-89 | G6: ='Menu principal'!O$21 -> 43190 | I6: =DAYS360(DEFIS!G6,H6) -> -42570 | J6: =IF(Tabela5[[#This Row],[ENTREGA]]="",Tabela5[[#This Row],[VENCIMENTO]]-TODAY(),"") -> -53 | K6: =IF(I6>0.99,"Vencida","No Prazo") -> No Prazo
A7: APM TURISMO E DIVULGAÇÕES LTDA | C7: SN | D7: certificado | E7: ATIVA | F7: 051.806.727-08 | G7: ='Menu principal'!O$21 -> 43190 | I7: =DAYS360(DEFIS!G7,H7) -> -42570 | J7: =IF(Tabela5[[#This Row],[ENTREGA]]="",Tabela5[[#This Row],[VENCIMENTO]]-TODAY(),"") -> -53 | K7: =IF(I7>0.99,"Vencida","No Prazo") -> No Prazo
A8: AUTO CENTER LCG MANUT DE VEIC LTDA | C8: SN | D8: 286915126339 | E8: ATIVA | F8: 871.277.927-04 | G8: ='Menu principal'!O$21 -> 43190 | I8: =DAYS360(DEFIS!G8,H8) -> -42570 | J8: =IF(Tabela5[[#This Row],[ENTREGA]]="",Tabela5[[#This Row],[VENCIMENTO]]-TODAY(),"") -> -53 | K8: =IF(I8>0.99,"Vencida","No Prazo") -> No Prazo
A9: AUTO VIDROS LOBO JUNIOR LTDA ME | C9: SN | D9: 451341981764 | E9: ATIVA | F9: 847.266.107-59 | G9: ='Menu principal'!O$21 -> 43190 | I9: =DAYS360(DEFIS!G9,H9) -> -42570 | J9: =IF(Tabela5[[#This Row],[ENTREGA]]="",Tabela5[[#This Row],[VENCIMENTO]]-TODAY(),"") -> -53 | K9: =IF(I9>0.99,"Vencida","No Prazo") -> No Prazo
A10: (QUITANDA) BAR E RESTAURANTE DULCILIA LTDA. | C10: SN | E10: ATIVA | F10: 031.458.053-04 | G10: ='Menu principal'!O$21 -> 43190 | I10: =DAYS360(DEFIS!G10,H10) -> -42570 | J10: =IF(Tabela5[[#This Row],[ENTREGA]]="",Tabela5[[#This Row],[VENCIMENTO]]-TODAY(),"") -> -53 | K10: =IF(I10>0.99,"Vencida","No Prazo") -> No Prazo
A11: BAR LANC VILLARES DE BONSUCESSO LTDA | C11: SN | D11: 981254309351 | E11: ATIVA | F11: 671.479.097-04 | G11: ='Menu principal'!O$21 -> 43190 | I11: =DAYS360(DEFIS!G11,H11) -> -42570 | J11: =IF(Tabela5[[#This Row],[ENTREGA]]="",Tabela5[[#This Row],[VENCIMENTO]]-TODAY(),"") -> -53 | K11: =IF(I11>0.99,"Vencida","No Prazo") -> No Prazo
A12: B L QUINDOS ART.ALIMENTICIOS (emporio mineiro) | C12: SN | E12: ativa | F12: 597.862.307-44 | G12: ='Menu principal'!O$21 -> 43190 | I12: =DAYS360(DEFIS!G12,H12) -> -42570 | J12: =IF(Tabela5[[#This Row],[ENTREGA]]="",Tabela5[[#This Row],[VENCIMENTO]]-TODAY(),"") -> -53 | K12: =IF(I12>0.99,"Vencida","No Prazo") -> No Prazo
A13: BICHO FELIZ LTDA - EXCLUIDO S.N 2018 | C13: SN | D13: 17811160130 | E13: ATIVA | F13: 820.882.687-15 | G13: ='Menu principal'!O$21 -> 43190 | I13: =DAYS360(DEFIS!G13,H13) -> -42570 | J13: =IF(Tabela5[[#This Row],[ENTREGA]]="",Tabela5[[#This Row],[VENCIMENTO]]-TODAY(),"") -> -53 | K13: =IF(I13>0.99,"Vencida","No Prazo") -> No Prazo
A14: BOCA DE VAZ LOBO LANCHES LTDA | C14: SN | D14: 332571451507 | E14: INATIVA | F14: 082.144.197-35 | G14: ='Menu principal'!O$21 -> 43190 | I14: =DAYS360(DEFIS!G14,H14) -> -42570 | J14: =IF(Tabela5[[#This Row],[ENTREGA]]="",Tabela5[[#This Row],[VENCIMENTO]]-TODAY(),"") -> -53 | K14: =IF(I14>0.99,"Vencida","No Prazo") -> No Prazo
A15: CENTRO CULINÁRIO C C E G COM SERV G AL | C15: SN | D15: 434753221053 | E15: ATIVA | F15: 673.143.767-00 | G15: ='Menu principal'!O$21 -> 43190 | I15: =DAYS360(DEFIS!G15,H15) -> -42570 | J15: =IF(Tabela5[[#This Row],[ENTREGA]]="",Tabela5[[#This Row],[VENCIMENTO]]-TODAY(),"") -> -53 | K15: =IF(I15>0.99,"Vencida","No Prazo") -> No Prazo
A16: CENTRO DE ESTET LIRIOS LTDA | C16: SN | D16: CERTIFICADO | E16: ATIVA | F16: 110.875.237-37 | G16: ='Menu principal'!O$21 -> 43190 | I16: =DAYS360(DEFIS!G16,H16) -> -42570 | J16: =IF(Tabela5[[#This Row],[ENTREGA]]="",Tabela5[[#This Row],[VENCIMENTO]]-TODAY(),"") -> -53 | K16: =IF(I16>0.99,"Vencida","No Prazo") -> No Prazo
A17: C M NEVES EVENTOS ME | C17: SN | D17: 682276248561 | E17: ATIVA | F17: 081.837.997-95 | G17: ='Menu principal'!O$21 -> 43190 | I17: =DAYS360(DEFIS!G17,H17) -> -42570 | J17: =IF(Tabela5[[#This Row],[ENTREGA]]="",Tabela5[[#This Row],[VENCIMENTO]]-TODAY(),"") -> -53 | K17: =IF(I17>0.99,"Vencida","No Prazo") -> No Prazo
A18: CONGELADOS PINHEIROS 2003 LTDA | C18: SN | D18: 068807431207 | E18: ATIVA | F18: 491.461.814-15 | G18: ='Menu principal'!O$21 -> 43190 | I18: =DAYS360(DEFIS!G18,H18) -> -42570 | J18: =IF(Tabela5[[#This Row],[ENTREGA]]="",Tabela5[[#This Row],[VENCIMENTO]]-TODAY(),"") -> -53 | K18: =IF(I18>0.99,"Vencida","No Prazo") -> No Prazo
A19: CRECHE PRÉ ESCOLAR MEUS PEQ ANJINHOS LT | C19: SN | D19: 711345841578 | E19: ATIVA | F19: 723.595.367-53 | G19: ='Menu principal'!O$21 -> 43190 | I19: =DAYS360(DEFIS!G19,H19) -> -42570 | J19: =IF(Tabela5[[#This Row],[ENTREGA]]="",Tabela5[[#This Row],[VENCIMENTO]]-TODAY(),"") -> -53 | K19: =IF(I19>0.99,"Vencida","No Prazo") -> No Prazo
A20: DUE NORMA E ALESSANDA CURSO PREPAR LT | C20: SN | D20: 691376852675 | E20: ATIVA | F20: 082.694.237-77 | G20: ='Menu principal'!O$21 -> 43190 | I20: =DAYS360(DEFIS!G20,H20) -> -42570 | J20: =IF(Tabela5[[#This Row],[ENTREGA]]="",Tabela5[[#This Row],[VENCIMENTO]]-TODAY(),"") -> -53 | K20: =IF(I20>0.99,"Vencida","No Prazo") -> No Prazo
A21: E A DE SILVA COM DE PEÇAS E REP P/ VEIC | C21: SN | D21: 379918690396 | E21: ATIVA | F21: 103.403.647-50 | G21: ='Menu principal'!O$21 -> 43190 | I21: =DAYS360(DEFIS!G21,H21) -> -42570 | J21: =IF(Tabela5[[#This Row],[ENTREGA]]="",Tabela5[[#This Row],[VENCIMENTO]]-TODAY(),"") -> -53 | K21: =IF(I21>0.99,"Vencida","No Prazo") -> No Prazo
A22: ETIQUE - ROLL COM DE ETIQ E EMBAL LTDA | C22: SN | D22: 002.280.340.385 | E22: ATIVA | F22: 018.386.807-21 | G22: ='Menu principal'!O$21 -> 43190 | I22: =DAYS360(DEFIS!G22,H22) -> -42570 | J22: =IF(Tabela5[[#This Row],[ENTREGA]]="",Tabela5[[#This Row],[VENCIMENTO]]-TODAY(),"") -> -53 | K22: =IF(I22>0.99,"Vencida","No Prazo") -> No Prazo
A23: GALETO DE RAMOS LANCHONETE | C23: SN | D23: 890747544220 | E23: INATIVA | F23: 013.414.707-33 | G23: ='Menu principal'!O$21 -> 43190 | I23: =DAYS360(DEFIS!G23,H23) -> -42570 | J23: =IF(Tabela5[[#This Row],[ENTREGA]]="",Tabela5[[#This Row],[VENCIMENTO]]-TODAY(),"") -> -53 | K23: =IF(I23>0.99,"Vencida","No Prazo") -> No Prazo
A24: GLOBAL RENTAL SERVICE COM. E SERV. DE MAQ E EQIP. | C24: SN | E24: INATIVA | G24: ='Menu principal'!O$21 -> 43190 | I24: =DAYS360(DEFIS!G24,H24) -> -42570 | J24: =IF(Tabela5[[#This Row],[ENTREGA]]="",Tabela5[[#This Row],[VENCIMENTO]]-TODAY(),"") -> -53 | K24: =IF(I24>0.99,"Vencida","No Prazo") -> No Prazo
A25: GOLAN REFORMA E CONTRUÇÃO LTDA (dflash) POSSUI DESONERAÇÃO (FAZER DCTF) | C25: SN | D25: 139077946920 | E25: ATIVA | F25: 804.139.947-91 | G25: ='Menu principal'!O$21 -> 43190 | I25: =DAYS360(DEFIS!G25,H25) -> -42570 | J25: =IF(Tabela5[[#This Row],[ENTREGA]]="",Tabela5[[#This Row],[VENCIMENTO]]-TODAY(),"") -> -53 | K25: =IF(I25>0.99,"Vencida","No Prazo") -> No Prazo
A26: IMPRESSO PROD SERV GRAFICOS LTDA EXCLUIDA S.NACIONAL 2018 | C26: SN | D26: 923924798459 | E26: ATIVA | F26: 714.469.667-04 | G26: ='Menu principal'!O$21 -> 43190 | I26: =DAYS360(DEFIS!G26,H26) -> -42570 | J26: =IF(Tabela5[[#This Row],[ENTREGA]]="",Tabela5[[#This Row],[VENCIMENTO]]-TODAY(),"") -> -53 | K26: =IF(I26>0.99,"Vencida","No Prazo") -> No Prazo
A27: LAVANDERIA CARIOCA | C27: SN | D27: procuração digital | E27: ATIVA | G27: ='Menu principal'!O$21 -> 43190 | I27: =DAYS360(DEFIS!G27,H27) -> -42570 | J27: =IF(Tabela5[[#This Row],[ENTREGA]]="",Tabela5[[#This Row],[VENCIMENTO]]-TODAY(),"") -> -53 | K27: =IF(I27>0.99,"Vencida","No Prazo") -> No Prazo
A28: L A G SANTOS COMERCIAL HOSPITALAR | C28: SN | E28: ATIVA | G28: ='Menu principal'!O$21 -> 43190 | I28: =DAYS360(DEFIS!G28,H28) -> -42570 | J28: =IF(Tabela5[[#This Row],[ENTREGA]]="",Tabela5[[#This Row],[VENCIMENTO]]-TODAY(),"") -> -53 | K28: =IF(I28>0.99,"Vencida","No Prazo") -> No Prazo
A29: L L 3 CONTABILIDADE LTDA | C29: SN | D29: 276125386187 | E29: LL3 | F29: 361.291.867-20 | G29: ='Menu principal'!O$21 -> 43190 | I29: =DAYS360(DEFIS!G29,H29) -> -42570 | J29: =IF(Tabela5[[#This Row],[ENTREGA]]="",Tabela5[[#This Row],[VENCIMENTO]]-TODAY(),"") -> -53 | K29: =IF(I29>0.99,"Vencida","No Prazo") -> No Prazo
A30: LB MEGA SOUND LTDA | C30: SN | D30: 659006179196 | E30: ATIVA | F30: 086.858.747.85 | G30: ='Menu principal'!O$21 -> 43190 | I30: =DAYS360(DEFIS!G30,H30) -> -42570 | J30: =IF(Tabela5[[#This Row],[ENTREGA]]="",Tabela5[[#This Row],[VENCIMENTO]]-TODAY(),"") -> -53 | K30: =IF(I30>0.99,"Vencida","No Prazo") -> No Prazo
A31: LCDTEC SERV.MANUT DE EQUIP ELETRON LTDA | C31: SN | D31: 224592792222 | E31: ATIVA | F31: 754.111.057.49 | G31: ='Menu principal'!O$21 -> 43190 | I31: =DAYS360(DEFIS!G31,H31) -> -42570 | J31: =IF(Tabela5[[#This Row],[ENTREGA]]="",Tabela5[[#This Row],[VENCIMENTO]]-TODAY(),"") -> -53 | K31: =IF(I31>0.99,"Vencida","No Prazo") -> No Prazo
A32: MD ALTACAR | C32: SN | D32: 722941790039 | E32: ATIVA | F32: 321187750 | G32: ='Menu principal'!O$21 -> 43190 | I32: =DAYS360(DEFIS!G32,H32) -> -42570 | J32: =IF(Tabela5[[#This Row],[ENTREGA]]="",Tabela5[[#This Row],[VENCIMENTO]]-TODAY(),"") -> -53 | K32: =IF(I32>0.99,"Vencida","No Prazo") -> No Prazo
A33: M S CIPRIANO AGENCIAMENTO ESPORTIVO | C33: SN | D33: procuração digital | E33: ATIVA | F33: 706.202.721-98 | G33: ='Menu principal'!O$21 -> 43190 | I33: =DAYS360(DEFIS!G33,H33) -> -42570 | J33: =IF(Tabela5[[#This Row],[ENTREGA]]="",Tabela5[[#This Row],[VENCIMENTO]]-TODAY(),"") -> -53 | K33: =IF(I33>0.99,"Vencida","No Prazo") -> No Prazo
A34: MEMPHIS PRODUÇÕES ARTISTICAS E EVENTOS LT | C34: SN | D34: 384104504374 | E34: ATIVA | F34: 078.480.127-43 | G34: ='Menu principal'!O$21 -> 43190 | I34: =DAYS360(DEFIS!G34,H34) -> -42570 | J34: =IF(Tabela5[[#This Row],[ENTREGA]]="",Tabela5[[#This Row],[VENCIMENTO]]-TODAY(),"") -> -53 | K34: =IF(I34>0.99,"Vencida","No Prazo") -> No Prazo
A35: MERCEARIA HORIFRUT (MESMO DONO BAR DUCILIA) | C35: SN | D35: procuração digital | E35: ATIVA | F35: 072.128.717-45 | G35: ='Menu principal'!O$21 -> 43190 | I35: =DAYS360(DEFIS!G35,H35) -> -42570 | J35: =IF(Tabela5[[#This Row],[ENTREGA]]="",Tabela5[[#This Row],[VENCIMENTO]]-TODAY(),"") -> -53 | K35: =IF(I35>0.99,"Vencida","No Prazo") -> No Prazo
A36: MONTE SIÃO MANUTENÇÃO E REFORMAS LTDA | C36: SN | D36: 163153902872 | E36: ATIVA | F36: 021.024.317-11 | G36: ='Menu principal'!O$21 -> 43190 | I36: =DAYS360(DEFIS!G36,H36) -> -42570 | J36: =IF(Tabela5[[#This Row],[ENTREGA]]="",Tabela5[[#This Row],[VENCIMENTO]]-TODAY(),"") -> -53 | K36: =IF(I36>0.99,"Vencida","No Prazo") -> No Prazo
A37: N R MEIRELES -EXCLUIDA DO S.NACIONAL 2018 | C37: SN | D37: certificado | E37: ATIVA | F37: 483.196.437-91 | G37: ='Menu principal'!O$21 -> 43190 | I37: =DAYS360(DEFIS!G37,H37) -> -42570 | J37: =IF(Tabela5[[#This Row],[ENTREGA]]="",Tabela5[[#This Row],[VENCIMENTO]]-TODAY(),"") -> -53 | K37: =IF(I37>0.99,"Vencida","No Prazo") -> No Prazo
A38: NET DATA INFORMATICA LTDA | C38: SN | D38: 000.017.144.720 | E38: ATIVA | F38: 932.087.667-34 | G38: ='Menu principal'!O$21 -> 43190 | I38: =DAYS360(DEFIS!G38,H38) -> -42570 | J38: =IF(Tabela5[[#This Row],[ENTREGA]]="",Tabela5[[#This Row],[VENCIMENTO]]-TODAY(),"") -> -53 | K38: =IF(I38>0.99,"Vencida","No Prazo") -> No Prazo
A39: PEDRAS COM DE PLAST E COMUNIC VISUAL | C39: SN | D39: procuração digital | E39: ATIVA | F39: 047.466.667-09 | G39: ='Menu principal'!O$21 -> 43190 | I39: =DAYS360(DEFIS!G39,H39) -> -42570 | J39: =IF(Tabela5[[#This Row],[ENTREGA]]="",Tabela5[[#This Row],[VENCIMENTO]]-TODAY(),"") -> -53 | K39: =IF(I39>0.99,"Vencida","No Prazo") -> No Prazo
A40: QUITUNGO AUTO VIDROS ITABORAÍ LTDA EPP | C40: SN | D40: certificado | E40: ATIVA | F40: 033.158.747-51 | G40: ='Menu principal'!O$21 -> 43190 | I40: =DAYS360(DEFIS!G40,H40) -> -42570 | J40: =IF(Tabela5[[#This Row],[ENTREGA]]="",Tabela5[[#This Row],[VENCIMENTO]]-TODAY(),"") -> -53 | K40: =IF(I40>0.99,"Vencida","No Prazo") -> No Prazo
...

Sheet DMED

Sheet DSPJ

Sheet ECD
A1: EMPRESA INATIVAS | B1: CNPJ | C1: REGIME | D1: SITUAÇÃO | E1: RESPONSÁVEL | F1: VENCIMENTO | G1: ENTREGA | H1: ATRASO | I1: Controle | J1: STATUS
A2: ACA COMERCIO | C2: SN | D2: INATIVA | F2: ='Menu principal'!O$25 -> 43250 | G2: 43237 | H2: =DAYS360(F2,G2) -> -13 | I2: =IF(G2="",F2-TODAY( ),"") | J2: =IF(H2>0.99,"Vencida","No Prazo") -> No Prazo
A3: ADMINISTRADORA DE MOVEIS BAENA | C3: LP | D3: INATIVA | F3: ='Menu principal'!O$25 -> 43250 | G3: 43235 | H3: =DAYS360(F3,G3) -> -15 | I3: =IF(Tabela1[[#This Row],[ENTREGA]]="",Tabela1[[#This Row],[VENCIMENTO]]-TODAY( ),"") -> -1 | J3: =IF(H3>0.99,"Vencida","No Prazo") -> No Prazo
A4: AFAG REPRESSETNAÇÕES LTDA | C4: LP | D4: INATIVA | F4: ='Menu principal'!O$25 -> 43250 | G4: 43239 | H4: =DAYS360(F4,G4) -> -11 | I4: =IF(Tabela1[[#This Row],[ENTREGA]]="",Tabela1[[#This Row],[VENCIMENTO]]-TODAY( ),"") -> -1 | J4: =IF(H4>0.99,"Vencida","No Prazo") -> No Prazo
A5: BABY SAFE DO BRASIL | C5: LP | D5: INATIVA | F5: ='Menu principal'!O$25 -> 43250 | G5: 43240 | H5: =DAYS360(F5,G5) -> -10 | I5: =IF(Tabela1[[#This Row],[ENTREGA]]="",Tabela1[[#This Row],[VENCIMENTO]]-TODAY( ),"") -> -1 | J5: =IF(H5>0.99,"Vencida","No Prazo") -> No Prazo
A6: BAZAR GRACELAND DISCOS LTDA | C6: FORA | D6: INATIVA | F6: ='Menu principal'!O$25 -> 43250 | G6: 43241 | H6: =DAYS360(F6,G6) -> -9 | I6: =IF(Tabela1[[#This Row],[ENTREGA]]="",Tabela1[[#This Row],[VENCIMENTO]]-TODAY( ),"") | J6: =IF(H6>0.99,"Vencida","No Prazo") -> No Prazo
A7: DEPOSITO DE DOCES SANSIL LTDA ME | C7: FORA | D7: INATIVA | F7: ='Menu principal'!O$25 -> 43250 | G7: 43242 | H7: =DAYS360(F7,G7) -> -8 | I7: =IF(Tabela1[[#This Row],[ENTREGA]]="",Tabela1[[#This Row],[VENCIMENTO]]-TODAY( ),"") | J7: =IF(H7>0.99,"Vencida","No Prazo") -> No Prazo
A8: ELS CHAVES TREINAMENTO | C8: FORA | D8: INATIVA | F8: ='Menu principal'!O$25 -> 43250 | G8: 43243 | H8: =DAYS360(F8,G8) -> -7 | I8: =IF(Tabela1[[#This Row],[ENTREGA]]="",Tabela1[[#This Row],[VENCIMENTO]]-TODAY( ),"") | J8: =IF(H8>0.99,"Vencida","No Prazo") -> No Prazo
A9: ENGECORP CONSULT ASSES E PROJ ENGEN LT | C9: LP | D9: INATIVA | F9: ='Menu principal'!O$25 -> 43250 | G9: 43251 | H9: =DAYS360(F9,G9) -> 0 | I9: =IF(Tabela1[[#This Row],[ENTREGA]]="",Tabela1[[#This Row],[VENCIMENTO]]-TODAY( ),"") -> -1 | J9: =IF(H9>0.99,"Vencida","No Prazo") -> No Prazo
A10: FERBOR COM. REPRES. | C10: FORA | D10: INATIVA | F10: ='Menu principal'!O$25 -> 43250 | G10: 43245 | H10: =DAYS360(F10,G10) -> -5 | I10: =IF(Tabela1[[#This Row],[ENTREGA]]="",Tabela1[[#This Row],[VENCIMENTO]]-TODAY( ),"") | J10: =IF(H10>0.99,"Vencida","No Prazo") -> No Prazo
A11: FERGO SOLUÇÕES | C11: FORA | D11: INATIVA | F11: ='Menu principal'!O$25 -> 43250 | G11: 43246 | H11: =DAYS360(F11,G11) -> -4 | I11: =IF(Tabela1[[#This Row],[ENTREGA]]="",Tabela1[[#This Row],[VENCIMENTO]]-TODAY( ),"") | J11: =IF(H11>0.99,"Vencida","No Prazo") -> No Prazo
A12: FERNANDA CHAVES | C12: FORA | D12: INATIVA | F12: ='Menu principal'!O$25 -> 43250 | G12: 43250 | H12: =DAYS360(F12,G12) -> 0 | I12: =IF(Tabela1[[#This Row],[ENTREGA]]="",Tabela1[[#This Row],[VENCIMENTO]]-TODAY( ),"") | J12: =IF(H12>0.99,"Vencida","No Prazo") -> No Prazo
A13: FSW PLANEJAMENTO | C13: LP | D13: ATIVA | F13: ='Menu principal'!O$25 -> 43250 | G13: 43248 | H13: =DAYS360(F13,G13) -> -2 | I13: =IF(Tabela1[[#This Row],[ENTREGA]]="",Tabela1[[#This Row],[VENCIMENTO]]-TODAY( ),"") -> -1 | J13: =IF(H13>0.99,"Vencida","No Prazo") -> No Prazo
A14: GALETO DE RAMOS LANCHONETE | C14: SN | D14: INATIVA | F14: ='Menu principal'!O$25 -> 43250 | G14: 43249 | H14: =DAYS360(F14,G14) -> -1 | I14: =IF(Tabela1[[#This Row],[ENTREGA]]="",Tabela1[[#This Row],[VENCIMENTO]]-TODAY( ),"") | J14: =IF(H14>0.99,"Vencida","No Prazo") -> No Prazo
... A36: BOCA DE VAZ LOBO LANCHES LTDA | C36: SN | D36: INATIVA | F36: ='Menu principal'!O$25 -> 43250 | G36: 43271 | H36: =DAYS360(F36,G36) -> 20 | I36: =IF(Tabela1[[#This Row],[ENTREGA]]="",Tabela1[[#This Row],[VENCIMENTO]]-TODAY( ),"") | J36: =IF(H36>0.99,"Vencida","No Prazo") -> Vencida

Sheet ECF

Sheet EFD ICMS_IPI

Sheet GIA ST

Sheet REDF

Sheet GIA

Sheet STDA

Sheet GISS

Sheet DEISS

Sheet ISS SP

Sheet ISS BARUERI

Sheet ALVARÁ

Sheet CERTIFICADO

Sheet CND FED

Sheet CND EST

Sheet CND MUN

Sheet Plan1
