Workbook

Sheet Orçamento
A2: RENDA | B2: Orçamento | C2: Atual | D2: Diferença | E2: [42] | F2: RESUMO DO ORÇAMENTO | G2: Orçamento | H2: Atual | I2: Diferença
A3: =HYPERLINK("https://blog.mobills.com.br/dicas-aumentar-salario-pouco-tempo/","Salário") -> Salário | B3: 2000 | C3: 2000 | D3: =C3-B3 -> 0 | F3: Renda Total | G3: =Orçamento!$B$11 -> 2000 | H3: =Orçamento!$C$11 -> 2000 | I3: =G3-H3 -> 0
A4: Renda de Juros | D4: =C4-B4 -> 0 | F4: Despesas Totais | G4: =SUM(,Orçamento!$B$27,Orçamento!$B$37,Orçamento!$B$47,Orçamento!$B$54,Orçamento!$B$61,Orçamento!$G$61,Orçamento!$G$54,Orçamento!$G$44,Orçamento!$G$35,Orçamento!$G$18) -> 1345 | H4: =SUM(Orçamento!$C$27,Orçamento!$C$37,Orçamento!$C$47,Orçamento!$C$54,Orçamento!$C$61,Orçamento!$H$61,Orçamento!$H$54,Orçamento!$H$44,Orçamento!$H$35,Orçamento!$H$18) -> 1486 | I4: =G4-H4 -> -141
A5: Dividendos | D5: =C5-B5 -> 0 | F5: Resultado | G5: =G3-G4 -> 655 | H5: =H3-H4 -> 514 | I5: =H5-G5 -> -141
A6: Dinheiro Inesperado | D6: =C6-B6 -> 0
A7: Reembolsos | D7: =C7-B7 -> 0
A8: Transferência de Poupança | D8: =C8-B8 -> 0 | F8: VIDA DIÁRIA | G8: Orçamento | H8: Atual | I8: Diferença
A9: =HYPERLINK("https://blog.mobills.com.br/como-fazer-uma-renda-extra/","Renda extra") -> Renda extra | D9: =C9-B9 -> 0 | F9: =HYPERLINK("https://blog.mobills.com.br/economizar-no-supermercado/","Supermercado") -> Supermercado | I9: =G9-H9 -> 0
A10: Outros | D10: =C10-B10 -> 0 | F10: Suprimentos Pessoais | I10: =G10-H10 -> 0
A11: Renda Total | B11: =SUBTOTAL(9,Orçamento!$B$3:$B$10) -> 2000 | C11: =SUBTOTAL(9,Orçamento!$C$3:$C$10) -> 2000 | D11: =SUBTOTAL(9,Orçamento!$D$3:$D$10) -> 0 | F11: Roupas | I11: =G11-H11 -> 0
F12: Produtos de Limpeza | I12: =G12-H12 -> 0
A13: DESPESAS DE MORADIA | B13: Orçamento | C13: Atual | D13: Diferença | F13: Educação | I13: =G13-H13 -> 0
A14: Aluguel/Parcelas do Imóvel | B14: 1100 | C14: 1100 | D14: =B14-C14 -> 0 | F14: Jantar/Comer Fora | I14: =G14-H14 -> 0
A15: Seguros | B15: 50 | C15: 67 | D15: =B15-C15 -> -17 | F15: Salão de Beleza | I15: =G15-H15 -> 0
A16: =HYPERLINK("https://blog.mobills.com.br/consumo-de-energia-eletrica-reduzir/","Conta de Luz") -> Conta de Luz | B16: 43 | C16: 52 | D16: =B16-C16 -> -9 | F16: PetShop | I16: =G16-H16 -> 0
A17: =HYPERLINK("https://blog.mobills.com.br/gasolina-ou-alcool/","Gasolina") -> Gasolina | B17: 7 | C17: 7 | D17: =B17-C17 -> 0 | F17: Outros | I17: =G17-H17 -> 0
A18: =HYPERLINK("https://blog.mobills.com.br/formas-de-economizar-agua/","Conta de Água") -> Conta de Água | B18: 25 | C18: 25 | D18: =B18-C18 -> 0 | F18: ="Total " & Orçamento!$F$8 -> Total VIDA DIÁRIA | G18: =SUBTOTAL(9,Orçamento!$G$9:$G$17) -> 0 | H18: =SUBTOTAL(9,Orçamento!$H$9:$H$17) -> 0 | I18: =SUBTOTAL(9,Orçamento!$I$9:$I$17) -> 0
A19: Telefone | B19: 35 | C19: 35 | D19: =B19-C19 -> 0
A20: Tv a Cabo | B20: 15 | C20: 15 | D20: =B20-C20 -> 0 | F20: ENTRETENIMENTO | G20: Orçamento | H20: Atual | I20: Diferença
A21: Internet | B21: 0 | C21: 150 | D21: =B21-C21 -> -150 | F21: =HYPERLINK("https://blog.mobills.com.br/filmes-sobre-financas/","Filmes/Cinema") -> Filmes/Cinema | I21: =G21-H21 -> 0
A22: Eletrodomésticos | B22: 0 | C22: 0 | D22: =B22-C22 -> 0 | F22: Música | I22: =G22-H22 -> 0
A23: Jardinagem | B23: 20 | C23: 15 | D23: =B23-C23 -> 5 | F23: Games | I23: =G23-H23 -> 0
A24: Manutenção | B24: 50 | C24: 20 | D24: =B24-C24 -> 30 | F24: Shows | I24: =G24-H24 -> 0
A25: Melhorias | B25: 0 | C25: 0 | D25: =B25-C25 -> 0 | F25: =HYPERLINK("https://blog.mobills.com.br/livros-que-voce-deve-ler-se-quiser-se-tornar-rico/","Livros") -> Livros | I25: =G25-H25 -> 0
A26: Outros | B26: 0 | C26: 0 | D26: =B26-C26 -> 0 | F26: Hobbies | I26: =G26-H26 -> 0
A27: ="Total " & Orçamento!$A$13 -> Total DESPESAS DE MORADIA | B27: =SUBTOTAL(9,Orçamento!$B$14:$B$26) -> 1345 | C27: =SUBTOTAL(9,Orçamento!$C$14:$C$26) -> 1486 | D27: =SUBTOTAL(9,Orçamento!$D$14:$D$26) -> -141 | F27: Fotografia | I27: =G27-H27 -> 0
F28: Esportes | I28: =G28-H28 -> 0
A29: TRANSPORTE | B29: Orçamento | C29: Atual | D29: Diferença | F29: Passeios | I29: =G29-H29 -> 0
A30: Parcelamento do Carro | D30: =B30-C30 -> 0 | F30: Brinquedos | I30: =G30-H30 -> 0
A31: =HYPERLINK("https://blog.mobills.com.br/como-pagar-menos-no-seguro-do-carro/","Seguro do Carro") -> Seguro do Carro | D31: =B31-C31 -> 0 | F31: =HYPERLINK("https://blog.mobills.com.br/viagem-de-ferias-como-se-preparar/","Férias") -> Férias | I31: =G31-H31 -> 0
A32: Combustível | D32: =B32-C32 -> 0 | F32: Viagem | I32: =G32-H32 -> 0
A33: Ônibus/Táxi | D33: =B33-C33 -> 0 | F33: Teatro | I33: =G33-H33 -> 0
A34: Reparos | D34: =B34-C34 -> 0 | F34: Outros | I34: =G34-H34 -> 0
A35: Outros | D35: =B35-C35 -> 0 | F35: ="Total " & Orçamento!$F$20 -> Total ENTRETENIMENTO | G35: =SUBTOTAL(9,Orçamento!$G$21:$G$34) -> 0 | H35: =SUBTOTAL(9,Orçamento!$H$21:$H$34) -> 0 | I35: =SUBTOTAL(9,Orçamento!$I$21:$I$34) -> 0
A36: Outros | D36: =B36-C36 -> 0
A37: ="Total " & Orçamento!$A$29 -> Total TRANSPORTE | B37: =SUBTOTAL(9,Orçamento!$B$30:$B$36) -> 0 | C37: =SUBTOTAL(9,Orçamento!$C$30:$C$36) -> 0 | D37: =SUBTOTAL(9,Orçamento!$D$30:$D$36) -> 0 | F37: ECONOMIAS | G37: Orçamento | H37: Atual | I37: Diferença
F38: =HYPERLINK("https://blog.mobills.com.br/importancia-fundo-de-emergencia/","Fundo de Emergência") -> Fundo de Emergência | I38: =G38-H38 -> 0
A39: SAÚDE | B39: Orçamento | C39: Atual | D39: Diferença | F39: Transferência de Poupança | I39: =G39-H39 -> 0
A40: Seguro de Vida | D40: =B40-C40 -> 0 | F40: =HYPERLINK("https://blog.mobills.com.br/construir-seu-plano-de-investimentos/","Investimentos") -> Investimentos | I40: =G40-H40 -> 0
A41: Consulta | D41: =B41-C41 -> 0 | F41: Educação | I41: =G41-H41 -> 0
...
