Workbook

Sheet Início
A1: ESCALA DE TRABALHO- INÍCIO

Sheet Cadastro
A1: ESCALA DE TRABALHO - CADASTRO
B3: ID | C3: NOME DO FUNCIONÁRIO | H3: CARGO | J3: SEXO | K3: IDADE | L3: TURNO DE EXCEÇÃO
L4: I | M4: II | N4: III | Q4: CARGOS
B5: 1 | O5: FEMININO | Q5: 1 | R5: VENDEDOR
B6: 2 | O6: MASCULINO | Q6: 2 | R6: AUXILIAR
B7: 3 | Q7: 3 | R7: BALCONISTA
B8: 4 | Q8: 4 | R8: CAIXA
B9: 5 | Q9: 5 | R9: ESTOQUISTA
B10: 6
B11: 7
B12: 8
B13: 9
B14: 10
B15: 11
B16: 12
B17: 13
B18: 14
B19: 15
B20: 16
B21: 17
... B24: 20

Sheet Escala
A1: ESCALA DE TRABALHO - ESCALA
B3: ESCALA SEMANAL | N3: QUANTIFICAÇÃO SEMANAL | Y3: TURNO 1
Y4: SEGUNDA | Z4: TERÇA | AA4: QUARTA | AB4: QUINTA | AC4: SEXTA | AD4: SÁBADO | AE4: DOMINGO
C5: FUNCIONÁRIO | F5: SEGUNDA | G5: TERÇA | H5: QUARTA | I5: QUINTA | J5: SEXTA | K5: SÁBADO | L5: DOMINGO | N5: FUNCIONÁRIO | Q5: PE | R5: AU | S5: DE | T5: FE | V5: STATUS | X5: PE | Y5: =COUNTIF($F$6:$F$25,"PE") -> 0 | Z5: =COUNTIF($G$6:$G$25,"PE") -> 0 | AA5: =COUNTIF($H$6:$H$25,"PE") -> 0 | AB5: =COUNTIF($I$6:$I$25,"PE") -> 0 | AC5: =COUNTIF($J$6:$J$25,"PE") -> 0 | AD5: =COUNTIF($K$6:$K$25,"PE") -> 0 | AE5: =COUNTIF($L$6:$L$25,"PE") -> 0 | AF5: =SUM(Y5:AE5) -> 0
B6: TURNO I | C6: =Cadastro!C5 -> 0 | N6: =Cadastro!C5 -> 0 | Q6: =SUM(COUNTIF(F6:L6,"PE"),COUNTIF(F26:L26,"PE"),COUNTIF(F46:L46,"PE")) -> 0 | R6: =SUM(COUNTIF(F6:L6,"AU"),COUNTIF(F26:L26,"AU"),COUNTIF(F46:L46,"AU")) -> 0 | S6: =SUM(COUNTIF(F6:L6,"DE"),COUNTIF(F26:L26,"DE"),COUNTIF(F46:L46,"DE")) -> 0 | T6: =SUM(COUNTIF(F6:L6,"FE"),COUNTIF(F26:L26,"FE"),COUNTIF(F46:L46,"FE")) -> 0 | V6: PE | W6: PRESENTE | X6: AU | Y6: =COUNTIF($F$6:$F$25,"AU") -> 0 | Z6: =COUNTIF($G$6:$G$25,"AU") -> 0 | AA6: =COUNTIF($H$6:$H$25,"AU") -> 0 | AB6: =COUNTIF($I$6:$I$25,"AU") -> 0 | AC6: =COUNTIF($J$6:$J$25,"AU") -> 0 | AD6: =COUNTIF($K$6:$K$25,"AU") -> 0 | AE6: =COUNTIF($L$6:$L$25,"AU") -> 0 | AF6: =SUM(Y6:AE6) -> 0
C7: =Cadastro!C6 -> 0 | N7: =Cadastro!C6 -> 0 | Q7: =SUM(COUNTIF(F7:L7,"PE"),COUNTIF(F27:L27,"PE"),COUNTIF(F47:L47,"PE")) -> 0 | R7: =SUM(COUNTIF(F7:L7,"AU"),COUNTIF(F27:L27,"AU"),COUNTIF(F47:L47,"AU")) -> 0 | S7: =SUM(COUNTIF(F7:L7,"DE"),COUNTIF(F27:L27,"DE"),COUNTIF(F47:L47,"DE")) -> 0 | T7: =SUM(COUNTIF(F7:L7,"FE"),COUNTIF(F27:L27,"FE"),COUNTIF(F47:L47,"FE")) -> 0 | V7: AU | W7: AUSENTE | X7: DS | Y7: =COUNTIF($F$6:$F$25,"DS") -> 0 | Z7: =COUNTIF($G$6:$G$25,"DS") -> 0 | AA7: =COUNTIF($H$6:$H$25,"DS") -> 0 | AB7: =COUNTIF($I$6:$I$25,"DS") -> 0 | AC7: =COUNTIF($J$6:$J$25,"DS") -> 0 | AD7: =COUNTIF($J$6:$J$25,"DS") -> 0 | AE7: =COUNTIF($L$6:$L$25,"DS") -> 0 | AF7: =SUM(Y7:AE7) -> 0
C8: =Cadastro!C7 -> 0 | N8: =Cadastro!C7 -> 0 | Q8: =SUM(COUNTIF(F8:L8,"PE"),COUNTIF(F28:L28,"PE"),COUNTIF(F48:L48,"PE")) -> 0 | R8: =SUM(COUNTIF(F8:L8,"AU"),COUNTIF(F28:L28,"AU"),COUNTIF(F48:L48,"AU")) -> 0 | S8: =SUM(COUNTIF(F8:L8,"DE"),COUNTIF(F28:L28,"DE"),COUNTIF(F48:L48,"DE")) -> 0 | T8: =SUM(COUNTIF(F8:L8,"FE"),COUNTIF(F28:L28,"FE"),COUNTIF(F48:L48,"FE")) -> 0 | V8: DS | W8: DESCANSO | X8: FE | Y8: =COUNTIF($F$6:$F$25,"FE") -> 0 | Z8: =COUNTIF($G$6:$G$25,"FE") -> 0 | AA8: =COUNTIF($H$6:$H$25,"FE") -> 0 | AB8: =COUNTIF($I$6:$I$25,"FE") -> 0 | AC8: =COUNTIF($J$6:$J$25,"FE") -> 0 | AD8: =COUNTIF($J$6:$J$25,"FE") -> 0 | AE8: =COUNTIF($L$6:$L$25,"FE") -> 0 | AF8: =SUM(Y8:AE8) -> 0
C9: =Cadastro!C8 -> 0 | N9: =Cadastro!C8 -> 0 | Q9: =SUM(COUNTIF(F9:L9,"PE"),COUNTIF(F29:L29,"PE"),COUNTIF(F49:L49,"PE")) -> 0 | R9: =SUM(COUNTIF(F9:L9,"AU"),COUNTIF(F29:L29,"AU"),COUNTIF(F49:L49,"AU")) -> 0 | S9: =SUM(COUNTIF(F9:L9,"DE"),COUNTIF(F29:L29,"DE"),COUNTIF(F49:L49,"DE")) -> 0 | T9: =SUM(COUNTIF(F9:L9,"FE"),COUNTIF(F29:L29,"FE"),COUNTIF(F49:L49,"FE")) -> 0 | V9: FE | W9: FÉRIAS | Y9: TURNO 2 | AF9: =SUM(Y9:AE9) -> 0
C10: =Cadastro!C9 -> 0 | N10: =Cadastro!C9 -> 0 | Q10: =SUM(COUNTIF(F10:L10,"PE"),COUNTIF(F30:L30,"PE"),COUNTIF(F50:L50,"PE")) -> 0 | R10: =SUM(COUNTIF(F10:L10,"AU"),COUNTIF(F30:L30,"AU"),COUNTIF(F50:L50,"AU")) -> 0 | S10: =SUM(COUNTIF(F10:L10,"DE"),COUNTIF(F30:L30,"DE"),COUNTIF(F50:L50,"DE")) -> 0 | T10: =SUM(COUNTIF(F10:L10,"FE"),COUNTIF(F30:L30,"FE"),COUNTIF(F50:L50,"FE")) -> 0 | Y10: SEGUNDA | Z10: TERÇA | AA10: QUARTA | AB10: QUINTA | AC10: SEXTA | AD10: SÁBADO | AE10: DOMINGO | AF10: =SUM(Y10:AE10) -> 0
C11: =Cadastro!C10 -> 0 | N11: =Cadastro!C10 -> 0 | Q11: =SUM(COUNTIF(F11:L11,"PE"),COUNTIF(F31:L31,"PE"),COUNTIF(F51:L51,"PE")) -> 0 | R11: =SUM(COUNTIF(F11:L11,"AU"),COUNTIF(F31:L31,"AU"),COUNTIF(F51:L51,"AU")) -> 0 | S11: =SUM(COUNTIF(F11:L11,"DE"),COUNTIF(F31:L31,"DE"),COUNTIF(F51:L51,"DE")) -> 0 | T11: =SUM(COUNTIF(F11:L11,"FE"),COUNTIF(F31:L31,"FE"),COUNTIF(F51:L51,"FE")) -> 0 | X11: PE | Y11: =COUNTIF($F$26:$F$45,"PE") -> 0 | Z11: =COUNTIF($G$26:$G$45,"PE") -> 0 | AA11: =COUNTIF($H$26:$H$45,"PE") -> 0 | AB11: =COUNTIF($I$26:$I$45,"PE") -> 0 | AC11: =COUNTIF($J$26:$J$45,"PE") -> 0 | AD11: =COUNTIF($K$26:$K$45,"PE") -> 0 | AE11: =COUNTIF($L$26:$L$45,"PE") -> 0 | AF11: =SUM(Y11:AE11) -> 0
C12: =Cadastro!C11 -> 0 | N12: =Cadastro!C11 -> 0 | Q12: =SUM(COUNTIF(F12:L12,"PE"),COUNTIF(F32:L32,"PE"),COUNTIF(F52:L52,"PE")) -> 0 | R12: =SUM(COUNTIF(F12:L12,"AU"),COUNTIF(F32:L32,"AU"),COUNTIF(F52:L52,"AU")) -> 0 | S12: =SUM(COUNTIF(F12:L12,"DE"),COUNTIF(F32:L32,"DE"),COUNTIF(F52:L52,"DE")) -> 0 | T12: =SUM(COUNTIF(F12:L12,"FE"),COUNTIF(F32:L32,"FE"),COUNTIF(F52:L52,"FE")) -> 0 | X12: AU | Y12: =COUNTIF($F$26:$F$45,"AU") -> 0 | Z12: =COUNTIF($G$26:$G$45,"AU") -> 0 | AA12: =COUNTIF($H$26:$H$45,"AU") -> 0 | AB12: =COUNTIF($I$26:$I$45,"AU") -> 0 | AC12: =COUNTIF($J$26:$J$45,"AU") -> 0 | AD12: =COUNTIF($K$26:$K$45,"AU") -> 0 | AE12: =COUNTIF($L$26:$L$45,"AU") -> 0 | AF12: =SUM(Y12:AE12) -> 0
C13: =Cadastro!C12 -> 0 | N13: =Cadastro!C12 -> 0 | Q13: =SUM(COUNTIF(F13:L13,"PE"),COUNTIF(F33:L33,"PE"),COUNTIF(F53:L53,"PE")) -> 0 | R13: =SUM(COUNTIF(F13:L13,"AU"),COUNTIF(F33:L33,"AU"),COUNTIF(F53:L53,"AU")) -> 0 | S13: =SUM(COUNTIF(F13:L13,"DE"),COUNTIF(F33:L33,"DE"),COUNTIF(F53:L53,"DE")) -> 0 | T13: =SUM(COUNTIF(F13:L13,"FE"),COUNTIF(F33:L33,"FE"),COUNTIF(F53:L53,"FE")) -> 0 | X13: DS | Y13: =COUNTIF($F$26:$F$45,"DS") -> 0 | Z13: =COUNTIF($G$26:$G$45,"DS") -> 0 | AA13: =COUNTIF($H$26:$H$45,"DS") -> 0 | AB13: =COUNTIF($I$26:$I$45,"DS") -> 0 | AC13: =COUNTIF($J$26:$J$45,"DS") -> 0 | AD13: =COUNTIF($K$26:$K$45,"DS") -> 0 | AE13: =COUNTIF($L$26:$L$45,"DS") -> 0 | AF13: =SUM(Y13:AE13) -> 0
C14: =Cadastro!C13 -> 0 | N14: =Cadastro!C13 -> 0 | Q14: =SUM(COUNTIF(F14:L14,"PE"),COUNTIF(F34:L34,"PE"),COUNTIF(F54:L54,"PE")) -> 0 | R14: =SUM(COUNTIF(F14:L14,"AU"),COUNTIF(F34:L34,"AU"),COUNTIF(F54:L54,"AU")) -> 0 | S14: =SUM(COUNTIF(F14:L14,"DE"),COUNTIF(F34:L34,"DE"),COUNTIF(F54:L54,"DE")) -> 0 | T14: =SUM(COUNTIF(F14:L14,"FE"),COUNTIF(F34:L34,"FE"),COUNTIF(F54:L54,"FE")) -> 0 | X14: FE | Y14: =COUNTIF($F$26:$F$45,"FE") -> 0 | Z14: =COUNTIF($G$26:$G$45,"FE") -> 0 | AA14: =COUNTIF($H$26:$H$45,"FE") -> 0 | AB14: =COUNTIF($I$26:$I$45,"FE") -> 0 | AC14: =COUNTIF($J$26:$J$45,"FE") -> 0 | AD14: =COUNTIF($K$26:$K$45,"FE") -> 0 | AE14: =COUNTIF($L$26:$L$45,"FE") -> 0 | AF14: =SUM(Y14:AE14) -> 0
C15: =Cadastro!C14 -> 0 | N15: =Cadastro!C14 -> 0 | Q15: =SUM(COUNTIF(F15:L15,"PE"),COUNTIF(F35:L35,"PE"),COUNTIF(F55:L55,"PE")) -> 0 | R15: =SUM(COUNTIF(F15:L15,"AU"),COUNTIF(F35:L35,"AU"),COUNTIF(F55:L55,"AU")) -> 0 | S15: =SUM(COUNTIF(F15:L15,"DE"),COUNTIF(F35:L35,"DE"),COUNTIF(F55:L55,"DE")) -> 0 | T15: =SUM(COUNTIF(F15:L15,"FE"),COUNTIF(F35:L35,"FE"),COUNTIF(F55:L55,"FE")) -> 0 | Y15: TURNO 3
C16: =Cadastro!C15 -> 0 | N16: =Cadastro!C15 -> 0 | Q16: =SUM(COUNTIF(F16:L16,"PE"),COUNTIF(F36:L36,"PE"),COUNTIF(F56:L56,"PE")) -> 0 | R16: =SUM(COUNTIF(F16:L16,"AU"),COUNTIF(F36:L36,"AU"),COUNTIF(F56:L56,"AU")) -> 0 | S16: =SUM(COUNTIF(F16:L16,"DE"),COUNTIF(F36:L36,"DE"),COUNTIF(F56:L56,"DE")) -> 0 | T16: =SUM(COUNTIF(F16:L16,"FE"),COUNTIF(F36:L36,"FE"),COUNTIF(F56:L56,"FE")) -> 0 | Y16: SEGUNDA | Z16: TERÇA | AA16: QUARTA | AB16: QUINTA | AC16: SEXTA | AD16: SÁBADO | AE16: DOMINGO
C17: =Cadastro!C16 -> 0 | N17: =Cadastro!C16 -> 0 | Q17: =SUM(COUNTIF(F17:L17,"PE"),COUNTIF(F37:L37,"PE"),COUNTIF(F57:L57,"PE")) -> 0 | R17: =SUM(COUNTIF(F17:L17,"AU"),COUNTIF(F37:L37,"AU"),COUNTIF(F57:L57,"AU")) -> 0 | S17: =SUM(COUNTIF(F17:L17,"DE"),COUNTIF(F37:L37,"DE"),COUNTIF(F57:L57,"DE")) -> 0 | T17: =SUM(COUNTIF(F17:L17,"FE"),COUNTIF(F37:L37,"FE"),COUNTIF(F57:L57,"FE")) -> 0 | X17: PE | Y17: =COUNTIF($F$46:$F$65,"PE") -> 0 | Z17: =COUNTIF($G$46:$G$65,"PE") -> 0 | AA17: =COUNTIF($H$46:$H$65,"PE") -> 0 | AB17: =COUNTIF($I$46:$I$65,"PE") -> 0 | AC17: =COUNTIF($I$46:$I$65,"PE") -> 0 | AD17: =COUNTIF($K$46:$K$65,"PE") -> 0 | AE17: =COUNTIF($L$46:$L$65,"PE") -> 0 | AF17: =SUM(Y17:AE17) -> 0
C18: =Cadastro!C17 -> 0 | N18: =Cadastro!C17 -> 0 | Q18: =SUM(COUNTIF(F18:L18,"PE"),COUNTIF(F38:L38,"PE"),COUNTIF(F58:L58,"PE")) -> 0 | R18: =SUM(COUNTIF(F18:L18,"AU"),COUNTIF(F38:L38,"AU"),COUNTIF(F58:L58,"AU")) -> 0 | S18: =SUM(COUNTIF(F18:L18,"DE"),COUNTIF(F38:L38,"DE"),COUNTIF(F58:L58,"DE")) -> 0 | T18: =SUM(COUNTIF(F18:L18,"FE"),COUNTIF(F38:L38,"FE"),COUNTIF(F58:L58,"FE")) -> 0 | X18: AU | Y18: =COUNTIF($F$46:$F$65,"AU") -> 0 | Z18: =COUNTIF($G$46:$G$65,"AU") -> 0 | AA18: =COUNTIF($H$46:$H$65,"AU") -> 0 | AB18: =COUNTIF($I$46:$I$65,"AU") -> 0 | AC18: =COUNTIF($I$46:$I$65,"AU") -> 0 | AD18: =COUNTIF($K$46:$K$65,"AU") -> 0 | AE18: =COUNTIF($L$46:$L$65,"AU") -> 0 | AF18: =SUM(Y18:AE18) -> 0
C19: =Cadastro!C18 -> 0 | N19: =Cadastro!C18 -> 0 | Q19: =SUM(COUNTIF(F19:L19,"PE"),COUNTIF(F39:L39,"PE"),COUNTIF(F59:L59,"PE")) -> 0 | R19: =SUM(COUNTIF(F19:L19,"AU"),COUNTIF(F39:L39,"AU"),COUNTIF(F59:L59,"AU")) -> 0 | S19: =SUM(COUNTIF(F19:L19,"DE"),COUNTIF(F39:L39,"DE"),COUNTIF(F59:L59,"DE")) -> 0 | T19: =SUM(COUNTIF(F19:L19,"FE"),COUNTIF(F39:L39,"FE"),COUNTIF(F59:L59,"FE")) -> 0 | X19: DS | Y19: =COUNTIF($F$46:$F$65,"DS") -> 0 | Z19: =COUNTIF($G$46:$G$65,"DS") -> 0 | AA19: =COUNTIF($H$46:$H$65,"DS") -> 0 | AB19: =COUNTIF($I$46:$I$65,"DS") -> 0 | AC19: =COUNTIF($I$46:$I$65,"DS") -> 0 | AD19: =COUNTIF($K$46:$K$65,"DS") -> 0 | AE19: =COUNTIF($L$46:$L$65,"DS") -> 0 | AF19: =SUM(Y19:AE19) -> 0
C20: =Cadastro!C19 -> 0 | N20: =Cadastro!C19 -> 0 | Q20: =SUM(COUNTIF(F20:L20,"PE"),COUNTIF(F40:L40,"PE"),COUNTIF(F60:L60,"PE")) -> 0 | R20: =SUM(COUNTIF(F20:L20,"AU"),COUNTIF(F40:L40,"AU"),COUNTIF(F60:L60,"AU")) -> 0 | S20: =SUM(COUNTIF(F20:L20,"DE"),COUNTIF(F40:L40,"DE"),COUNTIF(F60:L60,"DE")) -> 0 | T20: =SUM(COUNTIF(F20:L20,"FE"),COUNTIF(F40:L40,"FE"),COUNTIF(F60:L60,"FE")) -> 0 | X20: FE | Y20: =COUNTIF($F$46:$F$65,"FE") -> 0 | Z20: =COUNTIF($G$46:$G$65,"FE") -> 0 | AA20: =COUNTIF($H$46:$H$65,"FE") -> 0 | AB20: =COUNTIF($I$46:$I$65,"FE") -> 0 | AC20: =COUNTIF($I$46:$I$65,"FE") -> 0 | AD20: =COUNTIF($K$46:$K$65,"FE") -> 0 | AE20: =COUNTIF($L$46:$L$65,"FE") -> 0 | AF20: =SUM(Y20:AE20) -> 0
C21: =Cadastro!C20 -> 0 | N21: =Cadastro!C20 -> 0 | Q21: =SUM(COUNTIF(F21:L21,"PE"),COUNTIF(F41:L41,"PE"),COUNTIF(F61:L61,"PE")) -> 0 | R21: =SUM(COUNTIF(F21:L21,"AU"),COUNTIF(F41:L41,"AU"),COUNTIF(F61:L61,"AU")) -> 0 | S21: =SUM(COUNTIF(F21:L21,"DE"),COUNTIF(F41:L41,"DE"),COUNTIF(F61:L61,"DE")) -> 0 | T21: =SUM(COUNTIF(F21:L21,"FE"),COUNTIF(F41:L41,"FE"),COUNTIF(F61:L61,"FE")) -> 0 | Y21: SEGUNDA | Z21: TERÇA | AA21: QUARTA | AB21: QUINTA | AC21: SEXTA | AD21: SÁBADO | AE21: DOMINGO
C22: =Cadastro!C21 -> 0 | N22: =Cadastro!C21 -> 0 | Q22: =SUM(COUNTIF(F22:L22,"PE"),COUNTIF(F42:L42,"PE"),COUNTIF(F62:L62,"PE")) -> 0 | R22: =SUM(COUNTIF(F22:L22,"AU"),COUNTIF(F42:L42,"AU"),COUNTIF(F62:L62,"AU")) -> 0 | S22: =SUM(COUNTIF(F22:L22,"DE"),COUNTIF(F42:L42,"DE"),COUNTIF(F62:L62,"DE")) -> 0 | T22: =SUM(COUNTIF(F22:L22,"FE"),COUNTIF(F42:L42,"FE"),COUNTIF(F62:L62,"FE")) -> 0 | X22: PE | Y22: =Y5+Y11+Y17 -> 0 | Z22: =Z5+Z11+Z17 -> 0 | AA22: =AA5+AA11+AA17 -> 0 | AB22: =AB5+AB11+AB17 -> 0 | AC22: =AC5+AC11+AC17 -> 0 | AD22: =AD5+AD11+AD17 -> 0 | AE22: =AE5+AE11+AE17 -> 0 | AF22: =SUM(Y22:AE22) -> 0
C23: =Cadastro!C22 -> 0 | N23: =Cadastro!C22 -> 0 | Q23: =SUM(COUNTIF(F23:L23,"PE"),COUNTIF(F43:L43,"PE"),COUNTIF(F63:L63,"PE")) -> 0 | R23: =SUM(COUNTIF(F23:L23,"AU"),COUNTIF(F43:L43,"AU"),COUNTIF(F63:L63,"AU")) -> 0 | S23: =SUM(COUNTIF(F23:L23,"DE"),COUNTIF(F43:L43,"DE"),COUNTIF(F63:L63,"DE")) -> 0 | T23: =SUM(COUNTIF(F23:L23,"FE"),COUNTIF(F43:L43,"FE"),COUNTIF(F63:L63,"FE")) -> 0 | X23: AU | Y23: =Y6+Y12+Y18 -> 0 | Z23: =Z6+Z12+Z18 -> 0 | AA23: =AA6+AA12+AA18 -> 0 | AB23: =AB6+AB12+AB18 -> 0 | AC23: =AC6+AC12+AC18 -> 0 | AD23: =AD6+AD12+AD18 -> 0 | AE23: =AE6+AE12+AE18 -> 0 | AF23: =SUM(Y23:AE23) -> 0
C24: =Cadastro!C23 -> 0 | N24: =Cadastro!C23 -> 0 | Q24: =SUM(COUNTIF(F24:L24,"PE"),COUNTIF(F44:L44,"PE"),COUNTIF(F64:L64,"PE")) -> 0 | R24: =SUM(COUNTIF(F24:L24,"AU"),COUNTIF(F44:L44,"AU"),COUNTIF(F64:L64,"AU")) -> 0 | S24: =SUM(COUNTIF(F24:L24,"DE"),COUNTIF(F44:L44,"DE"),COUNTIF(F64:L64,"DE")) -> 0 | T24: =SUM(COUNTIF(F24:L24,"FE"),COUNTIF(F44:L44,"FE"),COUNTIF(F64:L64,"FE")) -> 0 | X24: DS | Y24: =Y7+Y13+Y19 -> 0 | Z24: =Z7+Z13+Z19 -> 0 | AA24: =AA7+AA13+AA19 -> 0 | AB24: =AB7+AB13+AB19 -> 0 | AC24: =AC7+AC13+AC19 -> 0 | AD24: =AD7+AD13+AD19 -> 0 | AE24: =AE7+AE13+AE19 -> 0 | AF24: =SUM(Y24:AE24) -> 0
C25: =Cadastro!C24 -> 0 | N25: =Cadastro!C24 -> 0 | Q25: =SUM(COUNTIF(F25:L25,"PE"),COUNTIF(F45:L45,"PE"),COUNTIF(F65:L65,"PE")) -> 0 | R25: =SUM(COUNTIF(F25:L25,"AU"),COUNTIF(F45:L45,"AU"),COUNTIF(F65:L65,"AU")) -> 0 | S25: =SUM(COUNTIF(F25:L25,"DE"),COUNTIF(F45:L45,"DE"),COUNTIF(F65:L65,"DE")) -> 0 | T25: =SUM(COUNTIF(F25:L25,"FE"),COUNTIF(F45:L45,"FE"),COUNTIF(F65:L65,"FE")) -> 0 | X25: FE | Y25: =Y8+Y14+Y20 -> 0 | Z25: =Z8+Z14+Z20 -> 0 | AA25: =AA8+AA14+AA20 -> 0 | AB25: =AB8+AB14+AB20 -> 0 | AC25: =AC8+AC14+AC20 -> 0 | AD25: =AD8+AD14+AD20 -> 0 | AE25: =AE8+AE14+AE20 -> 0 | AF25: =SUM(Y25:AE25) -> 0
B26: TURNO II | C26: =Cadastro!C5 -> 0
C27: =Cadastro!C6 -> 0 | Y27: PE | Z27: AU | AA27: DS | AB27: FE
C28: =Cadastro!C7 -> 0 | Y28: =AF11+AF17+AF22 -> 0 | Z28: =AF12+AF18+AF23 -> 0 | AA28: =AF13+AF19+AF24 -> 0 | AB28: =AF14+AF20+AF25 -> 0
C29: =Cadastro!C8 -> 0
C30: =Cadastro!C9 -> 0
C31: =Cadastro!C10 -> 0
C32: =Cadastro!C11 -> 0
C33: =Cadastro!C12 -> 0
C34: =Cadastro!C13 -> 0
C35: =Cadastro!C14 -> 0
C36: =Cadastro!C15 -> 0
C37: =Cadastro!C16 -> 0
C38: =Cadastro!C17 -> 0
C39: =Cadastro!C18 -> 0
C40: =Cadastro!C19 -> 0
... C45: =Cadastro!C24 -> 0
...

Sheet Panorama Semanal
A1: ESCALA DE TRABALHO - PANORAMA
