Workbook

Sheet FICHA FUNCIONAL
K1: FAAP - MÓDULO 1 - R3.1
C2: FICHA FUNCIONAL
B4: 1 | C4: MODALIDADE DE APOSENTADORIA: | E4: PREENCHA COM A MODALIDADE
B6: 2 | C6: REGRA DE OPÇÃO: | E6: PREENCHA A REGRA DESEJADA
E7: 0
B8: 3 | C8: FUNDAMENTAÇÃO A CONSTAR NO ATO: | E8: =$E$42 -> REVER FUNDAMENTAÇÃO E/OU MODALIDADE
B10: 4 | C10: ENTE DA FEDERAÇÃO: | E10: ESTADO DO RIO DE JANEIRO
B11: 5 | C11: PODER: | E11: EXECUTIVO
B12: 6 | C12: ÓRGÃO/ ENTIDADE:
C14: HISTÓRICO FUNCIONAL
B16: 7 | C16: NOME DO SERVIDOR:
B17: 8 | C17: MATRÍCULA: | M17: DESDE
B18: 9 | C18: CARGO:
B19: 10 | C19: CARREIRA:
B20: 11 | C20: ADMISSÃO:
B21: 12 | C21: NASCIMENTO: | I21: IDADE | M21: =CRÍTICA_IGP1!N11 -> 0
B22: 13 | C22: C.P.F.: | I22: =IF(M21>=70,CRÍTICA_IGP1!R20,IF(M21>=60,CONCATENATE("O SERVIDOR ATINGIRÁ A COMPULSÓRIA EM ",CRÍTICA_IGP1!Q20," DIAS, "," OU SEJA, EM "),""))
B23: 14 | C23: VALIDADE DA APOSENTADORIA: | M23: =IF($M$21>=70,CRÍTICA_IGP1!$R$22,IF($M$21>=60,CRÍTICA_IGP1!$R$22,0)) -> 0
B25: 15 | C25: SEXO: | E25: MASCULINO | K25: FEMININO
B27: 16 | C27: EFETIVO EXERCÍCIO DE FUNÇÕES DE MAGISTÉRIO | E27: SIM | K27: NÃO
B29: 17 | C29: REDAÇÃO DADA PELA: | E29: E.C. nº 20/98 | K29: E.C. nº 41/03 | M29: x
E31: ANOS | G31: DIAS | I31: CRÍTICAS
B32: 18 | C32: TEMPO NO CARGO: | E32: =CRÍTICA_IGP1!M13 -> 0 | G32: =CRÍTICA_IGP1!N13 -> 0 | I32: =CRÍTICA_IGP1!N68 -> NÃO CABE
B33: 19 | C33: TEMPO NA CARREIRA: | E33: =CRÍTICA_IGP1!M14 -> 0 | G33: =CRÍTICA_IGP1!N14 -> 0 | I33: =CRÍTICA_IGP1!N69 -> NÃO CABE
B34: 20 | C34: TEMPO NO SERV. PÚBLICO: | E34: =CRÍTICA_IGP1!M15 -> 0 | G34: =CRÍTICA_IGP1!N15 -> 0
B36: 20 | C36: VALIDADE DA REGRA: | E36: =CRÍTICA_IGP1!N10 -> -
B38: 21 | C38: CONCLUSÃO:
C39: =CRÍTICA_IGP1!B68 -> ADMISSÃO : | E39: =CRÍTICA_IGP1!C68 -> FALTA DATA
E40: =CRÍTICA_IGP1!C69 -> 0
C41: =CRÍTICA_IGP1!B70 -> IDADE : | E41: =CRÍTICA_IGP1!E70 -> FALSE
C42: FUNDAMENTAÇÃO: | E42: =IF(AND($E$6=$M$48,$E$20<=$K$51,OR($E$4=$F$52,$E$4=$F$53)),CRÍTICA_IGP1!$BO$17,CRÍTICA_IGP1!$D$73) -> REVER FUNDAMENTAÇÃO E/OU MODALIDADE
C43: PREVISÃO PARA APOSENTADORIA NA MODALIDADE E REGRA ESCOLHIDAS: | K43: =IF(OR($E$6=$M$50,$E$6=$M$51,$E$6=$M$52,AND($E$6=$M$48,$M$29="X")),CRÍTICA_IGP1!$AB$97,IF(AND($E$6=$M$47,CRÍTICA_IGP1!$AB$97<CRÍTICA_IGP1!$Q$11),CRÍTICA_IGP1!AB97,IF(AND($E$6=$M$49,CRÍTICA_IGP1!$AB$97<CRÍTICA_IGP1!$Q$13),CRÍTICA_IGP1!$AB$97,IF(AND($E$6=$M$48,$I$29="X",CRÍTICA_IGP1!$AB$97<CRÍTICA_IGP1!$Q$12),CRÍTICA_IGP1!$AB$97,"REVER")))) -> #VALUE!
C44: TRIBUNAL DE CONTAS DO ESTADO DO RIO DE JANEIRO - SUP
C45: Virgílio de Oliveira Souza (Técnica / Lógica) | F45: Luiz Cláudio Lopes de Sá - (Revisão / Lay out)
C46: LISTA JURISDICIONADOS - SUP | F46: MODALIDADES | H46: NÃO MEXER | K46: PODERES | M46: LISTA DE FUNDAMENTAÇÕES
B47: 1 | C47: ANGRA DOS REIS | F47: VOLUNTÁRIA INTEGRAL | K47: EXECUTIVO | M47: REGRAS ANTES EC20
B48: 1.1 | C48: ANGRA DOS REIS - MAGISTÉRIO | F48: VOLUNTÁRIA ESPECIAL | K48: LEGISLATIVO | M48: REGRA PERMANENTE
B49: 2 | C49: APERIBÉ | F49: VOLUNTÁRIA PROPORCIONAL POR IDADE | K49: JUDICIÁRIO | M49: TRANSIÇÃO EMENDA 20
B50: 3 | C50: ARARUAMA | F50: COMPULSÓRIA INTEGRAL | M50: TRANSIÇÃO_ART. 2º_EC41
B51: 4 | C51: AREAL | F51: COMPULSÓRIA PROPORCIONAL | K51: 37986 | M51: TRANSIÇÃO_ART. 6º_EC41
...

Sheet MTS - MAPA DE TEMPO DE SERVIÇO
L2: ='FICHA FUNCIONAL'!K1 -> FAAP - MÓDULO 1 - R3.1
C3: APURAÇÃO DO TEMPO DE SERVIÇO/CONTRIBUIÇÃO
B5: 1 | C5: SITUAÇÃO ANTES DA E.C. nº 20/98
B7: 2 | C7: DISCRIMINAÇÃO | D7: PERÍODO | H7: total | I7: =IF('FICHA FUNCIONAL'!E16>0,"NOME:","") | J7: =IF('FICHA FUNCIONAL'!$E$16>0,'FICHA FUNCIONAL'!$E$16,"") | N7: A T S
D8: início | G8: término | H8: DIAS | I8: =IF('FICHA FUNCIONAL'!E17>0,"MATRÍCULA:","") | J8: =IF('FICHA FUNCIONAL'!$E$17>0,'FICHA FUNCIONAL'!$E$17,"") | N8: TRIÊNIO
B9: 3 | C9: INSS | E9: a | I9: =IF(H9>0,"COMUNICAR AO INSS TEMPO AVERBADO.","")
B10: 4 | C10: OUTROS PODERES - INSS | E10: a | I10: =IF(H10>0,"COMUNICAR AO RPPS DO ENTE TEMPO AVERBADO.","")
C11: OUTROS PODERES | E11: a | H11: =CRÍTICA_IGP1!F28 -> 0 | I11: =IF(H11>0,"COMUNICAR AO RPPS DO ENTE TEMPO AVERBADO.","")
B12: 5 | C12: FORÇAS ARMADAS | E12: a | I12: =IF(H12>0,"COMPROVAR CERTIDÃO E/OU CERTIFICADO DE RESERVISTA.","")
B13: 6 | C13: ÓRGÃO DE ORIGEM | E13: a
C14: ÓRGÃO DE ORIGEM | E14: a | H14: =CRÍTICA_IGP1!F31 -> 0 | I14: orientações
C15: ÓRGÃO DE ORIGEM | D15: =IF('FICHA FUNCIONAL'!E20<CRÍTICA_IGP1!Q11,'FICHA FUNCIONAL'!E20,0) -> 0 | E15: a | G15: =IF(AND(CRÍTICA_IGP1!R22<CRÍTICA_IGP1!Q11,CRÍTICA_IGP1!R22<'FICHA FUNCIONAL'!E23),CRÍTICA_IGP1!R22-1,IF(D15=0,0,IF('FICHA FUNCIONAL'!E23<CRÍTICA_IGP1!Q11,'FICHA FUNCIONAL'!E23-1,CRÍTICA_IGP1!Q11-1))) -> 0 | H15: =IF(AND(D15<>0,G15<>0),(G15-D15+1),0) -> 0 | I15: A data máxima nessa situação é 15/12/98 (Antes da / EC nº 20/98)
B16: 7 | C16: LICENÇA ESPECIAL | D16: nº de períodos | H16: =CRÍTICA_IGP1!F33 -> 0 | I16: =CRÍTICA_IGP1!G33 -> Licença especial não gozada e computada em dobro.
B17: 8 | C17: FÉRIAS EM DOBRO | D17: nº anos | H17: =CRÍTICA_IGP1!F34 -> 0 | I17: =CRÍTICA_IGP1!G34 -> Férias não gozadas e computadas em dobro.
B18: 9 | C18: BÔNUS ESPECIAL | H18: =CRÍTICA_IGP1!F35 -> 0 | I18: =CRÍTICA_IGP1!G35 -> Acréscimo constitucional para professores (EC 20/98 e EC 41/03).
B19: 10 | C19: FALTAS | I19: Aponte as faltas ocorridas antes de 15/12/98 (Antes EC nº 20/98).
B20: 11 | C20: LICENÇA SEM VENCIMENTO | I20: Aponte licenças sem vencimentos anteriores a 15/12/98 (Antes EC nº 20/98).
B22: 12 | C22: SUBTOTAL | D22: PERÍODO | H22: total | J22: TEMPO CONVERTIDO
D23: início | G23: término | H23: DIAS | J23: =CRÍTICA_IGP1!K37 -> 0 | K23: anos | M23: =CRÍTICA_IGP1!M37 -> 0 | N23: dias
C24: (antes da EC nº 20/98) | D24: =CRÍTICA_IGP1!C37 -> 0 | E24: a | G24: =CRÍTICA_IGP1!E37 -> 0 | H24: =CRÍTICA_IGP1!F37 -> 0
B26: 13 | C26: CONCLUSÃO (caso seja necessária complementação)
C28: =CRÍTICA_IGP1!H42 -> NÃO HÁ PEDÁGIO A CUMPRIR | F28: DIAS | J28: TEMPO CONVERTIDO
B29: 14 | C29: TEMPO FALTANTE: | F29: =CRÍTICA_IGP1!E42 -> 0 | J29: =IF(F29>0,ROUNDDOWN(F29/365,0),0) -> 0 | K29: anos | M29: =(F29/365-J29)*365 -> 0 | N29: dias
B30: 15 | C30: PEDÁGIO: | F30: =CRÍTICA_IGP1!E43 -> 0 | J30: =IF(F30>0,ROUNDDOWN(F30/365,0),0) -> 0 | K30: anos | M30: =(F30/365-J30)*365 -> 0 | N30: dias
B31: 16 | C31: TEMPO A COMPLEMENTAR: | F31: =CRÍTICA_IGP1!E44 -> 0 | J31: =IF(F31>0,ROUNDDOWN(F31/365,0),0) -> 0 | K31: anos | M31: =(F31/365-J31)*365 -> 0 | N31: dias
B33: 17 | C33: SITUAÇÃO ENTRE A E.C. nº 20/98 A E.C. nº 41/03
C35: DISCRIMINAÇÃO | D35: PERÍODO | H35: total | J35: =IF($H$42>0,"DURANTE O PERÍODO DE LICENÇA SEM VENCIMENTOS, HOUVE CONTRIBUIÇÃO PARA O RPPS?","") | N35: NÃO CABE
D36: início | G36: término | H36: DIAS
C37: INSS | E37: a | I37: =IF(H37<>0,"INSS: DESCONSIDERE OS PERÍODOS CONCOMITANTES. COMUNIQUE AO RGPS","")
C38: OUTROS PODERES - INSS | E38: a | H38: =CRÍTICA_IGP1!F48 -> 0 | I38: =IF(H38>0,"COMUNICAR AO RPPS DO ENTE TEMPO AVERBADO.","")
C39: ÓRGÃO DE ORIGEM | E39: a | H39: =CRÍTICA_IGP1!F49 -> 0 | I39: orientações
C40: ÓRGÃO DE ORIGEM | D40: =IF('FICHA FUNCIONAL'!E20=0,0,IF('FICHA FUNCIONAL'!E20<CRÍTICA_IGP1!Q11,CRÍTICA_IGP1!Q11,IF(AND('FICHA FUNCIONAL'!E20>=CRÍTICA_IGP1!Q11,'FICHA FUNCIONAL'!E20<CRÍTICA_IGP1!Q12),'FICHA FUNCIONAL'!E20,0))) -> 0 | E40: a | G40: =IF('FICHA FUNCIONAL'!E6='FICHA FUNCIONAL'!M47,0,IF(AND('FICHA FUNCIONAL'!E23<CRÍTICA_IGP1!R22,'FICHA FUNCIONAL'!E23<CRÍTICA_IGP1!Q12),'FICHA FUNCIONAL'!E23-1,I44)) -> -1 | H40: =IF(AND(D40<>0,I45<>0,I44>=CRÍTICA_IGP1!Q11),IF(G40>=D40,(G40-D40+1-CRÍTICA_IGP1!N50),0),0) -> 0 | I40: =IF(CRÍTICA_IGP1!K2="TRANSIÇÃO EMENDA 20","A data máxima nessa situação é 30/12/2003 (Antes da Emenda nº 41/03).","A data máxima nessa situação é 19/02/2004 (Antes da MP nº 167/04).") -> A data máxima nessa situação é 19/02/2004 (Antes da MP nº 167/04).
C41: FALTAS | I41: Aponte as faltas ocorridas entre 16/12/98 e 19/02/2004(antes MP 167/04).
C42: LICENÇA SEM VENCIMENTO | I42: Aponte licenças sem vencimentos entre 16/12/98 e 19/02/04 (Antes MP 167/04).
C44: SUBTOTAL | D44: PERÍODO | H44: total | I44: =IF(CRÍTICA_IGP1!R22<CRÍTICA_IGP1!Q11,0,IF(AND(CRÍTICA_IGP1!R22<'FICHA FUNCIONAL'!E23,CRÍTICA_IGP1!R22<CRÍTICA_IGP1!Q12),IF(AND('FICHA FUNCIONAL'!E6='FICHA FUNCIONAL'!M49,CRÍTICA_IGP1!R22>CRÍTICA_IGP1!Q13),CRÍTICA_IGP1!Q13-1,IF(AND('FICHA FUNCIONAL'!E6='FICHA FUNCIONAL'!M48,'FICHA FUNCIONAL'!I29="X",CRÍTICA_IGP1!R22>CRÍTICA_IGP1!Q12),I45,IF(AND(CRÍTICA_IGP1!R22>=CRÍTICA_IGP1!Q11,CRÍTICA_IGP1!R22<CRÍTICA_IGP1!Q13),CRÍTICA_IGP1!R22-1,IF(AND(CRÍTICA_IGP1!R22>=CRÍTICA_IGP1!Q13,CRÍTICA_IGP1!R22<CRÍTICA_IGP1!Q12),CRÍTICA_IGP1!R22-1,I45)))),I45)) -> 0
D45: início | G45: término | H45: DIAS | I45: =IF('FICHA FUNCIONAL'!E6='FICHA FUNCIONAL'!M47,0,IF('FICHA FUNCIONAL'!E6='FICHA FUNCIONAL'!M49,IF(AND('FICHA FUNCIONAL'!E23>=CRÍTICA_IGP1!Q11,'FICHA FUNCIONAL'!E23<CRÍTICA_IGP1!Q13),'FICHA FUNCIONAL'!E23-1,CRÍTICA_IGP1!Q13-1),IF(AND('FICHA FUNCIONAL'!E6='FICHA FUNCIONAL'!M48,'FICHA FUNCIONAL'!I29="X"),IF(AND('FICHA FUNCIONAL'!E23>=CRÍTICA_IGP1!Q11,'FICHA FUNCIONAL'!E23<CRÍTICA_IGP1!Q12),'FICHA FUNCIONAL'!E23-1,CRÍTICA_IGP1!Q12-1),IF('FICHA FUNCIONAL'!E23>=CRÍTICA_IGP1!Q12,CRÍTICA_IGP1!Q12-1,IF(CRÍTICA_IGP1!R22<CRÍTICA_IGP1!N10,CRÍTICA_IGP1!R22-1,CRÍTICA_IGP1!N10-1))))) -> 25567 | J45: TEMPO CONVERTIDO
B46: 18 | C46: (entre a EC nº 20 e a EC nº 41) | D46: =CRÍTICA_IGP1!C45 -> 0 | E46: a | G46: =IF('FICHA FUNCIONAL'!E36<36145,G24,IF('FICHA FUNCIONAL'!E36<38037,IF(I45<I44,I45,I44),I44)) -> 0 | H46: =IF(CRÍTICA_IGP1!F46<>0,CRÍTICA_IGP1!F46,'MTS - MAPA DE TEMPO DE SERVIÇO'!H24) -> 0 | J46: =IF(H46>0,ROUNDDOWN(H46/365,0),0) -> 0 | K46: anos | M46: =(H46/365-J46)*365 -> 0 | N46: dias
B47: 19 | C47: (desde o início) | D47: =IF(D24<>0,D24,D46) -> 0 | E47: a | G47: =G46 -> 0 | H47: =CRÍTICA_IGP1!F52 -> 0 | J47: =IF(H47>0,ROUNDDOWN(H47/365,0),0) -> 0 | K47: anos | M47: =(H47/365-J47)*365 -> 0 | N47: dias
B49: 20 | C49: SITUAÇÃO APÓS A E.C. nº 41/03
C51: DISCRIMINAÇÃO | D51: PERÍODO | H51: total | J51: =IF($H$58>0,"DURANTE O PERÍODO DE LICENÇA SEM VENCIMENTOS, HOUVE CONTRIBUIÇÃO PARA O RPPS?","") | N51: NÃO CABE
...

Sheet RESUMO CONCLUSIVO
L2: ='MTS - MAPA DE TEMPO DE SERVIÇO'!L2 -> FAAP - MÓDULO 1 - R3.1
B3: 1 | C3: RESUMO CONCLUSIVO
C5: =IF('FICHA FUNCIONAL'!E16>0,"NOME:","") | D5: =IF('FICHA FUNCIONAL'!E16>0,'FICHA FUNCIONAL'!E16,"") | I5: =IF('FICHA FUNCIONAL'!E17>0,"MATRÍCULA:","") | J5: =IF('FICHA FUNCIONAL'!E17>0,'FICHA FUNCIONAL'!E17,"")
B7: 2 | C7: CONDIÇÕES DE APOSENTADORIA
B9: 3 | C9: MODALIDADE DE APOSENTADORIA ESCOLHIDA: | H9: =CRÍTICA_IGP1!$E$2 -> PREENCHA COM A MODALIDADE
B10: 4 | C10: REGRA DE OPÇÃO DE APOSENTADORIA ESCOLHIDA: | H10: =CRÍTICA_IGP1!$K$2 -> PREENCHA A REGRA DESEJADA
B11: 5 | C11: FUNDAMENTAÇÃO LEGAL A SER UTILIZADA NO ATO DE APOSENTADORIA: | H11: ='FICHA FUNCIONAL'!$E$8 -> REVER FUNDAMENTAÇÃO E/OU MODALIDADE
B14: 6 | C14: TEMPO DE CONTRIBUIÇÃO/SERVIÇO TOTAL APURADO: | G14: PERÍODO | J14: TOTAL
G15: início | I15: término | J15: DIAS | L15: TEMPO CONVERTIDO
G16: ='MTS - MAPA DE TEMPO DE SERVIÇO'!$D$68 -> REVER | H16: a | I16: ='MTS - MAPA DE TEMPO DE SERVIÇO'!$G$68 -> 0 | J16: ='MTS - MAPA DE TEMPO DE SERVIÇO'!$H$68 -> 0 | L16: =CRÍTICA_IGP1!$H$61 -> 0 | M16: anos | N16: =CRÍTICA_IGP1!$J$61 -> 0 | O16: dias
B18: 7 | C18: TEMPO DE CONTRIBUIÇÃO/SERVIÇO FALTANTE: | G18: TOTAL
G19: DIAS | L19: TEMPO CONVERTIDO
G20: =CRÍTICA_IGP1!$F$71 -> NADA A CUMPRIR | L20: =IF(CRÍTICA_IGP1!$Y$97>0,CRÍTICA_IGP1!$Y$97,0) -> 0 | M20: anos | N20: =IF(CRÍTICA_IGP1!$Z$97>0,CRÍTICA_IGP1!$Z$97,0) -> 0 | O20: dias
F22: CONDIÇÃO | L22: TEMPO FALTANTE
B23: 8 | C23: TEMPO NO CARGO: | F23: =CRÍTICA_IGP1!$N$68 -> NÃO CABE | L23: =IF(CRÍTICA_IGP1!$K$2=CRÍTICA_IGP1!$P$86,CRÍTICA_IGP1!$W$86,IF(CRÍTICA_IGP1!$K$2=CRÍTICA_IGP1!$P$87,CRÍTICA_IGP1!$W$87,IF(CRÍTICA_IGP1!$K$2=CRÍTICA_IGP1!$P$88,CRÍTICA_IGP1!$W$88,IF(CRÍTICA_IGP1!$K$2=CRÍTICA_IGP1!$P$89,CRÍTICA_IGP1!$W$89,IF(CRÍTICA_IGP1!$K$2=CRÍTICA_IGP1!$P$90,CRÍTICA_IGP1!$W$90,IF(CRÍTICA_IGP1!$K$2=CRÍTICA_IGP1!$P$91,CRÍTICA_IGP1!$W$91,0)))))) -> 0 | M23: anos | N23: =IF(CRÍTICA_IGP1!$K$2=CRÍTICA_IGP1!$P$86,CRÍTICA_IGP1!$AB$86,IF(CRÍTICA_IGP1!$K$2=CRÍTICA_IGP1!$P$87,CRÍTICA_IGP1!$AB$87,IF(CRÍTICA_IGP1!$K$2=CRÍTICA_IGP1!$P$88,CRÍTICA_IGP1!$AB$88,IF(CRÍTICA_IGP1!$K$2=CRÍTICA_IGP1!$P$89,CRÍTICA_IGP1!$AB$89,IF(CRÍTICA_IGP1!$K$2=CRÍTICA_IGP1!$P$90,CRÍTICA_IGP1!$AB$90,IF(CRÍTICA_IGP1!$K$2=CRÍTICA_IGP1!$P$91,CRÍTICA_IGP1!$AB$91,0)))))) -> 0 | O23: dias
B24: 9 | C24: TEMPO NA CARREIRA: | F24: =CRÍTICA_IGP1!$N$69 -> NÃO CABE | L24: =IF(CRÍTICA_IGP1!$K$2=CRÍTICA_IGP1!$P$86,CRÍTICA_IGP1!$X$86,IF(CRÍTICA_IGP1!$K$2=CRÍTICA_IGP1!$P$87,CRÍTICA_IGP1!$X$87,IF(CRÍTICA_IGP1!$K$2=CRÍTICA_IGP1!$P$88,CRÍTICA_IGP1!$X$88,IF(CRÍTICA_IGP1!$K$2=CRÍTICA_IGP1!$P$89,CRÍTICA_IGP1!$X$89,IF(CRÍTICA_IGP1!$K$2=CRÍTICA_IGP1!$P$90,CRÍTICA_IGP1!$X$90,IF(CRÍTICA_IGP1!$K$2=CRÍTICA_IGP1!$P$91,CRÍTICA_IGP1!$X$91,0)))))) -> 0 | M24: anos | N24: =IF(CRÍTICA_IGP1!$K$2=CRÍTICA_IGP1!$P$86,CRÍTICA_IGP1!$AC$86,IF(CRÍTICA_IGP1!$K$2=CRÍTICA_IGP1!$P$87,CRÍTICA_IGP1!$AC$87,IF(CRÍTICA_IGP1!$K$2=CRÍTICA_IGP1!$P$88,CRÍTICA_IGP1!$AC$88,IF(CRÍTICA_IGP1!$K$2=CRÍTICA_IGP1!$P$89,CRÍTICA_IGP1!$AC$89,IF(CRÍTICA_IGP1!$K$2=CRÍTICA_IGP1!$P$90,CRÍTICA_IGP1!$AC$90,IF(CRÍTICA_IGP1!$K$2=CRÍTICA_IGP1!$P$91,CRÍTICA_IGP1!$AC$91,0)))))) -> 0 | O24: dias
B25: 10 | C25: TEMPO NO SERVIÇO PÚBLICO: | F25: =CRÍTICA_IGP1!$N$70 -> OK | L25: =IF(CRÍTICA_IGP1!$K$2=CRÍTICA_IGP1!$P$86,CRÍTICA_IGP1!$Y$86,IF(CRÍTICA_IGP1!$K$2=CRÍTICA_IGP1!$P$87,CRÍTICA_IGP1!$Y$87,IF(CRÍTICA_IGP1!$K$2=CRÍTICA_IGP1!$P$88,CRÍTICA_IGP1!$Y$88,IF(CRÍTICA_IGP1!$K$2=CRÍTICA_IGP1!$P$89,CRÍTICA_IGP1!$Y$89,IF(CRÍTICA_IGP1!$K$2=CRÍTICA_IGP1!$P$90,CRÍTICA_IGP1!$Y$90,IF(CRÍTICA_IGP1!$K$2=CRÍTICA_IGP1!$P$91,CRÍTICA_IGP1!$Y$91,0)))))) -> 0 | M25: anos | N25: =IF(CRÍTICA_IGP1!$K$2=CRÍTICA_IGP1!$P$86,CRÍTICA_IGP1!$AD$86,IF(CRÍTICA_IGP1!$K$2=CRÍTICA_IGP1!$P$87,CRÍTICA_IGP1!$AD$87,IF(CRÍTICA_IGP1!$K$2=CRÍTICA_IGP1!$P$88,CRÍTICA_IGP1!$AD$88,IF(CRÍTICA_IGP1!$K$2=CRÍTICA_IGP1!$P$89,CRÍTICA_IGP1!$AD$89,IF(CRÍTICA_IGP1!$K$2=CRÍTICA_IGP1!$P$90,CRÍTICA_IGP1!$AD$90,IF(CRÍTICA_IGP1!$K$2=CRÍTICA_IGP1!$P$91,CRÍTICA_IGP1!$AD$91,0)))))) -> 0 | O25: dias
B26: 11 | C26: IDADE MÍNIMA: | F26: =CRÍTICA_IGP1!$E$70 -> FALSE | L26: =IF(CRÍTICA_IGP1!$K$2=CRÍTICA_IGP1!$P$86,CRÍTICA_IGP1!$Z$86,IF(CRÍTICA_IGP1!$K$2=CRÍTICA_IGP1!$P$87,CRÍTICA_IGP1!$Z$87,IF(CRÍTICA_IGP1!$K$2=CRÍTICA_IGP1!$P$88,CRÍTICA_IGP1!$Z$88,IF(CRÍTICA_IGP1!$K$2=CRÍTICA_IGP1!$P$89,CRÍTICA_IGP1!$Z$89,IF(CRÍTICA_IGP1!$K$2=CRÍTICA_IGP1!$P$90,CRÍTICA_IGP1!$Z$90,IF(CRÍTICA_IGP1!$K$2=CRÍTICA_IGP1!$P$91,CRÍTICA_IGP1!$Z$91,0)))))) -> 0 | M26: anos | N26: =IF(CRÍTICA_IGP1!$K$2=CRÍTICA_IGP1!$P$86,CRÍTICA_IGP1!$AE$86,IF(CRÍTICA_IGP1!$K$2=CRÍTICA_IGP1!$P$87,CRÍTICA_IGP1!$AE$87,IF(CRÍTICA_IGP1!$K$2=CRÍTICA_IGP1!$P$88,CRÍTICA_IGP1!$AE$88,IF(CRÍTICA_IGP1!$K$2=CRÍTICA_IGP1!$P$89,CRÍTICA_IGP1!$AE$89,IF(CRÍTICA_IGP1!$K$2=CRÍTICA_IGP1!$P$90,CRÍTICA_IGP1!$AE$90,IF(CRÍTICA_IGP1!$K$2=CRÍTICA_IGP1!$P$91,CRÍTICA_IGP1!$AE$91,0)))))) -> 0 | O26: dias
B28: 12 | C28: CONDIÇÕES PARA FIXAÇÃO DOS PROVENTOS
B30: 13 | C30: PROVENTOS
B31: 14 | C31: INTEGRAL | E31: parcela única (média): | H31: =IF(OR('FICHA FUNCIONAL'!$E$4='FICHA FUNCIONAL'!$F$47,'FICHA FUNCIONAL'!$E$4='FICHA FUNCIONAL'!$F$48,'FICHA FUNCIONAL'!$E$4='FICHA FUNCIONAL'!$F$50),IF(AND('FICHA FUNCIONAL'!$E$6='FICHA FUNCIONAL'!$M$48,'FICHA FUNCIONAL'!$M$29="X"),"SIM","NÃO"),'FICHA FUNCIONAL'!$M$55) -> REVER
E32: em parcelas distintas: | H32: =IF(AND('FICHA FUNCIONAL'!E6='FICHA FUNCIONAL'!M48,'FICHA FUNCIONAL'!I29="X",OR('FICHA FUNCIONAL'!E4='FICHA FUNCIONAL'!F47,'FICHA FUNCIONAL'!E4='FICHA FUNCIONAL'!F48,'FICHA FUNCIONAL'!E4='FICHA FUNCIONAL'!F50)),"SIM",IF(AND('FICHA FUNCIONAL'!E6='FICHA FUNCIONAL'!M49,OR('FICHA FUNCIONAL'!E4='FICHA FUNCIONAL'!F47,'FICHA FUNCIONAL'!E4='FICHA FUNCIONAL'!F48)),"SIM",IF(AND('FICHA FUNCIONAL'!E6='FICHA FUNCIONAL'!M47,OR('FICHA FUNCIONAL'!E4='FICHA FUNCIONAL'!F47,'FICHA FUNCIONAL'!E4='FICHA FUNCIONAL'!F48,'FICHA FUNCIONAL'!E4='FICHA FUNCIONAL'!F50)),"SIM",IF(AND('FICHA FUNCIONAL'!E6='FICHA FUNCIONAL'!M51,OR('FICHA FUNCIONAL'!E4='FICHA FUNCIONAL'!F47,'FICHA FUNCIONAL'!E4='FICHA FUNCIONAL'!F48)),"SIM",IF(AND('FICHA FUNCIONAL'!E6='FICHA FUNCIONAL'!M52,'FICHA FUNCIONAL'!E4='FICHA FUNCIONAL'!F47),"SIM",'FICHA FUNCIONAL'!M54))))) -> REVER
E33: paridade: | H33: =IF(AND($H$31="NÃO",$H$32="SIM"),"SIM","NÃO") -> NÃO | K33: FRAÇÃO | M33: PORCENTAGEM
B35: 15 | C35: PROPORCIONAL | E35: parcela única (média): | H35: =IF(AND('FICHA FUNCIONAL'!E6='FICHA FUNCIONAL'!M48,'FICHA FUNCIONAL'!M29="X"),IF(OR('FICHA FUNCIONAL'!E4='FICHA FUNCIONAL'!F49,'FICHA FUNCIONAL'!E4='FICHA FUNCIONAL'!F51),"SIM",'FICHA FUNCIONAL'!M57),IF(AND('FICHA FUNCIONAL'!E6='FICHA FUNCIONAL'!M50,'FICHA FUNCIONAL'!E4='FICHA FUNCIONAL'!F55),"SIM","NÃO")) -> NÃO | K35: =IF(AND('FICHA FUNCIONAL'!$E$6='FICHA FUNCIONAL'!$M$48,'FICHA FUNCIONAL'!$M$29="X",OR('FICHA FUNCIONAL'!$E$4='FICHA FUNCIONAL'!$F$49,'FICHA FUNCIONAL'!$E$4='FICHA FUNCIONAL'!$F$51,'FICHA FUNCIONAL'!$E$4='FICHA FUNCIONAL'!$F$53)),CRÍTICA_IGP1!$N$77,"") | M35: =IF(AND('FICHA FUNCIONAL'!$E$6='FICHA FUNCIONAL'!$M$48,'FICHA FUNCIONAL'!$M$29="X",OR('FICHA FUNCIONAL'!$E$4='FICHA FUNCIONAL'!$F$49,'FICHA FUNCIONAL'!$E$4='FICHA FUNCIONAL'!$F$51,'FICHA FUNCIONAL'!$E$4='FICHA FUNCIONAL'!$F$53)),CRÍTICA_IGP1!$N$78,"")
E36: em parcelas distintas: | H36: =IF(AND('FICHA FUNCIONAL'!E6='FICHA FUNCIONAL'!M48,'FICHA FUNCIONAL'!I29="X",OR('FICHA FUNCIONAL'!E4='FICHA FUNCIONAL'!F49,'FICHA FUNCIONAL'!E4='FICHA FUNCIONAL'!F51)),"SIM",IF(AND('FICHA FUNCIONAL'!E6='FICHA FUNCIONAL'!M47,OR('FICHA FUNCIONAL'!E4='FICHA FUNCIONAL'!F49,'FICHA FUNCIONAL'!E4='FICHA FUNCIONAL'!F51,'FICHA FUNCIONAL'!E4='FICHA FUNCIONAL'!F54)),"SIM",IF(AND('FICHA FUNCIONAL'!E6='FICHA FUNCIONAL'!M49,'FICHA FUNCIONAL'!E4='FICHA FUNCIONAL'!F54),"SIM",'FICHA FUNCIONAL'!M56))) -> REVER | K36: =IF('FICHA FUNCIONAL'!$E$6='FICHA FUNCIONAL'!$M$47,CRÍTICA_IGP1!$N$75,IF(AND('FICHA FUNCIONAL'!$E$6='FICHA FUNCIONAL'!$M$49,'FICHA FUNCIONAL'!$E$4='FICHA FUNCIONAL'!$F$54),CRÍTICA_IGP1!$N$75,IF(AND('FICHA FUNCIONAL'!$E$6='FICHA FUNCIONAL'!$M$50,'FICHA FUNCIONAL'!$E$4='FICHA FUNCIONAL'!$F$55),CRÍTICA_IGP1!$N$75,IF(AND('FICHA FUNCIONAL'!E6='FICHA FUNCIONAL'!M48,'FICHA FUNCIONAL'!I29="X"),CRÍTICA_IGP1!$N$75,"")))) | M36: =IF('FICHA FUNCIONAL'!$E$6='FICHA FUNCIONAL'!$M$47,CRÍTICA_IGP1!$N$76,IF(AND('FICHA FUNCIONAL'!$E$6='FICHA FUNCIONAL'!$M$49,'FICHA FUNCIONAL'!$E$4='FICHA FUNCIONAL'!$F$54),CRÍTICA_IGP1!$N$76,IF(AND('FICHA FUNCIONAL'!$E$6='FICHA FUNCIONAL'!$M$50,'FICHA FUNCIONAL'!$E$4='FICHA FUNCIONAL'!$F$55),CRÍTICA_IGP1!$N$76,IF(AND('FICHA FUNCIONAL'!E6='FICHA FUNCIONAL'!M48,'FICHA FUNCIONAL'!I29="X"),CRÍTICA_IGP1!$N$76,""))))
E37: paridade: | H37: =IF(AND($H$35="NÃO",$H$36="SIM"),"SIM","NÃO") -> NÃO
B39: 16 | C39: ALTERNATIVAS DE APOSENTADORIA
B41: 17 | C41: OPÇÃO | D41: MODALIDADE DE APOSENTADORIA | G41: REGRA DE OPÇÃO | J41: TEMPO | L41: IDADE | N41: PARIDADE
C42: =IF('FICHA FUNCIONAL'!$E$8<>"REVER FUNDAMENTAÇÃO E/OU MODALIDADE",IF(AND('FICHA FUNCIONAL'!$E$4='RESUMO CONCLUSIVO'!D42,'FICHA FUNCIONAL'!$E$6='RESUMO CONCLUSIVO'!G42),"X",""),"") | D42: =CRÍTICA_IGP1!$B$77 -> 0 | G42: =CRÍTICA_IGP1!$C$77 -> 0 | J42: =CRÍTICA_IGP1!$F$77 -> 0 | L42: =CRÍTICA_IGP1!$I$77 -> #N/A | N42: =CRÍTICA_IGP1!$J$77 -> #N/A
C43: =IF('FICHA FUNCIONAL'!$E$8<>"REVER FUNDAMENTAÇÃO E/OU MODALIDADE",IF(AND('FICHA FUNCIONAL'!$E$4='RESUMO CONCLUSIVO'!D43,'FICHA FUNCIONAL'!$E$6='RESUMO CONCLUSIVO'!G43),"X",""),"") | D43: =CRÍTICA_IGP1!$B$78 -> 0 | G43: =CRÍTICA_IGP1!$C$78 -> 0 | J43: =CRÍTICA_IGP1!$F$78 -> 0 | L43: =CRÍTICA_IGP1!$I$78 -> #N/A | N43: =CRÍTICA_IGP1!$J$78 -> #N/A
C44: =IF('FICHA FUNCIONAL'!$E$8<>"REVER FUNDAMENTAÇÃO E/OU MODALIDADE",IF(AND('FICHA FUNCIONAL'!$E$4='RESUMO CONCLUSIVO'!D44,'FICHA FUNCIONAL'!$E$6='RESUMO CONCLUSIVO'!G44),"X",""),"") | D44: =CRÍTICA_IGP1!$B$79 -> 0 | G44: =CRÍTICA_IGP1!$C$79 -> 0 | J44: =CRÍTICA_IGP1!$F$79 -> 0 | L44: =CRÍTICA_IGP1!$I$79 -> #N/A | N44: =CRÍTICA_IGP1!$J$79 -> #N/A
C45: =IF('FICHA FUNCIONAL'!$E$8<>"REVER FUNDAMENTAÇÃO E/OU MODALIDADE",IF(AND('FICHA FUNCIONAL'!$E$4='RESUMO CONCLUSIVO'!D45,'FICHA FUNCIONAL'!$E$6='RESUMO CONCLUSIVO'!G45,'FICHA FUNCIONAL'!$I$29="X"),"X",""),"") | D45: =CRÍTICA_IGP1!$B$80 -> 0 | G45: =CRÍTICA_IGP1!$C$80 -> 0 | J45: =CRÍTICA_IGP1!$F$80 -> 0 | L45: =CRÍTICA_IGP1!$I$80 -> #N/A | N45: =CRÍTICA_IGP1!$J$80 -> #N/A
C46: =IF('FICHA FUNCIONAL'!$E$8<>"REVER FUNDAMENTAÇÃO E/OU MODALIDADE",IF(AND('FICHA FUNCIONAL'!$E$4='RESUMO CONCLUSIVO'!D46,'FICHA FUNCIONAL'!$E$6='RESUMO CONCLUSIVO'!G46),"X",""),"") | D46: =CRÍTICA_IGP1!$B$81 -> 0 | G46: =CRÍTICA_IGP1!$C$81 -> 0 | J46: =CRÍTICA_IGP1!$F$81 -> 0 | L46: =CRÍTICA_IGP1!$I$81 -> #N/A | N46: =CRÍTICA_IGP1!$J$81 -> #N/A
C47: =IF('FICHA FUNCIONAL'!$E$8<>"REVER FUNDAMENTAÇÃO E/OU MODALIDADE",IF(AND('FICHA FUNCIONAL'!$E$4='RESUMO CONCLUSIVO'!D47,'FICHA FUNCIONAL'!$E$6='RESUMO CONCLUSIVO'!G47),"X",""),"") | D47: =CRÍTICA_IGP1!$B$82 -> 0 | G47: =CRÍTICA_IGP1!$C$82 -> 0 | J47: =CRÍTICA_IGP1!$F$82 -> 0 | L47: =CRÍTICA_IGP1!$I$82 -> #N/A | N47: =CRÍTICA_IGP1!$J$82 -> #N/A
C48: =IF('FICHA FUNCIONAL'!$E$8<>"REVER FUNDAMENTAÇÃO E/OU MODALIDADE",IF(AND('FICHA FUNCIONAL'!$E$4='RESUMO CONCLUSIVO'!D48,'FICHA FUNCIONAL'!$E$6='RESUMO CONCLUSIVO'!G48),"X",""),"") | D48: =CRÍTICA_IGP1!$B$83 -> 0 | G48: =CRÍTICA_IGP1!$C$83 -> 0 | J48: =CRÍTICA_IGP1!$F$83 -> 0 | L48: =CRÍTICA_IGP1!$I$83 -> #N/A | N48: =CRÍTICA_IGP1!$J$83 -> #N/A
C49: =IF('FICHA FUNCIONAL'!$E$8<>"REVER FUNDAMENTAÇÃO E/OU MODALIDADE",IF(AND('FICHA FUNCIONAL'!$E$4='RESUMO CONCLUSIVO'!D49,'FICHA FUNCIONAL'!$E$6='RESUMO CONCLUSIVO'!G49),"X",""),"") | D49: =CRÍTICA_IGP1!$B$84 -> 0 | G49: =CRÍTICA_IGP1!$C$84 -> 0 | J49: =CRÍTICA_IGP1!$F$84 -> 0 | L49: =CRÍTICA_IGP1!$I$84 -> #N/A | N49: =CRÍTICA_IGP1!$J$84 -> #N/A
C50: =IF('FICHA FUNCIONAL'!$E$8<>"REVER FUNDAMENTAÇÃO E/OU MODALIDADE",IF(AND('FICHA FUNCIONAL'!$E$4='RESUMO CONCLUSIVO'!D50,'FICHA FUNCIONAL'!$E$6='RESUMO CONCLUSIVO'!G50,'FICHA FUNCIONAL'!$I$29="X"),"X",""),"") | D50: =CRÍTICA_IGP1!$B$85 -> 0 | G50: =CRÍTICA_IGP1!$C$85 -> 0 | J50: =CRÍTICA_IGP1!$F$85 -> 0 | L50: =CRÍTICA_IGP1!$I$85 -> #N/A | N50: =CRÍTICA_IGP1!$J$85 -> #N/A
C51: =IF('FICHA FUNCIONAL'!$E$8<>"REVER FUNDAMENTAÇÃO E/OU MODALIDADE",IF(AND('FICHA FUNCIONAL'!$E$4='RESUMO CONCLUSIVO'!D51,'FICHA FUNCIONAL'!$E$6='RESUMO CONCLUSIVO'!G51,'FICHA FUNCIONAL'!$M$29="X"),"X",""),"") | D51: =CRÍTICA_IGP1!$B$86 -> 0 | G51: =CRÍTICA_IGP1!$C$86 -> 0 | J51: =CRÍTICA_IGP1!$F$86 -> 0 | L51: =CRÍTICA_IGP1!$I$86 -> #N/A | N51: =CRÍTICA_IGP1!$J$86 -> #N/A
C52: =IF('FICHA FUNCIONAL'!$E$8<>"REVER FUNDAMENTAÇÃO E/OU MODALIDADE",IF(AND('FICHA FUNCIONAL'!$E$4='RESUMO CONCLUSIVO'!D52,'FICHA FUNCIONAL'!$E$6='RESUMO CONCLUSIVO'!G52,'FICHA FUNCIONAL'!$M$29="X"),"X",""),"") | D52: =CRÍTICA_IGP1!$B$87 -> 0 | G52: =CRÍTICA_IGP1!$C$87 -> 0 | J52: =CRÍTICA_IGP1!$F$87 -> 0 | L52: =CRÍTICA_IGP1!$I$87 -> #N/A | N52: =CRÍTICA_IGP1!$J$87 -> #N/A
C53: =IF('FICHA FUNCIONAL'!$E$8<>"REVER FUNDAMENTAÇÃO E/OU MODALIDADE",IF(AND('FICHA FUNCIONAL'!$E$4='RESUMO CONCLUSIVO'!D53,'FICHA FUNCIONAL'!$E$6='RESUMO CONCLUSIVO'!G53),"X",""),"") | D53: =CRÍTICA_IGP1!$B$88 -> 0 | G53: =CRÍTICA_IGP1!$C$88 -> 0 | J53: =CRÍTICA_IGP1!$F$88 -> 0 | L53: =CRÍTICA_IGP1!$I$88 -> #N/A | N53: =CRÍTICA_IGP1!$J$88 -> #N/A
...

Sheet CENÁRIOS DE CONCESSÃO
L2: ='MTS - MAPA DE TEMPO DE SERVIÇO'!L2 -> FAAP - MÓDULO 1 - R3.1
B3: 1 | C3: CENÁRIOS DE CONCESSÃO
D5: =IF('FICHA FUNCIONAL'!E16>0,"NOME:","") | E5: =IF('FICHA FUNCIONAL'!E16>0,'FICHA FUNCIONAL'!E16,"") | J5: =IF('FICHA FUNCIONAL'!E17>0,"MATRÍCULA:","") | L5: =IF('FICHA FUNCIONAL'!E17>0,'FICHA FUNCIONAL'!E17,"")
B7: 2 | C7: CONDIÇÕES DE APOSENTADORIA
B9: 3 | C9: REGRA DE OPÇÃO | F9: MODALIDADE | H9: CONCLUSÃO | M9: VARIÁVEL | N9: TEMPO FALTANTE | O9: DATA PREVISTA
B10: 4 | C10: TRANSIÇÃO EMENDA 47/05 | F10: VOL. INTEGRAL | H10: =IF(OR(CRÍTICA_IGP1!Q173="O SERVIDOR NÃO FAZ JUS A ESSA REGRA E/OU MODALIDADE",CRÍTICA_IGP1!Q173="MARQUE O SEXO"),CRÍTICA_IGP1!Q173,IF(OR(CRÍTICA_IGP1!Q173>0,CRÍTICA_IGP1!R173>0,CRÍTICA_IGP1!S173>0,CRÍTICA_IGP1!T173>0,CRÍTICA_IGP1!U173>0),"REGRA NÃO CUMPRIDA","REGRA CUMPRIDA")) -> O SERVIDOR NÃO FAZ JUS A ESSA REGRA E/OU MODALIDADE | M10: =IF(AND(H10<>"O SERVIDOR NÃO FAZ JUS A ESSA REGRA E/OU MODALIDADE",H10<>"MARQUE O SEXO",H10<>"REGRA CUMPRIDA"),R10,"") | N10: =IF(CRÍTICA_IGP1!$AH$166<CRÍTICA_IGP1!$AH$173,"",IF(M10="","",HLOOKUP(M10,CRÍTICA_IGP1!$P$157:$U$173,17,FALSE))) -> #VALUE! | O10: =IF(CRÍTICA_IGP1!$AH$166<CRÍTICA_IGP1!$AH$173,"LIMITADA À COMPULSÓRIA",IF(N10="","",CRÍTICA_IGP1!$AH$173)) -> #VALUE! | R10: =IF(AND(CRÍTICA_IGP1!$Q$173>CRÍTICA_IGP1!$R$173,CRÍTICA_IGP1!$Q$173>CRÍTICA_IGP1!$S$173,CRÍTICA_IGP1!$Q$173>CRÍTICA_IGP1!$T$173,CRÍTICA_IGP1!$Q$173>CRÍTICA_IGP1!$U$173),"T. CONTRIBUIÇÃO",IF(AND(CRÍTICA_IGP1!$R$173>CRÍTICA_IGP1!$Q$173,CRÍTICA_IGP1!$R$173>CRÍTICA_IGP1!$S$173,CRÍTICA_IGP1!$R$173>CRÍTICA_IGP1!$T$173,CRÍTICA_IGP1!$R$173>CRÍTICA_IGP1!$U$173),"T. CARGO",IF(AND(CRÍTICA_IGP1!$S$173>CRÍTICA_IGP1!$Q$173,CRÍTICA_IGP1!$S$173>CRÍTICA_IGP1!$R$173,CRÍTICA_IGP1!$S$173>CRÍTICA_IGP1!$T$173,CRÍTICA_IGP1!$S$173>CRÍTICA_IGP1!$U$173),"T. CARREIRA",IF(AND(CRÍTICA_IGP1!$T$173>CRÍTICA_IGP1!$Q$173,CRÍTICA_IGP1!$T$173>CRÍTICA_IGP1!$R$173,CRÍTICA_IGP1!$T$173>CRÍTICA_IGP1!$S$173,CRÍTICA_IGP1!$T$173>CRÍTICA_IGP1!$U$173),"T. SERV. PÚBL.",IF(AND(CRÍTICA_IGP1!$U$173>CRÍTICA_IGP1!$Q$173,CRÍTICA_IGP1!$U$173>CRÍTICA_IGP1!$R$173,CRÍTICA_IGP1!$U$173>CRÍTICA_IGP1!$S$173,CRÍTICA_IGP1!$U$173>CRÍTICA_IGP1!$T$173),"IDADE",""))))) -> #VALUE!
B11: 5 | C11: TRANS. ART. 6º EMENDA 41/03 | F11: VOL. INTEGRAL | H11: =IF(OR(CRÍTICA_IGP1!Q171="O SERVIDOR NÃO FAZ JUS A ESSA REGRA E/OU MODALIDADE",CRÍTICA_IGP1!Q171="MARQUE O SEXO"),CRÍTICA_IGP1!Q171,IF(OR(CRÍTICA_IGP1!Q171>0,CRÍTICA_IGP1!R171>0,CRÍTICA_IGP1!S171>0,CRÍTICA_IGP1!T171>0,CRÍTICA_IGP1!U171>0),"REGRA NÃO CUMPRIDA","REGRA CUMPRIDA")) -> O SERVIDOR NÃO FAZ JUS A ESSA REGRA E/OU MODALIDADE | M11: =IF(AND(H11<>"O SERVIDOR NÃO FAZ JUS A ESSA REGRA E/OU MODALIDADE",H11<>"MARQUE O SEXO",H11<>"REGRA CUMPRIDA"),R11,"") | N11: =IF(CRÍTICA_IGP1!$AH$166<CRÍTICA_IGP1!$AH$171,"",IF(M11="","",HLOOKUP(M11,CRÍTICA_IGP1!$P$157:$U$173,15,FALSE))) | O11: =IF(CRÍTICA_IGP1!$AH$166<CRÍTICA_IGP1!$AH$171,"LIMITADA À COMPULSÓRIA",IF(N11="","",CRÍTICA_IGP1!$AH$171)) | R11: =IF(AND(CRÍTICA_IGP1!$Q$171>CRÍTICA_IGP1!$R$171,CRÍTICA_IGP1!$Q$171>CRÍTICA_IGP1!$S$171,CRÍTICA_IGP1!$Q$171>CRÍTICA_IGP1!$T$171,CRÍTICA_IGP1!$Q$171>CRÍTICA_IGP1!$U$171),"T. CONTRIBUIÇÃO",IF(AND(CRÍTICA_IGP1!$R$171>CRÍTICA_IGP1!$Q$171,CRÍTICA_IGP1!$R$171>CRÍTICA_IGP1!$S$171,CRÍTICA_IGP1!$R$171>CRÍTICA_IGP1!$T$171,CRÍTICA_IGP1!$R$171>CRÍTICA_IGP1!$U$171),"T. CARGO",IF(AND(CRÍTICA_IGP1!$S$171>CRÍTICA_IGP1!$Q$171,CRÍTICA_IGP1!$S$171>CRÍTICA_IGP1!$R$171,CRÍTICA_IGP1!$S$171>CRÍTICA_IGP1!$T$171,CRÍTICA_IGP1!$S$171>CRÍTICA_IGP1!$U$171),"T. CARREIRA",IF(AND(CRÍTICA_IGP1!$T$171>CRÍTICA_IGP1!$Q$171,CRÍTICA_IGP1!$T$171>CRÍTICA_IGP1!$R$171,CRÍTICA_IGP1!$T$171>CRÍTICA_IGP1!$S$171,CRÍTICA_IGP1!$T$171>CRÍTICA_IGP1!$U$171),"T. SERV. PÚBL.",IF(AND(CRÍTICA_IGP1!$U$171>CRÍTICA_IGP1!$Q$171,CRÍTICA_IGP1!$U$171>CRÍTICA_IGP1!$R$171,CRÍTICA_IGP1!$U$171>CRÍTICA_IGP1!$S$171,CRÍTICA_IGP1!$U$171>CRÍTICA_IGP1!$T$171),"IDADE",""))))) -> T. CONTRIBUIÇÃO
B12: 6 | C12: TRANS. ART. 6º EMENDA 41/03 | F12: VOL. ESPECIAL | H12: =IF(OR(CRÍTICA_IGP1!Q172="O SERVIDOR NÃO FAZ JUS A ESSA REGRA E/OU MODALIDADE",CRÍTICA_IGP1!Q172="MARQUE O SEXO",CRÍTICA_IGP1!Q172="CONFIRME MAGISTÉRIO"),CRÍTICA_IGP1!Q172,IF(OR(CRÍTICA_IGP1!Q172>0,CRÍTICA_IGP1!R172>0,CRÍTICA_IGP1!S172>0,CRÍTICA_IGP1!T172>0,CRÍTICA_IGP1!U172>0),"REGRA NÃO CUMPRIDA","REGRA CUMPRIDA")) -> O SERVIDOR NÃO FAZ JUS A ESSA REGRA E/OU MODALIDADE | M12: =IF(AND(H12<>"O SERVIDOR NÃO FAZ JUS A ESSA REGRA E/OU MODALIDADE",H12<>"MARQUE O SEXO",H12<>"REGRA CUMPRIDA",H12<>"CONFIRME MAGISTÉRIO"),R12,"") | N12: =IF(CRÍTICA_IGP1!$AH$166<CRÍTICA_IGP1!$AH$172,"",IF(M12="","",HLOOKUP(M12,CRÍTICA_IGP1!$P$157:$U$173,16,FALSE))) | O12: =IF(CRÍTICA_IGP1!$AH$166<CRÍTICA_IGP1!$AH$172,"LIMITADA À COMPULSÓRIA",IF(N12="","",CRÍTICA_IGP1!$AH$172)) | R12: =IF(AND(CRÍTICA_IGP1!$Q$172>CRÍTICA_IGP1!$R$172,CRÍTICA_IGP1!$Q$172>CRÍTICA_IGP1!$S$172,CRÍTICA_IGP1!$Q$172>CRÍTICA_IGP1!$T$172,CRÍTICA_IGP1!$Q$172>CRÍTICA_IGP1!$U$172),"T. CONTRIBUIÇÃO",IF(AND(CRÍTICA_IGP1!$R$172>CRÍTICA_IGP1!$Q$172,CRÍTICA_IGP1!$R$172>CRÍTICA_IGP1!$S$172,CRÍTICA_IGP1!$R$172>CRÍTICA_IGP1!$T$172,CRÍTICA_IGP1!$R$172>CRÍTICA_IGP1!$U$172),"T. CARGO",IF(AND(CRÍTICA_IGP1!$S$172>CRÍTICA_IGP1!$Q$172,CRÍTICA_IGP1!$S$172>CRÍTICA_IGP1!$R$172,CRÍTICA_IGP1!$S$172>CRÍTICA_IGP1!$T$172,CRÍTICA_IGP1!$S$172>CRÍTICA_IGP1!$U$172),"T. CARREIRA",IF(AND(CRÍTICA_IGP1!$T$172>CRÍTICA_IGP1!$Q$172,CRÍTICA_IGP1!$T$172>CRÍTICA_IGP1!$R$172,CRÍTICA_IGP1!$T$172>CRÍTICA_IGP1!$S$172,CRÍTICA_IGP1!$T$172>CRÍTICA_IGP1!$U$172),"T. SERV. PÚBL.",IF(AND(CRÍTICA_IGP1!$U$172>CRÍTICA_IGP1!$Q$172,CRÍTICA_IGP1!$U$172>CRÍTICA_IGP1!$R$172,CRÍTICA_IGP1!$U$172>CRÍTICA_IGP1!$S$172,CRÍTICA_IGP1!$U$172>CRÍTICA_IGP1!$T$172),"IDADE",""))))) -> T. CONTRIBUIÇÃO
B13: 7 | C13: TRANSIÇÃO EMENDA 20/98 | F13: VOL. INTEGRAL | H13: =IF(CRÍTICA_IGP1!AH167>=37986,"A PARTIR DE 31/12/2003 ESSA REGRA NÃO SE APLICA AO SERVIDOR",U13) -> REGRA NÃO CUMPRIDA | M13: =IF(AND(H13<>"A PARTIR DE 31/12/2003 ESSA REGRA NÃO SE APLICA AO SERVIDOR",H13<>"REGRA CUMPRIDA"),R13,"") -> IDADE | N13: =IF(M13="","",IF(CRÍTICA_IGP1!$AH$166<CRÍTICA_IGP1!$AH$167,"",HLOOKUP(M13,CRÍTICA_IGP1!$P$157:$U$173,11,FALSE))) -> MARQUE O SEXO | O13: =IF(H13="a partir de 31/12/2003 essa regra não se aplica ao servidor","",IF(N13="","",CRÍTICA_IGP1!AH167)) -> 15330 | R13: =IF('CENÁRIOS DE CONCESSÃO'!U13<>"O SERVIDOR NÃO FAZ JUS A ESSA REGRA E/OU MODALIDADE",IF(AND(CRÍTICA_IGP1!Q167>CRÍTICA_IGP1!R167,CRÍTICA_IGP1!Q167>=CRÍTICA_IGP1!T167,CRÍTICA_IGP1!Q167>=CRÍTICA_IGP1!U167),CRÍTICA_IGP1!$Q$157,IF(AND(CRÍTICA_IGP1!R167>CRÍTICA_IGP1!Q167,CRÍTICA_IGP1!R167>=CRÍTICA_IGP1!T167,CRÍTICA_IGP1!R167>=CRÍTICA_IGP1!U167),CRÍTICA_IGP1!$R$157,IF(AND(CRÍTICA_IGP1!T167>CRÍTICA_IGP1!Q167,CRÍTICA_IGP1!T167>CRÍTICA_IGP1!R167,CRÍTICA_IGP1!T167>=CRÍTICA_IGP1!U167),CRÍTICA_IGP1!$T$157,IF(AND(CRÍTICA_IGP1!U167>CRÍTICA_IGP1!Q167,CRÍTICA_IGP1!T167>CRÍTICA_IGP1!R167,CRÍTICA_IGP1!U167>CRÍTICA_IGP1!T167),CRÍTICA_IGP1!$U$157,"")))),"") -> IDADE | U13: =IF(OR(CRÍTICA_IGP1!Q167="A PARTIR DE 31/12/2003 ESSA REGRA NÃO SE APLICA AO SERVIDOR",CRÍTICA_IGP1!AH167>=37986),"A PARTIR DE 31/12/2003 ESSA REGRA NÃO SE APLICA AO SERVIDOR",IF(OR(CRÍTICA_IGP1!Q167>0,CRÍTICA_IGP1!R167>0,CRÍTICA_IGP1!T167>0,CRÍTICA_IGP1!U167>0,VI_TRANS_EC20!N82="NÃO"),"REGRA NÃO CUMPRIDA","REGRA CUMPRIDA")) -> REGRA NÃO CUMPRIDA
B14: 8 | C14: TRANSIÇÃO EMENDA 20/98 | F14: VOL. ESPECIAL | H14: =IF(CRÍTICA_IGP1!AH168>=37986,"A PARTIR DE 31/12/2003 ESSA REGRA NÃO SE APLICA AO SERVIDOR",U14) -> CONFIRME MAGISTÉRIO | M14: =IF(AND(H14<>"A PARTIR DE 31/12/2003 ESSA REGRA NÃO SE APLICA AO SERVIDOR",H14<>"regra cumprida",H14<>"CONFIRME MAGISTÉRIO"),R14,"") | N14: =IF(M14="","",IF(CRÍTICA_IGP1!AH166<CRÍTICA_IGP1!AH168,"",HLOOKUP(M14,CRÍTICA_IGP1!P157:U173,12,FALSE))) | O14: =IF(H14="a partir de 31/12/2003 essa regra não se aplica ao servidor","",IF(N14="","",CRÍTICA_IGP1!AH168)) | R14: =IF('CENÁRIOS DE CONCESSÃO'!U14<>"O SERVIDOR NÃO FAZ JUS A ESSA REGRA E/OU MODALIDADE",IF(AND(CRÍTICA_IGP1!Q168>CRÍTICA_IGP1!R168,CRÍTICA_IGP1!Q168>=CRÍTICA_IGP1!T168,CRÍTICA_IGP1!Q168>=CRÍTICA_IGP1!U168),CRÍTICA_IGP1!$Q$157,IF(AND(CRÍTICA_IGP1!R168>CRÍTICA_IGP1!Q168,CRÍTICA_IGP1!R168>=CRÍTICA_IGP1!T168,CRÍTICA_IGP1!R168>=CRÍTICA_IGP1!U168),CRÍTICA_IGP1!$R$157,IF(AND(CRÍTICA_IGP1!T168>CRÍTICA_IGP1!Q168,CRÍTICA_IGP1!T168>CRÍTICA_IGP1!R168,CRÍTICA_IGP1!T168>=CRÍTICA_IGP1!U168),CRÍTICA_IGP1!$T$157,IF(AND(CRÍTICA_IGP1!U168>CRÍTICA_IGP1!Q168,CRÍTICA_IGP1!T168>CRÍTICA_IGP1!R168,CRÍTICA_IGP1!U168>CRÍTICA_IGP1!T168),CRÍTICA_IGP1!$U$157,"")))),"") -> IDADE | U14: =IF(OR(CRÍTICA_IGP1!Q168="A PARTIR DE 31/12/2003 ESSA REGRA NÃO SE APLICA AO SERVIDOR",CRÍTICA_IGP1!AH168>=37986,CRÍTICA_IGP1!Q168="CONFIRME MAGISTÉRIO"),CRÍTICA_IGP1!Q168,IF(OR(CRÍTICA_IGP1!Q168>0,CRÍTICA_IGP1!R168>0,CRÍTICA_IGP1!T168>0,CRÍTICA_IGP1!U168>0,VE_TRANS_EC20!N90="NÃO"),"REGRA NÃO CUMPRIDA","REGRA CUMPRIDA")) -> CONFIRME MAGISTÉRIO
B15: 9 | C15: TRANSIÇÃO EMENDA 20/98 | F15: VOL. PROP. TSC | H15: =IF(CRÍTICA_IGP1!AH169>=37986,"A PARTIR DE 31/12/2003 ESSA REGRA NÃO SE APLICA AO SERVIDOR",U15) -> REGRA NÃO CUMPRIDA | M15: =IF(AND(H15<>"A PARTIR DE 31/12/2003 ESSA REGRA NÃO SE APLICA AO SERVIDOR",H15<>"regra cumprida"),R15,"") -> IDADE | N15: =IF(M15="","",IF(CRÍTICA_IGP1!AH166<CRÍTICA_IGP1!AH169,"",HLOOKUP(M15,CRÍTICA_IGP1!P157:U173,13,FALSE))) -> MARQUE O SEXO | O15: =IF(H15="a partir de 31/12/2003 essa regra não se aplica ao servidor","",IF(N15="","",CRÍTICA_IGP1!AH169)) -> 15330 | R15: =IF('CENÁRIOS DE CONCESSÃO'!U15<>"O SERVIDOR NÃO FAZ JUS A ESSA REGRA E/OU MODALIDADE",IF(AND(CRÍTICA_IGP1!Q169>CRÍTICA_IGP1!R169,CRÍTICA_IGP1!Q169>=CRÍTICA_IGP1!T169,CRÍTICA_IGP1!Q169>=CRÍTICA_IGP1!U169),CRÍTICA_IGP1!$Q$157,IF(AND(CRÍTICA_IGP1!R169>CRÍTICA_IGP1!Q169,CRÍTICA_IGP1!R169>=CRÍTICA_IGP1!T169,CRÍTICA_IGP1!R169>=CRÍTICA_IGP1!U169),CRÍTICA_IGP1!$R$157,IF(AND(CRÍTICA_IGP1!T169>CRÍTICA_IGP1!Q169,CRÍTICA_IGP1!T169>CRÍTICA_IGP1!R169,CRÍTICA_IGP1!T169>=CRÍTICA_IGP1!U169),CRÍTICA_IGP1!$T$157,IF(AND(CRÍTICA_IGP1!U169>CRÍTICA_IGP1!Q169,CRÍTICA_IGP1!T169>CRÍTICA_IGP1!R169,CRÍTICA_IGP1!U169>CRÍTICA_IGP1!T169),CRÍTICA_IGP1!$U$157,"")))),"") -> IDADE | U15: =IF(OR(CRÍTICA_IGP1!Q169="A PARTIR DE 31/12/2003 ESSA REGRA NÃO SE APLICA AO SERVIDOR",CRÍTICA_IGP1!AH169>=37986),"A PARTIR DE 31/12/2003 ESSA REGRA NÃO SE APLICA AO SERVIDOR",IF(OR(CRÍTICA_IGP1!Q169>0,CRÍTICA_IGP1!R169>0,CRÍTICA_IGP1!T169>0,CRÍTICA_IGP1!U169>0,VPTC_TRANS_EC20!N84="NÃO"),"REGRA NÃO CUMPRIDA","REGRA CUMPRIDA")) -> REGRA NÃO CUMPRIDA
B16: 10 | C16: REGRA PERMANENTE EC20/98 | F16: COMPULSÓRIA | H16: =IF(OR(CRÍTICA_IGP1!Q162="A PARTIR DE 20/02/2004 ESSA REGRA NÃO SE APLICA AO SERVIDOR",CRÍTICA_IGP1!AH162>=38037),"A PARTIR DE 20/02/2004 ESSA REGRA NÃO SE APLICA AO SERVIDOR",IF(CRÍTICA_IGP1!U162>0,"REGRA NÃO CUMPRIDA","REGRA CUMPRIDA")) -> REGRA NÃO CUMPRIDA | M16: =IF(H16="A PARTIR DE 20/02/2004 ESSA REGRA NÃO SE APLICA AO SERVIDOR","",IF(CRÍTICA_IGP1!$Q$20>0,"IDADE","")) -> IDADE | N16: =IF(M16<>"",IF(CRÍTICA_IGP1!$Q$20>0,CRÍTICA_IGP1!Q20,""),"") -> 25568 | O16: =IF(N16<>"",CRÍTICA_IGP1!AH162,"") -> 25568
B17: 11 | C17: REGRA PERMANENTE EC20/98 | F17: PROP. IDADE | H17: =IF(OR(CRÍTICA_IGP1!Q161="A PARTIR DE 20/02/2004 ESSA REGRA NÃO SE APLICA AO SERVIDOR",CRÍTICA_IGP1!AH161>=38037),"A PARTIR DE 20/02/2004 ESSA REGRA NÃO SE APLICA AO SERVIDOR",IF(CRÍTICA_IGP1!U161>0,"REGRA NÃO CUMPRIDA","REGRA CUMPRIDA")) -> #VALUE! | M17: =IF(H17="A PARTIR DE 20/02/2004 ESSA REGRA NÃO SE APLICA AO SERVIDOR","",IF(CRÍTICA_IGP1!$U$161>0,"IDADE","")) -> #VALUE! | N17: =IF(M17="","",IF(CRÍTICA_IGP1!AH162<CRÍTICA_IGP1!AH161,"",IF(CRÍTICA_IGP1!AH161>0,CRÍTICA_IGP1!AH161,""))) -> #VALUE! | O17: =IF(CRÍTICA_IGP1!$AH$162<CRÍTICA_IGP1!$AH$161,"LIMITADA À COMPULSÓRIA",IF(AND(N17>0,N17<>""),CRÍTICA_IGP1!$AH$161,"")) -> #VALUE!
B18: 12 | C18: REGRA PERMANENTE EC20/98 | F18: VOL. INTEGRAL | H18: =IF(OR(CRÍTICA_IGP1!Q159="A PARTIR DE 20/02/2004 ESSA REGRA NÃO SE APLICA AO SERVIDOR",CRÍTICA_IGP1!Q159="REVER FUNDAMENTAÇÃO E/OU MODALIDADE"),CRÍTICA_IGP1!Q159,IF(OR(CRÍTICA_IGP1!Q159>0,CRÍTICA_IGP1!R159>0,CRÍTICA_IGP1!T159>0,CRÍTICA_IGP1!U159>0),"REGRA NÃO CUMPRIDA","REGRA CUMPRIDA")) -> REVER FUNDAMENTAÇÃO E/OU MODALIDADE | M18: =IF(AND(H18<>"A PARTIR DE 20/02/2004 ESSA REGRA NÃO SE APLICA AO SERVIDOR",H18<>"PREENCHA CAMPO DESTINADO AO SEXO",H18<>"REGRA CUMPRIDA",H18<>"REVER FUNDAMENTAÇÃO E/OU MODALIDADE"),R18,"") | N18: =IF(M18="","",IF(CRÍTICA_IGP1!$AH$162<CRÍTICA_IGP1!$AH$159,"",HLOOKUP(M18,CRÍTICA_IGP1!$P$157:$U$173,3,FALSE))) | O18: =IF(CRÍTICA_IGP1!$AH$162<CRÍTICA_IGP1!$AH$159,"LIMITADA À COMPULSÓRIA",IF(N18="","",CRÍTICA_IGP1!$AH$159)) | R18: =IF('CENÁRIOS DE CONCESSÃO'!H18<>"O SERVIDOR NÃO FAZ JUS A ESSA REGRA E/OU MODALIDADE",IF(AND(CRÍTICA_IGP1!Q159>CRÍTICA_IGP1!R159,CRÍTICA_IGP1!Q159>=CRÍTICA_IGP1!T159,CRÍTICA_IGP1!Q159>=CRÍTICA_IGP1!U159),CRÍTICA_IGP1!$Q$157,IF(AND(CRÍTICA_IGP1!R159>CRÍTICA_IGP1!Q159,CRÍTICA_IGP1!R159>=CRÍTICA_IGP1!T159,CRÍTICA_IGP1!R159>=CRÍTICA_IGP1!U159),CRÍTICA_IGP1!$R$157,IF(AND(CRÍTICA_IGP1!T159>CRÍTICA_IGP1!Q159,CRÍTICA_IGP1!T159>CRÍTICA_IGP1!R159,CRÍTICA_IGP1!T159>=CRÍTICA_IGP1!U159),CRÍTICA_IGP1!$T$157,IF(AND(CRÍTICA_IGP1!U159>CRÍTICA_IGP1!Q159,CRÍTICA_IGP1!T159>CRÍTICA_IGP1!R159,CRÍTICA_IGP1!U159>CRÍTICA_IGP1!T159),CRÍTICA_IGP1!$U$157,"")))),"") -> T. CONTRIBUIÇÃO
B19: 13 | C19: REGRA PERMANENTE EC20/98 | F19: VOL. ESPECIAL | H19: =IF(OR(CRÍTICA_IGP1!Q160="A PARTIR DE 20/02/2004 ESSA REGRA NÃO SE APLICA AO SERVIDOR",CRÍTICA_IGP1!Q160="REVEJA FUNDAMENTAÇÃO E/OU MODALIDADE",CRÍTICA_IGP1!Q160="CONFIRME MAGISTÉRIO OU REVEJA FUNDAMENTAÇÃO"),CRÍTICA_IGP1!Q160,IF(OR(CRÍTICA_IGP1!Q160>0,CRÍTICA_IGP1!R160>0,CRÍTICA_IGP1!T160>0,CRÍTICA_IGP1!U160>0),"REGRA NÃO CUMPRIDA","REGRA CUMPRIDA")) -> CONFIRME MAGISTÉRIO OU REVEJA FUNDAMENTAÇÃO | M19: =IF(AND(H19<>"A PARTIR DE 20/02/2004 ESSA REGRA NÃO SE APLICA AO SERVIDOR",H19<>"PREENCHA CAMPO DESTINA AO SEXO",H19<>"regra cumprida",H19<>"CONFIRME MAGISTÉRIO OU REVEJA FUNDAMENTAÇÃO"),R19,"") | N19: =IF(M19="","",IF(CRÍTICA_IGP1!$AH$162<CRÍTICA_IGP1!$AH$160,"",HLOOKUP(M19,CRÍTICA_IGP1!$P$157:$U$173,4,FALSE))) | O19: =IF(CRÍTICA_IGP1!$AH$162<CRÍTICA_IGP1!$AH$160,"LIMITADA À COMPULSÓRIA",IF(N19="","",CRÍTICA_IGP1!$AH$160)) | R19: =IF('CENÁRIOS DE CONCESSÃO'!H19<>"O SERVIDOR NÃO FAZ JUS A ESSA REGRA E/OU MODALIDADE",IF(AND(CRÍTICA_IGP1!Q160>CRÍTICA_IGP1!R160,CRÍTICA_IGP1!Q160>=CRÍTICA_IGP1!T160,CRÍTICA_IGP1!Q160>=CRÍTICA_IGP1!U160),CRÍTICA_IGP1!$Q$157,IF(AND(CRÍTICA_IGP1!R160>CRÍTICA_IGP1!Q160,CRÍTICA_IGP1!R160>=CRÍTICA_IGP1!T160,CRÍTICA_IGP1!R160>=CRÍTICA_IGP1!U160),CRÍTICA_IGP1!$R$157,IF(AND(CRÍTICA_IGP1!T160>CRÍTICA_IGP1!Q160,CRÍTICA_IGP1!T160>CRÍTICA_IGP1!R160,CRÍTICA_IGP1!T160>=CRÍTICA_IGP1!U160),CRÍTICA_IGP1!$T$157,IF(AND(CRÍTICA_IGP1!U160>CRÍTICA_IGP1!Q160,CRÍTICA_IGP1!T160>CRÍTICA_IGP1!R160,CRÍTICA_IGP1!U160>CRÍTICA_IGP1!T160),CRÍTICA_IGP1!$U$157,"")))),"") -> IDADE
B20: 14 | C20: REGRA PERMANENTE EC41/03 | F20: COMPULSÓRIA | H20: =IF(CRÍTICA_IGP1!U166>0,"REGRA NÃO CUMPRIDA","REGRA CUMPRIDA") -> REGRA NÃO CUMPRIDA | M20: =IF(CRÍTICA_IGP1!$Q$20>0,"IDADE","") -> IDADE | N20: =IF(CRÍTICA_IGP1!$Q$20>0,CRÍTICA_IGP1!$Q$20,"") -> 25568 | O20: =IF(N20<>"",CRÍTICA_IGP1!AH166,"") -> 25568
B21: 15 | C21: REGRA PERMANENTE EC41/03 | F21: PROP. IDADE | H21: =IF(CRÍTICA_IGP1!U165>0,"REGRA NÃO CUMPRIDA","REGRA CUMPRIDA") -> REGRA NÃO CUMPRIDA | M21: =IF(CRÍTICA_IGP1!$U$165>0,"IDADE","") -> IDADE | N21: =IF(CRÍTICA_IGP1!$AH$166<CRÍTICA_IGP1!$AH$165,"",IF(CRÍTICA_IGP1!$AH$165>0,CRÍTICA_IGP1!$U$165,"")) -> #VALUE! | O21: =IF(CRÍTICA_IGP1!AH166<CRÍTICA_IGP1!AH165,"LIMITADA À COMPULSÓRIA",IF(AND(N21>0,N21<>""),CRÍTICA_IGP1!AH165,"")) -> #VALUE!
B22: 16 | C22: REGRA PERMANENTE EC41/03 | F22: VOL. INTEGRAL | H22: =IF(OR(CRÍTICA_IGP1!Q163>0,CRÍTICA_IGP1!R163>0,CRÍTICA_IGP1!T163>0,CRÍTICA_IGP1!U163>0),"REGRA NÃO CUMPRIDA","REGRA CUMPRIDA") -> REGRA NÃO CUMPRIDA | M22: =IF(H22<>"REGRA CUMPRIDA",R22,"") -> T. CONTRIBUIÇÃO | N22: =IF(CRÍTICA_IGP1!$AH$166<CRÍTICA_IGP1!$AH$163,"",IF(M22="","",HLOOKUP(M22,CRÍTICA_IGP1!$P$157:$U$173,7,FALSE))) -> PREENCHA CAMPO DESTINADO AO SEXO | O22: =IF(CRÍTICA_IGP1!$AH$166<CRÍTICA_IGP1!$AH$163,"LIMITADA À COMPULSÓRIA",IF(N22="","",CRÍTICA_IGP1!$AH$163)) -> 3650 | R22: =IF('CENÁRIOS DE CONCESSÃO'!H22<>"REGRA CUMPRIDA",IF(AND(CRÍTICA_IGP1!Q163>CRÍTICA_IGP1!R163,CRÍTICA_IGP1!Q163>=CRÍTICA_IGP1!T163,CRÍTICA_IGP1!Q163>=CRÍTICA_IGP1!U163),CRÍTICA_IGP1!$Q$157,IF(AND(CRÍTICA_IGP1!R163>CRÍTICA_IGP1!Q163,CRÍTICA_IGP1!R163>=CRÍTICA_IGP1!T163,CRÍTICA_IGP1!R163>=CRÍTICA_IGP1!U163),CRÍTICA_IGP1!$R$157,IF(AND(CRÍTICA_IGP1!T163>CRÍTICA_IGP1!Q163,CRÍTICA_IGP1!T163>CRÍTICA_IGP1!R163,CRÍTICA_IGP1!T163>=CRÍTICA_IGP1!U163),CRÍTICA_IGP1!$T$157,IF(AND(CRÍTICA_IGP1!U163>CRÍTICA_IGP1!Q163,CRÍTICA_IGP1!U163>CRÍTICA_IGP1!R163,CRÍTICA_IGP1!U163>CRÍTICA_IGP1!T163),CRÍTICA_IGP1!$U$157,"")))),"") -> T. CONTRIBUIÇÃO
B23: 17 | C23: REGRA PERMANENTE EC41/03 | F23: VOL. ESPECIAL | H23: =IF(OR(CRÍTICA_IGP1!Q164="PREENCHA CAMPO DESTINADO AO SEXO",CRÍTICA_IGP1!Q164="CONFIRME EFETIVO MAGISTÉRIO"),CRÍTICA_IGP1!Q164,IF(OR(CRÍTICA_IGP1!Q164>0,CRÍTICA_IGP1!R164>0,CRÍTICA_IGP1!T164>0,CRÍTICA_IGP1!U164>0),"REGRA NÃO CUMPRIDA","REGRA CUMPRIDA")) -> CONFIRME EFETIVO MAGISTÉRIO | M23: =IF('FICHA FUNCIONAL'!$I$27<>"X","",IF(H23<>"REGRA CUMPRIDA",R23,"")) | N23: =IF(CRÍTICA_IGP1!$AH$166<CRÍTICA_IGP1!$AH$164,"",IF(M23="","",HLOOKUP(M23,CRÍTICA_IGP1!$P$157:$U$173,8,FALSE))) | O23: =IF(CRÍTICA_IGP1!$AH$166<CRÍTICA_IGP1!$AH$164,"LIMITADA À COMPULSÓRIA",IF(N23="","",CRÍTICA_IGP1!$AH$164)) | R23: =IF('CENÁRIOS DE CONCESSÃO'!H23<>"O SERVIDOR NÃO FAZ JUS A ESSA REGRA E/OU MODALIDADE",IF(AND(CRÍTICA_IGP1!Q164>CRÍTICA_IGP1!R164,CRÍTICA_IGP1!Q164>=CRÍTICA_IGP1!T164,CRÍTICA_IGP1!Q164>=CRÍTICA_IGP1!U164),CRÍTICA_IGP1!$Q$157,IF(AND(CRÍTICA_IGP1!R164>CRÍTICA_IGP1!Q164,CRÍTICA_IGP1!R164>=CRÍTICA_IGP1!T164,CRÍTICA_IGP1!R164>=CRÍTICA_IGP1!U164),CRÍTICA_IGP1!$R$157,IF(AND(CRÍTICA_IGP1!T164>CRÍTICA_IGP1!Q164,CRÍTICA_IGP1!T164>CRÍTICA_IGP1!R164,CRÍTICA_IGP1!T164>=CRÍTICA_IGP1!U164),CRÍTICA_IGP1!$T$157,IF(AND(CRÍTICA_IGP1!U164>CRÍTICA_IGP1!Q164,CRÍTICA_IGP1!T164>CRÍTICA_IGP1!R164,CRÍTICA_IGP1!U164>CRÍTICA_IGP1!T164),CRÍTICA_IGP1!$U$157,"")))),"") -> IDADE
B24: 18 | C24: TRANS. ART. 2º EMENDA 41/03 | F24: VOL. REDUTOR | H24: =IF(CRÍTICA_IGP1!Q170="O SERVIDOR NÃO FAZ JUS A ESSA REGRA E/OU MODALIDADE",CRÍTICA_IGP1!Q170,IF(OR(CRÍTICA_IGP1!Q170>0,CRÍTICA_IGP1!R170>0,CRÍTICA_IGP1!U170>0,AND(CRÍTICA_IGP1!T170>0,CRÍTICA_IGP1!T170<>"NADA A CUMPRIR")),"REGRA NÃO CUMPRIDA","REGRA CUMPRIDA")) -> O SERVIDOR NÃO FAZ JUS A ESSA REGRA E/OU MODALIDADE | M24: =IF(H24<>"O SERVIDOR NÃO FAZ JUS A ESSA REGRA E/OU MODALIDADE",R24,"") | N24: =IF(CRÍTICA_IGP1!$AH$166<CRÍTICA_IGP1!$AH$170,"",IF(M24="","",HLOOKUP(M24,CRÍTICA_IGP1!$P$157:$U$173,14,FALSE))) | O24: =IF(CRÍTICA_IGP1!$AH$166<CRÍTICA_IGP1!$AH$170,"LIMITADA À COMPULSÓRIA",IF(N24="","",CRÍTICA_IGP1!$AH$170)) | R24: =IF('CENÁRIOS DE CONCESSÃO'!H24<>"O SERVIDOR NÃO FAZ JUS A ESSA REGRA E/OU MODALIDADE",IF(AND(CRÍTICA_IGP1!Q170>CRÍTICA_IGP1!R170,CRÍTICA_IGP1!Q170>=CRÍTICA_IGP1!T170,CRÍTICA_IGP1!Q170>=CRÍTICA_IGP1!U170),CRÍTICA_IGP1!$Q$157,IF(AND(CRÍTICA_IGP1!R170>CRÍTICA_IGP1!Q170,CRÍTICA_IGP1!R170>=CRÍTICA_IGP1!T170,CRÍTICA_IGP1!R170>=CRÍTICA_IGP1!U170),CRÍTICA_IGP1!$R$157,IF(AND(CRÍTICA_IGP1!T170>CRÍTICA_IGP1!Q170,CRÍTICA_IGP1!T170>CRÍTICA_IGP1!R170,CRÍTICA_IGP1!T170>=CRÍTICA_IGP1!U170),CRÍTICA_IGP1!$T$157,IF(AND(CRÍTICA_IGP1!U170>CRÍTICA_IGP1!Q170,CRÍTICA_IGP1!U170>CRÍTICA_IGP1!R170,CRÍTICA_IGP1!U170>CRÍTICA_IGP1!T170),CRÍTICA_IGP1!$U$157,"")))),"")
C28: TRIBUNAL DE CONTAS DO ESTADO DO RIO DE JANEIRO - SUP
C29: Virgílio de Oliveira Souza (Técnica / Lógica) | H29: Luiz Cláudio Lopes de Sá - (Revisão / Lay out)

Sheet CRÍTICA_IGP1
B2: TIPO DE APOSENTADORIA | D2: : | E2: ='FICHA FUNCIONAL'!E4 -> PREENCHA COM A MODALIDADE | J2: OPÇÃO: | K2: ='FICHA FUNCIONAL'!$E$6 -> PREENCHA A REGRA DESEJADA | O2: REGRAS ANTES EC20 | P2: TEMPO: | Q2: ART. 40 CF | R2: EC 20 | S2: ART 6º | T2: ART. 2º | U2: EC 47
O3: REGRA PERMANENTE
B4: HISTÓRICO FUNCIONAL | O4: TRANSIÇÃO EMENDA 20 | P4: CARGO | Q4: =IF(OR($E$2=$B$115,$E$2=$B$116,E2=B117),IF($M$13>=5,"ATENDE","NÃO CUMPRE"),"NÃO CABE") -> NÃO CABE | R4: =IF($N$8<$Q$11,IF($M$13>=5,"ATENDE","NÃO CUMPRE"),"REVER FUNDAMENTAÇÃO") -> NÃO CUMPRE | S4: =IF($N$8<$Q$13,IF($M$13>=5,"ATENDE","NÃO ATENDE"),"REVER FUNDAMENTAÇÃO") -> NÃO ATENDE | T4: =IF($N$8<$Q$11,IF($M$13>=5,"ATENDE","NÃO ATENDE"),"REVER FUNDAMENT.") -> NÃO ATENDE | U4: =IF($N$8<$Q$11,IF($M$13>=5,"ATENDE","NÃO ATENDE"),"REVER FUNDAMENT.") -> NÃO ATENDE | AA4: TT*365 | AB4: T+ID(DIAS) | AD4: ANOS | AE4: DIAS
O5: TRANSIÇÃO_ART. 2º_EC41
A6: PODER | B6: ENTE DA FEDERAÇÃO: | E6: ='FICHA FUNCIONAL'!$E$10 -> ESTADO DO RIO DE JANEIRO | I6: PODER: | J6: ='FICHA FUNCIONAL'!$E$11 -> EXECUTIVO | K6: Ó R G Ã O : | M6: ='FICHA FUNCIONAL'!$E$12 -> 0 | O6: TRANSIÇÃO_ART. 6º_EC41 | P6: CARREIRA | Q6: NÃO CABE | R6: =IF($N$8<$Q$11,"NÃO CABE","REVER FUNDAM.") -> NÃO CABE | S6: =IF($N$8<$Q$13,IF($M$14>=10,"ATENDE","NÃO ATENDE"),"REVER FUNDAMEN.") -> NÃO ATENDE | T6: =IF($N$8<$Q$11,"NÃO CABE","REVER FUNDAMENT.") -> NÃO CABE | U6: =IF($N$8<$Q$11,IF($M$14>=15,"ATENDE","NÃO ATENDE"),"REVER FUNDAMENT.") -> NÃO ATENDE | X6: HOMEM | Z6: 95 | AA6: =Z6*365+24 -> 34699 | AB6: =$O$9+$F$61 -> 0 | AC6: =IF($H$61>=35,$AA$6-$AB$6,12775-$F$61) -> 12775 | AD6: =ROUNDDOWN($AC$6/365,0) -> 35 | AE6: =(($AC$6/365)-$AD$6)*365 -> 0 | BN6: MODALIDADES | BO6: REGRA PERMANENTE (ATUAL) | BP6: REGRAS DE TRANSIÇÃO | BQ6: REGRA PERMANENTE (EMENDA Nº 20/98) | BR6: REGRAS DE TRANSIÇÃO | BS6: REGRAS DE TRANSIÇÃO | BT6: REGRAS DE TRANSIÇÃO | BU6: REGRAS ANTIGAS (até 15/12/1998)
A7: EXECUTIVO | B7: NOME : | C7: ='FICHA FUNCIONAL'!$E$16 -> 0 | K7: MATRÍCULA : | N7: ='FICHA FUNCIONAL'!$E$17 -> 0 | O7: TRANSIÇÃO_EMENDA 47 | P7: SERVIÇO PÚBLICO: | Q7: =IF(OR($E$2=$B$115,$E$2=$B$116,E2=B117),IF($M$15>=10,"ATENDE","NÃO CUMPRE"),O77) -> OK | R7: 0 | S7: =IF($N$8<$Q$13,IF($M$15>=20,"ATENDE","NÃO ATENDE"),"REVER FUNDAMENT.") -> NÃO ATENDE | T7: 0 | U7: =IF($N$8<$Q$11,IF($M$15>=25,"ATENDE","NÃO ATENDE"),"REVER FUNDAMENT.") -> NÃO ATENDE | X7: MULHER | Z7: 85 | AA7: =Z7*365+22 -> 31047 | AB7: =$O$9+$F$61 -> 0 | AC7: =IF($H$61>=30,$AA$7-$AB$7,10950-$F$61) -> 10950 | AD7: =ROUNDDOWN($AC$7/365,0) -> 30 | AE7: =(($AC$7/365)-$AD$7)*365 -> 0 | BN7: VOLUNTÁRIA INTEGRAL | BO7: Art. 40, §1º, III, alínea "a", da CR/88 (redação dada pela EC nº 41/03) | BP7: Art. 6º, EC Nº 41/03 | BQ7: Art. 40, §1º, III, alínea "a", da CR/88 (redação dada pela EC nº 20/98) | BR7: Art. 8º, caput, da EC nº 20/98 c/c art. 3º da EC nº 41/03 | BS7: Art. 3º da EC nº 47/2005 | BT7: REVER FUNDAMENTAÇÃO E/OU MODALIDADE | BU7: Art. 40, III, alínea "a", da CR/88 (redação original)
A8: LEGISLATIVO | B8: CARGO : | C8: ='FICHA FUNCIONAL'!$E$18 -> 0 | I8: DESDE: | J8: ='FICHA FUNCIONAL'!$M$18 -> 0 | K8: ADMISSÃO : | N8: ='FICHA FUNCIONAL'!E20 -> 0 | O8: =IF($D$12="X",$BN$16,"") | Q8: IDADE SEM ARREDONDAMENTO | X8: PROFESSOR | Z8: 85 | AA8: =Z8*365+22 -> 31047 | AB8: =$O$9+$F$61 -> 0 | AC8: =IF($H$61>=30,$AA$8-$AB$8,10950-$F$61) -> 10950 | AD8: =ROUNDDOWN($AC$8/365,0) -> 30 | AE8: =(($AC$8/365)-$AD$8)*365 -> 0 | BN8: VOLUNTÁRIA ESPECIAL | BO8: Art. 40, §5º, da CR/88 (redação dada pela EC nº 41/03) | BP8: Art. 6º, EC Nº 41/03 c/c art. 40, § 5º, da CR/88 | BQ8: Art. 40, §5º, da CR/88 (redação dada pela EC nº 20/98) | BR8: Art. 8º, caput, § 4º, da EC nº 20/98 c/c art. 3º da EC nº 41/03 | BS8: REVER FUNDAMENTAÇÃO E/OU MODALIDADE | BT8: REVER FUNDAMENTAÇÃO E/OU MODALIDADE | BU8: Art. 40, III, alínea "b", da CR/88 (redação original)
A9: JUDICIÁRIO | B9: CARREIRA: | C9: ='FICHA FUNCIONAL'!$E$19 -> 0 | I9: DESDE: | J9: ='FICHA FUNCIONAL'!$M$19 -> 0 | K9: NASCIMENTO : | N9: ='FICHA FUNCIONAL'!$E$21 -> 0 | O9: =IF($N$9=0,0,O$10-$N$9+1) -> 0 | P9: =IF(D10="X",N11*365+15,IF(G10="X",N11*365+14,O9)) -> 0 | Q9: =IF($G$10="x",($O$9-12)/365,($O$9-14)/365) -> -0.038356164 | R9: =(Q9-N11)*365 -> -14 | S9: =365-R9 -> 379 | X9: PROFESSORA | Z9: 75 | AA9: =Z9*365+19 -> 27394 | AB9: =$O$9+$F$61 -> 0 | AC9: =IF($H$61>=25,$AA$9-$AB$9,9125-$F$61) -> 9125 | AD9: =ROUNDDOWN($AC$9/365,0) -> 25 | AE9: =(($AC$9/365)-$AD$9)*365 -> 0 | BN9: VOLUNTÁRIA PROPORCIONAL POR IDADE | BO9: Art. 40, §1º, III, alínea "b", da CR/88 (redação dada pela EC nº 41/03) | BP9: REVER FUNDAMENTAÇÃO E/OU MODALIDADE | BQ9: Art. 40, §1º, III, alínea "b", da CR/88 (redação dada pela EC nº 20/98) | BR9: REVER FUNDAMENTAÇÃO E/OU MODALIDADE | BS9: REVER FUNDAMENTAÇÃO E/OU MODALIDADE | BT9: REVER FUNDAMENTAÇÃO E/OU MODALIDADE | BU9: Art. 40, III, alínea "d", da CR/88 (redação original)
B10: SEXO : | D10: ='FICHA FUNCIONAL'!$I$25 -> 0 | E10: MASCULINO | G10: ='FICHA FUNCIONAL'!$M$25 -> 0 | H10: FEMININO | K10: VALIDADE DA REGRA: | N10: =IF($O$10=0,"-",$O$11) -> - | O10: =IF($K$2=$O$3,IF($D$14="X",$R$12,IF($G$14="X",$H$19,0)),IF($K$2=$O$2,$R$11,IF($K$2=$O$4,$R$13,$H$19))) -> 0 | P10: =65*365+16 -> 23741 | X10: MODALIDADE/FUNDAMENTAÇÃO | AB10: TEMPO FALTANTE | AC10: IDADE | AD10: TEMPO FALTANTE | AG10: CONCLUSÃO | AO10: TEMPO | AP10: IDADE | AQ10: SOMA | AR10: CONDIÇÃO | AX10: REGRA ANTES EC20 | BN10: COMPULSÓRIA INTEGRAL | BO10: Art. 40, §1º, II, da CR/88 (redação dada pela EC nº 41/03) | BP10: REVER FUNDAMENTAÇÃO E/OU MODALIDADE | BQ10: Art. 40, §1º, II, da CR/88 (redação dada pela EC nº 20/98) | BR10: REVER FUNDAMENTAÇÃO E/OU MODALIDADE | BS10: REVER FUNDAMENTAÇÃO E/OU MODALIDADE | BT10: REVER FUNDAMENTAÇÃO E/OU MODALIDADE | BU10: Art. 40, II, da CR/88 (redação original)
K11: CPF : | L11: ='FICHA FUNCIONAL'!$E$22 -> 0 | N11: =IF($G$10="x",ROUNDDOWN(($O$9-14)/365,0),ROUNDDOWN(($O$9-15)/365,0)) -> 0 | O11: =IF($D$14="X",IF(OR(E49<>0,E50<>0),IF(E46<=O10,E46,O10),O10),$O$10) -> 0 | P11: EC Nº 20/98 | Q11: 36145 | R11: =IF($H$19<36144,$H$19,36144) -> 0 | X11: REGRA ANTES EMENDA 20/98 | AB11: =ROUNDDOWN($C$65/365,0) -> 0 | AC11: =IF(OR(E2=B118,E2=B119),(70-N11),IF(E2=B117,IF(D10="X",(65-N11),IF(G10="X",(60-N11),"MARQUE O SEXO")),"NÃO CABE")) -> NÃO CABE | AD11: =IF(OR(AC11="MARQUE O SEXO",AC11="NÃO CABE"),0,IF(AND(AB11<=0,AC11<=0),"NADA A CUMPRIR",IF(AB11>AC11,C65,IF(AC11>AB11,(AC11*365),0)))) -> 0 | AG11: =IF($K$2=$O$2,IF(OR(E2=B115,E2=B116,E2=B117,E2=B118,E2=B119,E2=B122),IF(OR(AD11<>"NADA A CUMPRIR",AD11<>"MARQUE O SEXO"),"NÃO SATISFAZ TEMPO DE CONTRIBUIÇÃO E/OU IDADE","SATISFAZ TEMPO DE CONTRIBUIÇÃO E IDADE")),IF(OR(AD11<>"NADA A CUMPRIR",AD11<>"MARQUE O SEXO"),"NÃO SATISFAZ TEMPO DE CONTRIBUIÇÃO E/OU IDADE","SATISFAZ TEMPO DE CONTRIBUIÇÃO E/OU IDADE")) -> NÃO SATISFAZ TEMPO DE CONTRIBUIÇÃO E/OU IDADE | AO11: =ROUNDDOWN($F$61/365,0) -> 0 | AP11: =AP12 -> 0 | AQ11: =SUM(AO11:AP11) -> 0 | AR11: =IF(OR($E$70="atende limite mínimo de idade",$F$71="nada a cumprir"),"SATISFAZ TEMPO DE CONTRIBUIÇÃO E/OU IDADE","NÃO SATISFAZ TEMPO DE CONTRIBUIÇÃO E/OU IDADE") -> SATISFAZ TEMPO DE CONTRIBUIÇÃO E/OU IDADE | BN11: COMPULSÓRIA PROPORCIONAL | BO11: Art. 40, §1º, II, da CR/88 (redação dada pela EC nº 41/03) | BP11: REVER FUNDAMENTAÇÃO E/OU MODALIDADE | BQ11: Art. 40, §1º, II, da CR/88 (redação dada pela EC nº 20/98) | BR11: REVER FUNDAMENTAÇÃO E/OU MODALIDADE | BS11: REVER FUNDAMENTAÇÃO E/OU MODALIDADE | BT11: REVER FUNDAMENTAÇÃO E/OU MODALIDADE | BU11: Art. 40, II, da CR/88 (redação original)
B12: EFET - MAGISTÉRIO | D12: ='FICHA FUNCIONAL'!$I$27 -> 0 | E12: SIM | G12: ='FICHA FUNCIONAL'!$M$27 -> 0 | H12: NÃO | M12: ANOS | N12: DIAS | P12: MPV 167/04 | Q12: 38037 | R12: =IF($H$19<38036,$H$19,38036) -> 0 | X12: REGRA PERMANENTE | AB12: =ROUNDDOWN($C$65/365,0) -> 0 | AC12: =IF($G$10="x",55-$N$11,IF($D$10="x",60-$N$11,0)) -> 0 | AD12: =IF(AND($AB$12<=0,$AC$12<=0),"NADA A CUMPRIR",IF($G$10="X",$I$147-$P$9,IF($D$10="X",$J$147-$P$9,"REVER TEMPO E/OU IDADE"))) -> NADA A CUMPRIR | AG12: =IF($K$2=$O$3,IF($E$2=$B$115,IF($AD$12<>"NADA A CUMPRIR","NÃO SATISFAZ TEMPO DE CONTRIBUIÇÃO E/OU IDADE","SATISFAZ TEMPO DE CONTRIBUIÇÃO E IDADE"),IF($AD$12<>"NADA A CUMPRIR","NÃO SATISFAZ TEMPO DE CONTRIBUIÇÃO E/OU IDADE","SATISFAZ TEMPO DE CONTRIBUIÇÃO E IDADE")),"NÃO É INTEGRAL DA REGRA PERMANENTE") -> NÃO É INTEGRAL DA REGRA PERMANENTE | AO12: =ROUNDDOWN($F$61/365,0) -> 0 | AP12: =$N$11 -> 0 | AQ12: =SUM(AO12:AP12) -> 0 | AR12: =IF(AND($E$70="atende limite mínimo de idade",$F$71="nada a cumprir"),"SATISFAZ TEMPO DE CONTRIBUIÇÃO E IDADE","NÃO SATISFAZ TEMPO DE CONTRIBUIÇÃO E/OU IDADE") -> NÃO SATISFAZ TEMPO DE CONTRIBUIÇÃO E/OU IDADE | BN12: INVALIDEZ INTEGRAL | BO12: Art. 40, §1º, I, da CR/88 (redação dada pela EC nº 41/03) | BP12: REVER FUNDAMENTAÇÃO E/OU MODALIDADE | BQ12: Art. 40, §1º, I, da CR/88 (redação dada pela EC nº 20/98) | BR12: REVER FUNDAMENTAÇÃO E/OU MODALIDADE | BS12: REVER FUNDAMENTAÇÃO E/OU MODALIDADE | BT12: REVER FUNDAMENTAÇÃO E/OU MODALIDADE | BU12: Art. 40, I, da CR/88 (redação original)
J13: TEMPO CARGO: | M13: =ROUNDDOWN($O$13/365,0) -> 0 | N13: =O13-(M13*365) -> 0 | O13: =IF($J$8=0,0,O$10-$J$8-$O$63-$O$61) -> 0 | P13: EC Nº 41/03 | Q13: 37986 | R13: =IF($H$19<37985,$H$19,37985) -> 0 | X13: REGRA PERM. MAGISTÉRIO | AB13: =$AB$12 -> 0 | AC13: =IF($G$10="x",50-$N$11,IF($D$10="x",55-$N$11,0)) -> 0 | AD13: =IF(AND($AB$13<0,$AC$13<0),"NADA A CUMPRIR",IF($G$10="X",$I$148-$P$9,IF($D$10="X",$J$148-$P$9,"REVER TEMPO E/OU IDADE"))) -> REVER TEMPO E/OU IDADE | AG13: =IF($K$2=$O$3,IF($E$2=$B$116,IF($AD$13<>"NADA A CUMPRIR","NÃO SATISFAZ TEMPO DE CONTRIBUIÇÃO E/OU IDADE","SATISFAZ TEMPO DE CONTRIBUIÇÃO E IDADE"),IF($AD$13<>"NADA A CUMPRIR","NÃO SATISFAZ TEMPO DE CONTRIBUIÇÃO E/OU IDADE","SATISFAZ TEMPO DE CONTRIBUIÇÃO E IDADE")),"NÃO É ESPECIAL DA REGRA PERMANENTE") -> NÃO É ESPECIAL DA REGRA PERMANENTE | AO13: =ROUNDDOWN($F$61/365,0) -> 0 | AP13: =$AP$12 -> 0 | AQ13: =SUM(AO13:AP13) -> 0 | AR13: =IF(AND($E$70="atende limite mínimo de idade",$F$71="nada a cumprir"),"SATISFAZ TEMPO DE CONTRIBUIÇÃO E IDADE","NÃO SATISFAZ TEMPO DE CONTRIBUIÇÃO E/OU IDADE") -> NÃO SATISFAZ TEMPO DE CONTRIBUIÇÃO E/OU IDADE | BN13: INVALIDEZ PROPORCIONAL | BO13: Art. 40, §1º, I, da CR/88 (redação dada pela EC nº 41/03) | BP13: REVER FUNDAMENTAÇÃO E/OU MODALIDADE | BQ13: Art. 40, §1º, I, da CR/88 (redação dada pela EC nº 20/98) | BR13: REVER FUNDAMENTAÇÃO E/OU MODALIDADE | BS13: REVER FUNDAMENTAÇÃO E/OU MODALIDADE | BT13: REVER FUNDAMENTAÇÃO E/OU MODALIDADE | BU13: Art. 40, I, da CR/88 (redação original)
B14: REDAÇÃO DADA PELA | D14: ='FICHA FUNCIONAL'!$I$29 -> 0 | E14: EMENDA Nº 20/98 | G14: ='FICHA FUNCIONAL'!$M$29 -> x | H14: EMENDA Nº 41/03 | J14: TEMPO CARREIRA: | M14: =ROUNDDOWN($O$14/365,0) -> 0 | N14: =O14-(M14*365) -> 0 | O14: =IF($J$9=0,0,O$10-$J$9-$O$63-$O$61) -> 0 | P14: CONSTITUIÇÃO FEDERAL | Q14: 32421 | X14: REGRA PERMANENTE_IDADE | AB14: =$AB$12 -> 0 | AC14: =IF($G$10="x",60-$N$11,IF($D$10="x",65-$N$11,0)) -> 0 | AD14: =IF(AND($AB$14<0,$AC$14<0),"NADA A CUMPRIR",$C$65) -> 0 | AG14: =IF($K$2=$O$3,IF($E$2=$B$117,IF($AD$13<>"NADA A CUMPRIR","NÃO SATISFAZ A IDADE E/OU TEMPO DE CONTRIBUIÇÃO","IDADE E TEMPO DE CONTRIBUIÇÃO SATISFEITOS"),IF($AD$13<>"NADA A CUMPRIR","NÃO SATISFAZ A IDADE E/OU TEMPO DE CONTRIBUIÇÃO","IDADE E TEMPO DE CONTRIBUIÇÃO SATISFEITOS")),"NÃO É VOLUNTÁRIA POR IDADE / REGRA PERMANENTE") -> NÃO É VOLUNTÁRIA POR IDADE / REGRA PERMANENTE | AO14: =ROUNDDOWN($F$61/365,0) -> 0 | AP14: =$AP$12 -> 0 | AR14: =IF(AND($E$70="atende limite mínimo de idade",$F$71="NÃO CABE"),"SATISFAZ TEMPO DE CONTRIBUIÇÃO E/OU IDADE","NÃO SATISFAZ TEMPO DE CONTRIBUIÇÃO E/OU IDADE") -> NÃO SATISFAZ TEMPO DE CONTRIBUIÇÃO E/OU IDADE | BN14: VOL. PROPORCIONAL T. CONTRIBUIÇÃO | BO14: REVER FUNDAMENTAÇÃO E/OU MODALIDADE | BP14: REVER FUNDAMENTAÇÃO E/OU MODALIDADE | BQ14: REVER FUNDAMENTAÇÃO E/OU MODALIDADE | BR14: Art. 8º, § 1º, da EC nº 20/98 c/c art. 3º da EC nº 41/03 | BS14: REVER FUNDAMENTAÇÃO E/OU MODALIDADE | BT14: REVER FUNDAMENTAÇÃO E/OU MODALIDADE | BU14: Art. 40, III, alínea "c", da CR/88 (redação original)
B15: ADICIONAL POR TEMPO DE SERVIÇO: | G15: ='MTS - MAPA DE TEMPO DE SERVIÇO'!$N$8 -> TRIÊNIO | J15: TEMPO DE SERVIÇO PÚBLICO: | M15: =ROUNDDOWN($O$15/365,0) -> 0 | N15: =O15-(M15*365) -> 0 | O15: =IF(AND('MTS - MAPA DE TEMPO DE SERVIÇO'!$N$35="SIM",'MTS - MAPA DE TEMPO DE SERVIÇO'!$N$51="SIM"),$O$16,IF(AND('MTS - MAPA DE TEMPO DE SERVIÇO'!$N$35="SIM",'MTS - MAPA DE TEMPO DE SERVIÇO'!$N$51="NÃO"),$O$17,IF(AND('MTS - MAPA DE TEMPO DE SERVIÇO'!$N$35="NÃO",'MTS - MAPA DE TEMPO DE SERVIÇO'!$N$51="SIM"),$O$18,IF(AND('MTS - MAPA DE TEMPO DE SERVIÇO'!$N$35="NÃO",'MTS - MAPA DE TEMPO DE SERVIÇO'!$N$51="NÃO"),$O$19,$O$16)))) -> 0 | P15: ADIN 609-6 - decisão TCE | Q15: 35915 | X15: TRANSIÇÃO EMENDA 20 | AB15: =$AB$12 -> 0 | AC15: =IF($G$10="x",48-$N$11,IF($D$10="x",53-$N$11,0)) -> 0 | AD15: =IF(AND($AB$15<0,$AC$15<0),"NADA A CUMPRIR",IF($G$10="X",$I$147-$P$9,IF($D$10="X",$J$147-$P$9,"REVER TEMPO E/OU IDADE"))) -> REVER TEMPO E/OU IDADE | AG15: =IF($K$2=$O$4,IF($E$2=$B$115,IF($AD$15<>"NADA A CUMPRIR","NÃO SATISFAZ A IDADE E/OU TEMPO DE CONTRIBUIÇÃO","IDADE E TEMPO DE CONTRIBUIÇÃO SATISFEITOS"),IF($AD$15<>"NADA A CUMPRIR","NÃO SATISFAZ A IDADE E/OU TEMPO DE CONTRIBUIÇÃO","IDADE E TEMPO DE CONTRIBUIÇÃO SATISFEITOS")),"NÃO É INTEGRAL - TRANSIÇÃO EMENDA 20") -> NÃO É INTEGRAL - TRANSIÇÃO EMENDA 20 | AO15: =ROUNDDOWN($F$61/365,0) -> 0 | AP15: =$AP$12 -> 0 | AQ15: =SUM(AO15:AP15) -> 0 | AR15: =IF(AND($E$70="atende limite mínimo de idade",$F$71="nada a cumprir"),"SATISFAZ TEMPO DE CONTRIBUIÇÃO E IDADE","NÃO SATISFAZ TEMPO DE CONTRIBUIÇÃO E/OU IDADE") -> NÃO SATISFAZ TEMPO DE CONTRIBUIÇÃO E/OU IDADE | BN15: VOLUNTÁRIA COM REDUTOR | BO15: REVER FUNDAMENTAÇÃO E/OU MODALIDADE | BP15: REVER FUNDAMENTAÇÃO E/OU MODALIDADE | BQ15: REVER FUNDAMENTAÇÃO E/OU MODALIDADE | BR15: REVER FUNDAMENTAÇÃO E/OU MODALIDADE | BS15: REVER FUNDAMENTAÇÃO E/OU MODALIDADE | BT15: Art. 2º da EC nº 41/03 | BU15: REVER FUNDAMENTAÇÃO E/OU MODALIDADE
O16: =IF($N$10<$Q$11,SUM($F$27:$F$34),IF($N$10<$Q$12,SUM($F$27:$F$34)+$H$51-$O$20,SUM($F$27:$F$34)+$H$51+$H$60-$O$22)) -> 0 | P16: APOSENTADORIA COMPULSÓRIA_CONDIÇÕES | X16: TRANS. EC Nº 20 MAGISTÉRIO | AB16: =$AB$12 -> 0 | AC16: =IF($G$10="x",48-$N$11,IF($D$10="x",53-$N$11,0)) -> 0 | AD16: =IF(AND($AB$16<0,$AC$16<0),"NADA A CUMPRIR",IF($G$10="X",$I$148-$P$9,IF($D$10="X",$J$148-$P$9,"REVER TEMPO E/OU IDADE"))) -> REVER TEMPO E/OU IDADE | AG16: =IF($K$2=$O$4,IF($E$2=$B$116,IF($AD$16<>"NADA A CUMPRIR","NÃO SATISFAZ A IDADE E/OU TEMPO DE CONTRIBUIÇÃO","IDADE E TEMPO DE CONTRIBUIÇÃO SATISFEITOS"),IF($AD$16<>"NADA A CUMPRIR","NÃO SATISFAZ A IDADE E/OU TEMPO DE CONTRIBUIÇÃO","IDADE E TEMPO DE CONTRIBUIÇÃO SATISFEITOS")),"NÃO É ESPECIAL - TRANSIÇÃO EMENDA 20/98") -> NÃO É ESPECIAL - TRANSIÇÃO EMENDA 20/98 | AO16: =ROUNDDOWN($F$61/365,0) -> 0 | AP16: =$AP$12 -> 0 | AQ16: =SUM(AO16:AP16) -> 0 | AR16: =IF(AND($E$70="atende limite mínimo de idade",$F$71="nada a cumprir"),"SATISFAZ TEMPO DE CONTRIBUIÇÃO E IDADE","NÃO SATISFAZ TEMPO DE CONTRIBUIÇÃO E/OU IDADE") -> NÃO SATISFAZ TEMPO DE CONTRIBUIÇÃO E/OU IDADE | BN16: VOLUNTÁRIA COM REDUTOR - MAGISTÉRIO | BO16: REVER FUNDAMENTAÇÃO E/OU MODALIDADE | BP16: REVER FUNDAMENTAÇÃO E/OU MODALIDADE | BQ16: REVER FUNDAMENTAÇÃO E/OU MODALIDADE | BR16: REVER FUNDAMENTAÇÃO E/OU MODALIDADE | BS16: REVER FUNDAMENTAÇÃO E/OU MODALIDADE | BT16: Art. 2º, § 4º, da EC nº 41/03 | BU16: REVER FUNDAMENTAÇÃO E/OU MODALIDADE
B17: DOCUMENTAÇÃO : | O17: =IF($N$10<$Q$11,SUM($F$27:$F$34),IF($N$10<$Q$12,SUM($F$27:$F$34)+$H$51-$O$20,SUM($F$27:$F$34)+$H$51-$O$20+$H$60)) -> 0 | P17: ADICIONAL POR TEMPO DE SERVIÇO | X17: TRANS. EC Nº 20_TEMPO SERVIÇO | AB17: =$AB$12 -> 0 | AC17: =IF($G$10="x",48-$N$11,IF($D$10="x",53-$N$11,0)) -> 0 | AD17: =IF(AND($AB$17<=0,$AC$17<=0),"NADA A CUMPRIR",IF($G$10="X",$I$148-$P$9,IF($D$10="X",$J$148-$P$9,"REVER TEMPO E/OU IDADE"))) -> NADA A CUMPRIR | AG17: =IF($K$2=$O$4,IF($E$2=$B$122,IF($AD$17<>"NADA A CUMPRIR","NÃO SATISFAZ TEMPO DE CONTRIBUIÇÃO E/OU IDADE","SATISFAZ TEMPO DE CONTRIBUIÇÃO E IDADE"),IF($AD$17<>"NADA A CUMPRIR","NÃO SATISFAZ TEMPO DE CONTRIBUIÇÃO E/OU IDADE","SATISFAZ TEMPO DE CONTRIBUIÇÃO E IDADE")),"NÃO É VOL. TEMPO. CONTRIBUIÇÃO - TRANSIÇÃO EMENDA 20/98") -> NÃO É VOL. TEMPO. CONTRIBUIÇÃO - TRANSIÇÃO EMENDA 20/98 | AO17: =ROUNDDOWN($F$61/365,0) -> 0 | AP17: =$AP$12 -> 0 | AQ17: =SUM(AO17:AP17) -> 0 | AR17: =IF(AND($E$70="atende limite mínimo de idade",$F$71="nada a cumprir"),"SATISFAZ TEMPO DE CONTRIBUIÇÃO E IDADE","NÃO SATISFAZ TEMPO DE CONTRIBUIÇÃO E/OU IDADE") -> NÃO SATISFAZ TEMPO DE CONTRIBUIÇÃO E/OU IDADE | BN17: INVALIDEZ (EMENDA Nº 70/2012) | BO17: Art. 40, §1º, I, da CR/88 (redação EC nº 41/03) c/c Art. 6º_A da EC nº 41/03 | BP17: REVER FUNDAMENTAÇÃO E/OU MODALIDADE | BQ17: REVER FUNDAMENTAÇÃO E/OU MODALIDADE | BR17: REVER FUNDAMENTAÇÃO E/OU MODALIDADE | BS17: REVER FUNDAMENTAÇÃO E/OU MODALIDADE | BT17: REVER FUNDAMENTAÇÃO E/OU MODALIDADE | BU17: REVER FUNDAMENTAÇÃO E/OU MODALIDADE
