Workbook

Sheet Morar Sozinha
A1: DESAFIO MORAR SOZINHA
A2: Mês | B2: 1 Mês | C2: 2 Mês | D2: 3 Mês | E2: 4 Mês | F2: 5 Mês | G2: 6 Mês | H2: 7 Mês | I2: 8 Mês | J2: 9 Mês | K2: 10 Mês | L2: 11 Mês | M2: 12 Mês | N2: Total
B3: 43739 | C3: 43770 | D3: 43800 | E3: 43831 | F3: 43862 | G3: 43891 | H3: 43922 | I3: 43952 | J3: 43983 | K3: 44013 | L3: 44044 | M3: 44075
A4: Valor | B4: 37.5 | C4: 75 | D4: 115 | E4: 200 | F4: 205 | G4: 1000 | H4: 1362.5 | I4: 1365 | J4: 1375 | K4: 1525 | L4: 1687 | M4: 1838 | N4: =SUM(B4:M4) -> 10785
A5: Dia do Deposito

Sheet Plan2
A1: Código | B1: ITSA3F | C1: Variação | D1: 0.0038 | F1: Código | G1: ITSA3F | H1: Variação | I1: 0.0038
A2: Valor | B2: 13.05 | C2: Horário | D2: 0.47569444 | F2: Valor | G2: 13.05 | H2: Horário | I2: 0.47569444
A3: Data de Compra | C3: ITAUSA | F3: Data de Compra
A4: Valor de Compra | F4: Valor de Compra
A5: Verificação | C5: Valor | F5: Verificação | H5: Valor
B21: EQUATORIAL | C21: EQTL3
B22: JBS | C22: JBSS3
B23: ALPARGATAS | C23: ALPA4
B24: CVC | C24: CVCB3
B25: MAGAZINELUIZ | C25: MGLU3

Sheet OUTUBRO
A1: Lançamentos nacionais
A2: MAURO ELIR DE SOUZA (3189) | C2: =SUBTOTAL(9,C4:C77) -> 2655.945
A3: DATA | B3: MOVIMENTAÇÃO | C3: VALOR EM R$
A4: 43509 | B4: NETSHOES ZATTINI*Z08/10 | C4: 51.06 | D4: natalia
A5: 43525 | B5: ame dig-AME Digita07/12 | C5: 104.83 | D5: weslley
A6: 43552 | B6: PAG*MaquinaCartao 07/12 | C6: 4.9 | D6: natalia
A7: 43634 | B7: MERCADO PAGO 04/04 | C7: 54.3 | D7: elizabeth
A8: 43643 | B8: HOTMART *Xtrem04/05 | C8: 66.04 | D8: rafael
A9: 43666 | B9: RIACHUELO 157 03/03 | C9: 59.9 | D9: natalia
A10: 43666 | B10: KALUNGA MADUREIRA 03/03 | C10: 67.47 | D10: natalia
A11: 43670 | B11: VIA VAREJO S A 03/08 | C11: 191.11 | D11: lidane
A12: 43679 | B12: DROGARIA ATUAL 02/02 | C12: 39.8 | D12: natalia
A13: 43684 | B13: PAG*InstitutoDanie02/06 | C13: 58.1 | D13: natalia
A14: 43708 | B14: PG *TEC CONCURSOS | C14: 29.9 | D14: natalia
A15: 43708 | B15: PAG*JoseHenriqueVieir | C15: 25 | D15: natalia
... A63: 43729 | B63: MERCADINHO DIVISA | C63: 20.04 | D63: natalia
A64: 43729 | B64: SUPERMERCADO GUANABARA | C64: 223.325 | D64: natalia | E64: 446.65
A65: 43729 | B65: SUPERMERCADO GUANABARA | C65: 223.325 | D65: lidane
A66: 43729 | B66: CARLA LARISSA DE SANTA | C66: 14 | D66: natalia
A67: 43729 | B67: CARLA LARISSA DE SANTA | C67: 14 | D67: lidane
A68: 43730 | B68: CARLA LARISSA DE SANTA | C68: 25.05 | D68: natalia
A69: 43731 | B69: SEGURO MAXI PROTECAO | C69: 10.06 | D69: natalia
A70: 43731 | B70: LIG BLOQUEIO | C70: 1.5 | D70: natalia
A71: 43731 | B71: SEG RENDA EXTRA HOSP | C71: 15.65 | D71: natalia
A72: 43735 | B72: EBANX *SPOTIFY | C72: 6.725 | D72: rafael
A73: 43735 | B73: EBANX *SPOTIFY | C73: 6.725 | D73: yuri
A74: 43735 | B74: EBANX *SPOTIFY | C74: 6.725 | D74: natalia
A75: 43735 | B75: EBANX *SPOTIFY | C75: 6.725 | D75: cris
A76: 43736 | B76: Uber Do Brasil Tecnolo | C76: 97.79 | D76: elizabeth
A77: 43737 | B77: SUPERMERCADO GUANABARA | C77: 150 | D77: elizabeth
A78: Crédito do cartão final (3189) | C78: =C39 -> -264
A79: Débito do cartão final (3189) | C79: =SUM(C4:C38,C40:C77) -> 3348.38
C80: =SUM(C78:C79) -> 3084.38
E82: 548.98
C83: =SUM(C11,C65,C67) -> 428.435
B85: natalia | C85: 2011.7183
B86: lidiane | C86: 428.435
B87: mauro
B88: elizabeth | C88: 366.99
B89: weslley | C89: 104.83
...

Sheet NOVEMBRO
A1: Lançamentos nacionais
A2: MAURO ELIR DE SOUZA (3189) | C2: =SUBTOTAL(9,C4:C31) -> 1495.69
A3: DATA | B3: MOVIMENTAÇÃO | C3: VALOR EM R$
A4: 43509 | B4: NETSHOES ZATTINI*Z09/10 | C4: 51.06 | D4: natalia
A5: 43525 | B5: ame dig-AME Digita08/12 | C5: 104.83 | D5: weslley
A6: 43552 | B6: PAG*MaquinaCartao 08/12 | C6: 4.9 | D6: natalia
A7: 43643 | B7: HOTMART *Xtrem05/05 | C7: 66.04 | D7: rafael
A8: 43670 | B8: VIA VAREJO S A 04/08 | C8: 191.11 | D8: lidane
A9: 43684 | B9: PAG*InstitutoDanie03/06 | C9: 58.1 | D9: natalia
A10: 43709 | B10: PARCELA DE ANUIDAD04/12 | C10: 20.66 | D10: natalia
A11: 43710 | B11: COMPUSA 02/02 | C11: 70 | D11: natalia
A12: 43711 | B12: HTM*HOTMART hotmar02/07 | C12: 78.25 | D12: natalia
A13: 43717 | B13: UNISUAM | C13: 460.36 | D13: natalia
A14: 43721 | B14: PAGOLIVRE*ESPLASE13X18 | C14: 228.16 | D14: natalia
A15: 43721 | B15: PG *ESTRATEGIACON 02/12 | C15: 48.12 | D15: natalia
... A31: 43735 | B31: EBANX *SPOTIFY | C31: 6.725 | D31: cris
C33: =SUM(C4:C31) -> 1565.69
B39: natalia | C39: 1112.3433
B40: lidiane | C40: 191.11
B41: mauro
B42: elizabeth
B43: weslley | C43: 104.83
B44: rafael | C44: 87.003333
B45: cris | C45: 20.963333
B46: marcela | C46: 14.238333
B47: bruna | C47: 14.238333
B48: catia | C48: 14.238333
B49: rebeca
B50: yuri | C50: 6.725
C51: =SUM(C39:C50) -> 1565.69
C53: =C51-C33 -> 0

Sheet DEZEMBRO
A1: Lançamentos nacionais
A2: MAURO ELIR DE SOUZA (3189) | C2: =SUBTOTAL(9,C4:C29) -> 1429.65
A3: DATA | B3: MOVIMENTAÇÃO | C3: VALOR EM R$
A4: 43509 | B4: NETSHOES ZATTINI*Z09/10 | C4: 51.06 | D4: natalia
A5: 43525 | B5: ame dig-AME Digita08/12 | C5: 104.83 | D5: weslley
A6: 43552 | B6: PAG*MaquinaCartao 08/12 | C6: 4.9 | D6: natalia
A7: 43670 | B7: VIA VAREJO S A 04/08 | C7: 191.11 | D7: lidane
A8: 43684 | B8: PAG*InstitutoDanie03/06 | C8: 58.1 | D8: natalia
A9: 43709 | B9: PARCELA DE ANUIDAD04/12 | C9: 20.66 | D9: natalia
A10: 43711 | B10: HTM*HOTMART hotmar02/07 | C10: 78.25 | D10: natalia
A11: 43717 | B11: UNISUAM | C11: 460.36 | D11: natalia
A12: 43721 | B12: PAGOLIVRE*ESPLASE13X18 | C12: 228.16 | D12: natalia
A13: 43721 | B13: PG *ESTRATEGIACON 02/12 | C13: 48.12 | D13: natalia
A14: 43722 | B14: PG *ESTRATEGIACON 02/06 | C14: 5.75 | D14: natalia
A15: 43725 | B15: MERCPAGO*QCONCURSO02/12 | C15: 17.6 | D15: natalia
... A29: 43735 | B29: EBANX *SPOTIFY | C29: 6.725 | D29: cris
C31: =SUM(C4:C29) -> 1429.65
B37: natalia | C37: 1042.3433
B38: lidiane | C38: 191.11
B39: mauro
B40: elizabeth
B41: weslley | C41: 104.83
B42: rafael | C42: 20.963333
B43: cris | C43: 20.963333
B44: marcela | C44: 14.238333
B45: bruna | C45: 14.238333
B46: catia | C46: 14.238333
B47: rebeca
B48: yuri | C48: 6.725
C49: =SUM(C37:C48) -> 1429.65
C50: =C31-C49 -> 0

Sheet A RECEBER
A1: Tipo | B1: Nome | C1: Valor | D1: Janeiro | E1: Fevereiro | F1: Março | G1: Abril | H1: Maio | I1: Junho | J1: Julho | K1: Agosto | L1: Setembro | M1: Outubro | N1: Novembro | O1: Dezembro
A2: Cartão - Itaú | B2: Weslley | C2: 104.83 | M2: 104.83 | N2: 104.83 | O2: 104.83
B3: Elizabeth | C3: 54.3 | M3: 54.3
B4: Rafael | C4: 66.04 | M4: 66.04 | N4: 66.04
B5: Cris | C5: 6.73 | M5: 6.73 | N5: 6.73 | O5: 6.73
B6: Rafael | C6: 6.73 | M6: 6.73 | N6: 6.73 | O6: 6.73
B7: Yuri | C7: 6.73 | M7: 6.73 | N7: 6.73 | O7: 6.73
B8: Elizabeth | C8: 64.9 | M8: 64.9
B9: Cris | C9: 14.241667 | M9: 14.241667 | N9: 14.241667 | O9: 14.241667
B10: Marcela | C10: 14.241667 | M10: 14.241667 | N10: 14.241667 | O10: 14.241667
B11: Catia | C11: 14.241667 | M11: 14.241667 | N11: 14.241667 | O11: 14.241667
B12: Rafael | C12: 14.241667 | M12: 14.241667 | N12: 14.241667 | O12: 14.241667
B13: Bruna | C13: 14.241667 | M13: 14.241667 | N13: 14.241667 | O13: 14.241667
B14: Rebeca | C14: 15 | M14: 15
B15: Rafael | C15: 17.6 | M15: 17.6 | N15: 17.6 | O15: 17.6
B16: Weslley | C16: 11.7 | M16: 11.7 | N16: 11.7
B17: Weslley | C17: 33.81 | M17: 33.81 | N17: 33.81 | O17: 33.81
D19: =SUM(D2:D17) -> 0 | E19: =SUM(E2:E17) -> 0 | F19: =SUM(F2:F17) -> 0 | G19: =SUM(G2:G17) -> 0 | H19: =SUM(H2:H17) -> 0 | I19: =SUM(I2:I17) -> 0 | J19: =SUM(J2:J17) -> 0 | K19: =SUM(K2:K17) -> 0 | ... O19: =SUM(O2:O17) -> 247.63833

Sheet CARTÃO DE CRÉDITO - NUBANK
E1: =SUBTOTAL(9,E3:E35) -> 633.68 | G1: =SUBTOTAL(9,G3:G35) -> 180.01 | H1: =SUBTOTAL(9,H3:H35) -> 0 | I1: =SUBTOTAL(9,I3:I35) -> 0 | J1: =SUBTOTAL(9,J3:J35) -> 0 | K1: =SUBTOTAL(9,K3:K35) -> 0 | L1: =SUBTOTAL(9,L3:L35) -> 0 | M1: =SUBTOTAL(9,M3:M35) -> 0 | N1: =SUBTOTAL(9,N3:N35) -> 0 | ... S1: =SUBTOTAL(9,S3:S35) -> 51.41
A2: Cód. | B2: Data | C2: Nome | D2: Descrição | E2: Valor Total | F2: Parcelas | G2: Valor Parcelado | H2: Jan | I2: Fev | J2: Mar | K2: Abr | L2: Mai | M2: Jun | N2: Jul | O2: Ago | P2: Set | Q2: Out | R2: Nov | S2: Dez
A3: Nubank | C3: Natália | D3: Parcelamento | E3: =F3*G3 -> 1147.7 | F3: 10 | G3: 114.77 | O3: 114.77 | P3: 114.77 | Q3: 114.77 | R3: 114.77 | S3: 114.77
A4: Nubank | C4: Natália | D4: Baggaio | E4: =F4*G4 -> 147.76 | F4: 4 | G4: 36.94 | O4: 36.94 | P4: =36.92+36.92 -> 73.84
A5: Nubank | C5: Natália | D5: GooglePlay | E5: =F5*G5 -> 6.99 | F5: 1 | G5: 6.99 | O5: 6.99 | P5: 0
A6: Nubank | C6: Elizabeth | D6: Sky | E6: =F6*G6 -> 58.9 | F6: 1 | G6: 58.9 | O6: 58.9 | P6: 0 | Q6: 0 | R6: 0 | S6: 0
A7: Nubank | C7: Natália | D7: Microsoft | E7: =F7*G7 -> 29 | F7: 1 | G7: 29 | O7: 29 | P7: 29
A8: Nubank | C8: Natália | D8: Restaurante | E8: =F8*G8 -> 78.56 | F8: 1 | G8: 78.56 | O8: 78.56 | P8: 0
A9: Nubank | C9: Rafael | D9: Qconcursos | E9: =F9*G9 -> 211.2 | F9: 12 | G9: 17.6 | O9: 17.6 | P9: 17.6 | Q9: 17.6 | R9: 17.6 | S9: 17.6
A10: Nubank | C10: Natália | D10: Rio Beleza | E10: =F10*G10 -> 70.96 | F10: 2 | G10: 35.48 | O10: 35.48 | P10: 35.48
A11: Nubank | C11: Natália | D11: Netflix | E11: =F11*G11 -> 262.8 | F11: 12 | G11: 21.9 | O11: 0 | P11: 21.9 | Q11: 21.9 | R11: 21.9 | S11: 21.9
A12: Nubank | C12: Natália | D12: Burguer King | E12: =F12*G12 -> 20.9 | F12: 1 | G12: 20.9 | O12: 0 | P12: 20.9
A13: Nubank | C13: Natália | D13: Doce Pelicula | E13: =F13*G13 -> 94.69 | F13: 1 | G13: 94.69 | O13: 94.69 | P13: 0
A14: Nubank | C14: Weslley | D14: Lojas Americanas | E14: =F14*G14 -> 35.1 | F14: 3 | G14: 11.7 | O14: 0 | P14: 11.7 | Q14: 11.7 | R14: 11.7 | S14: 0
A15: Nubank | C15: Weslley | D15: Lojas Americanas | E15: =F15*G15 -> 270.48 | F15: 8 | G15: 33.81 | O15: 0 | P15: 33.66 | Q15: 33.81 | R15: 33.81 | S15: 33.81
A16: Nubank | C16: Lidiane | D16: Japa | E16: =F16*G16 -> 58 | F16: 1 | G16: 58 | O16: 0 | P16: 58 | Q16: 0 | R16: 0 | S16: 0
E17: =F17*G17 -> 0
E18: =F18*G18 -> 0
E19: =F19*G19 -> 0
E20: =F20*G20 -> 0
E21: =F21*G21 -> 0
E22: =F22*G22 -> 0
E23: =F23*G23 -> 0
E24: =F24*G24 -> 0
E25: =F25*G25 -> 0
E26: =F26*G26 -> 0
E27: =F27*G27 -> 0
E28: =F28*G28 -> 0
... E35: =F35*G35 -> 0

Sheet CARTÃO DE CRÉDITO - ITAÚ
E1: =SUBTOTAL(9,E3:E62) -> 1173.4017 | G1: =SUBTOTAL(9,G3:G62) -> 380.74833 | H1: =SUBTOTAL(9,H3:H62) -> 0 | I1: =SUBTOTAL(9,I3:I62) -> 0 | J1: =SUBTOTAL(9,J3:J62) -> 0 | K1: =SUBTOTAL(9,K3:K62) -> 0 | L1: =SUBTOTAL(9,L3:L62) -> 0 | M1: =SUBTOTAL(9,M3:M62) -> 0 | N1: =SUBTOTAL(9,N3:N62) -> 0 | ... S1: =SUBTOTAL(9,S3:S62) -> 91.398333
A2: Cód. | B2: Data | C2: Nome | D2: Descrição | E2: Valor Total | F2: Parcelas | G2: Valor Parcelado | H2: Jan | I2: Fev | J2: Mar | K2: Abr | L2: Mai | M2: Jun | N2: Jul | O2: Ago | P2: Set | Q2: Out | R2: Nov | S2: Dez
A3: Itaú | C3: Natália | D3: Zattini | E3: =F3*G3 -> 510.6 | F3: 10 | G3: 51.06 | O3: 51.06 | P3: 51.06 | Q3: 51.06 | R3: 51.06 | S3: 51.06
A4: Itaú | C4: Weslley | D4: Celular | E4: =F4*G4 -> 1257.96 | F4: 12 | G4: 104.83 | O4: 104.83 | P4: 104.83 | Q4: 104.83 | R4: 104.83 | S4: 104.83
A5: Itaú | C5: Natália | D5: Máquina de Cartão | E5: =F5*G5 -> 58.8 | F5: 12 | G5: 4.9 | O5: 4.9 | P5: 4.9 | Q5: 4.9 | R5: 4.9 | S5: 4.9
A6: Itaú | C6: Natália | D6: C&A | E6: =F6*G6 -> 261.93 | F6: 3 | G6: 87.31 | O6: 87.31 | P6: 0
A7: Itaú | C7: Natália | D7: O Amigão | E7: =F7*G7 -> 114.06 | F7: 3 | G7: 38.02 | O7: 38.02 | P7: 0
A8: Itaú | C8: Natália | D8: Leader | E8: =F8*G8 -> 149.97 | F8: 3 | G8: 49.99 | O8: 49.99 | P8: 0
A9: Itaú | C9: Natália | D9: Riachuelo | E9: =F9*G9 -> 161.64 | F9: 3 | G9: 53.88 | O9: 53.88 | P9: 0
A10: Itaú | C10: Natália | D10: Mercado Pago | E10: =F10*G10 -> -0.09 | F10: 1 | G10: -0.09 | O10: -0.09 | P10: 0
A11: Itaú | C11: Elizabeth | D11: Mercado Pago | E11: =F11*G11 -> 217.2 | F11: 4 | G11: 54.3 | O11: 54.3 | P11: 54.3 | Q11: 54.3 | R11: 0 | S11: 0
A12: Itaú | C12: Rafael | D12: Xtrem | E12: =F12*G12 -> 330.2 | F12: 5 | G12: 66.04 | O12: 66.04 | P12: 66.04 | Q12: 66.04 | R12: 66.04 | S12: 0
A13: Itaú | C13: Natália | D13: UCB | E13: =F13*G13 -> 510.97 | F13: 1 | G13: 510.97 | O13: 510.97 | P13: 0
A14: Itaú | C14: Natália | D14: Uber Do Brasil Tecnolo | E14: =F14*G14 -> 19.97 | F14: 1 | G14: 19.97 | O14: 19.97 | P14: 0
A15: Itaú | C15: Natália | D15: Uber Do Brasil Tecnolo | E15: =F15*G15 -> 20.2 | F15: 1 | G15: 20.2 | O15: 20.2 | P15: 0
A16: Itaú | C16: Natália | D16: Drogaria Pop | E16: =F16*G16 -> 68.08 | F16: 2 | G16: 34.04 | O16: 34.04 | P16: 34.04
A17: Itaú | C17: Natália | D17: Drogaria Pop | E17: =F17*G17 -> 86.42 | F17: 2 | G17: 43.21 | O17: 43.21 | P17: 43.21
A18: Itaú | C18: Natália | D18: Anuidade | E18: =F18*G18 -> 248.88 | F18: 12 | G18: 20.74 | O18: 20.74 | P18: 20.66 | Q18: 20.66 | R18: 20.74 | S18: 20.74
A19: Itaú | C19: Natália | D19: Espaço Laser | E19: =F19*G19 -> 4106.88 | F19: 18 | G19: 228.16 | O19: 228.16 | P19: 228.16 | Q19: 228.16 | R19: 228.16 | S19: 228.16
A20: Itaú | C20: Natália | D20: Alfa Concursos | E20: =F20*G20 -> -450.4 | F20: 1 | G20: -450.4 | O20: -450.4 | P20: 0
A21: Itaú | C21: Natália | D21: Alfa Concursos | E21: =F21*G21 -> 450.4 | F21: 1 | G21: 450.4 | O21: 450.4 | P21: 0
A22: Itaú | C22: Natália | D22: Riachuelo | E22: =F22*G22 -> 179.7 | F22: 3 | G22: 59.9 | O22: 59.9 | P22: 59.9 | Q22: 59.9
A23: Itaú | C23: Natália | D23: Kalunga | E23: =F23*G23 -> 202.41 | F23: 3 | G23: 67.47 | O23: 67.47 | P23: 67.47 | Q23: 67.47
A24: Itaú | C24: Natália | D24: Seguro Maxi Proteção | E24: =F24*G24 -> 9.76 | F24: 1 | G24: 9.76 | O24: 9.76 | P24: 9.76 | Q24: 6.73 | R24: 9.76 | S24: 9.76
A25: Itaú | C25: Natália | D25: Lig Bloqueio | E25: =F25*G25 -> 1.5 | F25: 1 | G25: 1.5 | O25: 1.5 | P25: 1.5 | Q25: 1.5 | R25: 1.5 | S25: 1.5
A26: Itaú | C26: Natália | D26: Seg Renda | E26: =F26*G26 -> 15.65 | F26: 1 | G26: 15.65 | O26: 15.65 | P26: 15.65 | Q26: 15.65 | R26: 15.65 | S26: 15.65
A27: Itaú | C27: Natália | D27: O Amigão | E27: =F27*G27 -> 68.92 | F27: 2 | G27: 34.46 | O27: 34.46 | P27: 34.46
A28: Itaú | C28: Natália | D28: Mecanico | E28: =F28*G28 -> 500.01 | F28: 3 | G28: 166.67 | O28: 166.67 | P28: 166.67 | Q28: 166.67
A29: Itaú | C29: Natália | D29: Drogaria Pop | E29: =F29*G29 -> -0.01 | F29: 1 | G29: -0.01 | O29: 0 | P29: -0.02
A30: Itaú | C30: Natália | D30: UNISUAM | E30: =F30*G30 -> 511.5 | F30: 1 | G30: 511.5 | O30: 0 | P30: 511.5 | Q30: 460.36 | R30: 511.5 | S30: 511.5
A31: Itaú | C31: Natália | D31: Lojas Magal | E31: =F31*G31 -> 24.05 | F31: 1 | G31: 24.05 | O31: 0 | P31: 24.05
A32: Itaú | C32: Natália | D32: MR Protter | E32: =F32*G32 -> 12 | F32: 1 | G32: 12 | O32: 0 | P32: 12
A33: Itaú | C33: Natália | D33: Tec Concursos | E33: =F33*G33 -> 119.6 | F33: 4 | G33: 29.9 | O33: 0 | P33: 29.9 | Q33: 29.9 | R33: 29.9 | S33: 29.9
A34: Itaú | C34: Natália | D34: Mercadinho da Divisa | E34: =F34*G34 -> 28.29 | F34: 1 | G34: 28.29 | O34: 0 | P34: 28.29
A35: Itaú | C35: Natália | D35: Recreio | E35: =F35*G35 -> 4.78 | F35: 1 | G35: 4.78 | O35: 0 | P35: 4.78
A36: Itaú | C36: Natália | D36: Drogaria Atual | E36: =F36*G36 -> 79.6 | F36: 2 | G36: 39.8 | O36: 0 | P36: 39.8 | Q36: 39.8
A37: Itaú | C37: Natália | D37: Restaurante | E37: =F37*G37 -> 87.81 | F37: 1 | G37: =19.9+26.56+16.45+24.9 -> 87.81 | O37: 0 | P37: 87.81
A38: Itaú | C38: Natália | D38: Uber Do Brasil Tecnolo | E38: =F38*G38 -> 42.04 | F38: 1 | G38: 42.04 | O38: 0 | P38: 42.04
A39: Itaú | C39: Elizabeth | D39: Uber Do Brasil Tecnolo | E39: =F39*G39 -> 89.11 | F39: 1 | G39: 89.11 | O39: 0 | P39: 89.11 | Q39: 0 | R39: 0 | S39: 0
A40: Itaú | B40: 43704 | C40: Natália | D40: Spotify | E40: =F40*G40 -> 33.65 | F40: 5 | G40: 6.73 | O40: 0 | P40: 26.9 | Q40: 6.73 | R40: 6.73 | S40: 6.73
...

Sheet CARTÃO DE CRÉDITO - OUTROS
E1: =SUBTOTAL(9,E3:E6) -> 1525.51 | G1: =SUBTOTAL(9,G3:G6) -> 241.57 | H1: =SUBTOTAL(9,H3:H6) -> 0 | I1: =SUBTOTAL(9,I3:I6) -> 0 | J1: =SUBTOTAL(9,J3:J6) -> 0 | K1: =SUBTOTAL(9,K3:K6) -> 0 | L1: =SUBTOTAL(9,L3:L6) -> 0 | M1: =SUBTOTAL(9,M3:M6) -> 0 | N1: =SUBTOTAL(9,N3:N6) -> 0 | ... S1: =SUBTOTAL(9,S3:S6) -> 53.9
A2: Cód. | B2: Data | C2: Nome | D2: Descrição | E2: Valor Total | F2: Parcelas | G2: Valor Parcelado | H2: Jan | I2: Fev | J2: Mar | K2: Abr | L2: Mai | M2: Jun | N2: Jul | O2: Ago | P2: Set | Q2: Out | R2: Nov | S2: Dez
A3: Riachuelo | C3: Natália | D3: Roupas | E3: =F3*G3 -> 878.56 | F3: 8 | G3: 109.82 | O3: 109.82 | P3: 115.72 | Q3: 115.72
A4: Riachuelo | C4: Natália | D4: Bolsa Protegida | E4: =F4*G4 -> 17.7 | F4: 3 | G4: 5.9 | O4: 5.9 | P4: 5.9
A5: Renner | C5: Natália | D5: Calças | E5: =F5*G5 -> 359.75 | F5: 5 | G5: 71.95 | O5: 287.6 | P5: 0
A6: Renner | B6: 43691 | C6: Natália | D6: Roupas | E6: =F6*G6 -> 269.5 | F6: 5 | G6: 53.9 | O6: 0 | P6: =54.2+53.9 -> 108.1 | R6: 53.9 | S6: 53.9

Sheet PLANO DENTAL-SAÚDE
A1: Descrição - Plano Dental | C1: Valores | E1: Descrição - Plano Odontológico | G1: Valores
A2: Valor Contratado | C2: 50 | E2: Valor Contratado | G2: 119.9
A3: Taxa de Juros Mensal | E3: Taxa de Juros Mensal
A4: Período do finan. em meses | C4: Indeterminado | E4: Período do finan. em meses | G4: Indeterminado
A5: Pagamento Mensal | C5: =C2 -> 50 | E5: Pagamento Mensal | G5: =G2 -> 119.9
A6: Data Inicio do Plano | C6: 43774 | E6: Data Inicio do Plano
A7: Seguradora | C7: Amil | E7: Seguradora | G7: Ortopride
A8: Tipo | C8: Boleto | E8: Tipo | G8: Carne
A10: N | B10: Data de Pagamento | C10: Valor da Parcela | E10: N | F10: Data de Pagamento | G10: Valor da Parcela
A11: 1 | B11: 43779 | C11: 50 | E11: 1 | F11: 43322 | G11: 119.9 | H11: Ok
A12: 2 | B12: 43809 | C12: 50 | E12: 2 | F12: 43322 | G12: 119.9 | H12: Ok
A13: 3 | B13: =B12+30 -> 43839 | C13: 50 | E13: 3 | F13: =F12+30 -> 43352
A14: 4 | B14: =B13+30 -> 43869 | C14: 50 | E14: 4 | F14: =F13+30 -> 43382
A15: 5 | B15: =B14+30 -> 43899 | C15: 50 | E15: 5 | F15: =F14+30 -> 43412
A16: 6 | B16: =B15+30 -> 43929 | C16: 50 | E16: 6 | F16: =F15+30 -> 43442
A17: 7 | B17: =B16+30 -> 43959 | C17: 50 | E17: 7 | F17: =F16+30 -> 43472
A18: 8 | B18: =B17+30 -> 43989 | C18: 50 | E18: 8 | F18: =F17+30 -> 43502
A19: 9 | B19: =B18+30 -> 44019 | C19: 50 | E19: 9 | F19: =F18+30 -> 43532
A20: 10 | B20: =B19+30 -> 44049 | C20: 50 | E20: 10 | F20: =F19+30 -> 43562
A21: 11 | B21: =B20+30 -> 44079 | C21: 50 | E21: 11 | F21: =F20+30 -> 43592
A22: 12 | B22: =B21+30 -> 44109 | C22: 50 | E22: 12 | F22: =F21+30 -> 43622
E23: 13 | F23: =F22+30 -> 43652
E24: 14 | F24: =F23+30 -> 43682
E25: 15 | F25: =F24+30 -> 43712
E26: 16 | F26: =F25+30 -> 43742
E27: 17 | F27: =F26+30 -> 43772
E28: 18 | F28: =F27+30 -> 43802
E29: 19 | F29: =F28+30 -> 43832
E30: 20 | F30: =F29+30 -> 43862
E31: 21 | F31: =F30+30 -> 43892
E32: 22 | F32: =F31+30 -> 43922
E33: 23 | F33: =F32+30 -> 43952
E34: 24 | F34: =F33+30 -> 43982
... E58: 48 | F58: =F57+30 -> 44702
A62: 43739 | B62: 43770 | C62: 43800
A63: =SUM(G26) -> 0 | B63: =SUM(C11,G27) -> 50 | C63: =SUM(C12,G27) -> 50

Sheet FINANCIAMENTOS
A1: Descrição - Carro | C1: Valores
A2: Valor da Entrada | C2: 10000
A3: Valor Contratado | C3: 21936
A4: Taxa de Juros Mensal
A5: Período do finan. em meses | C5: 48
A6: Pagamento Mensal | C6: =C3/C5 -> 457
A7: Valor a ser pago | C7: =SUM(C2:C3) -> 31936
A8: Data Inicio do Empréstimo | C8: 43311
A9: Banco | C9: BV Financeira
A10: Tipo | C10: Carnê
A12: N | B12: Data de Pagamento | C12: Valor da Parcela
A13: 1 | B13: 43342 | C13: 457 | D13: Ok
A14: 2 | B14: =B13+31 -> 43373 | C14: 457 | D14: Ok
A15: 3 | B15: =B14+31 -> 43404 | C15: 457 | D15: Ok
A16: 4 | B16: =B15+30 -> 43434 | C16: 457 | D16: Ok
A17: 5 | B17: =B16+31 -> 43465 | C17: 457 | D17: Ok
A18: 6 | B18: =B17+31 -> 43496 | C18: 457 | D18: Ok
A19: 7 | B19: =B18+28 -> 43524 | C19: 457 | D19: Ok
A20: 8 | B20: =B19+31 -> 43555 | C20: 457 | D20: Ok
A21: 9 | B21: =B20+30 -> 43585 | C21: 457 | D21: Ok
A22: 10 | B22: =B21+31 -> 43616 | C22: 457 | D22: Ok
A23: 11 | B23: =B22+30 -> 43646 | C23: 457 | D23: Ok
A24: 12 | B24: =B23+31 -> 43677 | C24: 457 | D24: Ok
A25: 13 | B25: =B24+31 -> 43708 | C25: 457 | D25: Ok
A26: 14 | B26: =B25+30 -> 43738 | C26: 457 | D26: Ok
A27: 15 | B27: =B26+31 -> 43769 | C27: 457
A28: 16 | B28: =B27+30 -> 43799 | C28: 457
A29: 17 | B29: =B28+31 -> 43830 | C29: 457
A30: 18 | B30: =B29+31 -> 43861 | C30: 457
A31: 19 | B31: =B30+29 -> 43890 | C31: 457
A32: 20 | B32: =B31+31 -> 43921 | C32: 457
A33: 21 | B33: =B32+30 -> 43951 | C33: 457
A34: 22 | B34: =B33+31 -> 43982 | C34: 457
A35: 23 | B35: =B34+30 -> 44012 | C35: 457
A36: 24 | B36: =B35+31 -> 44043 | C36: 457
A37: 25 | B37: =B36+31 -> 44074 | C37: 457
A38: 26 | B38: =B37+30 -> 44104 | C38: 457
A39: 27 | B39: =B38+31 -> 44135 | C39: 457
A40: 28 | B40: =B39+30 -> 44165 | C40: 457
A41: 29 | B41: =B40+31 -> 44196 | C41: 457
...

Sheet EMPRÉSTIMOS
A1: Descrição - 001 | C1: Valores | E1: Descrição - 002 | G1: Valores | I1: Descrição - 003 | K1: Valores
A2: Valor Contratado | C2: 2000 | E2: Valor Contratado | G2: 2001 | I2: Valor Contratado | K2: 700
A3: Taxa de Juros Mensal | E3: Taxa de Juros Mensal | I3: Taxa de Juros Mensal
A4: Período do empr. em meses | C4: 7 | E4: Período do empr. em meses | G4: 6 | I4: Período do empr. em meses | K4: 1
A5: Pagamento Mensal | C5: 405.86 | E5: Pagamento Mensal | G5: 222.235 | I5: Pagamento Mensal | K5: 700
A6: Valor a ser pago | C6: =C4*C5 -> 2841.02 | E6: Valor a ser pago | G6: =G4*G5 -> 1333.41 | I6: Valor a ser pago | K6: =K4*K5 -> 700
A7: Data Inicio do Empréstimo | C7: 43678 | E7: Data Inicio do Empréstimo | G7: 43678 | I7: Data Inicio do Empréstimo
A8: Banco | C8: Itaú | E8: Banco | G8: Itaú | I8: Banco | K8: Itaú
A9: Tipo | C9: Déito na CC | E9: Tipo | G9: Déito na CC | I9: Tipo | K9: Cheque Especial
A11: N | B11: Data de Pagamento | C11: Valor da Parcela | E11: N | F11: Data de Pagamento | G11: Valor da Parcela | I11: N | J11: Data de Pagamento | K11: Valor da Parcela
A12: 1 | B12: 43718 | C12: 405.86 | E12: 1 | F12: 43718 | G12: 222.235 | I12: 1 | J12: 43718 | K12: 700
A13: 2 | B13: 43748 | C13: 405.86 | E13: 2 | F13: 43748 | G13: 222.235 | I13: 2 | J13: 43748 | K13: 700
A14: 3 | B14: 43779 | C14: 405.86 | E14: 3 | F14: 43779 | G14: 222.235 | I14: 3 | J14: 43779 | K14: 700
A15: 4 | B15: 43809 | C15: 405.86 | E15: 4 | F15: 43809 | G15: 222.235 | I15: 4 | J15: 43809 | K15: 700
A16: 5 | B16: 43840 | C16: 405.86 | E16: 5 | F16: 43840 | G16: 222.235 | I16: 5 | J16: 43840 | K16: 700
A17: 6 | B17: 43871 | C17: 405.86 | E17: 6 | F17: 43871 | G17: 222.235 | I17: 6 | J17: 43871 | K17: 700
A18: 7 | B18: 43900 | C18: 405.86 | I18: 7 | J18: 43900 | K18: 700
B20: 43739 | C20: 43770 | D20: 43800
B21: =SUM(C13,G13,K13) -> 1328.095 | C21: =SUM(C14,G14,K14) -> 1328.095 | D21: =SUM(C15,G15,K15) -> 1328.095

Sheet Receita x Despesa
A1: Receita | B1: Janeiro | C1: Fevereiro | D1: Março | E1: Abril | F1: Maio | G1: Junho | H1: Julho | I1: Agosto | J1: Setembro | K1: Outubro | L1: Novembro | M1: Dezembro | N1: Total | O1: Janeiro | P1: Fevereiro | Q1: Março | R1: Abril | S1: Maio | T1: Junho | U1: Julho | V1: Agosto | W1: Setembro | X1: Outubro | Y1: Novembro | Z1: Dezembro | AA1: Total
A2: Salário | B2: 0 | C2: 0 | D2: 0 | E2: 0 | F2: 0 | G2: 0 | H2: 0 | I2: 0 | J2: ='PLANO DE SAÚDE'!M9 -> 1151.5494 | K2: 1084.57 | N2: =SUM(B2:M2) -> 2236.1194 | Q2: 4000 | R2: 4000 | S2: 4000 | T2: 4000 | U2: 4000 | V2: 4000 | W2: 4000 | X2: 4000 | Y2: 4000 | Z2: 4000 | AA2: =SUM(O2:Z2) -> 40000
A3: Férias | B3: 0 | C3: 0 | D3: 0 | E3: 0 | F3: 0 | G3: 0 | H3: 0 | I3: 0 | J3: 0 | L3: 0 | M3: 0 | N3: =SUM(B3:M3) -> 0
A4: 13º salário | B4: 0 | C4: 0 | D4: 0 | E4: 0 | F4: 0 | G4: 0 | H4: 0 | I4: 0 | K4: 0 | L4: 0 | M4: 0 | N4: =SUM(B4:M4) -> 0 | AA4: =SUM(O4:Z4) -> 0
A5: Vale Refeição/Alimentação | B5: 0 | C5: 0 | D5: 0 | E5: 0 | F5: 0 | G5: 0 | H5: 0 | I5: 0 | J5: 0 | K5: 0 | L5: 0 | M5: 0 | N5: =SUM(B5:M5) -> 0 | AA5: =SUM(O5:Z5) -> 0
A6: Receita extra | B6: 0 | C6: 0 | D6: 0 | E6: 0 | F6: 0 | G6: 0 | H6: 0 | I6: 0 | J6: 1573.69 | K6: =55+700 -> 755 | L6: 700 | M6: 700 | N6: =SUM(B6:M6) -> 3728.69 | AA6: =SUM(O6:Z6) -> 0
A7: Aluguel | B7: 0 | C7: 0 | D7: 0 | E7: 0 | F7: 0 | G7: 0 | H7: 0 | I7: 0 | J7: =650+260 -> 910 | K7: =650 -> 650 | L7: =650 -> 650 | M7: =650 -> 650 | N7: =SUM(B7:M7) -> 2860 | O7: 650 | P7: 650 | Q7: 650 | R7: 650 | S7: 650 | T7: 650 | U7: 650 | V7: 650 | W7: 650 | X7: 650 | Y7: 650 | Z7: 650 | AA7: =SUM(O7:Z7) -> 7800
A8: Outras Receitas (Terceiros) | B8: 0 | C8: 0 | D8: 0 | E8: 0 | F8: 0 | G8: 0 | H8: 0 | I8: 0 | J8: =377.24 -> 377.24 | K8: ='A RECEBER'!M19 -> 459.57833 | L8: ='A RECEBER'!N19 -> 325.37833 | M8: ='A RECEBER'!O19 -> 247.63833 | N8: =SUM(B8:M8) -> 1409.835 | AA8: =SUM(O8:Z8) -> 0
A9: Total da Receita Líquida | B9: =SUM(B2:B8) -> 0 | C9: =SUM(C2:C8) -> 0 | D9: =SUM(D2:D8) -> 0 | E9: =SUM(E2:E8) -> 0 | F9: =SUM(F2:F8) -> 0 | G9: =SUM(G2:G8) -> 0 | H9: =SUM(H2:H8) -> 0 | I9: =SUM(I2:I8) -> 0 | ... AA9: =SUM(AA2:AA8) -> 47800
A11: Despesa | B11: Janeiro | C11: Fevereiro | D11: Março | E11: Abril | F11: Maio | G11: Junho | H11: Julho | I11: Agosto | J11: Setembro | K11: Outubro | L11: Novembro | M11: Dezembro | N11: Total | O11: Janeiro | P11: Fevereiro | Q11: Março | R11: Abril | S11: Maio | T11: Junho | U11: Julho | V11: Agosto | W11: Setembro | X11: Outubro | Y11: Novembro | Z11: Dezembro | AA11: Total
A12: Alimentação | B12: =SUM(B13:B17) -> 0 | C12: =SUM(C13:C17) -> 0 | D12: =SUM(D13:D17) -> 0 | E12: =SUM(E13:E17) -> 0 | F12: =SUM(F13:F17) -> 0 | G12: =SUM(G13:G17) -> 0 | H12: =SUM(H13:H17) -> 0 | I12: =SUM(I13:I17) -> 0 | ... M12: =SUM(M13:M17) -> 0 | N12: =SUM(B12:M12) -> 0 | O12: =SUM(O13:O17) -> 0 | P12: =SUM(P13:P17) -> 0 | Q12: =SUM(Q13:Q17) -> 300 | R12: =SUM(R13:R17) -> 300 | S12: =SUM(S13:S17) -> 300 | T12: =SUM(T13:T17) -> 300 | U12: =SUM(U13:U17) -> 300 | V12: =SUM(V13:V17) -> 300 | ... Z12: =SUM(Z13:Z17) -> 300 | AA12: =SUM(O12:Z12) -> 3000
A13: Supermercado | B13: 0 | C13: 0 | D13: 0 | E13: 0 | F13: 0 | G13: 0 | H13: 0 | I13: 0 | J13: 0 | K13: 0 | L13: 0 | M13: 0 | N13: =SUM(B13:M13) -> 0 | Q13: 300 | R13: 300 | S13: 300 | T13: 300 | U13: 300 | V13: 300 | W13: 300 | X13: 300 | Y13: 300 | Z13: 300 | AA13: =SUM(O13:Z13) -> 3000
A14: Feira / Sacolão | B14: 0 | C14: 0 | D14: 0 | E14: 0 | F14: 0 | G14: 0 | H14: 0 | I14: 0 | J14: 0 | K14: 0 | L14: 0 | M14: 0 | N14: =SUM(B14:M14) -> 0 | AA14: =SUM(O14:Z14) -> 0
A15: Padaria | B15: 0 | C15: 0 | D15: 0 | E15: 0 | F15: 0 | G15: 0 | H15: 0 | I15: 0 | J15: 0 | K15: 0 | L15: 0 | M15: 0 | N15: =SUM(B15:M15) -> 0 | AA15: =SUM(O15:Z15) -> 0
A16: Refeição fora de casa | B16: 0 | C16: 0 | D16: 0 | E16: 0 | F16: 0 | G16: 0 | H16: 0 | I16: 0 | J16: 0 | K16: 0 | L16: 0 | M16: 0 | N16: =SUM(B16:M16) -> 0 | AA16: =SUM(O16:Z16) -> 0
A17: Outros (café, água, sorvetes, etc) | B17: 0 | C17: 0 | D17: 0 | E17: 0 | F17: 0 | G17: 0 | H17: 0 | I17: 0 | J17: 0 | K17: 0 | L17: 0 | M17: 0 | N17: =SUM(B17:M17) -> 0 | AA17: =SUM(O17:Z17) -> 0
A18: Moradia | B18: =SUM(B19:B30) -> 0 | C18: =SUM(C19:C30) -> 0 | D18: =SUM(D19:D30) -> 0 | E18: =SUM(E19:E30) -> 0 | F18: =SUM(F19:F30) -> 0 | G18: =SUM(G19:G30) -> 0 | H18: =SUM(H19:H30) -> 0 | I18: =SUM(I19:I30) -> 0 | ... AA18: =SUM(AA19:AA30) -> 2279.9
A19: Prestação /Aluguel de imóvel | B19: 0 | C19: 0 | D19: 0 | E19: 0 | F19: 0 | G19: 0 | H19: 0 | I19: 0 | J19: 0 | K19: 0 | L19: 0 | M19: 0 | N19: =SUM(B19:M19) -> 0 | AA19: =SUM(O19:Z19) -> 0
A20: Condomínio | B20: 0 | C20: 0 | D20: 0 | E20: 0 | F20: 0 | G20: 0 | H20: 0 | I20: 0 | J20: 0 | K20: 0 | L20: 0 | M20: 0 | N20: =SUM(B20:M20) -> 0 | AA20: =SUM(O20:Z20) -> 0
A21: Consumo de água | B21: 0 | C21: 0 | D21: 0 | E21: 0 | F21: 0 | G21: 0 | H21: 0 | I21: 0 | J21: 0 | K21: 0 | L21: 0 | M21: 0 | N21: =SUM(B21:M21) -> 0 | AA21: =SUM(O21:Z21) -> 0
A22: Serviço de limpeza (diarista ou mensalista) | B22: 0 | C22: 0 | D22: 0 | E22: 0 | F22: 0 | G22: 0 | H22: 0 | I22: 0 | J22: 0 | K22: 0 | L22: 0 | M22: 0 | N22: =SUM(B22:M22) -> 0 | Q22: 140 | R22: 140 | S22: 140 | T22: 140 | U22: 140 | V22: 140 | W22: 140 | X22: 140 | Y22: 140 | Z22: 140 | AA22: =SUM(O22:Z22) -> 1400
A23: Energia Elétrica | B23: 0 | C23: 0 | D23: 0 | E23: 0 | F23: 0 | G23: 0 | H23: 0 | I23: 0 | J23: 0 | K23: 0 | L23: 0 | M23: 0 | N23: =SUM(B23:M23) -> 0 | AA23: =SUM(O23:Z23) -> 0
A24: Gás | B24: 0 | C24: 0 | D24: 0 | E24: 0 | F24: 0 | G24: 0 | H24: 0 | I24: 0 | J24: 0 | K24: 0 | L24: 0 | M24: 0 | N24: =SUM(B24:M24) -> 0 | Q24: 70 | T24: 70 | W24: 70 | Z24: 70 | AA24: =SUM(O24:Z24) -> 280
A25: IPTU | B25: 0 | C25: 0 | D25: 0 | E25: 0 | F25: 0 | G25: 0 | H25: 0 | I25: 0 | J25: 0 | K25: 0 | L25: 0 | M25: 0 | N25: =SUM(B25:M25) -> 0 | AA25: =SUM(O25:Z25) -> 0
A26: Decoração da casa | B26: 0 | C26: 0 | D26: 0 | E26: 0 | F26: 0 | G26: 0 | H26: 0 | I26: 0 | J26: 0 | K26: 0 | L26: 0 | M26: 0 | N26: =SUM(B26:M26) -> 0 | AA26: =SUM(O26:Z26) -> 0
A27: Manutenção / Reforma da casa | B27: 0 | C27: 0 | D27: 0 | E27: 0 | F27: 0 | G27: 0 | H27: 0 | I27: 0 | J27: 0 | K27: 0 | L27: 0 | M27: 0 | N27: =SUM(B27:M27) -> 0 | AA27: =SUM(O27:Z27) -> 0
A28: Celular | B28: 0 | C28: 0 | D28: 0 | E28: 0 | F28: 0 | G28: 0 | H28: 0 | I28: 0 | J28: 59.99 | K28: 59.99 | L28: 59.99 | M28: 59.99 | N28: =SUM(B28:M28) -> 239.96 | Q28: 59.99 | R28: 59.99 | S28: 59.99 | T28: 59.99 | U28: 59.99 | V28: 59.99 | W28: 59.99 | X28: 59.99 | Y28: 59.99 | Z28: 59.99 | AA28: =SUM(O28:Z28) -> 599.9
A29: Telefone fixo | B29: 0 | C29: 0 | D29: 0 | E29: 0 | F29: 0 | G29: 0 | H29: 0 | I29: 0 | J29: 0 | K29: 0 | L29: 0 | M29: 0 | N29: =SUM(B29:M29) -> 0 | AA29: =SUM(O29:Z29) -> 0
A30: Internet / TV a cabo | B30: 0 | C30: 0 | D30: 0 | E30: 0 | F30: 0 | G30: 0 | H30: 0 | I30: 0 | J30: 50 | K30: 50 | L30: 50 | M30: 50 | N30: =SUM(B30:M30) -> 200 | AA30: =SUM(O30:Z30) -> 0
A31: Educação | B31: =SUM(B32:B35) -> 0 | C31: =SUM(C32:C35) -> 0 | D31: =SUM(D32:D35) -> 0 | E31: =SUM(E32:E35) -> 0 | F31: =SUM(F32:F35) -> 0 | G31: =SUM(G32:G35) -> 0 | H31: =SUM(H32:H35) -> 0 | I31: =SUM(I32:I35) -> 0 | ... AA31: =SUM(AA32:AA35) -> 7000
A32: Matricula Escolar/ Mensalidade | B32: 0 | C32: 0 | D32: 0 | E32: 0 | F32: 0 | G32: 0 | H32: 0 | I32: 0 | J32: 0 | K32: 0 | L32: 0 | M32: 0 | N32: =SUM(B32:M32) -> 0 | Q32: 700 | R32: 700 | S32: 700 | T32: 700 | U32: 700 | V32: 700 | W32: 700 | X32: 700 | Y32: 700 | Z32: 700 | AA32: =SUM(O32:Z32) -> 7000
A33: Material Escolar | B33: 0 | C33: 0 | D33: 0 | E33: 0 | F33: 0 | G33: 0 | H33: 0 | I33: 0 | J33: 0 | K33: 0 | L33: 0 | M33: 0 | N33: =SUM(B33:M33) -> 0 | AA33: =SUM(O33:Z33) -> 0
A34: Outros cursos | B34: 0 | C34: 0 | D34: 0 | E34: 0 | F34: 0 | G34: 0 | H34: 0 | I34: 0 | J34: 0 | K34: 0 | L34: 0 | M34: 0 | N34: =SUM(B34:M34) -> 0 | AA34: =SUM(O34:Z34) -> 0
A35: Transporte escolar | B35: 0 | C35: 0 | D35: 0 | E35: 0 | F35: 0 | G35: 0 | H35: 0 | I35: 0 | J35: 0 | K35: 0 | L35: 0 | M35: 0 | N35: =SUM(B35:M35) -> 0 | AA35: =SUM(O35:Z35) -> 0
A36: Saúde | B36: =SUM(B37:B42) -> 0 | C36: =SUM(C37:C42) -> 0 | D36: =SUM(D37:D42) -> 0 | E36: =SUM(E37:E42) -> 0 | F36: =SUM(F37:F42) -> 0 | G36: =SUM(G37:G42) -> 0 | H36: =SUM(H37:H42) -> 0 | I36: =SUM(I37:I42) -> 0 | ... AA36: =SUM(AA37:AA42) -> 6128
A37: Plano de saúde / Dental / Odontológico | B37: 0 | C37: 0 | D37: 0 | E37: 0 | F37: 0 | G37: 0 | H37: 0 | I37: 0 | J37: 0 | K37: ='PLANO DENTAL-SAÚDE'!A63 -> 0 | L37: ='PLANO DENTAL-SAÚDE'!B63 -> 50 | M37: ='PLANO DENTAL-SAÚDE'!C63 -> 50 | N37: =SUM(B37:M37) -> 100 | Q37: 390 | R37: 390 | S37: 390 | T37: 390 | U37: 390 | V37: 390 | W37: 390 | X37: 390 | Y37: 390 | Z37: 390 | AA37: =SUM(O37:Z37) -> 3900
A38: Medicamentos | B38: 0 | C38: 0 | D38: 0 | E38: 0 | F38: 0 | G38: 0 | H38: 0 | I38: 0 | J38: 0 | K38: 0 | L38: 0 | M38: 0 | N38: =SUM(B38:M38) -> 0 | AA38: =SUM(O38:Z38) -> 0
A39: Dentista | B39: =DENTISTA!I2 -> 0 | C39: 0 | D39: 0 | E39: 0 | F39: 0 | G39: 0 | H39: 0 | I39: 0 | J39: 0 | K39: 0 | L39: 0 | M39: =DENTISTA!T2 -> 0 | N39: =SUM(B39:M39) -> 0 | O39: =DENTISTA!U2 -> 119 | P39: =DENTISTA!V2 -> 119 | Q39: =DENTISTA!W2 -> 119 | R39: =DENTISTA!X2 -> 119 | S39: =DENTISTA!Y2 -> 119 | T39: =DENTISTA!Z2 -> 119 | U39: =DENTISTA!AA2 -> 119 | V39: =DENTISTA!AB2 -> 119 | ... Z39: =DENTISTA!AF2 -> 119 | AA39: =SUM(O39:Z39) -> 1428
A40: Terapia / Psicólogo / Acupuntura | B40: 0 | C40: 0 | D40: 0 | E40: 0 | F40: 0 | G40: 0 | H40: 0 | I40: 0 | J40: 0 | K40: 0 | L40: 0 | M40: 0 | N40: =SUM(B40:M40) -> 0 | AA40: =SUM(O40:Z40) -> 0
A41: Médicos/Exames fora do plano de saúde | B41: 0 | C41: 0 | D41: 0 | E41: 0 | F41: 0 | G41: 0 | H41: 0 | I41: 0 | J41: 0 | K41: 0 | L41: 0 | M41: 0 | N41: =SUM(B41:M41) -> 0 | AA41: =SUM(O41:Z41) -> 0
...

Sheet DENTISTA
A1: MÊS | B1: 43252 | C1: 43282 | D1: 43313 | E1: 43344 | F1: 43374 | G1: 43405 | H1: 43435 | I1: 43466 | J1: 43497 | K1: 43525 | L1: 43556 | M1: 43586 | N1: 43617 | O1: 43647 | P1: 43678 | Q1: 43709 | R1: 43739 | S1: 43770 | T1: 43800 | U1: 43831 | V1: 43862 | W1: 43891 | X1: 43922 | Y1: 43952 | Z1: 43983 | AA1: 44013 | AB1: 44044 | AC1: 44075 | AD1: 44105 | AE1: 44136 | AF1: 44166
A2: VALOR | B2: 119 | C2: 119 | D2: 119 | E2: 119 | F2: 119 | G2: 119 | H2: 119 | I2: 0 | J2: 0 | K2: 160 | L2: 160 | M2: 160 | N2: 160 | O2: 160 | P2: 160 | Q2: 160 | R2: 160 | S2: 160 | T2: 0 | U2: 119 | V2: 119 | W2: 119 | X2: 119 | Y2: 119 | Z2: 119 | AA2: 119 | AB2: 119 | AC2: 119 | AD2: 119 | AE2: 119 | AF2: 119
A3: DATA DE PAGAMENTO
K5: Adiantamento | L5: =SUM(K2:S2) -> 1440
F8: 26.9
F9: =F8/3 -> 8.9666667 | G9: =83.64+F9 -> 92.606667
F12: =8.97*3 -> 26.91

Sheet Receitaaa x Despesa
A1: Receita | B1: Janeiro | C1: Fevereiro | D1: Março | E1: Abril | F1: Maio | G1: Junho | H1: Julho | I1: Agosto | J1: Setembro | K1: Outubro | L1: Novembro | M1: Dezembro | N1: Total | O1: Janeiro | P1: Fevereiro | Q1: Março | R1: Abril | S1: Maio | T1: Junho | U1: Julho | V1: Agosto | W1: Setembro | X1: Outubro | Y1: Novembro | Z1: Dezembro | AA1: Total
A2: Salário / Adiantamento | B2: 0 | C2: 0 | D2: 0 | E2: 0 | F2: 0 | G2: 0 | H2: 0 | I2: ='PLANO DE SAÚDE'!L11 -> 894.09 | J2: ='PLANO DE SAÚDE'!M9 -> 1151.5494 | K2: ='PLANO DE SAÚDE'!N9 -> 1121.2931 | L2: ='PLANO DE SAÚDE'!O9 -> 1121.2931 | M2: ='PLANO DE SAÚDE'!P9 -> 1121.2931 | N2: =SUM(B2:M2) -> 5409.5187 | Q2: 4000 | R2: 4000 | S2: 4000 | T2: 4000 | U2: 4000 | V2: 4000 | W2: 4000 | X2: 4000 | Y2: 4000 | Z2: 4000 | AA2: =SUM(O2:Z2) -> 40000
A3: Vale Refeição | B3: 0 | C3: 0 | D3: 0 | E3: 0 | F3: 0 | G3: 0 | H3: 0 | I3: 0 | J3: 0 | K3: 250 | L3: 0 | M3: 0 | N3: =SUM(B3:M3) -> 250
A4: Férias | B4: 0 | C4: 0 | D4: 0 | E4: 0 | F4: 0 | G4: 0 | H4: 0 | I4: 0 | K4: 0 | L4: 0 | M4: 0 | N4: =SUM(B4:M4) -> 0 | AA4: =SUM(O4:Z4) -> 0
A5: 13º salário | B5: 0 | C5: 0 | D5: 0 | E5: 0 | F5: 0 | G5: 0 | H5: 0 | I5: 0 | J5: 0 | K5: 0 | L5: 0 | M5: 0 | N5: =SUM(B5:M5) -> 0 | AA5: =SUM(O5:Z5) -> 0
A6: Aposentadoria | B6: 0 | C6: 0 | D6: 0 | E6: 0 | F6: 0 | G6: 0 | H6: 0 | I6: 0 | J6: 1573.69 | K6: 0 | L6: 0 | M6: 0 | N6: =SUM(B6:M6) -> 1573.69 | AA6: =SUM(O6:Z6) -> 0
A7: Receita extra (aluguel, restituição IR) | B7: 0 | C7: 0 | D7: 0 | E7: 0 | F7: 0 | G7: 0 | H7: 0 | I7: =650+260 -> 910 | J7: =650+260 -> 910 | K7: =650 -> 650 | L7: =650 -> 650 | M7: =650 -> 650 | N7: =SUM(B7:M7) -> 3770 | O7: 650 | P7: 650 | Q7: 650 | R7: 650 | S7: 650 | T7: 650 | U7: 650 | V7: 650 | W7: 650 | X7: 650 | Y7: 650 | Z7: 650 | AA7: =SUM(O7:Z7) -> 7800
A8: Outras Receitas | B8: 0 | C8: 0 | D8: 0 | E8: 0 | F8: 0 | G8: 0 | H8: 833 | I8: =510.97+104.83+83.64+113.2+2000+1000+125 -> 3937.64 | J8: =377.24 -> 377.24 | K8: =436.54+500+700 -> 1636.54 | L8: 302.34 | M8: 224.6 | N8: =SUM(B8:M8) -> 7311.36 | AA8: =SUM(O8:Z8) -> 0
A9: Total da Receita Líquida | B9: =SUM(B2:B8) -> 0 | C9: =SUM(C2:C8) -> 0 | D9: =SUM(D2:D8) -> 0 | E9: =SUM(E2:E8) -> 0 | F9: =SUM(F2:F8) -> 0 | G9: =SUM(G2:G8) -> 0 | H9: =SUM(H2:H8) -> 833 | I9: =SUM(I2:I8) -> 5741.73 | ... AA9: =SUM(AA2:AA8) -> 47800
A11: Despesa | B11: Janeiro | C11: Fevereiro | D11: Março | E11: Abril | F11: Maio | G11: Junho | H11: Julho | I11: Agosto | J11: Setembro | K11: Outubro | L11: Novembro | M11: Dezembro | N11: Total | O11: Janeiro | P11: Fevereiro | Q11: Março | R11: Abril | S11: Maio | T11: Junho | U11: Julho | V11: Agosto | W11: Setembro | X11: Outubro | Y11: Novembro | Z11: Dezembro | AA11: Total
A12: Alimentação | B12: =SUM(B13:B17) -> 0 | C12: =SUM(C13:C17) -> 0 | D12: =SUM(D13:D17) -> 0 | E12: =SUM(E13:E17) -> 0 | F12: =SUM(F13:F17) -> 0 | G12: =SUM(G13:G17) -> 0 | H12: =SUM(H13:H17) -> 0 | I12: =SUM(I13:I17) -> 236.65 | ... M12: =SUM(M13:M17) -> 0 | N12: =SUM(B12:M12) -> 486.65 | O12: =SUM(O13:O17) -> 0 | P12: =SUM(P13:P17) -> 0 | Q12: =SUM(Q13:Q17) -> 300 | R12: =SUM(R13:R17) -> 300 | S12: =SUM(S13:S17) -> 300 | T12: =SUM(T13:T17) -> 300 | U12: =SUM(U13:U17) -> 300 | V12: =SUM(V13:V17) -> 300 | ... Z12: =SUM(Z13:Z17) -> 300 | AA12: =SUM(O12:Z12) -> 3000
A13: Supermercado | B13: 0 | C13: 0 | D13: 0 | E13: 0 | F13: 0 | G13: 0 | H13: 0 | I13: 200 | J13: 0 | K13: 250 | L13: 0 | M13: 0 | N13: =SUM(B13:M13) -> 450 | Q13: 300 | R13: 300 | S13: 300 | T13: 300 | U13: 300 | V13: 300 | W13: 300 | X13: 300 | Y13: 300 | Z13: 300 | AA13: =SUM(O13:Z13) -> 3000
A14: Feira / Sacolão | B14: 0 | C14: 0 | D14: 0 | E14: 0 | F14: 0 | G14: 0 | H14: 0 | I14: 0 | J14: 0 | K14: 0 | L14: 0 | M14: 0 | N14: =SUM(B14:M14) -> 0 | AA14: =SUM(O14:Z14) -> 0
A15: Padaria | B15: 0 | C15: 0 | D15: 0 | E15: 0 | F15: 0 | G15: 0 | H15: 0 | I15: 0 | J15: 0 | K15: 0 | L15: 0 | M15: 0 | N15: =SUM(B15:M15) -> 0 | AA15: =SUM(O15:Z15) -> 0
A16: Refeição fora de casa | B16: 0 | C16: 0 | D16: 0 | E16: 0 | F16: 0 | G16: 0 | H16: 0 | I16: 0 | J16: 0 | K16: 0 | L16: 0 | M16: 0 | N16: =SUM(B16:M16) -> 0 | AA16: =SUM(O16:Z16) -> 0
A17: Outros (café, água, sorvetes, etc) | B17: 0 | C17: 0 | D17: 0 | E17: 0 | F17: 0 | G17: 0 | H17: 0 | I17: 36.65 | J17: 0 | K17: 0 | L17: 0 | M17: 0 | N17: =SUM(B17:M17) -> 36.65 | AA17: =SUM(O17:Z17) -> 0
A18: Moradia | B18: =SUM(B19:B30) -> 0 | C18: =SUM(C19:C30) -> 0 | D18: =SUM(D19:D30) -> 0 | E18: =SUM(E19:E30) -> 0 | F18: =SUM(F19:F30) -> 0 | G18: =SUM(G19:G30) -> 0 | H18: =SUM(H19:H30) -> 0 | I18: =SUM(I19:I30) -> 109.99 | ... AA18: =SUM(AA19:AA30) -> 2279.9
A19: Prestação /Aluguel de imóvel | B19: 0 | C19: 0 | D19: 0 | E19: 0 | F19: 0 | G19: 0 | H19: 0 | I19: 0 | J19: 0 | K19: 0 | L19: 0 | M19: 0 | N19: =SUM(B19:M19) -> 0 | AA19: =SUM(O19:Z19) -> 0
A20: Condomínio | B20: 0 | C20: 0 | D20: 0 | E20: 0 | F20: 0 | G20: 0 | H20: 0 | I20: 0 | J20: 0 | K20: 0 | L20: 0 | M20: 0 | N20: =SUM(B20:M20) -> 0 | AA20: =SUM(O20:Z20) -> 0
A21: Consumo de água | B21: 0 | C21: 0 | D21: 0 | E21: 0 | F21: 0 | G21: 0 | H21: 0 | I21: 0 | J21: 0 | K21: 0 | L21: 0 | M21: 0 | N21: =SUM(B21:M21) -> 0 | AA21: =SUM(O21:Z21) -> 0
A22: Serviço de limpeza (diarista ou mensalista) | B22: 0 | C22: 0 | D22: 0 | E22: 0 | F22: 0 | G22: 0 | H22: 0 | I22: 0 | J22: 0 | K22: 0 | L22: 0 | M22: 0 | N22: =SUM(B22:M22) -> 0 | Q22: 140 | R22: 140 | S22: 140 | T22: 140 | U22: 140 | V22: 140 | W22: 140 | X22: 140 | Y22: 140 | Z22: 140 | AA22: =SUM(O22:Z22) -> 1400
A23: Energia Elétrica | B23: 0 | C23: 0 | D23: 0 | E23: 0 | F23: 0 | G23: 0 | H23: 0 | I23: 0 | J23: 0 | K23: 0 | L23: 0 | M23: 0 | N23: =SUM(B23:M23) -> 0 | AA23: =SUM(O23:Z23) -> 0
A24: Gás | B24: 0 | C24: 0 | D24: 0 | E24: 0 | F24: 0 | G24: 0 | H24: 0 | I24: 0 | J24: 0 | K24: 0 | L24: 0 | M24: 0 | N24: =SUM(B24:M24) -> 0 | Q24: 70 | T24: 70 | W24: 70 | Z24: 70 | AA24: =SUM(O24:Z24) -> 280
A25: IPTU | B25: 0 | C25: 0 | D25: 0 | E25: 0 | F25: 0 | G25: 0 | H25: 0 | I25: 0 | J25: 0 | K25: 0 | L25: 0 | M25: 0 | N25: =SUM(B25:M25) -> 0 | AA25: =SUM(O25:Z25) -> 0
A26: Decoração da casa | B26: 0 | C26: 0 | D26: 0 | E26: 0 | F26: 0 | G26: 0 | H26: 0 | I26: 0 | J26: 0 | K26: 0 | L26: 0 | M26: 0 | N26: =SUM(B26:M26) -> 0 | AA26: =SUM(O26:Z26) -> 0
A27: Manutenção / Reforma da casa | B27: 0 | C27: 0 | D27: 0 | E27: 0 | F27: 0 | G27: 0 | H27: 0 | I27: 0 | J27: 0 | K27: 0 | L27: 0 | M27: 0 | N27: =SUM(B27:M27) -> 0 | AA27: =SUM(O27:Z27) -> 0
A28: Celular | B28: 0 | C28: 0 | D28: 0 | E28: 0 | F28: 0 | G28: 0 | H28: 0 | I28: 59.99 | J28: 59.99 | K28: 59.99 | L28: 59.99 | M28: 59.99 | N28: =SUM(B28:M28) -> 299.95 | Q28: 59.99 | R28: 59.99 | S28: 59.99 | T28: 59.99 | U28: 59.99 | V28: 59.99 | W28: 59.99 | X28: 59.99 | Y28: 59.99 | Z28: 59.99 | AA28: =SUM(O28:Z28) -> 599.9
A29: Telefone fixo | B29: 0 | C29: 0 | D29: 0 | E29: 0 | F29: 0 | G29: 0 | H29: 0 | I29: 0 | J29: 0 | K29: 0 | L29: 0 | M29: 0 | N29: =SUM(B29:M29) -> 0 | AA29: =SUM(O29:Z29) -> 0
A30: Internet / TV a cabo | B30: 0 | C30: 0 | D30: 0 | E30: 0 | F30: 0 | G30: 0 | H30: 0 | I30: 50 | J30: 50 | K30: 100 | L30: 50 | M30: 50 | N30: =SUM(B30:M30) -> 300 | AA30: =SUM(O30:Z30) -> 0
A31: Educação | B31: =SUM(B32:B35) -> 0 | C31: =SUM(C32:C35) -> 0 | D31: =SUM(D32:D35) -> 0 | E31: =SUM(E32:E35) -> 0 | F31: =SUM(F32:F35) -> 0 | G31: =SUM(G32:G35) -> 0 | H31: =SUM(H32:H35) -> 0 | I31: =SUM(I32:I35) -> 0 | ... AA31: =SUM(AA32:AA35) -> 7000
A32: Matricula Escolar/ Mensalidade | B32: 0 | C32: 0 | D32: 0 | E32: 0 | F32: 0 | G32: 0 | H32: 0 | I32: 0 | J32: 0 | K32: 0 | L32: 0 | M32: 0 | N32: =SUM(B32:M32) -> 0 | Q32: 700 | R32: 700 | S32: 700 | T32: 700 | U32: 700 | V32: 700 | W32: 700 | X32: 700 | Y32: 700 | Z32: 700 | AA32: =SUM(O32:Z32) -> 7000
A33: Material Escolar | B33: 0 | C33: 0 | D33: 0 | E33: 0 | F33: 0 | G33: 0 | H33: 0 | I33: 0 | J33: 0 | K33: 0 | L33: 0 | M33: 0 | N33: =SUM(B33:M33) -> 0 | AA33: =SUM(O33:Z33) -> 0
A34: Outros cursos | B34: 0 | C34: 0 | D34: 0 | E34: 0 | F34: 0 | G34: 0 | H34: 0 | I34: 0 | J34: 0 | K34: 0 | L34: 0 | M34: 0 | N34: =SUM(B34:M34) -> 0 | AA34: =SUM(O34:Z34) -> 0
A35: Transporte escolar | B35: 0 | C35: 0 | D35: 0 | E35: 0 | F35: 0 | G35: 0 | H35: 0 | I35: 0 | J35: 0 | K35: 0 | L35: 0 | M35: 0 | N35: =SUM(B35:M35) -> 0 | AA35: =SUM(O35:Z35) -> 0
A36: Animal de Estimação | B36: =SUM(B37:B40) -> 0 | C36: =SUM(C37:C40) -> 0 | D36: =SUM(D37:D40) -> 0 | E36: =SUM(E37:E40) -> 0 | F36: =SUM(F37:F40) -> 0 | G36: =SUM(G37:G40) -> 0 | H36: =SUM(H37:H40) -> 0 | I36: =SUM(I37:I40) -> 0 | ... AA36: =SUM(AA37:AA40) -> 0
A37: Ração | B37: 0 | C37: 0 | D37: 0 | E37: 0 | F37: 0 | G37: 0 | H37: 0 | I37: 0 | J37: 0 | K37: 0 | L37: 0 | M37: 0 | N37: =SUM(B37:M37) -> 0 | AA37: =SUM(O37:Z37) -> 0
A38: Banho / Tosa | B38: 0 | C38: 0 | D38: 0 | E38: 0 | F38: 0 | G38: 0 | H38: 0 | I38: 0 | J38: 0 | K38: 0 | L38: 0 | M38: 0 | N38: =SUM(B38:M38) -> 0 | AA38: =SUM(O38:Z38) -> 0
A39: Veterinário / medicamento | B39: 0 | C39: 0 | D39: 0 | E39: 0 | F39: 0 | G39: 0 | H39: 0 | I39: 0 | J39: 0 | K39: 0 | L39: 0 | M39: 0 | N39: =SUM(B39:M39) -> 0 | AA39: =SUM(O39:Z39) -> 0
A40: Outros (acessórios, brinquedos, hotel, dog walker) | B40: 0 | C40: 0 | D40: 0 | E40: 0 | F40: 0 | G40: 0 | H40: 0 | I40: 0 | J40: 0 | K40: 0 | L40: 0 | M40: 0 | N40: =SUM(B40:M40) -> 0 | AA40: =SUM(O40:Z40) -> 0
A41: Saúde | B41: =SUM(B42:B47) -> 0 | C41: =SUM(C42:C47) -> 0 | D41: =SUM(D42:D47) -> 160 | E41: =SUM(E42:E47) -> 160 | F41: =SUM(F42:F47) -> 160 | G41: =SUM(G42:G47) -> 160 | H41: =SUM(H42:H47) -> 160 | I41: =SUM(I42:I47) -> 160 | ... AA41: =SUM(AA42:AA47) -> 6128
...

Sheet ADIANTAMENTOS
B1: EMPRSTIMOS | C1: =#REF! -> #REF!
B2: CARTÃO DE CRÉDITO | C2: ='CARTÃO DE CRÉDITO - OUTROS'!#REF! -> #REF!
B3: DENTISTA | C3: =DENTISTA!L5 -> 1440
C4: =SUM(C1:C3) -> #REF!
E5: 7000
E6: =C4-E5 -> #REF!

Sheet VT E VR
A1: SETEMBRO | G1: OUTUBRO
A2: Dia | B2: DATA | C2: VT | D2: VR | G2: Dia | H2: DATA | I2: VT | J2: VR
A3: Segunda-feira | B3: 43717 | C3: =4.05*2 -> 8.1 | D3: 25 | G3: Segunda-feira | H3: 43752 | I3: =4.05*2 -> 8.1 | J3: 25 | K3: =SUM(J3:J12) -> 250
A4: Terça-feira | B4: 43718 | C4: =4.05*2 -> 8.1 | D4: 25 | G4: Terça-feira | H4: 43753 | I4: =4.05*2 -> 8.1 | J4: 25 | K4: 0.18
A5: Quarta-feira | B5: 43719 | C5: =4.05*2 -> 8.1 | D5: 25 | G5: Quarta-feira | H5: 43754 | I5: =4.05*2 -> 8.1 | J5: 25 | K5: =K3*K4 -> 45
A6: Quinta-feira | B6: 43720 | C6: =4.05*2 -> 8.1 | D6: 25 | G6: Quinta-feira | H6: 43755 | I6: =4.05*2 -> 8.1 | J6: 25 | K6: =K3-K5 -> 205
A7: Sexta-feira | B7: 43721 | C7: =4.05*2 -> 8.1 | D7: 25 | G7: Sexta-feira | H7: 43756 | I7: =4.05*2 -> 8.1 | J7: 25
A8: Segunda-feira | B8: 43724 | C8: =4.05*2 -> 8.1 | D8: 25 | G8: Segunda-feira | H8: 43759 | I8: =4.05*2 -> 8.1 | J8: 25
A9: Terça-feira | B9: 43725 | C9: =4.05*2 -> 8.1 | D9: 25 | G9: Terça-feira | H9: 43760 | I9: =4.05*2 -> 8.1 | J9: 25
A10: Quarta-feira | B10: 43726 | C10: =4.05*2 -> 8.1 | D10: 25 | G10: Quarta-feira | H10: 43761 | I10: =4.05*2 -> 8.1 | J10: 25
A11: Quinta-feira | B11: 43727 | C11: =4.05*2 -> 8.1 | D11: 25 | G11: Quinta-feira | H11: 43762 | I11: =4.05*2 -> 8.1 | J11: 25
A12: Sexta-feira | B12: 43728 | E12: FALTA | G12: Sexta-feira | H12: 43763 | I12: =4.05*2 -> 8.1 | J12: 25
A13: Segunda-feira | B13: 43731 | E13: FALTA | G13: Segunda-feira | H13: 43766 | I13: =4.05*2 -> 8.1 | J13: 25
A14: Terça-feira | B14: 43732 | E14: FALTA | G14: Terça-feira | H14: 43767 | I14: =4.05*2 -> 8.1 | J14: 25
A15: Quarta-feira | B15: 43733 | E15: FALTA | G15: Quarta-feira | H15: 43768 | I15: =4.05*2 -> 8.1 | J15: 25
A16: Quinta-feira | B16: 43734 | E16: FALTA | G16: Quinta-feira | H16: 43769 | I16: =4.05*2 -> 8.1 | J16: 25
A17: Sexta-feira | B17: 43735 | C17: =4.05*2 -> 8.1 | D17: 25 | G17: Sexta-feira | H17: 43770 | I17: =4.05*2 -> 8.1 | J17: 25
A18: Segunda-feira | B18: 43738 | C18: =4.05*2 -> 8.1 | D18: 25 | G18: Segunda-feira | H18: 43773 | I18: =4.05*2 -> 8.1 | J18: 25
A19: Terça-feira | B19: 43739 | C19: =4.05*2 -> 8.1 | D19: 25 | G19: Terça-feira | H19: 43774 | I19: =4.05*2 -> 8.1 | J19: 25
A20: Quarta-feira | B20: 43740 | C20: =4.05*2 -> 8.1 | D20: 25 | G20: Quarta-feira | H20: 43775 | I20: =4.05*2 -> 8.1 | J20: 25
A21: Quinta-feira | B21: 43741 | C21: =4.05*2 -> 8.1 | D21: 25 | G21: Quinta-feira | H21: 43776 | I21: =4.05*2 -> 8.1 | J21: 25
A22: Sexta-feira | B22: 43742 | C22: =4.05*2 -> 8.1 | D22: 25 | G22: Sexta-feira | H22: 43777 | I22: =4.05*2 -> 8.1 | J22: 25
A23: Segunda-feira | B23: 43745 | C23: =4.05*2 -> 8.1 | D23: 25
A24: Terça-feira | B24: 43746 | C24: =4.05*2 -> 8.1 | D24: 25
A25: Quarta-feira | B25: 43747 | C25: =4.05*2 -> 8.1 | D25: 25
A26: Quinta-feira | B26: 43748 | C26: =4.05*2 -> 8.1 | D26: 25
A27: Sexta-feira | B27: 43749 | C27: =4.05*2 -> 8.1
A28: Total Setembro | C28: =SUM(C3:C27) -> 162 | D28: =SUM(D3:D26) -> 475 | G28: Total Setembro | I28: =SUM(I3:I27) -> 162 | J28: =SUM(J3:J26) -> 500

Sheet PLANO DE SAÚDE
A1: MÊS DE AQUISIÇÃO | B1: 43631 | C1: Valor Total | D1: 246.42
A2: Mês | B2: Valor Total | C2: Valor Cooparticipação | D2: Taxa | E2: Valor a ser descontado | G2: Descrição | H2: Abril | I2: Maio | J2: Junho | K2: Julho | L2: Agosto | M2: Setembro | N2: Outubro | O2: Novembro | P2: Dezembro
A3: Junho | B3: =C3*2 -> 243.1 | C3: 121.55 | D3: 0 | E3: =C3+D3 -> 121.55 | F3: =E4-E3 -> 12.66 | G3: SALÁRIO | H3: 1327.04 | I3: 1327.04 | J3: 1327.04 | K3: 1327.04 | L3: 1327.04 | M3: 1406.6624 | N3: 1366.8512 | O3: 1366.8512 | P3: 1366.8512
A4: Julho | B4: =$D$1 -> 246.42 | C4: =B4/2 -> 123.21 | D4: 11 | E4: =C4+D4 -> 134.21 | G4: VT | H4: 1 | I4: 1 | J4: 1 | K4: 1 | L4: 1 | M4: 1 | N4: 1 | O4: 1 | P4: 1
A5: Agosto | B5: =$D$1 -> 246.42 | C5: =B5/2 -> 123.21 | D5: 11 | E5: =C5+D5 -> 134.21 | G5: VR | H5: 1 | I5: 1 | J5: 1 | K5: 1 | L5: 1 | M5: 7.37 | N5: 1 | O5: 1 | P5: 1
A6: Setembro | B6: =$D$1 -> 246.42 | C6: =B6/2 -> 123.21 | D6: 11 | E6: =C6+D6 -> 134.21 | G6: INSS | H6: =H3*8% -> 106.1632 | I6: =I3*8% -> 106.1632 | J6: =J3*8% -> 106.1632 | K6: =K3*8% -> 106.1632 | L6: =L3*8% -> 106.1632 | M6: =M3*8% -> 112.53299 | N6: =N3*8% -> 109.3481 | O6: =O3*8% -> 109.3481 | P6: =P3*8% -> 109.3481
A7: Outubro | B7: =$D$1 -> 246.42 | C7: =B7/2 -> 123.21 | D7: 11 | E7: =C7+D7 -> 134.21 | G7: TOTAL | H7: =H3-H4-H5-H6 -> 1218.8768 | I7: =I3-I4-I5-I6 -> 1218.8768 | J7: =J3-J4-J5-J6 -> 1218.8768 | K7: =K3-K4-K5-K6 -> 1218.8768 | L7: =L3-L4-L5-L6 -> 1218.8768 | M7: =M3-M4-M5-M6 -> 1285.7594 | N7: =N3-N4-N5-N6 -> 1255.5031 | O7: =O3-O4-O5-O6 -> 1255.5031 | P7: =P3-P4-P5-P6 -> 1255.5031
A8: Novembro | B8: =$D$1 -> 246.42 | C8: =B8/2 -> 123.21 | D8: 11 | E8: =C8+D8 -> 134.21 | G8: PLANO DE SAÚDE | H8: 0 | I8: 0 | J8: 0 | K8: =E3 -> 121.55 | L8: =SUM(E4:E5) -> 268.42 | M8: =E6 -> 134.21 | N8: =E7 -> 134.21 | O8: =E8 -> 134.21 | P8: =E9 -> 134.21
A9: Dezembro | B9: =$D$1 -> 246.42 | C9: =B9/2 -> 123.21 | D9: 11 | E9: =C9+D9 -> 134.21 | G9: SALÁRIO A RECEBER | H9: =H7-H8 -> 1218.8768 | I9: =I7-I8 -> 1218.8768 | J9: =J7-J8 -> 1218.8768 | K9: =K7-K8 -> 1097.3268 | L9: =L7-L8 -> 950.4568 | M9: =M7-M8 -> 1151.5494 | N9: =N7-N8 -> 1121.2931 | O9: =O7-O8 -> 1121.2931 | P9: =P7-P8 -> 1121.2931
G11: SALÁRIO RECEBIDO | H11: 1220.88 | I11: 1218.88 | J11: 1218.88 | K11: 1097.33 | L11: =759.78+K16 -> 894.09
G13: DIFERENÇA | H13: =H11-H9 -> 2.0032 | I13: =I11-I9 -> 0.0032 | J13: =J11-J9 -> 0.0032 | K13: =K11-K9 -> 0.0032 | L13: =L11-L9 -> -56.3668 | M13: =M11-M9 -> -1151.5494 | N13: =N11-N9 -> -1121.2931 | O13: =O11-O9 -> -1121.2931 | P13: =P11-P9 -> -1121.2931
I15: julho | K15: 324.79
I16: julho | K16: 134.31
E17: 1327.04 | F17: 1 | I17: total desc. | K17: =K15+K16 -> 459.1
B18: DISSIDIO | E18: 106.16 | F18: =E18*F17 -> 106.16 | I18: DIFERENÇA A SER DEVOLVIDA | K18: =K17-L8 -> 190.68
B19: 0.03 | F19: =F18/E17 -> 0.079997589
B20: =L3 -> 1327.04 | F20: =E17*F19 -> 106.16
B21: AGOSTO | C21: SETEMBRO
B22: =B20*B19 -> 39.8112 | C22: =B20*B19 -> 39.8112 | F22: =C24*F19 -> 112.5296 | G22: =F22-F20 -> 6.3696
B23: =B20+B22 -> 1366.8512 | C23: =B20+C22 -> 1366.8512
C24: =C23+B22 -> 1406.6624
