Workbook
Name CANAIS: [1]Registros!$D$4:$D$13
Name CLIENTES: [1]Registros!$D$16:$D$1048576
Name FORMASPGTO: [1]Registros!$G$4:$G$11
Name MESES: [1]Registros!$I$15:$I$26
Name PRODUTOS: [1]Registros!$A$4:$A$500

Sheet Início
A1: FOLHA DE PAGAMENTO - INÍCIO

Sheet Tabulação
A1: FOLHA DE PAGAMENTO - TABULAÇÃO
A3: MÊS | B3: DATAINICIO | C3: DATAFIM | D3: FERIADOS/RECESSO | J3: DIAS ÚTEIS
C4: =B4+30 -> 30 | J4: =NETWORKDAYS(B4,C4,D4:I4) -> 21
C5: =B5+27 -> 27 | J5: =NETWORKDAYS(B5,C5,D5:I5) -> 20
C6: =B6+30 -> 30 | J6: =NETWORKDAYS(B6,C6,D6:I6) -> 21
C7: =B7+29 -> 29 | J7: =NETWORKDAYS(B7,C7,D7:I7) -> 20
C8: =B8+30 -> 30 | J8: =NETWORKDAYS(B8,C8,D8:I8) -> 21
C9: =B9+29 -> 29 | J9: =NETWORKDAYS(B9,C9,D9:I9) -> 20
C10: =B10+30 -> 30 | J10: =NETWORKDAYS(B10,C10,D10:I10) -> 21
C11: =B11+30 -> 30 | J11: =NETWORKDAYS(B11,C11,D11:I11) -> 21
C12: =B12+29 -> 29 | J12: =NETWORKDAYS(B12,C12,D12:I12) -> 20
C13: =B13+30 -> 30 | J13: =NETWORKDAYS(B13,C13,D13:I13) -> 21
C14: =B14+29 -> 29 | J14: =NETWORKDAYS(B14,C14,D14:I14) -> 20
C15: =B15+30 -> 30 | J15: =NETWORKDAYS(B15,C15,D15:I15) -> 21
C18: PREÇO DA PASSAGEM: | D18: 2.1
A19: FUNCIONÁRIO | B19: CARGO/FUNÇÃO | C19: FORMAÇÃO | D19: QUANTIDADE DE VIAGENS | E19: AUXILIO TRANSPORTE/DIA | G19: TABELA IR | J19: PARCELA A DESCONTAR
E20: =$D$18*D20 -> 0 | G20: 0 | H20: 1787.77 | I20: 0 | J20: 0
E21: =$D$18*D21 -> 0 | G21: 1787.78 | H21: 2679.29 | I21: 0.075 | J21: 134.08
E22: =$D$18*D22 -> 0 | G22: 2679.3 | H22: 3572.43 | I22: 0.15 | J22: 335.03
E23: =$D$18*D23 -> 0 | G23: 3572.44 | H23: 4463.81 | I23: 0.225 | J23: 602.96
E24: =$D$18*D24 -> 0 | G24: 4463.82 | H24: Acima | I24: 0.275 | J24: 826.15
E25: =$D$18*D25 -> 0 | G25: TABELAS INSS
E26: =$D$18*D26 -> 0 | G26: R$- | H26: 1317.07 | I26: 0.08
E27: =$D$18*D27 -> 0 | G27: 1317.08 | H27: 2195.12 | I27: 0.09
E28: =$D$18*D28 -> 0 | G28: 2195.13 | H28: 4390.24 | I28: 0.11
E29: =$D$18*D29 -> 0 | G29: 4390.24 | H29: Acima | I29: =G29*I28 -> 482.9264
E30: =$D$18*D30 -> 0 | G30: ENCARGOS
E31: =$D$18*D31 -> 0 | G31: INSS Empresa | H31: 0.258
E32: =$D$18*D32 -> 0 | G32: SAT | H32: 0.02
E33: =$D$18*D33 -> 0 | G33: FGTS | H33: 0.08
E34: =$D$18*D34 -> 0
E35: =$D$18*D35 -> 0
E36: =$D$18*D36 -> 0
E37: =$D$18*D37 -> 0
E38: =$D$18*D38 -> 0
E39: =$D$18*D39 -> 0
E40: =$D$18*D40 -> 0
E41: =$D$18*D41 -> 0
E42: =$D$18*D42 -> 0
E43: =$D$18*D43 -> 0
...

Sheet Pagamentos
A1: FOLHA DE PAGAMENTO - PAGAMENTOS
A3: FUNCIONÁRIO | B3: CARGO/FUNÇÃO | C3: JANEIRO | D3: FEVEREIRO | E3: MARÇO | F3: ABRIL | G3: MAIO | H3: JUNHO | I3: JULHO | J3: AGOSTO | K3: SETEMBRO | L3: OUTUBRO | M3: NOVEMBRO | N3: DEZEMBRO | O3: 13º | P3: TOTAL
C4: =COLUMN(C3)-1 -> 2 | D4: =COLUMN(D3)-1 -> 3 | E4: =COLUMN(E3)-1 -> 4 | F4: =COLUMN(F3)-1 -> 5 | G4: =COLUMN(G3)-1 -> 6 | H4: =COLUMN(H3)-1 -> 7 | I4: =COLUMN(I3)-1 -> 8 | J4: =COLUMN(J3)-1 -> 9 | ... P4: =COLUMN(P3)-1 -> 15
A5: SALÁRIO BRUTO | C5: SALÁRIO BRUTO
A6: =IF($A40="","",$A40) | B6: =IF($B40="","",$B40) | C6: =C40+C74 -> 0 | D6: =D40+D74 -> 0 | E6: =E40+E74 -> 0 | F6: =F40+F74 -> 0 | G6: =G40+G74 -> 0 | H6: =H40+H74 -> 0 | I6: =I40+I74 -> 0 | J6: =J40+J74 -> 0 | ... N6: =N40+N74 -> 0 | O6: =IF(COUNTIF(C40:N40,">0")>0,(SUM(C40:N40)+SUM(C74:N74))/COUNTIF(C40:N40,">0"),0) -> 0 | P6: =SUM(C6:N6) -> 0
A7: =IF($A41="","",$A41) | B7: =IF($B41="","",$B41) | C7: =C41+C75 -> 0 | D7: =D41+D75 -> 0 | E7: =E41+E75 -> 0 | F7: =F41+F75 -> 0 | G7: =G41+G75 -> 0 | H7: =H41+H75 -> 0 | I7: =I41+I75 -> 0 | J7: =J41+J75 -> 0 | ... N7: =N41+N75 -> 0 | O7: =IF(COUNTIF(C41:N41,">0")>0,(SUM(C41:N41)+SUM(C75:N75))/COUNTIF(C41:N41,">0"),0) -> 0 | P7: =SUM(C7:N7) -> 0
A8: =IF($A42="","",$A42) | B8: =IF($B42="","",$B42) | C8: =C42+C76 -> 0 | D8: =D42+D76 -> 0 | E8: =E42+E76 -> 0 | F8: =F42+F76 -> 0 | G8: =G42+G76 -> 0 | H8: =H42+H76 -> 0 | I8: =I42+I76 -> 0 | J8: =J42+J76 -> 0 | ... N8: =N42+N76 -> 0 | O8: =IF(COUNTIF(C42:N42,">0")>0,(SUM(C42:N42)+SUM(C76:N76))/COUNTIF(C42:N42,">0"),0) -> 0 | P8: =SUM(C8:N8) -> 0
A9: =IF($A43="","",$A43) | B9: =IF($B43="","",$B43) | C9: =C43+C77 -> 0 | D9: =D43+D77 -> 0 | E9: =E43+E77 -> 0 | F9: =F43+F77 -> 0 | G9: =G43+G77 -> 0 | H9: =H43+H77 -> 0 | I9: =I43+I77 -> 0 | J9: =J43+J77 -> 0 | ... N9: =N43+N77 -> 0 | O9: =IF(COUNTIF(C43:N43,">0")>0,(SUM(C43:N43)+SUM(C77:N77))/COUNTIF(C43:N43,">0"),0) -> 0 | P9: =SUM(C9:N9) -> 0
A10: =IF($A44="","",$A44) | B10: =IF($B44="","",$B44) | C10: =C44+C78 -> 0 | D10: =D44+D78 -> 0 | E10: =E44+E78 -> 0 | F10: =F44+F78 -> 0 | G10: =G44+G78 -> 0 | H10: =H44+H78 -> 0 | I10: =I44+I78 -> 0 | J10: =J44+J78 -> 0 | ... N10: =N44+N78 -> 0 | O10: =IF(COUNTIF(C44:N44,">0")>0,(SUM(C44:N44)+SUM(C78:N78))/COUNTIF(C44:N44,">0"),0) -> 0 | P10: =SUM(C10:N10) -> 0
A11: =IF($A45="","",$A45) | B11: =IF($B45="","",$B45) | C11: =C45+C79 -> 0 | D11: =D45+D79 -> 0 | E11: =E45+E79 -> 0 | F11: =F45+F79 -> 0 | G11: =G45+G79 -> 0 | H11: =H45+H79 -> 0 | I11: =I45+I79 -> 0 | J11: =J45+J79 -> 0 | ... N11: =N45+N79 -> 0 | O11: =IF(COUNTIF(C45:N45,">0")>0,(SUM(C45:N45)+SUM(C79:N79))/COUNTIF(C45:N45,">0"),0) -> 0 | P11: =SUM(C11:N11) -> 0
A12: =IF($A46="","",$A46) | B12: =IF($B46="","",$B46) | C12: =C46+C80 -> 0 | D12: =D46+D80 -> 0 | E12: =E46+E80 -> 0 | F12: =F46+F80 -> 0 | G12: =G46+G80 -> 0 | H12: =H46+H80 -> 0 | I12: =I46+I80 -> 0 | J12: =J46+J80 -> 0 | ... N12: =N46+N80 -> 0 | O12: =IF(COUNTIF(C46:N46,">0")>0,(SUM(C46:N46)+SUM(C80:N80))/COUNTIF(C46:N46,">0"),0) -> 0 | P12: =SUM(C12:N12) -> 0
A13: =IF($A47="","",$A47) | B13: =IF($B47="","",$B47) | C13: =C47+C81 -> 0 | D13: =D47+D81 -> 0 | E13: =E47+E81 -> 0 | F13: =F47+F81 -> 0 | G13: =G47+G81 -> 0 | H13: =H47+H81 -> 0 | I13: =I47+I81 -> 0 | J13: =J47+J81 -> 0 | ... N13: =N47+N81 -> 0 | O13: =IF(COUNTIF(C47:N47,">0")>0,(SUM(C47:N47)+SUM(C81:N81))/COUNTIF(C47:N47,">0"),0) -> 0 | P13: =SUM(C13:N13) -> 0
A14: =IF($A48="","",$A48) | B14: =IF($B48="","",$B48) | C14: =C48+C82 -> 0 | D14: =D48+D82 -> 0 | E14: =E48+E82 -> 0 | F14: =F48+F82 -> 0 | G14: =G48+G82 -> 0 | H14: =H48+H82 -> 0 | I14: =I48+I82 -> 0 | J14: =J48+J82 -> 0 | ... N14: =N48+N82 -> 0 | O14: =IF(COUNTIF(C48:N48,">0")>0,(SUM(C48:N48)+SUM(C82:N82))/COUNTIF(C48:N48,">0"),0) -> 0 | P14: =SUM(C14:N14) -> 0
A15: =IF($A49="","",$A49) | B15: =IF($B49="","",$B49) | C15: =C49+C83 -> 0 | D15: =D49+D83 -> 0 | E15: =E49+E83 -> 0 | F15: =F49+F83 -> 0 | G15: =G49+G83 -> 0 | H15: =H49+H83 -> 0 | I15: =I49+I83 -> 0 | J15: =J49+J83 -> 0 | ... N15: =N49+N83 -> 0 | O15: =IF(COUNTIF(C49:N49,">0")>0,(SUM(C49:N49)+SUM(C83:N83))/COUNTIF(C49:N49,">0"),0) -> 0 | P15: =SUM(C15:N15) -> 0
A16: =IF($A50="","",$A50) | B16: =IF($B50="","",$B50) | C16: =C50+C84 -> 0 | D16: =D50+D84 -> 0 | E16: =E50+E84 -> 0 | F16: =F50+F84 -> 0 | G16: =G50+G84 -> 0 | H16: =H50+H84 -> 0 | I16: =I50+I84 -> 0 | J16: =J50+J84 -> 0 | ... N16: =N50+N84 -> 0 | O16: =IF(COUNTIF(C50:N50,">0")>0,(SUM(C50:N50)+SUM(C84:N84))/COUNTIF(C50:N50,">0"),0) -> 0 | P16: =SUM(C16:N16) -> 0
A17: =IF($A51="","",$A51) | B17: =IF($B51="","",$B51) | C17: =C51+C85 -> 0 | D17: =D51+D85 -> 0 | E17: =E51+E85 -> 0 | F17: =F51+F85 -> 0 | G17: =G51+G85 -> 0 | H17: =H51+H85 -> 0 | I17: =I51+I85 -> 0 | J17: =J51+J85 -> 0 | ... N17: =N51+N85 -> 0 | O17: =IF(COUNTIF(C51:N51,">0")>0,(SUM(C51:N51)+SUM(C85:N85))/COUNTIF(C51:N51,">0"),0) -> 0 | P17: =SUM(C17:N17) -> 0
... A36: =IF($A70="","",$A70) | B36: =IF($B70="","",$B70) | C36: =C70+C104 -> 0 | D36: =D70+D104 -> 0 | E36: =E70+E104 -> 0 | F36: =F70+F104 -> 0 | G36: =G70+G104 -> 0 | H36: =H70+H104 -> 0 | I36: =I70+I104 -> 0 | J36: =J70+J104 -> 0 | ... N36: =N70+N104 -> 0 | O36: =IF(COUNTIF(C70:N70,">0")>0,(SUM(C70:N70)+SUM(C104:N104))/COUNTIF(C70:N70,">0"),0) -> 0 | P36: =SUM(C36:N36) -> 0
A37: TOTAL | C37: =SUM(C6:C36) -> 0 | D37: =SUM(D6:D36) -> 0 | E37: =SUM(E6:E36) -> 0 | F37: =SUM(F6:F36) -> 0 | G37: =SUM(G6:G36) -> 0 | H37: =SUM(H6:H36) -> 0 | I37: =SUM(I6:I36) -> 0 | J37: =SUM(J6:J36) -> 0 | ... P37: =SUM(P6:P36) -> 0
A39: SALÁRIO BASE | C39: SALÁRIO BASE
A40: =IF(Tabulação!A20<>"",Tabulação!A20,"") | B40: =IF(Tabulação!B20<>"",Tabulação!B20,"") | P40: =SUM(C40:O40) -> 0
A41: =IF(Tabulação!A21<>"",Tabulação!A21,"") | B41: =IF(Tabulação!B21<>"",Tabulação!B21,"") | P41: =SUM(C41:N41) -> 0
A42: =IF(Tabulação!A22<>"",Tabulação!A22,"") | B42: =IF(Tabulação!B22<>"",Tabulação!B22,"") | P42: =SUM(C42:N42) -> 0
A43: =IF(Tabulação!A23<>"",Tabulação!A23,"") | B43: =IF(Tabulação!B23<>"",Tabulação!B23,"") | P43: =SUM(C43:N43) -> 0
A44: =IF(Tabulação!A24<>"",Tabulação!A24,"") | B44: =IF(Tabulação!B24<>"",Tabulação!B24,"") | P44: =SUM(C44:N44) -> 0
A45: =IF(Tabulação!A25<>"",Tabulação!A25,"") | B45: =IF(Tabulação!B25<>"",Tabulação!B25,"") | P45: =SUM(C45:N45) -> 0
A46: =IF(Tabulação!A26<>"",Tabulação!A26,"") | B46: =IF(Tabulação!B26<>"",Tabulação!B26,"") | P46: =SUM(C46:N46) -> 0
A47: =IF(Tabulação!A27<>"",Tabulação!A27,"") | B47: =IF(Tabulação!B27<>"",Tabulação!B27,"") | P47: =SUM(C47:N47) -> 0
A48: =IF(Tabulação!A28<>"",Tabulação!A28,"") | B48: =IF(Tabulação!B28<>"",Tabulação!B28,"") | P48: =SUM(C48:N48) -> 0
A49: =IF(Tabulação!A29<>"",Tabulação!A29,"") | B49: =IF(Tabulação!B29<>"",Tabulação!B29,"") | P49: =SUM(C49:N49) -> 0
A50: =IF(Tabulação!A30<>"",Tabulação!A30,"") | B50: =IF(Tabulação!B30<>"",Tabulação!B30,"") | P50: =SUM(C50:N50) -> 0
A51: =IF(Tabulação!A31<>"",Tabulação!A31,"") | B51: =IF(Tabulação!B31<>"",Tabulação!B31,"") | P51: =SUM(C51:N51) -> 0
A52: =IF(Tabulação!A32<>"",Tabulação!A32,"") | B52: =IF(Tabulação!B32<>"",Tabulação!B32,"") | P52: =SUM(C52:N52) -> 0
... A70: =IF(Tabulação!A50<>"",Tabulação!A50,"") | B70: =IF(Tabulação!B50<>"",Tabulação!B50,"") | P70: =SUM(C70:N70) -> 0
A71: TOTAL | C71: =SUM(C40:C70) -> 0 | D71: =SUM(D40:D70) -> 0 | E71: =SUM(E40:E70) -> 0 | F71: =SUM(F40:F70) -> 0 | G71: =SUM(G40:G70) -> 0 | H71: =SUM(H40:H70) -> 0 | I71: =SUM(I40:I70) -> 0 | J71: =SUM(J40:J70) -> 0 | ... N71: =SUM(N40:N70) -> 0 | P71: =SUM(P40:P70) -> 0
A73: PARTICIPAÇÃO NOS RESULTADOS/ADICIONAIS | C73: PARTICIPAÇÃO NOS RESULTADOS/ADICIONAIS
A74: =IF($A40="","",$A40) | B74: =IF($B40="","",$B40) | P74: =SUM(C74:O74) -> 0
A75: =IF($A41="","",$A41) | B75: =IF($B41="","",$B41) | P75: =SUM(C75:N75) -> 0
A76: =IF($A42="","",$A42) | B76: =IF($B42="","",$B42) | P76: =SUM(C76:N76) -> 0
A77: =IF($A43="","",$A43) | B77: =IF($B43="","",$B43) | P77: =SUM(C77:N77) -> 0
A78: =IF($A44="","",$A44) | B78: =IF($B44="","",$B44) | P78: =SUM(C78:N78) -> 0
...

Sheet Gráficos
A1: FOLHA DE PAGAMENTO - GRÁFICOS
A4: SELECIONE O MÊS: | B4: FEVEREIRO
D8: =CONCATENATE("Total pago pela empresa no mês de"," ",B4) -> Total pago pela empresa no mês de FEVEREIRO
C9: SALÁRIO LÍQUIDO | D9: =VLOOKUP(C9,Pagamentos!$B:$P,HLOOKUP($B$4,Pagamentos!$3:$4,2,0),0) -> 0
C10: INSS | D10: =VLOOKUP(C10,Pagamentos!$B:$P,HLOOKUP($B$4,Pagamentos!$3:$4,2,0),0) -> 0
C11: IR | D11: =VLOOKUP(C11,Pagamentos!$B:$P,HLOOKUP($B$4,Pagamentos!$3:$4,2,0),0) -> 0
C12: TRANSPORTE | D12: =VLOOKUP(C12,Pagamentos!$B:$P,HLOOKUP($B$4,Pagamentos!$3:$4,2,0),0) -> 0
C13: INSS PAGO PELA EMPRESA | D13: =VLOOKUP(C13,Pagamentos!$B:$P,HLOOKUP($B$4,Pagamentos!$3:$4,2,0),0) -> 0
C14: FGTS | D14: =VLOOKUP(C14,Pagamentos!$B:$P,HLOOKUP($B$4,Pagamentos!$3:$4,2,0),0) -> 0
C15: SAT | D15: =VLOOKUP(C15,Pagamentos!$B:$P,HLOOKUP($B$4,Pagamentos!$3:$4,2,0),0) -> 0
A36: SELECIONE O MÊS: | B36: FEVEREIRO
C38: =CONCATENATE("Participação nos resultados/Adicionais:"," ",B36) -> Participação nos resultados/Adicionais: FEVEREIRO
B39: =IF(Tabulação!A20<>"",Tabulação!A20,"") | C39: =IF(VLOOKUP(B39,Pagamentos!$A$74:$P$104,HLOOKUP($B$36,Pagamentos!$3:$4,2,0)+1,0)<>0,VLOOKUP(B39,Pagamentos!$A$74:$P$104,HLOOKUP($B$36,Pagamentos!$3:$4,2,0)+1,0),"")
B40: =IF(Tabulação!A21<>"",Tabulação!A21,"") | C40: =IF(VLOOKUP(B40,Pagamentos!$A$74:$P$104,HLOOKUP($B$36,Pagamentos!$3:$4,2,0)+1,0)<>0,VLOOKUP(B40,Pagamentos!$A$74:$P$104,HLOOKUP($B$36,Pagamentos!$3:$4,2,0)+1,0),"")
B41: =IF(Tabulação!A22<>"",Tabulação!A22,"") | C41: =IF(VLOOKUP(B41,Pagamentos!$A$74:$P$104,HLOOKUP($B$36,Pagamentos!$3:$4,2,0)+1,0)<>0,VLOOKUP(B41,Pagamentos!$A$74:$P$104,HLOOKUP($B$36,Pagamentos!$3:$4,2,0)+1,0),"")
B42: =IF(Tabulação!A23<>"",Tabulação!A23,"") | C42: =IF(VLOOKUP(B42,Pagamentos!$A$74:$P$104,HLOOKUP($B$36,Pagamentos!$3:$4,2,0)+1,0)<>0,VLOOKUP(B42,Pagamentos!$A$74:$P$104,HLOOKUP($B$36,Pagamentos!$3:$4,2,0)+1,0),"")
B43: =IF(Tabulação!A24<>"",Tabulação!A24,"") | C43: =IF(VLOOKUP(B43,Pagamentos!$A$74:$P$104,HLOOKUP($B$36,Pagamentos!$3:$4,2,0)+1,0)<>0,VLOOKUP(B43,Pagamentos!$A$74:$P$104,HLOOKUP($B$36,Pagamentos!$3:$4,2,0)+1,0),"")
B44: =IF(Tabulação!A25<>"",Tabulação!A25,"") | C44: =IF(VLOOKUP(B44,Pagamentos!$A$74:$P$104,HLOOKUP($B$36,Pagamentos!$3:$4,2,0)+1,0)<>0,VLOOKUP(B44,Pagamentos!$A$74:$P$104,HLOOKUP($B$36,Pagamentos!$3:$4,2,0)+1,0),"")
B45: =IF(Tabulação!A26<>"",Tabulação!A26,"") | C45: =IF(VLOOKUP(B45,Pagamentos!$A$74:$P$104,HLOOKUP($B$36,Pagamentos!$3:$4,2,0)+1,0)<>0,VLOOKUP(B45,Pagamentos!$A$74:$P$104,HLOOKUP($B$36,Pagamentos!$3:$4,2,0)+1,0),"")
B46: =IF(Tabulação!A27<>"",Tabulação!A27,"") | C46: =IF(VLOOKUP(B46,Pagamentos!$A$74:$P$104,HLOOKUP($B$36,Pagamentos!$3:$4,2,0)+1,0)<>0,VLOOKUP(B46,Pagamentos!$A$74:$P$104,HLOOKUP($B$36,Pagamentos!$3:$4,2,0)+1,0),"")
B47: =IF(Tabulação!A28<>"",Tabulação!A28,"") | C47: =IF(VLOOKUP(B47,Pagamentos!$A$74:$P$104,HLOOKUP($B$36,Pagamentos!$3:$4,2,0)+1,0)<>0,VLOOKUP(B47,Pagamentos!$A$74:$P$104,HLOOKUP($B$36,Pagamentos!$3:$4,2,0)+1,0),"")
B48: =IF(Tabulação!A29<>"",Tabulação!A29,"") | C48: =IF(VLOOKUP(B48,Pagamentos!$A$74:$P$104,HLOOKUP($B$36,Pagamentos!$3:$4,2,0)+1,0)<>0,VLOOKUP(B48,Pagamentos!$A$74:$P$104,HLOOKUP($B$36,Pagamentos!$3:$4,2,0)+1,0),"")
B49: =IF(Tabulação!A30<>"",Tabulação!A30,"") | C49: =IF(VLOOKUP(B49,Pagamentos!$A$74:$P$104,HLOOKUP($B$36,Pagamentos!$3:$4,2,0)+1,0)<>0,VLOOKUP(B49,Pagamentos!$A$74:$P$104,HLOOKUP($B$36,Pagamentos!$3:$4,2,0)+1,0),"")
B50: =IF(Tabulação!A31<>"",Tabulação!A31,"") | C50: =IF(VLOOKUP(B50,Pagamentos!$A$74:$P$104,HLOOKUP($B$36,Pagamentos!$3:$4,2,0)+1,0)<>0,VLOOKUP(B50,Pagamentos!$A$74:$P$104,HLOOKUP($B$36,Pagamentos!$3:$4,2,0)+1,0),"")
... B80: =IF(Tabulação!A61<>"",Tabulação!A61,"") | C80: =IF(VLOOKUP(B80,Pagamentos!$A$74:$P$104,HLOOKUP($B$36,Pagamentos!$3:$4,2,0)+1,0)<>0,VLOOKUP(B80,Pagamentos!$A$74:$P$104,HLOOKUP($B$36,Pagamentos!$3:$4,2,0)+1,0),"")
