Workbook
Name Icms: #REF!
Name Icms: #REF!
Name Icms: #REF!

Sheet Simples Nacional
A1: PLANILHA DE CÁLCULO SIMPLES NACIONAL
F2: Aviso Desbloqueio
F3: Recomenda-se a utilização do software gratuito LibreOffice.
F4: Download: | G4: https://pt-br.libreoffice.org/baixe-ja/
D8: Referência | E8: Anexo I
B9: Função Contábil | D9: Setor | E9: =IFERROR(VLOOKUP($E$8,Anexos!A44:B49,2,0),"") -> Comércio
D11: Regra Antiga | E11: =2017 -> 2017
B13: =2017 -> 2017 | C13: meses → | D13: =DATE(B13,1,1) -> 42736 | E13: =EDATE(D13,1) -> 42767 | F13: =EDATE(E13,1) -> 42795 | G13: =EDATE(F13,1) -> 42826 | H13: =EDATE(G13,1) -> 42856 | I13: =EDATE(H13,1) -> 42887 | J13: =EDATE(I13,1) -> 42917 | K13: =EDATE(J13,1) -> 42948 | L13: =EDATE(K13,1) -> 42979 | ... O13: =EDATE(N13,1) -> 43070
B14: Receita Bruta Mensal - 2016 | C14: Redução da Base de Cálculo ↓ | D14: 20000 | E14: 20000 | F14: 20000 | G14: 20000 | H14: 20000 | I14: 20000 | J14: 20000 | K14: 20000 | L14: 20000 | M14: 20000 | N14: 20000 | O14: 20000
B15: Receita Bruta Mensal | D15: 20000 | E15: 20000 | F15: 20000 | G15: 20000 | H15: 20000 | I15: 20000 | J15: 20000 | K15: 20000 | L15: 20000 | M15: 20000 | N15: 20000 | O15: 20000
B16: Receita Acumulada (12 meses) | D16: =AVERAGE(D14:O$14)*12 -> 240000 | E16: =AVERAGE(E14:O$14,D15)*12 -> 240000 | F16: =AVERAGE(F14:O$14,$D$15:E15)*12 -> 240000 | G16: =AVERAGE(G14:O$14,$D$15:F15)*12 -> 240000 | H16: =AVERAGE(H14:O$14,$D$15:G15)*12 -> 240000 | I16: =AVERAGE(I14:O$14,$D$15:H15)*12 -> 240000 | J16: =AVERAGE(J14:O$14,$D$15:I15)*12 -> 240000 | K16: =AVERAGE(K14:O$14,$D$15:J15)*12 -> 240000 | L16: =AVERAGE(L15:O$15,$D$15:K15)*12 -> 240000 | M16: =AVERAGE(M14:O$14,$D$15:L15)*12 -> 240000 | N16: =AVERAGE(N14:O$14,$D$15:M15)*12 -> 240000 | O16: =AVERAGE(O14:O$14,$D$15:N15)*12 -> 240000
B17: Alíquota Integral | D17: =IFERROR(_xlfn.IFS($E$8="Anexo I",VLOOKUP(D16,Anexos!$A$22:$AG$41,3),$E$8="Anexo II",VLOOKUP(D16,Anexos!$A$22:$AG$41,10),$E$8="Anexo III",VLOOKUP(D16,Anexos!$A$22:$AG$41,18),$E$8="Anexo IV",VLOOKUP(D16,Anexos!$A$22:$AG$41,25),$E$8="Anexo VI",VLOOKUP(D16,Anexos!$A$22:$AG$41,31)),0) -> 0.0547 | E17: =IFERROR(_xlfn.IFS($E$8="Anexo I",VLOOKUP(E16,Anexos!$A$22:$AG$41,3),$E$8="Anexo II",VLOOKUP(E16,Anexos!$A$22:$AG$41,10),$E$8="Anexo III",VLOOKUP(E16,Anexos!$A$22:$AG$41,18),$E$8="Anexo IV",VLOOKUP(E16,Anexos!$A$22:$AG$41,25),$E$8="Anexo VI",VLOOKUP(E16,Anexos!$A$22:$AG$41,31)),0) -> 0.0547 | F17: =IFERROR(_xlfn.IFS($E$8="Anexo I",VLOOKUP(F16,Anexos!$A$22:$AG$41,3),$E$8="Anexo II",VLOOKUP(F16,Anexos!$A$22:$AG$41,10),$E$8="Anexo III",VLOOKUP(F16,Anexos!$A$22:$AG$41,18),$E$8="Anexo IV",VLOOKUP(F16,Anexos!$A$22:$AG$41,25),$E$8="Anexo VI",VLOOKUP(F16,Anexos!$A$22:$AG$41,31)),0) -> 0.0547 | G17: =IFERROR(_xlfn.IFS($E$8="Anexo I",VLOOKUP(G16,Anexos!$A$22:$AG$41,3),$E$8="Anexo II",VLOOKUP(G16,Anexos!$A$22:$AG$41,10),$E$8="Anexo III",VLOOKUP(G16,Anexos!$A$22:$AG$41,18),$E$8="Anexo IV",VLOOKUP(G16,Anexos!$A$22:$AG$41,25),$E$8="Anexo VI",VLOOKUP(G16,Anexos!$A$22:$AG$41,31)),0) -> 0.0547 | H17: =IFERROR(_xlfn.IFS($E$8="Anexo I",VLOOKUP(H16,Anexos!$A$22:$AG$41,3),$E$8="Anexo II",VLOOKUP(H16,Anexos!$A$22:$AG$41,10),$E$8="Anexo III",VLOOKUP(H16,Anexos!$A$22:$AG$41,18),$E$8="Anexo IV",VLOOKUP(H16,Anexos!$A$22:$AG$41,25),$E$8="Anexo VI",VLOOKUP(H16,Anexos!$A$22:$AG$41,31)),0) -> 0.0547 | I17: =IFERROR(_xlfn.IFS($E$8="Anexo I",VLOOKUP(I16,Anexos!$A$22:$AG$41,3),$E$8="Anexo II",VLOOKUP(I16,Anexos!$A$22:$AG$41,10),$E$8="Anexo III",VLOOKUP(I16,Anexos!$A$22:$AG$41,18),$E$8="Anexo IV",VLOOKUP(I16,Anexos!$A$22:$AG$41,25),$E$8="Anexo VI",VLOOKUP(I16,Anexos!$A$22:$AG$41,31)),0) -> 0.0547 | J17: =IFERROR(_xlfn.IFS($E$8="Anexo I",VLOOKUP(J16,Anexos!$A$22:$AG$41,3),$E$8="Anexo II",VLOOKUP(J16,Anexos!$A$22:$AG$41,10),$E$8="Anexo III",VLOOKUP(J16,Anexos!$A$22:$AG$41,18),$E$8="Anexo IV",VLOOKUP(J16,Anexos!$A$22:$AG$41,25),$E$8="Anexo VI",VLOOKUP(J16,Anexos!$A$22:$AG$41,31)),0) -> 0.0547 | K17: =IFERROR(_xlfn.IFS($E$8="Anexo I",VLOOKUP(K16,Anexos!$A$22:$AG$41,3),$E$8="Anexo II",VLOOKUP(K16,Anexos!$A$22:$AG$41,10),$E$8="Anexo III",VLOOKUP(K16,Anexos!$A$22:$AG$41,18),$E$8="Anexo IV",VLOOKUP(K16,Anexos!$A$22:$AG$41,25),$E$8="Anexo VI",VLOOKUP(K16,Anexos!$A$22:$AG$41,31)),0) -> 0.0547 | ... O17: =IFERROR(_xlfn.IFS($E$8="Anexo I",VLOOKUP(O16,Anexos!$A$22:$AG$41,3),$E$8="Anexo II",VLOOKUP(O16,Anexos!$A$22:$AG$41,10),$E$8="Anexo III",VLOOKUP(O16,Anexos!$A$22:$AG$41,18),$E$8="Anexo IV",VLOOKUP(O16,Anexos!$A$22:$AG$41,25),$E$8="Anexo VI",VLOOKUP(O16,Anexos!$A$22:$AG$41,31)),0) -> 0.0547
B18: Simples Nacional | D18: =IFERROR(D15*(SUM(D19:D26)),0) -> 1094 | E18: =IFERROR(E15*(SUM(E19:E26)),0) -> 1094 | F18: =IFERROR(F15*(SUM(F19:F26)),0) -> 1094 | G18: =IFERROR(G15*(SUM(G19:G26)),0) -> 1094 | H18: =IFERROR(H15*(SUM(H19:H26)),0) -> 1094 | I18: =IFERROR(I15*(SUM(I19:I26)),0) -> 1094 | J18: =IFERROR(J15*(SUM(J19:J26)),0) -> 1094 | K18: =IFERROR(K15*(SUM(K19:K26)),0) -> 1094 | ... O18: =IFERROR(O15*(SUM(O19:O26)),0) -> 1094
B19: Repartição do IRPJ | C19: 1 | D19: =IFERROR(_xlfn.IFS($E$8="Anexo I",VLOOKUP(D16,Anexos!$A$22:$AG$41,4),$E$8="Anexo II",VLOOKUP(D16,Anexos!$A$22:$AG$41,11),$E$8="Anexo III",VLOOKUP(D16,Anexos!$A$22:$AG$41,19),$E$8="Anexo IV",VLOOKUP(D16,Anexos!$A$22:$AG$41,26))*$C$19,0) -> 0 | E19: =IFERROR(_xlfn.IFS($E$8="Anexo I",VLOOKUP(E16,Anexos!$A$22:$AG$41,4),$E$8="Anexo II",VLOOKUP(E16,Anexos!$A$22:$AG$41,11),$E$8="Anexo III",VLOOKUP(E16,Anexos!$A$22:$AG$41,19),$E$8="Anexo IV",VLOOKUP(E16,Anexos!$A$22:$AG$41,26))*$C$19,0) -> 0 | F19: =IFERROR(_xlfn.IFS($E$8="Anexo I",VLOOKUP(F16,Anexos!$A$22:$AG$41,4),$E$8="Anexo II",VLOOKUP(F16,Anexos!$A$22:$AG$41,11),$E$8="Anexo III",VLOOKUP(F16,Anexos!$A$22:$AG$41,19),$E$8="Anexo IV",VLOOKUP(F16,Anexos!$A$22:$AG$41,26))*$C$19,0) -> 0 | G19: =IFERROR(_xlfn.IFS($E$8="Anexo I",VLOOKUP(G16,Anexos!$A$22:$AG$41,4),$E$8="Anexo II",VLOOKUP(G16,Anexos!$A$22:$AG$41,11),$E$8="Anexo III",VLOOKUP(G16,Anexos!$A$22:$AG$41,19),$E$8="Anexo IV",VLOOKUP(G16,Anexos!$A$22:$AG$41,26))*$C$19,0) -> 0 | H19: =IFERROR(_xlfn.IFS($E$8="Anexo I",VLOOKUP(H16,Anexos!$A$22:$AG$41,4),$E$8="Anexo II",VLOOKUP(H16,Anexos!$A$22:$AG$41,11),$E$8="Anexo III",VLOOKUP(H16,Anexos!$A$22:$AG$41,19),$E$8="Anexo IV",VLOOKUP(H16,Anexos!$A$22:$AG$41,26))*$C$19,0) -> 0 | I19: =IFERROR(_xlfn.IFS($E$8="Anexo I",VLOOKUP(I16,Anexos!$A$22:$AG$41,4),$E$8="Anexo II",VLOOKUP(I16,Anexos!$A$22:$AG$41,11),$E$8="Anexo III",VLOOKUP(I16,Anexos!$A$22:$AG$41,19),$E$8="Anexo IV",VLOOKUP(I16,Anexos!$A$22:$AG$41,26))*$C$19,0) -> 0 | J19: =IFERROR(_xlfn.IFS($E$8="Anexo I",VLOOKUP(J16,Anexos!$A$22:$AG$41,4),$E$8="Anexo II",VLOOKUP(J16,Anexos!$A$22:$AG$41,11),$E$8="Anexo III",VLOOKUP(J16,Anexos!$A$22:$AG$41,19),$E$8="Anexo IV",VLOOKUP(J16,Anexos!$A$22:$AG$41,26))*$C$19,0) -> 0 | K19: =IFERROR(_xlfn.IFS($E$8="Anexo I",VLOOKUP(K16,Anexos!$A$22:$AG$41,4),$E$8="Anexo II",VLOOKUP(K16,Anexos!$A$22:$AG$41,11),$E$8="Anexo III",VLOOKUP(K16,Anexos!$A$22:$AG$41,19),$E$8="Anexo IV",VLOOKUP(K16,Anexos!$A$22:$AG$41,26))*$C$19,0) -> 0 | ... O19: =IFERROR(_xlfn.IFS($E$8="Anexo I",VLOOKUP(O16,Anexos!$A$22:$AG$41,4),$E$8="Anexo II",VLOOKUP(O16,Anexos!$A$22:$AG$41,11),$E$8="Anexo III",VLOOKUP(O16,Anexos!$A$22:$AG$41,19),$E$8="Anexo IV",VLOOKUP(O16,Anexos!$A$22:$AG$41,26))*$C$19,0) -> 0
B20: Repartição do CSLL | C20: 1 | D20: =IFERROR(_xlfn.IFS($E$8="Anexo I",VLOOKUP(D16,Anexos!$A$22:$AG$41,5),$E$8="Anexo II",VLOOKUP(D16,Anexos!$A$22:$AG$41,12),$E$8="Anexo III",VLOOKUP(D16,Anexos!$A$22:$AG$41,20),$E$8="Anexo IV",VLOOKUP(D16,Anexos!$A$22:$AG$41,27))*$C$20,0) -> 0 | E20: =IFERROR(_xlfn.IFS($E$8="Anexo I",VLOOKUP(E16,Anexos!$A$22:$AG$41,5),$E$8="Anexo II",VLOOKUP(E16,Anexos!$A$22:$AG$41,12),$E$8="Anexo III",VLOOKUP(E16,Anexos!$A$22:$AG$41,20),$E$8="Anexo IV",VLOOKUP(E16,Anexos!$A$22:$AG$41,27))*$C$20,0) -> 0 | F20: =IFERROR(_xlfn.IFS($E$8="Anexo I",VLOOKUP(F16,Anexos!$A$22:$AG$41,5),$E$8="Anexo II",VLOOKUP(F16,Anexos!$A$22:$AG$41,12),$E$8="Anexo III",VLOOKUP(F16,Anexos!$A$22:$AG$41,20),$E$8="Anexo IV",VLOOKUP(F16,Anexos!$A$22:$AG$41,27))*$C$20,0) -> 0 | G20: =IFERROR(_xlfn.IFS($E$8="Anexo I",VLOOKUP(G16,Anexos!$A$22:$AG$41,5),$E$8="Anexo II",VLOOKUP(G16,Anexos!$A$22:$AG$41,12),$E$8="Anexo III",VLOOKUP(G16,Anexos!$A$22:$AG$41,20),$E$8="Anexo IV",VLOOKUP(G16,Anexos!$A$22:$AG$41,27))*$C$20,0) -> 0 | H20: =IFERROR(_xlfn.IFS($E$8="Anexo I",VLOOKUP(H16,Anexos!$A$22:$AG$41,5),$E$8="Anexo II",VLOOKUP(H16,Anexos!$A$22:$AG$41,12),$E$8="Anexo III",VLOOKUP(H16,Anexos!$A$22:$AG$41,20),$E$8="Anexo IV",VLOOKUP(H16,Anexos!$A$22:$AG$41,27))*$C$20,0) -> 0 | I20: =IFERROR(_xlfn.IFS($E$8="Anexo I",VLOOKUP(I16,Anexos!$A$22:$AG$41,5),$E$8="Anexo II",VLOOKUP(I16,Anexos!$A$22:$AG$41,12),$E$8="Anexo III",VLOOKUP(I16,Anexos!$A$22:$AG$41,20),$E$8="Anexo IV",VLOOKUP(I16,Anexos!$A$22:$AG$41,27))*$C$20,0) -> 0 | J20: =IFERROR(_xlfn.IFS($E$8="Anexo I",VLOOKUP(J16,Anexos!$A$22:$AG$41,5),$E$8="Anexo II",VLOOKUP(J16,Anexos!$A$22:$AG$41,12),$E$8="Anexo III",VLOOKUP(J16,Anexos!$A$22:$AG$41,20),$E$8="Anexo IV",VLOOKUP(J16,Anexos!$A$22:$AG$41,27))*$C$20,0) -> 0 | K20: =IFERROR(_xlfn.IFS($E$8="Anexo I",VLOOKUP(K16,Anexos!$A$22:$AG$41,5),$E$8="Anexo II",VLOOKUP(K16,Anexos!$A$22:$AG$41,12),$E$8="Anexo III",VLOOKUP(K16,Anexos!$A$22:$AG$41,20),$E$8="Anexo IV",VLOOKUP(K16,Anexos!$A$22:$AG$41,27))*$C$20,0) -> 0 | ... O20: =IFERROR(_xlfn.IFS($E$8="Anexo I",VLOOKUP(O16,Anexos!$A$22:$AG$41,5),$E$8="Anexo II",VLOOKUP(O16,Anexos!$A$22:$AG$41,12),$E$8="Anexo III",VLOOKUP(O16,Anexos!$A$22:$AG$41,20),$E$8="Anexo IV",VLOOKUP(O16,Anexos!$A$22:$AG$41,27))*$C$20,0) -> 0
B21: Repartição do COFINS | C21: 1 | D21: =IFERROR(_xlfn.IFS($E$8="Anexo I",VLOOKUP(D16,Anexos!$A$22:$AG$41,6),$E$8="Anexo II",VLOOKUP(D16,Anexos!$A$22:$AG$41,13),$E$8="Anexo III",VLOOKUP(D16,Anexos!$A$22:$AG$41,21),$E$8="Anexo IV",VLOOKUP(D16,Anexos!$A$22:$AG$41,28))*$C$21,0) -> 0.0086 | E21: =IFERROR(_xlfn.IFS($E$8="Anexo I",VLOOKUP(E16,Anexos!$A$22:$AG$41,6),$E$8="Anexo II",VLOOKUP(E16,Anexos!$A$22:$AG$41,13),$E$8="Anexo III",VLOOKUP(E16,Anexos!$A$22:$AG$41,21),$E$8="Anexo IV",VLOOKUP(E16,Anexos!$A$22:$AG$41,28))*$C$21,0) -> 0.0086 | F21: =IFERROR(_xlfn.IFS($E$8="Anexo I",VLOOKUP(F16,Anexos!$A$22:$AG$41,6),$E$8="Anexo II",VLOOKUP(F16,Anexos!$A$22:$AG$41,13),$E$8="Anexo III",VLOOKUP(F16,Anexos!$A$22:$AG$41,21),$E$8="Anexo IV",VLOOKUP(F16,Anexos!$A$22:$AG$41,28))*$C$21,0) -> 0.0086 | G21: =IFERROR(_xlfn.IFS($E$8="Anexo I",VLOOKUP(G16,Anexos!$A$22:$AG$41,6),$E$8="Anexo II",VLOOKUP(G16,Anexos!$A$22:$AG$41,13),$E$8="Anexo III",VLOOKUP(G16,Anexos!$A$22:$AG$41,21),$E$8="Anexo IV",VLOOKUP(G16,Anexos!$A$22:$AG$41,28))*$C$21,0) -> 0.0086 | H21: =IFERROR(_xlfn.IFS($E$8="Anexo I",VLOOKUP(H16,Anexos!$A$22:$AG$41,6),$E$8="Anexo II",VLOOKUP(H16,Anexos!$A$22:$AG$41,13),$E$8="Anexo III",VLOOKUP(H16,Anexos!$A$22:$AG$41,21),$E$8="Anexo IV",VLOOKUP(H16,Anexos!$A$22:$AG$41,28))*$C$21,0) -> 0.0086 | I21: =IFERROR(_xlfn.IFS($E$8="Anexo I",VLOOKUP(I16,Anexos!$A$22:$AG$41,6),$E$8="Anexo II",VLOOKUP(I16,Anexos!$A$22:$AG$41,13),$E$8="Anexo III",VLOOKUP(I16,Anexos!$A$22:$AG$41,21),$E$8="Anexo IV",VLOOKUP(I16,Anexos!$A$22:$AG$41,28))*$C$21,0) -> 0.0086 | J21: =IFERROR(_xlfn.IFS($E$8="Anexo I",VLOOKUP(J16,Anexos!$A$22:$AG$41,6),$E$8="Anexo II",VLOOKUP(J16,Anexos!$A$22:$AG$41,13),$E$8="Anexo III",VLOOKUP(J16,Anexos!$A$22:$AG$41,21),$E$8="Anexo IV",VLOOKUP(J16,Anexos!$A$22:$AG$41,28))*$C$21,0) -> 0.0086 | K21: =IFERROR(_xlfn.IFS($E$8="Anexo I",VLOOKUP(K16,Anexos!$A$22:$AG$41,6),$E$8="Anexo II",VLOOKUP(K16,Anexos!$A$22:$AG$41,13),$E$8="Anexo III",VLOOKUP(K16,Anexos!$A$22:$AG$41,21),$E$8="Anexo IV",VLOOKUP(K16,Anexos!$A$22:$AG$41,28))*$C$21,0) -> 0.0086 | ... O21: =IFERROR(_xlfn.IFS($E$8="Anexo I",VLOOKUP(O16,Anexos!$A$22:$AG$41,6),$E$8="Anexo II",VLOOKUP(O16,Anexos!$A$22:$AG$41,13),$E$8="Anexo III",VLOOKUP(O16,Anexos!$A$22:$AG$41,21),$E$8="Anexo IV",VLOOKUP(O16,Anexos!$A$22:$AG$41,28))*$C$21,0) -> 0.0086
B22: Repartição do PIS/Pasep | C22: 1 | D22: =IFERROR(_xlfn.IFS($E$8="Anexo I",VLOOKUP(D16,Anexos!$A$22:$AG$41,7),$E$8="Anexo II",VLOOKUP(D16,Anexos!$A$22:$AG$41,14),$E$8="Anexo III",VLOOKUP(D16,Anexos!$A$22:$AG$41,22),$E$8="Anexo IV",VLOOKUP(D16,Anexos!$A$22:$AG$41,29))*$C$22,0) -> 0 | E22: =IFERROR(_xlfn.IFS($E$8="Anexo I",VLOOKUP(E16,Anexos!$A$22:$AG$41,7),$E$8="Anexo II",VLOOKUP(E16,Anexos!$A$22:$AG$41,14),$E$8="Anexo III",VLOOKUP(E16,Anexos!$A$22:$AG$41,22),$E$8="Anexo IV",VLOOKUP(E16,Anexos!$A$22:$AG$41,29))*$C$22,0) -> 0 | F22: =IFERROR(_xlfn.IFS($E$8="Anexo I",VLOOKUP(F16,Anexos!$A$22:$AG$41,7),$E$8="Anexo II",VLOOKUP(F16,Anexos!$A$22:$AG$41,14),$E$8="Anexo III",VLOOKUP(F16,Anexos!$A$22:$AG$41,22),$E$8="Anexo IV",VLOOKUP(F16,Anexos!$A$22:$AG$41,29))*$C$22,0) -> 0 | G22: =IFERROR(_xlfn.IFS($E$8="Anexo I",VLOOKUP(G16,Anexos!$A$22:$AG$41,7),$E$8="Anexo II",VLOOKUP(G16,Anexos!$A$22:$AG$41,14),$E$8="Anexo III",VLOOKUP(G16,Anexos!$A$22:$AG$41,22),$E$8="Anexo IV",VLOOKUP(G16,Anexos!$A$22:$AG$41,29))*$C$22,0) -> 0 | H22: =IFERROR(_xlfn.IFS($E$8="Anexo I",VLOOKUP(H16,Anexos!$A$22:$AG$41,7),$E$8="Anexo II",VLOOKUP(H16,Anexos!$A$22:$AG$41,14),$E$8="Anexo III",VLOOKUP(H16,Anexos!$A$22:$AG$41,22),$E$8="Anexo IV",VLOOKUP(H16,Anexos!$A$22:$AG$41,29))*$C$22,0) -> 0 | I22: =IFERROR(_xlfn.IFS($E$8="Anexo I",VLOOKUP(I16,Anexos!$A$22:$AG$41,7),$E$8="Anexo II",VLOOKUP(I16,Anexos!$A$22:$AG$41,14),$E$8="Anexo III",VLOOKUP(I16,Anexos!$A$22:$AG$41,22),$E$8="Anexo IV",VLOOKUP(I16,Anexos!$A$22:$AG$41,29))*$C$22,0) -> 0 | J22: =IFERROR(_xlfn.IFS($E$8="Anexo I",VLOOKUP(J16,Anexos!$A$22:$AG$41,7),$E$8="Anexo II",VLOOKUP(J16,Anexos!$A$22:$AG$41,14),$E$8="Anexo III",VLOOKUP(J16,Anexos!$A$22:$AG$41,22),$E$8="Anexo IV",VLOOKUP(J16,Anexos!$A$22:$AG$41,29))*$C$22,0) -> 0 | K22: =IFERROR(_xlfn.IFS($E$8="Anexo I",VLOOKUP(K16,Anexos!$A$22:$AG$41,7),$E$8="Anexo II",VLOOKUP(K16,Anexos!$A$22:$AG$41,14),$E$8="Anexo III",VLOOKUP(K16,Anexos!$A$22:$AG$41,22),$E$8="Anexo IV",VLOOKUP(K16,Anexos!$A$22:$AG$41,29))*$C$22,0) -> 0 | ... O22: =IFERROR(_xlfn.IFS($E$8="Anexo I",VLOOKUP(O16,Anexos!$A$22:$AG$41,7),$E$8="Anexo II",VLOOKUP(O16,Anexos!$A$22:$AG$41,14),$E$8="Anexo III",VLOOKUP(O16,Anexos!$A$22:$AG$41,22),$E$8="Anexo IV",VLOOKUP(O16,Anexos!$A$22:$AG$41,29))*$C$22,0) -> 0
B23: Repartição do CPP | C23: 1 | D23: =IFERROR(_xlfn.IFS($E$8="Anexo I",VLOOKUP(D16,Anexos!$A$22:$AG$41,8),$E$8="Anexo II",VLOOKUP(D16,Anexos!$A$22:$AG$41,15),$E$8="Anexo III",VLOOKUP(D16,Anexos!$A$22:$AG$41,23))*$C$23,0) -> 0.0275 | E23: =IFERROR(_xlfn.IFS($E$8="Anexo I",VLOOKUP(E16,Anexos!$A$22:$AG$41,8),$E$8="Anexo II",VLOOKUP(E16,Anexos!$A$22:$AG$41,15),$E$8="Anexo III",VLOOKUP(E16,Anexos!$A$22:$AG$41,23))*$C$23,0) -> 0.0275 | F23: =IFERROR(_xlfn.IFS($E$8="Anexo I",VLOOKUP(F16,Anexos!$A$22:$AG$41,8),$E$8="Anexo II",VLOOKUP(F16,Anexos!$A$22:$AG$41,15),$E$8="Anexo III",VLOOKUP(F16,Anexos!$A$22:$AG$41,23))*$C$23,0) -> 0.0275 | G23: =IFERROR(_xlfn.IFS($E$8="Anexo I",VLOOKUP(G16,Anexos!$A$22:$AG$41,8),$E$8="Anexo II",VLOOKUP(G16,Anexos!$A$22:$AG$41,15),$E$8="Anexo III",VLOOKUP(G16,Anexos!$A$22:$AG$41,23))*$C$23,0) -> 0.0275 | H23: =IFERROR(_xlfn.IFS($E$8="Anexo I",VLOOKUP(H16,Anexos!$A$22:$AG$41,8),$E$8="Anexo II",VLOOKUP(H16,Anexos!$A$22:$AG$41,15),$E$8="Anexo III",VLOOKUP(H16,Anexos!$A$22:$AG$41,23))*$C$23,0) -> 0.0275 | I23: =IFERROR(_xlfn.IFS($E$8="Anexo I",VLOOKUP(I16,Anexos!$A$22:$AG$41,8),$E$8="Anexo II",VLOOKUP(I16,Anexos!$A$22:$AG$41,15),$E$8="Anexo III",VLOOKUP(I16,Anexos!$A$22:$AG$41,23))*$C$23,0) -> 0.0275 | J23: =IFERROR(_xlfn.IFS($E$8="Anexo I",VLOOKUP(J16,Anexos!$A$22:$AG$41,8),$E$8="Anexo II",VLOOKUP(J16,Anexos!$A$22:$AG$41,15),$E$8="Anexo III",VLOOKUP(J16,Anexos!$A$22:$AG$41,23))*$C$23,0) -> 0.0275 | K23: =IFERROR(_xlfn.IFS($E$8="Anexo I",VLOOKUP(K16,Anexos!$A$22:$AG$41,8),$E$8="Anexo II",VLOOKUP(K16,Anexos!$A$22:$AG$41,15),$E$8="Anexo III",VLOOKUP(K16,Anexos!$A$22:$AG$41,23))*$C$23,0) -> 0.0275 | ... O23: =IFERROR(_xlfn.IFS($E$8="Anexo I",VLOOKUP(O16,Anexos!$A$22:$AG$41,8),$E$8="Anexo II",VLOOKUP(O16,Anexos!$A$22:$AG$41,15),$E$8="Anexo III",VLOOKUP(O16,Anexos!$A$22:$AG$41,23))*$C$23,0) -> 0.0275
B24: Repartição do IPI | C24: 1 | D24: =IFERROR(_xlfn.IFS($E$8="Anexo II",VLOOKUP(D16,Anexos!$A$22:$AG$41,17))*$C$24,0) -> 0 | E24: =IFERROR(_xlfn.IFS($E$8="Anexo II",VLOOKUP(E16,Anexos!$A$22:$AG$41,17))*$C$24,0) -> 0 | F24: =IFERROR(_xlfn.IFS($E$8="Anexo II",VLOOKUP(F16,Anexos!$A$22:$AG$41,17))*$C$24,0) -> 0 | G24: =IFERROR(_xlfn.IFS($E$8="Anexo II",VLOOKUP(G16,Anexos!$A$22:$AG$41,17))*$C$24,0) -> 0 | H24: =IFERROR(_xlfn.IFS($E$8="Anexo II",VLOOKUP(H16,Anexos!$A$22:$AG$41,17))*$C$24,0) -> 0 | I24: =IFERROR(_xlfn.IFS($E$8="Anexo II",VLOOKUP(I16,Anexos!$A$22:$AG$41,17))*$C$24,0) -> 0 | J24: =IFERROR(_xlfn.IFS($E$8="Anexo II",VLOOKUP(J16,Anexos!$A$22:$AG$41,17))*$C$24,0) -> 0 | K24: =IFERROR(_xlfn.IFS($E$8="Anexo II",VLOOKUP(K16,Anexos!$A$22:$AG$41,17))*$C$24,0) -> 0 | ... O24: =IFERROR(_xlfn.IFS($E$8="Anexo II",VLOOKUP(O16,Anexos!$A$22:$AG$41,17))*$C$24,0) -> 0
B25: Repartição do ICMS | C25: 1 | D25: =IFERROR(_xlfn.IFS($E$8="Anexo I",VLOOKUP(D16,Anexos!$A$22:$AG$41,9),$E$8="Anexo II",VLOOKUP(D16,Anexos!$A$22:$AG$41,16))*$C$25,0) -> 0.0186 | E25: =IFERROR(_xlfn.IFS($E$8="Anexo I",VLOOKUP(E16,Anexos!$A$22:$AG$41,9),$E$8="Anexo II",VLOOKUP(E16,Anexos!$A$22:$AG$41,16))*$C$25,0) -> 0.0186 | F25: =IFERROR(_xlfn.IFS($E$8="Anexo I",VLOOKUP(F16,Anexos!$A$22:$AG$41,9),$E$8="Anexo II",VLOOKUP(F16,Anexos!$A$22:$AG$41,16))*$C$25,0) -> 0.0186 | G25: =IFERROR(_xlfn.IFS($E$8="Anexo I",VLOOKUP(G16,Anexos!$A$22:$AG$41,9),$E$8="Anexo II",VLOOKUP(G16,Anexos!$A$22:$AG$41,16))*$C$25,0) -> 0.0186 | H25: =IFERROR(_xlfn.IFS($E$8="Anexo I",VLOOKUP(H16,Anexos!$A$22:$AG$41,9),$E$8="Anexo II",VLOOKUP(H16,Anexos!$A$22:$AG$41,16))*$C$25,0) -> 0.0186 | I25: =IFERROR(_xlfn.IFS($E$8="Anexo I",VLOOKUP(I16,Anexos!$A$22:$AG$41,9),$E$8="Anexo II",VLOOKUP(I16,Anexos!$A$22:$AG$41,16))*$C$25,0) -> 0.0186 | J25: =IFERROR(_xlfn.IFS($E$8="Anexo I",VLOOKUP(J16,Anexos!$A$22:$AG$41,9),$E$8="Anexo II",VLOOKUP(J16,Anexos!$A$22:$AG$41,16))*$C$25,0) -> 0.0186 | K25: =IFERROR(_xlfn.IFS($E$8="Anexo I",VLOOKUP(K16,Anexos!$A$22:$AG$41,9),$E$8="Anexo II",VLOOKUP(K16,Anexos!$A$22:$AG$41,16))*$C$25,0) -> 0.0186 | ... O25: =IFERROR(_xlfn.IFS($E$8="Anexo I",VLOOKUP(O16,Anexos!$A$22:$AG$41,9),$E$8="Anexo II",VLOOKUP(O16,Anexos!$A$22:$AG$41,16))*$C$25,0) -> 0.0186
B26: Repartição do ISS | C26: 1 | D26: =IFERROR(_xlfn.IFS($E$8="Anexo III",VLOOKUP(D16,Anexos!$A$22:$AG$41,24),$E$8="Anexo IV",VLOOKUP(D16,Anexos!$A$22:$AG$41,30),$E$8="Anexo VI",VLOOKUP(D16,Anexos!$A$22:$AG$41,33))*$C$26,0) -> 0 | E26: =IFERROR(_xlfn.IFS($E$8="Anexo III",VLOOKUP(E16,Anexos!$A$22:$AG$41,24),$E$8="Anexo IV",VLOOKUP(E16,Anexos!$A$22:$AG$41,30),$E$8="Anexo VI",VLOOKUP(E16,Anexos!$A$22:$AG$41,33))*$C$26,0) -> 0 | F26: =IFERROR(_xlfn.IFS($E$8="Anexo III",VLOOKUP(F16,Anexos!$A$22:$AG$41,24),$E$8="Anexo IV",VLOOKUP(F16,Anexos!$A$22:$AG$41,30),$E$8="Anexo VI",VLOOKUP(F16,Anexos!$A$22:$AG$41,33))*$C$26,0) -> 0 | G26: =IFERROR(_xlfn.IFS($E$8="Anexo III",VLOOKUP(G16,Anexos!$A$22:$AG$41,24),$E$8="Anexo IV",VLOOKUP(G16,Anexos!$A$22:$AG$41,30),$E$8="Anexo VI",VLOOKUP(G16,Anexos!$A$22:$AG$41,33))*$C$26,0) -> 0 | H26: =IFERROR(_xlfn.IFS($E$8="Anexo III",VLOOKUP(H16,Anexos!$A$22:$AG$41,24),$E$8="Anexo IV",VLOOKUP(H16,Anexos!$A$22:$AG$41,30),$E$8="Anexo VI",VLOOKUP(H16,Anexos!$A$22:$AG$41,33))*$C$26,0) -> 0 | I26: =IFERROR(_xlfn.IFS($E$8="Anexo III",VLOOKUP(I16,Anexos!$A$22:$AG$41,24),$E$8="Anexo IV",VLOOKUP(I16,Anexos!$A$22:$AG$41,30),$E$8="Anexo VI",VLOOKUP(I16,Anexos!$A$22:$AG$41,33))*$C$26,0) -> 0 | J26: =IFERROR(_xlfn.IFS($E$8="Anexo III",VLOOKUP(J16,Anexos!$A$22:$AG$41,24),$E$8="Anexo IV",VLOOKUP(J16,Anexos!$A$22:$AG$41,30),$E$8="Anexo VI",VLOOKUP(J16,Anexos!$A$22:$AG$41,33))*$C$26,0) -> 0 | K26: =IFERROR(_xlfn.IFS($E$8="Anexo III",VLOOKUP(K16,Anexos!$A$22:$AG$41,24),$E$8="Anexo IV",VLOOKUP(K16,Anexos!$A$22:$AG$41,30),$E$8="Anexo VI",VLOOKUP(K16,Anexos!$A$22:$AG$41,33))*$C$26,0) -> 0 | ... O26: =IFERROR(_xlfn.IFS($E$8="Anexo III",VLOOKUP(O16,Anexos!$A$22:$AG$41,24),$E$8="Anexo IV",VLOOKUP(O16,Anexos!$A$22:$AG$41,30),$E$8="Anexo VI",VLOOKUP(O16,Anexos!$A$22:$AG$41,33))*$C$26,0) -> 0
D28: Regra Atual | E28: =TODAY() -> 43151
B30: =YEAR($E$28) -> 2018 | C30: meses → | D30: =DATE(B30,1,1) -> 43101 | E30: =EDATE(D30,1) -> 43132 | F30: =EDATE(E30,1) -> 43160 | G30: =EDATE(F30,1) -> 43191 | H30: =EDATE(G30,1) -> 43221 | I30: =EDATE(H30,1) -> 43252 | J30: =EDATE(I30,1) -> 43282 | K30: =EDATE(J30,1) -> 43313 | L30: =EDATE(K30,1) -> 43344 | ... O30: =EDATE(N30,1) -> 43435
B31: Receita Bruta Mensal | C31: Redução da Base de Cálculo ↓ | D31: 20000 | E31: 0
B32: Receita Acumulada (12 meses) | D32: =AVERAGE(D15:$O$15)*12 -> 240000 | E32: =AVERAGE(E15:$O$15,$D$31)*12 -> 240000 | F32: =AVERAGE(F15:$O$15,$D$31:E31)*12 -> 220000 | G32: =AVERAGE(G15:$O$15,$D$31:F31)*12 -> 218181.82 | H32: =AVERAGE(H15:$O$15,$D$31:G31)*12 -> 216000 | I32: =AVERAGE(I15:$O$15,$D$31:H31)*12 -> 213333.33 | J32: =AVERAGE(J15:$O$15,$D$31:I31)*12 -> 210000 | K32: =AVERAGE(K15:$O$15,$D$31:J31)*12 -> 205714.29 | L32: =AVERAGE(L15:$O$15,$D$31:K31)*12 -> 200000 | M32: =AVERAGE(M15:$O$15,$D$31:L31)*12 -> 192000 | ... O32: =AVERAGE(O15:$O$15,$D$31:N31)*12 -> 160000
B33: Alíquota da Tabela | D33: =IFERROR(_xlfn.IFS($E$8="Anexo I",VLOOKUP(D32,Anexos!$A$12:$AP$17,3),$E$8="Anexo II",VLOOKUP(D32,Anexos!$A$12:$AP$17,11),$E$8="Anexo III",VLOOKUP(D32,Anexos!$A$12:$AP$17,20),$E$8="Anexo IV",VLOOKUP(D32,Anexos!$A$12:$AP$17,28),$E$8="Anexo V",VLOOKUP(D32,Anexos!$A$12:$AP$17,35)),0) -> 0.073 | E33: =IFERROR(_xlfn.IFS($E$8="Anexo I",VLOOKUP(E32,Anexos!$A$12:$AP$17,3),$E$8="Anexo II",VLOOKUP(E32,Anexos!$A$12:$AP$17,11),$E$8="Anexo III",VLOOKUP(E32,Anexos!$A$12:$AP$17,20),$E$8="Anexo IV",VLOOKUP(E32,Anexos!$A$12:$AP$17,28),$E$8="Anexo V",VLOOKUP(E32,Anexos!$A$12:$AP$17,35)),0) -> 0.073 | F33: =IFERROR(_xlfn.IFS($E$8="Anexo I",VLOOKUP(F32,Anexos!$A$12:$AP$17,3),$E$8="Anexo II",VLOOKUP(F32,Anexos!$A$12:$AP$17,11),$E$8="Anexo III",VLOOKUP(F32,Anexos!$A$12:$AP$17,20),$E$8="Anexo IV",VLOOKUP(F32,Anexos!$A$12:$AP$17,28),$E$8="Anexo V",VLOOKUP(F32,Anexos!$A$12:$AP$17,35)),0) -> 0.073 | G33: =IFERROR(_xlfn.IFS($E$8="Anexo I",VLOOKUP(G32,Anexos!$A$12:$AP$17,3),$E$8="Anexo II",VLOOKUP(G32,Anexos!$A$12:$AP$17,11),$E$8="Anexo III",VLOOKUP(G32,Anexos!$A$12:$AP$17,20),$E$8="Anexo IV",VLOOKUP(G32,Anexos!$A$12:$AP$17,28),$E$8="Anexo V",VLOOKUP(G32,Anexos!$A$12:$AP$17,35)),0) -> 0.073 | H33: =IFERROR(_xlfn.IFS($E$8="Anexo I",VLOOKUP(H32,Anexos!$A$12:$AP$17,3),$E$8="Anexo II",VLOOKUP(H32,Anexos!$A$12:$AP$17,11),$E$8="Anexo III",VLOOKUP(H32,Anexos!$A$12:$AP$17,20),$E$8="Anexo IV",VLOOKUP(H32,Anexos!$A$12:$AP$17,28),$E$8="Anexo V",VLOOKUP(H32,Anexos!$A$12:$AP$17,35)),0) -> 0.073 | I33: =IFERROR(_xlfn.IFS($E$8="Anexo I",VLOOKUP(I32,Anexos!$A$12:$AP$17,3),$E$8="Anexo II",VLOOKUP(I32,Anexos!$A$12:$AP$17,11),$E$8="Anexo III",VLOOKUP(I32,Anexos!$A$12:$AP$17,20),$E$8="Anexo IV",VLOOKUP(I32,Anexos!$A$12:$AP$17,28),$E$8="Anexo V",VLOOKUP(I32,Anexos!$A$12:$AP$17,35)),0) -> 0.073 | J33: =IFERROR(_xlfn.IFS($E$8="Anexo I",VLOOKUP(J32,Anexos!$A$12:$AP$17,3),$E$8="Anexo II",VLOOKUP(J32,Anexos!$A$12:$AP$17,11),$E$8="Anexo III",VLOOKUP(J32,Anexos!$A$12:$AP$17,20),$E$8="Anexo IV",VLOOKUP(J32,Anexos!$A$12:$AP$17,28),$E$8="Anexo V",VLOOKUP(J32,Anexos!$A$12:$AP$17,35)),0) -> 0.073 | K33: =IFERROR(_xlfn.IFS($E$8="Anexo I",VLOOKUP(K32,Anexos!$A$12:$AP$17,3),$E$8="Anexo II",VLOOKUP(K32,Anexos!$A$12:$AP$17,11),$E$8="Anexo III",VLOOKUP(K32,Anexos!$A$12:$AP$17,20),$E$8="Anexo IV",VLOOKUP(K32,Anexos!$A$12:$AP$17,28),$E$8="Anexo V",VLOOKUP(K32,Anexos!$A$12:$AP$17,35)),0) -> 0.073 | ... O33: =IFERROR(_xlfn.IFS($E$8="Anexo I",VLOOKUP(O32,Anexos!$A$12:$AP$17,3),$E$8="Anexo II",VLOOKUP(O32,Anexos!$A$12:$AP$17,11),$E$8="Anexo III",VLOOKUP(O32,Anexos!$A$12:$AP$17,20),$E$8="Anexo IV",VLOOKUP(O32,Anexos!$A$12:$AP$17,28),$E$8="Anexo V",VLOOKUP(O32,Anexos!$A$12:$AP$17,35)),0) -> 0.04
B34: Memória de Cálculo | D34: =IFERROR(D32*D33,0) -> 17520 | E34: =IFERROR(E32*E33,0) -> 17520 | F34: =IFERROR(F32*F33,0) -> 16060 | G34: =IFERROR(G32*G33,0) -> 15927.273 | H34: =IFERROR(H32*H33,0) -> 15768 | I34: =IFERROR(I32*I33,0) -> 15573.333 | J34: =IFERROR(J32*J33,0) -> 15330 | K34: =IFERROR(K32*K33,0) -> 15017.143 | ... O34: =IFERROR(O32*O33,0) -> 6400
B35: Dedução da Tabela | D35: =-IFERROR(_xlfn.IFS($E$8="Anexo I",VLOOKUP(D32,Anexos!$A$12:$AP$17,4),$E$8="Anexo II",VLOOKUP(D32,Anexos!$A$12:$AP$17,12),$E$8="Anexo III",VLOOKUP(D32,Anexos!$A$12:$AP$17,21),$E$8="Anexo IV",VLOOKUP(D32,Anexos!$A$12:$AP$17,29),$E$8="Anexo V",VLOOKUP(D32,Anexos!$A$12:$AP$17,36)),0) -> -5940 | E35: =-IFERROR(_xlfn.IFS($E$8="Anexo I",VLOOKUP(E32,Anexos!$A$12:$AP$17,4),$E$8="Anexo II",VLOOKUP(E32,Anexos!$A$12:$AP$17,12),$E$8="Anexo III",VLOOKUP(E32,Anexos!$A$12:$AP$17,21),$E$8="Anexo IV",VLOOKUP(E32,Anexos!$A$12:$AP$17,29),$E$8="Anexo V",VLOOKUP(E32,Anexos!$A$12:$AP$17,36)),0) -> -5940 | F35: =-IFERROR(_xlfn.IFS($E$8="Anexo I",VLOOKUP(F32,Anexos!$A$12:$AP$17,4),$E$8="Anexo II",VLOOKUP(F32,Anexos!$A$12:$AP$17,12),$E$8="Anexo III",VLOOKUP(F32,Anexos!$A$12:$AP$17,21),$E$8="Anexo IV",VLOOKUP(F32,Anexos!$A$12:$AP$17,29),$E$8="Anexo V",VLOOKUP(F32,Anexos!$A$12:$AP$17,36)),0) -> -5940 | G35: =-IFERROR(_xlfn.IFS($E$8="Anexo I",VLOOKUP(G32,Anexos!$A$12:$AP$17,4),$E$8="Anexo II",VLOOKUP(G32,Anexos!$A$12:$AP$17,12),$E$8="Anexo III",VLOOKUP(G32,Anexos!$A$12:$AP$17,21),$E$8="Anexo IV",VLOOKUP(G32,Anexos!$A$12:$AP$17,29),$E$8="Anexo V",VLOOKUP(G32,Anexos!$A$12:$AP$17,36)),0) -> -5940 | H35: =-IFERROR(_xlfn.IFS($E$8="Anexo I",VLOOKUP(H32,Anexos!$A$12:$AP$17,4),$E$8="Anexo II",VLOOKUP(H32,Anexos!$A$12:$AP$17,12),$E$8="Anexo III",VLOOKUP(H32,Anexos!$A$12:$AP$17,21),$E$8="Anexo IV",VLOOKUP(H32,Anexos!$A$12:$AP$17,29),$E$8="Anexo V",VLOOKUP(H32,Anexos!$A$12:$AP$17,36)),0) -> -5940 | I35: =-IFERROR(_xlfn.IFS($E$8="Anexo I",VLOOKUP(I32,Anexos!$A$12:$AP$17,4),$E$8="Anexo II",VLOOKUP(I32,Anexos!$A$12:$AP$17,12),$E$8="Anexo III",VLOOKUP(I32,Anexos!$A$12:$AP$17,21),$E$8="Anexo IV",VLOOKUP(I32,Anexos!$A$12:$AP$17,29),$E$8="Anexo V",VLOOKUP(I32,Anexos!$A$12:$AP$17,36)),0) -> -5940 | J35: =-IFERROR(_xlfn.IFS($E$8="Anexo I",VLOOKUP(J32,Anexos!$A$12:$AP$17,4),$E$8="Anexo II",VLOOKUP(J32,Anexos!$A$12:$AP$17,12),$E$8="Anexo III",VLOOKUP(J32,Anexos!$A$12:$AP$17,21),$E$8="Anexo IV",VLOOKUP(J32,Anexos!$A$12:$AP$17,29),$E$8="Anexo V",VLOOKUP(J32,Anexos!$A$12:$AP$17,36)),0) -> -5940 | K35: =-IFERROR(_xlfn.IFS($E$8="Anexo I",VLOOKUP(K32,Anexos!$A$12:$AP$17,4),$E$8="Anexo II",VLOOKUP(K32,Anexos!$A$12:$AP$17,12),$E$8="Anexo III",VLOOKUP(K32,Anexos!$A$12:$AP$17,21),$E$8="Anexo IV",VLOOKUP(K32,Anexos!$A$12:$AP$17,29),$E$8="Anexo V",VLOOKUP(K32,Anexos!$A$12:$AP$17,36)),0) -> -5940 | ... O35: =-IFERROR(_xlfn.IFS($E$8="Anexo I",VLOOKUP(O32,Anexos!$A$12:$AP$17,4),$E$8="Anexo II",VLOOKUP(O32,Anexos!$A$12:$AP$17,12),$E$8="Anexo III",VLOOKUP(O32,Anexos!$A$12:$AP$17,21),$E$8="Anexo IV",VLOOKUP(O32,Anexos!$A$12:$AP$17,29),$E$8="Anexo V",VLOOKUP(O32,Anexos!$A$12:$AP$17,36)),0) -> 0
B36: Alíquota Efetiva Integral | D36: =IFERROR(ROUND(SUM(D34:D35)/D32,4),0) -> 0.0483 | E36: =IFERROR(ROUND(SUM(E34:E35)/E32,4),0) -> 0.0483 | F36: =IFERROR(ROUND(SUM(F34:F35)/F32,4),0) -> 0.046 | G36: =IFERROR(ROUND(SUM(G34:G35)/G32,4),0) -> 0.0458 | H36: =IFERROR(ROUND(SUM(H34:H35)/H32,4),0) -> 0.0455 | I36: =IFERROR(ROUND(SUM(I34:I35)/I32,4),0) -> 0.0452 | J36: =IFERROR(ROUND(SUM(J34:J35)/J32,4),0) -> 0.0447 | K36: =IFERROR(ROUND(SUM(K34:K35)/K32,4),0) -> 0.0441 | ... O36: =IFERROR(ROUND(SUM(O34:O35)/O32,4),0) -> 0.04
B37: Simples Nacional | D37: =IFERROR(D31*SUM(D38:D45),0) -> 966 | E37: =IFERROR(E31*SUM(E38:E45),0) -> 0 | F37: =IFERROR(F31*SUM(F38:F45),0) -> 0 | G37: =IFERROR(G31*SUM(G38:G45),0) -> 0 | H37: =IFERROR(H31*SUM(H38:H45),0) -> 0 | I37: =IFERROR(I31*SUM(I38:I45),0) -> 0 | J37: =IFERROR(J31*SUM(J38:J45),0) -> 0 | K37: =IFERROR(K31*SUM(K38:K45),0) -> 0 | ... O37: =IFERROR(O31*SUM(O38:O45),0) -> 0
B38: Repartição do IRPJ | C38: 1 | D38: =IFERROR(_xlfn.IFS($E$8="Anexo I",VLOOKUP(D32,Anexos!$A$12:$AP$17,5),$E$8="Anexo II",VLOOKUP(D32,Anexos!$A$12:$AP$17,13),$E$8="Anexo III",VLOOKUP(D32,Anexos!$A$12:$AP$17,22),$E$8="Anexo IV",VLOOKUP(D32,Anexos!$A$12:$AP$17,30),$E$8="Anexo V",VLOOKUP(D32,Anexos!$A$12:$AP$17,37))*D36*$C$38,0) -> 0.0026565 | E38: =IFERROR(_xlfn.IFS($E$8="Anexo I",VLOOKUP(E32,Anexos!$A$12:$AP$17,5),$E$8="Anexo II",VLOOKUP(E32,Anexos!$A$12:$AP$17,13),$E$8="Anexo III",VLOOKUP(E32,Anexos!$A$12:$AP$17,22),$E$8="Anexo IV",VLOOKUP(E32,Anexos!$A$12:$AP$17,30),$E$8="Anexo V",VLOOKUP(E32,Anexos!$A$12:$AP$17,37))*E36*$C$38,0) -> 0.0026565 | F38: =IFERROR(_xlfn.IFS($E$8="Anexo I",VLOOKUP(F32,Anexos!$A$12:$AP$17,5),$E$8="Anexo II",VLOOKUP(F32,Anexos!$A$12:$AP$17,13),$E$8="Anexo III",VLOOKUP(F32,Anexos!$A$12:$AP$17,22),$E$8="Anexo IV",VLOOKUP(F32,Anexos!$A$12:$AP$17,30),$E$8="Anexo V",VLOOKUP(F32,Anexos!$A$12:$AP$17,37))*F36*$C$38,0) -> 0.00253 | G38: =IFERROR(_xlfn.IFS($E$8="Anexo I",VLOOKUP(G32,Anexos!$A$12:$AP$17,5),$E$8="Anexo II",VLOOKUP(G32,Anexos!$A$12:$AP$17,13),$E$8="Anexo III",VLOOKUP(G32,Anexos!$A$12:$AP$17,22),$E$8="Anexo IV",VLOOKUP(G32,Anexos!$A$12:$AP$17,30),$E$8="Anexo V",VLOOKUP(G32,Anexos!$A$12:$AP$17,37))*G36*$C$38,0) -> 0.002519 | H38: =IFERROR(_xlfn.IFS($E$8="Anexo I",VLOOKUP(H32,Anexos!$A$12:$AP$17,5),$E$8="Anexo II",VLOOKUP(H32,Anexos!$A$12:$AP$17,13),$E$8="Anexo III",VLOOKUP(H32,Anexos!$A$12:$AP$17,22),$E$8="Anexo IV",VLOOKUP(H32,Anexos!$A$12:$AP$17,30),$E$8="Anexo V",VLOOKUP(H32,Anexos!$A$12:$AP$17,37))*H36*$C$38,0) -> 0.0025025 | I38: =IFERROR(_xlfn.IFS($E$8="Anexo I",VLOOKUP(I32,Anexos!$A$12:$AP$17,5),$E$8="Anexo II",VLOOKUP(I32,Anexos!$A$12:$AP$17,13),$E$8="Anexo III",VLOOKUP(I32,Anexos!$A$12:$AP$17,22),$E$8="Anexo IV",VLOOKUP(I32,Anexos!$A$12:$AP$17,30),$E$8="Anexo V",VLOOKUP(I32,Anexos!$A$12:$AP$17,37))*I36*$C$38,0) -> 0.002486 | J38: =IFERROR(_xlfn.IFS($E$8="Anexo I",VLOOKUP(J32,Anexos!$A$12:$AP$17,5),$E$8="Anexo II",VLOOKUP(J32,Anexos!$A$12:$AP$17,13),$E$8="Anexo III",VLOOKUP(J32,Anexos!$A$12:$AP$17,22),$E$8="Anexo IV",VLOOKUP(J32,Anexos!$A$12:$AP$17,30),$E$8="Anexo V",VLOOKUP(J32,Anexos!$A$12:$AP$17,37))*J36*$C$38,0) -> 0.0024585 | K38: =IFERROR(_xlfn.IFS($E$8="Anexo I",VLOOKUP(K32,Anexos!$A$12:$AP$17,5),$E$8="Anexo II",VLOOKUP(K32,Anexos!$A$12:$AP$17,13),$E$8="Anexo III",VLOOKUP(K32,Anexos!$A$12:$AP$17,22),$E$8="Anexo IV",VLOOKUP(K32,Anexos!$A$12:$AP$17,30),$E$8="Anexo V",VLOOKUP(K32,Anexos!$A$12:$AP$17,37))*K36*$C$38,0) -> 0.0024255 | ... O38: =IFERROR(_xlfn.IFS($E$8="Anexo I",VLOOKUP(O32,Anexos!$A$12:$AP$17,5),$E$8="Anexo II",VLOOKUP(O32,Anexos!$A$12:$AP$17,13),$E$8="Anexo III",VLOOKUP(O32,Anexos!$A$12:$AP$17,22),$E$8="Anexo IV",VLOOKUP(O32,Anexos!$A$12:$AP$17,30),$E$8="Anexo V",VLOOKUP(O32,Anexos!$A$12:$AP$17,37))*O36*$C$38,0) -> 0.0022
B39: Repartição do CSLL | C39: 1 | D39: =IFERROR(_xlfn.IFS($E$8="Anexo I",VLOOKUP(D32,Anexos!$A$12:$AP$17,6),$E$8="Anexo II",VLOOKUP(D32,Anexos!$A$12:$AP$17,14),$E$8="Anexo III",VLOOKUP(D32,Anexos!$A$12:$AP$17,23),$E$8="Anexo IV",VLOOKUP(D32,Anexos!$A$12:$AP$17,31),$E$8="Anexo V",VLOOKUP(D32,Anexos!$A$12:$AP$17,38))*D36*$C$39,0) -> 0.0016905 | E39: =IFERROR(_xlfn.IFS($E$8="Anexo I",VLOOKUP(E32,Anexos!$A$12:$AP$17,6),$E$8="Anexo II",VLOOKUP(E32,Anexos!$A$12:$AP$17,14),$E$8="Anexo III",VLOOKUP(E32,Anexos!$A$12:$AP$17,23),$E$8="Anexo IV",VLOOKUP(E32,Anexos!$A$12:$AP$17,31),$E$8="Anexo V",VLOOKUP(E32,Anexos!$A$12:$AP$17,38))*E36*$C$39,0) -> 0.0016905 | F39: =IFERROR(_xlfn.IFS($E$8="Anexo I",VLOOKUP(F32,Anexos!$A$12:$AP$17,6),$E$8="Anexo II",VLOOKUP(F32,Anexos!$A$12:$AP$17,14),$E$8="Anexo III",VLOOKUP(F32,Anexos!$A$12:$AP$17,23),$E$8="Anexo IV",VLOOKUP(F32,Anexos!$A$12:$AP$17,31),$E$8="Anexo V",VLOOKUP(F32,Anexos!$A$12:$AP$17,38))*F36*$C$39,0) -> 0.00161 | G39: =IFERROR(_xlfn.IFS($E$8="Anexo I",VLOOKUP(G32,Anexos!$A$12:$AP$17,6),$E$8="Anexo II",VLOOKUP(G32,Anexos!$A$12:$AP$17,14),$E$8="Anexo III",VLOOKUP(G32,Anexos!$A$12:$AP$17,23),$E$8="Anexo IV",VLOOKUP(G32,Anexos!$A$12:$AP$17,31),$E$8="Anexo V",VLOOKUP(G32,Anexos!$A$12:$AP$17,38))*G36*$C$39,0) -> 0.001603 | H39: =IFERROR(_xlfn.IFS($E$8="Anexo I",VLOOKUP(H32,Anexos!$A$12:$AP$17,6),$E$8="Anexo II",VLOOKUP(H32,Anexos!$A$12:$AP$17,14),$E$8="Anexo III",VLOOKUP(H32,Anexos!$A$12:$AP$17,23),$E$8="Anexo IV",VLOOKUP(H32,Anexos!$A$12:$AP$17,31),$E$8="Anexo V",VLOOKUP(H32,Anexos!$A$12:$AP$17,38))*H36*$C$39,0) -> 0.0015925 | I39: =IFERROR(_xlfn.IFS($E$8="Anexo I",VLOOKUP(I32,Anexos!$A$12:$AP$17,6),$E$8="Anexo II",VLOOKUP(I32,Anexos!$A$12:$AP$17,14),$E$8="Anexo III",VLOOKUP(I32,Anexos!$A$12:$AP$17,23),$E$8="Anexo IV",VLOOKUP(I32,Anexos!$A$12:$AP$17,31),$E$8="Anexo V",VLOOKUP(I32,Anexos!$A$12:$AP$17,38))*I36*$C$39,0) -> 0.001582 | J39: =IFERROR(_xlfn.IFS($E$8="Anexo I",VLOOKUP(J32,Anexos!$A$12:$AP$17,6),$E$8="Anexo II",VLOOKUP(J32,Anexos!$A$12:$AP$17,14),$E$8="Anexo III",VLOOKUP(J32,Anexos!$A$12:$AP$17,23),$E$8="Anexo IV",VLOOKUP(J32,Anexos!$A$12:$AP$17,31),$E$8="Anexo V",VLOOKUP(J32,Anexos!$A$12:$AP$17,38))*J36*$C$39,0) -> 0.0015645 | K39: =IFERROR(_xlfn.IFS($E$8="Anexo I",VLOOKUP(K32,Anexos!$A$12:$AP$17,6),$E$8="Anexo II",VLOOKUP(K32,Anexos!$A$12:$AP$17,14),$E$8="Anexo III",VLOOKUP(K32,Anexos!$A$12:$AP$17,23),$E$8="Anexo IV",VLOOKUP(K32,Anexos!$A$12:$AP$17,31),$E$8="Anexo V",VLOOKUP(K32,Anexos!$A$12:$AP$17,38))*K36*$C$39,0) -> 0.0015435 | ... O39: =IFERROR(_xlfn.IFS($E$8="Anexo I",VLOOKUP(O32,Anexos!$A$12:$AP$17,6),$E$8="Anexo II",VLOOKUP(O32,Anexos!$A$12:$AP$17,14),$E$8="Anexo III",VLOOKUP(O32,Anexos!$A$12:$AP$17,23),$E$8="Anexo IV",VLOOKUP(O32,Anexos!$A$12:$AP$17,31),$E$8="Anexo V",VLOOKUP(O32,Anexos!$A$12:$AP$17,38))*O36*$C$39,0) -> 0.0014
B40: Repartição do COFINS | C40: 1 | D40: =IFERROR(_xlfn.IFS($E$8="Anexo I",VLOOKUP(D32,Anexos!$A$12:$AP$17,7),$E$8="Anexo II",VLOOKUP(D32,Anexos!$A$12:$AP$17,15),$E$8="Anexo III",VLOOKUP(D32,Anexos!$A$12:$AP$17,24),$E$8="Anexo IV",VLOOKUP(D32,Anexos!$A$12:$AP$17,32),$E$8="Anexo V",VLOOKUP(D32,Anexos!$A$12:$AP$17,39))*D36*$C$40,0) -> 0.00615342 | E40: =IFERROR(_xlfn.IFS($E$8="Anexo I",VLOOKUP(E32,Anexos!$A$12:$AP$17,7),$E$8="Anexo II",VLOOKUP(E32,Anexos!$A$12:$AP$17,15),$E$8="Anexo III",VLOOKUP(E32,Anexos!$A$12:$AP$17,24),$E$8="Anexo IV",VLOOKUP(E32,Anexos!$A$12:$AP$17,32),$E$8="Anexo V",VLOOKUP(E32,Anexos!$A$12:$AP$17,39))*E36*$C$40,0) -> 0.00615342 | F40: =IFERROR(_xlfn.IFS($E$8="Anexo I",VLOOKUP(F32,Anexos!$A$12:$AP$17,7),$E$8="Anexo II",VLOOKUP(F32,Anexos!$A$12:$AP$17,15),$E$8="Anexo III",VLOOKUP(F32,Anexos!$A$12:$AP$17,24),$E$8="Anexo IV",VLOOKUP(F32,Anexos!$A$12:$AP$17,32),$E$8="Anexo V",VLOOKUP(F32,Anexos!$A$12:$AP$17,39))*F36*$C$40,0) -> 0.0058604 | G40: =IFERROR(_xlfn.IFS($E$8="Anexo I",VLOOKUP(G32,Anexos!$A$12:$AP$17,7),$E$8="Anexo II",VLOOKUP(G32,Anexos!$A$12:$AP$17,15),$E$8="Anexo III",VLOOKUP(G32,Anexos!$A$12:$AP$17,24),$E$8="Anexo IV",VLOOKUP(G32,Anexos!$A$12:$AP$17,32),$E$8="Anexo V",VLOOKUP(G32,Anexos!$A$12:$AP$17,39))*G36*$C$40,0) -> 0.00583492 | H40: =IFERROR(_xlfn.IFS($E$8="Anexo I",VLOOKUP(H32,Anexos!$A$12:$AP$17,7),$E$8="Anexo II",VLOOKUP(H32,Anexos!$A$12:$AP$17,15),$E$8="Anexo III",VLOOKUP(H32,Anexos!$A$12:$AP$17,24),$E$8="Anexo IV",VLOOKUP(H32,Anexos!$A$12:$AP$17,32),$E$8="Anexo V",VLOOKUP(H32,Anexos!$A$12:$AP$17,39))*H36*$C$40,0) -> 0.0057967 | I40: =IFERROR(_xlfn.IFS($E$8="Anexo I",VLOOKUP(I32,Anexos!$A$12:$AP$17,7),$E$8="Anexo II",VLOOKUP(I32,Anexos!$A$12:$AP$17,15),$E$8="Anexo III",VLOOKUP(I32,Anexos!$A$12:$AP$17,24),$E$8="Anexo IV",VLOOKUP(I32,Anexos!$A$12:$AP$17,32),$E$8="Anexo V",VLOOKUP(I32,Anexos!$A$12:$AP$17,39))*I36*$C$40,0) -> 0.00575848 | J40: =IFERROR(_xlfn.IFS($E$8="Anexo I",VLOOKUP(J32,Anexos!$A$12:$AP$17,7),$E$8="Anexo II",VLOOKUP(J32,Anexos!$A$12:$AP$17,15),$E$8="Anexo III",VLOOKUP(J32,Anexos!$A$12:$AP$17,24),$E$8="Anexo IV",VLOOKUP(J32,Anexos!$A$12:$AP$17,32),$E$8="Anexo V",VLOOKUP(J32,Anexos!$A$12:$AP$17,39))*J36*$C$40,0) -> 0.00569478 | K40: =IFERROR(_xlfn.IFS($E$8="Anexo I",VLOOKUP(K32,Anexos!$A$12:$AP$17,7),$E$8="Anexo II",VLOOKUP(K32,Anexos!$A$12:$AP$17,15),$E$8="Anexo III",VLOOKUP(K32,Anexos!$A$12:$AP$17,24),$E$8="Anexo IV",VLOOKUP(K32,Anexos!$A$12:$AP$17,32),$E$8="Anexo V",VLOOKUP(K32,Anexos!$A$12:$AP$17,39))*K36*$C$40,0) -> 0.00561834 | ... O40: =IFERROR(_xlfn.IFS($E$8="Anexo I",VLOOKUP(O32,Anexos!$A$12:$AP$17,7),$E$8="Anexo II",VLOOKUP(O32,Anexos!$A$12:$AP$17,15),$E$8="Anexo III",VLOOKUP(O32,Anexos!$A$12:$AP$17,24),$E$8="Anexo IV",VLOOKUP(O32,Anexos!$A$12:$AP$17,32),$E$8="Anexo V",VLOOKUP(O32,Anexos!$A$12:$AP$17,39))*O36*$C$40,0) -> 0.005096
B41: Repartição do PIS/Pasep | C41: 1 | D41: =IFERROR(_xlfn.IFS($E$8="Anexo I",VLOOKUP(D32,Anexos!$A$12:$AP$17,8),$E$8="Anexo II",VLOOKUP(D32,Anexos!$A$12:$AP$17,16),$E$8="Anexo III",VLOOKUP(D32,Anexos!$A$12:$AP$17,25),$E$8="Anexo IV",VLOOKUP(D32,Anexos!$A$12:$AP$17,33),$E$8="Anexo V",VLOOKUP(D32,Anexos!$A$12:$AP$17,40))*D36*$C$41,0) -> 0.00133308 | E41: =IFERROR(_xlfn.IFS($E$8="Anexo I",VLOOKUP(E32,Anexos!$A$12:$AP$17,8),$E$8="Anexo II",VLOOKUP(E32,Anexos!$A$12:$AP$17,16),$E$8="Anexo III",VLOOKUP(E32,Anexos!$A$12:$AP$17,25),$E$8="Anexo IV",VLOOKUP(E32,Anexos!$A$12:$AP$17,33),$E$8="Anexo V",VLOOKUP(E32,Anexos!$A$12:$AP$17,40))*E36*$C$41,0) -> 0.00133308 | F41: =IFERROR(_xlfn.IFS($E$8="Anexo I",VLOOKUP(F32,Anexos!$A$12:$AP$17,8),$E$8="Anexo II",VLOOKUP(F32,Anexos!$A$12:$AP$17,16),$E$8="Anexo III",VLOOKUP(F32,Anexos!$A$12:$AP$17,25),$E$8="Anexo IV",VLOOKUP(F32,Anexos!$A$12:$AP$17,33),$E$8="Anexo V",VLOOKUP(F32,Anexos!$A$12:$AP$17,40))*F36*$C$41,0) -> 0.0012696 | G41: =IFERROR(_xlfn.IFS($E$8="Anexo I",VLOOKUP(G32,Anexos!$A$12:$AP$17,8),$E$8="Anexo II",VLOOKUP(G32,Anexos!$A$12:$AP$17,16),$E$8="Anexo III",VLOOKUP(G32,Anexos!$A$12:$AP$17,25),$E$8="Anexo IV",VLOOKUP(G32,Anexos!$A$12:$AP$17,33),$E$8="Anexo V",VLOOKUP(G32,Anexos!$A$12:$AP$17,40))*G36*$C$41,0) -> 0.00126408 | H41: =IFERROR(_xlfn.IFS($E$8="Anexo I",VLOOKUP(H32,Anexos!$A$12:$AP$17,8),$E$8="Anexo II",VLOOKUP(H32,Anexos!$A$12:$AP$17,16),$E$8="Anexo III",VLOOKUP(H32,Anexos!$A$12:$AP$17,25),$E$8="Anexo IV",VLOOKUP(H32,Anexos!$A$12:$AP$17,33),$E$8="Anexo V",VLOOKUP(H32,Anexos!$A$12:$AP$17,40))*H36*$C$41,0) -> 0.0012558 | I41: =IFERROR(_xlfn.IFS($E$8="Anexo I",VLOOKUP(I32,Anexos!$A$12:$AP$17,8),$E$8="Anexo II",VLOOKUP(I32,Anexos!$A$12:$AP$17,16),$E$8="Anexo III",VLOOKUP(I32,Anexos!$A$12:$AP$17,25),$E$8="Anexo IV",VLOOKUP(I32,Anexos!$A$12:$AP$17,33),$E$8="Anexo V",VLOOKUP(I32,Anexos!$A$12:$AP$17,40))*I36*$C$41,0) -> 0.00124752 | J41: =IFERROR(_xlfn.IFS($E$8="Anexo I",VLOOKUP(J32,Anexos!$A$12:$AP$17,8),$E$8="Anexo II",VLOOKUP(J32,Anexos!$A$12:$AP$17,16),$E$8="Anexo III",VLOOKUP(J32,Anexos!$A$12:$AP$17,25),$E$8="Anexo IV",VLOOKUP(J32,Anexos!$A$12:$AP$17,33),$E$8="Anexo V",VLOOKUP(J32,Anexos!$A$12:$AP$17,40))*J36*$C$41,0) -> 0.00123372 | K41: =IFERROR(_xlfn.IFS($E$8="Anexo I",VLOOKUP(K32,Anexos!$A$12:$AP$17,8),$E$8="Anexo II",VLOOKUP(K32,Anexos!$A$12:$AP$17,16),$E$8="Anexo III",VLOOKUP(K32,Anexos!$A$12:$AP$17,25),$E$8="Anexo IV",VLOOKUP(K32,Anexos!$A$12:$AP$17,33),$E$8="Anexo V",VLOOKUP(K32,Anexos!$A$12:$AP$17,40))*K36*$C$41,0) -> 0.00121716 | ... O41: =IFERROR(_xlfn.IFS($E$8="Anexo I",VLOOKUP(O32,Anexos!$A$12:$AP$17,8),$E$8="Anexo II",VLOOKUP(O32,Anexos!$A$12:$AP$17,16),$E$8="Anexo III",VLOOKUP(O32,Anexos!$A$12:$AP$17,25),$E$8="Anexo IV",VLOOKUP(O32,Anexos!$A$12:$AP$17,33),$E$8="Anexo V",VLOOKUP(O32,Anexos!$A$12:$AP$17,40))*O36*$C$41,0) -> 0.001104
B42: Repartição do CPP | C42: 1 | D42: =IFERROR(_xlfn.IFS($E$8="Anexo I",VLOOKUP(D32,Anexos!$A$12:$AP$17,9),$E$8="Anexo II",VLOOKUP(D32,Anexos!$A$12:$AP$17,17),$E$8="Anexo III",VLOOKUP(D32,Anexos!$A$12:$AP$17,26),$E$8="Anexo V",VLOOKUP(D32,Anexos!$A$12:$AP$17,41))*D36*$C$42,0) -> 0.0200445 | E42: =IFERROR(_xlfn.IFS($E$8="Anexo I",VLOOKUP(E32,Anexos!$A$12:$AP$17,9),$E$8="Anexo II",VLOOKUP(E32,Anexos!$A$12:$AP$17,17),$E$8="Anexo III",VLOOKUP(E32,Anexos!$A$12:$AP$17,26),$E$8="Anexo V",VLOOKUP(E32,Anexos!$A$12:$AP$17,41))*E36*$C$42,0) -> 0.0200445 | F42: =IFERROR(_xlfn.IFS($E$8="Anexo I",VLOOKUP(F32,Anexos!$A$12:$AP$17,9),$E$8="Anexo II",VLOOKUP(F32,Anexos!$A$12:$AP$17,17),$E$8="Anexo III",VLOOKUP(F32,Anexos!$A$12:$AP$17,26),$E$8="Anexo V",VLOOKUP(F32,Anexos!$A$12:$AP$17,41))*F36*$C$42,0) -> 0.01909 | G42: =IFERROR(_xlfn.IFS($E$8="Anexo I",VLOOKUP(G32,Anexos!$A$12:$AP$17,9),$E$8="Anexo II",VLOOKUP(G32,Anexos!$A$12:$AP$17,17),$E$8="Anexo III",VLOOKUP(G32,Anexos!$A$12:$AP$17,26),$E$8="Anexo V",VLOOKUP(G32,Anexos!$A$12:$AP$17,41))*G36*$C$42,0) -> 0.019007 | H42: =IFERROR(_xlfn.IFS($E$8="Anexo I",VLOOKUP(H32,Anexos!$A$12:$AP$17,9),$E$8="Anexo II",VLOOKUP(H32,Anexos!$A$12:$AP$17,17),$E$8="Anexo III",VLOOKUP(H32,Anexos!$A$12:$AP$17,26),$E$8="Anexo V",VLOOKUP(H32,Anexos!$A$12:$AP$17,41))*H36*$C$42,0) -> 0.0188825 | I42: =IFERROR(_xlfn.IFS($E$8="Anexo I",VLOOKUP(I32,Anexos!$A$12:$AP$17,9),$E$8="Anexo II",VLOOKUP(I32,Anexos!$A$12:$AP$17,17),$E$8="Anexo III",VLOOKUP(I32,Anexos!$A$12:$AP$17,26),$E$8="Anexo V",VLOOKUP(I32,Anexos!$A$12:$AP$17,41))*I36*$C$42,0) -> 0.018758 | J42: =IFERROR(_xlfn.IFS($E$8="Anexo I",VLOOKUP(J32,Anexos!$A$12:$AP$17,9),$E$8="Anexo II",VLOOKUP(J32,Anexos!$A$12:$AP$17,17),$E$8="Anexo III",VLOOKUP(J32,Anexos!$A$12:$AP$17,26),$E$8="Anexo V",VLOOKUP(J32,Anexos!$A$12:$AP$17,41))*J36*$C$42,0) -> 0.0185505 | K42: =IFERROR(_xlfn.IFS($E$8="Anexo I",VLOOKUP(K32,Anexos!$A$12:$AP$17,9),$E$8="Anexo II",VLOOKUP(K32,Anexos!$A$12:$AP$17,17),$E$8="Anexo III",VLOOKUP(K32,Anexos!$A$12:$AP$17,26),$E$8="Anexo V",VLOOKUP(K32,Anexos!$A$12:$AP$17,41))*K36*$C$42,0) -> 0.0183015 | ... O42: =IFERROR(_xlfn.IFS($E$8="Anexo I",VLOOKUP(O32,Anexos!$A$12:$AP$17,9),$E$8="Anexo II",VLOOKUP(O32,Anexos!$A$12:$AP$17,17),$E$8="Anexo III",VLOOKUP(O32,Anexos!$A$12:$AP$17,26),$E$8="Anexo V",VLOOKUP(O32,Anexos!$A$12:$AP$17,41))*O36*$C$42,0) -> 0.0166
B43: Repartição do IPI | C43: 1 | D43: =IFERROR(_xlfn.IFS($E$8="Anexo II",VLOOKUP(D32,Anexos!$A$12:$AP$17,18))*D36*$C$43,0) -> 0 | E43: =IFERROR(_xlfn.IFS($E$8="Anexo II",VLOOKUP(E32,Anexos!$A$12:$AP$17,18))*E36*$C$43,0) -> 0 | F43: =IFERROR(_xlfn.IFS($E$8="Anexo II",VLOOKUP(F32,Anexos!$A$12:$AP$17,18))*F36*$C$43,0) -> 0 | G43: =IFERROR(_xlfn.IFS($E$8="Anexo II",VLOOKUP(G32,Anexos!$A$12:$AP$17,18))*G36*$C$43,0) -> 0 | H43: =IFERROR(_xlfn.IFS($E$8="Anexo II",VLOOKUP(H32,Anexos!$A$12:$AP$17,18))*H36*$C$43,0) -> 0 | I43: =IFERROR(_xlfn.IFS($E$8="Anexo II",VLOOKUP(I32,Anexos!$A$12:$AP$17,18))*I36*$C$43,0) -> 0 | J43: =IFERROR(_xlfn.IFS($E$8="Anexo II",VLOOKUP(J32,Anexos!$A$12:$AP$17,18))*J36*$C$43,0) -> 0 | K43: =IFERROR(_xlfn.IFS($E$8="Anexo II",VLOOKUP(K32,Anexos!$A$12:$AP$17,18))*K36*$C$43,0) -> 0 | ... O43: =IFERROR(_xlfn.IFS($E$8="Anexo II",VLOOKUP(O32,Anexos!$A$12:$AP$17,18))*O36*$C$43,0) -> 0
B44: Repartição do ICMS | C44: 1 | D44: =IFERROR(_xlfn.IFS($E$8="Anexo I",VLOOKUP(D32,Anexos!$A$12:$AP$17,10),$E$8="Anexo II",VLOOKUP(D32,Anexos!$A$12:$AP$17,19))*D36*$C$44,0) -> 0.016422 | E44: =IFERROR(_xlfn.IFS($E$8="Anexo I",VLOOKUP(E32,Anexos!$A$12:$AP$17,10),$E$8="Anexo II",VLOOKUP(E32,Anexos!$A$12:$AP$17,19))*E36*$C$44,0) -> 0.016422 | F44: =IFERROR(_xlfn.IFS($E$8="Anexo I",VLOOKUP(F32,Anexos!$A$12:$AP$17,10),$E$8="Anexo II",VLOOKUP(F32,Anexos!$A$12:$AP$17,19))*F36*$C$44,0) -> 0.01564 | G44: =IFERROR(_xlfn.IFS($E$8="Anexo I",VLOOKUP(G32,Anexos!$A$12:$AP$17,10),$E$8="Anexo II",VLOOKUP(G32,Anexos!$A$12:$AP$17,19))*G36*$C$44,0) -> 0.015572 | H44: =IFERROR(_xlfn.IFS($E$8="Anexo I",VLOOKUP(H32,Anexos!$A$12:$AP$17,10),$E$8="Anexo II",VLOOKUP(H32,Anexos!$A$12:$AP$17,19))*H36*$C$44,0) -> 0.01547 | I44: =IFERROR(_xlfn.IFS($E$8="Anexo I",VLOOKUP(I32,Anexos!$A$12:$AP$17,10),$E$8="Anexo II",VLOOKUP(I32,Anexos!$A$12:$AP$17,19))*I36*$C$44,0) -> 0.015368 | J44: =IFERROR(_xlfn.IFS($E$8="Anexo I",VLOOKUP(J32,Anexos!$A$12:$AP$17,10),$E$8="Anexo II",VLOOKUP(J32,Anexos!$A$12:$AP$17,19))*J36*$C$44,0) -> 0.015198 | K44: =IFERROR(_xlfn.IFS($E$8="Anexo I",VLOOKUP(K32,Anexos!$A$12:$AP$17,10),$E$8="Anexo II",VLOOKUP(K32,Anexos!$A$12:$AP$17,19))*K36*$C$44,0) -> 0.014994 | ... O44: =IFERROR(_xlfn.IFS($E$8="Anexo I",VLOOKUP(O32,Anexos!$A$12:$AP$17,10),$E$8="Anexo II",VLOOKUP(O32,Anexos!$A$12:$AP$17,19))*O36*$C$44,0) -> 0.0136
B45: Repartição do ISS | C45: 1 | D45: =IFERROR(_xlfn.IFS($E$8="Anexo III",VLOOKUP(D32,Anexos!$A$12:$AP$17,27),$E$8="Anexo IV",VLOOKUP(D32,Anexos!$A$12:$AP$17,34),$E$8="Anexo V",VLOOKUP(D32,Anexos!$A$12:$AP$17,42))*D36*$C$45,0) -> 0 | E45: =IFERROR(_xlfn.IFS($E$8="Anexo III",VLOOKUP(E32,Anexos!$A$12:$AP$17,27),$E$8="Anexo IV",VLOOKUP(E32,Anexos!$A$12:$AP$17,34),$E$8="Anexo V",VLOOKUP(E32,Anexos!$A$12:$AP$17,42))*E36*$C$45,0) -> 0 | F45: =IFERROR(_xlfn.IFS($E$8="Anexo III",VLOOKUP(F32,Anexos!$A$12:$AP$17,27),$E$8="Anexo IV",VLOOKUP(F32,Anexos!$A$12:$AP$17,34),$E$8="Anexo V",VLOOKUP(F32,Anexos!$A$12:$AP$17,42))*F36*$C$45,0) -> 0 | G45: =IFERROR(_xlfn.IFS($E$8="Anexo III",VLOOKUP(G32,Anexos!$A$12:$AP$17,27),$E$8="Anexo IV",VLOOKUP(G32,Anexos!$A$12:$AP$17,34),$E$8="Anexo V",VLOOKUP(G32,Anexos!$A$12:$AP$17,42))*G36*$C$45,0) -> 0 | H45: =IFERROR(_xlfn.IFS($E$8="Anexo III",VLOOKUP(H32,Anexos!$A$12:$AP$17,27),$E$8="Anexo IV",VLOOKUP(H32,Anexos!$A$12:$AP$17,34),$E$8="Anexo V",VLOOKUP(H32,Anexos!$A$12:$AP$17,42))*H36*$C$45,0) -> 0 | I45: =IFERROR(_xlfn.IFS($E$8="Anexo III",VLOOKUP(I32,Anexos!$A$12:$AP$17,27),$E$8="Anexo IV",VLOOKUP(I32,Anexos!$A$12:$AP$17,34),$E$8="Anexo V",VLOOKUP(I32,Anexos!$A$12:$AP$17,42))*I36*$C$45,0) -> 0 | J45: =IFERROR(_xlfn.IFS($E$8="Anexo III",VLOOKUP(J32,Anexos!$A$12:$AP$17,27),$E$8="Anexo IV",VLOOKUP(J32,Anexos!$A$12:$AP$17,34),$E$8="Anexo V",VLOOKUP(J32,Anexos!$A$12:$AP$17,42))*J36*$C$45,0) -> 0 | K45: =IFERROR(_xlfn.IFS($E$8="Anexo III",VLOOKUP(K32,Anexos!$A$12:$AP$17,27),$E$8="Anexo IV",VLOOKUP(K32,Anexos!$A$12:$AP$17,34),$E$8="Anexo V",VLOOKUP(K32,Anexos!$A$12:$AP$17,42))*K36*$C$45,0) -> 0 | ... O45: =IFERROR(_xlfn.IFS($E$8="Anexo III",VLOOKUP(O32,Anexos!$A$12:$AP$17,27),$E$8="Anexo IV",VLOOKUP(O32,Anexos!$A$12:$AP$17,34),$E$8="Anexo V",VLOOKUP(O32,Anexos!$A$12:$AP$17,42))*O36*$C$45,0) -> 0

Sheet Simples Nacional Fator "r"
A1: PLANILHA DE CÁLCULO SIMPLES NACIONAL FATOR "R" 2018
F2: Aviso Desbloqueio
F3: Recomenda-se a utilização do software gratuito LibreOffice.
F4: Download: | G4: https://pt-br.libreoffice.org/baixe-ja/
D7: Referência | E7: Fator "r" para Anexos III ou V
D8: Setor | E8: Prestação de Serviços | G8: arquitetura e urbanismo
B9: Função Contábil
B11: =YEAR($E$15) -> 2018 | C11: meses → | D11: =DATE(B11,1,1) -> 43101 | E11: =EDATE(D11,1) -> 43132 | F11: =EDATE(E11,1) -> 43160 | G11: =EDATE(F11,1) -> 43191 | H11: =EDATE(G11,1) -> 43221 | I11: =EDATE(H11,1) -> 43252 | J11: =EDATE(I11,1) -> 43282 | K11: =EDATE(J11,1) -> 43313 | L11: =EDATE(K11,1) -> 43344 | ... O11: =EDATE(N11,1) -> 43435
B12: Receita Bruta Mensal - 2017 | C12: Referência | D12: 20000 | E12: 20000 | F12: 20000 | G12: 20000 | H12: 20000 | I12: 20000 | J12: 20000 | K12: 20000 | L12: 20000 | M12: 20000 | N12: 20000 | O12: 20000
B13: Folha de Pagamento - Fator "r" | D13: 5000 | E13: 5000 | F13: 5000 | G13: 5000 | H13: 5000 | I13: 5000 | J13: 5000 | K13: 5000 | L13: 5000 | M13: 5000 | N13: 5000 | O13: 5000
D15: Data Atual | E15: =TODAY() -> 43151
B17: =YEAR($E$15) -> 2018 | C17: meses → | D17: =DATE(B17,1,1) -> 43101 | E17: =EDATE(D17,1) -> 43132 | F17: =EDATE(E17,1) -> 43160 | G17: =EDATE(F17,1) -> 43191 | H17: =EDATE(G17,1) -> 43221 | I17: =EDATE(H17,1) -> 43252 | J17: =EDATE(I17,1) -> 43282 | K17: =EDATE(J17,1) -> 43313 | L17: =EDATE(K17,1) -> 43344 | ... O17: =EDATE(N17,1) -> 43435
B18: Receita Bruta Mensal | C18: Redução da Base de Cálculo ↓ | D18: 20000
B19: Receita Acumulada (12 meses) | D19: =AVERAGE(D12:$O$12)*12 -> 240000 | E19: =AVERAGE(E12:$O$12,$D$18)*12 -> 240000 | F19: =AVERAGE(F12:$O$12,$D$18:E18)*12 -> 240000 | G19: =AVERAGE(G12:$O$12,$D$18:F18)*12 -> 240000 | H19: =AVERAGE(H12:$O$12,$D$18:G18)*12 -> 240000 | I19: =AVERAGE(I12:$O$12,$D$18:H18)*12 -> 240000 | J19: =AVERAGE(J12:$O$12,$D$18:I18)*12 -> 240000 | K19: =AVERAGE(K12:$O$12,$D$18:J18)*12 -> 240000 | L19: =AVERAGE(L12:$O$12,$D$18:K18)*12 -> 240000 | M19: =AVERAGE(M12:$O$12,$D$18:L18)*12 -> 240000 | ... O19: =AVERAGE(O12:$O$12,$D$18:N18)*12 -> 240000
B20: Folha de Pagamento - Fator "r" | D20: 10000
B21: Anexo Serviço - Fator "r" | D21: =IFERROR(IF(AVERAGE(D13:$O13)*12/D19>=0.28,"Anexo III","Anexo V"),"") -> Anexo V | E21: =IFERROR(IF(AVERAGE(E13:$O13,$D20)*12/E19>=0.28,"Anexo III","Anexo V"),"") -> Anexo V | F21: =IFERROR(IF(AVERAGE(F13:$O13,$D20:E20)*12/F19>=0.28,"Anexo III","Anexo V"),"") -> Anexo V | G21: =IFERROR(IF(AVERAGE(G13:$O13,$D20:F20)*12/G19>=0.28,"Anexo III","Anexo V"),"") -> Anexo V | H21: =IFERROR(IF(AVERAGE(H13:$O13,$D20:G20)*12/H19>=0.28,"Anexo III","Anexo V"),"") -> Anexo V | I21: =IFERROR(IF(AVERAGE(I13:$O13,$D20:H20)*12/I19>=0.28,"Anexo III","Anexo V"),"") -> Anexo III | J21: =IFERROR(IF(AVERAGE(J13:$O13,$D20:I20)*12/J19>=0.28,"Anexo III","Anexo V"),"") -> Anexo III | K21: =IFERROR(IF(AVERAGE(K13:$O13,$D20:J20)*12/K19>=0.28,"Anexo III","Anexo V"),"") -> Anexo III | L21: =IFERROR(IF(AVERAGE(L13:$O13,$D20:K20)*12/L19>=0.28,"Anexo III","Anexo V"),"") -> Anexo III | M21: =IFERROR(IF(AVERAGE(M13:$O13,$D20:L20)*12/M19>=0.28,"Anexo III","Anexo V"),"") -> Anexo III | ... O21: =IFERROR(IF(AVERAGE(O13:$O13,$D20:N20)*12/O19>=0.28,"Anexo III","Anexo V"),"") -> Anexo III
B22: Alíquota da Tabela | D22: =IFERROR(_xlfn.IFS(D21="Anexo III",VLOOKUP(D19,Anexos!$A$12:$AP$17,20),D21="Anexo V",VLOOKUP(D19,Anexos!$A$12:$AP$17,35)),0) -> 0.18 | E22: =IFERROR(_xlfn.IFS(E21="Anexo III",VLOOKUP(E19,Anexos!$A$12:$AP$17,20),E21="Anexo V",VLOOKUP(E19,Anexos!$A$12:$AP$17,35)),0) -> 0.18 | F22: =IFERROR(_xlfn.IFS(F21="Anexo III",VLOOKUP(F19,Anexos!$A$12:$AP$17,20),F21="Anexo V",VLOOKUP(F19,Anexos!$A$12:$AP$17,35)),0) -> 0.18 | G22: =IFERROR(_xlfn.IFS(G21="Anexo III",VLOOKUP(G19,Anexos!$A$12:$AP$17,20),G21="Anexo V",VLOOKUP(G19,Anexos!$A$12:$AP$17,35)),0) -> 0.18 | H22: =IFERROR(_xlfn.IFS(H21="Anexo III",VLOOKUP(H19,Anexos!$A$12:$AP$17,20),H21="Anexo V",VLOOKUP(H19,Anexos!$A$12:$AP$17,35)),0) -> 0.18 | I22: =IFERROR(_xlfn.IFS(I21="Anexo III",VLOOKUP(I19,Anexos!$A$12:$AP$17,20),I21="Anexo V",VLOOKUP(I19,Anexos!$A$12:$AP$17,35)),0) -> 0.112 | J22: =IFERROR(_xlfn.IFS(J21="Anexo III",VLOOKUP(J19,Anexos!$A$12:$AP$17,20),J21="Anexo V",VLOOKUP(J19,Anexos!$A$12:$AP$17,35)),0) -> 0.112 | K22: =IFERROR(_xlfn.IFS(K21="Anexo III",VLOOKUP(K19,Anexos!$A$12:$AP$17,20),K21="Anexo V",VLOOKUP(K19,Anexos!$A$12:$AP$17,35)),0) -> 0.112 | ... O22: =IFERROR(_xlfn.IFS(O21="Anexo III",VLOOKUP(O19,Anexos!$A$12:$AP$17,20),O21="Anexo V",VLOOKUP(O19,Anexos!$A$12:$AP$17,35)),0) -> 0.112
B23: Memória de Cálculo | D23: =IFERROR(D19*D22,0) -> 43200 | E23: =IFERROR(E19*E22,0) -> 43200 | F23: =IFERROR(F19*F22,0) -> 43200 | G23: =IFERROR(G19*G22,0) -> 43200 | H23: =IFERROR(H19*H22,0) -> 43200 | I23: =IFERROR(I19*I22,0) -> 26880 | J23: =IFERROR(J19*J22,0) -> 26880 | K23: =IFERROR(K19*K22,0) -> 26880 | ... O23: =IFERROR(O19*O22,0) -> 26880
B24: Dedução da Tabela | D24: =-IFERROR(_xlfn.IFS(D21="Anexo I",VLOOKUP(D19,Anexos!$A$12:$AP$17,4),D21="Anexo II",VLOOKUP(D19,Anexos!$A$12:$AP$17,12),D21="Anexo III",VLOOKUP(D19,Anexos!$A$12:$AP$17,21),D21="Anexo IV",VLOOKUP(D19,Anexos!$A$12:$AP$17,29),D21="Anexo V",VLOOKUP(D19,Anexos!$A$12:$AP$17,36)),0) -> -4500 | E24: =-IFERROR(_xlfn.IFS(E21="Anexo I",VLOOKUP(E19,Anexos!$A$12:$AP$17,4),E21="Anexo II",VLOOKUP(E19,Anexos!$A$12:$AP$17,12),E21="Anexo III",VLOOKUP(E19,Anexos!$A$12:$AP$17,21),E21="Anexo IV",VLOOKUP(E19,Anexos!$A$12:$AP$17,29),E21="Anexo V",VLOOKUP(E19,Anexos!$A$12:$AP$17,36)),0) -> -4500 | F24: =-IFERROR(_xlfn.IFS(F21="Anexo I",VLOOKUP(F19,Anexos!$A$12:$AP$17,4),F21="Anexo II",VLOOKUP(F19,Anexos!$A$12:$AP$17,12),F21="Anexo III",VLOOKUP(F19,Anexos!$A$12:$AP$17,21),F21="Anexo IV",VLOOKUP(F19,Anexos!$A$12:$AP$17,29),F21="Anexo V",VLOOKUP(F19,Anexos!$A$12:$AP$17,36)),0) -> -4500 | G24: =-IFERROR(_xlfn.IFS(G21="Anexo I",VLOOKUP(G19,Anexos!$A$12:$AP$17,4),G21="Anexo II",VLOOKUP(G19,Anexos!$A$12:$AP$17,12),G21="Anexo III",VLOOKUP(G19,Anexos!$A$12:$AP$17,21),G21="Anexo IV",VLOOKUP(G19,Anexos!$A$12:$AP$17,29),G21="Anexo V",VLOOKUP(G19,Anexos!$A$12:$AP$17,36)),0) -> -4500 | H24: =-IFERROR(_xlfn.IFS(H21="Anexo I",VLOOKUP(H19,Anexos!$A$12:$AP$17,4),H21="Anexo II",VLOOKUP(H19,Anexos!$A$12:$AP$17,12),H21="Anexo III",VLOOKUP(H19,Anexos!$A$12:$AP$17,21),H21="Anexo IV",VLOOKUP(H19,Anexos!$A$12:$AP$17,29),H21="Anexo V",VLOOKUP(H19,Anexos!$A$12:$AP$17,36)),0) -> -4500 | I24: =-IFERROR(_xlfn.IFS(I21="Anexo I",VLOOKUP(I19,Anexos!$A$12:$AP$17,4),I21="Anexo II",VLOOKUP(I19,Anexos!$A$12:$AP$17,12),I21="Anexo III",VLOOKUP(I19,Anexos!$A$12:$AP$17,21),I21="Anexo IV",VLOOKUP(I19,Anexos!$A$12:$AP$17,29),I21="Anexo V",VLOOKUP(I19,Anexos!$A$12:$AP$17,36)),0) -> -9360 | J24: =-IFERROR(_xlfn.IFS(J21="Anexo I",VLOOKUP(J19,Anexos!$A$12:$AP$17,4),J21="Anexo II",VLOOKUP(J19,Anexos!$A$12:$AP$17,12),J21="Anexo III",VLOOKUP(J19,Anexos!$A$12:$AP$17,21),J21="Anexo IV",VLOOKUP(J19,Anexos!$A$12:$AP$17,29),J21="Anexo V",VLOOKUP(J19,Anexos!$A$12:$AP$17,36)),0) -> -9360 | K24: =-IFERROR(_xlfn.IFS(K21="Anexo I",VLOOKUP(K19,Anexos!$A$12:$AP$17,4),K21="Anexo II",VLOOKUP(K19,Anexos!$A$12:$AP$17,12),K21="Anexo III",VLOOKUP(K19,Anexos!$A$12:$AP$17,21),K21="Anexo IV",VLOOKUP(K19,Anexos!$A$12:$AP$17,29),K21="Anexo V",VLOOKUP(K19,Anexos!$A$12:$AP$17,36)),0) -> -9360 | ... O24: =-IFERROR(_xlfn.IFS(O21="Anexo I",VLOOKUP(O19,Anexos!$A$12:$AP$17,4),O21="Anexo II",VLOOKUP(O19,Anexos!$A$12:$AP$17,12),O21="Anexo III",VLOOKUP(O19,Anexos!$A$12:$AP$17,21),O21="Anexo IV",VLOOKUP(O19,Anexos!$A$12:$AP$17,29),O21="Anexo V",VLOOKUP(O19,Anexos!$A$12:$AP$17,36)),0) -> -9360
B25: Alíquota Efetiva Integral | D25: =IFERROR(ROUND(SUM(D23:D24)/D19,4),0) -> 0.1613 | E25: =IFERROR(ROUND(SUM(E23:E24)/E19,4),0) -> 0.1613 | F25: =IFERROR(ROUND(SUM(F23:F24)/F19,4),0) -> 0.1613 | G25: =IFERROR(ROUND(SUM(G23:G24)/G19,4),0) -> 0.1613 | H25: =IFERROR(ROUND(SUM(H23:H24)/H19,4),0) -> 0.1613 | I25: =IFERROR(ROUND(SUM(I23:I24)/I19,4),0) -> 0.073 | J25: =IFERROR(ROUND(SUM(J23:J24)/J19,4),0) -> 0.073 | K25: =IFERROR(ROUND(SUM(K23:K24)/K19,4),0) -> 0.073 | ... O25: =IFERROR(ROUND(SUM(O23:O24)/O19,4),0) -> 0.073
B26: Valor Simples Nacional | D26: =IFERROR(D18*(SUM(D27:D32)),0) -> 3226 | E26: =IFERROR(E18*(SUM(E27:E32)),0) -> 0 | F26: =IFERROR(F18*(SUM(F27:F32)),0) -> 0 | G26: =IFERROR(G18*(SUM(G27:G32)),0) -> 0 | H26: =IFERROR(H18*(SUM(H27:H32)),0) -> 0 | I26: =IFERROR(I18*(SUM(I27:I32)),0) -> 0 | J26: =IFERROR(J18*(SUM(J27:J32)),0) -> 0 | K26: =IFERROR(K18*(SUM(K27:K32)),0) -> 0 | ... O26: =IFERROR(O18*(SUM(O27:O32)),0) -> 0
B27: Repartição do IRPJ | C27: 1 | D27: =IFERROR(_xlfn.IFS(D21="Anexo III",VLOOKUP(D19,Anexos!$A$12:$AP$17,22),D21="Anexo V",VLOOKUP(D19,Anexos!$A$12:$AP$17,37))*D25*$C$27,0) -> 0.037099 | E27: =IFERROR(_xlfn.IFS(E21="Anexo III",VLOOKUP(E19,Anexos!$A$12:$AP$17,22),E21="Anexo V",VLOOKUP(E19,Anexos!$A$12:$AP$17,37))*E25*$C$27,0) -> 0.037099 | F27: =IFERROR(_xlfn.IFS(F21="Anexo III",VLOOKUP(F19,Anexos!$A$12:$AP$17,22),F21="Anexo V",VLOOKUP(F19,Anexos!$A$12:$AP$17,37))*F25*$C$27,0) -> 0.037099 | G27: =IFERROR(_xlfn.IFS(G21="Anexo III",VLOOKUP(G19,Anexos!$A$12:$AP$17,22),G21="Anexo V",VLOOKUP(G19,Anexos!$A$12:$AP$17,37))*G25*$C$27,0) -> 0.037099 | H27: =IFERROR(_xlfn.IFS(H21="Anexo III",VLOOKUP(H19,Anexos!$A$12:$AP$17,22),H21="Anexo V",VLOOKUP(H19,Anexos!$A$12:$AP$17,37))*H25*$C$27,0) -> 0.037099 | I27: =IFERROR(_xlfn.IFS(I21="Anexo III",VLOOKUP(I19,Anexos!$A$12:$AP$17,22),I21="Anexo V",VLOOKUP(I19,Anexos!$A$12:$AP$17,37))*I25*$C$27,0) -> 0.00292 | J27: =IFERROR(_xlfn.IFS(J21="Anexo III",VLOOKUP(J19,Anexos!$A$12:$AP$17,22),J21="Anexo V",VLOOKUP(J19,Anexos!$A$12:$AP$17,37))*J25*$C$27,0) -> 0.00292 | K27: =IFERROR(_xlfn.IFS(K21="Anexo III",VLOOKUP(K19,Anexos!$A$12:$AP$17,22),K21="Anexo V",VLOOKUP(K19,Anexos!$A$12:$AP$17,37))*K25*$C$27,0) -> 0.00292 | ... O27: =IFERROR(_xlfn.IFS(O21="Anexo III",VLOOKUP(O19,Anexos!$A$12:$AP$17,22),O21="Anexo V",VLOOKUP(O19,Anexos!$A$12:$AP$17,37))*O25*$C$27,0) -> 0.00292
B28: Repartição do CSLL | C28: 1 | D28: =IFERROR(_xlfn.IFS(D21="Anexo III",VLOOKUP(D19,Anexos!$A$12:$AP$17,23),D21="Anexo V",VLOOKUP(D19,Anexos!$A$12:$AP$17,38))*D25*$C$28,0) -> 0.024195 | E28: =IFERROR(_xlfn.IFS(E21="Anexo III",VLOOKUP(E19,Anexos!$A$12:$AP$17,23),E21="Anexo V",VLOOKUP(E19,Anexos!$A$12:$AP$17,38))*E25*$C$28,0) -> 0.024195 | F28: =IFERROR(_xlfn.IFS(F21="Anexo III",VLOOKUP(F19,Anexos!$A$12:$AP$17,23),F21="Anexo V",VLOOKUP(F19,Anexos!$A$12:$AP$17,38))*F25*$C$28,0) -> 0.024195 | G28: =IFERROR(_xlfn.IFS(G21="Anexo III",VLOOKUP(G19,Anexos!$A$12:$AP$17,23),G21="Anexo V",VLOOKUP(G19,Anexos!$A$12:$AP$17,38))*G25*$C$28,0) -> 0.024195 | H28: =IFERROR(_xlfn.IFS(H21="Anexo III",VLOOKUP(H19,Anexos!$A$12:$AP$17,23),H21="Anexo V",VLOOKUP(H19,Anexos!$A$12:$AP$17,38))*H25*$C$28,0) -> 0.024195 | I28: =IFERROR(_xlfn.IFS(I21="Anexo III",VLOOKUP(I19,Anexos!$A$12:$AP$17,23),I21="Anexo V",VLOOKUP(I19,Anexos!$A$12:$AP$17,38))*I25*$C$28,0) -> 0.002555 | J28: =IFERROR(_xlfn.IFS(J21="Anexo III",VLOOKUP(J19,Anexos!$A$12:$AP$17,23),J21="Anexo V",VLOOKUP(J19,Anexos!$A$12:$AP$17,38))*J25*$C$28,0) -> 0.002555 | K28: =IFERROR(_xlfn.IFS(K21="Anexo III",VLOOKUP(K19,Anexos!$A$12:$AP$17,23),K21="Anexo V",VLOOKUP(K19,Anexos!$A$12:$AP$17,38))*K25*$C$28,0) -> 0.002555 | ... O28: =IFERROR(_xlfn.IFS(O21="Anexo III",VLOOKUP(O19,Anexos!$A$12:$AP$17,23),O21="Anexo V",VLOOKUP(O19,Anexos!$A$12:$AP$17,38))*O25*$C$28,0) -> 0.002555
B29: Repartição do COFINS | C29: 1 | D29: =IFERROR(_xlfn.IFS(D21="Anexo III",VLOOKUP(D19,Anexos!$A$12:$AP$17,24),D21="Anexo V",VLOOKUP(D19,Anexos!$A$12:$AP$17,39))*D25*$C$29,0) -> 0.0227433 | E29: =IFERROR(_xlfn.IFS(E21="Anexo III",VLOOKUP(E19,Anexos!$A$12:$AP$17,24),E21="Anexo V",VLOOKUP(E19,Anexos!$A$12:$AP$17,39))*E25*$C$29,0) -> 0.0227433 | F29: =IFERROR(_xlfn.IFS(F21="Anexo III",VLOOKUP(F19,Anexos!$A$12:$AP$17,24),F21="Anexo V",VLOOKUP(F19,Anexos!$A$12:$AP$17,39))*F25*$C$29,0) -> 0.0227433 | G29: =IFERROR(_xlfn.IFS(G21="Anexo III",VLOOKUP(G19,Anexos!$A$12:$AP$17,24),G21="Anexo V",VLOOKUP(G19,Anexos!$A$12:$AP$17,39))*G25*$C$29,0) -> 0.0227433 | H29: =IFERROR(_xlfn.IFS(H21="Anexo III",VLOOKUP(H19,Anexos!$A$12:$AP$17,24),H21="Anexo V",VLOOKUP(H19,Anexos!$A$12:$AP$17,39))*H25*$C$29,0) -> 0.0227433 | I29: =IFERROR(_xlfn.IFS(I21="Anexo III",VLOOKUP(I19,Anexos!$A$12:$AP$17,24),I21="Anexo V",VLOOKUP(I19,Anexos!$A$12:$AP$17,39))*I25*$C$29,0) -> 0.0102565 | J29: =IFERROR(_xlfn.IFS(J21="Anexo III",VLOOKUP(J19,Anexos!$A$12:$AP$17,24),J21="Anexo V",VLOOKUP(J19,Anexos!$A$12:$AP$17,39))*J25*$C$29,0) -> 0.0102565 | K29: =IFERROR(_xlfn.IFS(K21="Anexo III",VLOOKUP(K19,Anexos!$A$12:$AP$17,24),K21="Anexo V",VLOOKUP(K19,Anexos!$A$12:$AP$17,39))*K25*$C$29,0) -> 0.0102565 | ... O29: =IFERROR(_xlfn.IFS(O21="Anexo III",VLOOKUP(O19,Anexos!$A$12:$AP$17,24),O21="Anexo V",VLOOKUP(O19,Anexos!$A$12:$AP$17,39))*O25*$C$29,0) -> 0.0102565
B30: Repartição do PIS/Pasep | C30: 1 | D30: =IFERROR(_xlfn.IFS(D21="Anexo III",VLOOKUP(D19,Anexos!$A$12:$AP$17,25),D21="Anexo V",VLOOKUP(D19,Anexos!$A$12:$AP$17,40))*D25*$C$30,0) -> 0.00491965 | E30: =IFERROR(_xlfn.IFS(E21="Anexo III",VLOOKUP(E19,Anexos!$A$12:$AP$17,25),E21="Anexo V",VLOOKUP(E19,Anexos!$A$12:$AP$17,40))*E25*$C$30,0) -> 0.00491965 | F30: =IFERROR(_xlfn.IFS(F21="Anexo III",VLOOKUP(F19,Anexos!$A$12:$AP$17,25),F21="Anexo V",VLOOKUP(F19,Anexos!$A$12:$AP$17,40))*F25*$C$30,0) -> 0.00491965 | G30: =IFERROR(_xlfn.IFS(G21="Anexo III",VLOOKUP(G19,Anexos!$A$12:$AP$17,25),G21="Anexo V",VLOOKUP(G19,Anexos!$A$12:$AP$17,40))*G25*$C$30,0) -> 0.00491965 | H30: =IFERROR(_xlfn.IFS(H21="Anexo III",VLOOKUP(H19,Anexos!$A$12:$AP$17,25),H21="Anexo V",VLOOKUP(H19,Anexos!$A$12:$AP$17,40))*H25*$C$30,0) -> 0.00491965 | I30: =IFERROR(_xlfn.IFS(I21="Anexo III",VLOOKUP(I19,Anexos!$A$12:$AP$17,25),I21="Anexo V",VLOOKUP(I19,Anexos!$A$12:$AP$17,40))*I25*$C$30,0) -> 0.0022265 | J30: =IFERROR(_xlfn.IFS(J21="Anexo III",VLOOKUP(J19,Anexos!$A$12:$AP$17,25),J21="Anexo V",VLOOKUP(J19,Anexos!$A$12:$AP$17,40))*J25*$C$30,0) -> 0.0022265 | K30: =IFERROR(_xlfn.IFS(K21="Anexo III",VLOOKUP(K19,Anexos!$A$12:$AP$17,25),K21="Anexo V",VLOOKUP(K19,Anexos!$A$12:$AP$17,40))*K25*$C$30,0) -> 0.0022265 | ... O30: =IFERROR(_xlfn.IFS(O21="Anexo III",VLOOKUP(O19,Anexos!$A$12:$AP$17,25),O21="Anexo V",VLOOKUP(O19,Anexos!$A$12:$AP$17,40))*O25*$C$30,0) -> 0.0022265
