Workbook

Sheet Comentários
B2: COMENTÁRIOS
B4: ATENÇÃO: Na aba "GPS_Multas e Juros", Digitar somente nos campos onde estão indicados pela seta vermelha. (São somente 5 campos)
B6: Para o cálculo correto é necessário fazer a Manutenção em duas planilhas
B7: Terá que ser feita somente na aba "Feriados" e na aba "SELIC_2017_2018". Abaixo seguem explicações de como deve ser feito, é bem simples:
B8: Aba Feriados -> Nesta aba já estão inseridos todos os feriados nacionais do ano de 2011 a 2020
B9: Pergunta: Porque tem esta planilha de feriados ?
B10: Resposta: Para fazer a contagem de dias para calcular a multa, o Previdência considera a partir do dia seguinte ao vencimento, se este dia for sábado, domingo ou feriado, ele vai buscar o
B11: próximo dia útil, e para que o cálculo seja exato, foi necessário criar esta planilha de feriados.
B12: Você deve antes de tudo, verificar os feriados estaduais e/ou municipais de sua cidade, porque na tabela só estão os feriados nacionais, vou dar um exemplo:
B13: O dia 20 de novembro é considerado feriado em alguns municipios/estados, se for o seu seu caso, é só ir na aba calendário e incluir este dia, logo abaixo dos feriados de cada ano. Tem
B14: as linhas em branco para digitar, é só informar a data e a descrição do feriado (o dia da semana já trás automático). Obs: Pode incluir na próxima linha em branco, não é necessário deixar na
B15: ordem cronológica.
... B25: OBS: Esta planilha permite fazer cálculos em atraso desde o mês 01/2011 até 12/2020 (se até lá não mudar a forma de cálculo).

Sheet GPS_Multas e Juros
B2: CÁLCULO DE MULTAS E JUROS DA GPS (INSS)
B4: MULTA
B5: Mês e ano Competência da GPS | C5: 42522
B6: Valor da GPS (Campo 6 - Valor do INSS) | C6: 4397.52 | H6: IMPORTANTE
B7: Valor da GPS (Campo 9 - Valor Outras Entidades ) | C7: 879.51 | H7: No campo "Mês e ano Competência da GPS" digitar no formato
B8: Limite 20% (teto) | C8: =(C6+C7)*20% -> 1055.406 | H8: MM/AAAA, ou seja, com barras.
B9: Data do vencimento da GPS | C9: 42571 | H9: Nos campos "Data do vencimento da GPS" e "Data que será paga a guia"
B10: Inicio da contagem dos dias para cálculo da multa | C10: =WORKDAY(C9,1,Feriados!B5:B162) -> 42572 | H10: digitar no formato DD/MM/AAAA, também com barras.
B11: Data que será paga a guia | C11: 42853
B12: Qtde de dias (do vencimento para o pagamento) | C12: =C11-C10+1 -> 282
B13: Valor da multa diária | C13: =(C6+C7)*0.33% -> 17.414199
B14: Valor da multa total (Multa diária x Qtde. de dias) | C14: =C13*C12 -> 4910.8041
B15: Valor da multa | C15: =IF(C8<=C14,C8,IF(C8>C14,C14)) -> 1055.406
B17: JUROS
B18: Mês posterior ao vencimento | C18: =EDATE(C9,1) -> 42602
B19: Mês anterior ao pagamento | C19: =EDATE(C11,-1) -> 42822
B20: Taxa SELIC - Calculado do mês posterior ao vencimento | C20: =IFERROR(VLOOKUP(C5,SELIC_2011_2012!A2:C25,3,FALSE),IFERROR(VLOOKUP(C5,SELIC_2013_2014!A2:C25,3,FALSE),IFERROR(VLOOKUP(C5,SELIC_2015_2016!A2:C25,3,FALSE),IFERROR(VLOOKUP(C5,SELIC_2017_2018!A2:C25,3,FALSE),IFERROR(VLOOKUP(C5,'SELIC_2019 E 2020'!A2:C25,3,FALSE),0))))) -> 0.0855
B21: até o mês anterior ao pagamento
B22: Acréscimo SELIC | C22: =IF(MONTH(C9)=MONTH(C11),0%,IF(YEAR(C9)<YEAR(C11),1%,IF(YEAR(C9)=YEAR(C11),1%))) -> 0.01
B23: Total SELIC | C23: =SUM(C20:C22) -> 0.0955
B24: Valor dos juros | C24: =(C6+C7)*C23 -> 503.95637 | H24: Caso queira gerar um demonstrativo da GPS, é só clicar no botão a esquerda
B26: Total da GPS a pagar | C26: =C6+C7+C15+C24 -> 6836.3924

Sheet Feriados
B2: FERIADOS DE 2011 A 2020
B4: 2020
B5: 43831 | C5: =CHOOSE(WEEKDAY(B5),"domingo","segunda","terça","quarta","quinta","sexta","sábado") -> quarta | D5: Confraternização Universal
B6: 43931 | C6: =CHOOSE(WEEKDAY(B6),"domingo","segunda","terça","quarta","quinta","sexta","sábado") -> sexta | D6: Paixão de Cristo
B7: 43942 | C7: =CHOOSE(WEEKDAY(B7),"domingo","segunda","terça","quarta","quinta","sexta","sábado") -> terça | D7: Tiradentes
B8: 43952 | C8: =CHOOSE(WEEKDAY(B8),"domingo","segunda","terça","quarta","quinta","sexta","sábado") -> sexta | D8: Dia do Trabalho
B9: 43993 | C9: =CHOOSE(WEEKDAY(B9),"domingo","segunda","terça","quarta","quinta","sexta","sábado") -> quinta | D9: Corpus Christi
B10: 44081 | C10: =CHOOSE(WEEKDAY(B10),"domingo","segunda","terça","quarta","quinta","sexta","sábado") -> segunda | D10: Independência do Brasil
B11: 44116 | C11: =CHOOSE(WEEKDAY(B11),"domingo","segunda","terça","quarta","quinta","sexta","sábado") -> segunda | D11: Nossa Senhora Aparecida
B12: 44137 | C12: =CHOOSE(WEEKDAY(B12),"domingo","segunda","terça","quarta","quinta","sexta","sábado") -> segunda | D12: Finados
B13: 44150 | C13: =CHOOSE(WEEKDAY(B13),"domingo","segunda","terça","quarta","quinta","sexta","sábado") -> domingo | D13: Proclamação da República
B14: 44190 | C14: =CHOOSE(WEEKDAY(B14),"domingo","segunda","terça","quarta","quinta","sexta","sábado") -> sexta | D14: Natal
C15: =CHOOSE(WEEKDAY(B15),"domingo","segunda","terça","quarta","quinta","sexta","sábado") -> sábado
C16: =CHOOSE(WEEKDAY(B16),"domingo","segunda","terça","quarta","quinta","sexta","sábado") -> sábado
C17: =CHOOSE(WEEKDAY(B17),"domingo","segunda","terça","quarta","quinta","sexta","sábado") -> sábado
C18: =CHOOSE(WEEKDAY(B18),"domingo","segunda","terça","quarta","quinta","sexta","sábado") -> sábado
B20: 2019
B21: 43466 | C21: =CHOOSE(WEEKDAY(B21),"domingo","segunda","terça","quarta","quinta","sexta","sábado") -> terça | D21: Confraternização Universal
B22: 43574 | C22: =CHOOSE(WEEKDAY(B22),"domingo","segunda","terça","quarta","quinta","sexta","sábado") -> sexta | D22: Paixão de Cristo
B23: 43576 | C23: =CHOOSE(WEEKDAY(B23),"domingo","segunda","terça","quarta","quinta","sexta","sábado") -> domingo | D23: Tiradentes
B24: 43586 | C24: =CHOOSE(WEEKDAY(B24),"domingo","segunda","terça","quarta","quinta","sexta","sábado") -> quarta | D24: Dia do Trabalho
B25: 43636 | C25: =CHOOSE(WEEKDAY(B25),"domingo","segunda","terça","quarta","quinta","sexta","sábado") -> quinta | D25: Corpus Christi
B26: 43715 | C26: =CHOOSE(WEEKDAY(B26),"domingo","segunda","terça","quarta","quinta","sexta","sábado") -> sábado | D26: Independência do Brasil
B27: 43750 | C27: =CHOOSE(WEEKDAY(B27),"domingo","segunda","terça","quarta","quinta","sexta","sábado") -> sábado | D27: Nossa Senhora Aparecida
B28: 43771 | C28: =CHOOSE(WEEKDAY(B28),"domingo","segunda","terça","quarta","quinta","sexta","sábado") -> sábado | D28: Finados
B29: 43784 | C29: =CHOOSE(WEEKDAY(B29),"domingo","segunda","terça","quarta","quinta","sexta","sábado") -> sexta | D29: Proclamação da República
B30: 43824 | C30: =CHOOSE(WEEKDAY(B30),"domingo","segunda","terça","quarta","quinta","sexta","sábado") -> quarta | D30: Natal
C31: =CHOOSE(WEEKDAY(B31),"domingo","segunda","terça","quarta","quinta","sexta","sábado") -> sábado
C32: =CHOOSE(WEEKDAY(B32),"domingo","segunda","terça","quarta","quinta","sexta","sábado") -> sábado
C33: =CHOOSE(WEEKDAY(B33),"domingo","segunda","terça","quarta","quinta","sexta","sábado") -> sábado
C34: =CHOOSE(WEEKDAY(B34),"domingo","segunda","terça","quarta","quinta","sexta","sábado") -> sábado
B36: 2018
B37: 43101 | C37: =CHOOSE(WEEKDAY(B37),"domingo","segunda","terça","quarta","quinta","sexta","sábado") -> segunda | D37: Confraternização Universal
B38: 43189 | C38: =CHOOSE(WEEKDAY(B38),"domingo","segunda","terça","quarta","quinta","sexta","sábado") -> sexta | D38: Paixão de Cristo
B39: 43211 | C39: =CHOOSE(WEEKDAY(B39),"domingo","segunda","terça","quarta","quinta","sexta","sábado") -> sábado | D39: Tiradentes
B40: 43221 | C40: =CHOOSE(WEEKDAY(B40),"domingo","segunda","terça","quarta","quinta","sexta","sábado") -> terça | D40: Dia do Trabalho
B41: 43251 | C41: =CHOOSE(WEEKDAY(B41),"domingo","segunda","terça","quarta","quinta","sexta","sábado") -> quinta | D41: Corpus Christi
B42: 43350 | C42: =CHOOSE(WEEKDAY(B42),"domingo","segunda","terça","quarta","quinta","sexta","sábado") -> sexta | D42: Independência do Brasil
B43: 43385 | C43: =CHOOSE(WEEKDAY(B43),"domingo","segunda","terça","quarta","quinta","sexta","sábado") -> sexta | D43: Nossa Senhora Aparecida
B44: 43406 | C44: =CHOOSE(WEEKDAY(B44),"domingo","segunda","terça","quarta","quinta","sexta","sábado") -> sexta | D44: Finados
...

Sheet SELIC_2017_2018
A1: Mês | B1: SELIC do Mês | C1: Juros
A2: 42736 | B2: 0.0109 | C2: =SUM(B4:$B$25)+SUM('SELIC_2019 E 2020'!$B$2:$B$25) -> 0.0105
A3: 42767 | B3: 0.0087 | C3: =SUM(B5:$B$25)+SUM('SELIC_2019 E 2020'!$B$2:$B$25) -> 0
A4: 42795 | B4: 0.0105 | C4: =SUM(B6:$B$25)+SUM('SELIC_2019 E 2020'!$B$2:$B$25) -> 0
A5: 42826 | B5: 0 | C5: =SUM(B7:$B$25)+SUM('SELIC_2019 E 2020'!$B$2:$B$25) -> 0
A6: 42856 | B6: 0 | C6: =SUM(B8:$B$25)+SUM('SELIC_2019 E 2020'!$B$2:$B$25) -> 0
A7: 42887 | B7: 0 | C7: =SUM(B9:$B$25)+SUM('SELIC_2019 E 2020'!$B$2:$B$25) -> 0
A8: 42917 | B8: 0 | C8: =SUM(B10:$B$25)+SUM('SELIC_2019 E 2020'!$B$2:$B$25) -> 0
A9: 42948 | B9: 0 | C9: =SUM(B11:$B$25)+SUM('SELIC_2019 E 2020'!$B$2:$B$25) -> 0
A10: 42979 | B10: 0 | C10: =SUM(B12:$B$25)+SUM('SELIC_2019 E 2020'!$B$2:$B$25) -> 0
A11: 43009 | B11: 0 | C11: =SUM(B13:$B$25)+SUM('SELIC_2019 E 2020'!$B$2:$B$25) -> 0
A12: 43040 | B12: 0 | C12: =SUM(B14:$B$25)+SUM('SELIC_2019 E 2020'!$B$2:$B$25) -> 0
A13: 43070 | B13: 0 | C13: =SUM(B15:$B$25)+SUM('SELIC_2019 E 2020'!$B$2:$B$25) -> 0
... A23: 43374 | B23: 0 | C23: =SUM(B25:$B$25)+SUM('SELIC_2019 E 2020'!$B$2:$B$25) -> 0
A24: 43405 | B24: 0 | C24: =SUM(B$26:$B26)+SUM('SELIC_2019 E 2020'!$B$2:$B$25) -> 0
A25: 43435 | B25: 0 | C25: =SUM(B$26:$B27)+SUM('SELIC_2019 E 2020'!$B$3:$B$25) -> 0

Sheet SELIC_2019 E 2020
A1: Mês | B1: SELIC do Mês | C1: Juros
A2: 43466 | B2: 0 | C2: =SUM(B4:$B$25) -> 0
A3: 43497 | B3: 0 | C3: =SUM(B5:$B$25) -> 0
A4: 43525 | B4: 0 | C4: =SUM(B6:$B$25) -> 0
A5: 43556 | B5: 0 | C5: =SUM(B7:$B$25) -> 0
A6: 43586 | B6: 0 | C6: =SUM(B8:$B$25) -> 0
A7: 43617 | B7: 0 | C7: =SUM(B9:$B$25) -> 0
A8: 43647 | B8: 0 | C8: =SUM(B10:$B$25) -> 0
A9: 43678 | B9: 0 | C9: =SUM(B11:$B$25) -> 0
A10: 43709 | B10: 0 | C10: =SUM(B12:$B$25) -> 0
A11: 43739 | B11: 0 | C11: =SUM(B13:$B$25) -> 0
A12: 43770 | B12: 0 | C12: =SUM(B14:$B$25) -> 0
A13: 43800 | B13: 0 | C13: =SUM(B15:$B$25) -> 0
... A23: 44105 | B23: 0 | C23: =SUM(B25:$B$25) -> 0
A24: 44136 | B24: 0 | C24: =SUM(B$26:$B26) -> 0
A25: 44166 | B25: 0 | C25: =SUM(B$26:$B27) -> 0

Sheet SELIC_2015_2016
A1: Mês | B1: SELIC do Mês | C1: Juros
A2: 42005 | B2: 0.0094 | C2: =SUM(B4:B25)+SUM(SELIC_2017_2018!$B$2:$B$25)+SUM('SELIC_2019 E 2020'!$B$2:$B$25) -> 0.2699
A3: 42036 | B3: 0.0082 | C3: =SUM(B5:B26)+SUM(SELIC_2017_2018!$B$2:$B$25)+SUM('SELIC_2019 E 2020'!$B$2:$B$25) -> 0.2595
A4: 42064 | B4: 0.0104 | C4: =SUM(B6:B27)+SUM(SELIC_2017_2018!$B$2:$B$25)+SUM('SELIC_2019 E 2020'!$B$2:$B$25) -> 0.25
A5: 42095 | B5: 0.0095 | C5: =SUM(B7:B28)+SUM(SELIC_2017_2018!$B$2:$B$25)+SUM('SELIC_2019 E 2020'!$B$2:$B$25) -> 0.2401
A6: 42125 | B6: 0.0099 | C6: =SUM(B8:B29)+SUM(SELIC_2017_2018!$B$2:$B$25)+SUM('SELIC_2019 E 2020'!$B$2:$B$25) -> 0.2294
A7: 42156 | B7: 0.0107 | C7: =SUM(B9:B30)+SUM(SELIC_2017_2018!$B$2:$B$25)+SUM('SELIC_2019 E 2020'!$B$2:$B$25) -> 0.2176
A8: 42186 | B8: 0.0118 | C8: =SUM(B10:B31)+SUM(SELIC_2017_2018!$B$2:$B$25)+SUM('SELIC_2019 E 2020'!$B$2:$B$25) -> 0.2065
A9: 42217 | B9: 0.0111 | C9: =SUM(B11:B32)+SUM(SELIC_2017_2018!$B$2:$B$25)+SUM('SELIC_2019 E 2020'!$B$2:$B$25) -> 0.1954
A10: 42248 | B10: 0.0111 | C10: =SUM(B12:B33)+SUM(SELIC_2017_2018!$B$2:$B$25)+SUM('SELIC_2019 E 2020'!$B$2:$B$25) -> 0.1843
A11: 42278 | B11: 0.0111 | C11: =SUM(B13:B34)+SUM(SELIC_2017_2018!$B$2:$B$25)+SUM('SELIC_2019 E 2020'!$B$2:$B$25) -> 0.1737
A12: 42309 | B12: 0.0106 | C12: =SUM(B14:B35)+SUM(SELIC_2017_2018!$B$2:$B$25)+SUM('SELIC_2019 E 2020'!$B$2:$B$25) -> 0.1621
A13: 42339 | B13: 0.0116 | C13: =SUM(B15:B36)+SUM(SELIC_2017_2018!$B$2:$B$25)+SUM('SELIC_2019 E 2020'!$B$2:$B$25) -> 0.1515
... A24: 42675 | B24: 0.0104 | C24: =SUM(B26:B47)+SUM(SELIC_2017_2018!$B$2:$B$25)+SUM('SELIC_2019 E 2020'!$B$2:$B$25) -> 0.0301
A25: 42705 | B25: 0.0112 | C25: =SUM(B27:B48)+SUM(SELIC_2017_2018!$B$3:$B$25)+SUM('SELIC_2019 E 2020'!$B$2:$B$25) -> 0.0192

Sheet SELIC_2013_2014
A1: Mês | B1: SELIC do Mês | C1: Juros
A2: 41275 | B2: 0.006 | C2: =SUM(B4:B25)+SUM(SELIC_2015_2016!$B$2:$B$25)+SUM(SELIC_2017_2018!$B$2:$B$25)+SUM('SELIC_2019 E 2020'!$B$2:$B$25) -> 0.4598
A3: 41306 | B3: 0.0049 | C3: =SUM(B5:B26)+SUM(SELIC_2015_2016!$B$2:$B$25)+SUM(SELIC_2017_2018!$B$2:$B$25)+SUM('SELIC_2019 E 2020'!$B$2:$B$25) -> 0.4543
A4: 41334 | B4: 0.0055 | C4: =SUM(B6:B27)+SUM(SELIC_2015_2016!$B$2:$B$25)+SUM(SELIC_2017_2018!$B$2:$B$25)+SUM('SELIC_2019 E 2020'!$B$2:$B$25) -> 0.4482
A5: 41365 | B5: 0.0061 | C5: =SUM(B7:B28)+SUM(SELIC_2015_2016!$B$2:$B$25)+SUM(SELIC_2017_2018!$B$2:$B$25)+SUM('SELIC_2019 E 2020'!$B$2:$B$25) -> 0.4422
A6: 41395 | B6: 0.006 | C6: =SUM(B8:B29)+SUM(SELIC_2015_2016!$B$2:$B$25)+SUM(SELIC_2017_2018!$B$2:$B$25)+SUM('SELIC_2019 E 2020'!$B$2:$B$25) -> 0.4361
A7: 41426 | B7: 0.0061 | C7: =SUM(B9:B30)+SUM(SELIC_2015_2016!$B$2:$B$25)+SUM(SELIC_2017_2018!$B$2:$B$25)+SUM('SELIC_2019 E 2020'!$B$2:$B$25) -> 0.4289
A8: 41456 | B8: 0.0072 | C8: =SUM(B10:B31)+SUM(SELIC_2015_2016!$B$2:$B$25)+SUM(SELIC_2017_2018!$B$2:$B$25)+SUM('SELIC_2019 E 2020'!$B$2:$B$25) -> 0.4218
A9: 41487 | B9: 0.0071 | C9: =SUM(B11:B32)+SUM(SELIC_2015_2016!$B$2:$B$25)+SUM(SELIC_2017_2018!$B$2:$B$25)+SUM('SELIC_2019 E 2020'!$B$2:$B$25) -> 0.4147
A10: 41518 | B10: 0.0071 | C10: =SUM(B12:B33)+SUM(SELIC_2015_2016!$B$2:$B$25)+SUM(SELIC_2017_2018!$B$2:$B$25)+SUM('SELIC_2019 E 2020'!$B$2:$B$25) -> 0.4066
A11: 41548 | B11: 0.0081 | C11: =SUM(B13:B34)+SUM(SELIC_2015_2016!$B$2:$B$25)+SUM(SELIC_2017_2018!$B$2:$B$25)+SUM('SELIC_2019 E 2020'!$B$2:$B$25) -> 0.3994
A12: 41579 | B12: 0.0072 | C12: =SUM(B14:B35)+SUM(SELIC_2015_2016!$B$2:$B$25)+SUM(SELIC_2017_2018!$B$2:$B$25)+SUM('SELIC_2019 E 2020'!$B$2:$B$25) -> 0.3915
A13: 41609 | B13: 0.0079 | C13: =SUM(B15:B36)+SUM(SELIC_2015_2016!$B$2:$B$25)+SUM(SELIC_2017_2018!$B$2:$B$25)+SUM('SELIC_2019 E 2020'!$B$2:$B$25) -> 0.383
... A24: 41944 | B24: 0.0084 | C24: =SUM(B26:B47)+SUM(SELIC_2015_2016!$B$2:$B$25)+SUM(SELIC_2017_2018!$B$2:$B$25)+SUM('SELIC_2019 E 2020'!$B$2:$B$25) -> 0.2875
A25: 41974 | B25: 0.0096 | C25: =SUM(B27:B48)+SUM(SELIC_2015_2016!$B$3:$B$25)+SUM(SELIC_2017_2018!$B$2:$B$25)+SUM('SELIC_2019 E 2020'!$B$2:$B$25) -> 0.2781

Sheet SELIC_2011_2012
A1: Mês | B1: SELIC do Mês | C1: Juros
A2: 40544 | B2: 0.0086 | C2: =SUM(B4:B25)+SUM(SELIC_2013_2014!$B$2:$B$25)+SUM(SELIC_2015_2016!$B$2:$B$25)+SUM(SELIC_2017_2018!$B$2:$B$25)+SUM('SELIC_2019 E 2020'!$B$2:$B$25) -> 0.6458
A3: 40575 | B3: 0.0084 | C3: =SUM(B5:B25)+SUM(SELIC_2013_2014!$B$2:$B$25)+SUM(SELIC_2015_2016!$B$2:$B$25)+SUM(SELIC_2017_2018!$B$2:$B$25)+SUM('SELIC_2019 E 2020'!$B$2:$B$25) -> 0.6366
A4: 40603 | B4: 0.0092 | C4: =SUM(B6:B25)+SUM(SELIC_2013_2014!$B$2:$B$25)+SUM(SELIC_2015_2016!$B$2:$B$25)+SUM(SELIC_2017_2018!$B$2:$B$25)+SUM('SELIC_2019 E 2020'!$B$2:$B$25) -> 0.6282
A5: 40634 | B5: 0.0084 | C5: =SUM(B7:B25)+SUM(SELIC_2013_2014!$B$2:$B$25)+SUM(SELIC_2015_2016!$B$2:$B$25)+SUM(SELIC_2017_2018!$B$2:$B$25)+SUM('SELIC_2019 E 2020'!$B$2:$B$25) -> 0.6183
A6: 40664 | B6: 0.0099 | C6: =SUM(B8:B25)+SUM(SELIC_2013_2014!$B$2:$B$25)+SUM(SELIC_2015_2016!$B$2:$B$25)+SUM(SELIC_2017_2018!$B$2:$B$25)+SUM('SELIC_2019 E 2020'!$B$2:$B$25) -> 0.6087
A7: 40695 | B7: 0.0096 | C7: =SUM(B9:B25)+SUM(SELIC_2013_2014!$B$2:$B$25)+SUM(SELIC_2015_2016!$B$2:$B$25)+SUM(SELIC_2017_2018!$B$2:$B$25)+SUM('SELIC_2019 E 2020'!$B$2:$B$25) -> 0.599
A8: 40725 | B8: 0.0097 | C8: =SUM(B10:B25)+SUM(SELIC_2013_2014!$B$2:$B$25)+SUM(SELIC_2015_2016!$B$2:$B$25)+SUM(SELIC_2017_2018!$B$2:$B$25)+SUM('SELIC_2019 E 2020'!$B$2:$B$25) -> 0.5883
A9: 40756 | B9: 0.0107 | C9: =SUM(B11:B25)+SUM(SELIC_2013_2014!$B$2:$B$25)+SUM(SELIC_2015_2016!$B$2:$B$25)+SUM(SELIC_2017_2018!$B$2:$B$25)+SUM('SELIC_2019 E 2020'!$B$2:$B$25) -> 0.5789
A10: 40787 | B10: 0.0094 | C10: =SUM(B12:B25)+SUM(SELIC_2013_2014!$B$2:$B$25)+SUM(SELIC_2015_2016!$B$2:$B$25)+SUM(SELIC_2017_2018!$B$2:$B$25)+SUM('SELIC_2019 E 2020'!$B$2:$B$25) -> 0.5701
A11: 40817 | B11: 0.0088 | C11: =SUM(B13:B25)+SUM(SELIC_2013_2014!$B$2:$B$25)+SUM(SELIC_2015_2016!$B$2:$B$25)+SUM(SELIC_2017_2018!$B$2:$B$25)+SUM('SELIC_2019 E 2020'!$B$2:$B$25) -> 0.5615
A12: 40848 | B12: 0.0086 | C12: =SUM(B14:B25)+SUM(SELIC_2013_2014!$B$2:$B$25)+SUM(SELIC_2015_2016!$B$2:$B$25)+SUM(SELIC_2017_2018!$B$2:$B$25)+SUM('SELIC_2019 E 2020'!$B$2:$B$25) -> 0.5524
A13: 40878 | B13: 0.0091 | C13: =SUM(B15:B25)+SUM(SELIC_2013_2014!$B$2:$B$25)+SUM(SELIC_2015_2016!$B$2:$B$25)+SUM(SELIC_2017_2018!$B$2:$B$25)+SUM('SELIC_2019 E 2020'!$B$2:$B$25) -> 0.5435
A14: 40909 | B14: 0.0089 | C14: =SUM(B16:B25)+SUM(SELIC_2013_2014!$B$2:$B$25)+SUM(SELIC_2015_2016!$B$2:$B$25)+SUM(SELIC_2017_2018!$B$2:$B$25)+SUM('SELIC_2019 E 2020'!$B$2:$B$25) -> 0.536
A15: 40940 | B15: 0.0075 | C15: =SUM(B17:B25)+SUM(SELIC_2013_2014!$B$2:$B$25)+SUM(SELIC_2015_2016!$B$2:$B$25)+SUM(SELIC_2017_2018!$B$2:$B$25)+SUM('SELIC_2019 E 2020'!$B$2:$B$25) -> 0.5278
A16: 40969 | B16: 0.0082 | C16: =SUM(B18:B25)+SUM(SELIC_2013_2014!$B$2:$B$25)+SUM(SELIC_2015_2016!$B$2:$B$25)+SUM(SELIC_2017_2018!$B$2:$B$25)+SUM('SELIC_2019 E 2020'!$B$2:$B$25) -> 0.5207
A17: 41000 | B17: 0.0071 | C17: =SUM(B19:B25)+SUM(SELIC_2013_2014!$B$2:$B$25)+SUM(SELIC_2015_2016!$B$2:$B$25)+SUM(SELIC_2017_2018!$B$2:$B$25)+SUM('SELIC_2019 E 2020'!$B$2:$B$25) -> 0.5133
A18: 41030 | B18: 0.0074 | C18: =SUM(B20:B25)+SUM(SELIC_2013_2014!$B$2:$B$25)+SUM(SELIC_2015_2016!$B$2:$B$25)+SUM(SELIC_2017_2018!$B$2:$B$25)+SUM('SELIC_2019 E 2020'!$B$2:$B$25) -> 0.5069
A19: 41061 | B19: 0.0064 | C19: =SUM(B21:B25)+SUM(SELIC_2013_2014!$B$2:$B$25)+SUM(SELIC_2015_2016!$B$2:$B$25)+SUM(SELIC_2017_2018!$B$2:$B$25)+SUM('SELIC_2019 E 2020'!$B$2:$B$25) -> 0.5001
A20: 41091 | B20: 0.0068 | C20: =SUM(B22:B25)+SUM(SELIC_2013_2014!$B$2:$B$25)+SUM(SELIC_2015_2016!$B$2:$B$25)+SUM(SELIC_2017_2018!$B$2:$B$25)+SUM('SELIC_2019 E 2020'!$B$2:$B$25) -> 0.4932
A21: 41122 | B21: 0.0069 | C21: =SUM(B23:B25)+SUM(SELIC_2013_2014!$B$2:$B$25)+SUM(SELIC_2015_2016!$B$2:$B$25)+SUM(SELIC_2017_2018!$B$2:$B$25)+SUM('SELIC_2019 E 2020'!$B$2:$B$25) -> 0.4878
A22: 41153 | B22: 0.0054 | C22: =SUM(B24:B25)+SUM(SELIC_2013_2014!$B$2:$B$25)+SUM(SELIC_2015_2016!$B$2:$B$25)+SUM(SELIC_2017_2018!$B$2:$B$25)+SUM('SELIC_2019 E 2020'!$B$2:$B$25) -> 0.4817
A23: 41183 | B23: 0.0061 | C23: =SUM(B25:B25)+SUM(SELIC_2013_2014!$B$2:$B$25)+SUM(SELIC_2015_2016!$B$2:$B$25)+SUM(SELIC_2017_2018!$B$2:$B$25)+SUM('SELIC_2019 E 2020'!$B$2:$B$25) -> 0.4762
A24: 41214 | B24: 0.0055 | C24: =SUM(B26:B26)+SUM(SELIC_2013_2014!$B$2:$B$25)+SUM(SELIC_2015_2016!$B$2:$B$25)+SUM(SELIC_2017_2018!$B$2:$B$25)+SUM('SELIC_2019 E 2020'!$B$2:$B$25) -> 0.4707
A25: 41244 | B25: 0.0055 | C25: =SUM(B26:B27)+SUM(SELIC_2013_2014!$B$3:$B$25)+SUM(SELIC_2015_2016!$B$2:$B$25)+SUM(SELIC_2017_2018!$B$2:$B$25)+SUM('SELIC_2019 E 2020'!$B$2:$B$25) -> 0.4647

Sheet GPS_Demontrativo
D2: 3 - CÓDIGO DE PAGAMENTO | E2: 2100
B3: MINISTÉRIO DA PREVIDÊNCIA SOCIAL - MPS
B4: INSTITUTO NACIONAL DO SEGURO SOCIAL - INSS
B5: SECRETARIA DA RECEITA PREVIDENCIÁRIA - SRP
B6: GUIA DA PREVIDÊNCIA SOCIAL - GPS | D6: 4 - COMPETÊNCIA | E6: ='GPS_Multas e Juros'!C5 -> 42522
D7: 5 - IDENTIFICADOR
B8: 1 - NOME OU RAZÃO SOCIAL / FONE / ENDEREÇO | D8: 6 - VALOR DO INSS | E8: ='GPS_Multas e Juros'!C6 -> 4397.52
D13: 7 -
D14: 8 -
B15: 2 - VENCIMENTO | C15: ='GPS_Multas e Juros'!C11 -> 42853 | D15: 9 - VALOR OUTRAS ENTIDADES | E15: ='GPS_Multas e Juros'!C7 -> 879.51
B16: (Uso exclusivo INSS)
B17: ATENÇÃO:É vedada a utilização de GPS para recolhimento de receita de valor inferior ao estipulado em resolução publicada pelo INSS. A receita que resultar valor inferior deverá ser adicionada à contribuição ou importância correspondente nos meses subsequentes, até que o total seja igual ou superior ao valor mínimo fixado. | D17: 10 - ATM/MULTA E JUROS | E17: ='GPS_Multas e Juros'!C15+'GPS_Multas e Juros'!C24 -> 1559.3624
D18: 11 - TOTAL | E18: =E8+E15+E17 -> 6836.3924
B19: AUTENTICAÇÃO BANCÁRIA
