Workbook

Sheet SIMULADOR
B1: Simulador de Cálculo do Ponto de Equilibrio
M3: NOTA: AS INFORMAÇÕES ACIMA, SEU USO E INTERPRETAÇÃO SÃO DE EXCLUSIVA E ÚNICA RESPONSABILIDADE DE SEUS INFORMANTES, NÃO SE RESPONSABILIZANDO O AUTOR, PELO USO INADEQUADO, OU INFORMAÇÕES INDEVIDAS QUE POSSAM VIR A GERAR INTERPRETAÇÕES E DECISÕES GERENCIAIS/EMPRESARIAIS SEM O DEVIDO ACOMPANHAMENTO DE PROFISSIONAL DA ÁREA.
B4: DEMONSTRAÇÃO DE RESULTADOS | C4: % Composição LUCRO BRUTO | F4: Valores | G4: % | I4: LEGENDA:
B5: RECEITA BRUTA | C5: 1 | F5: 93025 | G5: =F5/$F$5 -> 100%
B6: IMPOSTOS | C6: =RECEITA!Q8 -> 0.76% | D6: Gastos Variáveis | F6: =+$F$5*C6 -> R$ 707.40 | G6: =F6/$F$5 -> 1% | I6: Bases para simular DRE
B7: CUSTO MERCAD/PRODUTOS | C7: =RECEITA!Q9 -> 46.21% | F7: =+$F$5*C7 -> R$ 42,983.80 | G7: =F7/$F$5 -> 46%
B8: OUTROS VÁRIAVEIS | C8: =RECEITA!Q36 -> 0.00% | F8: =+$F$5*C8 -> R$ - | G8: =F8/$F$5 -> 0% | I8: Bases para Calcular PE
B9: LUCRO BRUTO / MARGEM DE CONTRIBUIÇÃO | C9: =C5-SUM(C6:C8) -> 53.03% | F9: =F5-SUM(F6:F8) -> R$ 49,333.80 | G9: =F9/$F$5 -> 53%
B10: DESP. ESTRUTURAIS | D10: Gastos Fixos | F10: =ESTRUTURA!C33 -> R$ 4,440.00 | G10: =F10/$F$5 -> 5% | I10: =I35 -> R$ 48,565.29 | J10: é seu PONTO
B11: DESP. PESSOAL | F11: =ESTRUTURA!F33 -> R$ 11,308.45 | G11: =F11/$F$5 -> 12% | I11: DE EQUILIBRIO, para a estrutura de despesas FIXAS e parcentuais informados.
B12: DESP. ADMIN. E GERAIS | F12: =ESTRUTURA!I33 -> R$ 10,007.11 | G12: =F12/$F$5 -> 11%
B13: LUCRO LIQUIDO | F13: =F9-F10-F11-F12 -> R$ 23,578.25 | G13: =F13/$F$5 -> 25.35%
B17: COMPOSIÇÃO | C17: ITENS | D17: % | F17: ITENS | G17: Inicio Linha Grafico | H17: Fim Linha Gráfico
B18: =F5 -> 93,025.00 | C18: VENDAS | D18: =SUM(D19:D20) -> 100% | F18: VENDAS | G18: 0 | H18: =B18 -> 93,025.00
B19: =SUM(F6:F8) -> 43,691.20 | C19: CUSTO VARIAVEL | D19: =B19/$B$18 -> 47.0% | F19: CUSTO VARIAVEL | G19: =B21 -> 25,755.56 | H19: =B21+B19 -> 69,446.76
B20: =+B18-B19 -> 49,333.80 | C20: LUCRO VARIAVEL | D20: =B20/$B$18 -> 53.0% | F20: CUSTO FIXO | G20: =B21 -> 25,755.56 | H20: =G20 -> 25,755.56
B21: =SUM(F10:F12) -> 25,755.56 | C21: CUSTO FIXO | D21: =B21/$B$18 -> 27.7% | F21: PTO DE EQUIL. | G21: =I35 -> 48,565.29 | H21: =G21 -> 48,565.29
B22: =+B20-B21 -> 23,578.25 | C22: LUCRO OPERACIONAL | D22: =B22/$B$18 -> 25.3%
C35: PONTO DE EQUILIBRIO = | D35: CUSTO FIXO | H35: =B21 -> R$ 25,755.56 | I35: =H35/H36 -> R$ 48,565.29
D36: MARGEM DE CONTRIBUIÇÃO | H36: =B20/B18 -> 53%
B38: LUCRATIVIDADE DESEJADA | D38: 0.1
B39: PONTO DE EQUILIBRIO ECONOMICO = | D39: =H35/(H36-D38) -> R$ 59,850.93

Sheet RECEITA
C2: Simulador de Cálculo do Ponto de Equilibrio
B5: COMPOSIÇÃO DA RECEITA BRUTA (LINHAS ou PRODUTOS) | D5: Quant. | E5: Valor venda Unitario | F5: Custo Unitario | G5: margem | H5: ESTIMATIVA DE RECEITA DA REFERIDA LINHA ou PRODUTO | J5: ESTIMATIVA DE CUSTO DA REFERIDA LINHA ou PRODUTO (sempre correspondente a RECEITA ESTIMADA) | K5: IMPOSTOS FEDERAIS INCIDENTES SOBRE A RECEITA BRUTA (%TOTAL) | L5: MARGEM TOTAL | M5: IMPOSTOS MUNICIPAIS, INCIDENTE SOBRE OS SERVIÇOS (%TOTAL) | N5: TOTAL IMPOSTOS EM R$ | P5: DEMONSTRAÇÃO DE RESULTADOS | Q5: % Composição LUCRO BRUTO
I6: Pe Quantidade
C7: BLUSA LOSANGO | D7: 50 | E7: 22.5 | F7: 10.82 | G7: =E7-F7 -> R$ 11.68 | H7: =E7*D7 -> R$ 1,125.00 | J7: =F7*D7 -> R$ 541.00 | K7: 0.05 | L7: =G7*D7 -> R$ 584.00 | M7: - | P7: RECEITA BRUTA | Q7: 1
C8: CASACO PELE | D8: 900 | E8: 17 | F8: 12.92 | G8: =E8-F8 -> R$ 4.08 | H8: =E8*D8 -> R$ 15,300.00 | J8: =F8*D8 -> R$ 11,628.00 | K8: 0.05 | L8: =G8*D8 -> R$ 3,672.00 | M8: - | P8: IMPOSTOS | Q8: =N36/H36 -> 0.76%
G9: =E9-F9 -> R$ - | H9: =E9*D9 -> R$ - | J9: =F9*D9 -> R$ - | K9: 0.05 | L9: =G9*D9 -> R$ - | M9: - | P9: CUSTO MERCAD/PRODUTOS | Q9: =J36/H36 -> 46.21%
G10: =E10-F10 -> R$ - | H10: =E10*D10 -> R$ - | J10: =F10*D10 -> R$ - | K10: 0.05 | L10: =G10*D10 -> R$ - | M10: - | P10: OUTROS VÁRIAVEIS | Q10: 0
G11: =E11-F11 -> R$ - | H11: =E11*D11 -> R$ - | J11: =F11*D11 -> R$ - | K11: 0.05 | L11: =G11*D11 -> R$ - | M11: 0 | P11: LUCRO BRUTO | Q11: =Q7-SUM(Q8:Q10) -> 53.03%
C12: BLUSA LOSANGO | D12: 900 | E12: 26 | F12: 10.82 | G12: =E12-F12 -> R$ 15.18 | H12: =E12*D12 -> R$ 23,400.00 | J12: =F12*D12 -> R$ 9,738.00 | K12: 0.05 | L12: =G12*D12 -> R$ 13,662.00
C13: VESTIDO | D13: 200 | E13: 38 | F13: 14.69 | G13: =E13-F13 -> R$ 23.31 | H13: =E13*D13 -> R$ 7,600.00 | J13: =F13*D13 -> R$ 2,938.00 | K13: 0.05 | L13: =G13*D13 -> R$ 4,662.00
C14: BLUSA RENDADA | D14: 200 | E14: 21.8 | F14: 7.5 | G14: =E14-F14 -> R$ 14.30 | H14: =E14*D14 -> R$ 4,360.00 | J14: =F14*D14 -> R$ 1,500.00 | K14: 0.05 | L14: =G14*D14 -> R$ 2,860.00
C15: BLUSA V | D15: 200 | E15: 22 | F15: 9.5 | G15: =E15-F15 -> R$ 12.50 | H15: =E15*D15 -> R$ 4,400.00 | J15: =F15*D15 -> R$ 1,900.00 | K15: 0.05 | L15: =G15*D15 -> R$ 2,500.00
C16: BLUSA LOSANGO | D16: 200 | E16: 24 | F16: 10.82 | G16: =E16-F16 -> R$ 13.18 | H16: =E16*D16 -> R$ 4,800.00 | J16: =F16*D16 -> R$ 2,164.00 | K16: 0.05 | L16: =G16*D16 -> R$ 2,636.00
C17: CASACO TRANÇA | D17: 1000 | E17: 25.6 | F17: 9.73 | G17: =E17-F17 -> R$ 15.87 | H17: =E17*D17 -> R$ 25,600.00 | J17: =F17*D17 -> R$ 9,730.00 | K17: 0.05 | L17: =G17*D17 -> R$ 15,870.00 | P17: OUTROS VARIÁVEIS | Q17: %
C18: BLUSA LOSANGO | D18: 140 | E18: 24 | F18: 10.82 | G18: =E18-F18 -> R$ 13.18 | H18: =E18*D18 -> R$ 3,360.00 | J18: =F18*D18 -> R$ 1,514.80 | K18: 0.05 | L18: =G18*D18 -> R$ 1,845.20 | P18: Comissão | Q18: 0
C19: BLUSA V | D19: 140 | E19: 22 | F19: 9.5 | G19: =E19-F19 -> R$ 12.50 | H19: =E19*D19 -> R$ 3,080.00 | J19: =F19*D19 -> R$ 1,330.00 | K19: 0.05 | L19: =G19*D19 -> R$ 1,750.00 | P19: INSPEÇÃO | Q19: 0
G20: =E20-F20 -> R$ - | H20: =E20*D20 -> R$ - | J20: =F20*D20 -> R$ - | K20: 0.05 | L20: =G20*D20 -> R$ - | N20: =H20*SUM(K20) -> R$ -
G21: =E21-F21 -> R$ - | H21: =E21*D21 -> R$ - | J21: =F21*D21 -> R$ - | K21: 0.05 | L21: =G21*D21 -> R$ - | N21: =H21*SUM(K21) -> R$ -
G22: =E22-F22 -> R$ - | H22: =E22*D22 -> R$ - | J22: =F22*D22 -> R$ - | K22: 0.05 | L22: =G22*D22 -> R$ - | N22: =H22*SUM(K22) -> R$ -
G23: =E23-F23 -> R$ - | H23: =E23*D23 -> R$ - | J23: =F23*D23 -> R$ - | K23: 0.05 | L23: =G23*D23 -> R$ - | N23: =H23*SUM(K23) -> R$ -
G24: =E24-F24 -> R$ - | H24: =E24*D24 -> R$ - | J24: =F24*D24 -> R$ - | K24: 0.05 | L24: =G24*D24 -> R$ - | N24: =H24*SUM(K24) -> R$ -
G25: =E25-F25 -> R$ - | H25: =E25*D25 -> R$ - | J25: =F25*D25 -> R$ - | K25: 0.05 | L25: =G25*D25 -> R$ - | N25: =H25*SUM(K25) -> R$ -
G26: =E26-F26 -> R$ - | H26: =E26*D26 -> R$ - | J26: =F26*D26 -> R$ - | K26: 0.05 | L26: =G26*D26 -> R$ - | N26: =H26*SUM(K26) -> R$ -
G27: =E27-F27 -> R$ - | H27: =E27*D27 -> R$ - | J27: =F27*D27 -> R$ - | K27: 0.05 | L27: =G27*D27 -> R$ - | N27: =H27*SUM(K27) -> R$ -
G28: =E28-F28 -> R$ - | H28: =E28*D28 -> R$ - | J28: =F28*D28 -> R$ - | K28: 0.05 | L28: =G28*D28 -> R$ - | N28: =H28*SUM(K28) -> R$ -
G29: =E29-F29 -> R$ - | H29: =E29*D29 -> R$ - | J29: =F29*D29 -> R$ - | K29: 0.05 | L29: =G29*D29 -> R$ - | N29: =H29*SUM(K29) -> R$ -
G30: =E30-F30 -> R$ - | H30: =E30*D30 -> R$ - | J30: =F30*D30 -> R$ - | K30: 0.05 | L30: =G30*D30 -> R$ - | N30: =H30*SUM(K30) -> R$ -
G31: =E31-F31 -> R$ - | H31: =E31*D31 -> R$ - | J31: =F31*D31 -> R$ - | K31: 0.05 | L31: =G31*D31 -> R$ - | N31: =H31*SUM(K31) -> R$ -
... G34: =E34-F34 -> R$ - | H34: =E34*D34 -> R$ - | J34: =F34*D34 -> R$ - | K34: 0.05 | L34: =G34*D34 -> R$ - | N34: =H34*SUM(K34) -> R$ -
N35: =H35*SUM(K35:M35) -> R$ -
D36: =SUM(D7:D35) -> 3930 | H36: =SUM(H7:H35) -> R$ 93,025.00 | I36: 0 | J36: =SUM(J7:J35) -> R$ 42,983.80 | K36: 0.05 | L36: =SUM(L7:L35) -> R$ 50,041.20 | M36: =SUM(M7:M35) -> 0.00% | N36: 707.4 | Q36: =SUM(Q18:Q35) -> 0.00%
C38: NOTA: Verifique com seu contador o % de IMPOSTOS que cada ITEM QUE COMPÕE sua RECEITA BRUTA POSSUI...
C39: NOTA: Se informar a RECEITA de UMA UNIDADE... Os CUSTOS DEVERÃO ser DE UMA UNIDADE... ( SEMPRE A ESTIMATIVA DE RECEITA, DEVERÁ TER
C40: SEU CUSTO CORRESPONDENDE - SEM CRÉDITO DE IMPOSTOS !!! )

Sheet terceiro
A1: COMPOSIÇÃO DA RECEITA BRUTA (LINHAS ou PRODUTOS) | C1: Quant. | D1: Valor venda Unitario | E1: Custo Unitario | F1: MAGEM UNITÁRIA BRUTO | G1: RECEITA DE VENDA | H1: CUSTO MERCADORIA | I1: MARGEM TOTAL | J1: TOTAL KG | L1: IMPOSTOS FEDERAIS INCIDENTES SOBRE A RECEITA BRUTA (%TOTAL)
B3: Blusa listrada | C3: 140 | D3: 25 | E3: 19 | F3: =D3-E3 -> R$ 6.00 | G3: =D3*C3 -> R$ 3,500.00 | H3: =E3*C3 -> R$ 2,660.00 | I3: =F3*C3 -> R$ 840.00 | J3: =C3*0.25 -> 35 | K3: =(J3*7)*0.14 -> R$ 34.30
B4: Blusa Bico | C4: 140 | D4: 22 | E4: 15 | F4: =D4-E4 -> R$ 7.00 | G4: =D4*C4 -> R$ 3,080.00 | H4: =E4*C4 -> R$ 2,100.00 | I4: =F4*C4 -> R$ 980.00 | J4: =C4*0.25 -> 35 | K4: =(J4*7)*0.14 -> R$ 34.30
B5: Casaco Coração | C5: 800 | D5: 21 | E5: 15 | F5: =D5-E5 -> R$ 6.00 | G5: =D5*C5 -> R$ 16,800.00 | H5: =E5*C5 -> R$ 12,000.00 | I5: =F5*C5 -> R$ 4,800.00 | J5: =C5*0.25 -> 200 | K5: =(J5*7)*0.14 -> R$ 196.00
B6: Casaco Coração | C6: 500 | D6: 21 | E6: 15 | F6: =D6-E6 -> R$ 6.00 | G6: =D6*C6 -> R$ 10,500.00 | H6: =E6*C6 -> R$ 7,500.00 | I6: =F6*C6 -> R$ 3,000.00 | J6: =C6*0.25 -> 125 | K6: =(J6*7)*0.14 -> R$ 122.50
B7: Casaco Colins | C7: 1000 | D7: 20 | E7: 15.5 | F7: =D7-E7 -> R$ 4.50 | G7: =D7*C7 -> R$ 20,000.00 | H7: =E7*C7 -> R$ 15,500.00 | I7: =F7*C7 -> R$ 4,500.00 | J7: =C7*0.25 -> 250 | K7: =(J7*7)*0.14 -> R$ 245.00
B8: blusa bico | C8: 200 | D8: 21 | E8: 15 | F8: =D8-E8 -> R$ 6.00 | G8: =D8*C8 -> R$ 4,200.00 | H8: =E8*C8 -> R$ 3,000.00 | I8: =F8*C8 -> R$ 1,200.00 | J8: =C8*0.25 -> 50 | K8: =(J8*7)*0.14 -> R$ 49.00
B9: Casaco Coração | C9: 400 | D9: 21 | E9: 15 | F9: =D9-E9 -> R$ 6.00 | G9: =D9*C9 -> R$ 8,400.00 | H9: =E9*C9 -> R$ 6,000.00 | I9: =F9*C9 -> R$ 2,400.00 | J9: =C9*0.25 -> 100 | K9: =(J9*7)*0.14 -> R$ 98.00
B10: Casaco Colins | C10: 300 | D10: 20 | E10: 15.5 | F10: =D10-E10 -> R$ 4.50 | G10: =D10*C10 -> R$ 6,000.00 | H10: =E10*C10 -> R$ 4,650.00 | I10: =F10*C10 -> R$ 1,350.00 | J10: =C10*0.25 -> 75 | K10: =(J10*7)*0.14 -> R$ 73.50
B11: Blusa Ilhos | C11: 200 | D11: 26 | E11: 20 | F11: =D11-E11 -> R$ 6.00 | G11: =D11*C11 -> R$ 5,200.00 | H11: =E11*C11 -> R$ 4,000.00 | I11: =F11*C11 -> R$ 1,200.00 | J11: =C11*0.25 -> 50 | K11: =(J11*7)*0.14 -> R$ 49.00
B12: Blusa Bico | C12: 200 | D12: 21 | E12: 15 | F12: =D12-E12 -> R$ 6.00 | G12: =D12*C12 -> R$ 4,200.00 | H12: =E12*C12 -> R$ 3,000.00 | I12: =F12*C12 -> R$ 1,200.00 | J12: =C12*0.25 -> 50 | K12: =(J12*7)*0.14 -> R$ 49.00
B13: Casaco Coração | C13: 400 | D13: 21 | E13: 15.5 | F13: =D13-E13 -> R$ 5.50 | G13: =D13*C13 -> R$ 8,400.00 | H13: =E13*C13 -> R$ 6,200.00 | I13: =F13*C13 -> R$ 2,200.00 | J13: =C13*0.25 -> 100 | K13: =(J13*7)*0.14 -> R$ 98.00
B14: Casaco Colins | C14: 400 | D14: 20 | E14: 15.5 | F14: =D14-E14 -> R$ 4.50 | G14: =D14*C14 -> R$ 8,000.00 | H14: =E14*C14 -> R$ 6,200.00 | I14: =F14*C14 -> R$ 1,800.00 | J14: =C14*0.25 -> 100 | K14: =(J14*7)*0.14 -> R$ 98.00
... B28: Casaco Colins | C28: 400 | D28: 20 | E28: 15.5 | F28: =D28-E28 -> R$ 4.50 | G28: =D28*C28 -> R$ 8,000.00 | H28: =E28*C28 -> R$ 6,200.00 | I28: =F28*C28 -> R$ 1,800.00 | J28: =C28*0.25 -> 100 | K28: =(J28*7)*0.14 -> R$ 98.00
B29: VESTIDO VALIZE | C29: 40 | D29: 39.5 | G29: =D29*C29 -> R$ 1,580.00 | J29: =C29*0.25 -> 10 | K29: =(J29*7)*0.14 -> R$ 9.80
B30: MAX CROPED | C30: 20 | D30: 25 | E30: 19 | G30: =D30*C30 -> R$ 500.00 | J30: =C30*0.25 -> 5 | K30: =(J30*7)*0.14 -> R$ 4.90
B31: Blusa listrada | C31: 20 | D31: 33 | G31: =D31*C31 -> R$ 660.00 | J31: =C31*0.25 -> 5 | K31: =(J31*7)*0.14 -> R$ 4.90
B32: Blusa Ilhos | C32: 70 | D32: 24 | E32: 20 | G32: =D32*C32 -> R$ 1,680.00 | J32: =C32*0.25 -> 17.5 | K32: =(J32*7)*0.14 -> R$ 17.15
B33: Casaco Coração | C33: 300 | E33: 15 | J33: =C33*0.25 -> 75 | K33: =(J33*7)*0.14 -> R$ 73.50
B34: BLUSA PERS. | C34: 1000 | E34: 15.5 | J34: =C34*0.25 -> 250 | K34: =(J34*7)*0.14 -> R$ 245.00
B35: Casaco Rodolfo | C35: 1200 | E35: 16 | J35: =C35*0.25 -> 300 | K35: =(J35*7)*0.14 -> R$ 294.00
B36: Casaco Rodolfo | C36: 900 | E36: 16 | J36: =C36*0.25 -> 225 | K36: =(J36*7)*0.14 -> R$ 220.50
B37: Casaco Rodolfo | C37: 600 | E37: 16 | J37: =C37*0.25 -> 150 | K37: =(J37*7)*0.14 -> R$ 147.00
B38: Casaco Rodolfo | C38: 1200 | E38: 16 | J38: =C38*0.25 -> 300 | K38: =(J38*7)*0.14 -> R$ 294.00
B39: Casaco Masculino | C39: 500 | E39: 24 | J39: =C39*0.25 -> 125 | K39: =(J39*7)*0.14 -> R$ 122.50
B40: Casaco isabela | C40: 500 | E40: 19 | J40: =C40*0.25 -> 125 | K40: =(J40*7)*0.14 -> R$ 122.50
B41: Blusa Bico | C41: 500 | E41: 15 | J41: =C41*0.25 -> 125 | K41: =(J41*7)*0.14 -> R$ 122.50
B42: Casaco Masculino | C42: 500 | E42: 24 | J42: =C42*0.25 -> 125 | K42: =(J42*7)*0.14 -> R$ 122.50
B43: Casaco isabela | C43: 500 | E43: 19 | F43: =D43-E43 -> -R$ 19.00 | G43: =D43*C43 -> R$ - | H43: =E43*C43 -> R$ 9,500.00 | I43: =F43*C43 -> -R$ 9,500.00 | J43: =G43*SUM(L43) -> R$ -
B44: Blusa Bico | C44: 500 | E44: 15 | F44: =D44-E44 -> -R$ 15.00 | G44: =D44*C44 -> R$ - | H44: =E44*C44 -> R$ 7,500.00 | I44: =F44*C44 -> -R$ 7,500.00 | J44: =G44*SUM(L44) -> R$ -
B45: blusa bico | C45: 200 | E45: 15 | F45: =D45-E45 -> -R$ 15.00 | H45: =E45*C45 -> R$ 3,000.00 | I45: =F45*C45 -> -R$ 3,000.00
B46: Blusa Ilhos | C46: 300 | E46: 20 | F46: =D46-E46 -> -R$ 20.00 | H46: =E46*C46 -> R$ 6,000.00 | I46: =F46*C46 -> -R$ 6,000.00
B47: blusa ciganinha | C47: 100 | E47: 15
B48: Casaco Colins | C48: 400 | E48: 15.5
B49: Blusa Bico | C49: 200 | E49: 15
B50: Blusa Ilhos | C50: 200 | E50: 20
B51: blusa ciganinha | C51: 100 | E51: 15
B52: Casaco Colins | C52: 400 | E52: 15.5
B53: blusa bico | C53: 200 | E53: 15
B54: Blusa Ilhos | C54: 300 | E54: 20
...

Sheet ESTRUTURA
B2: Simulador de Cálculo do Ponto de Equilibrio
B4: ESTRUTURA
B6: DESPESAS ESTRUTURAIS (FIXAS) | C6: VALORES | E6: DESPESAS PESSOAL (FIXAS) | F6: VALORES | H6: DESPESAS ADMINISTRATIVAS E GERAIS (FIXAS) | I6: VALORES
B7: CEMIG | C7: 2800
B8: COPASA | C8: 76 | E8: Folha | F8: 9548.45 | H8: COMBUSTIVEL | I8: 300
B9: SEGURO | C9: 384 | H9: FRETE
B10: IPVA | C10: 420 | E10: Café | F10: 280 | H10: CONTADOR | I10: 600
B11: DUCATO | H11: Material Escritório | I11: 200
B12: SEGURO | C12: 460 | H12: Telefone | I12: 250
B13: IPVA | C13: 300 | H13: Progamador | I13: 1140
E14: Andre plantao | F14: 500 | H14: RA | I14: 297.6
H15: Motoboy | I15: 230
E16: comissoes | F16: 930 | H16: Manutenção | I16: 127.64
H17: internet | I17: 60
H18: EXTINTOR
H19: FOTOS SITE | I19: 500
E20: Exames | F20: 50 | H20: LAUDOS | I20: 750
H21: BB TRANSPORTES + comb. | I21: 110
H22: Celular | I22: 650
H23: FERNANDA COSTURA | I23: 2995.4
H24: Transportadoras | I24: =L24/2 -> R$ 1,230.57 | L24: 2461.13
H25: SIMONE COSTURA | I25: 527.9
H26: CORREIO | I26: 38
C33: =SUM(C7:C32) -> R$ 4,440.00 | F33: =SUM(F7:F32) -> R$ 11,308.45 | I33: =SUM(I7:I32) -> R$ 10,007.11
B35: NOTA: Verifique com seu contador o % de IMPOSTOS que cada ITEM QUE COMPÕE sua RECEITA BRUTA POSSUI...
B36: NOTA: Se informar a RECEITA de UMA UNIDADE... Os CUSTOS DEVERÃO serem DE UMA UNIDADE... ( SEMPRE A ESTIMATIVA DE RECEITA, DEVERÁ TER
B37: SEU CUSTO CORRESPONDENDE - SEM CRÉDITO DE IMPOSTOS !!! )
