Workbook
Name FERIADO: FERIADO!$A$2:$A$937

Sheet __FDSCACHE__
B1: This sheet contains Factset binary data for use with this workbook's =FDS codes. Modifying the worksheet's contents may damage the workbook's =FDS functionality.

Sheet Resumo Cenarios
B2: RESUMO RESULTADOS DA MODELAGEM | I2: VICTOR LOPES SCHMUTZLER
C3: (R$ milhões) | I3: +55 (11) 3553-2529
B6: CENÁRIO BASE | D6: 2010 | E6: 2011 | F6: =E6+1 -> 2012 | G6: =F6+1 -> 2013 | H6: =G6+1 -> 2014 | I6: =H6+1 -> 2015 | J6: =I6+1 -> 2016 | K6: =J6+1 -> 2017 | L6: =K6+1 -> 2018 | M6: =L6+1 -> 2019 | ... P6: =O6+1 -> 2022
B8: AG Concessões
B9: Dividendos Recebidos pela AGC (proporcionais a participação)
C10: CEMIG (via AGC Energias) | E10: 93.3 | F10: =PROJ_AGCeAGPar!K59 -> 116.52927 | G10: =PROJ_AGCeAGPar!L59 -> 121.76695 | H10: =PROJ_AGCeAGPar!M59 -> 114.43103 | I10: =PROJ_AGCeAGPar!N59 -> 113.78005 | J10: =PROJ_AGCeAGPar!O59 -> 122.95298 | K10: =PROJ_AGCeAGPar!P59 -> 134.02746 | L10: =PROJ_AGCeAGPar!Q59 -> 150.72766 | M10: =PROJ_AGCeAGPar!R59 -> 143.90413 | ... P10: =PROJ_AGCeAGPar!U59 -> 177.80988
C11: % Payout (Lucro Líq. Ajustado) | E11: =PROJ_AGCeAGPar!J56 -> 0.53583437 | F11: =PROJ_AGCeAGPar!K56 -> 0.5 | G11: =PROJ_AGCeAGPar!L56 -> 0.5 | H11: =PROJ_AGCeAGPar!M56 -> 0.5 | I11: =PROJ_AGCeAGPar!N56 -> 0.5 | J11: =PROJ_AGCeAGPar!O56 -> 0.5 | K11: =PROJ_AGCeAGPar!P56 -> 0.5 | L11: =PROJ_AGCeAGPar!Q56 -> 0.5 | ... P11: =PROJ_AGCeAGPar!U56 -> 0.5
C12: CCR | D12: 141.5 | E12: =PROJ_AGCeAGPar!J78 -> 147.7 | F12: =PROJ_AGCeAGPar!K78 -> 108.38642 | G12: =PROJ_AGCeAGPar!L78 -> 212.08366 | H12: =PROJ_AGCeAGPar!M78 -> 266.29701 | I12: =PROJ_AGCeAGPar!N78 -> 330.23453 | J12: =PROJ_AGCeAGPar!O78 -> 392.09472 | K12: =PROJ_AGCeAGPar!P78 -> 452.03243 | L12: =PROJ_AGCeAGPar!Q78 -> 509.33965 | ... P12: =PROJ_AGCeAGPar!U78 -> 783.4107
C13: % Payout (Lucro Líq. Ajustado) | D13: =PROJ_AGCeAGPar!I75 -> 1.2665914 | E13: =PROJ_AGCeAGPar!J75 -> 0.88609375 | F13: =PROJ_AGCeAGPar!K75 -> 0.85 | G13: =PROJ_AGCeAGPar!L75 -> 0.85 | H13: =PROJ_AGCeAGPar!M75 -> 0.85 | I13: =PROJ_AGCeAGPar!N75 -> 0.85 | J13: =PROJ_AGCeAGPar!O75 -> 0.85 | K13: =PROJ_AGCeAGPar!P75 -> 0.85 | ... P13: =PROJ_AGCeAGPar!U75 -> 0.85
C14: SANEPAR | D14: 2.6 | E14: 2.4 | F14: =PROJ_AGCeAGPar!K94 -> 5.7008304 | G14: =PROJ_AGCeAGPar!L94 -> 12.885385 | H14: =PROJ_AGCeAGPar!M94 -> 14.353805 | I14: =PROJ_AGCeAGPar!N94 -> 15.659714 | J14: =PROJ_AGCeAGPar!O94 -> 17.133528 | K14: =PROJ_AGCeAGPar!P94 -> 18.799764 | L14: =PROJ_AGCeAGPar!Q94 -> 20.470687 | M14: =PROJ_AGCeAGPar!R94 -> 22.311411 | ... P14: =PROJ_AGCeAGPar!U94 -> 29.038832
C15: % Payout (Lucro Líq. Ajustado) | D15: =PROJ_AGCeAGPar!I91 -> 0.29432837 | E15: =PROJ_AGCeAGPar!J91 -> 0.25 | F15: =PROJ_AGCeAGPar!K91 -> 0.5 | G15: =PROJ_AGCeAGPar!L91 -> 0.5 | H15: =PROJ_AGCeAGPar!M91 -> 0.5 | I15: =PROJ_AGCeAGPar!N91 -> 0.5 | J15: =PROJ_AGCeAGPar!O91 -> 0.5 | K15: =PROJ_AGCeAGPar!P91 -> 0.5 | ... P15: =PROJ_AGCeAGPar!U91 -> 0.5
C16: WATERPORT | D16: 12.6 | E16: 19.2 | F16: =PROJ_AGCeAGPar!K110 -> 21.024015 | G16: =PROJ_AGCeAGPar!L110 -> 23.132809 | H16: =PROJ_AGCeAGPar!M110 -> 24.659574 | I16: =PROJ_AGCeAGPar!N110 -> 26.050374 | J16: =PROJ_AGCeAGPar!O110 -> 27.613396 | K16: =PROJ_AGCeAGPar!P110 -> 29.170792 | L16: =PROJ_AGCeAGPar!Q110 -> 30.85103 | M16: =PROJ_AGCeAGPar!R110 -> 32.66507 | ... P16: =PROJ_AGCeAGPar!U110 -> 38.968113
C17: % Payout (Lucro Líq. Ajustado) | D17: =PROJ_AGCeAGPar!I107 -> 0.74117647 | E17: =PROJ_AGCeAGPar!J107 -> 0.96 | F17: =PROJ_AGCeAGPar!K107 -> 0.96 | G17: =PROJ_AGCeAGPar!L107 -> 0.96 | H17: =PROJ_AGCeAGPar!M107 -> 0.96 | I17: =PROJ_AGCeAGPar!N107 -> 0.96 | J17: =PROJ_AGCeAGPar!O107 -> 0.96 | K17: =PROJ_AGCeAGPar!P107 -> 0.96 | ... P17: =PROJ_AGCeAGPar!U107 -> 0.96
C18: Outros | D18: =59.1+2.4 -> 61.5 | E18: 8.4 | F18: =PROJ_AGCeAGPar!K128 -> 6.966 | G18: =PROJ_AGCeAGPar!L128 -> 0 | H18: =PROJ_AGCeAGPar!M128 -> 0 | I18: =PROJ_AGCeAGPar!N128 -> 0 | J18: =PROJ_AGCeAGPar!O128 -> 0 | K18: =PROJ_AGCeAGPar!P128 -> 0 | L18: =PROJ_AGCeAGPar!Q128 -> 0 | M18: =PROJ_AGCeAGPar!R128 -> 0 | ... P18: =PROJ_AGCeAGPar!U128 -> 0
B19: Total Dividendos Recebidos pela AGC (Caixa) | D19: =D10+D12+D14+D16+D18 -> 218.2 | E19: 271.27 | F19: =F10+F12+F14+F16+F18 -> 258.60653 | G19: =G10+G12+G14+G16+G18 -> 369.86879 | H19: =H10+H12+H14+H16+H18 -> 419.74142 | I19: =I10+I12+I14+I16+I18 -> 485.72467 | J19: =J10+J12+J14+J16+J18 -> 559.79462 | K19: =K10+K12+K14+K16+K18 -> 634.03045 | L19: =L10+L12+L14+L16+L18 -> 711.38902 | M19: =M10+M12+M14+M16+M18 -> 776.93778 | ... P19: =P10+P12+P14+P16+P18 -> 1029.2275
C20: Var. YoY% | E20: =E19/D19-1 -> 0.24321723 | F20: =F19/E19-1 -> -0.046682167 | G20: =G19/F19-1 -> 0.43023765 | H20: =H19/G19-1 -> 0.13483871 | I20: =I19/H19-1 -> 0.15719974 | J20: =J19/I19-1 -> 0.1524937 | K20: =K19/J19-1 -> 0.13261262 | L20: =L19/K19-1 -> 0.1220108 | ... P20: =P19/O19-1 -> 0.10643011
B21: Resultado de Equivalência Patrimonial na AGC | D21: =PROJ_AGCeAGPar!I152 -> 398.987 | E21: =PROJ_AGCeAGPar!J152 -> 435.337 | F21: =PROJ_AGCeAGPar!K152 -> 449.14806 | G21: =PROJ_AGCeAGPar!L152 -> 555.83506 | H21: =PROJ_AGCeAGPar!M152 -> 623.93844 | I21: =PROJ_AGCeAGPar!N152 -> 728.5796 | J21: =PROJ_AGCeAGPar!O152 -> 822.3844 | K21: =PROJ_AGCeAGPar!P152 -> 933.81038 | ... P21: =PROJ_AGCeAGPar!U152 -> 1465.2211
C22: Var. YoY% | E22: =E21/D21-1 -> 0.091105725 | F22: =F21/E21-1 -> 0.031724991 | G22: =G21/F21-1 -> 0.23753192 | H22: =H21/G21-1 -> 0.12252444 | I22: =I21/H21-1 -> 0.1677107 | J22: =J21/I21-1 -> 0.12875024 | K22: =K21/J21-1 -> 0.13549135 | L22: =L21/K21-1 -> 0.059374022 | ... P22: =P21/O21-1 -> 0.12833646
B23: Resultado Líquido AGC | D23: =PROJ_AGCeAGPar!I172 -> 661.965 | E23: =PROJ_AGCeAGPar!J172 -> 348.793 | F23: =PROJ_AGCeAGPar!K172 -> 663.25113 | G23: =PROJ_AGCeAGPar!L172 -> 496.44688 | H23: =PROJ_AGCeAGPar!M172 -> 581.06879 | I23: =PROJ_AGCeAGPar!N172 -> 688.22048 | J23: =PROJ_AGCeAGPar!O172 -> 780.21277 | K23: =PROJ_AGCeAGPar!P172 -> 891.28839 | ... P23: =PROJ_AGCeAGPar!U172 -> 1420.4983
C24: Var. YoY% | E24: =E23/D23-1 -> -0.4730945 | F24: =F23/E23-1 -> 0.90156088 | G24: =G23/F23-1 -> -0.25149485 | H24: =H23/G23-1 -> 0.17045512 | I24: =I23/H23-1 -> 0.18440447 | J24: =J23/I23-1 -> 0.13366689 | K24: =K23/J23-1 -> 0.14236581 | L24: =L23/K23-1 -> 0.059827254 | ... P24: =P23/O23-1 -> 0.13304231
B25: Dividendos Pagos pela AGC | D25: =PROJ_AGCeAGPar!I177 -> 157.2164 | E25: =PROJ_AGCeAGPar!J177 -> 82.838 | F25: =PROJ_AGCeAGPar!K177 -> 472.56643 | G25: =PROJ_AGCeAGPar!L177 -> 117.90613 | H25: =PROJ_AGCeAGPar!M177 -> 469.21305 | I25: =PROJ_AGCeAGPar!N177 -> 555.73804 | J25: =PROJ_AGCeAGPar!O177 -> 630.02181 | K25: =PROJ_AGCeAGPar!P177 -> 719.71538 | ... P25: =PROJ_AGCeAGPar!U177 -> 1147.0523
C26: % Payout | D26: =PROJ_AGCeAGPar!I178 -> 0.24999953 | E26: =PROJ_AGCeAGPar!J178 -> 0.24999898 | F26: =PROJ_AGCeAGPar!K178 -> 0.75 | G26: =PROJ_AGCeAGPar!L178 -> 0.25 | H26: =PROJ_AGCeAGPar!M178 -> 0.85 | I26: =PROJ_AGCeAGPar!N178 -> 0.85 | J26: =PROJ_AGCeAGPar!O178 -> 0.85 | K26: =PROJ_AGCeAGPar!P178 -> 0.85 | ... P26: =PROJ_AGCeAGPar!U178 -> 0.85
B27: AG Participações
B28: (=) Resultado Líquido AGPar | D28: =PROJ_AGCeAGPar!I293 -> 310.985 | E28: =PROJ_AGCeAGPar!J293 -> 238.446 | F28: =PROJ_AGCeAGPar!K293 -> 784.92858 | G28: =PROJ_AGCeAGPar!L293 -> 527.97254 | H28: =PROJ_AGCeAGPar!M293 -> 538.23025 | I28: =PROJ_AGCeAGPar!N293 -> 655.10182 | J28: =PROJ_AGCeAGPar!O293 -> 781.30466 | K28: =PROJ_AGCeAGPar!P293 -> 928.49474 | ... P28: =PROJ_AGCeAGPar!U293 -> 1654.8959
C29: Var. YoY% | E29: =E28/D28-1 -> -0.23325562 | F29: =F28/E28-1 -> 2.2918505 | G29: =G28/F28-1 -> -0.32736231 | H29: =H28/G28-1 -> 0.019428496 | I29: =I28/H28-1 -> 0.21714046 | J29: =J28/I28-1 -> 0.19264614 | K29: =K28/J28-1 -> 0.18839012 | L29: =L28/K28-1 -> 0.094896625 | ... P29: =P28/O28-1 -> 0.14309834
C30: (-) Resultado de Equivalência Patrimonial na AGPar | D30: =PROJ_AGCeAGPar!I342 -> -529.116 | E30: =PROJ_AGCeAGPar!J342 -> -263.525 | F30: =PROJ_AGCeAGPar!K342 -> -835.01583 | G30: =PROJ_AGCeAGPar!L342 -> -577.67118 | H30: =PROJ_AGCeAGPar!M342 -> -566.14679 | I30: =PROJ_AGCeAGPar!N342 -> -659.27828 | J30: =PROJ_AGCeAGPar!O342 -> -754.16479 | K30: =PROJ_AGCeAGPar!P342 -> -873.05481 | ... P30: =PROJ_AGCeAGPar!U342 -> -1420.4983
C31: Var. YoY% | E31: =E30/D30-1 -> -0.50195231 | F31: =F30/E30-1 -> 2.1686399 | G31: =G30/F30-1 -> -0.30819135 | H31: =H30/G30-1 -> -0.019949724 | I31: =I30/H30-1 -> 0.16450059 | J31: =J30/I30-1 -> 0.14392482 | K31: =K30/J30-1 -> 0.15764462 | L31: =L30/K30-1 -> 0.067342179 | ... P31: =P30/O30-1 -> 0.13506456
C32: (+) Dividendos e JSCP recebidos de controladas | D32: =PROJ_AGCeAGPar!I343 -> 133.4004 | E32: =PROJ_AGCeAGPar!J343 -> 67 | F32: =PROJ_AGCeAGPar!K343 -> 401.68146 | G32: =PROJ_AGCeAGPar!L343 -> 100.22021 | H32: =PROJ_AGCeAGPar!M343 -> 398.83109 | I32: =PROJ_AGCeAGPar!N343 -> 472.37733 | J32: =PROJ_AGCeAGPar!O343 -> 535.51854 | K32: =PROJ_AGCeAGPar!P343 -> 611.75807 | ... P32: =PROJ_AGCeAGPar!U343 -> 974.99449
C33: (+/-) Variação Contas de Ativo e Passivo | D33: =PROJ_AGCeAGPar!I344 -> -40.612 | E33: =PROJ_AGCeAGPar!J344 -> 70.696 | F33: =PROJ_AGCeAGPar!K344 -> -101.55367 | G33: =PROJ_AGCeAGPar!L344 -> -8.5445853 | H33: =PROJ_AGCeAGPar!M344 -> -54.126451 | I33: =PROJ_AGCeAGPar!N344 -> 13.220023 | J33: =PROJ_AGCeAGPar!O344 -> 6.2198675 | K33: =PROJ_AGCeAGPar!P344 -> -2.995157 | ... P33: =PROJ_AGCeAGPar!U344 -> -5.4454302
C34: (+/-) Investimentos permanentes | D34: =PROJ_AGCeAGPar!I347+PROJ_AGCeAGPar!I348 -> 353.39561 | E34: =PROJ_AGCeAGPar!J347+PROJ_AGCeAGPar!J348 -> -274.162 | F34: =PROJ_AGCeAGPar!K347+PROJ_AGCeAGPar!K348 -> -349.11504 | G34: =PROJ_AGCeAGPar!L347+PROJ_AGCeAGPar!L348 -> 17.68592 | H34: =PROJ_AGCeAGPar!M347+PROJ_AGCeAGPar!M348 -> 70.381958 | I34: =PROJ_AGCeAGPar!N347+PROJ_AGCeAGPar!N348 -> 83.360706 | J34: =PROJ_AGCeAGPar!O347+PROJ_AGCeAGPar!O348 -> 94.503271 | K34: =PROJ_AGCeAGPar!P347+PROJ_AGCeAGPar!P348 -> 107.95731 | ... P34: =PROJ_AGCeAGPar!U347+PROJ_AGCeAGPar!U348 -> 172.05785
B35: (=) FCF operacional após Atividades de Investimento | D35: =D28+D30+D32+D33+D34 -> 228.053 | E35: =E28+E30+E32+E33+E34 -> -161.545 | F35: =F28+F30+F32+F33+F34 -> -99.0745 | G35: =G28+G30+G32+G33+G34 -> 59.662915 | H35: =H28+H30+H32+H33+H34 -> 387.17006 | I35: =I28+I30+I32+I33+I34 -> 564.7816 | J35: =J28+J30+J32+J33+J34 -> 663.38155 | K35: =K28+K30+K32+K33+K34 -> 772.16015 | ... P35: =P28+P30+P32+P33+P34 -> 1376.0045
C36: (+/-) Captação / (Amortização) de dívida | D36: =PROJ_AGCeAGPar!I351 -> -144.941 | E36: =PROJ_AGCeAGPar!J351 -> 119.702 | F36: =PROJ_AGCeAGPar!K351 -> 878.39035 | G36: =PROJ_AGCeAGPar!L351 -> 40.974688 | H36: =PROJ_AGCeAGPar!M351 -> 1.6377812 | I36: =PROJ_AGCeAGPar!N351 -> -0.89489201 | J36: =PROJ_AGCeAGPar!O351 -> -140.24065 | K36: =PROJ_AGCeAGPar!P351 -> -141.11105 | ... P36: =PROJ_AGCeAGPar!U351 -> -153.24672
C37: (+/-) Variação no Capital Social Líquida | D37: =PROJ_AGCeAGPar!I352 -> -75.541 | E37: =PROJ_AGCeAGPar!J352 -> 105.025 | F37: =PROJ_AGCeAGPar!K352 -> -65.100751 | G37: =PROJ_AGCeAGPar!L352 -> -17.555044 | H37: =PROJ_AGCeAGPar!M352 -> -70.381958 | I37: =PROJ_AGCeAGPar!N352 -> -83.360706 | J37: =PROJ_AGCeAGPar!O352 -> -94.503271 | K37: =PROJ_AGCeAGPar!P352 -> -107.95731 | ... P37: =PROJ_AGCeAGPar!U352 -> -172.05785
C38: (-) Dividendos e juros sobre Capital Próprio pagos | D38: =PROJ_AGCeAGPar!I353 -> -40.116 | E38: =PROJ_AGCeAGPar!J353 -> -82.517 | F38: =PROJ_AGCeAGPar!K353 -> -121.31979 | G38: =PROJ_AGCeAGPar!L353 -> -107.83843 | H38: =PROJ_AGCeAGPar!M353 -> -57.447727 | I38: =PROJ_AGCeAGPar!N353 -> -227.81266 | J38: =PROJ_AGCeAGPar!O353 -> -276.61644 | K38: =PROJ_AGCeAGPar!P353 -> -333.07769 | ... P38: =PROJ_AGCeAGPar!U353 -> -614.01768
B39: (=) Fluxo de Caixa Livre | D39: =D35+D36+D37+D38 -> -32.545 | E39: =E35+E36+E37+E38 -> -19.335 | F39: =F35+F36+F37+F38 -> 592.89532 | G39: =G35+G36+G37+G38 -> -24.755876 | H39: =H35+H36+H37+H38 -> 260.97816 | I39: =I35+I36+I37+I38 -> 252.71334 | J39: =J35+J36+J37+J38 -> 152.02119 | K39: =K35+K36+K37+K38 -> 190.0141 | ... P39: =P35+P36+P37+P38 -> 436.68227
B40: Caixa + Aplicações Financeiras | D40: =PROJ_AGCeAGPar!I368 -> 30.927 | E40: =PROJ_AGCeAGPar!J368 -> 11.592 | F40: =PROJ_AGCeAGPar!K368 -> 604.48732 | G40: =PROJ_AGCeAGPar!L368 -> 579.73144 | H40: =PROJ_AGCeAGPar!M368 -> 840.7096 | I40: =PROJ_AGCeAGPar!N368 -> 1093.4229 | J40: =PROJ_AGCeAGPar!O368 -> 1245.4441 | K40: =PROJ_AGCeAGPar!P368 -> 1435.4582 | ... P40: =PROJ_AGCeAGPar!U368 -> 3086.4429
B41: Investimentos Permanentes | D41: =PROJ_AGCeAGPar!I314+PROJ_AGCeAGPar!I315+PROJ_AGCeAGPar!I316 -> 1498.731 | E41: =PROJ_AGCeAGPar!J314+PROJ_AGCeAGPar!J315+PROJ_AGCeAGPar!J316 -> 1969.418 | F41: =PROJ_AGCeAGPar!K314+PROJ_AGCeAGPar!K315+PROJ_AGCeAGPar!K316 -> 2751.8674 | G41: =PROJ_AGCeAGPar!L314+PROJ_AGCeAGPar!L315+PROJ_AGCeAGPar!L316 -> 3211.6324 | H41: =PROJ_AGCeAGPar!M314+PROJ_AGCeAGPar!M315+PROJ_AGCeAGPar!M316 -> 3308.5662 | I41: =PROJ_AGCeAGPar!N314+PROJ_AGCeAGPar!N315+PROJ_AGCeAGPar!N316 -> 3412.1064 | J41: =PROJ_AGCeAGPar!O314+PROJ_AGCeAGPar!O315+PROJ_AGCeAGPar!O316 -> 3536.2494 | K41: =PROJ_AGCeAGPar!P314+PROJ_AGCeAGPar!P315+PROJ_AGCeAGPar!P316 -> 3689.5888 | ... P41: =PROJ_AGCeAGPar!U314+PROJ_AGCeAGPar!U315+PROJ_AGCeAGPar!U316 -> 4786.5075
B42: Patrimônio Líquido | D42: =PROJ_AGCeAGPar!I329 -> 1415.165 | E42: =PROJ_AGCeAGPar!J329 -> 1676.119 | F42: =PROJ_AGCeAGPar!K329 -> 2274.627 | G42: =PROJ_AGCeAGPar!L329 -> 2677.2061 | H42: =PROJ_AGCeAGPar!M329 -> 3087.6067 | I42: =PROJ_AGCeAGPar!N329 -> 3431.5351 | J42: =PROJ_AGCeAGPar!O329 -> 3841.7201 | K42: =PROJ_AGCeAGPar!P329 -> 4329.1798 | ... P42: =PROJ_AGCeAGPar!U329 -> 7798.6233
C43: Divida CP | D43: =PROJ_AGCeAGPar!I365 -> 40.402 | E43: =PROJ_AGCeAGPar!J365 -> 40.196 | F43: =PROJ_AGCeAGPar!K365 -> 0 | G43: =PROJ_AGCeAGPar!L365 -> 14.634678 | H43: =PROJ_AGCeAGPar!M365 -> 14.634678 | I43: =PROJ_AGCeAGPar!N365 -> 147.96801 | J43: =PROJ_AGCeAGPar!O365 -> 585.22674 | K43: =PROJ_AGCeAGPar!P365 -> 583.64895 | ... P43: =PROJ_AGCeAGPar!U365 -> 58.538713
C44: Divida LP | D44: =PROJ_AGCeAGPar!I366 -> 40.004 | E44: =PROJ_AGCeAGPar!J366 -> 159.912 | F44: =PROJ_AGCeAGPar!K366 -> 1078.4984 | G44: =PROJ_AGCeAGPar!L366 -> 1104.8384 | H44: =PROJ_AGCeAGPar!M366 -> 1106.4761 | I44: =PROJ_AGCeAGPar!N366 -> 972.24792 | J44: =PROJ_AGCeAGPar!O366 -> 394.74855 | K44: =PROJ_AGCeAGPar!P366 -> 255.21528 | ... P44: =PROJ_AGCeAGPar!U366 -> 71.165587
...

Sheet Projeção -->

Sheet PROJ_AGCeAGPar
I1: LEGENDA:
B2: MODELAGEM AG Concessões e AG Par (Controladoras) | I2: Dados Realizados Inputados | L2: VICTOR LOPES SCHMUTZLER
C3: (R$ milhões) | I3: Dados Realizados Calculados | L3: +55 (11) 3553-2529
I4: Dados Projetados Inputados
B5: 1. ESTRUTURA ACIONÁRIA AG CONCESSÕES (Controladora) | I5: Dados Projetados Calculados
C7: (Antes da Venda de Quiport e Aeris)
B43: 2. PROJEÇÕES AG CONCESSÕES (Controladora)
E46: 2006 | F46: 2007 | G46: 2008 | H46: 2009 | I46: 2010 | J46: 2011 | K46: 2012 | L46: 2013 | M46: 2014 | N46: 2015 | O46: 2016 | P46: 2017 | Q46: 2018 | R46: 2019 | S46: 2020 | T46: 2021 | U46: 2022
C48: CEMIG
C49: Receita Operacional Líquida | E49: 8605.143 | F49: 10245.914 | G49: 10890.322 | H49: 11705.083 | I49: 12863.33 | J49: 15814 | K49: =J49*(1+K51*K$379) -> 17561.086 | L49: =K49*(1+L51*L$379) -> 17649.159 | M49: =L49*(1+M51*M$379) -> 18581.034 | N49: =M49*(1+N51*N$379) -> 19367.012 | O49: =N49*(1+O51*O$379) -> 20529.033 | P49: =O49*(1+P51*P$379) -> 21879.843 | Q49: =P49*(1+Q51*Q$379) -> 22194.913 | R49: =Q49*(1+R51*R$379) -> 23173.708 | ... U49: =T49*(1+U51*U$379) -> 26862.887
C50: Var. % YoY | F50: =F49/E49-1 -> 0.1906733 | G50: =G49/F49-1 -> 0.062894145 | H50: =H49/G49-1 -> 0.074815143 | I50: =I49/H49-1 -> 0.098952481 | J50: =J49/I49-1 -> 0.22938617 | K50: =K49/J49-1 -> 0.11047719 | L50: =L49/K49-1 -> 0.0050152017 | M50: =M49/L49-1 -> 0.0528 | ... U50: =U49/T49-1 -> 0.061154693
C51: Elasticidade-PIBx | F51: =F50/F$379 -> 3.1281225 | G51: =G50/G$379 -> 1.2166861 | H51: =H50/H$379 -> -22.792259 | I51: =I50/I$379 -> 1.3134793 | J51: =J50/J$379 -> 8.3939315 | K51: 3.2 | L51: 0.1 | M51: 1.2 | N51: 0.9 | O51: 1.2 | P51: 1.4 | Q51: 0.3 | R51: 0.9 | S51: 0.6 | T51: 1.2 | U51: 1.2
C52: Lucro Líquido Ajustado | G52: 1887.035 | H52: 1861.4 | I52: 2257.976 | J52: 2415 | K52: =K54*K49 -> 2704.4073 | L52: =L54*L49 -> 2541.4788 | M52: =M54*M49 -> 2527.0207 | N52: =N54*N49 -> 2730.7487 | O52: =O54*O49 -> 2976.7097 | P52: =P54*P49 -> 3347.616 | Q52: =Q54*Q49 -> 3196.0674 | R52: =R54*R49 -> 3290.6666 | ... U52: =U54*U49 -> 4324.9248
C53: Var. % YoY | H53: =H52/G52-1 -> -0.013584804 | I53: =I52/H52-1 -> 0.21305254 | J53: =J52/I52-1 -> 0.069541926 | K53: =K52/J52-1 -> 0.11983738 | L53: =L52/K52-1 -> -0.060245526 | M53: =M52/L52-1 -> -0.0056888889 | N53: =N52/M52-1 -> 0.080619853 | O53: =O52/N52-1 -> 0.090070922 | ... U53: =U52/T52-1 -> 0.095166061
C54: Mg Líquida | G54: =G52/G49 -> 0.17327633 | H54: =H52/H49 -> 0.15902493 | I54: =I52/I49 -> 0.17553588 | J54: =J52/J49 -> 0.15271279 | K54: 0.154 | L54: 0.144 | M54: 0.136 | N54: 0.141 | O54: 0.145 | P54: 0.153 | Q54: 0.144 | R54: 0.142 | S54: 0.15 | T54: 0.156 | U54: 0.161
C55: Dividendos Distribuidos | G55: 943.517 | H55: 930.702 | I55: 1196.074 | J55: 1294.04 | K55: =K56*K52 -> 1352.2036 | L55: =L56*L52 -> 1270.7394 | M55: =M56*M52 -> 1263.5103 | N55: =N56*N52 -> 1365.3743 | O55: =O56*O52 -> 1488.3549 | P55: =P56*P52 -> 1673.808 | Q55: =Q56*Q52 -> 1598.0337 | R55: =R56*R52 -> 1645.3333 | ... U55: =U56*U52 -> 2162.4624
C56: Payout % (jun/dez ano seguinte) | G56: =G55/G52 -> 0.49999974 | H56: =H55/H52 -> 0.50000107 | I56: =I55/I52 -> 0.52971068 | J56: =J55/J52 -> 0.53583437 | K56: 0.5 | L56: =K56 -> 0.5 | M56: =L56 -> 0.5 | N56: =M56 -> 0.5 | O56: =N56 -> 0.5 | P56: =O56 -> 0.5 | Q56: =P56 -> 0.5 | R56: =Q56 -> 0.5 | S56: =R56 -> 0.5 | ... U56: =T56 -> 0.5
C57: Dividendos Propostos de AGC | G57: =G55*$D$59 -> 135.9608 | H57: =H55*$D$59 -> 134.11416 | I57: =I55*$D$59 -> 172.35426 | J57: =J55*$D$59 -> 186.47116 | K57: =K55*$D$59 -> 194.85254 | L57: =L55*$D$59 -> 183.11355 | M57: =M55*$D$59 -> 182.07184 | N57: =N55*$D$59 -> 196.75044 | ... U57: =U55*$D$59 -> 311.61083
C58: % do payout no período (ano 0) | G58: 0 | H58: 0 | I58: 0 | J58: 0 | K58: =J58 -> 0 | L58: =K58 -> 0 | M58: =L58 -> 0 | N58: =M58 -> 0 | O58: =N58 -> 0 | P58: =O58 -> 0 | Q58: =P58 -> 0 | R58: =Q58 -> 0 | ... U58: =T58 -> 0
C59: Participação de AGC (Dividendos recebidos caixa) | D59: 0.1441 | G59: =(F56*F52*$D$59) -> 0 | H59: 0 | I59: 0 | J59: =I57/J64 -> 107.70735 | K59: =((J57*(1-J58))+(K57*K58))/K64 -> 116.52927 | L59: =((K57*(1-K58))+(L57*L58))/L64 -> 121.76695 | M59: =((L57*(1-L58))+(M57*M58))/M64 -> 114.43103 | N59: =((M57*(1-M58))+(N57*N58))/N64 -> 113.78005 | O59: =((N57*(1-N58))+(O57*O58))/O64 -> 122.95298 | P59: =((O57*(1-O58))+(P57*P58))/P64 -> 134.02746 | Q59: =((P57*(1-P58))+(Q57*Q58))/Q64 -> 150.72766 | R59: =((Q57*(1-Q58))+(R57*R58))/R64 -> 143.90413 | ... U59: =((T57*(1-T58))+(U57*U58))/U64 -> 177.80988
C60: Patrimônio Líquido | E60: 7522.453 | F60: 8390.177 | G60: 9351.634 | H60: 10275.505 | I60: 11476.133 | J60: 11745 | K60: =J60+(1-K56)*K52 -> 13097.204 | L60: =K60+(1-L56)*L52 -> 14367.943 | M60: =L60+(1-M56)*M52 -> 15631.453 | N60: =M60+(1-N56)*N52 -> 16996.828 | O60: =N60+(1-O56)*O52 -> 18485.183 | P60: =O60+(1-P56)*P52 -> 20158.991 | Q60: =P60+(1-Q56)*Q52 -> 21757.024 | R60: =Q60+(1-R56)*R52 -> 23402.358 | ... U60: =T60+(1-U56)*U52 -> 29329.541
C61: Variação PL (Resultado Equivalencia Patrimonial AGC) | F61: =(F60-E60)*$D$59 -> 125.03903 | G61: =(G60-F60)*$D$59 -> 138.54595 | H61: =(H60-G60)*$D$59 -> 133.12981 | I61: =(I60-H60)*$D$59 -> 173.01049 | J61: =(J52*$D$59)/J64 -> 217.47255 | K61: =(K52*$D$59)/K64 -> 243.53389 | L61: =(L52*$D$59)/L64 -> 228.86206 | M61: =(M52*$D$59)/M64 -> 227.56009 | N61: =(N52*$D$59)/N64 -> 245.90595 | O61: =(O52*$D$59)/O64 -> 268.05493 | P61: =(P52*$D$59)/P64 -> 301.45531 | Q61: =(Q52*$D$59)/Q64 -> 287.80825 | ... U61: =(U52*$D$59)/U64 -> 389.4627
F62: =F60*$D$59 -> 1209.0245 | G62: =G60*$D$59 -> 1347.5705 | H62: =H60*$D$59 -> 1480.7003 | I62: =I60*$D$59 -> 1653.7108 | J62: =J60*$D$59 -> 1692.4545 | K62: =K60*$D$59 -> 1887.307 | L62: =L60*$D$59 -> 2070.4206 | M62: =M60*$D$59 -> 2252.4924 | ... U62: =U60*$D$59 -> 4226.3869
H63: PL Holding AGC Energia S.A. => | I63: 913.402 | J63: =1057.646 -> 1057.646 | K63: =K62/K64 -> 1179.4129 | L63: =L62/L64 -> 1293.844 | M63: =M62/M64 -> 1407.624 | N63: =N62/N64 -> 1530.577 | O63: =O62/O64 -> 1664.6045 | P63: =P62/P64 -> 1815.3321 | Q63: =Q62/Q64 -> 1959.2362 | R63: =R62/R64 -> 2107.3997 | ... U63: =U62/U64 -> 2641.147
H64: Ratio ajuste para Equivalencia AGC Energia S.A. => | I64: =I62/I63 -> 1.8104961 | J64: =J62/J63 -> 1.6002089 | K64: =J64 -> 1.6002089 | L64: =K64 -> 1.6002089 | M64: =L64 -> 1.6002089 | N64: =M64 -> 1.6002089 | O64: =N64 -> 1.6002089 | P64: =O64 -> 1.6002089 | Q64: =P64 -> 1.6002089 | R64: =Q64 -> 1.6002089 | ... U64: =T64 -> 1.6002089
C67: CCR
C68: Receita Operacional Líquida | H68: =3817.653-728.316 -> 3089.337 | I68: 3775.8538 | J68: 4577.5718 | K68: =J68*(1+K70*K$379) -> 5162.3074 | L68: =K68*(1+L70*L$379) -> 5809.5577 | M68: =L68*(1+M70*M$379) -> 6499.7331 | N68: =M68*(1+N70*N$379) -> 7171.8056 | O68: =N68*(1+O70*O$379) -> 7817.268 | P68: =O68*(1+P70*P$379) -> 8552.0912 | Q68: =P68*(1+Q70*Q$379) -> 9332.042 | R68: =Q68*(1+R70*R$379) -> 10200.855 | ... U68: =T68*(1+U70*U$379) -> 12513.621
C69: Var. % YoY | I69: =I68/H68-1 -> 0.22222142 | J69: =J68/I68-1 -> 0.21232759 | K69: =K68/J68-1 -> 0.12773925 | L69: =L68/K68-1 -> 0.12538004 | M69: =M68/L68-1 -> 0.1188 | N69: =N68/M68-1 -> 0.1034 | O69: =O68/N68-1 -> 0.09 | P69: =P68/O68-1 -> 0.094 | ... U69: =U68/T68-1 -> 0.061154693
C70: Elasticidade-PIBx | I70: =I69/I$379 -> 2.9497314 | J70: =J69/J$379 -> 7.7697067 | K70: 3.7 | L70: 2.5 | M70: 2.7 | N70: 2.2 | O70: 1.8 | P70: 2 | Q70: 1.9 | R70: 1.9 | S70: 1.8 | T70: 1.2 | U70: 1.2
C71: Lucro Líquido Ajustado | G71: 714 | H71: 709 | I71: 672 | J71: 899.36646 | K71: =K73*K68 -> 1269.9276 | L71: =L73*L68 -> 1638.2953 | M71: =M73*M68 -> 2027.9167 | N71: =N73*N68 -> 2517.3037 | O71: =O73*O68 -> 2915.841 | P71: =P73*P68 -> 3352.4198 | Q71: =Q73*Q68 -> 3732.8168 | R71: =R73*R68 -> 4284.3591 | ... U71: =U73*U68 -> 5806.3201
C72: Var. % YoY | I72: =I71/H71-1 -> -0.052186178 | J72: =J71/I71-1 -> 0.33834295 | K72: =K71/J71-1 -> 0.41202465 | L72: =L71/K71-1 -> 0.2900698 | M72: =M71/L71-1 -> 0.23782128 | N72: =N71/M71-1 -> 0.241325 | O72: =O71/N71-1 -> 0.15831909 | P72: =P71/O71-1 -> 0.14972654 | ... U72: =U71/T71-1 -> 0.14772908
C73: Mg Líquida | H73: =H71/H68 -> 0.22949908 | I73: =I71/I68 -> 0.17797299 | J73: =J71/J68 -> 0.19647239 | K73: 0.246 | L73: 0.282 | M73: 0.312 | N73: 0.351 | O73: 0.373 | P73: 0.392 | Q73: 0.4 | R73: 0.42 | S73: 0.433 | T73: 0.429 | U73: 0.464
C74: Dividendos Distribuidos | G74: 605 | H74: 569.11935 | I74: 851.14942 | J74: 796.923 | K74: =K75*K71 -> 1079.4385 | L74: =L75*L71 -> 1392.551 | M74: =M75*M71 -> 1723.7292 | N74: =N75*N71 -> 2139.7082 | O74: =O75*O71 -> 2478.4648 | P74: =P75*P71 -> 2849.5568 | Q74: =Q75*Q71 -> 3172.8943 | R74: =R75*R71 -> 3641.7053 | ... U74: =U75*U71 -> 4935.3721
C75: Payout % (dez e abr/mai ano seguinte) | G75: =G74/G71 -> 0.84733894 | H75: =H74/H71 -> 0.80270713 | I75: =I74/I71 -> 1.2665914 | J75: =J74/J71 -> 0.88609375 | K75: 0.85 | L75: 0.85 | M75: =L75 -> 0.85 | N75: =M75 -> 0.85 | O75: =N75 -> 0.85 | P75: =O75 -> 0.85 | Q75: =P75 -> 0.85 | R75: =Q75 -> 0.85 | S75: =R75 -> 0.85 | T75: =S75 -> 0.85 | U75: =T75 -> 0.85
C76: Dividendos Propostos de AGC | G76: =G74*$D$78 -> 101.24675 | H76: =H74*$D$78 -> 95.242124 | I76: =I74*$D$78 -> 142.43986 | J76: =J74*$D$78 -> 133.36506 | K76: =K74*$D$78 -> 180.64403 | L76: =L74*$D$78 -> 233.04341 | M76: =M74*$D$78 -> 288.46609 | N76: =N74*$D$78 -> 358.08016 | ... U76: =U74*$D$78 -> 825.93452
C77: % do payout no período (ano 0) | G77: 0 | H77: 0 | I77: 0 | J77: 0 | K77: 0.6 | L77: =K77 -> 0.6 | M77: =L77 -> 0.6 | N77: =M77 -> 0.6 | O77: =N77 -> 0.6 | P77: =O77 -> 0.6 | Q77: =P77 -> 0.6 | R77: =Q77 -> 0.6 | S77: =R77 -> 0.6 | ... U77: =T77 -> 0.6
C78: Participação de AGC (Dividendos recebidos caixa) | D78: 0.16735 | H78: 100.8 | I78: 141.5 | J78: 147.7 | K78: =(K76*K77) -> 108.38642 | L78: =(K76*(1-K77))+(L76*L77) -> 212.08366 | M78: =(L76*(1-L77))+(M76*M77) -> 266.29701 | N78: =(M76*(1-M77))+(N76*N77) -> 330.23453 | O78: =(N76*(1-N77))+(O76*O77) -> 392.09472 | P78: =(O76*(1-O77))+(P76*P77) -> 452.03243 | Q78: =(P76*(1-P77))+(Q76*Q77) -> 509.33965 | R78: =(Q76*(1-Q77))+(R76*R77) -> 578.05717 | S78: =(R76*(1-R77))+(S76*S77) -> 654.6859 | ... U78: =(T76*(1-T77))+(U76*U77) -> 783.4107
C79: Patrimônio Líquido | H79: 3345.171 | I79: 3182.387 | J79: 3267.625 | K79: =J79+(1-K75)*K71+300 -> 3758.1141 | L79: =K79+(1-L75)*L71 -> 4003.8584 | M79: =L79+(1-M75)*M71 -> 4308.0459 | N79: =M79+(1-N75)*N71 -> 4685.6415 | O79: =N79+(1-O75)*O71 -> 5123.0177 | P79: =O79+(1-P75)*P71 -> 5625.8806 | Q79: =P79+(1-Q75)*Q71 -> 6185.8031 | R79: =Q79+(1-R75)*R71 -> 6828.457 | S79: =R79+(1-S75)*S71 -> 7550.6316 | ... U79: =T79+(1-U75)*U71 -> 9180.4243
C80: Variação PL (Resultado Equivalencia Patrimonial AGC) | H80: =(H79-G79)*$D$78 -> 559.81437 | I80: =(I79-H79)*$D$78 -> -27.241902 | J80: =J71*$D$78 -> 150.50898 | K80: =K71*$D$78+360*D78 -> 272.76839 | L80: =L71*$D$78 -> 274.16871 | M80: =M71*$D$78 -> 339.37187 | N80: =N71*$D$78 -> 421.27078 | O80: =O71*$D$78 -> 487.96599 | P80: =P71*$D$78 -> 561.02745 | Q80: =Q71*$D$78 -> 624.68689 | R80: =R71*$D$78 -> 716.9875 | S80: =S71*$D$78 -> 805.70617 | ... U80: =U71*$D$78 -> 971.68767
C83: SANEPAR
...

Sheet PROJ_ConsAG
I1: LEGENDA:
B2: MODELAGEM ConAG (Consolidado) | I2: Dados Realizados Inputados | L2: VICTOR LOPES SCHMUTZLER
C3: (R$ milhões) | I3: Dados Realizados Calculados | L3: +55 (11) 3553-2529
I4: Dados Projetados Inputados
I5: Dados Projetados Calculados
C7: DRE | E7: 2006 | F7: 2007 | G7: 2008 | H7: 2009 | I7: 2010 | J7: 2011 | K7: 2012 | L7: 2013 | M7: 2014 | N7: 2015 | O7: 2016 | P7: 2017 | Q7: 2018 | R7: 2019 | S7: 2020 | T7: 2021 | U7: 2022
C8: Receita Líquida de Vendas e Serviços | I8: 4256.129 | J8: 4337.532 | K8: =J8*(1+K10*K207) -> 4408.0692 | L8: =K8*(1+L10*L207) -> 4518.606 | M8: =L8*(1+M10*M207) -> 4618.0153 | N8: =M8*(1+N10*N207) -> 4726.5387 | O8: =N8*(1+O10*O207) -> 4844.7021 | P8: =O8*(1+P10*P207) -> 4958.5526 | Q8: =P8*(1+Q10*Q207) -> 5077.5579 | R8: =Q8*(1+R10*R207) -> 5201.9581 | ... U8: =T8*(1+U10*U207) -> 5605.8785
C9: Var. % YoY | J9: =J8/I8-1 -> 0.019126065 | K9: =K8/J8-1 -> 0.016262061 | L9: =L8/K8-1 -> 0.025076008 | M9: =M8/L8-1 -> 0.022 | N9: =N8/M8-1 -> 0.0235 | O9: =O8/N8-1 -> 0.025 | P9: =P8/O8-1 -> 0.0235 | Q9: =Q8/P8-1 -> 0.024 | ... U9: =U8/T8-1 -> 0.025481122
C10: Elasticidade-PIB | J10: =J9/J207 -> 0.69988038 | K10: 0.5 | L10: =K10 -> 0.5 | M10: =L10 -> 0.5 | N10: =M10 -> 0.5 | O10: =N10 -> 0.5 | P10: =O10 -> 0.5 | Q10: =P10 -> 0.5 | R10: =Q10 -> 0.5 | S10: =R10 -> 0.5 | ... U10: =T10 -> 0.5
C11: (-) Custo dos Bens e/ou Serviços Vendidos | I11: -3327.617 | J11: -3456.696 | K11: =K12*K8 -> -3512.909 | L11: =L12*L8 -> -3600.9987 | M11: =M12*M8 -> -3680.2207 | N11: =N12*N8 -> -3766.7059 | O11: =O12*O8 -> -3860.8735 | P11: =P12*P8 -> -3951.6041 | Q11: =Q12*Q8 -> -4046.4426 | R11: =R12*R8 -> -4145.5804 | ... U11: =U12*U8 -> -4467.4754
C12: % Receita Líquida | I12: =I11/I8 -> -0.7818412 | J12: =J11/J8 -> -0.79692692 | K12: =J12 -> -0.79692692 | L12: =K12 -> -0.79692692 | M12: =L12 -> -0.79692692 | N12: =M12 -> -0.79692692 | O12: =N12 -> -0.79692692 | P12: =O12 -> -0.79692692 | Q12: =P12 -> -0.79692692 | R12: =Q12 -> -0.79692692 | ... U12: =T12 -> -0.79692692
C13: (=) Resultado Bruto | I13: =I8+I11 -> 928.512 | J13: =J8+J11 -> 880.836 | K13: =K8+K11 -> 895.16021 | L13: =L8+L11 -> 917.60725 | M13: =M8+M11 -> 937.79461 | N13: =N8+N11 -> 959.83279 | O13: =O8+O11 -> 983.82861 | P13: =P8+P11 -> 1006.9486 | ... U13: =U8+U11 -> 1138.403
C14: Var. % YoY | J14: =J13/I13-1 -> -0.051346671 | K14: =K13/J13-1 -> 0.016262061 | L14: =L13/K13-1 -> 0.025076008 | M14: =M13/L13-1 -> 0.022 | N14: =N13/M13-1 -> 0.0235 | O14: =O13/N13-1 -> 0.025 | P14: =P13/O13-1 -> 0.0235 | Q14: =Q13/P13-1 -> 0.024 | ... U14: =U13/T13-1 -> 0.025481122
C15: (-) (Despesas)/Receitas Operacionais (ex equiv. Patr) | I15: =-439.919+75.428-I18 -> -455.819 | J15: =-265.006+67.101-J18 -> -398.752 | K15: =K17*K8 -> -440.80692 | L15: =L17*L8 -> -451.8606 | M15: =M17*M8 -> -461.80153 | N15: =N17*N8 -> -472.65387 | O15: =O17*O8 -> -484.47021 | P15: =P17*P8 -> -495.85526 | Q15: =Q17*Q8 -> -507.75579 | R15: =R17*R8 -> -520.19581 | ... U15: =U17*U8 -> -560.58785
C16: Var. % YoY | J16: =J15/I15-1 -> -0.12519662 | K16: =K15/J15-1 -> 0.10546636 | L16: =L15/K15-1 -> 0.025076008 | M16: =M15/L15-1 -> 0.022 | N16: =N15/M15-1 -> 0.0235 | O16: =O15/N15-1 -> 0.025 | P16: =P15/O15-1 -> 0.0235 | Q16: =Q15/P15-1 -> 0.024 | ... U16: =U15/T15-1 -> 0.025481122
C17: % Receita Líquida | I17: =I15/I8 -> -0.10709708 | J17: =J15/J8 -> -0.091930619 | K17: -0.1 | L17: =K17 -> -0.1 | M17: =L17 -> -0.1 | N17: =M17 -> -0.1 | O17: =N17 -> -0.1 | P17: =O17 -> -0.1 | Q17: =P17 -> -0.1 | R17: =Q17 -> -0.1 | S17: =R17 -> -0.1 | ... U17: =T17 -> -0.1
C18: (+/-) Resultado de Equivalência Patrimonial | I18: 91.328 | J18: 200.847 | K18: =K20*K8 -> 198.36311 | L18: =L20*L8 -> 203.33727 | M18: =M20*M8 -> 207.81069 | N18: =N20*N8 -> 212.69424 | O18: =O20*O8 -> 218.0116 | P18: =P20*P8 -> 223.13487 | Q18: =Q20*Q8 -> 228.49011 | R18: =R20*R8 -> 234.08811 | ... U18: =U20*U8 -> 252.26453
C19: Var. % YoY | J19: =J18/I18-1 -> 1.1991832 | K19: =K18/J18-1 -> -0.012367054 | L19: =L18/K18-1 -> 0.025076008 | M19: =M18/L18-1 -> 0.022 | N19: =N18/M18-1 -> 0.0235 | O19: =O18/N18-1 -> 0.025 | P19: =P18/O18-1 -> 0.0235 | Q19: =Q18/P18-1 -> 0.024 | ... U19: =U18/T18-1 -> 0.025481122
C20: % Receita Líquida | I20: =I18/I8 -> 0.021457996 | J20: =J18/J8 -> 0.046304442 | K20: 0.045 | L20: =K20 -> 0.045 | M20: =L20 -> 0.045 | N20: =M20 -> 0.045 | O20: =N20 -> 0.045 | P20: =O20 -> 0.045 | Q20: =P20 -> 0.045 | R20: =Q20 -> 0.045 | S20: =R20 -> 0.045 | ... U20: =T20 -> 0.045
C21: (=) EBITDA | I21: =I13+I15+I18 -> 564.021 | J21: =J13+J15+J18 -> 682.931 | K21: =K13+K15+K18 -> 652.7164 | L21: =L13+L15+L18 -> 669.08392 | M21: =M13+M15+M18 -> 683.80377 | N21: =N13+N15+N18 -> 699.87316 | O21: =O13+O15+O18 -> 717.36999 | P21: =P13+P15+P18 -> 734.22818 | ... U21: =U13+U15+U18 -> 830.07971
C22: % Margem EBITDA | I22: =I21/I8 -> 0.13251971 | J22: =J21/J8 -> 0.15744691 | K22: =K21/K8 -> 0.14807308 | L22: =L21/L8 -> 0.14807308 | M22: =M21/M8 -> 0.14807308 | N22: =N21/N8 -> 0.14807308 | O22: =O21/O8 -> 0.14807308 | P22: =P21/P8 -> 0.14807308 | ... U22: =U21/U8 -> 0.14807308
C23: Var. % YoY | J23: =J21/I21-1 -> 0.21082548 | K23: =K21/J21-1 -> -0.044242534 | L23: =L21/K21-1 -> 0.025076008 | M23: =M21/L21-1 -> 0.022 | N23: =N21/M21-1 -> 0.0235 | O23: =O21/N21-1 -> 0.025 | P23: =P21/O21-1 -> 0.0235 | Q23: =Q21/P21-1 -> 0.024 | ... U23: =U21/T21-1 -> 0.025481122
C24: (-) Depreciação e Amortização | I24: -75.428 | J24: -67.101 | K24: =K50 -> -84.967877 | L24: =L50 -> -103.28278 | M24: =M50 -> -122.00062 | N24: =N50 -> -141.15832 | O24: =O50 -> -160.79497 | P24: =P50 -> -180.89307 | Q24: =Q50 -> -201.47354 | R24: =R50 -> -222.55822 | ... U24: =U50 -> -289.04915
C26: (=) EBIT | I26: =I21+I24 -> 488.593 | J26: =J21+J24 -> 615.83 | K26: =K21+K24 -> 567.74853 | L26: =L21+L24 -> 565.80114 | M26: =M21+M24 -> 561.80315 | N26: =N21+N24 -> 558.71484 | O26: =O21+O24 -> 556.57502 | P26: =P21+P24 -> 553.33511 | ... U26: =U21+U24 -> 541.03056
C27: % Margem EBIT | I27: =I26/I8 -> 0.11479751 | J27: =J26/J8 -> 0.14197705 | K27: =K26/K8 -> 0.12879755 | L27: =L26/L8 -> 0.12521586 | M27: =M26/M8 -> 0.12165467 | N27: =N26/N8 -> 0.11820803 | O27: =O26/O8 -> 0.11488323 | P27: =P26/P8 -> 0.11159206 | ... U27: =U26/U8 -> 0.09651129
C29: (+/-) Resultado Financeiro | I29: =I30+I31+I32 -> -24.2543 | J29: =J30+J31+J32 -> -77.075 | K29: =K30+K31+K32 -> 58.453055 | L29: =L30+L31+L32 -> 78.832877 | M29: =M30+M31+M32 -> 80.98922 | N29: =N30+N31+N32 -> 69.220981 | O29: =O30+O31+O32 -> 58.090226 | P29: =P30+P31+P32 -> 51.747597 | ... U29: =U30+U31+U32 -> 117.19844
C30: Receitas Financeiras | I30: 175.042 | J30: 53.319 | K30: =K199 -> 106.0201 | L30: =L199 -> 96.892115 | M30: =M199 -> 97.806867 | N30: =N199 -> 81.703964 | O30: =O199 -> 65.935942 | P30: =P199 -> 57.008614 | Q30: =Q199 -> 60.028424 | R30: =R199 -> 69.728436 | ... U30: =U199 -> 117.19844
C31: Despesas Financeiras | I31: -153.538 | J31: -78.84 | K31: =K162+K189+K171 -> -23.298464 | L31: =L162+L189+L171 -> -16.049077 | M31: =M162+M189+M171 -> -15.92556 | N31: =N162+N189+N171 -> -11.447976 | O31: =O162+O189+O171 -> -7.5268177 | P31: =P162+P189+P171 -> -5.2610167 | Q31: =Q162+Q189+Q171 -> -2.0053154 | R31: =R162+R189+R171 -> 0 | ... U31: =U162+U189+U171 -> 0
C32: Variação Cambial, líquida | I32: -45.7583 | J32: -51.554 | K32: =-K187 -> -24.268584 | L32: =-L187 -> -2.0101605 | M32: =-M187 -> -0.89208718 | N32: =-N187 -> -1.0350076 | O32: =-O187 -> -0.31889832 | P32: =-P187 -> 0 | Q32: =-Q187 -> 0 | R32: =-R187 -> 0 | ... U32: =-U187 -> 0
C33: (=) EBT | I33: =I26+I29 -> 464.3387 | J33: =J26+J29 -> 538.755 | K33: =K26+K29 -> 626.20158 | L33: =L26+L29 -> 644.63402 | M33: =M26+M29 -> 642.79237 | N33: =N26+N29 -> 627.93582 | O33: =O26+O29 -> 614.66525 | P33: =P26+P29 -> 605.0827 | ... U33: =U26+U29 -> 658.229
C34: (-) Imposto de Renda e Contribuição Social sobre o Lucro | I34: =I36+I38 -> -100.146 | J34: =J36+J38 -> -142.476 | K34: =K36+K38 -> -176.55039 | L34: =L36+L38 -> -181.1585 | M34: =M36+M38 -> -180.69809 | N34: =N36+N38 -> -176.98395 | O34: =O36+O38 -> -173.66631 | P34: =P36+P38 -> -171.27068 | ... U34: =U36+U38 -> -184.55725
C35: % EBT | I35: =I34/I33 -> -0.21567446 | J35: =J34/J33 -> -0.26445416 | K35: =K34/K33 -> -0.2819386 | L35: =L34/L33 -> -0.28102536 | M35: =M34/M33 -> -0.28111425 | N35: =N34/N33 -> -0.28185039 | O35: =O34/O33 -> -0.28253804 | P35: =P34/P33 -> -0.28305333 | ... U35: =U34/U33 -> -0.28038456
C36: Corrente | I36: -108.324 | J36: -107.994 | K36: =K37*K33 -> -156.55039 | L36: =L37*L33 -> -161.1585 | M36: =M37*M33 -> -160.69809 | N36: =N37*N33 -> -156.98395 | O36: =O37*O33 -> -153.66631 | P36: =P37*P33 -> -151.27068 | Q36: =Q37*Q33 -> -152.09981 | R36: =R37*R33 -> -154.36005 | ... U36: =U37*U33 -> -164.55725
C37: % EBT | I37: =I36/I33 -> -0.23328661 | J37: =J36/J33 -> -0.20045104 | K37: -0.25 | L37: =K37 -> -0.25 | M37: =L37 -> -0.25 | N37: =M37 -> -0.25 | O37: =N37 -> -0.25 | P37: =O37 -> -0.25 | Q37: =P37 -> -0.25 | R37: =Q37 -> -0.25 | S37: =R37 -> -0.25 | ... U37: =T37 -> -0.25
C38: Diferido | I38: 8.178 | J38: -34.482 | K38: -20 | L38: -20 | M38: -20 | N38: -20 | O38: -20 | P38: -20 | Q38: -20 | R38: -20 | S38: -20 | T38: -20 | U38: -20
C39: (=) Lucro/Prejuízo do Período | I39: =I33+I34 -> 364.1927 | J39: =J33+J34 -> 396.279 | K39: =K33+K34 -> 449.65118 | L39: =L33+L34 -> 463.47551 | M39: =M33+M34 -> 462.09428 | N39: =N33+N34 -> 450.95186 | O39: =O33+O34 -> 440.99893 | P39: =P33+P34 -> 433.81203 | ... U39: =U33+U34 -> 473.67175
C40: % Receita Líquida | I40: =I39/I8 -> 0.085568999 | J40: =J39/J8 -> 0.091360479 | K40: =K39/K8 -> 0.10200638 | L40: =L39/L8 -> 0.10257046 | M40: =M39/M8 -> 0.10006339 | N40: =N39/N8 -> 0.095408478 | O40: =O39/O8 -> 0.091027048 | P40: =P39/P8 -> 0.087487632 | ... U40: =U39/U8 -> 0.084495544
B42: Mutações PL
C43: (-) Reserva Legal | D43: 0.05 | I43: =I39*5% -> 18.209635 | J43: =J39*5% -> 19.81395 | K43: =K39*5% -> 22.482559 | L43: =L39*5% -> 23.173776 | M43: =M39*5% -> 23.104714 | N43: =N39*5% -> 22.547593 | O43: =O39*5% -> 22.049947 | P43: =P39*5% -> 21.690601 | ... U43: =U39*5% -> 23.683587
C44: (-) Dividendos a pagar | I44: =250+I91 -> 256.742 | J44: =99.281+J91 -> 100.858 | K44: =MAX(0,(K39-K43)*K45) -> 106.79216 | L44: =MAX(0,(L39-L43)*L45) -> 110.07543 | M44: =MAX(0,(M39-M43)*M45) -> 109.74739 | N44: =MAX(0,(N39-N43)*N45) -> 107.10107 | O44: =MAX(0,(O39-O43)*O45) -> 104.73725 | P44: =MAX(0,(P39-P43)*P45) -> 103.03036 | Q44: =MAX(0,(Q39-Q43)*Q45) -> 103.62111 | R44: =MAX(0,(R39-R43)*R45) -> 105.23153 | ... U44: =MAX(0,(U39-U43)*U45) -> 112.49704
...

Sheet Financiamentos

Sheet DIVIDA AGPar
F1: LEGENDA:
B2: MODELO DE DÍVIDA | F2: Dados Realizados Inputados | I2: VICTOR LOPES SCHMUTZLER
F3: Dados Realizados Calculados | I3: +55 (11) 3553-2529
F4: Dados Projetados Inputados
B5: 1. RESUMO FINANCIAMENTOS | F5: Dados Projetados Calculados
B7: CONSOLIDADO ANUAL | D7: 2009 | E7: 2010 | F7: 2011 | G7: =F7+1 -> 2012 | H7: =G7+1 -> 2013 | I7: =H7+1 -> 2014 | J7: =I7+1 -> 2015 | K7: =J7+1 -> 2016 | L7: =K7+1 -> 2017 | M7: =L7+1 -> 2018 | N7: =M7+1 -> 2019 | ... AD7: =AC7+1 -> 2035
B9: Empréstimos e financiamentos
B10: Saldo inicial (Balanço)
B11: Novo funding (Caixa)
B12: Juros apropriados (DRE)
B13: Juros pagos (Caixa)
B14: Amortização principal (Caixa)
B15: Saldo final (Balanço)
B16: Saldo Curto Prazo (Balanço)
B17: Saldo Longo Prazo (Balanço)
B19: Debêntures
A20: 15 | B20: Saldo inicial (Balanço) | F20: 0 | G20: =F26 -> 200106.7 | H20: =G26 -> 1083015.9 | I20: =H26 -> 1123739.6 | J20: =I26 -> 1125126.4 | K20: =J26 -> 1123980.6 | L20: =K26 -> 983488.94 | M20: =L26 -> 842126.91 | N20: =M26 -> 700974.25 | ... AD20: =AC26 -> 0
A21: 16 | B21: Novo funding (Caixa) | G21: =SUMIF($E$83:$GQ$83,G$7,$E97:$GQ97)+SUMIF($E$113:$GQ$113,G$7,$E127:$GQ127)+SUMIF($E$53:$GQ$53,G$7,$E67:$GQ67)+SUMIF($E$143:$GQ$143,G$7,$E157:$GQ157)+SUMIF($E$173:$GQ$173,G$7,$E187:$GQ187) -> 903512.21 | H21: =SUMIF($E$83:$GQ$83,H$7,$E97:$GQ97)+SUMIF($E$113:$GQ$113,H$7,$E127:$GQ127)+SUMIF($E$53:$GQ$53,H$7,$E67:$GQ67)+SUMIF($E$143:$GQ$143,H$7,$E157:$GQ157)+SUMIF($E$173:$GQ$173,H$7,$E187:$GQ187) -> 0 | I21: =SUMIF($E$83:$GQ$83,I$7,$E97:$GQ97)+SUMIF($E$113:$GQ$113,I$7,$E127:$GQ127)+SUMIF($E$53:$GQ$53,I$7,$E67:$GQ67)+SUMIF($E$143:$GQ$143,I$7,$E157:$GQ157)+SUMIF($E$173:$GQ$173,I$7,$E187:$GQ187) -> 0 | J21: =SUMIF($E$83:$GQ$83,J$7,$E97:$GQ97)+SUMIF($E$113:$GQ$113,J$7,$E127:$GQ127)+SUMIF($E$53:$GQ$53,J$7,$E67:$GQ67)+SUMIF($E$143:$GQ$143,J$7,$E157:$GQ157)+SUMIF($E$173:$GQ$173,J$7,$E187:$GQ187) -> 0 | K21: =SUMIF($E$83:$GQ$83,K$7,$E97:$GQ97)+SUMIF($E$113:$GQ$113,K$7,$E127:$GQ127)+SUMIF($E$53:$GQ$53,K$7,$E67:$GQ67)+SUMIF($E$143:$GQ$143,K$7,$E157:$GQ157)+SUMIF($E$173:$GQ$173,K$7,$E187:$GQ187) -> 0 | L21: =SUMIF($E$83:$GQ$83,L$7,$E97:$GQ97)+SUMIF($E$113:$GQ$113,L$7,$E127:$GQ127)+SUMIF($E$53:$GQ$53,L$7,$E67:$GQ67)+SUMIF($E$143:$GQ$143,L$7,$E157:$GQ157)+SUMIF($E$173:$GQ$173,L$7,$E187:$GQ187) -> 0 | M21: =SUMIF($E$83:$GQ$83,M$7,$E97:$GQ97)+SUMIF($E$113:$GQ$113,M$7,$E127:$GQ127)+SUMIF($E$53:$GQ$53,M$7,$E67:$GQ67)+SUMIF($E$143:$GQ$143,M$7,$E157:$GQ157)+SUMIF($E$173:$GQ$173,M$7,$E187:$GQ187) -> 0 | N21: =SUMIF($E$83:$GQ$83,N$7,$E97:$GQ97)+SUMIF($E$113:$GQ$113,N$7,$E127:$GQ127)+SUMIF($E$53:$GQ$53,N$7,$E67:$GQ67)+SUMIF($E$143:$GQ$143,N$7,$E157:$GQ157)+SUMIF($E$173:$GQ$173,N$7,$E187:$GQ187) -> 0 | ... AD21: =SUMIF($E$83:$GQ$83,AD$7,$E97:$GQ97)+SUMIF($E$113:$GQ$113,AD$7,$E127:$GQ127)+SUMIF($E$53:$GQ$53,AD$7,$E67:$GQ67)+SUMIF($E$143:$GQ$143,AD$7,$E157:$GQ157)+SUMIF($E$173:$GQ$173,AD$7,$E187:$GQ187) -> 0
A22: 17 | B22: Correção Monetária IPCA | G22: =SUMIF($E$83:$GQ$83,G$7,$E98:$GQ98)+SUMIF($E$113:$GQ$113,G$7,$E128:$GQ128)+SUMIF($E$53:$GQ$53,G$7,$E68:$GQ68)+SUMIF($E$143:$GQ$143,G$7,$E158:$GQ158)+SUMIF($E$173:$GQ$173,G$7,$E188:$GQ188) -> 7060.0664 | H22: =SUMIF($E$83:$GQ$83,H$7,$E98:$GQ98)+SUMIF($E$113:$GQ$113,H$7,$E128:$GQ128)+SUMIF($E$53:$GQ$53,H$7,$E68:$GQ68)+SUMIF($E$143:$GQ$143,H$7,$E158:$GQ158)+SUMIF($E$173:$GQ$173,H$7,$E188:$GQ188) -> 16631.86 | I22: =SUMIF($E$83:$GQ$83,I$7,$E98:$GQ98)+SUMIF($E$113:$GQ$113,I$7,$E128:$GQ128)+SUMIF($E$53:$GQ$53,I$7,$E68:$GQ68)+SUMIF($E$143:$GQ$143,I$7,$E158:$GQ158)+SUMIF($E$173:$GQ$173,I$7,$E188:$GQ188) -> 13066.137 | J22: =SUMIF($E$83:$GQ$83,J$7,$E98:$GQ98)+SUMIF($E$113:$GQ$113,J$7,$E128:$GQ128)+SUMIF($E$53:$GQ$53,J$7,$E68:$GQ68)+SUMIF($E$143:$GQ$143,J$7,$E158:$GQ158)+SUMIF($E$173:$GQ$173,J$7,$E188:$GQ188) -> 13654.113 | K22: =SUMIF($E$83:$GQ$83,K$7,$E98:$GQ98)+SUMIF($E$113:$GQ$113,K$7,$E128:$GQ128)+SUMIF($E$53:$GQ$53,K$7,$E68:$GQ68)+SUMIF($E$143:$GQ$143,K$7,$E158:$GQ158)+SUMIF($E$173:$GQ$173,K$7,$E188:$GQ188) -> 14268.548 | L22: =SUMIF($E$83:$GQ$83,L$7,$E98:$GQ98)+SUMIF($E$113:$GQ$113,L$7,$E128:$GQ128)+SUMIF($E$53:$GQ$53,L$7,$E68:$GQ68)+SUMIF($E$143:$GQ$143,L$7,$E158:$GQ158)+SUMIF($E$173:$GQ$173,L$7,$E188:$GQ188) -> 13253.896 | M22: =SUMIF($E$83:$GQ$83,M$7,$E98:$GQ98)+SUMIF($E$113:$GQ$113,M$7,$E128:$GQ128)+SUMIF($E$53:$GQ$53,M$7,$E68:$GQ68)+SUMIF($E$143:$GQ$143,M$7,$E158:$GQ158)+SUMIF($E$173:$GQ$173,M$7,$E188:$GQ188) -> 13784.051 | N22: =SUMIF($E$83:$GQ$83,N$7,$E98:$GQ98)+SUMIF($E$113:$GQ$113,N$7,$E128:$GQ128)+SUMIF($E$53:$GQ$53,N$7,$E68:$GQ68)+SUMIF($E$143:$GQ$143,N$7,$E158:$GQ158)+SUMIF($E$173:$GQ$173,N$7,$E188:$GQ188) -> 14335.414 | ... AD22: =SUMIF($E$83:$GQ$83,AD$7,$E98:$GQ98)+SUMIF($E$113:$GQ$113,AD$7,$E128:$GQ128)+SUMIF($E$53:$GQ$53,AD$7,$E68:$GQ68)+SUMIF($E$143:$GQ$143,AD$7,$E158:$GQ158)+SUMIF($E$173:$GQ$173,AD$7,$E188:$GQ188) -> 0
A23: 18 | B23: Juros apropriados (DRE) | G23: =SUMIF($E$83:$GQ$83,G$7,$E99:$GQ99)+SUMIF($E$113:$GQ$113,G$7,$E129:$GQ129)+SUMIF($E$53:$GQ$53,G$7,$E69:$GQ69)+SUMIF($E$143:$GQ$143,G$7,$E159:$GQ159)+SUMIF($E$173:$GQ$173,G$7,$E189:$GQ189) -> 45046.256 | H23: =SUMIF($E$83:$GQ$83,H$7,$E99:$GQ99)+SUMIF($E$113:$GQ$113,H$7,$E129:$GQ129)+SUMIF($E$53:$GQ$53,H$7,$E69:$GQ69)+SUMIF($E$143:$GQ$143,H$7,$E159:$GQ159)+SUMIF($E$173:$GQ$173,H$7,$E189:$GQ189) -> 72825.801 | I23: =SUMIF($E$83:$GQ$83,I$7,$E99:$GQ99)+SUMIF($E$113:$GQ$113,I$7,$E129:$GQ129)+SUMIF($E$53:$GQ$53,I$7,$E69:$GQ69)+SUMIF($E$143:$GQ$143,I$7,$E159:$GQ159)+SUMIF($E$173:$GQ$173,I$7,$E189:$GQ189) -> 81286.403 | J23: =SUMIF($E$83:$GQ$83,J$7,$E99:$GQ99)+SUMIF($E$113:$GQ$113,J$7,$E129:$GQ129)+SUMIF($E$53:$GQ$53,J$7,$E69:$GQ69)+SUMIF($E$143:$GQ$143,J$7,$E159:$GQ159)+SUMIF($E$173:$GQ$173,J$7,$E189:$GQ189) -> 81570.32 | K23: =SUMIF($E$83:$GQ$83,K$7,$E99:$GQ99)+SUMIF($E$113:$GQ$113,K$7,$E129:$GQ129)+SUMIF($E$53:$GQ$53,K$7,$E69:$GQ69)+SUMIF($E$143:$GQ$143,K$7,$E159:$GQ159)+SUMIF($E$173:$GQ$173,K$7,$E189:$GQ189) -> 76141.744 | L23: =SUMIF($E$83:$GQ$83,L$7,$E99:$GQ99)+SUMIF($E$113:$GQ$113,L$7,$E129:$GQ129)+SUMIF($E$53:$GQ$53,L$7,$E69:$GQ69)+SUMIF($E$143:$GQ$143,L$7,$E159:$GQ159)+SUMIF($E$173:$GQ$173,L$7,$E189:$GQ189) -> 62358.75 | M23: =SUMIF($E$83:$GQ$83,M$7,$E99:$GQ99)+SUMIF($E$113:$GQ$113,M$7,$E129:$GQ129)+SUMIF($E$53:$GQ$53,M$7,$E69:$GQ69)+SUMIF($E$143:$GQ$143,M$7,$E159:$GQ159)+SUMIF($E$173:$GQ$173,M$7,$E189:$GQ189) -> 47881.463 | N23: =SUMIF($E$83:$GQ$83,N$7,$E99:$GQ99)+SUMIF($E$113:$GQ$113,N$7,$E129:$GQ129)+SUMIF($E$53:$GQ$53,N$7,$E69:$GQ69)+SUMIF($E$143:$GQ$143,N$7,$E159:$GQ159)+SUMIF($E$173:$GQ$173,N$7,$E189:$GQ189) -> 34067.337 | ... AD23: =SUMIF($E$83:$GQ$83,AD$7,$E99:$GQ99)+SUMIF($E$113:$GQ$113,AD$7,$E129:$GQ129)+SUMIF($E$53:$GQ$53,AD$7,$E69:$GQ69)+SUMIF($E$143:$GQ$143,AD$7,$E159:$GQ159)+SUMIF($E$173:$GQ$173,AD$7,$E189:$GQ189) -> 0
A24: 19 | B24: Juros pagos (Caixa) | G24: =SUMIF($E$83:$GQ$83,G$7,$E100:$GQ100)+SUMIF($E$113:$GQ$113,G$7,$E130:$GQ130)+SUMIF($E$53:$GQ$53,G$7,$E70:$GQ70)+SUMIF($E$143:$GQ$143,G$7,$E160:$GQ160)+SUMIF($E$173:$GQ$173,G$7,$E190:$GQ190) -> -32514.617 | H24: =SUMIF($E$83:$GQ$83,H$7,$E100:$GQ100)+SUMIF($E$113:$GQ$113,H$7,$E130:$GQ130)+SUMIF($E$53:$GQ$53,H$7,$E70:$GQ70)+SUMIF($E$143:$GQ$143,H$7,$E160:$GQ160)+SUMIF($E$173:$GQ$173,H$7,$E190:$GQ190) -> -48733.949 | I24: =SUMIF($E$83:$GQ$83,I$7,$E100:$GQ100)+SUMIF($E$113:$GQ$113,I$7,$E130:$GQ130)+SUMIF($E$53:$GQ$53,I$7,$E70:$GQ70)+SUMIF($E$143:$GQ$143,I$7,$E160:$GQ160)+SUMIF($E$173:$GQ$173,I$7,$E190:$GQ190) -> -78331.056 | J24: =SUMIF($E$83:$GQ$83,J$7,$E100:$GQ100)+SUMIF($E$113:$GQ$113,J$7,$E130:$GQ130)+SUMIF($E$53:$GQ$53,J$7,$E70:$GQ70)+SUMIF($E$143:$GQ$143,J$7,$E160:$GQ160)+SUMIF($E$173:$GQ$173,J$7,$E190:$GQ190) -> -81735.622 | K24: =SUMIF($E$83:$GQ$83,K$7,$E100:$GQ100)+SUMIF($E$113:$GQ$113,K$7,$E130:$GQ130)+SUMIF($E$53:$GQ$53,K$7,$E70:$GQ70)+SUMIF($E$143:$GQ$143,K$7,$E160:$GQ160)+SUMIF($E$173:$GQ$173,K$7,$E190:$GQ190) -> -82933.906 | L24: =SUMIF($E$83:$GQ$83,L$7,$E100:$GQ100)+SUMIF($E$113:$GQ$113,L$7,$E130:$GQ130)+SUMIF($E$53:$GQ$53,L$7,$E70:$GQ70)+SUMIF($E$143:$GQ$143,L$7,$E160:$GQ160)+SUMIF($E$173:$GQ$173,L$7,$E190:$GQ190) -> -69006.661 | M24: =SUMIF($E$83:$GQ$83,M$7,$E100:$GQ100)+SUMIF($E$113:$GQ$113,M$7,$E130:$GQ130)+SUMIF($E$53:$GQ$53,M$7,$E70:$GQ70)+SUMIF($E$143:$GQ$143,M$7,$E160:$GQ160)+SUMIF($E$173:$GQ$173,M$7,$E190:$GQ190) -> -54850.162 | N24: =SUMIF($E$83:$GQ$83,N$7,$E100:$GQ100)+SUMIF($E$113:$GQ$113,N$7,$E130:$GQ130)+SUMIF($E$53:$GQ$53,N$7,$E70:$GQ70)+SUMIF($E$143:$GQ$143,N$7,$E160:$GQ160)+SUMIF($E$173:$GQ$173,N$7,$E190:$GQ190) -> -40709.883 | ... AD24: =SUMIF($E$83:$GQ$83,AD$7,$E100:$GQ100)+SUMIF($E$113:$GQ$113,AD$7,$E130:$GQ130)+SUMIF($E$53:$GQ$53,AD$7,$E70:$GQ70)+SUMIF($E$143:$GQ$143,AD$7,$E160:$GQ160)+SUMIF($E$173:$GQ$173,AD$7,$E190:$GQ190) -> 0
A25: 20 | B25: Amortização principal (Caixa) | G25: =SUMIF($E$83:$GQ$83,G$7,$E101:$GQ101)+SUMIF($E$113:$GQ$113,G$7,$E131:$GQ131)+SUMIF($E$53:$GQ$53,G$7,$E71:$GQ71)+SUMIF($E$143:$GQ$143,G$7,$E161:$GQ161)+SUMIF($E$173:$GQ$173,G$7,$E191:$GQ191) -> -40194.704 | H25: =SUMIF($E$83:$GQ$83,H$7,$E101:$GQ101)+SUMIF($E$113:$GQ$113,H$7,$E131:$GQ131)+SUMIF($E$53:$GQ$53,H$7,$E71:$GQ71)+SUMIF($E$143:$GQ$143,H$7,$E161:$GQ161)+SUMIF($E$173:$GQ$173,H$7,$E191:$GQ191) -> 0 | I25: =SUMIF($E$83:$GQ$83,I$7,$E101:$GQ101)+SUMIF($E$113:$GQ$113,I$7,$E131:$GQ131)+SUMIF($E$53:$GQ$53,I$7,$E71:$GQ71)+SUMIF($E$143:$GQ$143,I$7,$E161:$GQ161)+SUMIF($E$173:$GQ$173,I$7,$E191:$GQ191) -> -14634.678 | J25: =SUMIF($E$83:$GQ$83,J$7,$E101:$GQ101)+SUMIF($E$113:$GQ$113,J$7,$E131:$GQ131)+SUMIF($E$53:$GQ$53,J$7,$E71:$GQ71)+SUMIF($E$143:$GQ$143,J$7,$E161:$GQ161)+SUMIF($E$173:$GQ$173,J$7,$E191:$GQ191) -> -14634.678 | K25: =SUMIF($E$83:$GQ$83,K$7,$E101:$GQ101)+SUMIF($E$113:$GQ$113,K$7,$E131:$GQ131)+SUMIF($E$53:$GQ$53,K$7,$E71:$GQ71)+SUMIF($E$143:$GQ$143,K$7,$E161:$GQ161)+SUMIF($E$173:$GQ$173,K$7,$E191:$GQ191) -> -147968.01 | L25: =SUMIF($E$83:$GQ$83,L$7,$E101:$GQ101)+SUMIF($E$113:$GQ$113,L$7,$E131:$GQ131)+SUMIF($E$53:$GQ$53,L$7,$E71:$GQ71)+SUMIF($E$143:$GQ$143,L$7,$E161:$GQ161)+SUMIF($E$173:$GQ$173,L$7,$E191:$GQ191) -> -147968.01 | M25: =SUMIF($E$83:$GQ$83,M$7,$E101:$GQ101)+SUMIF($E$113:$GQ$113,M$7,$E131:$GQ131)+SUMIF($E$53:$GQ$53,M$7,$E71:$GQ71)+SUMIF($E$143:$GQ$143,M$7,$E161:$GQ161)+SUMIF($E$173:$GQ$173,M$7,$E191:$GQ191) -> -147968.01 | N25: =SUMIF($E$83:$GQ$83,N$7,$E101:$GQ101)+SUMIF($E$113:$GQ$113,N$7,$E131:$GQ131)+SUMIF($E$53:$GQ$53,N$7,$E71:$GQ71)+SUMIF($E$143:$GQ$143,N$7,$E161:$GQ161)+SUMIF($E$173:$GQ$173,N$7,$E191:$GQ191) -> -147968.01 | ... AD25: =SUMIF($E$83:$GQ$83,AD$7,$E101:$GQ101)+SUMIF($E$113:$GQ$113,AD$7,$E131:$GQ131)+SUMIF($E$53:$GQ$53,AD$7,$E71:$GQ71)+SUMIF($E$143:$GQ$143,AD$7,$E161:$GQ161)+SUMIF($E$173:$GQ$173,AD$7,$E191:$GQ191) -> 0
A26: 21 | B26: Saldo final (Balanço) | F26: =IFERROR(HLOOKUP(DATE(F7,12,1),$E$82:$AA$102,$A26,0),0)+IFERROR(HLOOKUP(DATE(F7,12,1),$E$112:$AA$132,$A26,0),0)+IFERROR(HLOOKUP(DATE(F7,12,1),$E$142:$AA$162,$A26,0),0)+IFERROR(HLOOKUP(DATE(F7,12,1),$E$172:$AA$192,$A26,0),0)+IFERROR(HLOOKUP(DATE(F7,12,1),$E$52:$AA$72,$A26,0),0) -> 200106.7 | G26: =IFERROR(HLOOKUP(DATE(G7,12,1),$E$82:$AC$102,$A26,0),0)+IFERROR(HLOOKUP(DATE(G7,12,1),$E$112:$GQ$132,$A26,0),0)+IFERROR(HLOOKUP(DATE(G7,12,1),$E$142:$GQ$162,$A26,0),0)+IFERROR(HLOOKUP(DATE(G7,12,1),$E$172:$GQ$192,$A26,0),0)+IFERROR(HLOOKUP(DATE(G7,12,1),$E$52:$AC$72,$A26,0),0) -> 1083015.9 | H26: =IFERROR(HLOOKUP(DATE(H7,12,1),$E$82:$AC$102,$A26,0),0)+IFERROR(HLOOKUP(DATE(H7,12,1),$E$112:$GQ$132,$A26,0),0)+IFERROR(HLOOKUP(DATE(H7,12,1),$E$142:$GQ$162,$A26,0),0)+IFERROR(HLOOKUP(DATE(H7,12,1),$E$172:$GQ$192,$A26,0),0)+IFERROR(HLOOKUP(DATE(H7,12,1),$E$52:$AC$72,$A26,0),0) -> 1123739.6 | I26: =IFERROR(HLOOKUP(DATE(I7,12,1),$E$82:$AC$102,$A26,0),0)+IFERROR(HLOOKUP(DATE(I7,12,1),$E$112:$GQ$132,$A26,0),0)+IFERROR(HLOOKUP(DATE(I7,12,1),$E$142:$GQ$162,$A26,0),0)+IFERROR(HLOOKUP(DATE(I7,12,1),$E$172:$GQ$192,$A26,0),0)+IFERROR(HLOOKUP(DATE(I7,12,1),$E$52:$AC$72,$A26,0),0) -> 1125126.4 | J26: =IFERROR(HLOOKUP(DATE(J7,12,1),$E$82:$AC$102,$A26,0),0)+IFERROR(HLOOKUP(DATE(J7,12,1),$E$112:$GQ$132,$A26,0),0)+IFERROR(HLOOKUP(DATE(J7,12,1),$E$142:$GQ$162,$A26,0),0)+IFERROR(HLOOKUP(DATE(J7,12,1),$E$172:$GQ$192,$A26,0),0)+IFERROR(HLOOKUP(DATE(J7,12,1),$E$52:$AC$72,$A26,0),0) -> 1123980.6 | K26: =IFERROR(HLOOKUP(DATE(K7,12,1),$E$82:$AC$102,$A26,0),0)+IFERROR(HLOOKUP(DATE(K7,12,1),$E$112:$GQ$132,$A26,0),0)+IFERROR(HLOOKUP(DATE(K7,12,1),$E$142:$GQ$162,$A26,0),0)+IFERROR(HLOOKUP(DATE(K7,12,1),$E$172:$GQ$192,$A26,0),0)+IFERROR(HLOOKUP(DATE(K7,12,1),$E$52:$AC$72,$A26,0),0) -> 983488.94 | L26: =IFERROR(HLOOKUP(DATE(L7,12,1),$E$82:$AC$102,$A26,0),0)+IFERROR(HLOOKUP(DATE(L7,12,1),$E$112:$GQ$132,$A26,0),0)+IFERROR(HLOOKUP(DATE(L7,12,1),$E$142:$GQ$162,$A26,0),0)+IFERROR(HLOOKUP(DATE(L7,12,1),$E$172:$GQ$192,$A26,0),0)+IFERROR(HLOOKUP(DATE(L7,12,1),$E$52:$AC$72,$A26,0),0) -> 842126.91 | M26: =IFERROR(HLOOKUP(DATE(M7,12,1),$E$82:$AC$102,$A26,0),0)+IFERROR(HLOOKUP(DATE(M7,12,1),$E$112:$GQ$132,$A26,0),0)+IFERROR(HLOOKUP(DATE(M7,12,1),$E$142:$GQ$162,$A26,0),0)+IFERROR(HLOOKUP(DATE(M7,12,1),$E$172:$GQ$192,$A26,0),0)+IFERROR(HLOOKUP(DATE(M7,12,1),$E$52:$AC$72,$A26,0),0) -> 700974.25 | N26: =IFERROR(HLOOKUP(DATE(N7,12,1),$E$82:$AC$102,$A26,0),0)+IFERROR(HLOOKUP(DATE(N7,12,1),$E$112:$GQ$132,$A26,0),0)+IFERROR(HLOOKUP(DATE(N7,12,1),$E$142:$GQ$162,$A26,0),0)+IFERROR(HLOOKUP(DATE(N7,12,1),$E$172:$GQ$192,$A26,0),0)+IFERROR(HLOOKUP(DATE(N7,12,1),$E$52:$AC$72,$A26,0),0) -> 560699.11 | ... AD26: =IFERROR(HLOOKUP(DATE(AD7,12,1),$E$82:$AC$102,$A26,0),0)+IFERROR(HLOOKUP(DATE(AD7,12,1),$E$112:$GQ$132,$A26,0),0)+IFERROR(HLOOKUP(DATE(AD7,12,1),$E$142:$GQ$162,$A26,0),0)+IFERROR(HLOOKUP(DATE(AD7,12,1),$E$172:$GQ$192,$A26,0),0)+IFERROR(HLOOKUP(DATE(AD7,12,1),$E$52:$AC$72,$A26,0),0) -> 0
B27: Saldo Curto Prazo (Balanço) | F27: =IF(F26>0,-SUM(G25),0) -> 40194.704 | G27: =IF(G26>0,-SUM(H25),0) -> 0 | H27: =IF(H26>0,-SUM(I25),0) -> 14634.678 | I27: =IF(I26>0,-SUM(J25),0) -> 14634.678 | J27: =IF(J26>0,-SUM(K25),0) -> 147968.01 | K27: =IF(K26>0,-SUM(L25:O25),0) -> 585226.74 | L27: =IF(L26>0,-SUM(M25:P25),0) -> 583648.95 | M27: =IF(M26>0,-SUM(N25:Q25),0) -> 587382.49 | N27: =IF(N26>0,-SUM(O25:R25),0) -> 454049.16 | O27: =IF(O26>0,-SUM(P25:S25),0) -> 327361.13 | P27: =IF(P26>0,-SUM(Q25:T25),0) -> 195605.59 | Q27: =IF(Q26>0,-SUM(R25:U25),0) -> 58538.713 | R27: =IF(R26>0,-SUM(S25:V25),0) -> 58538.713 | ... AD27: =IF(AD26>0,-SUM(AE25:AH25),0) -> 0
B28: Saldo Longo Prazo (Balanço) | F28: =ROUND(F26-F27+F30,8) -> 159912 | G28: =ROUND(G26-G27+G30,8) -> 1078498.4 | H28: =ROUND(H26-H27+H30,8) -> 1104838.4 | I28: =ROUND(I26-I27+I30,8) -> 1106476.1 | J28: =ROUND(J26-J27+J30,8) -> 972247.92 | K28: =ROUND(K26-K27+K30,8) -> 394748.55 | L28: =ROUND(L26-L27+L30,8) -> 255215.28 | M28: =ROUND(M26-M27+M30,8) -> 110580.06 | ... AB28: =ROUND(AB26-AB27+AB30,8) -> 0 | AC28: =ROUND(AC26-AC27,8) -> 0 | AD28: =ROUND(AD26-AD27,8) -> 0
B30: Custos das Transações | F30: 0 | G30: =-0.5%*(G21) -> -4517.5611 | H30: =G30+H31 -> -4266.5854 | I30: =H30+I31 -> -4015.6098 | J30: =I30+J31 -> -3764.6342 | K30: =J30+K31 -> -3513.6586 | L30: =K30+L31 -> -3262.683 | M30: =L30+M31 -> -3011.7074 | N30: =M30+N31 -> -2760.7318 | O30: =N30+O31 -> -2509.7561 | ... X30: =W30+X31 -> -250.97561 | Y30: 0
G31: =-F30/20 -> 0 | H31: =-G30/18 -> 250.97561 | I31: =H31 -> 250.97561 | J31: =I31 -> 250.97561 | K31: =J31 -> 250.97561 | L31: =K31 -> 250.97561 | M31: =L31 -> 250.97561 | N31: =M31 -> 250.97561 | O31: =N31 -> 250.97561 | P31: =O31 -> 250.97561 | ... Y31: =X31 -> 250.97561
B33: Dívida de Balanceamento
B34: Saldo Inicial | G34: =PROJ_AGCeAGPar!I320 -> 0 | H34: =PROJ_AGCeAGPar!J320 -> 0 | I34: =PROJ_AGCeAGPar!K320 -> 0 | J34: =PROJ_AGCeAGPar!L320 -> 0 | K34: =PROJ_AGCeAGPar!M320 -> 0 | L34: =PROJ_AGCeAGPar!N320 -> 0 | M34: =PROJ_AGCeAGPar!O320 -> 0 | N34: =PROJ_AGCeAGPar!P320 -> 0 | ... AA34: =PROJ_AGCeAGPar!AC320 -> 0
B35: Adição | G35: =MAX(0,G39-G34) -> 0 | H35: =MAX(0,H39-H34) -> 0 | I35: =MAX(0,I39-I34) -> 0 | J35: =MAX(0,J39-J34) -> 0 | K35: =MAX(0,K39-K34) -> 0 | L35: =MAX(0,L39-L34) -> 0 | M35: =MAX(0,M39-M34) -> 0 | N35: =MAX(0,N39-N34) -> 0 | ... Y35: =MAX(0,Y39-Y34) -> 0 | Z35: =Z39-Z34 -> 0 | AA35: =AA39-AA34 -> 0
B36: Amortização | G36: =MIN(0,G39-G34) -> 0 | H36: =MIN(0,H39-H34) -> 0 | I36: =MIN(0,I39-I34) -> 0 | J36: =MIN(0,J39-J34) -> 0 | K36: =MIN(0,K39-K34) -> 0 | L36: =MIN(0,L39-L34) -> 0 | M36: =MIN(0,M39-M34) -> 0 | N36: =MIN(0,N39-N34) -> 0 | ... Y36: =MIN(0,Y39-Y34) -> 0 | Z36: =Z39-Z34 -> 0 | AA36: =AA39-AA34 -> 0
B37: Juros no Período | C37: % CDI | G37: =-G38*(G34) -> 0 | H37: =-H38*(H34) -> 0 | I37: =-I38*(I34) -> 0 | J37: =-J38*(J34) -> 0 | K37: =-K38*(K34) -> 0 | L37: =-L38*(L34) -> 0 | M37: =-M38*(M34) -> 0 | N37: =-N38*(N34) -> 0 | ... AA37: =-AA38*(AA34) -> 0
B38: Custo médio da Dívida | C38: 1 | G38: =$C$38*HLOOKUP(G$7,Macroeconomics!$B$5:$GB$36,Macroeconomics!$A$24,0) -> 0.087560431 | H38: =$C$38*HLOOKUP(H$7,Macroeconomics!$B$5:$GB$36,Macroeconomics!$A$24,0) -> 0.084449317 | I38: =$C$38*HLOOKUP(I$7,Macroeconomics!$B$5:$GB$36,Macroeconomics!$A$24,0) -> 0.096145243 | J38: =$C$38*HLOOKUP(J$7,Macroeconomics!$B$5:$GB$36,Macroeconomics!$A$24,0) -> 0.094942253 | K38: =$C$38*HLOOKUP(K$7,Macroeconomics!$B$5:$GB$36,Macroeconomics!$A$24,0) -> 0.0967 | L38: =$C$38*HLOOKUP(L$7,Macroeconomics!$B$5:$GB$36,Macroeconomics!$A$24,0) -> 0.0967 | M38: =$C$38*HLOOKUP(M$7,Macroeconomics!$B$5:$GB$36,Macroeconomics!$A$24,0) -> 0.0943 | N38: =$C$38*HLOOKUP(N$7,Macroeconomics!$B$5:$GB$36,Macroeconomics!$A$24,0) -> 0.0942 | ... AA38: =$C$38*HLOOKUP(AA$7,Macroeconomics!$B$5:$GB$36,Macroeconomics!$A$24,0) -> 0.0893
B39: Saldo Final | G39: =PROJ_AGCeAGPar!J320 -> 0 | H39: =PROJ_AGCeAGPar!K320 -> 0 | I39: =PROJ_AGCeAGPar!L320 -> 0 | J39: =PROJ_AGCeAGPar!M320 -> 0 | K39: =PROJ_AGCeAGPar!N320 -> 0 | L39: =PROJ_AGCeAGPar!O320 -> 0 | M39: =PROJ_AGCeAGPar!P320 -> 0 | N39: =PROJ_AGCeAGPar!Q320 -> 0 | ... AA39: =PROJ_AGCeAGPar!AD320 -> 0
B41: Receita Financeira
B42: Caixa+AFI+Mútuos Inicial | D42: =PROJ_AGCeAGPar!G305+PROJ_AGCeAGPar!G306+PROJ_AGCeAGPar!G307*20%+PROJ_AGCeAGPar!G312 -> 273.6552 | E42: =PROJ_AGCeAGPar!H305+PROJ_AGCeAGPar!H306+PROJ_AGCeAGPar!H307*20%+PROJ_AGCeAGPar!H312 -> 574.6262 | F42: =PROJ_AGCeAGPar!I305+PROJ_AGCeAGPar!I306+PROJ_AGCeAGPar!I307*20%+PROJ_AGCeAGPar!I312 -> 51.3862 | G42: =PROJ_AGCeAGPar!J305+PROJ_AGCeAGPar!J306+PROJ_AGCeAGPar!J307*20%+PROJ_AGCeAGPar!J312 -> 13.444 | H42: =PROJ_AGCeAGPar!K305+PROJ_AGCeAGPar!K306+PROJ_AGCeAGPar!K307*20%+PROJ_AGCeAGPar!K312 -> 606.33932 | I42: =PROJ_AGCeAGPar!L305+PROJ_AGCeAGPar!L306+PROJ_AGCeAGPar!L307*20%+PROJ_AGCeAGPar!L312 -> 582.39049 | J42: =PROJ_AGCeAGPar!M305+PROJ_AGCeAGPar!M306+PROJ_AGCeAGPar!M307*20%+PROJ_AGCeAGPar!M312 -> 843.33904 | K42: =PROJ_AGCeAGPar!N305+PROJ_AGCeAGPar!N306+PROJ_AGCeAGPar!N307*20%+PROJ_AGCeAGPar!N312 -> 1096.2916 | ... Y42: =PROJ_AGCeAGPar!AB305+PROJ_AGCeAGPar!AB306+PROJ_AGCeAGPar!AB307*20%+PROJ_AGCeAGPar!AB312 -> 0
B43: Caixa+AFI+Mútuos Final | D43: =PROJ_AGCeAGPar!H305+PROJ_AGCeAGPar!H306+PROJ_AGCeAGPar!H307*20%+PROJ_AGCeAGPar!H312 -> 574.6262 | E43: =PROJ_AGCeAGPar!I305+PROJ_AGCeAGPar!I306+PROJ_AGCeAGPar!I307*20%+PROJ_AGCeAGPar!I312 -> 51.3862 | F43: =PROJ_AGCeAGPar!J305+PROJ_AGCeAGPar!J306+PROJ_AGCeAGPar!J307*20%+PROJ_AGCeAGPar!J312 -> 13.444 | G43: =PROJ_AGCeAGPar!K305+PROJ_AGCeAGPar!K306+PROJ_AGCeAGPar!K307*20%+PROJ_AGCeAGPar!K312 -> 606.33932 | H43: =PROJ_AGCeAGPar!L305+PROJ_AGCeAGPar!L306+PROJ_AGCeAGPar!L307*20%+PROJ_AGCeAGPar!L312 -> 582.39049 | I43: =PROJ_AGCeAGPar!M305+PROJ_AGCeAGPar!M306+PROJ_AGCeAGPar!M307*20%+PROJ_AGCeAGPar!M312 -> 843.33904 | J43: =PROJ_AGCeAGPar!N305+PROJ_AGCeAGPar!N306+PROJ_AGCeAGPar!N307*20%+PROJ_AGCeAGPar!N312 -> 1096.2916 | K43: =PROJ_AGCeAGPar!O305+PROJ_AGCeAGPar!O306+PROJ_AGCeAGPar!O307*20%+PROJ_AGCeAGPar!O312 -> 1246.6281 | ... Y43: =PROJ_AGCeAGPar!AC305+PROJ_AGCeAGPar!AC306+PROJ_AGCeAGPar!AC307*20%+PROJ_AGCeAGPar!AC312 -> 0
B44: Saldo Médio | D44: =(D42+D43)/2 -> 424.1407 | E44: =(E42+E43)/2 -> 313.0062 | F44: =(F42+F43)/2 -> 32.4151 | G44: =(G42+G43)/2 -> 309.89166 | H44: =(H42+H43)/2 -> 594.3649 | I44: =(I42+I43)/2 -> 712.86476 | J44: =(J42+J43)/2 -> 969.81534 | K44: =(K42+K43)/2 -> 1171.4599 | ... Y44: =(Y42+Y43)/2 -> 0
B45: Receita Financeiras (% CDI) | C45: 1 | D45: =PROJ_AGCeAGPar!H287 -> 4.533 | E45: =PROJ_AGCeAGPar!I287 -> 4.305 | F45: =PROJ_AGCeAGPar!J287 -> 1.458 | G45: =HLOOKUP(G$7,Macroeconomics!$B$5:$GB$36,Macroeconomics!$A$24,0)*$C$45*G42 -> 1.1771624 | H45: =HLOOKUP(H$7,Macroeconomics!$B$5:$GB$36,Macroeconomics!$A$24,0)*$C$45*H42*50% -> 25.60247 | I45: =HLOOKUP(I$7,Macroeconomics!$B$5:$GB$36,Macroeconomics!$A$24,0)*$C$45*I42 -> 55.994075 | J45: =HLOOKUP(J$7,Macroeconomics!$B$5:$GB$36,Macroeconomics!$A$24,0)*$C$45*J42 -> 80.068508 | K45: =HLOOKUP(K$7,Macroeconomics!$B$5:$GB$36,Macroeconomics!$A$24,0)*$C$45*K42 -> 106.0114 | L45: =HLOOKUP(L$7,Macroeconomics!$B$5:$GB$36,Macroeconomics!$A$24,0)*$C$45*L42 -> 120.54893 | M45: =HLOOKUP(M$7,Macroeconomics!$B$5:$GB$36,Macroeconomics!$A$24,0)*$C$45*M42 -> 135.47539 | N45: =HLOOKUP(N$7,Macroeconomics!$B$5:$GB$36,Macroeconomics!$A$24,0)*$C$45*N42 -> 156.3898 | O45: =HLOOKUP(O$7,Macroeconomics!$B$5:$GB$36,Macroeconomics!$A$24,0)*$C$45*O42 -> 182.25807 | P45: =HLOOKUP(P$7,Macroeconomics!$B$5:$GB$36,Macroeconomics!$A$24,0)*$C$45*P42 -> 214.16591 | ... Y45: =HLOOKUP(Y$7,Macroeconomics!$B$5:$GB$36,Macroeconomics!$A$24,0)*$C$45*Y42 -> 0
B46: % Saldo Médio | D46: =D45/D44 -> 0.010687491 | E46: =E45/E44 -> 0.013753721 | F46: =F45/F44 -> 0.044979038 | G46: =G45/G44 -> 0.0037986257 | H46: =H45/H44 -> 0.04307534 | I46: =I45/I44 -> 0.078547963 | J46: =J45/J44 -> 0.082560571 | K46: =K45/K44 -> 0.090495121 | ... Y46: =Y45/Y44 -> #DIV/0!
...

Sheet DIVIDA AGConcessoes
F1: LEGENDA:
B2: MODELO DE DÍVIDA | F2: Dados Realizados Inputados | I2: VICTOR LOPES SCHMUTZLER
F3: Dados Realizados Calculados | I3: +55 (11) 3553-2529
F4: Dados Projetados Inputados
B5: 1. RESUMO FINANCIAMENTOS | F5: Dados Projetados Calculados
B7: CONSOLIDADO ANUAL | D7: 2009 | E7: 2010 | F7: 2011 | G7: =F7+1 -> 2012 | H7: =G7+1 -> 2013 | I7: =H7+1 -> 2014 | J7: =I7+1 -> 2015 | K7: =J7+1 -> 2016 | L7: =K7+1 -> 2017 | M7: =L7+1 -> 2018 | N7: =M7+1 -> 2019 | ... Y7: =X7+1 -> 2030
B9: Debentures
B10: Saldo inicial (Balanço)
B11: Novo funding (Caixa)
B12: Juros apropriados (DRE)
B13: Juros pagos (Caixa)
B14: Amortização principal (Caixa)
B15: Saldo final (Balanço)
B16: Saldo Curto Prazo (Balanço)
B17: Saldo Longo Prazo (Balanço)
B19: Empréstimos e financiamentos
A20: 15 | B20: Saldo inicial (Balanço) | F20: 0 | G20: =F26 -> 335.214 | H20: =G26 -> 292764.24 | I20: =H26 -> 101010.09 | J20: =I26 -> 47500 | K20: =J26 -> 0 | L20: =K26 -> 0 | M20: =L26 -> 0 | N20: =M26 -> 0 | ... Y20: =X26 -> 0
A21: 16 | B21: Novo funding (Caixa) | G21: =SUMIF($E$112:$GQ$112,G$7,$E126:$GQ126)+SUMIF($E$52:$GQ$52,G$7,$E66:$GQ66)+SUMIF($E$82:$GQ$82,G$7,$E96:$GQ96) -> 0 | H21: =SUMIF($E$112:$GQ$112,H$7,$E126:$GQ126)+SUMIF($E$52:$GQ$52,H$7,$E66:$GQ66)+SUMIF($E$82:$GQ$82,H$7,$E96:$GQ96) -> 0 | I21: =SUMIF($E$112:$GQ$112,I$7,$E126:$GQ126)+SUMIF($E$52:$GQ$52,I$7,$E66:$GQ66)+SUMIF($E$82:$GQ$82,I$7,$E96:$GQ96) -> 0 | J21: =SUMIF($E$112:$GQ$112,J$7,$E126:$GQ126)+SUMIF($E$52:$GQ$52,J$7,$E66:$GQ66)+SUMIF($E$82:$GQ$82,J$7,$E96:$GQ96) -> 0 | K21: =SUMIF($E$112:$GQ$112,K$7,$E126:$GQ126)+SUMIF($E$52:$GQ$52,K$7,$E66:$GQ66)+SUMIF($E$82:$GQ$82,K$7,$E96:$GQ96) -> 0 | L21: =SUMIF($E$112:$GQ$112,L$7,$E126:$GQ126)+SUMIF($E$52:$GQ$52,L$7,$E66:$GQ66)+SUMIF($E$82:$GQ$82,L$7,$E96:$GQ96) -> 0 | M21: =SUMIF($E$112:$GQ$112,M$7,$E126:$GQ126)+SUMIF($E$52:$GQ$52,M$7,$E66:$GQ66)+SUMIF($E$82:$GQ$82,M$7,$E96:$GQ96) -> 0 | N21: =SUMIF($E$112:$GQ$112,N$7,$E126:$GQ126)+SUMIF($E$52:$GQ$52,N$7,$E66:$GQ66)+SUMIF($E$82:$GQ$82,N$7,$E96:$GQ96) -> 0 | ... Y21: =SUMIF($E$112:$GQ$112,Y$7,$E126:$GQ126)+SUMIF($E$52:$GQ$52,Y$7,$E66:$GQ66)+SUMIF($E$82:$GQ$82,Y$7,$E96:$GQ96) -> 0
