Workbook
Name AnoSelecionado: [1]Relatório!$G$1
Name Anoslst: OFFSET('[1]Inserção de Dados'!$C$3:$J$3,0,1,1,COUNTA('[1]Inserção de Dados'!$C$3:$J$3)-1)
Name Ativo_não_Circulante___ANC: '[2]LIQUIDEZ CORRENTE'!#REF!
Name BuiltIn_Print_Area: #REF!
Name Caixa_Mínimo_Operacional___CMO: #REF!
Name Capital_Circulante_Líquido___CCL: #REF!
Name Categoria: [3]Cadastros!$A$3:$A$8
Name Categoria1: '[4]Lista de Compras'!$B$4
Name Categoria2: '[4]Lista de Compras'!$C$4
Name Categoria3: '[4]Lista de Compras'!$D$4
Name Categoria4: '[4]Lista de Compras'!$E$4
Name Categoria5: '[4]Lista de Compras'!$F$4
Name Ciclo_de_Caixa___CC: #REF!
Name Clientes: '[5]CADASTRO DE CLIENTES'!#REF!
Name Custo_das_Mercadorias_Vendidas___CMV: #REF!
Name CustoMédioPorLitro: [6]CONSUMO!$C$4
Name CustoMédioPorQuilômetro: [6]CONSUMO!$E$4
Name Departamento: [3]Cadastros!$F$2:$F$11
Name Depósito: '[7]Prestação de Serviço'!$G$24
Name DRE: '[2]LIQUIDEZ CORRENTE'!#REF!
Name EstaColuna: '[8]Tarefas Semanais'!XFD$4:INDEX('[8]Tarefas Semanais'!XFD:XFD,ÚltimaLinha,1)
Name EsteDiaSemana: CHOOSE(WEEKDAY(TODAY()),1,2,3,4,5,6,7)
Name Giro_de_Caixa___GC: #REF!
Name HoraAtual: TIME(HOUR(NOW()),MINUTE(NOW()),SECOND(NOW()))
Name horas: #REF!
Name Icms: '[9]Comparativo Vendedores'!#REF!
Name InícioCalendário: '[8]Tarefas Semanais'!$D$2
Name InícioDaSemana: '[8]Tarefas Semanais'!#REF!
Name IntervaloMinutos: '[8]Tarefas Semanais'!$A$3
Name lista_bancos: #REF!
Name ListaCategoriaPresentes: '[10]INFO DA LISTA'!$D$5:$D$11
Name ListaPessoas: '[10]INFO DA LISTA'!$B$5:$B$11
Name LucroLíquido: '[11]Lucros e perdas'!$N$32
Name MédiadeMPL: [6]CONSUMO!$D$4
Name Métricaslst: OFFSET('[1]Inserção de Dados'!$C$4:$C$28,0,0,COUNTA('[1]Inserção de Dados'!$C$4:$C$28))
Name NativeTimeline_DATA: #N/A
Name Necessidade_de_Investimento_em_Giro___NIG: #REF!
Name Necessidade_Total_de_Financiamento_Permanente___NTFP: #REF!
Name NomeCobrança: '[7]Prestação de Serviço'!$B$10
Name Passivo_não_Circulante___PNC: '[2]LIQUIDEZ CORRENTE'!#REF!
Name Patrimônio_Líquido___PL: '[2]LIQUIDEZ CORRENTE'!#REF!
Name PesquisaCategoria: #REF!
Name PesquisaCliente: [7]!ListadeClientes[Nome da Empresa]
Name Prazo_Médio_de_Cobrança___PMC_ou_PMR: #REF!
Name Prazo_Médio_de_Estocagem_de_Matéria_prima___PME: #REF!
Name Prazo_Médio_de_Pagamento___PMP: #REF!
Name prioridades: formulas!$A$3:$A$7
Name QuilômetrosdeViagem: [6]CONSUMO!$G$3
Name Rel_Despesas: '[12]Relatório Despesas'!$B$2:$B$72
Name rngFeriados: [13]DADOS!$C$5:$I$20
Name Salário_Base: '[14]Custo com Funcionário'!$B$5
Name Saldo_do_Disponível___SD_ou_ST__Saldo_Tesouraria: #REF!
Name Segmentação_de_dados_Categoria_do_presente: #N/A
Name Segmentação_de_dados_Comprado: #N/A
Name Segmentação_de_dados_Para: #N/A
Name Segmentação_de_dados_Status_de_embrulho: #N/A
Name Segmentação_de_dados_Status_de_entreda: #N/A
Name SegmentaçãodeDados_CATEGORIA: #N/A
Name SegmentaçãodeDados_SUBCATEGORIA: #N/A
Name status_nome: [15]listas!$A$2:$A$8

Sheet formulas
A2: Prioridades | C2: Completo | D2: Status | E2: Cálculo Prioridade
A3: 1 | C3: TRUE | D3: =IFERROR(C3*(E3/SUM($E$3:$E$17)),0) -> 0.2189781 | E3: =IFERROR(1/Gráfico!D12,0) -> 1
A4: 2 | C4: FALSE | D4: =IFERROR(C4*(E4/SUM($E$3:$E$17)),0) -> 0 | E4: =IFERROR(1/Gráfico!D13,0) -> 0.5
A5: 3 | C5: TRUE | D5: =IFERROR(C5*(E5/SUM($E$3:$E$17)),0) -> 0.072992701 | E5: =IFERROR(1/Gráfico!D14,0) -> 0.33333333
A6: 4 | C6: FALSE | D6: =IFERROR(C6*(E6/SUM($E$3:$E$17)),0) -> 0 | E6: =IFERROR(1/Gráfico!D15,0) -> 0.25
A7: 5 | C7: TRUE | D7: =IFERROR(C7*(E7/SUM($E$3:$E$17)),0) -> 0.04379562 | E7: =IFERROR(1/Gráfico!D16,0) -> 0.2
C8: FALSE | D8: =IFERROR(C8*(E8/SUM($E$3:$E$17)),0) -> 0 | E8: =IFERROR(1/Gráfico!D17,0) -> 1
C9: TRUE | D9: =IFERROR(C9*(E9/SUM($E$3:$E$17)),0) -> 0.10948905 | E9: =IFERROR(1/Gráfico!D18,0) -> 0.5
C10: FALSE | D10: =IFERROR(C10*(E10/SUM($E$3:$E$17)),0) -> 0 | E10: =IFERROR(1/Gráfico!D19,0) -> 0.33333333
C11: TRUE | D11: =IFERROR(C11*(E11/SUM($E$3:$E$17)),0) -> 0.054744526 | E11: =IFERROR(1/Gráfico!D20,0) -> 0.25
C12: FALSE | D12: =IFERROR(C12*(E12/SUM($E$3:$E$17)),0) -> 0 | E12: =IFERROR(1/Gráfico!D21,0) -> 0.2
C13: FALSE | D13: =IFERROR(C13*(E13/SUM($E$3:$E$17)),0) -> 0 | E13: =IFERROR(1/Gráfico!#REF!,0) -> 0
C14: FALSE | D14: =IFERROR(C14*(E14/SUM($E$3:$E$17)),0) -> 0 | E14: =IFERROR(1/Gráfico!#REF!,0) -> 0
C15: FALSE | D15: =IFERROR(C15*(E15/SUM($E$3:$E$17)),0) -> 0 | E15: =IFERROR(1/Gráfico!#REF!,0) -> 0
C16: FALSE | D16: =IFERROR(C16*(E16/SUM($E$3:$E$17)),0) -> 0 | E16: =IFERROR(1/Gráfico!#REF!,0) -> 0
C17: FALSE | D17: =IFERROR(C17*(E17/SUM($E$3:$E$17)),0) -> 0 | E17: =IFERROR(1/Gráfico!#REF!,0) -> 0
D18: =SUM(D3:D17) -> 0.5

Sheet Tarefas dos Projetos
C2: TAREFAS POR PROJETO
C4: NOME DO PROJETO 1
C5: Nome do responsável: | E5: Prazo final execução:
C7: % conclusão | D7: Fase / Andamento | E7: Data de conclusão | F7: Anotações
C8: 10 | D8: Descreva a tarefa a ser desempenhada | E8: 36892
C9: 20 | D9: Descreva a tarefa a ser desempenhada | E9: 36893
C10: 30 | D10: Descreva a tarefa a ser desempenhada | E10: 36894
C11: 40 | D11: Descreva a tarefa a ser desempenhada | E11: 36895
C12: 50 | D12: Descreva a tarefa a ser desempenhada | E12: 36896
C13: 60 | D13: Descreva a tarefa a ser desempenhada | E13: 36897
C14: 70 | D14: Descreva a tarefa a ser desempenhada | E14: 36898
C15: 80 | D15: Descreva a tarefa a ser desempenhada | E15: 36899
C16: 90 | D16: Descreva a tarefa a ser desempenhada | E16: 36900
C17: 100 | D17: Descreva a tarefa a ser desempenhada | E17: 36901
C20: NOME DO PROJETO 2
C21: Nome do responsável: | E21: Prazo final execução:
C23: % conclusão | D23: Fase / Andamento | E23: Data de conclusão | F23: Anotações
C24: 10 | D24: Descreva a tarefa a ser desempenhada | E24: 36892
C25: 20 | D25: Descreva a tarefa a ser desempenhada | E25: 36893
C26: 30 | D26: Descreva a tarefa a ser desempenhada | E26: 36894
C27: 40 | D27: Descreva a tarefa a ser desempenhada | E27: 36895
C28: 50 | D28: Descreva a tarefa a ser desempenhada | E28: 36896
C29: 60 | D29: Descreva a tarefa a ser desempenhada | E29: 36897
C30: 70 | D30: Descreva a tarefa a ser desempenhada | E30: 36898
C31: 80 | D31: Descreva a tarefa a ser desempenhada | E31: 36899
C32: 90 | D32: Descreva a tarefa a ser desempenhada | E32: 36900
C33: 100 | D33: Descreva a tarefa a ser desempenhada | E33: 36901
C36: NOME DO PROJETO 3
C37: Nome do responsável: | E37: Prazo final execução:
C39: % conclusão | D39: Fase / Andamento | E39: Data de conclusão | F39: Anotações
C40: 10 | D40: Descreva a tarefa a ser desempenhada | E40: 36892
C41: 20 | D41: Descreva a tarefa a ser desempenhada | E41: 36893
C42: 30 | D42: Descreva a tarefa a ser desempenhada | E42: 36894
C43: 40 | D43: Descreva a tarefa a ser desempenhada | E43: 36895
C44: 50 | D44: Descreva a tarefa a ser desempenhada | E44: 36896
C45: 60 | D45: Descreva a tarefa a ser desempenhada | E45: 36897
C46: 70 | D46: Descreva a tarefa a ser desempenhada | E46: 36898
C47: 80 | D47: Descreva a tarefa a ser desempenhada | E47: 36899
C48: 90 | D48: Descreva a tarefa a ser desempenhada | E48: 36900
C49: 100 | D49: Descreva a tarefa a ser desempenhada | E49: 36901
...

Sheet Gráfico
B2: Lista de Tarefas
B11: Item | C11: Projeto | D11: Prioridade | E11: Completo
B12: 1 | C12: Projeto 1 | D12: 1
B13: 2 | C13: Projeto 2 | D13: 2
B14: 3 | C14: Projeto 3 | D14: 3
B15: 4 | C15: Projeto 4 | D15: 4
B16: 5 | C16: Projeto 5 | D16: 5
B17: 6 | C17: Projeto 6 | D17: 1
B18: 7 | C18: Projeto 7 | D18: 2
B19: 8 | C19: Projeto 8 | D19: 3
B20: 9 | C20: Projeto 9 | D20: 4
B21: 10 | C21: Projeto 10 | D21: 5
