Workbook

Sheet Painel Inicial
B3: Bem-vindo à Planilha de Medição de Obra do Sienge Esse modelo de Planilha de Medição de Obra permite fazer as medições individuais, ter uma visão consolidada, permitindo de maneira fácil visualizar a evolução da obra e ter uma ferramenta para auxiliar na prestação de contas. Acesse um dos botões do menu abaixo: | O3: Apareceu uma barra rosa no topo do arquivo dizendo que a planilha não é segura? Basta clicar em "Obter mais detalhes" e posteriormente clicar no botão “Editar mesmo assim”.
B6: Caso você precise fazer algum tipo de edição, fique tranquilo, pois esse arquivo é desbloqueado e permite a adaptação para sua empresa. E não esqueça, se as planilhas não permitirem mais o desempenho desejado para sua empresa e você quiser uma gestão mais madura, sem retrabalho e que permita fácil acesso a informações gerenciais, você precisa de um ERP, um Software de Gestão de Obras. Quem sabe não é a hora de conhecer o Sienge? Acesse: www.sienge.com.br .
B18: Faça a gestão completa de sua obra com o Sienge, saiba mais em www.sienge.com.br ou (48) 3027 8110.

Sheet Como Utilizar
B4: Em todas as abas da Planilha de Medição de Obras, preencha apenas os campos com fundo azul claro. Todos as outras informações são geradas automaticamente.

Sheet Cadastro Institucional
B3: Fatores de Cálculo | C3: BDI
C4: LS (Encargos Sociais) | F4: Preencha apenas as células com esse azul claro como cor de fundo!
B6: Obra | C6: Nome
C7: Endereço
B9: Informações Institucionais | C9: Razão Social
C10: CNPJ
C11: Inscrição Estadual
C12: Responsável
C13: Cargo
C14: Telefone
C15: E-mail

Sheet Etapas
E1: OBRA | F1: ='Cadastro Institucional'!D$6 -> 0 | G1: ='Cadastro Institucional'!D$7 -> 0
A2: CNPJ | B2: Razão Social | C2: Inscrição Estadual | D2: Responsável | E2: Cargo | F2: Telefone | G2: E-mail
A3: ='Cadastro Institucional'!D$10 -> 0 | B3: ='Cadastro Institucional'!D$9 -> 0 | C3: ='Cadastro Institucional'!D$11 -> 0 | D3: ='Cadastro Institucional'!D$12 -> 0 | E3: ='Cadastro Institucional'!D$13 -> 0 | F3: ='Cadastro Institucional'!D$14 -> 0 | G3: ='Cadastro Institucional'!D$15 -> 0
A5: Etapa | B5: Descrição
A6: 1 | D6: Preencha apenas as células com esse azul claro como cor de fundo!
A7: 2
A8: 3
A9: 4
A10: 5
A11: 6
A12: 7
A13: 8
A14: 9
A15: 10
A16: 11
A17: 12
A18: 13
... A25: 20

Sheet Itens de Contrato
E1: OBRA | F1: ='Cadastro Institucional'!D$6 -> 0 | G1: ='Cadastro Institucional'!D$7 -> 0
A2: CNPJ | B2: Razão Social | C2: Inscrição Estadual | D2: Responsável | E2: Cargo | F2: Telefone | G2: E-mail
A3: ='Cadastro Institucional'!D$10 -> 0 | B3: ='Cadastro Institucional'!D$9 -> 0 | C3: ='Cadastro Institucional'!D$11 -> 0 | D3: ='Cadastro Institucional'!D$12 -> 0 | E3: ='Cadastro Institucional'!D$13 -> 0 | F3: ='Cadastro Institucional'!D$14 -> 0 | G3: ='Cadastro Institucional'!D$15 -> 0
I4: Preencha apenas as células com esse azul claro como cor de fundo!
A5: Etapa | B5: Item | C5: Descrição | D5: Unidade | E5: Quantidade | F5: Valor Unitário | G5: Valor Total
G6: =(E6*F6)*(1+(SUM('Cadastro Institucional'!D$3:D$4))) -> 0
G7: =(E7*F7)*(1+(SUM('Cadastro Institucional'!D$3:D$4))) -> 0
G8: =(E8*F8)*(1+(SUM('Cadastro Institucional'!D$3:D$4))) -> 0
G9: =(E9*F9)*(1+(SUM('Cadastro Institucional'!D$3:D$4))) -> 0
G10: =(E10*F10)*(1+(SUM('Cadastro Institucional'!D$3:D$4))) -> 0
G11: =(E11*F11)*(1+(SUM('Cadastro Institucional'!D$3:D$4))) -> 0
G12: =(E12*F12)*(1+(SUM('Cadastro Institucional'!D$3:D$4))) -> 0
G13: =(E13*F13)*(1+(SUM('Cadastro Institucional'!D$3:D$4))) -> 0
G14: =(E14*F14)*(1+(SUM('Cadastro Institucional'!D$3:D$4))) -> 0
G15: =(E15*F15)*(1+(SUM('Cadastro Institucional'!D$3:D$4))) -> 0
G16: =(E16*F16)*(1+(SUM('Cadastro Institucional'!D$3:D$4))) -> 0
G17: =(E17*F17)*(1+(SUM('Cadastro Institucional'!D$3:D$4))) -> 0
... G151: =(E151*F151)*(1+(SUM('Cadastro Institucional'!D$3:D$4))) -> 0

Sheet Medição Consolidada (Itens de C
E1: OBRA | F1: ='Cadastro Institucional'!D$6 -> 0 | G1: ='Cadastro Institucional'!D$7 -> 0
A2: CNPJ | B2: Razão Social | C2: Inscrição Estadual | D2: Responsável | E2: Cargo | F2: Telefone | G2: E-mail
A3: ='Cadastro Institucional'!D$10 -> 0 | B3: ='Cadastro Institucional'!D$9 -> 0 | C3: ='Cadastro Institucional'!D$11 -> 0 | D3: ='Cadastro Institucional'!D$12 -> 0 | E3: ='Cadastro Institucional'!D$13 -> 0 | F3: ='Cadastro Institucional'!D$14 -> 0 | G3: ='Cadastro Institucional'!D$15 -> 0
A5: Etapa | B5: Item | C5: Descrição | D5: Quantidade Contratada | E5: Valor Contratado | F5: Saldo Total à Medir | G5: Quantidade Executada | H5: % Executado | I5: Valor Executado
A6: ='Itens de Contrato'!A6 -> 0 | B6: ='Itens de Contrato'!B6 -> 0 | C6: =VLOOKUP(B6,'Itens de Contrato'!B$5:G$151,2,0) -> #N/A | D6: =VLOOKUP(B6,'Itens de Contrato'!B$5:G$151,4) -> #N/A | E6: =D6*'Itens de Contrato'!F6 -> #N/A | F6: =D6-G6 -> #N/A | G6: =SUM('Medição 01'!G6,'Medição 02'!G6,'Medição 03'!G6,'Medição 04'!G6,'Medição 05'!G6,'Medição 06'!G6,'Medição 07'!G6,'Medição 08'!G6,'Medição 09'!G6,'Medição 10'!G6,'Medição 11'!G6,'Medição 12'!G6) -> 0 | H6: =G6/D6 -> #DIV/0! | I6: =G6*'Itens de Contrato'!F6 -> 0
A7: ='Itens de Contrato'!A7 -> 0 | B7: ='Itens de Contrato'!B7 -> 0 | C7: =VLOOKUP(B7,'Itens de Contrato'!B$5:G$151,2,0) -> #N/A | D7: =VLOOKUP(B7,'Itens de Contrato'!B$5:G$151,4) -> #N/A | E7: =D7*'Itens de Contrato'!F7 -> #N/A | F7: =D7-G7 -> #N/A | G7: =SUM('Medição 01'!G7,'Medição 02'!G7,'Medição 03'!G7,'Medição 04'!G7,'Medição 05'!G7,'Medição 06'!G7,'Medição 07'!G7,'Medição 08'!G7,'Medição 09'!G7,'Medição 10'!G7,'Medição 11'!G7,'Medição 12'!G7) -> 0 | H7: =G7/D7 -> #DIV/0! | I7: =G7*'Itens de Contrato'!F7 -> 0
A8: ='Itens de Contrato'!A8 -> 0 | B8: ='Itens de Contrato'!B8 -> 0 | C8: =VLOOKUP(B8,'Itens de Contrato'!B$5:G$151,2,0) -> #N/A | D8: =VLOOKUP(B8,'Itens de Contrato'!B$5:G$151,4) -> #N/A | E8: =D8*'Itens de Contrato'!F8 -> #N/A | F8: =D8-G8 -> #N/A | G8: =SUM('Medição 01'!G8,'Medição 02'!G8,'Medição 03'!G8,'Medição 04'!G8,'Medição 05'!G8,'Medição 06'!G8,'Medição 07'!G8,'Medição 08'!G8,'Medição 09'!G8,'Medição 10'!G8,'Medição 11'!G8,'Medição 12'!G8) -> 0 | H8: =G8/D8 -> #DIV/0! | I8: =G8*'Itens de Contrato'!F8 -> 0
A9: ='Itens de Contrato'!A9 -> 0 | B9: ='Itens de Contrato'!B9 -> 0 | C9: =VLOOKUP(B9,'Itens de Contrato'!B$5:G$151,2,0) -> #N/A | D9: =VLOOKUP(B9,'Itens de Contrato'!B$5:G$151,4) -> #N/A | E9: =D9*'Itens de Contrato'!F9 -> #N/A | F9: =D9-G9 -> #N/A | G9: =SUM('Medição 01'!G9,'Medição 02'!G9,'Medição 03'!G9,'Medição 04'!G9,'Medição 05'!G9,'Medição 06'!G9,'Medição 07'!G9,'Medição 08'!G9,'Medição 09'!G9,'Medição 10'!G9,'Medição 11'!G9,'Medição 12'!G9) -> 0 | H9: =G9/D9 -> #DIV/0! | I9: =G9*'Itens de Contrato'!F9 -> 0
A10: ='Itens de Contrato'!A10 -> 0 | B10: ='Itens de Contrato'!B10 -> 0 | C10: =VLOOKUP(B10,'Itens de Contrato'!B$5:G$151,2,0) -> #N/A | D10: =VLOOKUP(B10,'Itens de Contrato'!B$5:G$151,4) -> #N/A | E10: =D10*'Itens de Contrato'!F10 -> #N/A | F10: =D10-G10 -> #N/A | G10: =SUM('Medição 01'!G10,'Medição 02'!G10,'Medição 03'!G10,'Medição 04'!G10,'Medição 05'!G10,'Medição 06'!G10,'Medição 07'!G10,'Medição 08'!G10,'Medição 09'!G10,'Medição 10'!G10,'Medição 11'!G10,'Medição 12'!G10) -> 0 | H10: =G10/D10 -> #DIV/0! | I10: =G10*'Itens de Contrato'!F10 -> 0
A11: ='Itens de Contrato'!A11 -> 0 | B11: ='Itens de Contrato'!B11 -> 0 | C11: =VLOOKUP(B11,'Itens de Contrato'!B$5:G$151,2,0) -> #N/A | D11: =VLOOKUP(B11,'Itens de Contrato'!B$5:G$151,4) -> #N/A | E11: =D11*'Itens de Contrato'!F11 -> #N/A | F11: =D11-G11 -> #N/A | G11: =SUM('Medição 01'!G11,'Medição 02'!G11,'Medição 03'!G11,'Medição 04'!G11,'Medição 05'!G11,'Medição 06'!G11,'Medição 07'!G11,'Medição 08'!G11,'Medição 09'!G11,'Medição 10'!G11,'Medição 11'!G11,'Medição 12'!G11) -> 0 | H11: =G11/D11 -> #DIV/0! | I11: =G11*'Itens de Contrato'!F11 -> 0
A12: ='Itens de Contrato'!A12 -> 0 | B12: ='Itens de Contrato'!B12 -> 0 | C12: =VLOOKUP(B12,'Itens de Contrato'!B$5:G$151,2,0) -> #N/A | D12: =VLOOKUP(B12,'Itens de Contrato'!B$5:G$151,4) -> #N/A | E12: =D12*'Itens de Contrato'!F12 -> #N/A | F12: =D12-G12 -> #N/A | G12: =SUM('Medição 01'!G12,'Medição 02'!G12,'Medição 03'!G12,'Medição 04'!G12,'Medição 05'!G12,'Medição 06'!G12,'Medição 07'!G12,'Medição 08'!G12,'Medição 09'!G12,'Medição 10'!G12,'Medição 11'!G12,'Medição 12'!G12) -> 0 | H12: =G12/D12 -> #DIV/0! | I12: =G12*'Itens de Contrato'!F12 -> 0
A13: ='Itens de Contrato'!A13 -> 0 | B13: ='Itens de Contrato'!B13 -> 0 | C13: =VLOOKUP(B13,'Itens de Contrato'!B$5:G$151,2,0) -> #N/A | D13: =VLOOKUP(B13,'Itens de Contrato'!B$5:G$151,4) -> #N/A | E13: =D13*'Itens de Contrato'!F13 -> #N/A | F13: =D13-G13 -> #N/A | G13: =SUM('Medição 01'!G13,'Medição 02'!G13,'Medição 03'!G13,'Medição 04'!G13,'Medição 05'!G13,'Medição 06'!G13,'Medição 07'!G13,'Medição 08'!G13,'Medição 09'!G13,'Medição 10'!G13,'Medição 11'!G13,'Medição 12'!G13) -> 0 | H13: =G13/D13 -> #DIV/0! | I13: =G13*'Itens de Contrato'!F13 -> 0
A14: ='Itens de Contrato'!A14 -> 0 | B14: ='Itens de Contrato'!B14 -> 0 | C14: =VLOOKUP(B14,'Itens de Contrato'!B$5:G$151,2,0) -> #N/A | D14: =VLOOKUP(B14,'Itens de Contrato'!B$5:G$151,4) -> #N/A | E14: =D14*'Itens de Contrato'!F14 -> #N/A | F14: =D14-G14 -> #N/A | G14: =SUM('Medição 01'!G14,'Medição 02'!G14,'Medição 03'!G14,'Medição 04'!G14,'Medição 05'!G14,'Medição 06'!G14,'Medição 07'!G14,'Medição 08'!G14,'Medição 09'!G14,'Medição 10'!G14,'Medição 11'!G14,'Medição 12'!G14) -> 0 | H14: =G14/D14 -> #DIV/0! | I14: =G14*'Itens de Contrato'!F14 -> 0
A15: ='Itens de Contrato'!A15 -> 0 | B15: ='Itens de Contrato'!B15 -> 0 | C15: =VLOOKUP(B15,'Itens de Contrato'!B$5:G$151,2,0) -> #N/A | D15: =VLOOKUP(B15,'Itens de Contrato'!B$5:G$151,4) -> #N/A | E15: =D15*'Itens de Contrato'!F15 -> #N/A | F15: =D15-G15 -> #N/A | G15: =SUM('Medição 01'!G15,'Medição 02'!G15,'Medição 03'!G15,'Medição 04'!G15,'Medição 05'!G15,'Medição 06'!G15,'Medição 07'!G15,'Medição 08'!G15,'Medição 09'!G15,'Medição 10'!G15,'Medição 11'!G15,'Medição 12'!G15) -> 0 | H15: =G15/D15 -> #DIV/0! | I15: =G15*'Itens de Contrato'!F15 -> 0
A16: ='Itens de Contrato'!A16 -> 0 | B16: ='Itens de Contrato'!B16 -> 0 | C16: =VLOOKUP(B16,'Itens de Contrato'!B$5:G$151,2,0) -> #N/A | D16: =VLOOKUP(B16,'Itens de Contrato'!B$5:G$151,4) -> #N/A | E16: =D16*'Itens de Contrato'!F16 -> #N/A | F16: =D16-G16 -> #N/A | G16: =SUM('Medição 01'!G16,'Medição 02'!G16,'Medição 03'!G16,'Medição 04'!G16,'Medição 05'!G16,'Medição 06'!G16,'Medição 07'!G16,'Medição 08'!G16,'Medição 09'!G16,'Medição 10'!G16,'Medição 11'!G16,'Medição 12'!G16) -> 0 | H16: =G16/D16 -> #DIV/0! | I16: =G16*'Itens de Contrato'!F16 -> 0
A17: ='Itens de Contrato'!A17 -> 0 | B17: ='Itens de Contrato'!B17 -> 0 | C17: =VLOOKUP(B17,'Itens de Contrato'!B$5:G$151,2,0) -> #N/A | D17: =VLOOKUP(B17,'Itens de Contrato'!B$5:G$151,4) -> #N/A | E17: =D17*'Itens de Contrato'!F17 -> #N/A | F17: =D17-G17 -> #N/A | G17: =SUM('Medição 01'!G17,'Medição 02'!G17,'Medição 03'!G17,'Medição 04'!G17,'Medição 05'!G17,'Medição 06'!G17,'Medição 07'!G17,'Medição 08'!G17,'Medição 09'!G17,'Medição 10'!G17,'Medição 11'!G17,'Medição 12'!G17) -> 0 | H17: =G17/D17 -> #DIV/0! | I17: =G17*'Itens de Contrato'!F17 -> 0
... A151: ='Itens de Contrato'!A151 -> 0 | B151: ='Itens de Contrato'!B151 -> 0 | C151: =VLOOKUP(B151,'Itens de Contrato'!B$5:G$151,2,0) -> #N/A | D151: =VLOOKUP(B151,'Itens de Contrato'!B$5:G$151,4) -> #N/A | E151: =D151*'Itens de Contrato'!F151 -> #N/A | F151: =D151-G151 -> #N/A | G151: =SUM('Medição 01'!G151,'Medição 02'!G151,'Medição 03'!G151,'Medição 04'!G151,'Medição 05'!G151,'Medição 06'!G151,'Medição 07'!G151,'Medição 08'!G151,'Medição 09'!G151,'Medição 10'!G151,'Medição 11'!G151,'Medição 12'!G151) -> 0 | H151: =G151/D151 -> #DIV/0! | I151: =G151*'Itens de Contrato'!F151 -> 0

Sheet Medição Consolidada (Etapas)
E1: OBRA | F1: ='Cadastro Institucional'!D$6 -> 0 | G1: ='Cadastro Institucional'!D$7 -> 0
A2: CNPJ | B2: Razão Social | C2: Inscrição Estadual | D2: Responsável | E2: Cargo | F2: Telefone | G2: E-mail
A3: ='Cadastro Institucional'!D$10 -> 0 | B3: ='Cadastro Institucional'!D$9 -> 0 | C3: ='Cadastro Institucional'!D$11 -> 0 | D3: ='Cadastro Institucional'!D$12 -> 0 | E3: ='Cadastro Institucional'!D$13 -> 0 | F3: ='Cadastro Institucional'!D$14 -> 0 | G3: ='Cadastro Institucional'!D$15 -> 0
A5: Nº | B5: Etapa | C5: Quantidade Contratada | D5: Valor Contratado | E5: Saldo Total à Medir | F5: Quantidade Executada | G5: % Executado | H5: Valor Executado
A6: =Etapas!A6 -> 1 | B6: =Etapas!B6 -> 0 | C6: =SUMIF('Medição 01'!$A:$A,$B6,'Medição 01'!D:D) -> 0 | D6: =SUMIF('Medição 01'!$A:$A,$B6,'Medição 01'!E:E) -> 0 | E6: =SUMIF('Medição 01'!$A:$A,$B6,'Medição 01'!F:F) -> 0 | F6: =SUMIF('Medição 01'!$A:$A,$B6,'Medição 01'!G:G) -> 0 | G6: =F6/C6 -> #DIV/0! | H6: =SUMIF('Medição 01'!$A:$A,$B6,'Medição 01'!I:I) -> 0
A7: =Etapas!A7 -> 2 | B7: =Etapas!B7 -> 0 | C7: =SUMIF('Medição 01'!$A:$A,$B7,'Medição 01'!D:D) -> 0 | D7: =SUMIF('Medição 01'!$A:$A,$B7,'Medição 01'!E:E) -> 0 | E7: =SUMIF('Medição 01'!$A:$A,$B7,'Medição 01'!F:F) -> 0 | F7: =SUMIF('Medição 01'!$A:$A,$B7,'Medição 01'!G:G) -> 0 | G7: =F7/C7 -> #DIV/0! | H7: =SUMIF('Medição 01'!$A:$A,$B7,'Medição 01'!I:I) -> 0
A8: =Etapas!A8 -> 3 | B8: =Etapas!B8 -> 0 | C8: =SUMIF('Medição 01'!$A:$A,$B8,'Medição 01'!D:D) -> 0 | D8: =SUMIF('Medição 01'!$A:$A,$B8,'Medição 01'!E:E) -> 0 | E8: =SUMIF('Medição 01'!$A:$A,$B8,'Medição 01'!F:F) -> 0 | F8: =SUMIF('Medição 01'!$A:$A,$B8,'Medição 01'!G:G) -> 0 | G8: =F8/C8 -> #DIV/0! | H8: =SUMIF('Medição 01'!$A:$A,$B8,'Medição 01'!I:I) -> 0
A9: =Etapas!A9 -> 4 | B9: =Etapas!B9 -> 0 | C9: =SUMIF('Medição 01'!$A:$A,$B9,'Medição 01'!D:D) -> 0 | D9: =SUMIF('Medição 01'!$A:$A,$B9,'Medição 01'!E:E) -> 0 | E9: =SUMIF('Medição 01'!$A:$A,$B9,'Medição 01'!F:F) -> 0 | F9: =SUMIF('Medição 01'!$A:$A,$B9,'Medição 01'!G:G) -> 0 | G9: =F9/C9 -> #DIV/0! | H9: =SUMIF('Medição 01'!$A:$A,$B9,'Medição 01'!I:I) -> 0
A10: =Etapas!A10 -> 5 | B10: =Etapas!B10 -> 0 | C10: =SUMIF('Medição 01'!$A:$A,$B10,'Medição 01'!D:D) -> 0 | D10: =SUMIF('Medição 01'!$A:$A,$B10,'Medição 01'!E:E) -> 0 | E10: =SUMIF('Medição 01'!$A:$A,$B10,'Medição 01'!F:F) -> 0 | F10: =SUMIF('Medição 01'!$A:$A,$B10,'Medição 01'!G:G) -> 0 | G10: =F10/C10 -> #DIV/0! | H10: =SUMIF('Medição 01'!$A:$A,$B10,'Medição 01'!I:I) -> 0
A11: =Etapas!A11 -> 6 | B11: =Etapas!B11 -> 0 | C11: =SUMIF('Medição 01'!$A:$A,$B11,'Medição 01'!D:D) -> 0 | D11: =SUMIF('Medição 01'!$A:$A,$B11,'Medição 01'!E:E) -> 0 | E11: =SUMIF('Medição 01'!$A:$A,$B11,'Medição 01'!F:F) -> 0 | F11: =SUMIF('Medição 01'!$A:$A,$B11,'Medição 01'!G:G) -> 0 | G11: =F11/C11 -> #DIV/0! | H11: =SUMIF('Medição 01'!$A:$A,$B11,'Medição 01'!I:I) -> 0
A12: =Etapas!A12 -> 7 | B12: =Etapas!B12 -> 0 | C12: =SUMIF('Medição 01'!$A:$A,$B12,'Medição 01'!D:D) -> 0 | D12: =SUMIF('Medição 01'!$A:$A,$B12,'Medição 01'!E:E) -> 0 | E12: =SUMIF('Medição 01'!$A:$A,$B12,'Medição 01'!F:F) -> 0 | F12: =SUMIF('Medição 01'!$A:$A,$B12,'Medição 01'!G:G) -> 0 | G12: =F12/C12 -> #DIV/0! | H12: =SUMIF('Medição 01'!$A:$A,$B12,'Medição 01'!I:I) -> 0
A13: =Etapas!A13 -> 8 | B13: =Etapas!B13 -> 0 | C13: =SUMIF('Medição 01'!$A:$A,$B13,'Medição 01'!D:D) -> 0 | D13: =SUMIF('Medição 01'!$A:$A,$B13,'Medição 01'!E:E) -> 0 | E13: =SUMIF('Medição 01'!$A:$A,$B13,'Medição 01'!F:F) -> 0 | F13: =SUMIF('Medição 01'!$A:$A,$B13,'Medição 01'!G:G) -> 0 | G13: =F13/C13 -> #DIV/0! | H13: =SUMIF('Medição 01'!$A:$A,$B13,'Medição 01'!I:I) -> 0
A14: =Etapas!A14 -> 9 | B14: =Etapas!B14 -> 0 | C14: =SUMIF('Medição 01'!$A:$A,$B14,'Medição 01'!D:D) -> 0 | D14: =SUMIF('Medição 01'!$A:$A,$B14,'Medição 01'!E:E) -> 0 | E14: =SUMIF('Medição 01'!$A:$A,$B14,'Medição 01'!F:F) -> 0 | F14: =SUMIF('Medição 01'!$A:$A,$B14,'Medição 01'!G:G) -> 0 | G14: =F14/C14 -> #DIV/0! | H14: =SUMIF('Medição 01'!$A:$A,$B14,'Medição 01'!I:I) -> 0
A15: =Etapas!A15 -> 10 | B15: =Etapas!B15 -> 0 | C15: =SUMIF('Medição 01'!$A:$A,$B15,'Medição 01'!D:D) -> 0 | D15: =SUMIF('Medição 01'!$A:$A,$B15,'Medição 01'!E:E) -> 0 | E15: =SUMIF('Medição 01'!$A:$A,$B15,'Medição 01'!F:F) -> 0 | F15: =SUMIF('Medição 01'!$A:$A,$B15,'Medição 01'!G:G) -> 0 | G15: =F15/C15 -> #DIV/0! | H15: =SUMIF('Medição 01'!$A:$A,$B15,'Medição 01'!I:I) -> 0
A16: =Etapas!A16 -> 11 | B16: =Etapas!B16 -> 0 | C16: =SUMIF('Medição 01'!$A:$A,$B16,'Medição 01'!D:D) -> 0 | D16: =SUMIF('Medição 01'!$A:$A,$B16,'Medição 01'!E:E) -> 0 | E16: =SUMIF('Medição 01'!$A:$A,$B16,'Medição 01'!F:F) -> 0 | F16: =SUMIF('Medição 01'!$A:$A,$B16,'Medição 01'!G:G) -> 0 | G16: =F16/C16 -> #DIV/0! | H16: =SUMIF('Medição 01'!$A:$A,$B16,'Medição 01'!I:I) -> 0
A17: =Etapas!A17 -> 12 | B17: =Etapas!B17 -> 0 | C17: =SUMIF('Medição 01'!$A:$A,$B17,'Medição 01'!D:D) -> 0 | D17: =SUMIF('Medição 01'!$A:$A,$B17,'Medição 01'!E:E) -> 0 | E17: =SUMIF('Medição 01'!$A:$A,$B17,'Medição 01'!F:F) -> 0 | F17: =SUMIF('Medição 01'!$A:$A,$B17,'Medição 01'!G:G) -> 0 | G17: =F17/C17 -> #DIV/0! | H17: =SUMIF('Medição 01'!$A:$A,$B17,'Medição 01'!I:I) -> 0
... A25: =Etapas!A25 -> 20 | B25: =Etapas!B25 -> 0 | C25: =SUMIF('Medição 01'!$A:$A,$B25,'Medição 01'!D:D) -> 0 | D25: =SUMIF('Medição 01'!$A:$A,$B25,'Medição 01'!E:E) -> 0 | E25: =SUMIF('Medição 01'!$A:$A,$B25,'Medição 01'!F:F) -> 0 | F25: =SUMIF('Medição 01'!$A:$A,$B25,'Medição 01'!G:G) -> 0 | G25: =F25/C25 -> #DIV/0! | H25: =SUMIF('Medição 01'!$A:$A,$B25,'Medição 01'!I:I) -> 0

Sheet Medição 01
E1: OBRA | F1: ='Cadastro Institucional'!D$6 -> 0 | G1: ='Cadastro Institucional'!D$7 -> 0
A2: CNPJ | B2: Razão Social | C2: Inscrição Estadual | D2: Responsável | E2: Cargo | F2: Telefone | G2: E-mail | H2: Medição Nº | I2: Período
A3: ='Cadastro Institucional'!D$10 -> 0 | B3: ='Cadastro Institucional'!D$9 -> 0 | C3: ='Cadastro Institucional'!D$11 -> 0 | D3: ='Cadastro Institucional'!D$12 -> 0 | E3: ='Cadastro Institucional'!D$13 -> 0 | F3: ='Cadastro Institucional'!D$14 -> 0 | G3: ='Cadastro Institucional'!D$15 -> 0
A5: Etapa | B5: Item | C5: Descrição | D5: Quantidade Contratada | E5: Valor Contratado | F5: Saldo Total à Medir | G5: Quantidade Executada | H5: % Executado | I5: Valor Executado | K5: Preencha apenas as células com esse azul claro como cor de fundo!
A6: ='Itens de Contrato'!A6 -> 0 | B6: ='Itens de Contrato'!B6 -> 0 | C6: =VLOOKUP(B6,'Itens de Contrato'!B$5:G$151,2,0) -> #N/A | E6: =D6*'Itens de Contrato'!F6 -> 0 | F6: ='Itens de Contrato'!E6 -> 0 | H6: =G6/D6 -> #DIV/0! | I6: =G6*'Itens de Contrato'!F6 -> 0
A7: ='Itens de Contrato'!A7 -> 0 | B7: ='Itens de Contrato'!B7 -> 0 | C7: =VLOOKUP(B7,'Itens de Contrato'!B$5:G$151,2,0) -> #N/A | E7: =D7*'Itens de Contrato'!F7 -> 0 | F7: ='Itens de Contrato'!E7 -> 0 | H7: =G7/D7 -> #DIV/0! | I7: =G7*'Itens de Contrato'!F7 -> 0
A8: ='Itens de Contrato'!A8 -> 0 | B8: ='Itens de Contrato'!B8 -> 0 | C8: =VLOOKUP(B8,'Itens de Contrato'!B$5:G$151,2,0) -> #N/A | E8: =D8*'Itens de Contrato'!F8 -> 0 | F8: ='Itens de Contrato'!E8 -> 0 | H8: =G8/D8 -> #DIV/0! | I8: =G8*'Itens de Contrato'!F8 -> 0
A9: ='Itens de Contrato'!A9 -> 0 | B9: ='Itens de Contrato'!B9 -> 0 | C9: =VLOOKUP(B9,'Itens de Contrato'!B$5:G$151,2,0) -> #N/A | E9: =D9*'Itens de Contrato'!F9 -> 0 | F9: ='Itens de Contrato'!E9 -> 0 | H9: =G9/D9 -> #DIV/0! | I9: =G9*'Itens de Contrato'!F9 -> 0
A10: ='Itens de Contrato'!A10 -> 0 | B10: ='Itens de Contrato'!B10 -> 0 | C10: =VLOOKUP(B10,'Itens de Contrato'!B$5:G$151,2,0) -> #N/A | E10: =D10*'Itens de Contrato'!F10 -> 0 | F10: ='Itens de Contrato'!E10 -> 0 | H10: =G10/D10 -> #DIV/0! | I10: =G10*'Itens de Contrato'!F10 -> 0
A11: ='Itens de Contrato'!A11 -> 0 | B11: ='Itens de Contrato'!B11 -> 0 | C11: =VLOOKUP(B11,'Itens de Contrato'!B$5:G$151,2,0) -> #N/A | E11: =D11*'Itens de Contrato'!F11 -> 0 | F11: ='Itens de Contrato'!E11 -> 0 | H11: =G11/D11 -> #DIV/0! | I11: =G11*'Itens de Contrato'!F11 -> 0
A12: ='Itens de Contrato'!A12 -> 0 | B12: ='Itens de Contrato'!B12 -> 0 | C12: =VLOOKUP(B12,'Itens de Contrato'!B$5:G$151,2,0) -> #N/A | E12: =D12*'Itens de Contrato'!F12 -> 0 | F12: ='Itens de Contrato'!E12 -> 0 | H12: =G12/D12 -> #DIV/0! | I12: =G12*'Itens de Contrato'!F12 -> 0
A13: ='Itens de Contrato'!A13 -> 0 | B13: ='Itens de Contrato'!B13 -> 0 | C13: =VLOOKUP(B13,'Itens de Contrato'!B$5:G$151,2,0) -> #N/A | E13: =D13*'Itens de Contrato'!F13 -> 0 | F13: ='Itens de Contrato'!E13 -> 0 | H13: =G13/D13 -> #DIV/0! | I13: =G13*'Itens de Contrato'!F13 -> 0
A14: ='Itens de Contrato'!A14 -> 0 | B14: ='Itens de Contrato'!B14 -> 0 | C14: =VLOOKUP(B14,'Itens de Contrato'!B$5:G$151,2,0) -> #N/A | E14: =D14*'Itens de Contrato'!F14 -> 0 | F14: ='Itens de Contrato'!E14 -> 0 | H14: =G14/D14 -> #DIV/0! | I14: =G14*'Itens de Contrato'!F14 -> 0
A15: ='Itens de Contrato'!A15 -> 0 | B15: ='Itens de Contrato'!B15 -> 0 | C15: =VLOOKUP(B15,'Itens de Contrato'!B$5:G$151,2,0) -> #N/A | E15: =D15*'Itens de Contrato'!F15 -> 0 | F15: ='Itens de Contrato'!E15 -> 0 | H15: =G15/D15 -> #DIV/0! | I15: =G15*'Itens de Contrato'!F15 -> 0
A16: ='Itens de Contrato'!A16 -> 0 | B16: ='Itens de Contrato'!B16 -> 0 | C16: =VLOOKUP(B16,'Itens de Contrato'!B$5:G$151,2,0) -> #N/A | E16: =D16*'Itens de Contrato'!F16 -> 0 | F16: ='Itens de Contrato'!E16 -> 0 | H16: =G16/D16 -> #DIV/0! | I16: =G16*'Itens de Contrato'!F16 -> 0
A17: ='Itens de Contrato'!A17 -> 0 | B17: ='Itens de Contrato'!B17 -> 0 | C17: =VLOOKUP(B17,'Itens de Contrato'!B$5:G$151,2,0) -> #N/A | E17: =D17*'Itens de Contrato'!F17 -> 0 | F17: ='Itens de Contrato'!E17 -> 0 | H17: =G17/D17 -> #DIV/0! | I17: =G17*'Itens de Contrato'!F17 -> 0
... A151: ='Itens de Contrato'!A151 -> 0 | B151: ='Itens de Contrato'!B151 -> 0 | C151: =VLOOKUP(B151,'Itens de Contrato'!B$5:G$151,2,0) -> #N/A | E151: =D151*'Itens de Contrato'!F151 -> 0 | F151: ='Itens de Contrato'!E151 -> 0 | H151: =G151/D151 -> #DIV/0! | I151: =G151*'Itens de Contrato'!F151 -> 0

Sheet Medição 02
E1: OBRA | F1: ='Cadastro Institucional'!D$6 -> 0 | G1: ='Cadastro Institucional'!D$7 -> 0
A2: CNPJ | B2: Razão Social | C2: Inscrição Estadual | D2: Responsável | E2: Cargo | F2: Telefone | G2: E-mail | H2: Medição Nº | I2: Período
A3: ='Cadastro Institucional'!D$10 -> 0 | B3: ='Cadastro Institucional'!D$9 -> 0 | C3: ='Cadastro Institucional'!D$11 -> 0 | D3: ='Cadastro Institucional'!D$12 -> 0 | E3: ='Cadastro Institucional'!D$13 -> 0 | F3: ='Cadastro Institucional'!D$14 -> 0 | G3: ='Cadastro Institucional'!D$15 -> 0
A5: Etapa | B5: Item | C5: Descrição | D5: Quantidade Contratada | E5: Valor Contratado | F5: Saldo Total à Medir | G5: Quantidade Executada | H5: % Executado | I5: Valor Executado | K5: Preencha apenas as células com esse azul claro como cor de fundo!
A6: ='Itens de Contrato'!A6 -> 0 | B6: ='Itens de Contrato'!B6 -> 0 | C6: =VLOOKUP(B6,'Itens de Contrato'!B$5:G$151,2,0) -> #N/A | E6: =D6*'Itens de Contrato'!F6 -> 0 | F6: ='Medição 01'!F6-'Medição 01'!G6 -> 0 | H6: =G6/D6 -> #DIV/0! | I6: =G6*'Itens de Contrato'!F6 -> 0
A7: ='Itens de Contrato'!A7 -> 0 | B7: ='Itens de Contrato'!B7 -> 0 | C7: =VLOOKUP(B7,'Itens de Contrato'!B$5:G$151,2,0) -> #N/A | E7: =D7*'Itens de Contrato'!F7 -> 0 | F7: ='Medição 01'!F7-'Medição 01'!G7 -> 0 | H7: =G7/D7 -> #DIV/0! | I7: =G7*'Itens de Contrato'!F7 -> 0
A8: ='Itens de Contrato'!A8 -> 0 | B8: ='Itens de Contrato'!B8 -> 0 | C8: =VLOOKUP(B8,'Itens de Contrato'!B$5:G$151,2,0) -> #N/A | E8: =D8*'Itens de Contrato'!F8 -> 0 | F8: ='Medição 01'!F8-'Medição 01'!G8 -> 0 | H8: =G8/D8 -> #DIV/0! | I8: =G8*'Itens de Contrato'!F8 -> 0
A9: ='Itens de Contrato'!A9 -> 0 | B9: ='Itens de Contrato'!B9 -> 0 | C9: =VLOOKUP(B9,'Itens de Contrato'!B$5:G$151,2,0) -> #N/A | E9: =D9*'Itens de Contrato'!F9 -> 0 | F9: ='Medição 01'!F9-'Medição 01'!G9 -> 0 | H9: =G9/D9 -> #DIV/0! | I9: =G9*'Itens de Contrato'!F9 -> 0
A10: ='Itens de Contrato'!A10 -> 0 | B10: ='Itens de Contrato'!B10 -> 0 | C10: =VLOOKUP(B10,'Itens de Contrato'!B$5:G$151,2,0) -> #N/A | E10: =D10*'Itens de Contrato'!F10 -> 0 | F10: ='Medição 01'!F10-'Medição 01'!G10 -> 0 | H10: =G10/D10 -> #DIV/0! | I10: =G10*'Itens de Contrato'!F10 -> 0
A11: ='Itens de Contrato'!A11 -> 0 | B11: ='Itens de Contrato'!B11 -> 0 | C11: =VLOOKUP(B11,'Itens de Contrato'!B$5:G$151,2,0) -> #N/A | E11: =D11*'Itens de Contrato'!F11 -> 0 | F11: ='Medição 01'!F11-'Medição 01'!G11 -> 0 | H11: =G11/D11 -> #DIV/0! | I11: =G11*'Itens de Contrato'!F11 -> 0
A12: ='Itens de Contrato'!A12 -> 0 | B12: ='Itens de Contrato'!B12 -> 0 | C12: =VLOOKUP(B12,'Itens de Contrato'!B$5:G$151,2,0) -> #N/A | E12: =D12*'Itens de Contrato'!F12 -> 0 | F12: ='Medição 01'!F12-'Medição 01'!G12 -> 0 | H12: =G12/D12 -> #DIV/0! | I12: =G12*'Itens de Contrato'!F12 -> 0
A13: ='Itens de Contrato'!A13 -> 0 | B13: ='Itens de Contrato'!B13 -> 0 | C13: =VLOOKUP(B13,'Itens de Contrato'!B$5:G$151,2,0) -> #N/A | E13: =D13*'Itens de Contrato'!F13 -> 0 | F13: ='Medição 01'!F13-'Medição 01'!G13 -> 0 | H13: =G13/D13 -> #DIV/0! | I13: =G13*'Itens de Contrato'!F13 -> 0
A14: ='Itens de Contrato'!A14 -> 0 | B14: ='Itens de Contrato'!B14 -> 0 | C14: =VLOOKUP(B14,'Itens de Contrato'!B$5:G$151,2,0) -> #N/A | E14: =D14*'Itens de Contrato'!F14 -> 0 | F14: ='Medição 01'!F14-'Medição 01'!G14 -> 0 | H14: =G14/D14 -> #DIV/0! | I14: =G14*'Itens de Contrato'!F14 -> 0
A15: ='Itens de Contrato'!A15 -> 0 | B15: ='Itens de Contrato'!B15 -> 0 | C15: =VLOOKUP(B15,'Itens de Contrato'!B$5:G$151,2,0) -> #N/A | E15: =D15*'Itens de Contrato'!F15 -> 0 | F15: ='Medição 01'!F15-'Medição 01'!G15 -> 0 | H15: =G15/D15 -> #DIV/0! | I15: =G15*'Itens de Contrato'!F15 -> 0
A16: ='Itens de Contrato'!A16 -> 0 | B16: ='Itens de Contrato'!B16 -> 0 | C16: =VLOOKUP(B16,'Itens de Contrato'!B$5:G$151,2,0) -> #N/A | E16: =D16*'Itens de Contrato'!F16 -> 0 | F16: ='Medição 01'!F16-'Medição 01'!G16 -> 0 | H16: =G16/D16 -> #DIV/0! | I16: =G16*'Itens de Contrato'!F16 -> 0
A17: ='Itens de Contrato'!A17 -> 0 | B17: ='Itens de Contrato'!B17 -> 0 | C17: =VLOOKUP(B17,'Itens de Contrato'!B$5:G$151,2,0) -> #N/A | E17: =D17*'Itens de Contrato'!F17 -> 0 | F17: ='Medição 01'!F17-'Medição 01'!G17 -> 0 | H17: =G17/D17 -> #DIV/0! | I17: =G17*'Itens de Contrato'!F17 -> 0
... A151: ='Itens de Contrato'!A151 -> 0 | B151: ='Itens de Contrato'!B151 -> 0 | C151: =VLOOKUP(B151,'Itens de Contrato'!B$5:G$151,2,0) -> #N/A | E151: =D151*'Itens de Contrato'!F151 -> 0 | F151: ='Medição 01'!F151-'Medição 01'!G151 -> 0 | H151: =G151/D151 -> #DIV/0! | I151: =G151*'Itens de Contrato'!F151 -> 0

Sheet Medição 03
E1: OBRA | F1: ='Cadastro Institucional'!D$6 -> 0 | G1: ='Cadastro Institucional'!D$7 -> 0
A2: CNPJ | B2: Razão Social | C2: Inscrição Estadual | D2: Responsável | E2: Cargo | F2: Telefone | G2: E-mail | H2: Medição Nº | I2: Período
A3: ='Cadastro Institucional'!D$10 -> 0 | B3: ='Cadastro Institucional'!D$9 -> 0 | C3: ='Cadastro Institucional'!D$11 -> 0 | D3: ='Cadastro Institucional'!D$12 -> 0 | E3: ='Cadastro Institucional'!D$13 -> 0 | F3: ='Cadastro Institucional'!D$14 -> 0 | G3: ='Cadastro Institucional'!D$15 -> 0
A5: Etapa | B5: Item | C5: Descrição | D5: Quantidade Contratada | E5: Valor Contratado | F5: Saldo Total à Medir | G5: Quantidade Executada | H5: % Executado | I5: Valor Executado | K5: Preencha apenas as células com esse azul claro como cor de fundo!
A6: ='Itens de Contrato'!A6 -> 0 | B6: ='Itens de Contrato'!B6 -> 0 | C6: =VLOOKUP(B6,'Itens de Contrato'!B$5:G$151,2,0) -> #N/A | E6: =D6*'Itens de Contrato'!F6 -> 0 | F6: ='Medição 02'!F6-'Medição 02'!G6 -> 0 | H6: =G6/D6 -> #DIV/0! | I6: =G6*'Itens de Contrato'!F6 -> 0
A7: ='Itens de Contrato'!A7 -> 0 | B7: ='Itens de Contrato'!B7 -> 0 | C7: =VLOOKUP(B7,'Itens de Contrato'!B$5:G$151,2,0) -> #N/A | E7: =D7*'Itens de Contrato'!F7 -> 0 | F7: ='Medição 02'!F7-'Medição 02'!G7 -> 0 | H7: =G7/D7 -> #DIV/0! | I7: =G7*'Itens de Contrato'!F7 -> 0
A8: ='Itens de Contrato'!A8 -> 0 | B8: ='Itens de Contrato'!B8 -> 0 | C8: =VLOOKUP(B8,'Itens de Contrato'!B$5:G$151,2,0) -> #N/A | E8: =D8*'Itens de Contrato'!F8 -> 0 | F8: ='Medição 02'!F8-'Medição 02'!G8 -> 0 | H8: =G8/D8 -> #DIV/0! | I8: =G8*'Itens de Contrato'!F8 -> 0
A9: ='Itens de Contrato'!A9 -> 0 | B9: ='Itens de Contrato'!B9 -> 0 | C9: =VLOOKUP(B9,'Itens de Contrato'!B$5:G$151,2,0) -> #N/A | E9: =D9*'Itens de Contrato'!F9 -> 0 | F9: ='Medição 02'!F9-'Medição 02'!G9 -> 0 | H9: =G9/D9 -> #DIV/0! | I9: =G9*'Itens de Contrato'!F9 -> 0
A10: ='Itens de Contrato'!A10 -> 0 | B10: ='Itens de Contrato'!B10 -> 0 | C10: =VLOOKUP(B10,'Itens de Contrato'!B$5:G$151,2,0) -> #N/A | E10: =D10*'Itens de Contrato'!F10 -> 0 | F10: ='Medição 02'!F10-'Medição 02'!G10 -> 0 | H10: =G10/D10 -> #DIV/0! | I10: =G10*'Itens de Contrato'!F10 -> 0
A11: ='Itens de Contrato'!A11 -> 0 | B11: ='Itens de Contrato'!B11 -> 0 | C11: =VLOOKUP(B11,'Itens de Contrato'!B$5:G$151,2,0) -> #N/A | E11: =D11*'Itens de Contrato'!F11 -> 0 | F11: ='Medição 02'!F11-'Medição 02'!G11 -> 0 | H11: =G11/D11 -> #DIV/0! | I11: =G11*'Itens de Contrato'!F11 -> 0
A12: ='Itens de Contrato'!A12 -> 0 | B12: ='Itens de Contrato'!B12 -> 0 | C12: =VLOOKUP(B12,'Itens de Contrato'!B$5:G$151,2,0) -> #N/A | E12: =D12*'Itens de Contrato'!F12 -> 0 | F12: ='Medição 02'!F12-'Medição 02'!G12 -> 0 | H12: =G12/D12 -> #DIV/0! | I12: =G12*'Itens de Contrato'!F12 -> 0
A13: ='Itens de Contrato'!A13 -> 0 | B13: ='Itens de Contrato'!B13 -> 0 | C13: =VLOOKUP(B13,'Itens de Contrato'!B$5:G$151,2,0) -> #N/A | E13: =D13*'Itens de Contrato'!F13 -> 0 | F13: ='Medição 02'!F13-'Medição 02'!G13 -> 0 | H13: =G13/D13 -> #DIV/0! | I13: =G13*'Itens de Contrato'!F13 -> 0
A14: ='Itens de Contrato'!A14 -> 0 | B14: ='Itens de Contrato'!B14 -> 0 | C14: =VLOOKUP(B14,'Itens de Contrato'!B$5:G$151,2,0) -> #N/A | E14: =D14*'Itens de Contrato'!F14 -> 0 | F14: ='Medição 02'!F14-'Medição 02'!G14 -> 0 | H14: =G14/D14 -> #DIV/0! | I14: =G14*'Itens de Contrato'!F14 -> 0
A15: ='Itens de Contrato'!A15 -> 0 | B15: ='Itens de Contrato'!B15 -> 0 | C15: =VLOOKUP(B15,'Itens de Contrato'!B$5:G$151,2,0) -> #N/A | E15: =D15*'Itens de Contrato'!F15 -> 0 | F15: ='Medição 02'!F15-'Medição 02'!G15 -> 0 | H15: =G15/D15 -> #DIV/0! | I15: =G15*'Itens de Contrato'!F15 -> 0
A16: ='Itens de Contrato'!A16 -> 0 | B16: ='Itens de Contrato'!B16 -> 0 | C16: =VLOOKUP(B16,'Itens de Contrato'!B$5:G$151,2,0) -> #N/A | E16: =D16*'Itens de Contrato'!F16 -> 0 | F16: ='Medição 02'!F16-'Medição 02'!G16 -> 0 | H16: =G16/D16 -> #DIV/0! | I16: =G16*'Itens de Contrato'!F16 -> 0
A17: ='Itens de Contrato'!A17 -> 0 | B17: ='Itens de Contrato'!B17 -> 0 | C17: =VLOOKUP(B17,'Itens de Contrato'!B$5:G$151,2,0) -> #N/A | E17: =D17*'Itens de Contrato'!F17 -> 0 | F17: ='Medição 02'!F17-'Medição 02'!G17 -> 0 | H17: =G17/D17 -> #DIV/0! | I17: =G17*'Itens de Contrato'!F17 -> 0
... A151: ='Itens de Contrato'!A151 -> 0 | B151: ='Itens de Contrato'!B151 -> 0 | C151: =VLOOKUP(B151,'Itens de Contrato'!B$5:G$151,2,0) -> #N/A | E151: =D151*'Itens de Contrato'!F151 -> 0 | F151: ='Medição 02'!F151-'Medição 02'!G151 -> 0 | H151: =G151/D151 -> #DIV/0! | I151: =G151*'Itens de Contrato'!F151 -> 0

Sheet Medição 04
E1: OBRA | F1: ='Cadastro Institucional'!D$6 -> 0 | G1: ='Cadastro Institucional'!D$7 -> 0
A2: CNPJ | B2: Razão Social | C2: Inscrição Estadual | D2: Responsável | E2: Cargo | F2: Telefone | G2: E-mail | H2: Medição Nº | I2: Período
A3: ='Cadastro Institucional'!D$10 -> 0 | B3: ='Cadastro Institucional'!D$9 -> 0 | C3: ='Cadastro Institucional'!D$11 -> 0 | D3: ='Cadastro Institucional'!D$12 -> 0 | E3: ='Cadastro Institucional'!D$13 -> 0 | F3: ='Cadastro Institucional'!D$14 -> 0 | G3: ='Cadastro Institucional'!D$15 -> 0
A5: Etapa | B5: Item | C5: Descrição | D5: Quantidade Contratada | E5: Valor Contratado | F5: Saldo Total à Medir | G5: Quantidade Executada | H5: % Executado | I5: Valor Executado | K5: Preencha apenas as células com esse azul claro como cor de fundo!
A6: ='Itens de Contrato'!A6 -> 0 | B6: ='Itens de Contrato'!B6 -> 0 | C6: =VLOOKUP(B6,'Itens de Contrato'!B$5:G$151,2,0) -> #N/A | E6: =D6*'Itens de Contrato'!F6 -> 0 | F6: ='Medição 03'!F6-'Medição 03'!G6 -> 0 | H6: =G6/D6 -> #DIV/0! | I6: =G6*'Itens de Contrato'!F6 -> 0
A7: ='Itens de Contrato'!A7 -> 0 | B7: ='Itens de Contrato'!B7 -> 0 | C7: =VLOOKUP(B7,'Itens de Contrato'!B$5:G$151,2,0) -> #N/A | E7: =D7*'Itens de Contrato'!F7 -> 0 | F7: ='Medição 02'!F7-'Medição 02'!G7 -> 0 | H7: =G7/D7 -> #DIV/0! | I7: =G7*'Itens de Contrato'!F7 -> 0
A8: ='Itens de Contrato'!A8 -> 0 | B8: ='Itens de Contrato'!B8 -> 0 | C8: =VLOOKUP(B8,'Itens de Contrato'!B$5:G$151,2,0) -> #N/A | E8: =D8*'Itens de Contrato'!F8 -> 0 | F8: ='Medição 02'!F8-'Medição 02'!G8 -> 0 | H8: =G8/D8 -> #DIV/0! | I8: =G8*'Itens de Contrato'!F8 -> 0
A9: ='Itens de Contrato'!A9 -> 0 | B9: ='Itens de Contrato'!B9 -> 0 | C9: =VLOOKUP(B9,'Itens de Contrato'!B$5:G$151,2,0) -> #N/A | E9: =D9*'Itens de Contrato'!F9 -> 0 | F9: ='Medição 02'!F9-'Medição 02'!G9 -> 0 | H9: =G9/D9 -> #DIV/0! | I9: =G9*'Itens de Contrato'!F9 -> 0
A10: ='Itens de Contrato'!A10 -> 0 | B10: ='Itens de Contrato'!B10 -> 0 | C10: =VLOOKUP(B10,'Itens de Contrato'!B$5:G$151,2,0) -> #N/A | E10: =D10*'Itens de Contrato'!F10 -> 0 | F10: ='Medição 02'!F10-'Medição 02'!G10 -> 0 | H10: =G10/D10 -> #DIV/0! | I10: =G10*'Itens de Contrato'!F10 -> 0
A11: ='Itens de Contrato'!A11 -> 0 | B11: ='Itens de Contrato'!B11 -> 0 | C11: =VLOOKUP(B11,'Itens de Contrato'!B$5:G$151,2,0) -> #N/A | E11: =D11*'Itens de Contrato'!F11 -> 0 | F11: ='Medição 02'!F11-'Medição 02'!G11 -> 0 | H11: =G11/D11 -> #DIV/0! | I11: =G11*'Itens de Contrato'!F11 -> 0
A12: ='Itens de Contrato'!A12 -> 0 | B12: ='Itens de Contrato'!B12 -> 0 | C12: =VLOOKUP(B12,'Itens de Contrato'!B$5:G$151,2,0) -> #N/A | E12: =D12*'Itens de Contrato'!F12 -> 0 | F12: ='Medição 02'!F12-'Medição 02'!G12 -> 0 | H12: =G12/D12 -> #DIV/0! | I12: =G12*'Itens de Contrato'!F12 -> 0
A13: ='Itens de Contrato'!A13 -> 0 | B13: ='Itens de Contrato'!B13 -> 0 | C13: =VLOOKUP(B13,'Itens de Contrato'!B$5:G$151,2,0) -> #N/A | E13: =D13*'Itens de Contrato'!F13 -> 0 | F13: ='Medição 02'!F13-'Medição 02'!G13 -> 0 | H13: =G13/D13 -> #DIV/0! | I13: =G13*'Itens de Contrato'!F13 -> 0
A14: ='Itens de Contrato'!A14 -> 0 | B14: ='Itens de Contrato'!B14 -> 0 | C14: =VLOOKUP(B14,'Itens de Contrato'!B$5:G$151,2,0) -> #N/A | E14: =D14*'Itens de Contrato'!F14 -> 0 | F14: ='Medição 02'!F14-'Medição 02'!G14 -> 0 | H14: =G14/D14 -> #DIV/0! | I14: =G14*'Itens de Contrato'!F14 -> 0
A15: ='Itens de Contrato'!A15 -> 0 | B15: ='Itens de Contrato'!B15 -> 0 | C15: =VLOOKUP(B15,'Itens de Contrato'!B$5:G$151,2,0) -> #N/A | E15: =D15*'Itens de Contrato'!F15 -> 0 | F15: ='Medição 02'!F15-'Medição 02'!G15 -> 0 | H15: =G15/D15 -> #DIV/0! | I15: =G15*'Itens de Contrato'!F15 -> 0
A16: ='Itens de Contrato'!A16 -> 0 | B16: ='Itens de Contrato'!B16 -> 0 | C16: =VLOOKUP(B16,'Itens de Contrato'!B$5:G$151,2,0) -> #N/A | E16: =D16*'Itens de Contrato'!F16 -> 0 | F16: ='Medição 02'!F16-'Medição 02'!G16 -> 0 | H16: =G16/D16 -> #DIV/0! | I16: =G16*'Itens de Contrato'!F16 -> 0
A17: ='Itens de Contrato'!A17 -> 0 | B17: ='Itens de Contrato'!B17 -> 0 | C17: =VLOOKUP(B17,'Itens de Contrato'!B$5:G$151,2,0) -> #N/A | E17: =D17*'Itens de Contrato'!F17 -> 0 | F17: ='Medição 02'!F17-'Medição 02'!G17 -> 0 | H17: =G17/D17 -> #DIV/0! | I17: =G17*'Itens de Contrato'!F17 -> 0
A18: ='Itens de Contrato'!A18 -> 0 | B18: ='Itens de Contrato'!B18 -> 0 | C18: =VLOOKUP(B18,'Itens de Contrato'!B$5:G$151,2,0) -> #N/A | E18: =D18*'Itens de Contrato'!F18 -> 0 | F18: ='Medição 02'!F18-'Medição 02'!G18 -> 0 | H18: =G18/D18 -> #DIV/0! | I18: =G18*'Itens de Contrato'!F18 -> 0
... A151: ='Itens de Contrato'!A151 -> 0 | B151: ='Itens de Contrato'!B151 -> 0 | C151: =VLOOKUP(B151,'Itens de Contrato'!B$5:G$151,2,0) -> #N/A | E151: =D151*'Itens de Contrato'!F151 -> 0 | F151: ='Medição 02'!F151-'Medição 02'!G151 -> 0 | H151: =G151/D151 -> #DIV/0! | I151: =G151*'Itens de Contrato'!F151 -> 0

Sheet Medição 05
E1: OBRA | F1: ='Cadastro Institucional'!D$6 -> 0 | G1: ='Cadastro Institucional'!D$7 -> 0
A2: CNPJ | B2: Razão Social | C2: Inscrição Estadual | D2: Responsável | E2: Cargo | F2: Telefone | G2: E-mail | H2: Medição Nº | I2: Período
A3: ='Cadastro Institucional'!D$10 -> 0 | B3: ='Cadastro Institucional'!D$9 -> 0 | C3: ='Cadastro Institucional'!D$11 -> 0 | D3: ='Cadastro Institucional'!D$12 -> 0 | E3: ='Cadastro Institucional'!D$13 -> 0 | F3: ='Cadastro Institucional'!D$14 -> 0 | G3: ='Cadastro Institucional'!D$15 -> 0
A5: Etapa | B5: Item | C5: Descrição | D5: Quantidade Contratada | E5: Valor Contratado | F5: Saldo Total à Medir | G5: Quantidade Executada | H5: % Executado | I5: Valor Executado | K5: Preencha apenas as células com esse azul claro como cor de fundo!
A6: ='Itens de Contrato'!A6 -> 0 | B6: ='Itens de Contrato'!B6 -> 0 | C6: =VLOOKUP(B6,'Itens de Contrato'!B$5:G$151,2,0) -> #N/A | E6: =D6*'Itens de Contrato'!F6 -> 0 | F6: ='Medição 04'!F6-'Medição 04'!G6 -> 0 | H6: =G6/D6 -> #DIV/0! | I6: =G6*'Itens de Contrato'!F6 -> 0
A7: ='Itens de Contrato'!A7 -> 0 | B7: ='Itens de Contrato'!B7 -> 0 | C7: =VLOOKUP(B7,'Itens de Contrato'!B$5:G$151,2,0) -> #N/A | E7: =D7*'Itens de Contrato'!F7 -> 0 | F7: ='Medição 04'!F7-'Medição 04'!G7 -> 0 | H7: =G7/D7 -> #DIV/0! | I7: =G7*'Itens de Contrato'!F7 -> 0
A8: ='Itens de Contrato'!A8 -> 0 | B8: ='Itens de Contrato'!B8 -> 0 | C8: =VLOOKUP(B8,'Itens de Contrato'!B$5:G$151,2,0) -> #N/A | E8: =D8*'Itens de Contrato'!F8 -> 0 | F8: ='Medição 04'!F8-'Medição 04'!G8 -> 0 | H8: =G8/D8 -> #DIV/0! | I8: =G8*'Itens de Contrato'!F8 -> 0
A9: ='Itens de Contrato'!A9 -> 0 | B9: ='Itens de Contrato'!B9 -> 0 | C9: =VLOOKUP(B9,'Itens de Contrato'!B$5:G$151,2,0) -> #N/A | E9: =D9*'Itens de Contrato'!F9 -> 0 | F9: ='Medição 04'!F9-'Medição 04'!G9 -> 0 | H9: =G9/D9 -> #DIV/0! | I9: =G9*'Itens de Contrato'!F9 -> 0
A10: ='Itens de Contrato'!A10 -> 0 | B10: ='Itens de Contrato'!B10 -> 0 | C10: =VLOOKUP(B10,'Itens de Contrato'!B$5:G$151,2,0) -> #N/A | E10: =D10*'Itens de Contrato'!F10 -> 0 | F10: ='Medição 04'!F10-'Medição 04'!G10 -> 0 | H10: =G10/D10 -> #DIV/0! | I10: =G10*'Itens de Contrato'!F10 -> 0
A11: ='Itens de Contrato'!A11 -> 0 | B11: ='Itens de Contrato'!B11 -> 0 | C11: =VLOOKUP(B11,'Itens de Contrato'!B$5:G$151,2,0) -> #N/A | E11: =D11*'Itens de Contrato'!F11 -> 0 | F11: ='Medição 04'!F11-'Medição 04'!G11 -> 0 | H11: =G11/D11 -> #DIV/0! | I11: =G11*'Itens de Contrato'!F11 -> 0
A12: ='Itens de Contrato'!A12 -> 0 | B12: ='Itens de Contrato'!B12 -> 0 | C12: =VLOOKUP(B12,'Itens de Contrato'!B$5:G$151,2,0) -> #N/A | E12: =D12*'Itens de Contrato'!F12 -> 0 | F12: ='Medição 04'!F12-'Medição 04'!G12 -> 0 | H12: =G12/D12 -> #DIV/0! | I12: =G12*'Itens de Contrato'!F12 -> 0
A13: ='Itens de Contrato'!A13 -> 0 | B13: ='Itens de Contrato'!B13 -> 0 | C13: =VLOOKUP(B13,'Itens de Contrato'!B$5:G$151,2,0) -> #N/A | E13: =D13*'Itens de Contrato'!F13 -> 0 | F13: ='Medição 04'!F13-'Medição 04'!G13 -> 0 | H13: =G13/D13 -> #DIV/0! | I13: =G13*'Itens de Contrato'!F13 -> 0
A14: ='Itens de Contrato'!A14 -> 0 | B14: ='Itens de Contrato'!B14 -> 0 | C14: =VLOOKUP(B14,'Itens de Contrato'!B$5:G$151,2,0) -> #N/A | E14: =D14*'Itens de Contrato'!F14 -> 0 | F14: ='Medição 04'!F14-'Medição 04'!G14 -> 0 | H14: =G14/D14 -> #DIV/0! | I14: =G14*'Itens de Contrato'!F14 -> 0
A15: ='Itens de Contrato'!A15 -> 0 | B15: ='Itens de Contrato'!B15 -> 0 | C15: =VLOOKUP(B15,'Itens de Contrato'!B$5:G$151,2,0) -> #N/A | E15: =D15*'Itens de Contrato'!F15 -> 0 | F15: ='Medição 04'!F15-'Medição 04'!G15 -> 0 | H15: =G15/D15 -> #DIV/0! | I15: =G15*'Itens de Contrato'!F15 -> 0
A16: ='Itens de Contrato'!A16 -> 0 | B16: ='Itens de Contrato'!B16 -> 0 | C16: =VLOOKUP(B16,'Itens de Contrato'!B$5:G$151,2,0) -> #N/A | E16: =D16*'Itens de Contrato'!F16 -> 0 | F16: ='Medição 04'!F16-'Medição 04'!G16 -> 0 | H16: =G16/D16 -> #DIV/0! | I16: =G16*'Itens de Contrato'!F16 -> 0
A17: ='Itens de Contrato'!A17 -> 0 | B17: ='Itens de Contrato'!B17 -> 0 | C17: =VLOOKUP(B17,'Itens de Contrato'!B$5:G$151,2,0) -> #N/A | E17: =D17*'Itens de Contrato'!F17 -> 0 | F17: ='Medição 04'!F17-'Medição 04'!G17 -> 0 | H17: =G17/D17 -> #DIV/0! | I17: =G17*'Itens de Contrato'!F17 -> 0
... A151: ='Itens de Contrato'!A151 -> 0 | B151: ='Itens de Contrato'!B151 -> 0 | C151: =VLOOKUP(B151,'Itens de Contrato'!B$5:G$151,2,0) -> #N/A | E151: =D151*'Itens de Contrato'!F151 -> 0 | F151: ='Medição 04'!F151-'Medição 04'!G151 -> 0 | H151: =G151/D151 -> #DIV/0! | I151: =G151*'Itens de Contrato'!F151 -> 0

Sheet Medição 06
E1: OBRA | F1: ='Cadastro Institucional'!D$6 -> 0 | G1: ='Cadastro Institucional'!D$7 -> 0
A2: CNPJ | B2: Razão Social | C2: Inscrição Estadual | D2: Responsável | E2: Cargo | F2: Telefone | G2: E-mail | H2: Medição Nº | I2: Período
A3: ='Cadastro Institucional'!D$10 -> 0 | B3: ='Cadastro Institucional'!D$9 -> 0 | C3: ='Cadastro Institucional'!D$11 -> 0 | D3: ='Cadastro Institucional'!D$12 -> 0 | E3: ='Cadastro Institucional'!D$13 -> 0 | F3: ='Cadastro Institucional'!D$14 -> 0 | G3: ='Cadastro Institucional'!D$15 -> 0
A5: Etapa | B5: Item | C5: Descrição | D5: Quantidade Contratada | E5: Valor Contratado | F5: Saldo Total à Medir | G5: Quantidade Executada | H5: % Executado | I5: Valor Executado | K5: Preencha apenas as células com esse azul claro como cor de fundo!
A6: ='Itens de Contrato'!A6 -> 0 | B6: ='Itens de Contrato'!B6 -> 0 | C6: =VLOOKUP(B6,'Itens de Contrato'!B$5:G$151,2,0) -> #N/A | E6: =D6*'Itens de Contrato'!F6 -> 0 | F6: ='Medição 05'!F6-'Medição 05'!G6 -> 0 | H6: =G6/D6 -> #DIV/0! | I6: =G6*'Itens de Contrato'!F6 -> 0
A7: ='Itens de Contrato'!A7 -> 0 | B7: ='Itens de Contrato'!B7 -> 0 | C7: =VLOOKUP(B7,'Itens de Contrato'!B$5:G$151,2,0) -> #N/A | E7: =D7*'Itens de Contrato'!F7 -> 0 | F7: ='Medição 05'!F7-'Medição 05'!G7 -> 0 | H7: =G7/D7 -> #DIV/0! | I7: =G7*'Itens de Contrato'!F7 -> 0
A8: ='Itens de Contrato'!A8 -> 0 | B8: ='Itens de Contrato'!B8 -> 0 | C8: =VLOOKUP(B8,'Itens de Contrato'!B$5:G$151,2,0) -> #N/A | E8: =D8*'Itens de Contrato'!F8 -> 0 | F8: ='Medição 05'!F8-'Medição 05'!G8 -> 0 | H8: =G8/D8 -> #DIV/0! | I8: =G8*'Itens de Contrato'!F8 -> 0
A9: ='Itens de Contrato'!A9 -> 0 | B9: ='Itens de Contrato'!B9 -> 0 | C9: =VLOOKUP(B9,'Itens de Contrato'!B$5:G$151,2,0) -> #N/A | E9: =D9*'Itens de Contrato'!F9 -> 0 | F9: ='Medição 05'!F9-'Medição 05'!G9 -> 0 | H9: =G9/D9 -> #DIV/0! | I9: =G9*'Itens de Contrato'!F9 -> 0
A10: ='Itens de Contrato'!A10 -> 0 | B10: ='Itens de Contrato'!B10 -> 0 | C10: =VLOOKUP(B10,'Itens de Contrato'!B$5:G$151,2,0) -> #N/A | E10: =D10*'Itens de Contrato'!F10 -> 0 | F10: ='Medição 05'!F10-'Medição 05'!G10 -> 0 | H10: =G10/D10 -> #DIV/0! | I10: =G10*'Itens de Contrato'!F10 -> 0
A11: ='Itens de Contrato'!A11 -> 0 | B11: ='Itens de Contrato'!B11 -> 0 | C11: =VLOOKUP(B11,'Itens de Contrato'!B$5:G$151,2,0) -> #N/A | E11: =D11*'Itens de Contrato'!F11 -> 0 | F11: ='Medição 05'!F11-'Medição 05'!G11 -> 0 | H11: =G11/D11 -> #DIV/0! | I11: =G11*'Itens de Contrato'!F11 -> 0
A12: ='Itens de Contrato'!A12 -> 0 | B12: ='Itens de Contrato'!B12 -> 0 | C12: =VLOOKUP(B12,'Itens de Contrato'!B$5:G$151,2,0) -> #N/A | E12: =D12*'Itens de Contrato'!F12 -> 0 | F12: ='Medição 05'!F12-'Medição 05'!G12 -> 0 | H12: =G12/D12 -> #DIV/0! | I12: =G12*'Itens de Contrato'!F12 -> 0
A13: ='Itens de Contrato'!A13 -> 0 | B13: ='Itens de Contrato'!B13 -> 0 | C13: =VLOOKUP(B13,'Itens de Contrato'!B$5:G$151,2,0) -> #N/A | E13: =D13*'Itens de Contrato'!F13 -> 0 | F13: ='Medição 05'!F13-'Medição 05'!G13 -> 0 | H13: =G13/D13 -> #DIV/0! | I13: =G13*'Itens de Contrato'!F13 -> 0
A14: ='Itens de Contrato'!A14 -> 0 | B14: ='Itens de Contrato'!B14 -> 0 | C14: =VLOOKUP(B14,'Itens de Contrato'!B$5:G$151,2,0) -> #N/A | E14: =D14*'Itens de Contrato'!F14 -> 0 | F14: ='Medição 05'!F14-'Medição 05'!G14 -> 0 | H14: =G14/D14 -> #DIV/0! | I14: =G14*'Itens de Contrato'!F14 -> 0
A15: ='Itens de Contrato'!A15 -> 0 | B15: ='Itens de Contrato'!B15 -> 0 | C15: =VLOOKUP(B15,'Itens de Contrato'!B$5:G$151,2,0) -> #N/A | E15: =D15*'Itens de Contrato'!F15 -> 0 | F15: ='Medição 05'!F15-'Medição 05'!G15 -> 0 | H15: =G15/D15 -> #DIV/0! | I15: =G15*'Itens de Contrato'!F15 -> 0
A16: ='Itens de Contrato'!A16 -> 0 | B16: ='Itens de Contrato'!B16 -> 0 | C16: =VLOOKUP(B16,'Itens de Contrato'!B$5:G$151,2,0) -> #N/A | E16: =D16*'Itens de Contrato'!F16 -> 0 | F16: ='Medição 05'!F16-'Medição 05'!G16 -> 0 | H16: =G16/D16 -> #DIV/0! | I16: =G16*'Itens de Contrato'!F16 -> 0
A17: ='Itens de Contrato'!A17 -> 0 | B17: ='Itens de Contrato'!B17 -> 0 | C17: =VLOOKUP(B17,'Itens de Contrato'!B$5:G$151,2,0) -> #N/A | E17: =D17*'Itens de Contrato'!F17 -> 0 | F17: ='Medição 05'!F17-'Medição 05'!G17 -> 0 | H17: =G17/D17 -> #DIV/0! | I17: =G17*'Itens de Contrato'!F17 -> 0
... A151: ='Itens de Contrato'!A151 -> 0 | B151: ='Itens de Contrato'!B151 -> 0 | C151: =VLOOKUP(B151,'Itens de Contrato'!B$5:G$151,2,0) -> #N/A | E151: =D151*'Itens de Contrato'!F151 -> 0 | F151: ='Medição 05'!F151-'Medição 05'!G151 -> 0 | H151: =G151/D151 -> #DIV/0! | I151: =G151*'Itens de Contrato'!F151 -> 0

Sheet Medição 07
E1: OBRA | F1: ='Cadastro Institucional'!D$6 -> 0 | G1: ='Cadastro Institucional'!D$7 -> 0
A2: CNPJ | B2: Razão Social | C2: Inscrição Estadual | D2: Responsável | E2: Cargo | F2: Telefone | G2: E-mail | H2: Medição Nº | I2: Período
A3: ='Cadastro Institucional'!D$10 -> 0 | B3: ='Cadastro Institucional'!D$9 -> 0 | C3: ='Cadastro Institucional'!D$11 -> 0 | D3: ='Cadastro Institucional'!D$12 -> 0 | E3: ='Cadastro Institucional'!D$13 -> 0 | F3: ='Cadastro Institucional'!D$14 -> 0 | G3: ='Cadastro Institucional'!D$15 -> 0
A5: Etapa | B5: Item | C5: Descrição | D5: Quantidade Contratada | E5: Valor Contratado | F5: Saldo Total à Medir | G5: Quantidade Executada | H5: % Executado | I5: Valor Executado | K5: Preencha apenas as células com esse azul claro como cor de fundo!
A6: ='Itens de Contrato'!A6 -> 0 | B6: ='Itens de Contrato'!B6 -> 0 | C6: =VLOOKUP(B6,'Itens de Contrato'!B$5:G$151,2,0) -> #N/A | E6: =D6*'Itens de Contrato'!F6 -> 0 | F6: ='Medição 06'!F6-'Medição 06'!G6 -> 0 | H6: =G6/D6 -> #DIV/0! | I6: =G6*'Itens de Contrato'!F6 -> 0
A7: ='Itens de Contrato'!A7 -> 0 | B7: ='Itens de Contrato'!B7 -> 0 | C7: =VLOOKUP(B7,'Itens de Contrato'!B$5:G$151,2,0) -> #N/A | E7: =D7*'Itens de Contrato'!F7 -> 0 | F7: ='Medição 06'!F7-'Medição 06'!G7 -> 0 | H7: =G7/D7 -> #DIV/0! | I7: =G7*'Itens de Contrato'!F7 -> 0
A8: ='Itens de Contrato'!A8 -> 0 | B8: ='Itens de Contrato'!B8 -> 0 | C8: =VLOOKUP(B8,'Itens de Contrato'!B$5:G$151,2,0) -> #N/A | E8: =D8*'Itens de Contrato'!F8 -> 0 | F8: ='Medição 06'!F8-'Medição 06'!G8 -> 0 | H8: =G8/D8 -> #DIV/0! | I8: =G8*'Itens de Contrato'!F8 -> 0
A9: ='Itens de Contrato'!A9 -> 0 | B9: ='Itens de Contrato'!B9 -> 0 | C9: =VLOOKUP(B9,'Itens de Contrato'!B$5:G$151,2,0) -> #N/A | E9: =D9*'Itens de Contrato'!F9 -> 0 | F9: ='Medição 06'!F9-'Medição 06'!G9 -> 0 | H9: =G9/D9 -> #DIV/0! | I9: =G9*'Itens de Contrato'!F9 -> 0
A10: ='Itens de Contrato'!A10 -> 0 | B10: ='Itens de Contrato'!B10 -> 0 | C10: =VLOOKUP(B10,'Itens de Contrato'!B$5:G$151,2,0) -> #N/A | E10: =D10*'Itens de Contrato'!F10 -> 0 | F10: ='Medição 06'!F10-'Medição 06'!G10 -> 0 | H10: =G10/D10 -> #DIV/0! | I10: =G10*'Itens de Contrato'!F10 -> 0
A11: ='Itens de Contrato'!A11 -> 0 | B11: ='Itens de Contrato'!B11 -> 0 | C11: =VLOOKUP(B11,'Itens de Contrato'!B$5:G$151,2,0) -> #N/A | E11: =D11*'Itens de Contrato'!F11 -> 0 | F11: ='Medição 06'!F11-'Medição 06'!G11 -> 0 | H11: =G11/D11 -> #DIV/0! | I11: =G11*'Itens de Contrato'!F11 -> 0
A12: ='Itens de Contrato'!A12 -> 0 | B12: ='Itens de Contrato'!B12 -> 0 | C12: =VLOOKUP(B12,'Itens de Contrato'!B$5:G$151,2,0) -> #N/A | E12: =D12*'Itens de Contrato'!F12 -> 0 | F12: ='Medição 06'!F12-'Medição 06'!G12 -> 0 | H12: =G12/D12 -> #DIV/0! | I12: =G12*'Itens de Contrato'!F12 -> 0
A13: ='Itens de Contrato'!A13 -> 0 | B13: ='Itens de Contrato'!B13 -> 0 | C13: =VLOOKUP(B13,'Itens de Contrato'!B$5:G$151,2,0) -> #N/A | E13: =D13*'Itens de Contrato'!F13 -> 0 | F13: ='Medição 06'!F13-'Medição 06'!G13 -> 0 | H13: =G13/D13 -> #DIV/0! | I13: =G13*'Itens de Contrato'!F13 -> 0
A14: ='Itens de Contrato'!A14 -> 0 | B14: ='Itens de Contrato'!B14 -> 0 | C14: =VLOOKUP(B14,'Itens de Contrato'!B$5:G$151,2,0) -> #N/A | E14: =D14*'Itens de Contrato'!F14 -> 0 | F14: ='Medição 06'!F14-'Medição 06'!G14 -> 0 | H14: =G14/D14 -> #DIV/0! | I14: =G14*'Itens de Contrato'!F14 -> 0
A15: ='Itens de Contrato'!A15 -> 0 | B15: ='Itens de Contrato'!B15 -> 0 | C15: =VLOOKUP(B15,'Itens de Contrato'!B$5:G$151,2,0) -> #N/A | E15: =D15*'Itens de Contrato'!F15 -> 0 | F15: ='Medição 06'!F15-'Medição 06'!G15 -> 0 | H15: =G15/D15 -> #DIV/0! | I15: =G15*'Itens de Contrato'!F15 -> 0
A16: ='Itens de Contrato'!A16 -> 0 | B16: ='Itens de Contrato'!B16 -> 0 | C16: =VLOOKUP(B16,'Itens de Contrato'!B$5:G$151,2,0) -> #N/A | E16: =D16*'Itens de Contrato'!F16 -> 0 | F16: ='Medição 06'!F16-'Medição 06'!G16 -> 0 | H16: =G16/D16 -> #DIV/0! | I16: =G16*'Itens de Contrato'!F16 -> 0
A17: ='Itens de Contrato'!A17 -> 0 | B17: ='Itens de Contrato'!B17 -> 0 | C17: =VLOOKUP(B17,'Itens de Contrato'!B$5:G$151,2,0) -> #N/A | E17: =D17*'Itens de Contrato'!F17 -> 0 | F17: ='Medição 06'!F17-'Medição 06'!G17 -> 0 | H17: =G17/D17 -> #DIV/0! | I17: =G17*'Itens de Contrato'!F17 -> 0
... A151: ='Itens de Contrato'!A151 -> 0 | B151: ='Itens de Contrato'!B151 -> 0 | C151: =VLOOKUP(B151,'Itens de Contrato'!B$5:G$151,2,0) -> #N/A | E151: =D151*'Itens de Contrato'!F151 -> 0 | F151: ='Medição 06'!F151-'Medição 06'!G151 -> 0 | H151: =G151/D151 -> #DIV/0! | I151: =G151*'Itens de Contrato'!F151 -> 0

Sheet Medição 08
E1: OBRA | F1: ='Cadastro Institucional'!D$6 -> 0 | G1: ='Cadastro Institucional'!D$7 -> 0
A2: CNPJ | B2: Razão Social | C2: Inscrição Estadual | D2: Responsável | E2: Cargo | F2: Telefone | G2: E-mail | H2: Medição Nº | I2: Período
A3: ='Cadastro Institucional'!D$10 -> 0 | B3: ='Cadastro Institucional'!D$9 -> 0 | C3: ='Cadastro Institucional'!D$11 -> 0 | D3: ='Cadastro Institucional'!D$12 -> 0 | E3: ='Cadastro Institucional'!D$13 -> 0 | F3: ='Cadastro Institucional'!D$14 -> 0 | G3: ='Cadastro Institucional'!D$15 -> 0
A5: Etapa | B5: Item | C5: Descrição | D5: Quantidade Contratada | E5: Valor Contratado | F5: Saldo Total à Medir | G5: Quantidade Executada | H5: % Executado | I5: Valor Executado | K5: Preencha apenas as células com esse azul claro como cor de fundo!
A6: ='Itens de Contrato'!A6 -> 0 | B6: ='Itens de Contrato'!B6 -> 0 | C6: =VLOOKUP(B6,'Itens de Contrato'!B$5:G$151,2,0) -> #N/A | E6: =D6*'Itens de Contrato'!F6 -> 0 | F6: ='Medição 07'!F6-'Medição 07'!G6 -> 0 | H6: =G6/D6 -> #DIV/0! | I6: =G6*'Itens de Contrato'!F6 -> 0
A7: ='Itens de Contrato'!A7 -> 0 | B7: ='Itens de Contrato'!B7 -> 0 | C7: =VLOOKUP(B7,'Itens de Contrato'!B$5:G$151,2,0) -> #N/A | E7: =D7*'Itens de Contrato'!F7 -> 0 | F7: ='Medição 07'!F7-'Medição 07'!G7 -> 0 | H7: =G7/D7 -> #DIV/0! | I7: =G7*'Itens de Contrato'!F7 -> 0
A8: ='Itens de Contrato'!A8 -> 0 | B8: ='Itens de Contrato'!B8 -> 0 | C8: =VLOOKUP(B8,'Itens de Contrato'!B$5:G$151,2,0) -> #N/A | E8: =D8*'Itens de Contrato'!F8 -> 0 | F8: ='Medição 07'!F8-'Medição 07'!G8 -> 0 | H8: =G8/D8 -> #DIV/0! | I8: =G8*'Itens de Contrato'!F8 -> 0
A9: ='Itens de Contrato'!A9 -> 0 | B9: ='Itens de Contrato'!B9 -> 0 | C9: =VLOOKUP(B9,'Itens de Contrato'!B$5:G$151,2,0) -> #N/A | E9: =D9*'Itens de Contrato'!F9 -> 0 | F9: ='Medição 07'!F9-'Medição 07'!G9 -> 0 | H9: =G9/D9 -> #DIV/0! | I9: =G9*'Itens de Contrato'!F9 -> 0
A10: ='Itens de Contrato'!A10 -> 0 | B10: ='Itens de Contrato'!B10 -> 0 | C10: =VLOOKUP(B10,'Itens de Contrato'!B$5:G$151,2,0) -> #N/A | E10: =D10*'Itens de Contrato'!F10 -> 0 | F10: ='Medição 07'!F10-'Medição 07'!G10 -> 0 | H10: =G10/D10 -> #DIV/0! | I10: =G10*'Itens de Contrato'!F10 -> 0
A11: ='Itens de Contrato'!A11 -> 0 | B11: ='Itens de Contrato'!B11 -> 0 | C11: =VLOOKUP(B11,'Itens de Contrato'!B$5:G$151,2,0) -> #N/A | E11: =D11*'Itens de Contrato'!F11 -> 0 | F11: ='Medição 07'!F11-'Medição 07'!G11 -> 0 | H11: =G11/D11 -> #DIV/0! | I11: =G11*'Itens de Contrato'!F11 -> 0
A12: ='Itens de Contrato'!A12 -> 0 | B12: ='Itens de Contrato'!B12 -> 0 | C12: =VLOOKUP(B12,'Itens de Contrato'!B$5:G$151,2,0) -> #N/A | E12: =D12*'Itens de Contrato'!F12 -> 0 | F12: ='Medição 07'!F12-'Medição 07'!G12 -> 0 | H12: =G12/D12 -> #DIV/0! | I12: =G12*'Itens de Contrato'!F12 -> 0
A13: ='Itens de Contrato'!A13 -> 0 | B13: ='Itens de Contrato'!B13 -> 0 | C13: =VLOOKUP(B13,'Itens de Contrato'!B$5:G$151,2,0) -> #N/A | E13: =D13*'Itens de Contrato'!F13 -> 0 | F13: ='Medição 07'!F13-'Medição 07'!G13 -> 0 | H13: =G13/D13 -> #DIV/0! | I13: =G13*'Itens de Contrato'!F13 -> 0
A14: ='Itens de Contrato'!A14 -> 0 | B14: ='Itens de Contrato'!B14 -> 0 | C14: =VLOOKUP(B14,'Itens de Contrato'!B$5:G$151,2,0) -> #N/A | E14: =D14*'Itens de Contrato'!F14 -> 0 | F14: ='Medição 07'!F14-'Medição 07'!G14 -> 0 | H14: =G14/D14 -> #DIV/0! | I14: =G14*'Itens de Contrato'!F14 -> 0
A15: ='Itens de Contrato'!A15 -> 0 | B15: ='Itens de Contrato'!B15 -> 0 | C15: =VLOOKUP(B15,'Itens de Contrato'!B$5:G$151,2,0) -> #N/A | E15: =D15*'Itens de Contrato'!F15 -> 0 | F15: ='Medição 07'!F15-'Medição 07'!G15 -> 0 | H15: =G15/D15 -> #DIV/0! | I15: =G15*'Itens de Contrato'!F15 -> 0
A16: ='Itens de Contrato'!A16 -> 0 | B16: ='Itens de Contrato'!B16 -> 0 | C16: =VLOOKUP(B16,'Itens de Contrato'!B$5:G$151,2,0) -> #N/A | E16: =D16*'Itens de Contrato'!F16 -> 0 | F16: ='Medição 07'!F16-'Medição 07'!G16 -> 0 | H16: =G16/D16 -> #DIV/0! | I16: =G16*'Itens de Contrato'!F16 -> 0
A17: ='Itens de Contrato'!A17 -> 0 | B17: ='Itens de Contrato'!B17 -> 0 | C17: =VLOOKUP(B17,'Itens de Contrato'!B$5:G$151,2,0) -> #N/A | E17: =D17*'Itens de Contrato'!F17 -> 0 | F17: ='Medição 07'!F17-'Medição 07'!G17 -> 0 | H17: =G17/D17 -> #DIV/0! | I17: =G17*'Itens de Contrato'!F17 -> 0
... A151: ='Itens de Contrato'!A151 -> 0 | B151: ='Itens de Contrato'!B151 -> 0 | C151: =VLOOKUP(B151,'Itens de Contrato'!B$5:G$151,2,0) -> #N/A | E151: =D151*'Itens de Contrato'!F151 -> 0 | F151: ='Medição 07'!F151-'Medição 07'!G151 -> 0 | H151: =G151/D151 -> #DIV/0! | I151: =G151*'Itens de Contrato'!F151 -> 0

Sheet Medição 09
E1: OBRA | F1: ='Cadastro Institucional'!D$6 -> 0 | G1: ='Cadastro Institucional'!D$7 -> 0
A2: CNPJ | B2: Razão Social | C2: Inscrição Estadual | D2: Responsável | E2: Cargo | F2: Telefone | G2: E-mail | H2: Medição Nº | I2: Período
A3: ='Cadastro Institucional'!D$10 -> 0 | B3: ='Cadastro Institucional'!D$9 -> 0 | C3: ='Cadastro Institucional'!D$11 -> 0 | D3: ='Cadastro Institucional'!D$12 -> 0 | E3: ='Cadastro Institucional'!D$13 -> 0 | F3: ='Cadastro Institucional'!D$14 -> 0 | G3: ='Cadastro Institucional'!D$15 -> 0
A5: Etapa | B5: Item | C5: Descrição | D5: Quantidade Contratada | E5: Valor Contratado | F5: Saldo Total à Medir | G5: Quantidade Executada | H5: % Executado | I5: Valor Executado | K5: Preencha apenas as células com esse azul claro como cor de fundo!
A6: ='Itens de Contrato'!A6 -> 0 | B6: ='Itens de Contrato'!B6 -> 0 | C6: =VLOOKUP(B6,'Itens de Contrato'!B$5:G$151,2,0) -> #N/A | E6: =D6*'Itens de Contrato'!F6 -> 0 | F6: ='Medição 08'!F6-'Medição 08'!G6 -> 0 | H6: =G6/D6 -> #DIV/0! | I6: =G6*'Itens de Contrato'!F6 -> 0
A7: ='Itens de Contrato'!A7 -> 0 | B7: ='Itens de Contrato'!B7 -> 0 | C7: =VLOOKUP(B7,'Itens de Contrato'!B$5:G$151,2,0) -> #N/A | E7: =D7*'Itens de Contrato'!F7 -> 0 | F7: ='Medição 08'!F7-'Medição 08'!G7 -> 0 | H7: =G7/D7 -> #DIV/0! | I7: =G7*'Itens de Contrato'!F7 -> 0
A8: ='Itens de Contrato'!A8 -> 0 | B8: ='Itens de Contrato'!B8 -> 0 | C8: =VLOOKUP(B8,'Itens de Contrato'!B$5:G$151,2,0) -> #N/A | E8: =D8*'Itens de Contrato'!F8 -> 0 | F8: ='Medição 08'!F8-'Medição 08'!G8 -> 0 | H8: =G8/D8 -> #DIV/0! | I8: =G8*'Itens de Contrato'!F8 -> 0
A9: ='Itens de Contrato'!A9 -> 0 | B9: ='Itens de Contrato'!B9 -> 0 | C9: =VLOOKUP(B9,'Itens de Contrato'!B$5:G$151,2,0) -> #N/A | E9: =D9*'Itens de Contrato'!F9 -> 0 | F9: ='Medição 08'!F9-'Medição 08'!G9 -> 0 | H9: =G9/D9 -> #DIV/0! | I9: =G9*'Itens de Contrato'!F9 -> 0
A10: ='Itens de Contrato'!A10 -> 0 | B10: ='Itens de Contrato'!B10 -> 0 | C10: =VLOOKUP(B10,'Itens de Contrato'!B$5:G$151,2,0) -> #N/A | E10: =D10*'Itens de Contrato'!F10 -> 0 | F10: ='Medição 08'!F10-'Medição 08'!G10 -> 0 | H10: =G10/D10 -> #DIV/0! | I10: =G10*'Itens de Contrato'!F10 -> 0
A11: ='Itens de Contrato'!A11 -> 0 | B11: ='Itens de Contrato'!B11 -> 0 | C11: =VLOOKUP(B11,'Itens de Contrato'!B$5:G$151,2,0) -> #N/A | E11: =D11*'Itens de Contrato'!F11 -> 0 | F11: ='Medição 08'!F11-'Medição 08'!G11 -> 0 | H11: =G11/D11 -> #DIV/0! | I11: =G11*'Itens de Contrato'!F11 -> 0
A12: ='Itens de Contrato'!A12 -> 0 | B12: ='Itens de Contrato'!B12 -> 0 | C12: =VLOOKUP(B12,'Itens de Contrato'!B$5:G$151,2,0) -> #N/A | E12: =D12*'Itens de Contrato'!F12 -> 0 | F12: ='Medição 08'!F12-'Medição 08'!G12 -> 0 | H12: =G12/D12 -> #DIV/0! | I12: =G12*'Itens de Contrato'!F12 -> 0
A13: ='Itens de Contrato'!A13 -> 0 | B13: ='Itens de Contrato'!B13 -> 0 | C13: =VLOOKUP(B13,'Itens de Contrato'!B$5:G$151,2,0) -> #N/A | E13: =D13*'Itens de Contrato'!F13 -> 0 | F13: ='Medição 08'!F13-'Medição 08'!G13 -> 0 | H13: =G13/D13 -> #DIV/0! | I13: =G13*'Itens de Contrato'!F13 -> 0
A14: ='Itens de Contrato'!A14 -> 0 | B14: ='Itens de Contrato'!B14 -> 0 | C14: =VLOOKUP(B14,'Itens de Contrato'!B$5:G$151,2,0) -> #N/A | E14: =D14*'Itens de Contrato'!F14 -> 0 | F14: ='Medição 08'!F14-'Medição 08'!G14 -> 0 | H14: =G14/D14 -> #DIV/0! | I14: =G14*'Itens de Contrato'!F14 -> 0
A15: ='Itens de Contrato'!A15 -> 0 | B15: ='Itens de Contrato'!B15 -> 0 | C15: =VLOOKUP(B15,'Itens de Contrato'!B$5:G$151,2,0) -> #N/A | E15: =D15*'Itens de Contrato'!F15 -> 0 | F15: ='Medição 08'!F15-'Medição 08'!G15 -> 0 | H15: =G15/D15 -> #DIV/0! | I15: =G15*'Itens de Contrato'!F15 -> 0
A16: ='Itens de Contrato'!A16 -> 0 | B16: ='Itens de Contrato'!B16 -> 0 | C16: =VLOOKUP(B16,'Itens de Contrato'!B$5:G$151,2,0) -> #N/A | E16: =D16*'Itens de Contrato'!F16 -> 0 | F16: ='Medição 08'!F16-'Medição 08'!G16 -> 0 | H16: =G16/D16 -> #DIV/0! | I16: =G16*'Itens de Contrato'!F16 -> 0
A17: ='Itens de Contrato'!A17 -> 0 | B17: ='Itens de Contrato'!B17 -> 0 | C17: =VLOOKUP(B17,'Itens de Contrato'!B$5:G$151,2,0) -> #N/A | E17: =D17*'Itens de Contrato'!F17 -> 0 | F17: ='Medição 08'!F17-'Medição 08'!G17 -> 0 | H17: =G17/D17 -> #DIV/0! | I17: =G17*'Itens de Contrato'!F17 -> 0
... A151: ='Itens de Contrato'!A151 -> 0 | B151: ='Itens de Contrato'!B151 -> 0 | C151: =VLOOKUP(B151,'Itens de Contrato'!B$5:G$151,2,0) -> #N/A | E151: =D151*'Itens de Contrato'!F151 -> 0 | F151: ='Medição 08'!F151-'Medição 08'!G151 -> 0 | H151: =G151/D151 -> #DIV/0! | I151: =G151*'Itens de Contrato'!F151 -> 0

Sheet Medição 10
E1: OBRA | F1: ='Cadastro Institucional'!D$6 -> 0 | G1: ='Cadastro Institucional'!D$7 -> 0
A2: CNPJ | B2: Razão Social | C2: Inscrição Estadual | D2: Responsável | E2: Cargo | F2: Telefone | G2: E-mail | H2: Medição Nº | I2: Período
A3: ='Cadastro Institucional'!D$10 -> 0 | B3: ='Cadastro Institucional'!D$9 -> 0 | C3: ='Cadastro Institucional'!D$11 -> 0 | D3: ='Cadastro Institucional'!D$12 -> 0 | E3: ='Cadastro Institucional'!D$13 -> 0 | F3: ='Cadastro Institucional'!D$14 -> 0 | G3: ='Cadastro Institucional'!D$15 -> 0
A5: Etapa | B5: Item | C5: Descrição | D5: Quantidade Contratada | E5: Valor Contratado | F5: Saldo Total à Medir | G5: Quantidade Executada | H5: % Executado | I5: Valor Executado | K5: Preencha apenas as células com esse azul claro como cor de fundo!
A6: ='Itens de Contrato'!A6 -> 0 | B6: ='Itens de Contrato'!B6 -> 0 | C6: =VLOOKUP(B6,'Itens de Contrato'!B$5:G$151,2,0) -> #N/A | E6: =D6*'Itens de Contrato'!F6 -> 0 | F6: ='Medição 09'!F6-'Medição 09'!G6 -> 0 | H6: =G6/D6 -> #DIV/0! | I6: =G6*'Itens de Contrato'!F6 -> 0
A7: ='Itens de Contrato'!A7 -> 0 | B7: ='Itens de Contrato'!B7 -> 0 | C7: =VLOOKUP(B7,'Itens de Contrato'!B$5:G$151,2,0) -> #N/A | E7: =D7*'Itens de Contrato'!F7 -> 0 | F7: ='Medição 09'!F7-'Medição 09'!G7 -> 0 | H7: =G7/D7 -> #DIV/0! | I7: =G7*'Itens de Contrato'!F7 -> 0
A8: ='Itens de Contrato'!A8 -> 0 | B8: ='Itens de Contrato'!B8 -> 0 | C8: =VLOOKUP(B8,'Itens de Contrato'!B$5:G$151,2,0) -> #N/A | E8: =D8*'Itens de Contrato'!F8 -> 0 | F8: ='Medição 09'!F8-'Medição 09'!G8 -> 0 | H8: =G8/D8 -> #DIV/0! | I8: =G8*'Itens de Contrato'!F8 -> 0
