Workbook

Sheet Banco de Dados
A1: Notas DO ZÉH ROBERTO - DOUTOR CURRÍCULO | B1: uma vez que o trabalho intermitente se assemelha ao famoso "bico" ou Free-lancer" esta planilha calcula valores para, no máximo 30 dias. Acima desse tempo, entendo como trabalho por tempo parcial, autônomo ou empregado normal. Desta forma não aconselho o uso desta planilha para períodos superiores a 30 dias | F1: Acrescentei algumas observações em alguns campos, em função de duvidas que podem surgir, Para ler as observações, basta colocar o mouse sobre o campo que a observação ira aparecer.
A7: PREENCHER APENAS OS CAMPOS LARANJA PLANILHA ELABORADA POR ZÉH ROBERTO - DOUTOR CURRÍCULO | M7: para atualizar regularmente essa planilha acesse | P7: Dica senha AniverSAM
M8: http://www.doutorcurriculo.com.br/planilha-calculo-intermitente/
A9: Planilha calculo pagamento intermitente REVISÃO 06 (2018) | M9: Apuração de Valores
A10: nome da empresa | M10: Total a pagar | N10: Referencia | O10: valor a pagar
A11: CNPJ ou CPF | M11: =IF(AND(B18="",B19=""),"informe valor POR DIA OU HORA",IF(AND(B18<>0,B19<>0),"Apenas um campo pode ter valor",IF(B18="","total a pagar pelos dias","total a pagar pelas horas"))) -> total a pagar pelas horas | N11: =IF(AND(B18="",B19=""),0,IF(AND(B18<>0,B19<>0),0,IF(B18="",D20,D18))) -> 10 | O11: =IF(AND(B18="",B19=""),0,IF(AND(B18<>0,B19<>0),0,IF(B18="",B19*D20,B18*D18))) -> 700
A12: ENDEREÇO | M12: HE diurna | N12: =B33 -> 10 | O12: =IF(AND(B18="",B19=""),0,IF(AND(B18<>0,B19<>0),0,IF(B18="",B19/D19*B33*1.5,B18*B33*(1+C33)))) -> 1050
M13: HE noturna | O13: =IF(AND(B18="",B19=""),0,IF(AND(B18<>0,B19<>0),0,IF(B18="",B19/D19*N41*(1+C38)*1.2,B18*N41*(1+C38)*1.2))) -> 0
A14: mês referencia | B14: 43101 | M14: adic. Not sobre qtdade horas | N14: =C35 -> 0 | O14: =IF(C35>D18,"vide comentario 1",IF(AND(B18>0,B19>0),"CORRIJA",IF(B18="",F20*N40*0.2,B18*N40*N13+O13*N13))) -> 0
A15: nome trabalhador | M15: =IF(AND(B29="não",B30="não"),"Adicional Peric ou Insalub",IF(B29="SIM","Adicional Insalubridade",IF(B30="SIM","Adicional Periculosidade",IF(AND(B29="sim",B30="sim"),"escolha adicional","Adicional Peric ou Insalub")))) -> Adicional Insalubridade | N15: =D29 -> 0 | O15: =IF(M15="adicional periculosidade",(O11+O12)*D29,(IF(M15="adicional insalubridade",D29*(O11+O12+O13),0))) -> 0
A16: Função | M16: DSR | N16: =B31 -> 0 | O16: =(O11+O12+O15+O14+O13)/6 -> 291.66667
A17: valor combinado | D17: SALARIO FAMÍLIA (leia comentário) | M17: premio/ bônus / gratificação
A18: por hora | B18: 70 | C18: qtde Horas | D18: 10 | M18: outros eventos tributáveis INSS e IRRF
A19: ou por dia | C19: Nº de horas/dia | M19: informe manualmente)
A20: se combinado por dia | C20: Nº de dias | E20: vr hora dia | F20: =IF(B19="",0,B19/D19) -> 0 | H20: PORQUE CURRÍCULO É MAIS QUE PAPEL CHEIO DE LETRAS ENTENDA. O currículo precisa convencer o selecionador em apenas 10 segundos, consegue imaginar a pressão? Temos certeza que você não gostaria de saber que seu Currículo foi ignorado por estar mal elaborado. A “Reengenharia curricular” é uma técnica de distribuição de informações profissionais que AUMENTA em MUITO as chances de ser selecionado para uma entrevista de emprego. PARA ver dicas de curriculo, como se comportarem entrevista ou ainda CONHECER A REENGENHARIA ACESSE www.doutorcurriculo.com.br PARA conhecer a Reengenharia Curricular acesse | M20: férias proporcionais | N20: 1/12 | O20: =(O11+O12+O15+O16)/12 -> 170.13889
A21: PARA APURAÇÃO DO IRRF NO MÊS PELO REGIME CAIXA | M21: 1/3 férias proporcionais | N21: 1/3 | O21: =O20/3 -> 56.712963
A22: SEPARE SALARIO E 13 | B22: PRIMEIRO | C22: SEGUNDO | D22: TERCEIRO | E22: QUARTO | F22: total | M22: 13º Salario Proporcional | N22: 1/12 | O22: =(O11+O12+O15+O16)/12 -> 170.13889
A23: Salários pagos no mês | F23: =IF(SUM(B23:E23)=0,0,SUM(B23:E23)) -> 0 | M23: outros eventos isentos Impostos
A24: INSS desc. Salario no mês | F24: =IF(SUM(B24:E24)=0,0,SUM(B24:E24)) -> 0 | M24: Salario Família | N24: =F32 -> 1 | O24: =F35 -> 0
A25: IRRF desc. Salario no mês | F25: =IF(SUM(B25:E25)=0,0,SUM(B25:E25)) -> 0 | O25: 250
A26: 13 pagos no mês | F26: =IF(SUM(B26:E26)=0,0,SUM(B26:E26)) -> 0
A27: INSS desc. 13 no mês | F27: =IF(SUM(B27:E27)=0,0,SUM(B27:E27)) -> 0 | M27: total a pagar | O27: =SUM(O11:O26) -> 2688.6574
A28: IRRF desc. 13 no mês | F28: =IF(SUM(B28:E28)=0,0,SUM(B28:E28)) -> 0 | M28: descontos
A29: local insalubre | B29: SIM | C29: 0.3 | M29: INSS | N29: =O36 -> 0.09 | O29: =ROUND(IF(N36<'tabela INSS'!B8,'tabela INSS'!C8*N36,IF(AND(N36>'tabela INSS'!B8,N36<'tabela INSS'!B9),N36*'tabela INSS'!C9,IF(AND(N36>'tabela INSS'!A10,N36<'tabela INSS'!B10),N36*'tabela INSS'!C10,IF(N36>'tabela INSS'!B10,'tabela INSS'!C10*'tabela INSS'!B10))))-F24,2) -> 183.75
A30: local Periculoso | B30: SIM ou NÃO | C30: DEPENDENTES | M30: INSS s/ 13º Salário | N30: =O37 -> 0.08 | O30: =IF(O22>'tabela INSS'!B10,'tabela INSS'!B10*'tabela INSS'!C10,IF('Banco de Dados'!O22<'tabela INSS'!A9,'Banco de Dados'!O22*'tabela INSS'!C8,IF(AND('Banco de Dados'!O22>'tabela INSS'!B8,'Banco de Dados'!O22<'tabela INSS'!A10),'Banco de Dados'!O22*'tabela INSS'!C9,IF(AND('Banco de Dados'!O22>'tabela INSS'!B9,'Banco de Dados'!O22<'tabela INSS'!B10),'Banco de Dados'!O22*'tabela INSS'!C10,""))))-F27 -> 13.611111
A31: numero DSR no Período | B31: 0 | D31: Salário Família (leia o comentário) | M31: IRRF | N31: =O38 -> 0 | O31: =ROUND(IF(N38<'Tabela IRRF'!B8,'Tabela IRRF'!C8*N38,IF(AND(N38>'Tabela IRRF'!B8,N38<'Tabela IRRF'!B9),N38*'Tabela IRRF'!C9-'Tabela IRRF'!D9,IF(AND(N38>'Tabela IRRF'!B9,N38<'Tabela IRRF'!B10),N38*'Tabela IRRF'!C10-'Tabela IRRF'!D10,IF(AND(N38>'Tabela IRRF'!B10,N38<'Tabela IRRF'!B11),N38*'Tabela IRRF'!C11-'Tabela IRRF'!D11,IF(N38>'Tabela IRRF'!A12,N38*'Tabela IRRF'!C12-'Tabela IRRF'!D12,"")))))-F25,2) -> 0
A32: HORA EXTRA diurna | B32: qtdade | C32: % | D32: qtdade filhos menores de 14 anos | F32: 1 | M32: IRRF s/ 13 salário | N32: =O39 -> 0 | O32: =ROUND(IF(N39<'Tabela IRRF'!B8,'Tabela IRRF'!C8*N39,IF(AND(N39>'Tabela IRRF'!B8,N39<'Tabela IRRF'!B9),N39*'Tabela IRRF'!C9-'Tabela IRRF'!D9,IF(AND(N39>'Tabela IRRF'!B9,N39<'Tabela IRRF'!B10),N39*'Tabela IRRF'!C10-'Tabela IRRF'!D10,IF(AND(N39>'Tabela IRRF'!B10,N39<'Tabela IRRF'!B11),N39*'Tabela IRRF'!C11-'Tabela IRRF'!D11,IF(N39>'Tabela IRRF'!A12,N39*'Tabela IRRF'!C12-'Tabela IRRF'!D12,"")))))-F28,2) -> 0
A33: se houver | B33: 10 | C33: 0.5 | D33: SF já pago nesse mês? | F33: não | M33: adiantamentos | O33: =F38 -> 0
A34: ADICIONAL NOTURNO | C34: quantidade | E34: base calculo SF | F34: =IF(OR(F33="sim",F33=""),0,IF(SUM(B23:E23)+O11+O12+O13+O14+O15+O16+O17>'tabela INSS'!B14,0,SUM(B23:E23)+O11+O12+O13+O14+O15+O16+O17)) -> 0 | M34: =D39 -> Prejuízos causados (ou outro nome) | O34: =F39 -> 0
A35: qtde Horas Noturnas | E35: VR SF a ser pago | F35: =IF(F34=0,0,IF(F34<'tabela INSS'!B13,'tabela INSS'!C13,IF(OR('Banco de Dados'!F34>'tabela INSS'!B13,'Banco de Dados'!F34>'tabela INSS'!A15),'tabela INSS'!C14,IF('Banco de Dados'!F34>'tabela INSS'!B13,"Acima do teto"))))*F32 -> 0 | M35: liquido | O35: =O27-SUM(O29:O34) -> 2491.2963
A36: qtde minutos Noturnos | C36: 0 | M36: BASE CALCULO INSS | N36: =O11+O12+O15+O16+O19+O14+F23 -> 2041.6667 | O36: =IF(N36=0,0,IF(N36<'tabela INSS'!A9,'tabela INSS'!C8,IF(AND(N36>'tabela INSS'!B8,N36<'tabela INSS'!A10),'tabela INSS'!C9,IF(N36>'tabela INSS'!B9,'tabela INSS'!C10)))) -> 0.09
A37: HORA EXTRA Noturna | B37: qtdade | C37: % | D37: DESCONTOS EVENTUAIS | M37: BASE CALCULO INSS 13° Salário | N37: =O22+F26-F27-O30 -> 156.52778 | O37: =IF(N37=0,0,IF(N37<'tabela INSS'!A9,'tabela INSS'!C8,IF(AND(N37>'tabela INSS'!B8,N37<'tabela INSS'!A10),'tabela INSS'!C9,IF(N37>'tabela INSS'!B9,'tabela INSS'!C10)))) -> 0.08
A38: qtde HE Noturnas | B38: 0 | C38: 0.5 | D38: Adiantamentos | M38: BASE CALCULO IRRF | N38: =(ROUND(O11+O12+O15+O16+O14+O13+O17+O19+F23-O29-F24-('Tabela IRRF'!B4*D30),2)) -> 1857.92 | O38: =IF(N38<'Tabela IRRF'!A9,'Tabela IRRF'!C8,IF(AND(N38>'Tabela IRRF'!B8,N38<'Tabela IRRF'!A10),'Tabela IRRF'!C9,IF(AND(N38>'Tabela IRRF'!B9,N38<'Tabela IRRF'!A11),'Tabela IRRF'!C10,IF(EN38>'Tabela IRRF'!B10<'Tabela IRRF'!A12,'Tabela IRRF'!C11,IF(N38>'Tabela IRRF'!B11,'Tabela IRRF'!C12))))) -> 0
A39: qtde minutos Noturnos | D39: Prejuízos causados (ou outro nome) | M39: BASE CALCULO IRRF 13º Sal | N39: =O22+F26 -> 170.13889 | O39: =IF(N39<'Tabela IRRF'!A9,'Tabela IRRF'!C8,IF(AND(N39>'Tabela IRRF'!B8,N39<'Tabela IRRF'!A10),'Tabela IRRF'!C9,IF(AND(N39>'Tabela IRRF'!B9,N39<'Tabela IRRF'!A11),'Tabela IRRF'!C10,IF(EN39>'Tabela IRRF'!B10<'Tabela IRRF'!A12,'Tabela IRRF'!C11,IF(N39>'Tabela IRRF'!B11,'Tabela IRRF'!C12))))) -> 0
A40: encontrando erro ou falhas, por favor, me avise para que eu possa fazer os ajustes e atualizar a planilha zehroberto@doutorcurriculo.com.br | M40: base Hora Noturna | N40: =(C35*60+C36)/52.5 -> 0
M41: base Hora Extra Noturna | N41: =(B38*60+B39)/52.5 -> 0
M42: encontrando erro ou falhas, por favor, me avise para que eu possa fazer os ajustes e atualizar a planilha zehroberto@doutorcurriculo.com.br
H43: http://www.doutorcurriculo.com.br/services/reengenharia-curricular/

Sheet Tabela de tipos de contratacao
A1: Elaborado por Jose Roberto de Miranda, advogado, contador e ministrante de cursos e treinamentos na área de ESocial, Reforma Trabalhista, DP/RH, Fiscal e Contabilidade CIDADE – Taubaté – contatos jr.miranda@nobresadvogados.com.br, WhatsApp 012 99107 5095
A2: Tipo de serviço a ser prestado | B2: Contratação Sugerida
A3: Trabalhar todos os dias da semana | B3: PRAZO INDETERMINADO
A4: Compensar ou não o sábado
A5: Há Subordinação direta
A6: DSR – domingo ou qualquer outro dia da semana
A7: Com ou sem acordo de compensação de horas
A8: Sem previsão de termino do contrato
A9: Trabalhar todos os dias da semana, | B9: PRAZO DETERMINADO
A10: Compensar ou não o sábado
A11: Há Subordinação direta
A12: DSR – domingo ou qualquer outro dia da semana
A13: Com ou sem acordo de compensação de horas
A14: *COM TEMPO DEFINIDO PARA TERMINO
A15: O trabalho se assemelha ou está próximo do famoso bico. | B15: Contrato de Trabalho INTERMITENTE Por Prazo determinado ou indeterminado | C15: PORQUE CURRÍCULO É MAIS QUE PAPEL CHEIO DE LETRAS ENTENDA. O currículo precisa convencer o selecionador em apenas 10 segundos, consegue imaginar a pressão? Temos certeza que você não gostaria de saber que seu Currículo foi ignorado por estar mal elaborado. A “Reengenharia curricular” é uma técnica de distribuição de informações profissionais que AUMENTA em MUITO as chances de ser selecionado para uma entrevista de emprego. PARA ver dicas de curriculo, como se comportarem entrevista ou ainda CONHECER A REENGENHARIA ACESSE www.doutorcurriculo.com.br
A16: Trabalhar um, dois ou três dias da semana
A17: Há subordinação direta ou indireta
A18: Precisa ser convocado para ir trabalhar
A19: Pode ser convocado ou não
A20: Nao pode ter contrato de Experiecia
A21: Funcionário Pode ser substituído com facilidade se não comparecer
A22: Ausência não causará prejuízos consideráveis à empresa, mas apenas redistribuição do trabalho entre os outros funcionários
A23: Trabalhar em casa (home office) sem precisar comparecer na empresa com regularidade | B23: TELETRABALHO Por Prazo determinado ou indeterminado
A24: Uso de computadores e equipamentos de informática
A25: Todos os dias da semana
A26: Há Subordinação indireta – Apresentar resultados, Relatórios, produção, etc.
A27: Compensar ou não o sábado
A28: DSR – domingo ou qualquer outro dia da semana
A29: Com ou sem acordo de compensação de horas
A30: Com ou sem tempo definido para o término
A31: IRA trabalhar com constância sem precisar ser convocado ainda que o serviço seja em três ou quatro dias da semana | B31: Contrato por TEMPO PARCIAL Por Prazo determinado ou indeterminado | C31: encontando erro ou falhas, por favor, me avise para que eu possa fazer os ajustes e atualizar a planiha zehroberto@doutorcurriculo.com.br
A32: Não há necessidade de trabalhar o “dia todo”
A33: Pode ser ou não em Todos os dias úteis da semana
A34: carga maxima de trabalho 25 ou 30 horas
A35: Há subordinação direta e a ausência do funcionário não se consegue substituir com facilidade ou rapidez
A36: Trabalhar todos os dias da semana, | B36: TEMPORÁRIO
A37: Compensar ou não o sábado
A38: DSR – domingo ou qualquer outro dia da semana
A39: Com ou sem acordo de compensação de horas
A40: HÁ Necessidade de subordinação
...

Sheet Holerite
L3: DECLARO TER RECEBIDO A IMPORTÂNCIA LÍQUIDA DISCRIMINADA NESTE RECIBO.
B4: EMPREGADOR | H4: Recibo de Pagamento e Salário
B5: Nome | C5: ='Banco de Dados'!B10 -> 0 | J5: Referente ao Mês / Ano | N5: ASSINATURA DO FUNCIONÁRIO
B6: Endereço | C6: ='Banco de Dados'!B12 -> 0 | J6: ='Banco de Dados'!B14 -> 43101
B7: CNPJ | C7: ='Banco de Dados'!B11 -> 0
B10: CÓDIGO | C10: NOME DO FUNCIONÁRIO | H10: CBO | I10: FUNÇÃO
C11: ='Banco de Dados'!B15 -> 0 | I11: ='Banco de Dados'!B16 -> 0
B14: Cód. | C14: Descrição | H14: Referência | I14: Proventos | J14: Descontos
C16: =IF(OR('Banco de Dados'!O11="",'Banco de Dados'!O11=0),"",'Banco de Dados'!M11) -> total a pagar pelas horas | H16: =IF('Banco de Dados'!N11=0,"",'Banco de Dados'!N11) -> 10 | I16: =IF('Banco de Dados'!O11=0,"",'Banco de Dados'!O11) -> 700
C17: =IF(OR('Banco de Dados'!O12="",'Banco de Dados'!O12=0),"",'Banco de Dados'!M12) -> HE diurna | H17: =IF('Banco de Dados'!N12=0,"",'Banco de Dados'!N12) -> 10 | I17: =IF('Banco de Dados'!O12=0,"",'Banco de Dados'!O12) -> 1050
C18: =IF(OR('Banco de Dados'!O13="",'Banco de Dados'!O13=0),"",'Banco de Dados'!M13) | H18: =IF(OR('Banco de Dados'!N13=0,'Banco de Dados'!N13=""),"",'Banco de Dados'!N13) | I18: =IF('Banco de Dados'!O13=0,"",'Banco de Dados'!O13)
C19: =IF(OR('Banco de Dados'!O14="",'Banco de Dados'!O14=0),"",'Banco de Dados'!M14) | H19: =IF('Banco de Dados'!N14=0,"",'Banco de Dados'!N14) | I19: =IF('Banco de Dados'!O14=0,"",'Banco de Dados'!O14)
C20: =IF(OR('Banco de Dados'!O15="",'Banco de Dados'!O15=0),"",'Banco de Dados'!M15) | H20: =IF('Banco de Dados'!N15=0,"",'Banco de Dados'!N15) | I20: =IF('Banco de Dados'!O15=0,"",'Banco de Dados'!O15)
C21: =IF(OR('Banco de Dados'!O16="",'Banco de Dados'!O16=0),"",'Banco de Dados'!M16) -> DSR | H21: =IF('Banco de Dados'!N16=0,"",'Banco de Dados'!N16) | I21: =IF('Banco de Dados'!O16=0,"",'Banco de Dados'!O16) -> 291.66667
C22: =IF(OR('Banco de Dados'!O17="",'Banco de Dados'!O17=0),"",'Banco de Dados'!M17) | H22: =IF('Banco de Dados'!N17=0,"",'Banco de Dados'!N17) | I22: =IF('Banco de Dados'!O17="","",'Banco de Dados'!O17)
C23: =IF(OR('Banco de Dados'!O19="",'Banco de Dados'!O19=0),"",'Banco de Dados'!M19) | H23: =IF('Banco de Dados'!N18=0,"",'Banco de Dados'!N18) | I23: =IF('Banco de Dados'!O19="","",'Banco de Dados'!O19)
C24: =IF(OR('Banco de Dados'!O20="",'Banco de Dados'!O20=0),"",'Banco de Dados'!M20) -> férias proporcionais | H24: =IF(OR('Banco de Dados'!N20=0,'Banco de Dados'!N20=""),"",'Banco de Dados'!N20) -> 1/12 | I24: =IF(OR('Banco de Dados'!O20="",'Banco de Dados'!O20=0),"",'Banco de Dados'!O20) -> 170.13889
C25: =IF(OR('Banco de Dados'!O21="",'Banco de Dados'!O21=0),"",'Banco de Dados'!M21) -> 1/3 férias proporcionais | H25: =IF('Banco de Dados'!N21=0,"",'Banco de Dados'!N21) -> 1/3 | I25: =IF(OR('Banco de Dados'!O21="",'Banco de Dados'!O21=0),"",'Banco de Dados'!O21) -> 56.712963
C26: =IF(OR('Banco de Dados'!O22="",'Banco de Dados'!O22=0),"",'Banco de Dados'!M22) -> 13º Salario Proporcional | H26: =IF('Banco de Dados'!N22=0,"",'Banco de Dados'!N22) -> 1/12 | I26: =IF(OR('Banco de Dados'!O22="",'Banco de Dados'!O22=0),"",'Banco de Dados'!O22) -> 170.13889
C27: =IF(OR('Banco de Dados'!O25="",'Banco de Dados'!O25=0),"",'Banco de Dados'!M25) -> 0 | H27: =IF('Banco de Dados'!N25=0,"",'Banco de Dados'!N25) | I27: =IF(OR('Banco de Dados'!O25="",'Banco de Dados'!O25=0),"",'Banco de Dados'!O25) -> 250
C29: =IF(OR('Banco de Dados'!O24="",'Banco de Dados'!O24=0),"",'Banco de Dados'!M24) | H29: =IF(C29="","",'Banco de Dados'!F32) | I29: ='Banco de Dados'!F35 -> 0
C30: ='Banco de Dados'!M29 -> INSS | H30: =IF('Banco de Dados'!N30=0,"",'Banco de Dados'!N30) -> 0.08 | J30: =IF(OR('Banco de Dados'!O29="",'Banco de Dados'!O29=0),"",'Banco de Dados'!O29) -> 183.75
C31: ='Banco de Dados'!M30 -> INSS s/ 13º Salário | H31: =IF('Banco de Dados'!N31=0,"",'Banco de Dados'!N31) | J31: =IF(OR(,'Banco de Dados'!O30=0),"",'Banco de Dados'!O30) -> 13.611111
C32: ='Banco de Dados'!M31 -> IRRF | H32: =IF('Banco de Dados'!N32=0,"",'Banco de Dados'!N32) | J32: =IF(OR('Banco de Dados'!O31="",'Banco de Dados'!O31=0),"",'Banco de Dados'!O31)
C33: ='Banco de Dados'!M32 -> IRRF s/ 13 salário | H33: =IF('Banco de Dados'!N33=0,"",'Banco de Dados'!N33) | J33: =IF(OR('Banco de Dados'!O32="",'Banco de Dados'!O32=0),"",'Banco de Dados'!O32)
C34: ='Banco de Dados'!M33 -> adiantamentos | J34: =IF('Banco de Dados'!O33="","",'Banco de Dados'!O33) -> 0
C35: ='Banco de Dados'!M34 -> Prejuízos causados (ou outro nome) | J35: =IF('Banco de Dados'!O34="","",'Banco de Dados'!O34) -> 0
N37: DATA
M38: /
B39: MENSAGENS | I39: Total dos Vencimentos | J39: Total dos Descontos
I40: =SUM(I16:I38) -> 2688.6574 | J40: =SUM(J16:J36) -> 197.36111
I41: Líquido a Receber-> | J41: =I40-J40 -> 2491.2963 | M41: /
B43: Salário Base | D43: Base Cálc. INSS | E43: Base Cálc.FGTS | G43: FGTS do Mês | I43: Base Cálc. IRRF | J43: Faixa IRRF
B44: =I16 -> 700 | D44: ='Banco de Dados'!N36 -> 2041.6667 | E44: =D44 -> 2041.6667 | G44: =ROUND(E44*0.08,2) -> 163.33 | I44: ='Banco de Dados'!N38 -> 1857.92 | J44: 0
B45: 1ª VIA - EMPREGADOR
L49: DECLARO TER RECEBIDO A IMPORTÂNCIA LÍQUIDA DISCRIMINADA NESTE RECIBO.
B50: EMPREGADOR | H50: Recibo de Pagamento e Salário
B51: Nome | C51: =C5 -> 0 | J51: Referente ao Mês / Ano | N51: ASSINATURA DO FUNCIONÁRIO
B52: Endereço | C52: =C6 -> 0 | J52: =J6 -> 43101
B53: CNPJ | C53: =C7 -> 0
...

Sheet Sobre o TRABALHO INTERMITENTE
A1: SOBRE O CONTRATO DE TRABALHO INTERMITENTE O contrato de trabalho intermitente estabelece o vínculo empregatício com a principal diferença da ausência de continuidade. Dessa forma, o empregado somente prestará serviços nas oportunidades em que for solicitado pelo empregador, por determinado número de horas ou de dias. Não há obrigatoriedade de o trabalhador manter um único contrato deste tipo, podendo firmar o vínculo com diversos empregadores. Trata-se de uma novidade introduzida pela Reforma Trabalhista, Lei nº 13.467/2017, com vigor a partir de 11 de novembro de 2017. O trabalho intermitente é previsto pelo artigo 443 e seu parágrafo 3º, assim como pelo artigo 452-A e seus parágrafos, todos da CLT. Como qualquer contrato de trabalho, o intermitente deve ser formalizado por escrito com a assinatura da carteira de trabalho do empregado, com a especificação do valor da hora trabalhada. O patrão deverá convocar o empregado por qualquer meio de comunicação eficaz, informando a jornada solicitada, com pelo menos três dias corridos de antecedência. Recebida a convocação, o empregado terá um dia útil para responder se aceita a proposta ou não. Seu silêncio será equivalente à recusa. Aceita a convocação, a parte que descumprir a oferta pagará multa de metade da remuneração que seria devida. Ao final de cada período trabalhado o empregado receberá imediatamente a remuneração, as férias proporcionais com acréscimo de um terço, o décimo terceiro salário proporcional, o repouso semanal remunerado e eventuais adicionais legais. Haverá ainda o depósito do FGTS correspondente. . | M1: para baixar um modelo de contrato de trabalho intermitente acesse
M7: http://www.doutorcurriculo.com.br/modelo-de-contrato-intermitente/

Sheet tabela INSS
A1: para pedir a versao atualizada entre em contato com
A2: zehroberto@doutorcurriculo.com.br
B3: Passe o Mouse para ler as instruções
A5: TABELA INSS 2017 | D5: SENHA
A6: Contribuição (R$) | C6: Alíquota
A7: de | B7: ate
B8: 1693.72 | C8: 0.08
A9: =B8+0.01 -> 1693.73 | B9: 2822.9 | C9: 0.09
A10: =B9+0.01 -> 2822.91 | B10: 5645.8 | C10: 0.11
A11: salario Familia
A12: de | B12: ate | C12: valor
A13: 0 | B13: 877.67 | C13: 45
A14: 877.68 | B14: 1319.18 | C14: 31.71
A15: 1319.19 | B15: sem teto | C15: 0

Sheet Tabela IRRF
A1: para pedir a versao atualizada entre em contato com
A2: zehroberto@doutorcurriculo.com.br
A3: tabela ano | B3: 2017 | D3: SENHA
A4: deduçao por dependente | B4: 189.59
A5: TABELA IRRF DE 04/2015 / 2017
A6: base de Cálculo (R$) | C6: Alíquota (%) | D6: Parcela a Deduzir
A7: DE | B7: Até
B8: 1903.98 | C8: 0
A9: =B8+0.01 -> 1903.99 | B9: 2826.65 | C9: 0.075 | D9: 142.8
A10: =B9+0.01 -> 2826.66 | B10: 3751.05 | C10: 0.15 | D10: 354.8
A11: =B10+0.01 -> 3751.06 | B11: 4664.68 | C11: 0.225 | D11: 636.13
A12: =B11+0.01 -> 4664.69 | B12: ate infinito | C12: 0.275 | D12: 869.36
