Workbook

Sheet Início
A1: PLANO DE CARGOS E SALÁRIOS - INÍCIO

Sheet Controle de Cargos
A1: PLANO DE CARGOS E SALÁRIOS - CONTROLE
J2: 0
B3: CARGO | C3: NÍVEL | D3: QUANTIDADE | E3: SALÁRIO UNITÁRIO | F3: SALÁRIO POR NÍVEL | G3: SALÁRIO POR CARGO | I3: CARGO | J3: NÍVEL | K3: COMPETÊNCIA I | L3: COMPETÊNCIA II | M3: COMPETÊNCIA III
A5: =B5 -> RECEPCIONISTA | B5: RECEPCIONISTA | F5: =E5*D5 -> 0 | G5: =SUM(F5:F9) -> 0 | H5: =G5 -> 0 | I5: =B5 -> RECEPCIONISTA | J5: =C5 -> 0
A6: =B6 -> 0 | F6: =E6*D6 -> 0 | H6: =G6 -> 0 | J6: =C6 -> 0
A7: =B7 -> 0 | F7: =E7*D7 -> 0 | H7: =G7 -> 0 | J7: =C7 -> 0
A8: =B8 -> 0 | F8: =E8*D8 -> 0 | H8: =G8 -> 0 | J8: =C8 -> 0
A9: =B9 -> 0 | F9: =E9*D9 -> 0 | H9: =G9 -> 0 | J9: =C9 -> 0
A10: =B10 -> 0 | H10: =G10 -> 0
A11: =B11 -> ANALISTA RH | B11: ANALISTA RH | F11: =E11*D11 -> 0 | G11: =SUM(F11:F15) -> 0 | H11: =G11 -> 0 | I11: =B11 -> ANALISTA RH | J11: =C11 -> 0
A12: =B12 -> 0 | F12: =E12*D12 -> 0 | H12: =G12 -> 0 | J12: =C12 -> 0
A13: =B13 -> 0 | F13: =E13*D13 -> 0 | H13: =G13 -> 0 | J13: =C13 -> 0
A14: =B14 -> 0 | F14: =E14*D14 -> 0 | H14: =G14 -> 0 | J14: =C14 -> 0
A15: =B15 -> 0 | F15: =E15*D15 -> 0 | H15: =G15 -> 0 | J15: =C15 -> 0
A16: =B16 -> 0 | H16: =G16 -> 0
A17: =B17 -> CARGO | B17: CARGO | F17: =E17*D17 -> 0 | G17: =SUM(F17:F21) -> 0 | H17: =G17 -> 0 | I17: =B17 -> CARGO | J17: =C17 -> 0
A18: =B18 -> 0 | F18: =E18*D18 -> 0 | H18: =G18 -> 0 | J18: =C18 -> 0
A19: =B19 -> 0 | F19: =E19*D19 -> 0 | H19: =G19 -> 0 | J19: =C19 -> 0
A20: =B20 -> 0 | F20: =E20*D20 -> 0 | H20: =G20 -> 0 | J20: =C20 -> 0
A21: =B21 -> 0 | F21: =E21*D21 -> 0 | H21: =G21 -> 0 | J21: =C21 -> 0
A22: =B22 -> 0 | H22: =G22 -> 0
A23: =B23 -> CARGO | B23: CARGO | F23: =E23*D23 -> 0 | G23: =SUM(F23:F27) -> 0 | H23: =G23 -> 0 | I23: =B23 -> CARGO | J23: =C23 -> 0
A24: =B24 -> 0 | F24: =E24*D24 -> 0 | H24: =G24 -> 0 | J24: =C24 -> 0
A25: =B25 -> 0 | F25: =E25*D25 -> 0 | H25: =G25 -> 0 | J25: =C25 -> 0
A26: =B26 -> 0 | F26: =E26*D26 -> 0 | H26: =G26 -> 0 | J26: =C26 -> 0
A27: =B27 -> 0 | F27: =E27*D27 -> 0 | H27: =G27 -> 0 | J27: =C27 -> 0
A28: =B28 -> 0 | H28: =G28 -> 0
A29: =B29 -> CARGO | B29: CARGO | F29: =E29*D29 -> 0 | G29: =SUM(F29:F33) -> 0 | H29: =G29 -> 0 | I29: =B29 -> CARGO | J29: =C29 -> 0
A30: =B30 -> 0 | F30: =E30*D30 -> 0 | H30: =G30 -> 0 | J30: =C30 -> 0
A31: =B31 -> 0 | F31: =E31*D31 -> 0 | H31: =G31 -> 0 | J31: =C31 -> 0
A32: =B32 -> 0 | F32: =E32*D32 -> 0 | H32: =G32 -> 0 | J32: =C32 -> 0
A33: =B33 -> 0 | F33: =E33*D33 -> 0 | H33: =G33 -> 0 | J33: =C33 -> 0
A34: =B34 -> 0 | H34: =G34 -> 0
A35: =B35 -> CARGO | B35: CARGO | F35: =E35*D35 -> 0 | G35: =SUM(F35:F39) -> 0 | H35: =G35 -> 0 | I35: =B35 -> CARGO | J35: =C35 -> 0
A36: =B36 -> 0 | F36: =E36*D36 -> 0 | H36: =G36 -> 0 | J36: =C36 -> 0
A37: =B37 -> 0 | F37: =E37*D37 -> 0 | H37: =G37 -> 0 | J37: =C37 -> 0
A38: =B38 -> 0 | F38: =E38*D38 -> 0 | H38: =G38 -> 0 | J38: =C38 -> 0
A39: =B39 -> 0 | F39: =E39*D39 -> 0 | H39: =G39 -> 0 | J39: =C39 -> 0
A40: =B40 -> 0 | H40: =G40 -> 0
A41: =B41 -> CARGO | B41: CARGO | F41: =E41*D41 -> 0 | G41: =SUM(F41:F45) -> 0 | H41: =G41 -> 0 | I41: =B41 -> CARGO | J41: =C41 -> 0
...

Sheet Custos Fixos
C5: ATIVO
C6: CIRCULANTE | D6: =#REF!/#REF! -> #REF! | E6: =D6/$D$52 -> #REF!
C7: NÃO CIRCULANTE | D7: =#REF!/#REF! -> #REF! | E7: =D7/$D$52 -> #REF!
E8: =D8/$D$52 -> #REF!
C9: CIRCULANTE | D9: =#REF!/#REF! -> #REF! | E9: =D9/$D$52 -> #REF!
C10: NÃO CIRCULANTE | D10: =#REF!/#REF! -> #REF! | E10: =D10/$D$52 -> #REF!
C11: PATRIMONIO LÍQUIDO | D11: =#REF!/#REF! -> #REF! | E11: =D11/$D$52 -> #REF!
E12: =D12/$D$52 -> #REF!
E13: =D13/$D$52 -> #REF!
D14: - | E14: =D14/$D$52 -> #VALUE!
E15: =D15/$D$52 -> #REF!
E16: =D16/$D$52 -> #REF!
E17: =D17/$D$52 -> #REF!
E18: =D18/$D$52 -> #REF!
E19: =D19/$D$52 -> #REF!
E20: =D20/$D$52 -> #REF!
E21: =D21/$D$52 -> #REF!
E22: =D22/$D$52 -> #REF!
E23: =D23/$D$52 -> #REF!
E24: =D24/$D$52 -> #REF!
E25: =D25/$D$52 -> #REF!
E26: =D26/$D$52 -> #REF!
... E49: =D49/$D$52 -> #REF!
D50: - | E50: =D50/$D$52 -> #VALUE!
D51: - | E51: =D51/$D$52 -> #VALUE!
C52: TOTAL CUSTOS FIXOS | D52: =SUM(D6:D51) -> #REF!

Sheet Panorama
A1: PLANO DE CARGOS E SALÁRIOS - PANORAMA

Sheet Plan1
C3: ='Controle de Cargos'!A5 -> RECEPCIONISTA | D3: ='Controle de Cargos'!H5 -> 0
C4: ='Controle de Cargos'!A11 -> ANALISTA RH | D4: ='Controle de Cargos'!H11 -> 0
C5: ='Controle de Cargos'!A17 -> CARGO | D5: ='Controle de Cargos'!H17 -> 0
C6: ='Controle de Cargos'!A23 -> CARGO | D6: ='Controle de Cargos'!H23 -> 0
C7: ='Controle de Cargos'!A29 -> CARGO | D7: ='Controle de Cargos'!H29 -> 0
C8: ='Controle de Cargos'!A35 -> CARGO | D8: ='Controle de Cargos'!H35 -> 0
C9: ='Controle de Cargos'!A41 -> CARGO | D9: ='Controle de Cargos'!H41 -> 0
C10: ='Controle de Cargos'!A47 -> CARGO | D10: ='Controle de Cargos'!H47 -> 0
C11: ='Controle de Cargos'!A53 -> CARGO | D11: ='Controle de Cargos'!H53 -> 0
