Workbook

Sheet DICAS
A1: DICAS DE COMO APURAR CONTABILMENTE OS CUSTOS
A2: 1. Estruture adequadamente as informações contábeis. Para saber como fazê-lo, sugerimos a seguinte obra:
A3: CONTABILIDADE DE CUSTOS
A5: 2. Verifique se todos os custos estão sendo contabilizados adequadamente
A7: 3. Dê especial atenção à metodologia de rateio dos custos indiretos
A9: 4. Não esqueça de revisar o Plano de Contas, para ajustá-lo à necessidade de informações
A11: 5. Utilize custos padrões para aferir a eficácia do sistema
A13: 6. Não basta calcular custos. É preciso observar atentamente distorções e desperdícios - possibilitando gerenciar custos

Sheet Custo Produção
B2: PLANILHA DE CUSTO DE PRODUÇÃO | E2: Mês/ANO | F2: 43739
B3: CUSTOS APURADOS NA CONTA ESTOQUES EM ELABORAÇÃO
B4: Digite as informações nos campos AMARELOS | C4: Vl. Total | D4: Produto A | E4: Produto B | F4: Produto C
B5: Matérias Primas transferidas para produção | C5: =SUM(D5:F5) -> 14050 | D5: 5000 | E5: 4000 | F5: 5050
B6: Materiais de Embalagem transferidos para produção | C6: =SUM(D6:F6) -> 2925 | D6: 1770 | E6: 400 | F6: 755
B7: Custo da Mão de Obra da Produção apurada no mês | C7: =SUM(D7:F7) -> 5766 | D7: 2990 | E7: 988 | F7: 1788
B8: Gastos Gerais de Produção apurados no mês | C8: =SUM(D8:F8) -> 2265 | D8: 600 | E8: 888 | F8: 777
B9: TOTAL DO CUSTO DE PRODUÇÃO DO MÊS | C9: =SUM(C5:C8) -> 25006 | D9: =SUM(D5:D8) -> 10360 | E9: =SUM(E5:E8) -> 6276 | F9: =SUM(F5:F8) -> 8370
B10: Saldo Contábil Anterior de Produtos em Elaboração | C10: =SUM(D10:F10) -> 2071.5 | D10: 1269.5 | E10: 635 | F10: 167
B11: Saldo Contábil Acumulado de Prod. Elaboração | C11: =SUM(D11:F11) -> 27077.5 | D11: =D9+D10 -> 11629.5 | E11: =E9+E10 -> 6911 | F11: =F9+F10 -> 8537
B13: Estoques Iniciais de Estoques de Prod. em Elaboração (Unidades) | D13: 500 | E13: 350 | F13: 28
B14: Produção Acabada Transferida no mês (Unidades) | D14: 1800 | E14: 2500 | F14: 890
B15: Estoques Finais de Estoques de Prod. em Elaboração (Unidades) | D15: 400 | E15: 390 | F15: 75
B17: % de Acabamento dos Estoques em Elaboração Iniciais | D17: 0.44 | E17: 0.72 | F17: 0.62
B18: % de Acabamento dos Estoques em Elaboração Finais | D18: 0.51 | E18: 0.45 | F18: 0.69
B19: Produção Equivalente no mês (Unidades Consideradas Acabadas) | D19: =ROUND(D15*D18+D14-D13*D17,0) -> 1784 | E19: =ROUND(E15*E18+E14-E13*E17,0) -> 2424 | F19: =ROUND(F15*F18+F14-F13*F17,0) -> 924
B20: Produção Equivalente no mês (Unidades Transferidas Acabadas) | D20: =(ROUND((D14-D13*D17),0)) -> 1580 | E20: =(ROUND((E14-E13*E17),0)) -> 2248 | F20: =(ROUND((F14-F13*F17),0)) -> 873
B21: Produção Equivalente no mês (Unidades em Elaboração no Estoque) | D21: =D19-D20 -> 204 | E21: =E19-E20 -> 176 | F21: =F19-F20 -> 51
B22: Valor da Transferência de Produção no mês | C22: =SUM(D22:F22) -> 24774.68 | D22: =ROUND(D11/D19*D20,2) -> 10299.67 | E22: =ROUND(E11/E19*E20,2) -> 6409.21 | F22: =ROUND(F11/F19*F20,2) -> 8065.8
B23: Saldo Contábil Final em Elaboração | C23: =SUM(D23:F23) -> 2302.82 | D23: =ROUND(D11-D22,2) -> 1329.83 | E23: =ROUND(E11-E22,2) -> 501.79 | F23: =ROUND(F11-F22,2) -> 471.2
B24: Custo Unitário do Produto Acabado Transferido | D24: =D22/D14 -> 5.7220389 | E24: =E22/E14 -> 2.563684 | F24: =F22/F14 -> 9.0626966
B25: Custo Unitário do Produto em Elaboração no Estoque Final | D25: =D23/D15 -> 3.324575 | E25: =E23/E15 -> 1.286641 | F25: =F23/F15 -> 6.2826667
B27: Lançamentos contábeis: | C27: Débito | D27: Crédito | E27: =E2 -> Mês/ANO | F27: =F2 -> 43739
B28: D. Estoques de Produtos em Elaboração | C28: =SUM(D29:D32) -> 25006
B29: C. Estoques Matérias Primas | D29: =C5 -> 14050
B30: C. Estoques Materiais Embalagem | D30: =C6 -> 2925
B31: C. Cta. Transferência - Mão de Obra da Produção | D31: =C7 -> 5766
B32: C. Cta. Transferência - Gastos Gerais de Produção | D32: =C8 -> 2265
B33: Histórico: pela transferência de custos apurados no mês a produtos em elaboração
B35: D. Estoques de Produtos Acabados | C35: =C22 -> 24774.68
B36: C. Estoques de Produtos em Elaboração | D36: =C35 -> 24774.68
B37: Histórico: pela transferência de custos apurados no mês a produtos acabados
B39: Conciliação do Saldo Contábil dos Estoques de Produtos em Elaboração:
B40: Saldo Inicial Contábil | C40: =C10 -> 2071.5
B41: Custos Apurados no mês | C41: =C28 -> 25006
B42: Transferências a Produtos Acabados | C42: =-D36 -> -24774.68
B43: Saldo Final em Elaboração | C43: =SUM(C40:C42) -> 2302.82
B44: Distribuição do Saldo Final: | D44: =D4 -> Produto A | E44: =E4 -> Produto B | F44: =F4 -> Produto C
B45: Em unidades | D45: =D15 -> 400 | E45: =E15 -> 390 | F45: =F15 -> 75
B46: Custo Médio Unitário Final Apurado | D46: =D25 -> 3.324575 | E46: =E25 -> 1.286641 | F46: =F25 -> 6.2826667
...

Sheet Custo Prod Vendidos
B2: PLANILHA DE CUSTO DE PRODUTOS VENDIDOS | E2: Mês de | F2: ='Custo Produção'!F2 -> 43739
B3: CUSTOS APURADOS NA CONTA ESTOQUES DE PRODUTOS ACABADOS
B4: Digite as informações nos campos AMARELOS | C4: Vl. Total | D4: Produto A | E4: Produto B | F4: Produto C
B5: Saldo Contábil Inicial de Estoques Produtos Acabados | C5: =SUM(D5:F5) -> 13750 | D5: 4700 | E5: 4000 | F5: 5050
B6: Valor transferido Prod. Elaboração | C6: =SUM(D6:F6) -> 24774.68 | D6: ='Custo Produção'!D22 -> 10299.67 | E6: ='Custo Produção'!E22 -> 6409.21 | F6: ='Custo Produção'!F22 -> 8065.8
B7: Total dos Estoques Acumulados na Conta (R$) | C7: =SUM(D7:F7) -> 38524.68 | D7: =D5+D6 -> 14999.67 | E7: =E5+E6 -> 10409.21 | F7: =F5+F6 -> 13115.8
B8: Valor apurado do Custo dos Produtos Vendidos | C8: =SUM(D8:F8) -> 22029.405 | D8: =D16*D14 -> 8565.5258 | E8: =E16*E14 -> 6453.7102 | F8: =F16*F14 -> 7010.169
B9: Saldo Contábil Final | C9: =SUM(D9:F9) -> 16495.275 | D9: =D7-D8 -> 6434.1442 | E9: =E7-E8 -> 3955.4998 | F9: =F7-F8 -> 6105.631
B11: Saldo Estoques Iniciais de Produtos Acabados (Unidades) | D11: 825 | E11: 1500 | F11: 560
B12: Estoques Transferidos Prod. Elaboração (Unidades) | D12: ='Custo Produção'!D14 -> 1800 | E12: ='Custo Produção'!E14 -> 2500 | F12: ='Custo Produção'!F14 -> 890
B13: Total dos Estoques Acumulados na Conta (Unidades) | D13: =SUM(D11:D12) -> 2625 | E13: =SUM(E11:E12) -> 4000 | F13: =SUM(F11:F12) -> 1450
B14: Estoques Baixados por Venda (Unidades) | D14: 1499 | E14: 2480 | F14: 775
B15: Saldo Estoques Finais (Unidades) | D15: =D13-D14 -> 1126 | E15: =E13-E14 -> 1520 | F15: =F13-F14 -> 675
B16: Custo Médio Unitário Estoques Finais R$ | D16: =D7/D13 -> 5.71416 | E16: =E7/E13 -> 2.6023025 | F16: =F7/F13 -> 9.0453793
B18: Lançamentos contábeis: | C18: Débito | D18: Crédito
B19: D. Custo dos Produtos Vendidos | C19: =C8 -> 22029.405
B20: C. Estoques Produtos Acabados | D20: =C8 -> 22029.405
B22: Conciliação do Saldo em Estoque de Produtos Acabados:
B23: Saldo Inicial Contábil | C23: =C5 -> 13750
B24: Custos Transferidos de Estoques Elaboração | C24: =C6 -> 24774.68
B25: Custos Baixados a Custo Produtos Vendidos | C25: =C8 -> 22029.405
B26: Saldo Final Contábil | C26: =C23+C24-C25 -> 16495.275
B27: Distribuição do Saldo Final: | D27: =D4 -> Produto A | E27: =E4 -> Produto B | F27: =F4 -> Produto C
B28: Em unidades | D28: =D15 -> 1126 | E28: =E15 -> 1520 | F28: =F15 -> 675
B29: Custo Médio Unitário Final Apurado | D29: =D16 -> 5.71416 | E29: =E16 -> 2.6023025 | F29: =F16 -> 9.0453793
B30: Em valor R$ | C30: =SUM(D30:F30) -> 16495.275 | D30: =D28*D29 -> 6434.1442 | E30: =E28*E29 -> 3955.4998 | F30: =F28*F29 -> 6105.631
