Workbook

Sheet Resumo
A1: Resumo modelo RDT
B2: 2012 | C2: =+B2+1 -> 2013 | D2: =+C2+1 -> 2014 | E2: =+D2+1 -> 2015 | F2: =+E2+1 -> 2016 | G2: =+F2+1 -> 2017 | H2: =+G2+1 -> 2018 | I2: =+H2+1 -> 2019 | J2: =+I2+1 -> 2020 | ... R2: =+Q2+1 -> 2028
A3: Tráfego | B3: =+'Dados Financeiros'!L3 -> 2012 | C3: =+'Dados Financeiros'!Q3 -> 2013 | D3: =+'Dados Financeiros'!V3 -> 2014 | E3: =+'Dados Financeiros'!AA3 -> 2015E | F3: =+'Dados Financeiros'!AB3 -> 2016E | G3: =+'Dados Financeiros'!AC3 -> 2017E | H3: =+'Dados Financeiros'!AD3 -> 2018E | I3: =+'Dados Financeiros'!AE3 -> 2019E | J3: =+'Dados Financeiros'!AF3 -> 2020E | K3: =+'Dados Financeiros'!AG3 -> 2021E | L3: =+'Dados Financeiros'!AH3 -> 2022E | ... R3: =+'Dados Financeiros'!AN3 -> 2028E
A4: Tráfego (Mil Veículos Equivalentes) | B4: =+HLOOKUP(B3,Tráfego!$O$14:$CV$31,18,0) -> 43011.533 | C4: =+HLOOKUP(C3,Tráfego!$O$14:$CV$31,18,0) -> 46302.8 | D4: =+HLOOKUP(D3,Tráfego!$O$14:$CV$31,18,0) -> 48528.447 | E4: =+HLOOKUP(E3,Tráfego!$O$14:$CV$31,18,0) -> 46736.441 | F4: =+HLOOKUP(F3,Tráfego!$O$14:$CV$31,18,0) -> 48379.368 | G4: =+HLOOKUP(G3,Tráfego!$O$14:$CV$31,18,0) -> 51329.815 | H4: =+HLOOKUP(H3,Tráfego!$O$14:$CV$31,18,0) -> 55382.484 | I4: =+HLOOKUP(I3,Tráfego!$O$14:$CV$31,18,0) -> 58661.515 | ... R4: =+HLOOKUP(R3,Tráfego!$O$14:$CV$31,18,0) -> 83187.57
A5: YoY | C5: =+C4/B4-1 -> 0.076520569 | D5: =+D4/C4-1 -> 0.048067223 | E5: =+E4/D4-1 -> -0.036926918 | F5: =+F4/E4-1 -> 0.035153015 | G5: =+G4/F4-1 -> 0.060985643 | H5: =+H4/G4-1 -> 0.078953524 | I5: =+I4/H4-1 -> 0.059206988 | J5: =+J4/I4-1 -> 0.060351696 | ... R5: =+R4/Q4-1 -> 0.020203947
A6: Elasticidade PIB | B6: 2 | C6: =+C5/(HLOOKUP(C3,Despesas!$B$3:$AF$4,2,0)/100) -> 2.78892 | D6: =+D5/(HLOOKUP(D3,Despesas!$B$3:$AF$4,2,0)/100) -> 33.245214 | E6: =+E5/(HLOOKUP(E3,Despesas!$B$3:$AF$4,2,0)/100) -> 1.1911909 | F6: =+F5/(HLOOKUP(F3,Despesas!$B$3:$AF$4,2,0)/100) -> -1.7576508 | G6: =+G5/(HLOOKUP(G3,Despesas!$B$3:$AF$4,2,0)/100) -> 6.0985643 | H6: =+H5/(HLOOKUP(H3,Despesas!$B$3:$AF$4,2,0)/100) -> 3.9476762 | I6: =+I5/(HLOOKUP(I3,Despesas!$B$3:$AF$4,2,0)/100) -> 2.9603494 | J6: =+J5/(HLOOKUP(J3,Despesas!$B$3:$AF$4,2,0)/100) -> 3.0175848 | ... R6: =+R5/(HLOOKUP(R3,Despesas!$B$3:$AF$4,2,0)/100) -> 1.0101973
A7: Tráfego médio mensal por Km* | B7: =+(B4/12)/HLOOKUP(B3,Tráfego!$F$14:$CV$19,6,0) -> 8.8209244 | C7: =+(C4/12)/HLOOKUP(C3,Tráfego!$F$14:$CV$19,6,0) -> 9.4976596 | D7: =+(D4/12)/HLOOKUP(D3,Tráfego!$F$14:$CV$19,6,0) -> 9.9541857 | E7: =+(E4/12)/HLOOKUP(E3,Tráfego!$F$14:$CV$19,6,0) -> 9.5866083 | F7: =+(F4/12)/HLOOKUP(F3,Tráfego!$F$14:$CV$19,6,0) -> 9.7113394 | G7: =+(G4/12)/HLOOKUP(G3,Tráfego!$F$14:$CV$19,6,0) -> 10.303592 | H7: =+(H4/12)/HLOOKUP(H3,Tráfego!$F$14:$CV$19,6,0) -> 11.117097 | I7: =+(I4/12)/HLOOKUP(I3,Tráfego!$F$14:$CV$19,6,0) -> 11.775306 | ... R7: =+(R4/12)/HLOOKUP(R3,Tráfego!$F$14:$CV$19,6,0) -> 16.698497
A8: CAGR por fases
A9: Fase I (2012-2015) | B9: =+(E4/B4)^(1/(E2-B2))-1 -> 0.028072097
A10: Fase II (2015-2018) | B10: =+(H4/E4)^(1/(H2-E2))-1 -> 0.058210985 | D10: CAGR Total | F10: =+(R4/B4)^(1/(R2-B2))-1 -> 0.04208848
A11: Fase III (2018-2028) | B11: =+(R4/H4)^(1/(R2-H2))-1 -> 0.041522366 | D11: Haircut VTM | F11: =1-SUM(C4:R4)/1288075 -> 0.21420235 | G11: => Redução de tráfego em relação ao cenário da VTM (consultor de tráfego) durante os 15 anos
A12: *Em mil veículos equivalentes
A14: Dados Financeiros (R$ mm) | B14: =+B3 -> 2012 | C14: =+C3 -> 2013 | D14: =+D3 -> 2014 | E14: =+E3 -> 2015E | F14: =+F3 -> 2016E | G14: =+G3 -> 2017E | H14: =+H3 -> 2018E | I14: =+I3 -> 2019E | ... R14: =+R3 -> 2028E
A15: Receita Bruta de Pedágio | B15: =+HLOOKUP(B14,Tráfego!$J$14:$CV$35,22,0) -> 172.4 | C15: =+HLOOKUP(C14,Tráfego!$J$14:$CV$35,22,0) -> 186.1 | D15: =+HLOOKUP(D14,Tráfego!$J$14:$CV$35,22,0) -> 203.452 | E15: =+HLOOKUP(E14,Tráfego!$J$14:$CV$35,22,0) -> 211.33738 | F15: =+HLOOKUP(F14,Tráfego!$J$14:$CV$35,22,0) -> 248.19037 | G15: =+HLOOKUP(G14,Tráfego!$J$14:$CV$35,22,0) -> 280.91898 | H15: =+HLOOKUP(H14,Tráfego!$J$14:$CV$35,22,0) -> 325.02646 | I15: =+HLOOKUP(I14,Tráfego!$J$14:$CV$35,22,0) -> 362.68459 | ... R15: =+HLOOKUP(R14,Tráfego!$J$14:$CV$35,22,0) -> 765.00712
A16: Receita Operacional Líquida | B16: =+'Dados Financeiros'!L46-'Dados Financeiros'!L42 -> 161.73 | C16: =+'Dados Financeiros'!Q46-'Dados Financeiros'!Q42 -> 174.9 | D16: =+'Dados Financeiros'!V46-'Dados Financeiros'!V42 -> 190.743 | E16: =+'Dados Financeiros'!AA46-'Dados Financeiros'!AA42 -> 198.14047 | F16: =+'Dados Financeiros'!AB46-'Dados Financeiros'!AB42 -> 231.73988 | G16: =+'Dados Financeiros'!AC46-'Dados Financeiros'!AC42 -> 267.02458 | H16: =+'Dados Financeiros'!AD46-'Dados Financeiros'!AD42 -> 306.39217 | I16: =+'Dados Financeiros'!AE46-'Dados Financeiros'!AE42 -> 340.75006 | J16: =+'Dados Financeiros'!AF46-'Dados Financeiros'!AF42 -> 376.39341 | K16: =+'Dados Financeiros'!AG46-'Dados Financeiros'!AG42 -> 408.98416 | L16: =+'Dados Financeiros'!AH46-'Dados Financeiros'!AH42 -> 444.15966 | ... R16: =+'Dados Financeiros'!AN46-'Dados Financeiros'!AN42 -> 707.67175
A17: EBITDA Ajustado | B17: =+'Dados Financeiros'!L65 -> 93.047 | C17: =+'Dados Financeiros'!Q65 -> 99.085 | D17: =+'Dados Financeiros'!V65 -> 116.531 | E17: =+'Dados Financeiros'!AA65 -> 117.23565 | F17: =+'Dados Financeiros'!AB65 -> 162.92792 | G17: =+'Dados Financeiros'!AC65 -> 196.92392 | H17: =+'Dados Financeiros'!AD65 -> 232.15608 | I17: =+'Dados Financeiros'!AE65 -> 263.0321 | J17: =+'Dados Financeiros'!AF65 -> 295.00341 | K17: =+'Dados Financeiros'!AG65 -> 323.20869 | L17: =+'Dados Financeiros'!AH65 -> 353.75076 | ... R17: =+'Dados Financeiros'!AN65 -> 583.98648 | S17: =+SUM(B17:R17) -> 5156.9109
A18: Margem Ebitda Ajustada | B18: =+'Dados Financeiros'!L66 -> 0.57532307 | C18: =+'Dados Financeiros'!Q66 -> 0.56652373 | D18: =+'Dados Financeiros'!V66 -> 0.61093199 | E18: =+'Dados Financeiros'!AA66 -> 0.59167948 | F18: =+'Dados Financeiros'!AB66 -> 0.70306382 | G18: =+'Dados Financeiros'!AC66 -> 0.73747485 | H18: =+'Dados Financeiros'!AD66 -> 0.75770892 | I18: =+'Dados Financeiros'!AE66 -> 0.77192093 | J18: =+'Dados Financeiros'!AF66 -> 0.7837635 | K18: =+'Dados Financeiros'!AG66 -> 0.79027191 | L18: =+'Dados Financeiros'!AH66 -> 0.79644954 | ... R18: =+'Dados Financeiros'!AN66 -> 0.82522227
A20: Fluxo de Caixa Livre | C20: =+'Dados Financeiros'!Q206+'Dados Financeiros'!Q209 -> -66.548 | D20: =+'Dados Financeiros'!V206+'Dados Financeiros'!V209 -> -31.642 | E20: =+'Dados Financeiros'!AA206+'Dados Financeiros'!AA209 -> 49.615461 | F20: =+'Dados Financeiros'!AB206+'Dados Financeiros'!AB209 -> 1.224062 | G20: =+'Dados Financeiros'!AC206+'Dados Financeiros'!AC209 -> 25.753318 | H20: =+'Dados Financeiros'!AD206+'Dados Financeiros'!AD209 -> 88.453211 | I20: =+'Dados Financeiros'!AE206+'Dados Financeiros'!AE209 -> 104.01165 | J20: =+'Dados Financeiros'!AF206+'Dados Financeiros'!AF209 -> 126.93222 | K20: =+'Dados Financeiros'!AG206+'Dados Financeiros'!AG209 -> 84.870236 | L20: =+'Dados Financeiros'!AH206+'Dados Financeiros'!AH209 -> 129.31723 | ... R20: =+'Dados Financeiros'!AN206+'Dados Financeiros'!AN209 -> 292.52639
A22: Dívida Bruta | B22: =+'Dados Financeiros'!L105 -> 627 | C22: =+'Dados Financeiros'!Q105 -> 1068.1 | D22: =+'Dados Financeiros'!V105 -> 1107.232 | E22: =+'Dados Financeiros'!AA105 -> 1236.7545 | F22: =+'Dados Financeiros'!AB105 -> 1330.8547 | G22: =+'Dados Financeiros'!AC105 -> 1389.7638 | H22: =+'Dados Financeiros'!AD105 -> 1401.1626 | I22: =+'Dados Financeiros'!AE105 -> 1371.4743 | J22: =+'Dados Financeiros'!AF105 -> 1319.2578 | K22: =+'Dados Financeiros'!AG105 -> 1249.6896 | L22: =+'Dados Financeiros'!AH105 -> 1150.0385 | ... R22: =+'Dados Financeiros'!AN105 -> 56.557868
A23: Dívida Líquida | B23: =+'Dados Financeiros'!L106 -> 579.1 | C23: =+'Dados Financeiros'!Q106 -> 717.3 | D23: =+'Dados Financeiros'!V106 -> 858.38 | E23: =+'Dados Financeiros'!AA106 -> 954.71003 | F23: =+'Dados Financeiros'!AB106 -> 1047.5862 | G23: =+'Dados Financeiros'!AC106 -> 1087.7709 | H23: =+'Dados Financeiros'!AD106 -> 1048.098 | I23: =+'Dados Financeiros'!AE106 -> 981.96529 | J23: =+'Dados Financeiros'!AF106 -> 893.04547 | K23: =+'Dados Financeiros'!AG106 -> 818.96526 | L23: =+'Dados Financeiros'!AH106 -> 708.38692 | ... R23: =+'Dados Financeiros'!AN106 -> -584.40948
A25: Índices de Alavancagem
A26: Dívida Líquida / Ebitda | B26: =+'Dados Financeiros'!L109 -> 6.2237364 | C26: =+'Dados Financeiros'!Q109 -> 7.239239 | D26: =+'Dados Financeiros'!V109 -> 7.3661086 | E26: =+'Dados Financeiros'!AA109 -> 8.1435131 | F26: =+'Dados Financeiros'!AB109 -> 6.4297522 | G26: =+'Dados Financeiros'!AC109 -> 5.5238132 | H26: =+'Dados Financeiros'!AD109 -> 4.5146268 | I26: =+'Dados Financeiros'!AE109 -> 3.7332527 | J26: =+'Dados Financeiros'!AF109 -> 3.0272377 | K26: =+'Dados Financeiros'!AG109 -> 2.533859 | L26: =+'Dados Financeiros'!AH109 -> 2.0025029 | ... R26: =+'Dados Financeiros'!AN109 -> -1.0007243
A27: ICSD | E27: =+'Dados Financeiros'!AA237 -> 2.2558049 | F27: =+'Dados Financeiros'!AB237 -> 1.0118794 | G27: =+'Dados Financeiros'!AC237 -> 1.1577709 | H27: =+'Dados Financeiros'!AD237 -> 1.3129103 | I27: =+'Dados Financeiros'!AE237 -> 1.2425415 | J27: =+'Dados Financeiros'!AF237 -> 1.2845538 | K27: =+'Dados Financeiros'!AG237 -> 1.1483317 | L27: =+'Dados Financeiros'!AH237 -> 1.1677689 | ... O27: =+'Dados Financeiros'!AK237 -> 1.2454026 | P27: =+'Dados Financeiros'!AL237+0.009 -> 1.3093176 | Q27: =+'Dados Financeiros'!AM237 -> 1.191559 | R27: =+'Dados Financeiros'!AN237 -> 2.5874854
A28: Limite Covenant | E28: 1.15 | F28: 1.15 | G28: 1.15 | H28: 1.15 | I28: 1.15 | J28: 1.15 | K28: 1.15 | L28: 1.15 | M28: 1.15 | N28: 1.15 | O28: 1.15 | P28: 1.15 | Q28: 1.15 | R28: 1.15
A29: Teste | E29: =+IF(E27>1.14,"ok","verificar") -> ok | F29: =+IF(F27>1.14,"ok","verificar") -> verificar | G29: =+IF(G27>1.14,"ok","verificar") -> ok | H29: =+IF(H27>1.14,"ok","verificar") -> ok | I29: =+IF(I27>1.14,"ok","verificar") -> ok | J29: =+IF(J27>1.14,"ok","verificar") -> ok | K29: =+IF(K27>1.14,"ok","verificar") -> ok | L29: =+IF(L27>1.14,"ok","verificar") -> ok | ... R29: =+IF(R27>1.14,"ok","verificar") -> ok
A30: Dívida Bruta / Capital Total | C30: =+'Dados Financeiros'!Q235 -> 0.84082608 | D30: =+'Dados Financeiros'!V235 -> 0.84350315 | E30: =+'Dados Financeiros'!AA235 -> 0.86265546 | F30: =+'Dados Financeiros'!AB235 -> 0.86408774 | G30: =+'Dados Financeiros'!AC235 -> 0.84444334 | H30: =+'Dados Financeiros'!AD235 -> 0.80432645 | I30: =+'Dados Financeiros'!AE235 -> 0.74701595 | J30: =+'Dados Financeiros'!AF235 -> 0.68821629 | K30: =+'Dados Financeiros'!AG235 -> 0.62380026 | L30: =+'Dados Financeiros'!AH235 -> 0.55720351 | ... R30: =+'Dados Financeiros'!AN235 -> 0
A31: Limite Covenant | C31: 0.85 | D31: 0.85 | E31: 0.85 | F31: 0.85 | G31: 0.85 | H31: 0.85 | I31: 0.75 | J31: 0.75 | K31: 0.75 | L31: 0.75 | M31: 0.75 | N31: 0.75 | O31: 0.75 | P31: 0.75 | Q31: 0.75 | R31: 0.75
A32: Limite < 85% até 2018 e < 75% após | C32: =+IF(C30<=C31,"ok","verificar") -> ok | D32: =+IF(D30<=D31,"ok","verificar") -> ok | E32: =+IF(E30<=E31,"ok","verificar") -> verificar | F32: =+IF(F30<=F31,"ok","verificar") -> verificar | G32: =+IF(G30<=G31,"ok","verificar") -> ok | H32: =+IF(H30<=H31,"ok","verificar") -> ok | I32: =+IF(I30<=I31,"ok","verificar") -> ok | J32: =+IF(J30<=J31,"ok","verificar") -> ok | ... R32: =+IF(R30<=R31,"ok","verificar") -> ok
A34: Contas Reservas | B34: =+B14 -> 2012 | C34: =+C14 -> 2013 | D34: =+D14 -> 2014 | E34: =+E14 -> 2015E | F34: =+F14 -> 2016E | G34: =+G14 -> 2017E | H34: =+H14 -> 2018E | I34: =+I14 -> 2019E | ... R34: =+R14 -> 2028E
A35: =+'Dados Financeiros'!A225 -> Conta Reserva de Capex | C35: =+'Dados Financeiros'!Q225 -> 43.558037 | D35: =+'Dados Financeiros'!V225 -> 67.232978 | E35: =+'Dados Financeiros'!AA225 -> 90.214368 | F35: =+'Dados Financeiros'!AB225 -> 76.353182 | G35: =+'Dados Financeiros'!AC225 -> 63.112916 | H35: =+'Dados Financeiros'!AD225 -> 72.505883 | I35: =+'Dados Financeiros'!AE225 -> 74.119505 | J35: =+'Dados Financeiros'!AF225 -> 73.978922 | K35: =+'Dados Financeiros'!AG225 -> 62.32066 | L35: =+'Dados Financeiros'!AH225 -> 55.163442 | ... R35: =+'Dados Financeiros'!AN225 -> 102.84459
A36: =+'Dados Financeiros'!A226 -> Conta de Serviço de Dívida | C36: =+'Dados Financeiros'!Q226 -> 0 | D36: =+'Dados Financeiros'!V226 -> 98.202331 | E36: =+'Dados Financeiros'!AA226 -> 103.04091 | F36: =+'Dados Financeiros'!AB226 -> 118.68046 | G36: =+'Dados Financeiros'!AC226 -> 163.2152 | H36: =+'Dados Financeiros'!AD226 -> 191.72658 | I36: =+'Dados Financeiros'!AE226 -> 206.16739 | J36: =+'Dados Financeiros'!AF226 -> 214.30177 | K36: =+'Dados Financeiros'!AG226 -> 233.76343 | L36: =+'Dados Financeiros'!AH226 -> 268.86253 | ... R36: =+'Dados Financeiros'!AN226 -> 0
A37: =+'Dados Financeiros'!A227 -> Reserva para Despesas Operacionais | C37: =+'Dados Financeiros'!Q227 -> 16.45375 | D37: =+'Dados Financeiros'!V227 -> 16.27925 | E37: =+'Dados Financeiros'!AA227 -> 17.826543 | F37: =+'Dados Financeiros'!AB227 -> 15.031081 | G37: =+'Dados Financeiros'!AC227 -> 15.458659 | H37: =+'Dados Financeiros'!AD227 -> 16.345735 | I37: =+'Dados Financeiros'!AE227 -> 17.134572 | J37: =+'Dados Financeiros'!AF227 -> 17.941687 | K37: =+'Dados Financeiros'!AG227 -> 18.850449 | L37: =+'Dados Financeiros'!AH227 -> 19.807204 | ... R37: =+'Dados Financeiros'!AN227 -> 26.628492
A38: =+'Dados Financeiros'!A228 -> Conta de pré-financimanto de juros | C38: =+'Dados Financeiros'!Q228 -> 115.302 | D38: =+'Dados Financeiros'!V228 -> 29.393 | E38: =+'Dados Financeiros'!AA228 -> 29.393 | F38: =+'Dados Financeiros'!AB228 -> 0 | G38: =+'Dados Financeiros'!AC228 -> 0 | H38: =+'Dados Financeiros'!AD228 -> 0 | I38: =+'Dados Financeiros'!AE228 -> 0 | J38: =+'Dados Financeiros'!AF228 -> 0 | K38: =+'Dados Financeiros'!AG228 -> 0 | L38: =+'Dados Financeiros'!AH228 -> 0 | ... R38: =+'Dados Financeiros'!AN228 -> 0
A39: TOTAL DE RESERVAS | C39: =+SUM(C35:C38) -> 175.31379 | D39: =+SUM(D35:D38) -> 211.10756 | E39: =+SUM(E35:E38) -> 240.47482 | F39: =+SUM(F35:F38) -> 210.06472 | G39: =+SUM(G35:G38) -> 241.78677 | H39: =+SUM(H35:H38) -> 280.5782 | I39: =+SUM(I35:I38) -> 297.42147 | J39: =+SUM(J35:J38) -> 306.22238 | ... R39: =+SUM(R35:R38) -> 129.47308
A41: Caixa Final | C41: =+'Dados Financeiros'!Q7 -> 350.8 | D41: =+'Dados Financeiros'!V7 -> 248.852 | E41: =+'Dados Financeiros'!AA7 -> 282.04446 | F41: =+'Dados Financeiros'!AB7 -> 283.26852 | G41: =+'Dados Financeiros'!AC7 -> 301.99284 | H41: =+'Dados Financeiros'!AD7 -> 353.06455 | I41: =+'Dados Financeiros'!AE7 -> 389.50903 | J41: =+'Dados Financeiros'!AF7 -> 426.21234 | K41: =+'Dados Financeiros'!AG7 -> 430.72433 | L41: =+'Dados Financeiros'!AH7 -> 441.65162 | ... R41: =+'Dados Financeiros'!AN7 -> 640.96734
A42: Enquadramento | C42: =+IF(C41>C39,"ok", "verificar") -> ok | D42: =+IF(D41>D39,"ok", "verificar") -> ok | E42: =+IF(E41>E39,"ok", "verificar") -> ok | F42: =+IF(F41>F39,"ok", "verificar") -> ok | G42: =+IF(G41>G39,"ok", "verificar") -> ok | H42: =+IF(H41>H39,"ok", "verificar") -> ok | I42: =+IF(I41>I39,"ok", "verificar") -> ok | J42: =+IF(J41>J39,"ok", "verificar") -> ok | ... R42: =+IF(R41>R39,"ok", "verificar") -> ok

Sheet Dados Financeiros
A1: Rodovias do Tiete
A3: Balanço Patrimonial (R$ mn) | B3: 2010 | C3: 1T11 | D3: 2T11 | E3: 3T11 | F3: 4T11 | G3: 2011 | H3: 1T12 | I3: 2T12 | J3: 3T12 | K3: 4T12 | L3: 2012 | M3: 1T13 | N3: 2T13 | O3: 3T13 | P3: 4T13 | Q3: 2013 | R3: 1T14 | S3: 2T14 | T3: 3T14 | U3: 4T14 | V3: 2014 | W3: 1T15 | X3: 2T15 | Y3: 3T15 | Z3: 4T15E | AA3: 2015E | AB3: 2016E | AC3: 2017E | AD3: 2018E | AE3: 2019E | AF3: 2020E | AG3: 2021E | AH3: 2022E | AI3: 2023E | AJ3: 2024E | AK3: 2025E | AL3: 2026E | AM3: 2027E | AN3: 2028E
A4: Ativo Total | B4: 807.85 | C4: =+C6+C12+C14 -> 814.45 | D4: =+D6+D12+D14 -> 796.708 | E4: =+E6+E12+E14 -> 825.35 | F4: =+F6+F12+F14 -> 792.37 | G4: =+G6+G12+G14 -> 792.37 | H4: =+H6+H12+H14 -> 799.39 | I4: =+I6+I12+I14 -> 796.5 | J4: =+J6+J12+J14 -> 893.97 | ... AN4: =+AN6+AN12+AN14 -> 2613.1925
A6: Ativo Circulante | B6: 84.55 | C6: =+SUM(C7:C10) -> 92.36 | D6: =+SUM(D7:D10) -> 15.1 | E6: =+SUM(E7:E10) -> 89.9 | F6: =+SUM(F7:F10) -> 41.17 | G6: =+SUM(G7:G10) -> 41.17 | H6: =+SUM(H7:H10) -> 39.45 | I6: =+SUM(I7:I10) -> 14.8 | J6: =+SUM(J7:J10) -> 83.57 | ... AN6: =+SUM(AN7:AN10) -> 741.69985
A7: Caixa | B7: 75.1 | C7: 80 | D7: 3.9 | E7: 74 | F7: 27.3 | G7: =+F7 -> 27.3 | H7: 22.17 | I7: 3.9 | J7: 62.9 | K7: 47.9 | L7: =+K7 -> 47.9 | M7: 37.56 | N7: 5 | O7: =1.4+89.9+301.3 -> 392.6 | P7: =2.7+93.3+254.8 -> 350.8 | Q7: =+P7 -> 350.8 | R7: =3.6+114.3+236.7 -> 354.6 | S7: =16.848+67.915+209.436 -> 294.199 | T7: =3.299+77.501+203.58 -> 284.38 | U7: =11.966+29.361+207.525 -> 248.852 | V7: =11.966+29.361+207.525 -> 248.852 | W7: =22.958+24.334+213.805 -> 261.097 | X7: =70.869+28.411+177.222 -> 276.502 | Y7: =84.946+28.411+185.136 -> 298.493 | Z7: =Z222 -> 282.04446 | AA7: =AA222 -> 282.04446 | AB7: =AB222 -> 283.26852 | AC7: =AC222 -> 301.99284 | AD7: =AD222 -> 353.06455 | AE7: =AE222 -> 389.50903 | AF7: =AF222 -> 426.21234 | AG7: =AG222 -> 430.72433 | ... AN7: =AN222 -> 640.96734
A8: Contas a Receber | B8: 7.7 | C8: 10.36 | D8: 8 | E8: 12.6 | F8: 9.9 | G8: =+F8 -> 9.9 | H8: 12.28 | I8: 8 | J8: 10.9 | K8: 14.1 | L8: =+K8 -> 14.1 | M8: 10.59 | N8: 11 | O8: 13.9 | P8: 16.7 | Q8: =+P8 -> 16.7 | R8: 10.6 | S8: 14.311 | T8: 17.088 | U8: 18.218 | V8: 18.218 | W8: 11.227 | X8: 17.666 | Y8: 17.749 | Z8: =Z112 -> 19.398964 | AA8: =+AA112 -> 19.398964 | AB8: =+AB112 -> 22.337133 | AC8: =+AC112 -> 25.282708 | AD8: =+AD112 -> 29.252381 | AE8: =+AE112 -> 32.641613 | AF8: =+AF112 -> 36.157966 | AG8: =+AG112 -> 39.371979 | AH8: =+AH112 -> 42.841738 | ... AN8: =+AN112 -> 68.85064
A9: Tributos a Recuperar | B9: 0.2 | C9: 0 | D9: 1.9 | E9: 1.3 | F9: 1.8 | G9: =+F9 -> 1.8 | H9: 2 | I9: 1.9 | J9: 1.9 | K9: 3.8 | L9: =+K9 -> 3.8 | M9: 4.4 | N9: 5.3 | O9: 5.2 | P9: 5.4 | Q9: =+P9 -> 5.4 | R9: 6.1 | S9: 11.082 | T9: 11.211 | U9: 0.313 | V9: 0.313 | W9: 0.382 | X9: 0.312 | Y9: 0.324 | Z9: =Z115 -> 0.324 | AA9: =+AA115 -> 0.324 | AB9: =+AB115 -> 16.58172 | AC9: =+AC115 -> 16.58172 | AD9: =+AD115 -> 16.58172 | AE9: =+AE115 -> 16.58172 | AF9: =+AF115 -> 16.58172 | AG9: =+AG115 -> 16.58172 | AH9: =+AH115 -> 16.58172 | ... AN9: =+AN115 -> 16.58172
A10: Outros | B10: 1.55 | C10: 2 | D10: 1.3 | E10: 2 | F10: =41.17-F9-F8-F7 -> 2.17 | G10: =+F10 -> 2.17 | H10: 3 | I10: 1 | J10: =83.57-J9-J8-J7 -> 7.87 | K10: =70.6-K9-K8-K7 -> 4.8 | L10: =+K10 -> 4.8 | M10: =55.54-53 -> 2.54 | N10: 2 | O10: 3.8 | P10: =2+1.2 -> 3.2 | Q10: =+P10 -> 3.2 | R10: 3 | S10: =1.929+1.996 -> 3.925 | T10: =1.974+0.832 -> 2.806 | U10: =0.788+1.572 -> 2.36 | V10: =0.788+1.572 -> 2.36 | W10: =0.825+1.16 -> 1.985 | X10: =0.441+1.158 -> 1.599 | Y10: =2.039+1.835 -> 3.874 | Z10: =Z118 -> 4.2341306 | AA10: =+AA118 -> 4.2341306 | AB10: =+AB118 -> 4.9638074 | AC10: =+AC118 -> 5.6183797 | AD10: =+AD118 -> 6.5005292 | AE10: =+AE118 -> 7.2536918 | AF10: =+AF118 -> 8.0351036 | AG10: =+AG118 -> 8.7493286 | AH10: =+AH118 -> 9.5203863 | ... AN10: =+AN118 -> 15.300142
A12: Realizável a Longo Prazo | B12: 5.9 | C12: 4 | D12: 17.388 | E12: 5.5 | F12: 11.2 | G12: =+F12 -> 11.2 | H12: 8.9 | I12: 17.4 | J12: 18.7 | K12: 18.7 | L12: =+K12 -> 18.7 | M12: 21 | N12: 25.1 | O12: =3.7+22.7+1.8 -> 28.2 | P12: =27+0.24 -> 27.24 | Q12: =+P12 -> 27.24 | R12: 32.8 | S12: =37.251+0.179 -> 37.43 | T12: =40.019+0.318 -> 40.337 | U12: =13.311+46.207+0.374 -> 59.892 | V12: =13.311+46.207+0.374 -> 59.892 | W12: =63.703+0.348+13.312 -> 77.363 | X12: =74.128+0.461+15.679 -> 90.268 | Y12: =82.228+0.454+15.69 -> 98.372 | Z12: =Y12 -> 98.372 | AA12: =Z12 -> 98.372 | AB12: =AA12 -> 98.372 | AC12: =+AB12 -> 98.372 | AD12: =+AC12 -> 98.372 | AE12: =+AD12 -> 98.372 | AF12: =+AE12 -> 98.372 | AG12: =+AF12 -> 98.372 | AH12: =+AG12 -> 98.372 | AI12: =+AH12 -> 98.372 | AJ12: =+AI12 -> 98.372 | ... AN12: =+AM12 -> 98.372
A14: Ativos Fixos | B14: 717.4 | C14: =+C15+C16 -> 718.09 | D14: =+D15+D16 -> 764.22 | E14: =+E15+E16 -> 729.95 | F14: =+F15+F16 -> 740 | G14: =+G15+G16 -> 740 | H14: =+H15+H16 -> 751.04 | I14: =+I15+I16 -> 764.3 | J14: =+J15+J16 -> 791.7 | ... AN14: =+AN15+AN16 -> 1773.1206
A15: Imobilizado | B15: 1.6 | C15: 1.6 | D15: 8.87 | E15: 3.3 | F15: 6.5 | G15: =+F15 -> 6.5 | H15: 7.6 | I15: 8.9 | J15: 9.3 | K15: 9.4 | L15: =+K15 -> 9.4 | M15: 8.9 | N15: 8.7 | O15: 8.4 | P15: 9 | Q15: =+P15 -> 9 | R15: 9.6 | S15: 9.628 | T15: 10.214 | U15: 10.615 | V15: 10.615 | W15: 11.382 | X15: 11.707 | Y15: 11.432 | Z15: =Y15 -> 11.432 | AA15: =Z15 -> 11.432 | AB15: =AA15 -> 11.432 | AC15: =AB15 -> 11.432 | AD15: =AC15 -> 11.432 | AE15: =AD15 -> 11.432 | AF15: =AE15 -> 11.432 | AG15: =AF15 -> 11.432 | ... AN15: =AM15 -> 11.432
A16: Intangível | B16: 715.8 | C16: 716.49 | D16: 755.35 | E16: 726.65 | F16: 733.5 | G16: =+F16 -> 733.5 | H16: 743.44 | I16: 755.4 | J16: 782.4 | K16: 811.78 | L16: =+K16 -> 811.78 | M16: 838.98 | N16: 885.2 | O16: 911.9 | P16: 932.9 | Q16: =+P16 -> 932.9 | R16: 960.4 | S16: 994.155 | T16: 1033.605 | U16: 1064.798 | V16: 1064.798 | W16: 1073.348 | X16: 1083.925 | Y16: 1100.665 | Z16: =+Z83 -> 1138.503 | AA16: =+AA83 -> 1138.503 | AB16: =+AB83 -> 1220.1741 | AC16: =+AC83 -> 1298.8316 | AD16: =+AD83 -> 1335.996 | AE16: =+AE83 -> 1372.1336 | AF16: =+AF83 -> 1408.0311 | AG16: =+AG83 -> 1471.1904 | ... AN16: =+AN83 -> 1761.6886
A18: Passivo Total | B18: 807.89 | C18: =+C20+C28+C34 -> 814.37 | D18: =+D20+D28+D34 -> 796.559 | E18: =+E20+E28+E34 -> 825.19 | F18: =+F20+F28+F34 -> 792.37 | G18: =+G20+G28+G34 -> 792.37 | H18: =+H20+H28+H34 -> 799.6 | I18: =+I20+I28+I34 -> 796.65 | J18: =+J20+J28+J34 -> 893.76 | ... AN18: =+AN20+AN28+AN34 -> 2613.1925
A20: Passivo Circulante | B20: 548.79 | C20: =+SUM(C21:C26) -> 560.67 | D20: =+SUM(D21:D26) -> 546.259 | E20: =+SUM(E21:E26) -> 568.67 | F20: =+SUM(F21:F26) -> 533.17 | G20: =+SUM(G21:G26) -> 533.17 | H20: =+SUM(H21:H26) -> 545.4 | I20: =+SUM(I21:I26) -> 546.25 | J20: =+SUM(J21:J26) -> 644.2 | ... AN20: =+SUM(AN21:AN26) -> 146.16626
A21: Fornecedores | B21: 9.9 | C21: 7.9 | D21: 18.149 | E21: 9.4 | F21: 21.2 | G21: =+F21 -> 21.2 | H21: 24.9 | I21: 18.1 | J21: 14.5 | K21: 20.2 | L21: =+K21 -> 20.2 | M21: 27.8 | N21: 29.6 | O21: 28.1 | P21: 22.6 | Q21: =+P21 -> 22.6 | R21: 24.2 | S21: 33.684 | T21: 35.292 | U21: 34.735 | V21: 34.735 | W21: 25.638 | X21: =22.108 -> 22.108 | Y21: 28.861 | Z21: =Z121 -> 31.543945 | AA21: =+AA121 -> 31.543945 | AB21: =+AB121 -> 37.044575 | AC21: =+AC121 -> 41.929606 | AD21: =+AD121 -> 48.513031 | AE21: =+AE121 -> 54.133834 | AF21: =+AF121 -> 59.965461 | AG21: =+AG121 -> 65.295676 | AH21: =+AH121 -> 71.05003 | ... AN21: =+AN121 -> 114.18398
A22: Dívida CP | B22: 449.47 | C22: 466.37 | D22: 518.55 | E22: 504.1 | F22: 481.4 | G22: =+F22 -> 481.4 | H22: 501.1 | I22: 518.55 | J22: 602.1 | K22: 603.6 | L22: =+K22 -> 603.6 | M22: 604.9 | N22: 607.9 | O22: =51.97 -> 51.97 | P22: =37.8+3.3 -> 41.1 | Q22: =+P22 -> 41.1 | R22: 54 | S22: 3.123 | T22: 26.48 | U22: =3.911 -> 3.911 | V22: =3.911 -> 3.911 | W22: 26.774 | X22: =4.152 -> 4.152 | Y22: =25.267 -> 25.267 | Z22: =-AB158-AB159 -> 0 | AA22: =-AB158-AB159 -> 0 | AB22: =-AC158-AC159 -> 7.029 | AC22: =-AD158-AD159 -> 37.3815 | AD22: =-AE158-AE159 -> 57.51 | AE22: =-AF158-AF159 -> 68.2665 | AF22: =-AG158-AG159 -> 75.0825 | AG22: =-AH158-AH159 -> 90.099 | AH22: =-AI158-AI159 -> 112.251 | ... AN22: =-AO158-AO159 -> 0
A23: Derivativos | B23: 0 | C23: 0 | D23: 0 | E23: 0 | F23: 0 | G23: =+F23 -> 0 | H23: 0 | I23: 0 | J23: 6.2 | K23: 23.4 | L23: =+K23 -> 23.4 | M23: 30.2 | N23: 34.9 | O23: 0 | P23: 0 | Q23: =+P23 -> 0 | R23: 0 | S23: 0 | T23: 0 | U23: 0 | V23: 0 | W23: 0 | X23: 0 | Y23: 0 | Z23: 0 | AA23: 0 | AB23: 0 | AC23: 0 | AD23: 0 | AE23: 0 | AF23: 0 | AG23: 0 | AH23: 0 | AI23: 0 | AJ23: 0 | AK23: 0 | AL23: 0 | AM23: 0 | AN23: 0
A24: Provisões Sociais e Trabalhistas | B24: 2.1 | C24: 1.4 | D24: 3.2 | E24: 2 | F24: 3.5 | G24: =+F24 -> 3.5 | H24: 3.3 | I24: 3.2 | J24: 4 | K24: 3.6 | L24: =+K24 -> 3.6 | M24: 2.4 | N24: 3.4 | O24: 4 | P24: =2.2+3.7 -> 5.9 | Q24: =+P24 -> 5.9 | R24: =1.9+2.4 -> 4.3 | S24: =3.645+2.169 -> 5.814 | T24: =4.371+1.974 -> 6.345 | U24: =1.911+4.423 -> 6.334 | V24: =1.911+4.423 -> 6.334 | W24: 5.974 | X24: =4.607+1.994 -> 6.601 | Y24: =4.359+2.601 -> 6.96 | Z24: =Z124 -> 7.6070081 | AA24: =+AA124 -> 7.6070081 | AB24: =+AB124 -> 7.4457111 | AC24: =+AC124 -> 5.6183797 | AD24: =+AD124 -> 6.5005292 | AE24: =+AE124 -> 7.2536918 | AF24: =+AF124 -> 8.0351036 | AG24: =+AG124 -> 8.7493286 | AH24: =+AH124 -> 9.5203863 | ... AN24: =+AN124 -> 15.300142
A25: Provisão para Manutenção | B25: 84.7 | C25: 83 | D25: 3.36 | E25: 51.17 | F25: 23.2 | G25: =+F25 -> 23.2 | H25: 13.1 | I25: 3.4 | J25: 9.7 | K25: 3.6 | L25: =+K25 -> 3.6 | M25: 3.8 | N25: 7.1 | O25: 7.1 | P25: 0.8 | Q25: =+P25 -> 0.8 | R25: 0.9 | S25: 0.971 | T25: 0.997 | U25: 1.067 | V25: 1.067 | W25: 1.224 | X25: 1.322 | Y25: 1.382 | Z25: =+Y25 -> 1.382 | AA25: =+Z25 -> 1.382 | AB25: =+AA25 -> 1.382 | AC25: =+AB25 -> 1.382 | AD25: =+AC25 -> 1.382 | AE25: =+AD25 -> 1.382 | AF25: =+AE25 -> 1.382 | AG25: =+AF25 -> 1.382 | ... AN25: =+AM25 -> 1.382
A26: Outros | B26: 2.62 | C26: 2 | D26: 3 | E26: 2 | F26: =533.17-SUM(F21:F25) -> 3.87 | G26: =+F26 -> 3.87 | H26: 3 | I26: 3 | J26: =644.7-637 -> 7.7 | K26: =658.3-SUM(K21:K25) -> 3.9 | L26: =+K26 -> 3.9 | M26: =672.544-SUM(M21:M25) -> 3.444 | N26: 2.8 | O26: 3 | P26: 1 | Q26: =+P26 -> 1 | R26: 1 | S26: =45.667-SUM(S21:S25) -> 2.075 | T26: =69.903-SUM(T21:T25) -> 0.789 | U26: =0.229+0.267 -> 0.496 | V26: =0.229+0.267 -> 0.496 | W26: =2.04+0.487 -> 2.527 | X26: =0.468 -> 0.468 | Y26: =0.762 -> 0.762 | Z26: =+Z129 -> 0.83283623 | AA26: =+AA129 -> 0.83283623 | AB26: =+AB129 -> 4.9638074 | AC26: =+AC129 -> 5.6183797 | AD26: =+AD129 -> 6.5005292 | AE26: =+AE129 -> 7.2536918 | AF26: =+AF129 -> 8.0351036 | AG26: =+AG129 -> 8.7493286 | ... AN26: =+AN129 -> 15.300142
A28: Exigível de Longo Prazo | B28: 40.5 | C28: =+SUM(C29:C32) -> 38.7 | D28: =+SUM(D29:D32) -> 52.3 | E28: =+SUM(E29:E32) -> 45.35 | F28: =+SUM(F29:F32) -> 51.8 | G28: =+SUM(G29:G32) -> 51.8 | H28: =+SUM(H29:H32) -> 49.2 | I28: =+SUM(I29:I32) -> 52.4 | J28: =+SUM(J29:J32) -> 56.66 | ... AN28: =+SUM(AN29:AN32) -> 229.93512
A29: Dívida LP | B29: 0 | C29: 0 | D29: 0 | E29: 0 | F29: 0 | G29: =+F29 -> 0 | H29: 0 | I29: 0 | J29: 0 | K29: 0 | L29: =+K29 -> 0 | M29: 0 | N29: 0 | O29: 1020.8 | P29: 1027 | Q29: =+P29 -> 1027 | R29: 1056.6 | S29: 1073.856 | T29: 1082.87 | U29: 1103.321 | V29: 1103.321 | W29: 1144.89 | X29: 1175.374 | Y29: =1199.375 -> 1199.375 | Z29: =+Z136-Z22-Z177 -> 1236.7545 | AA29: =+AA136-AA22-AA177 -> 1236.7545 | AB29: =+AB136-AB22-AB177 -> 1323.8257 | AC29: =+AC136-AC22-AC177 -> 1352.3823 | AD29: =+AD136-AD22-AD177 -> 1343.6526 | AE29: =+AE136-AE22-AE177 -> 1303.2078 | AF29: =+AF136-AF22-AF177 -> 1244.1753 | AG29: =+AG136-AG22-AG177 -> 1159.5906 | ... AN29: =+AN136-AN22-AN177 -> 56.557868
A30: Provisões | B30: 6.5 | C30: 3.7 | D30: 9.3 | E30: 8.2 | F30: 10.4 | G30: =+F30 -> 10.4 | H30: 7 | I30: 9.4 | J30: 12.49 | K30: 19.2 | L30: =+K30 -> 19.2 | M30: 23.45 | N30: 28.3 | O30: 32.77 | P30: 36.3 | Q30: =+P30 -> 36.3 | R30: 41.9 | S30: 36.728 | T30: 41.848 | U30: 47.289 | V30: 47.289 | W30: 54.569 | X30: 59.43 | Y30: 68.519 | Z30: =+Z102 -> 72.595925 | AA30: =+AA102 -> 72.595925 | AB30: =+AB102 -> 75.877617 | AC30: =+AC102 -> 83.19062 | AD30: =+AD102 -> 86.462461 | AE30: =+AE102 -> 76.515665 | AF30: =+AF102 -> 79.633797 | AG30: =+AG102 -> 72.958486 | ... AN30: =+AN102 -> 100.23925
A31: Mútuos a Pagar | B31: 34 | C31: 35 | D31: 40 | E31: 37.15 | F31: 38.2 | G31: =+F31 -> 38.2 | H31: 39.2 | I31: 40 | J31: 40.87 | K31: 41.6 | L31: =+K31 -> 41.6 | M31: 42.33 | N31: 43.1 | O31: 44.1 | P31: 45.2 | Q31: =+P31 -> 45.2 | R31: 46.3 | S31: 57.362 | T31: 59.653 | U31: 62.229 | V31: 62.229 | W31: 64.84 | X31: 69.946 | Y31: 70.84 | Z31: =+Y31 -> 70.84 | AA31: =+Z31 -> 70.84 | AB31: =+AA31 -> 70.84 | AC31: =+AB31 -> 70.84 | AD31: =+AC31 -> 70.84 | AE31: =+AD31 -> 70.84 | AF31: =+AE31 -> 70.84 | AG31: =+AF31 -> 70.84 | ... AN31: =+AM31 -> 70.84
A32: Outros | B32: 0 | C32: 0 | D32: 3 | E32: 0 | F32: 3.2 | G32: =+F32 -> 3.2 | H32: 3 | I32: 3 | J32: =56.3-53 -> 3.3 | K32: 2.9 | L32: =+K32 -> 2.9 | M32: =68.66-M31-M30-M29 -> 2.88 | N32: 3.4 | O32: 1 | P32: 2.7 | Q32: =+P32 -> 2.7 | R32: 2 | S32: =1170.529-SUM(S29:S31) -> 2.583 | T32: =1186.896-SUM(T29:T31) -> 2.525 | U32: 2.468 | V32: 2.468 | W32: 2.412 | X32: 0 | Y32: 2.298 | Z32: =+Y32 -> 2.298 | AA32: =+Z32 -> 2.298 | AB32: =+AA32 -> 2.298 | AC32: =+AB32 -> 2.298 | AD32: =+AC32 -> 2.298 | AE32: =+AD32 -> 2.298 | AF32: =+AE32 -> 2.298 | AG32: =+AF32 -> 2.298 | ... AN32: =+AM32 -> 2.298
A34: Patrimônio Líquido | B34: 218.6 | C34: 215 | D34: 198 | E34: 211.17 | F34: 207.4 | G34: =+F34 -> 207.4 | H34: 205 | I34: 198 | J34: 192.9 | K34: 188.2 | L34: =+K34 -> 188.2 | M34: 183 | N34: 181.4 | O34: 170.9 | P34: 163 | Q34: =+P34 -> 163 | R34: 145.4 | S34: 148.534 | T34: 142.842 | U34: 143.198 | V34: 143.198 | W34: 107.936 | X34: 142.578 | Y34: 126.645 | Z34: =+Y34+Z78+Z211+Z216+Z101 -> 130.45438 | AA34: =Z34 -> 130.45438 | AB34: =+AA34+AB78+AB211+AB216+AB101 -> 126.42285 | AC34: =+AB34+AC78+AC211+AC216+AC101 -> 157.4705 | AD34: =+AC34+AD78+AD211+AD216+AD101 -> 227.54001 | AE34: =+AD34+AE78+AE211+AE216+AE101 -> 336.77244 | AF34: =+AE34+AF78+AF211+AF216+AF101 -> 455.37498 | AG34: =+AF34+AG78+AG211+AG216+AG101 -> 596.45935 | AH34: =+AG34+AH78+AH211+AH216+AH101 -> 740.78736 | AI34: =+AH34+AI78+AI211+AI216+AI101 -> 921.14638 | ... AN34: =+AM34+AN78+AN211+AN216+AN101 -> 2237.0911
A36: Check | B36: =+B18-B4 -> 0.04 | C36: =+C18-C4 -> -0.08 | D36: =+D18-D4 -> -0.149 | E36: =+E18-E4 -> -0.16 | F36: =+F18-F4 -> 0 | G36: =+G18-G4 -> 0 | H36: =+H18-H4 -> 0.21 | I36: =+I18-I4 -> 0.15 | ... AN36: =+AN18-AN4 -> 0
A38: Demonstração de Resultados (R$ mm) | B38: =+B3 -> 2010 | C38: =+C3 -> 1T11 | D38: =+D3 -> 2T11 | E38: =+E3 -> 3T11 | F38: =+F3 -> 4T11 | G38: =+G3 -> 2011 | H38: =+H3 -> 1T12 | I38: =+I3 -> 2T12 | ... AN38: =+AN3 -> 2028E
A39: Receita Bruta | B39: =+SUM(B40:B42) -> 185.09 | C39: =+SUM(C40:C42) -> 39.06 | D39: =+SUM(D40:D42) -> 52.54 | E39: =+SUM(E40:E42) -> 84.433 | F39: =+SUM(F40:F42) -> 80.577 | G39: =+SUM(G40:G42) -> 256.61 | H39: =+SUM(H40:H42) -> 69.077 | I39: =+SUM(I40:I42) -> 65.513 | ... AN39: =+SUM(AN40:AN42) -> 883.50402
A40: -- Receita com Pedágio | B40: 147.1 | C40: 35.3 | D40: =73-C40 -> 37.7 | E40: 43.36 | F40: =+G40-SUM(C40:E40) -> 42.32 | G40: 158.68 | H40: 40 | I40: =79.8-H40 -> 39.8 | J40: =126-I40-H40 -> 46.2 | K40: =+L40-SUM(H40:J40) -> 46.4 | L40: 172.4 | M40: 43.39 | N40: 44.1 | O40: =138.96-N40-M40 -> 51.47 | P40: =186.1-O40-N40-M40 -> 47.14 | Q40: =+SUM(M40:P40) -> 186.1 | R40: 48.4 | S40: 48.838 | T40: 52.821 | U40: =+V40-SUM(R40:T40) -> 53.393 | V40: 203.452 | W40: 48.391 | X40: =97.631-W40 -> 49.24 | Y40: =151.959-X40-W40 -> 54.328 | Z40: =HLOOKUP(Z38,Tráfego!$AH$14:$CV$35,22,0) -> 59.378381 | AA40: =HLOOKUP(AA38,Tráfego!$AI$14:$CV$35,22,0) -> 211.33738 | AB40: =HLOOKUP(AB38,Tráfego!$AI$14:$CV$35,22,0) -> 248.19037 | AC40: =HLOOKUP(AC38,Tráfego!$AI$14:$CV$35,22,0) -> 280.91898 | AD40: =HLOOKUP(AD38,Tráfego!$AI$14:$CV$35,22,0) -> 325.02646 | AE40: =HLOOKUP(AE38,Tráfego!$AI$14:$CV$35,22,0) -> 362.68459 | AF40: =HLOOKUP(AF38,Tráfego!$AI$14:$CV$35,22,0) -> 401.75518 | AG40: =HLOOKUP(AG38,Tráfego!$AI$14:$CV$35,22,0) -> 437.46643 | AH40: =HLOOKUP(AH38,Tráfego!$AI$14:$CV$35,22,0) -> 476.01931 | ... AN40: =HLOOKUP(AN38,Tráfego!$AI$14:$CV$35,22,0) -> 765.00712
A41: -- Receitas Acessórias | B41: 0.52 | C41: 0.1 | D41: =0.2-C41 -> 0.1 | E41: 0.126 | F41: =+G41-SUM(C41:E41) -> 0.254 | G41: 0.58 | H41: 0.077 | I41: =0.3-H41 -> 0.223 | J41: =0.6-I41-H41 -> 0.3 | K41: =+L41-SUM(H41:J41) -> 4.2 | L41: 4.8 | M41: 0.68 | N41: 1.1 | O41: =1.6-N41-M41 -> -0.18 | P41: =5.4-O41-N41-M41 -> 3.8 | Q41: =+SUM(M41:P41) -> 5.4 | R41: 0.4 | S41: 2.722 | T41: 1.56 | U41: =+V41-SUM(R41:T41) -> 1.558 | V41: 6.24 | W41: 0.392 | X41: =3.284-W41 -> 2.892 | Y41: =5.017-X41-W41 -> 1.733 | Z41: =HLOOKUP(Z38,Tráfego!$AH$14:$CV$38,25,0) -> 1.59695 | AA41: =HLOOKUP(AA38,Tráfego!$AI$14:$CV$38,25,0) -> 6.61395 | AB41: =HLOOKUP(AB38,Tráfego!$AI$14:$CV$38,25,0) -> 6.7197732 | AC41: =HLOOKUP(AC38,Tráfego!$AI$14:$CV$38,25,0) -> 12.80377 | AD41: =HLOOKUP(AD38,Tráfego!$AI$14:$CV$38,25,0) -> 12 | AE41: =HLOOKUP(AE38,Tráfego!$AI$14:$CV$38,25,0) -> 12.135 | AF41: =HLOOKUP(AF38,Tráfego!$AI$14:$CV$38,25,0) -> 12.271519 | AG41: =HLOOKUP(AG38,Tráfego!$AI$14:$CV$38,25,0) -> 12.409573 | AH41: =HLOOKUP(AH38,Tráfego!$AI$14:$CV$38,25,0) -> 12.549181 | ... AN41: =HLOOKUP(AN38,Tráfego!$AI$14:$CV$38,25,0) -> 13.420435
A42: -- Receita com Construção | B42: 37.47 | C42: 3.66 | D42: =18.4-C42 -> 14.74 | E42: 40.947 | F42: =+G42-SUM(C42:E42) -> 38.003 | G42: 97.35 | H42: 29 | I42: =54.49-H42 -> 25.49 | J42: =78.89-I42-H42 -> 24.4 | K42: =+L42-SUM(H42:J42) -> 34.58 | L42: 113.47 | M42: 30.4 | N42: 46.6 | O42: =107.2-N42-M42 -> 30.2 | P42: =142.2-O42-N42-M42 -> 35 | Q42: =+SUM(M42:P42) -> 142.2 | R42: 31.6 | S42: 36.776 | T42: 43.962 | U42: =+V42-SUM(R42:T42) -> 35.496 | V42: 147.834 | W42: 12.537 | X42: =26.967-W42 -> 14.43 | Y42: =45.949-X42-W42 -> 18.982 | Z42: =+Z92 -> 43.558037 | AA42: =+AA92 -> 89.558037 | AB42: =+AB92 -> 104.4411 | AC42: =+AC92 -> 103.061 | AD42: =+AD92 -> 63.141 | AE42: =+AE92 -> 62.857545 | AF42: =+AF92 -> 63.340201 | AG42: =+AG92 -> 91.319903 | ... AN42: =+AN92 -> 105.07647
A44: Impostos | B44: -12.7 | C44: -3 | D44: =-6.3-C44 -> -3.3 | E44: -3.7 | F44: =+G44-SUM(C44:E44) -> -4.2 | G44: -14.2 | H44: -3.44 | I44: =-6.9-H44 -> -3.46 | J44: =-10.89-I44-H44 -> -3.99 | K44: =+L44-SUM(H44:J44) -> -4.58 | L44: -15.47 | M44: -3.8 | N44: -3.9 | O44: =-12.1-N44-M44 -> -4.4 | P44: =-16.6-O44-N44-M44 -> -4.5 | Q44: =+SUM(M44:P44) -> -16.6 | R44: -4.8 | S44: -4.542 | T44: -4.712 | U44: =+V44-SUM(R44:T44) -> -4.895 | V44: -18.949 | W44: -4.227 | X44: =-8.74-W44 -> -4.513 | Y44: =-14.043-X44-W44 -> -5.303 | Z44: =HLOOKUP(Z38,Tráfego!$AH$14:$CV$41,28,0) -> -5.7678633 | AA44: =HLOOKUP(AA38,Tráfego!$AI$14:$CV$41,28,0) -> -19.810863 | AB44: =HLOOKUP(AB38,Tráfego!$AI$14:$CV$41,28,0) -> -23.170264 | AC44: =HLOOKUP(AC38,Tráfego!$AI$14:$CV$41,28,0) -> -26.698168 | AD44: =HLOOKUP(AD38,Tráfego!$AI$14:$CV$41,28,0) -> -30.634294 | AE44: =HLOOKUP(AE38,Tráfego!$AI$14:$CV$41,28,0) -> -34.069531 | AF44: =HLOOKUP(AF38,Tráfego!$AI$14:$CV$41,28,0) -> -37.633293 | AG44: =HLOOKUP(AG38,Tráfego!$AI$14:$CV$41,28,0) -> -40.891845 | AH44: =HLOOKUP(AH38,Tráfego!$AI$14:$CV$41,28,0) -> -44.40883 | ... AN44: =HLOOKUP(AN38,Tráfego!$AI$14:$CV$41,28,0) -> -70.755804
A46: Receita Líquida | B46: =+B39+B44 -> 172.39 | C46: =+C39+C44 -> 36.06 | D46: =+D39+D44 -> 49.24 | E46: =+E39+E44 -> 80.733 | F46: =+F39+F44 -> 76.377 | G46: =+G39+G44 -> 242.41 | H46: =+H39+H44 -> 65.637 | I46: =+I39+I44 -> 62.053 | ... R46: =+R39+R44 -> 75.6 | S46: 83.793 | T46: =T39+T44 -> 93.631 | U46: =U39+U44 -> 85.552 | V46: 338.577 | W46: =W39+W44 -> 57.093 | X46: =X39+X44 -> 62.049 | Y46: =Y39+Y44 -> 69.74 | Z46: =Z39+Z44 -> 98.765505 | AA46: =+AA39+AA44 -> 287.69851 | AB46: =+AB39+AB44 -> 336.18098 | AC46: =+AC39+AC44 -> 370.08558 | AD46: =+AD39+AD44 -> 369.53317 | AE46: =+AE39+AE44 -> 403.6076 | AF46: =+AF39+AF44 -> 439.73361 | AG46: =+AG39+AG44 -> 500.30406 | AH46: =+AH39+AH44 -> 511.85807 | ... AN46: =+AN39+AN44 -> 812.74822
A48: Custos e Despesas | B48: =+SUM(B49:B58) -> -108.89 | C48: =+SUM(C49:C58) -> -21.036 | D48: =+SUM(D49:D58) -> -33.664 | E48: =+SUM(E49:E58) -> -61.807 | F48: =+SUM(F49:F58) -> -61.089 | G48: =+SUM(G49:G58) -> -177.596 | H48: =+SUM(H49:H58) -> -48.913 | I48: =+SUM(I49:I58) -> -47.773 | ... AN48: =+SUM(AN49:AN58) -> -323.38207
A49: -- Pessoal | B49: -14.9 | C49: -3.8 | D49: =-8.2-C49 -> -4.4 | E49: -4.3 | F49: =+G49-SUM(C49:E49) -> -5.5 | G49: -18 | H49: -4.971 | I49: =-10.1-H49 -> -5.129 | J49: -5.1 | K49: =+L49-SUM(H49:J49) -> -4.1 | L49: -19.3 | M49: -4.657 | N49: -5.9 | O49: -5.7 | P49: =-20.1-O49-N49-M49 -> -3.843 | Q49: =+SUM(M49:P49) -> -20.1 | R49: -3.9 | S49: =-8.352-R49 -> -4.452 | T49: =-12.744-S49-R49 -> -4.392 | U49: =V49-SUM(R49:T49) -> -4.661 | V49: =-17.405 -> -17.405 | W49: -4.645 | X49: =-7.454-W49 -> -2.809 | Y49: =-12.213-X49-W49 -> -4.759 | Z49: =+Despesas!R21 -> -4.759 | AA49: =+Despesas!S21 -> -16.972 | AB49: =+Despesas!T21 -> -18.058208 | AC49: =+Despesas!U21 -> -18.961118 | AD49: =+Despesas!V21 -> -19.909174 | AE49: =+Despesas!W21 -> -20.805087 | AF49: =+Despesas!X21 -> -21.741316 | AG49: =+Despesas!Y21 -> -22.719675 | ... AN49: =+Despesas!AF21 -> -30.918339
A50: -- Serviços de Terceiros | B50: -22.76 | C50: -5.5 | D50: =-10.3-C50 -> -4.8 | E50: -6.3 | F50: =+G50-SUM(C50:E50) -> -6.3 | G50: -22.9 | H50: -1.43 | I50: =-10.1-H50 -> -8.67 | J50: -7.5 | K50: =+L50-SUM(H50:J50) -> -7.183 | L50: -24.783 | M50: -3.6 | N50: -0.3 | O50: -4.5 | P50: =-28.011-O50-N50-M50 -> -19.611 | Q50: =+SUM(M50:P50) -> -28.011 | R50: -2.3 | S50: =-4.222-R50 -> -1.922 | T50: =-6.295-S50-R50 -> -2.073 | U50: =V50-SUM(R50:T50) -> -2.017 | V50: -8.312 | W50: -2.296 | X50: =-4.126-W50 -> -1.83 | Y50: =-6.927-X50-W50 -> -2.801 | Z50: =+Despesas!R30 -> -2.3751353 | AA50: =+Despesas!S30 -> -9.3021353 | AB50: =+Despesas!T30 -> -4.4674266 | AC50: =+Despesas!U30 -> -3.0901088 | AD50: =+Despesas!V30 -> -3.2502646 | AE50: =+Despesas!W30 -> -3.2641613 | AF50: =+Despesas!X30 -> -3.2140415 | AG50: =+Despesas!Y30 -> -3.4997315 | ... AN50: =+Despesas!AF30 -> -6.1200569
A51: -- Depreciação e Amortização | B51: -9.8 | C51: -3 | D51: =-6-C51 -> -3 | E51: -2.8 | F51: =+G51-SUM(C51:E51) -> -4 | G51: -12.8 | H51: -3.6 | I51: =-7.3-H51 -> -3.7 | J51: -3.88 | K51: =+L51-SUM(H51:J51) -> -3.42 | L51: -14.6 | M51: -4.26 | N51: -4.35 | O51: -4.6 | P51: =-17.8-O51-N51-M51 -> -4.59 | Q51: =+SUM(M51:P51) -> -17.8 | R51: -5.1 | S51: =-9.573-R51 -> -4.473 | T51: =-14.03-S51-R51 -> -4.457 | U51: =V51-SUM(R51:T51) -> -6.441 | V51: -20.471 | W51: -5.58 | X51: =-11.225-W51 -> -5.645 | Y51: =-16.945-X51-W51 -> -5.72 | Z51: =-Z96 -> -5.72 | AA51: =-AA96 -> -22.665 | AB51: =-AB96 -> -22.770061 | AC51: =-AC96 -> -24.403482 | AD51: =-AD96 -> -25.976632 | AE51: =-AE96 -> -26.719919 | AF51: =-AF96 -> -27.442672 | AG51: =-AG96 -> -28.160622 | ... AN51: =-AN96 -> -33.808411
A52: -- Ônus variável da concessão | B52: -4.4 | C52: -1.06 | D52: =-2.2-C52 -> -1.14 | E52: -1.3 | F52: =+G52-SUM(C52:E52) -> -1.3 | G52: -4.8 | H52: -1.2 | I52: =-2.4-H52 -> -1.2 | J52: -1.39 | K52: =+L52-SUM(H52:J52) -> -1.51 | L52: -5.3 | M52: -1.3 | N52: -1.37 | O52: -0.7 | P52: =-4.479-O52-N52-M52 -> -1.109 | Q52: =+SUM(M52:P52) -> -4.479 | R52: -0.8 | S52: =-1.526-R52 -> -0.726 | T52: =-2.324-S52-R52 -> -0.798 | U52: =V52-SUM(R52:T52) -> -0.814 | V52: -3.138 | W52: -0.799 | X52: =-1.543-W52 -> -0.744 | Y52: =-2.42-X52-W52 -> -0.877 | Z52: =+Despesas!R33 -> -0.89067572 | AA52: =+Despesas!S33 -> -3.3106757 | AB52: =+Despesas!T33 -> -3.7228555 | AC52: =+Despesas!U33 -> -4.2137847 | AD52: =+Despesas!V33 -> -4.8753969 | AE52: =+Despesas!W33 -> -5.4402688 | AF52: =+Despesas!X33 -> -6.0263277 | AG52: =+Despesas!Y33 -> -6.5619965 | ... AN52: =+Despesas!AF33 -> -11.475107
A53: -- Manutenção e conservação | B53: -8.56 | C53: -2.07 | D53: =-4.7-C53 -> -2.63 | E53: -3.38 | F53: =+G53-SUM(C53:E53) -> -2.92 | G53: -11 | H53: -5.7 | I53: =-5.2-H53 -> 0.5 | J53: -1.9 | K53: =+L53-SUM(H53:J53) -> -2 | L53: -9.1 | M53: -6.6 | N53: -4.8 | O53: -10.6 | P53: =-13.225-O53-N53-M53 -> 8.775 | Q53: =+SUM(M53:P53) -> -13.225 | R53: -7 | S53: =-13.93-R53 -> -6.93 | T53: =-26.12-S53-R53 -> -12.19 | U53: =V53-SUM(R53:T53) -> -10.142 | V53: -36.262 | W53: -10.379 | X53: =-21.955-W53 -> -11.576 | Y53: =-31.971-X53-W53 -> -10.016 | Z53: =+Despesas!R36 -> -9.75036 | AA53: =+Despesas!S36 -> -41.72136 | AB53: =+Despesas!T36 -> -33.875832 | AC53: =+Despesas!U36 -> -35.569624 | AD53: =+Despesas!V36 -> -37.348105 | AE53: =+Despesas!W36 -> -39.028769 | AF53: =+Despesas!X36 -> -40.785064 | AG53: =+Despesas!Y36 -> -42.620392 | ... AN53: =+Despesas!AF36 -> -58.000465
...

Sheet Tráfego
A1: Rodovias do Tiete | Z1: =65*0.3 -> 19.5
A3: Dados Macro | B3: 2T09 | C3: 3T09 | D3: 4T09 | E3: 2009 | F3: 1T10 | G3: 2T10 | H3: 3T10 | I3: 4T10 | J3: 2010 | K3: 1T11 | L3: 2T11 | M3: 3T11 | N3: 4T11 | O3: 2011 | P3: 1T12 | Q3: 2T12 | R3: 3T12 | S3: 4T12 | T3: 2012 | U3: 1T13 | V3: 2T13 | W3: 3T13 | X3: 4T13 | Y3: 2013 | Z3: 1T14 | AA3: 2T14 | AB3: 3T14 | AC3: 4T14 | AD3: 2014 | AE3: 1T15 | AF3: 2T15 | AG3: 3T15 | AH3: 4T15E | AI3: 2015E | AJ3: 1T16E | AK3: 2T16E | AL3: 3T16E | AM3: 4T16E | AN3: 2016E | AO3: 1T17E | AP3: 2T17E | AQ3: 3T17E | AR3: 4T17E | AS3: 2017E | AT3: 1T18E | AU3: 2T18E | AV3: 3T18E | AW3: 4T18E | AX3: 2018E | AY3: 1T19E | AZ3: 2T19E | BA3: 3T19E | BB3: 4T19E | BC3: 2019E | BD3: 1T20E | BE3: 2T20E | BF3: 3T20E | BG3: 4T20E | BH3: 2020E | BI3: 1T21E | BJ3: 2T21E | BK3: 3T21E | BL3: 4T21E | BM3: 2021E | BN3: 1T22E | BO3: 2T22E | BP3: 3T22E | BQ3: 4T22E | BR3: 2022E | BS3: 1T23E | BT3: 2T23E | BU3: 3T23E | BV3: 4T23E | BW3: 2023E | BX3: 1T24E | BY3: 2T24E | BZ3: 3T24E | CA3: 4T24E | CB3: 2024E | CC3: 1T25E | CD3: 2T25E | CE3: 3T25E | CF3: 4T25E | CG3: 2025E | CH3: 1T26E | CI3: 2T26E | CJ3: 3T26E | CK3: 4T26E | CL3: 2026E | CM3: 1T27E | CN3: 2T27E | CO3: 3T27E | CP3: 4T27E | CQ3: 2027E | CR3: 1T28E | CS3: 2T28E | CT3: 3T28E | CU3: 4T28E | CV3: 2028E
A4: PIB | E4: -0.32824804 | J4: 7.5336155 | K4: 4.235654 | L4: 3.314358 | M4: 2.1219664 | N4: 1.3664596 | O4: 2.7325092 | P4: 0.75274305 | Q4: 0.48977593 | R4: 0.6 | S4: 2.95 | T4: 1 | U4: 2.706666 | V4: 3.3 | W4: 3.8386618 | X4: 3.4717008 | Y4: 3.3 | Z4: 2 | AA4: 2 | AB4: 2 | AC4: 2 | AD4: =Despesas!N4 -> 0.14458389 | AE4: =AI4 -> -3.1 | AF4: =AI4 -> -3.1 | AG4: =AI4 -> -3.1 | AH4: =AI4 -> -3.1 | AI4: =Despesas!S4 -> -3.1 | AJ4: =AN4 -> -2 | AK4: =AN4 -> -2 | AL4: =AN4 -> -2 | AM4: =AN4 -> -2 | AN4: =Despesas!T4 -> -2 | AO4: =AS4 -> 1 | AP4: =AS4 -> 1 | AQ4: =AS4 -> 1 | AR4: =AS4 -> 1 | AS4: =Despesas!U4 -> 1 | AT4: =AX4 -> 2 | AU4: =AX4 -> 2 | AV4: =AX4 -> 2 | AW4: =AX4 -> 2 | AX4: =Despesas!V4 -> 2 | AY4: =BC4 -> 2 | AZ4: =BC4 -> 2 | BA4: =BC4 -> 2 | BB4: =BC4 -> 2 | BC4: =Despesas!W4 -> 2 | BD4: =BH4 -> 2 | BE4: =BH4 -> 2 | BF4: =BH4 -> 2 | BG4: =BH4 -> 2 | BH4: =Despesas!X4 -> 2 | BI4: =BM4 -> 2 | BJ4: =BM4 -> 2 | BK4: =BM4 -> 2 | BL4: =BM4 -> 2 | BM4: =Despesas!Y4 -> 2 | BN4: =BR4 -> 2 | BO4: =BR4 -> 2 | BP4: =BR4 -> 2 | BQ4: =BR4 -> 2 | BR4: =Despesas!Z4 -> 2 | BS4: =BW4 -> 2 | BT4: =BW4 -> 2 | BU4: =BW4 -> 2 | BV4: =BW4 -> 2 | BW4: =Despesas!AA4 -> 2 | BX4: =CB4 -> 2 | BY4: =CB4 -> 2 | BZ4: =CB4 -> 2 | CA4: =CB4 -> 2 | CB4: =Despesas!AB4 -> 2 | CC4: =CG4 -> 2 | CD4: =CG4 -> 2 | CE4: =CG4 -> 2 | CF4: =CG4 -> 2 | CG4: =Despesas!AC4 -> 2 | CH4: =CL4 -> 2 | CI4: =CL4 -> 2 | CJ4: =CL4 -> 2 | CK4: =CL4 -> 2 | CL4: =Despesas!AD4 -> 2 | CM4: =CQ4 -> 2 | CN4: =CQ4 -> 2 | CO4: =CQ4 -> 2 | CP4: =CQ4 -> 2 | CQ4: =Despesas!AE4 -> 2 | CR4: =CV4 -> 2 | CS4: =CV4 -> 2 | CT4: =CV4 -> 2 | CU4: =CV4 -> 2 | CV4: =Despesas!AF4 -> 2
A5: IPCA | E5: 4.3116501 | J5: 5.9086887 | K5: 2.439696 | L5: 1.3956003 | M5: 1.0634041 | N5: 1.4569972 | O5: 6.5033527 | P5: 1.224539 | Q5: 1.08289 | R5: 1.416561 | S5: 1.9018948 | T5: 5.84 | U5: =+Y5/4 -> 1.35 | V5: =+Y5/4 -> 1.35 | W5: 0 | X5: =+Y5/4 -> 1.35 | Y5: 5.4 | Z5: =+AD5/4 -> 1.6025 | AA5: =+AD5/4 -> 1.6025 | AB5: =+AD5/4 -> 1.6025 | AC5: =+AD5/4 -> 1.6025 | AD5: =Despesas!N5 -> 6.41 | AE5: =AI5/4 -> 2.5 | AF5: =AI5/4 -> 2.5 | AG5: =AI5/4 -> 2.5 | AH5: =AI5/4 -> 2.5 | AI5: =Despesas!S5 -> 10 | AJ5: =AN5/4 -> 1.6 | AK5: =AN5/4 -> 1.6 | AL5: =AN5/4 -> 1.6 | AM5: =AN5/4 -> 1.6 | AN5: =Despesas!T5 -> 6.4 | AO5: =AS5/4 -> 1.25 | AP5: =AS5/4 -> 1.25 | AQ5: =AS5/4 -> 1.25 | AR5: =AS5/4 -> 1.25 | AS5: =Despesas!U5 -> 5 | AT5: =AX5/4 -> 1.25 | AU5: =AX5/4 -> 1.25 | AV5: =AX5/4 -> 1.25 | AW5: =AX5/4 -> 1.25 | AX5: =Despesas!V5 -> 5 | AY5: =BC5/4 -> 1.125 | AZ5: =BC5/4 -> 1.125 | BA5: =BC5/4 -> 1.125 | BB5: =BC5/4 -> 1.125 | BC5: =Despesas!W5 -> 4.5 | BD5: =BH5/4 -> 1.125 | BE5: =BH5/4 -> 1.125 | BF5: =BH5/4 -> 1.125 | BG5: =BH5/4 -> 1.125 | BH5: =Despesas!X5 -> 4.5 | BI5: =BM5/4 -> 1.125 | BJ5: =BM5/4 -> 1.125 | BK5: =BM5/4 -> 1.125 | BL5: =BM5/4 -> 1.125 | BM5: =Despesas!Y5 -> 4.5 | BN5: =BR5/4 -> 1.125 | BO5: =BR5/4 -> 1.125 | BP5: =BR5/4 -> 1.125 | BQ5: =BR5/4 -> 1.125 | BR5: =Despesas!Z5 -> 4.5 | BS5: =BW5/4 -> 1.125 | BT5: =BW5/4 -> 1.125 | BU5: =BW5/4 -> 1.125 | BV5: =BW5/4 -> 1.125 | BW5: =Despesas!AA5 -> 4.5 | BX5: =CB5/4 -> 1.125 | BY5: =CB5/4 -> 1.125 | BZ5: =CB5/4 -> 1.125 | CA5: =CB5/4 -> 1.125 | CB5: =Despesas!AB5 -> 4.5 | CC5: =CG5/4 -> 1.125 | CD5: =CG5/4 -> 1.125 | CE5: =CG5/4 -> 1.125 | CF5: =CG5/4 -> 1.125 | CG5: =Despesas!AC5 -> 4.5 | CH5: =CL5/4 -> 1.125 | CI5: =CL5/4 -> 1.125 | CJ5: =CL5/4 -> 1.125 | CK5: =CL5/4 -> 1.125 | CL5: =Despesas!AD5 -> 4.5 | CM5: =CQ5/4 -> 1.125 | CN5: =CQ5/4 -> 1.125 | CO5: =CQ5/4 -> 1.125 | CP5: =CQ5/4 -> 1.125 | CQ5: =Despesas!AE5 -> 4.5 | CR5: =CV5/4 -> 1.125 | CS5: =CV5/4 -> 1.125 | CT5: =CV5/4 -> 1.125 | CU5: =CV5/4 -> 1.125 | CV5: =Despesas!AF5 -> 4.5
A6: IGPM | E6: -1.7192492 | J6: 11.323143 | K6: 2.4312626 | L6: 0.69680368 | M6: 0.97144444 | N6: 0.91198891 | O6: 5.096813 | P6: 0.61573961 | Q6: 2.5570914 | R6: 3.7862169 | S6: 0.66992596 | T6: 7.82 | U6: =+Y6/4 -> 1.25 | V6: =+Y6/4 -> 1.25 | W6: =+Y6/4 -> 1.25 | X6: =+Y6/4 -> 1.25 | Y6: 5 | Z6: =+AD6/4 -> 0.9225 | AA6: =+AD6/4 -> 0.9225 | AB6: =+AD6/4 -> 0.9225 | AC6: =+AD6/4 -> 0.9225 | AD6: =Despesas!N6 -> 3.69 | AE6: =AI6/4 -> 2.475 | AF6: =AI6/4 -> 2.475 | AG6: =AI6/4 -> 2.475 | AH6: =AI6/4 -> 2.475 | AI6: =Despesas!S6 -> 9.9 | AJ6: =AN6/4 -> 1.625 | AK6: =AN6/4 -> 1.625 | AL6: =AN6/4 -> 1.625 | AM6: =AN6/4 -> 1.625 | AN6: =Despesas!T6 -> 6.5 | AO6: =AS6/4 -> 1.375 | AP6: =AS6/4 -> 1.375 | AQ6: =AS6/4 -> 1.375 | AR6: =AS6/4 -> 1.375 | AS6: =Despesas!U6 -> 5.5 | AT6: =AX6/4 -> 1.375 | AU6: =AX6/4 -> 1.375 | AV6: =AX6/4 -> 1.375 | AW6: =AX6/4 -> 1.375 | AX6: =Despesas!V6 -> 5.5 | AY6: =BC6/4 -> 1.375 | AZ6: =BC6/4 -> 1.375 | BA6: =BC6/4 -> 1.375 | BB6: =BC6/4 -> 1.375 | BC6: =Despesas!W6 -> 5.5 | BD6: =BH6/4 -> 1.375 | BE6: =BH6/4 -> 1.375 | BF6: =BH6/4 -> 1.375 | BG6: =BH6/4 -> 1.375 | BH6: =Despesas!X6 -> 5.5 | BI6: =BM6/4 -> 1.375 | BJ6: =BM6/4 -> 1.375 | BK6: =BM6/4 -> 1.375 | BL6: =BM6/4 -> 1.375 | BM6: =Despesas!Y6 -> 5.5 | BN6: =BR6/4 -> 1.375 | BO6: =BR6/4 -> 1.375 | BP6: =BR6/4 -> 1.375 | BQ6: =BR6/4 -> 1.375 | BR6: =Despesas!Z6 -> 5.5 | BS6: =BW6/4 -> 1.375 | BT6: =BW6/4 -> 1.375 | BU6: =BW6/4 -> 1.375 | BV6: =BW6/4 -> 1.375 | BW6: =Despesas!AA6 -> 5.5 | BX6: =CB6/4 -> 1.375 | BY6: =CB6/4 -> 1.375 | BZ6: =CB6/4 -> 1.375 | CA6: =CB6/4 -> 1.375 | CB6: =Despesas!AB6 -> 5.5 | CC6: =CG6/4 -> 1.375 | CD6: =CG6/4 -> 1.375 | CE6: =CG6/4 -> 1.375 | CF6: =CG6/4 -> 1.375 | CG6: =Despesas!AC6 -> 5.5 | CH6: =CL6/4 -> 1.375 | CI6: =CL6/4 -> 1.375 | CJ6: =CL6/4 -> 1.375 | CK6: =CL6/4 -> 1.375 | CL6: =Despesas!AD6 -> 5.5 | CM6: =CQ6/4 -> 1.375 | CN6: =CQ6/4 -> 1.375 | CO6: =CQ6/4 -> 1.375 | CP6: =CQ6/4 -> 1.375 | CQ6: =Despesas!AE6 -> 5.5 | CR6: =CV6/4 -> 1.375 | CS6: =CV6/4 -> 1.375 | CT6: =CV6/4 -> 1.375 | CU6: =CV6/4 -> 1.375 | CV6: =Despesas!AF6 -> 5.5
A7: Selic (fim de período) | E7: 8.75 | J7: 10.75 | K7: 11.75 | L7: 12.25 | M7: 12 | N7: 11 | O7: 11 | P7: 9.75 | Q7: 8.5 | R7: 7.5 | S7: 7.25 | T7: 7.25 | U7: =+Y7 -> 8.75 | V7: =+Y7 -> 8.75 | W7: =+Y7 -> 8.75 | X7: =+Y7 -> 8.75 | Y7: 8.75 | Z7: =+AD7 -> 11.75 | AA7: =+AD7 -> 11.75 | AB7: =+AD7 -> 11.75 | AC7: =+AD7 -> 11.75 | AD7: =Despesas!N7 -> 11.75 | AE7: =AI7 -> 14.25 | AF7: =AI7 -> 14.25 | AG7: =AI7 -> 14.25 | AH7: =AI7 -> 14.25 | AI7: =Despesas!S7 -> 14.25 | AJ7: =AN7 -> 12.75 | AK7: =AN7 -> 12.75 | AL7: =AN7 -> 12.75 | AM7: =AN7 -> 12.75 | AN7: =Despesas!T7 -> 12.75 | AO7: =AS7 -> 12.75 | AP7: =AS7 -> 12.75 | AQ7: =AS7 -> 12.75 | AR7: =AS7 -> 12.75 | AS7: =Despesas!U7 -> 12.75 | AT7: =AX7 -> 12.75 | AU7: =AX7 -> 12.75 | AV7: =AX7 -> 12.75 | AW7: =AX7 -> 12.75 | AX7: =Despesas!V7 -> 12.75 | AY7: =BC7 -> 12.75 | AZ7: =BC7 -> 12.75 | BA7: =BC7 -> 12.75 | BB7: =BC7 -> 12.75 | BC7: =Despesas!W7 -> 12.75 | BD7: =BH7 -> 12.75 | BE7: =BH7 -> 12.75 | BF7: =BH7 -> 12.75 | BG7: =BH7 -> 12.75 | BH7: =Despesas!X7 -> 12.75 | BI7: =BM7 -> 12.75 | BJ7: =BM7 -> 12.75 | BK7: =BM7 -> 12.75 | BL7: =BM7 -> 12.75 | BM7: =Despesas!Y7 -> 12.75 | BN7: =BR7 -> 12.75 | BO7: =BR7 -> 12.75 | BP7: =BR7 -> 12.75 | BQ7: =BR7 -> 12.75 | BR7: =Despesas!Z7 -> 12.75 | BS7: =BW7 -> 12.75 | BT7: =BW7 -> 12.75 | BU7: =BW7 -> 12.75 | BV7: =BW7 -> 12.75 | BW7: =Despesas!AA7 -> 12.75 | BX7: =CB7 -> 12.75 | BY7: =CB7 -> 12.75 | BZ7: =CB7 -> 12.75 | CA7: =CB7 -> 12.75 | CB7: =Despesas!AB7 -> 12.75 | CC7: =CG7 -> 12.75 | CD7: =CG7 -> 12.75 | CE7: =CG7 -> 12.75 | CF7: =CG7 -> 12.75 | CG7: =Despesas!AC7 -> 12.75 | CH7: =CL7 -> 12.75 | CI7: =CL7 -> 12.75 | CJ7: =CL7 -> 12.75 | CK7: =CL7 -> 12.75 | CL7: =Despesas!AD7 -> 12.75 | CM7: =CQ7 -> 12.75 | CN7: =CQ7 -> 12.75 | CO7: =CQ7 -> 12.75 | CP7: =CQ7 -> 12.75 | CQ7: =Despesas!AE7 -> 12.75 | CR7: =CV7 -> 12.75 | CS7: =CV7 -> 12.75 | CT7: =CV7 -> 12.75 | CU7: =CV7 -> 12.75 | CV7: =Despesas!AF7 -> 12.75
A8: Selic (média) | E8: 9.9166667 | J8: 10 | K8: 11.333333 | L8: 12.012097 | M8: 12.280769 | N8: 11.415385 | O8: 11.708333 | P8: 10.380952 | Q8: 8.6666667 | R8: 7.6666667 | S8: 7.25 | T8: 8.4583333 | U8: =+AVERAGE(T7:U7) -> 8 | V8: =+AVERAGE(U7:V7) -> 8.75 | W8: =+AVERAGE(V7:W7) -> 8.75 | X8: =+AVERAGE(W7:X7) -> 8.75 | Y8: 7.7291667 | Z8: =+AVERAGE(Y7:Z7) -> 10.25 | AA8: =+AVERAGE(Z7:AA7) -> 11.75 | AB8: =+AVERAGE(AA7:AB7) -> 11.75 | AC8: =+AVERAGE(AB7:AC7) -> 11.75 | AD8: =Despesas!N8 -> 11.020833 | AE8: =AVERAGE(AD7:AE7) -> 13 | AF8: =AVERAGE(AE7:AF7) -> 14.25 | AG8: =AVERAGE(AF7:AG7) -> 14.25 | AH8: =AVERAGE(AG7:AH7) -> 14.25 | AI8: =Despesas!S8 -> 13.58 | AJ8: =AVERAGE(AI7:AJ7) -> 13.5 | AK8: =AVERAGE(AJ7:AK7) -> 12.75 | AL8: =AVERAGE(AK7:AL7) -> 12.75 | AM8: =AVERAGE(AL7:AM7) -> 12.75 | AN8: =Despesas!T8 -> 13.5 | AO8: =AVERAGE(AN7:AO7) -> 12.75 | AP8: =AVERAGE(AO7:AP7) -> 12.75 | AQ8: =AVERAGE(AP7:AQ7) -> 12.75 | AR8: =AVERAGE(AQ7:AR7) -> 12.75 | AS8: =Despesas!U8 -> 12.75 | AT8: =AVERAGE(AS7:AT7) -> 12.75 | AU8: =AVERAGE(AT7:AU7) -> 12.75 | AV8: =AVERAGE(AU7:AV7) -> 12.75 | AW8: =AVERAGE(AV7:AW7) -> 12.75 | AX8: =Despesas!V8 -> 12.75 | AY8: =AVERAGE(AX7:AY7) -> 12.75 | AZ8: =AVERAGE(AY7:AZ7) -> 12.75 | BA8: =AVERAGE(AZ7:BA7) -> 12.75 | BB8: =AVERAGE(BA7:BB7) -> 12.75 | BC8: =Despesas!W8 -> 12.75 | BD8: =AVERAGE(BC7:BD7) -> 12.75 | BE8: =AVERAGE(BD7:BE7) -> 12.75 | BF8: =AVERAGE(BE7:BF7) -> 12.75 | BG8: =AVERAGE(BF7:BG7) -> 12.75 | BH8: =Despesas!X8 -> 12.75 | BI8: =AVERAGE(BH7:BI7) -> 12.75 | BJ8: =AVERAGE(BI7:BJ7) -> 12.75 | BK8: =AVERAGE(BJ7:BK7) -> 12.75 | BL8: =AVERAGE(BK7:BL7) -> 12.75 | BM8: =Despesas!Y8 -> 12.75 | BN8: =AVERAGE(BM7:BN7) -> 12.75 | BO8: =AVERAGE(BN7:BO7) -> 12.75 | BP8: =AVERAGE(BO7:BP7) -> 12.75 | BQ8: =AVERAGE(BP7:BQ7) -> 12.75 | BR8: =Despesas!Z8 -> 12.75 | BS8: =AVERAGE(BR7:BS7) -> 12.75 | BT8: =AVERAGE(BS7:BT7) -> 12.75 | BU8: =AVERAGE(BT7:BU7) -> 12.75 | BV8: =AVERAGE(BU7:BV7) -> 12.75 | BW8: =Despesas!AA8 -> 12.75 | BX8: =AVERAGE(BW7:BX7) -> 12.75 | BY8: =AVERAGE(BX7:BY7) -> 12.75 | BZ8: =AVERAGE(BY7:BZ7) -> 12.75 | CA8: =AVERAGE(BZ7:CA7) -> 12.75 | CB8: =Despesas!AB8 -> 12.75 | CC8: =AVERAGE(CB7:CC7) -> 12.75 | CD8: =AVERAGE(CC7:CD7) -> 12.75 | CE8: =AVERAGE(CD7:CE7) -> 12.75 | CF8: =AVERAGE(CE7:CF7) -> 12.75 | CG8: =Despesas!AC8 -> 12.75 | CH8: =AVERAGE(CG7:CH7) -> 12.75 | CI8: =AVERAGE(CH7:CI7) -> 12.75 | CJ8: =AVERAGE(CI7:CJ7) -> 12.75 | CK8: =AVERAGE(CJ7:CK7) -> 12.75 | CL8: =Despesas!AD8 -> 12.75 | CM8: =AVERAGE(CL7:CM7) -> 12.75 | CN8: =AVERAGE(CM7:CN7) -> 12.75 | CO8: =AVERAGE(CN7:CO7) -> 12.75 | CP8: =AVERAGE(CO7:CP7) -> 12.75 | CQ8: =Despesas!AE8 -> 12.75 | CR8: =AVERAGE(CQ7:CR7) -> 12.75 | CS8: =AVERAGE(CR7:CS7) -> 12.75 | CT8: =AVERAGE(CS7:CT7) -> 12.75 | CU8: =AVERAGE(CT7:CU7) -> 12.75 | CV8: =Despesas!AF8 -> 12.75
A10: Base Tarifária (R$ por Km) | B10: 2T09 | C10: 3T09 | D10: 4T09 | E10: =E3 -> 2009 | F10: =F3 -> 1T10 | G10: =G3 -> 2T10 | H10: =H3 -> 3T10 | I10: =I3 -> 4T10 | J10: =J3 -> 2010 | K10: =K3 -> 1T11 | L10: =L3 -> 2T11 | ... CV10: =CV3 -> 2028E
A11: Pista Simples | U11: 0.08294 | V11: =+U11 -> 0.08294 | W11: =+V11*(1+(W$5/100)*4) -> 0.08294 | X11: =+W11 -> 0.08294 | Z11: =+X11 -> 0.08294 | AA11: =+Z11 -> 0.08294 | AB11: =+AA11*(1+(AB$5/100)*4) -> 0.088256454 | AC11: =+AB11 -> 0.088256454 | AE11: =+AC11 -> 0.088256454 | AF11: =+AE11 -> 0.088256454 | AG11: =+AF11*(1+(AG$5/100)*4) -> 0.097082099 | AH11: =+AG11 -> 0.097082099 | AJ11: =+AH11 -> 0.097082099 | AK11: =+AJ11 -> 0.097082099 | AL11: =+AK11*(1+(AL$5/100)*4) -> 0.10329535 | AM11: =+AL11 -> 0.10329535 | AO11: =+AM11 -> 0.10329535 | AP11: =+AO11 -> 0.10329535 | AQ11: =+AP11*(1+(AQ$5/100)*4) -> 0.10846012 | AR11: =+AQ11 -> 0.10846012 | AT11: =+AR11 -> 0.10846012 | AU11: =+AT11 -> 0.10846012 | AV11: =+AU11*(1+(AV$5/100)*4) -> 0.11388313 | AW11: =+AV11 -> 0.11388313 | AY11: =+AW11 -> 0.11388313 | AZ11: =+AY11 -> 0.11388313 | BA11: =+AZ11*(1+(BA$5/100)*4) -> 0.11900787 | BB11: =+BA11 -> 0.11900787 | BD11: =+BB11 -> 0.11900787 | BE11: =+BD11 -> 0.11900787 | BF11: =+BE11*(1+(BF$5/100)*4) -> 0.12436322 | BG11: =+BF11 -> 0.12436322 | BI11: =+BG11 -> 0.12436322 | BJ11: =+BI11 -> 0.12436322 | BK11: =+BJ11*(1+(BK$5/100)*4) -> 0.12995957 | BL11: =+BK11 -> 0.12995957 | BN11: =+BL11 -> 0.12995957 | BO11: =+BN11 -> 0.12995957 | BP11: =+BO11*(1+(BP$5/100)*4) -> 0.13580775 | BQ11: =+BP11 -> 0.13580775 | BS11: =+BQ11 -> 0.13580775 | BT11: =+BS11 -> 0.13580775 | BU11: =+BT11*(1+(BU$5/100)*4) -> 0.1419191 | BV11: =+BU11 -> 0.1419191 | BX11: =+BV11 -> 0.1419191 | BY11: =+BX11 -> 0.1419191 | BZ11: =+BY11*(1+(BZ$5/100)*4) -> 0.14830546 | CA11: =+BZ11 -> 0.14830546 | CC11: =+CA11 -> 0.14830546 | CD11: =+CC11 -> 0.14830546 | CE11: =+CD11*(1+(CE$5/100)*4) -> 0.1549792 | CF11: =+CE11 -> 0.1549792 | CH11: =+CF11 -> 0.1549792 | CI11: =+CH11 -> 0.1549792 | CJ11: =+CI11*(1+(CJ$5/100)*4) -> 0.16195327 | CK11: =+CJ11 -> 0.16195327 | CM11: =+CK11 -> 0.16195327 | CN11: =+CM11 -> 0.16195327 | CO11: =+CN11*(1+(CO$5/100)*4) -> 0.16924116 | CP11: =+CO11 -> 0.16924116 | CR11: =+CP11 -> 0.16924116 | CS11: =+CR11 -> 0.16924116 | CT11: =+CS11*(1+(CT$5/100)*4) -> 0.17685701 | CU11: =+CT11 -> 0.17685701
A12: Pista Dupla | U12: 0.116112 | V12: =+U12 -> 0.116112 | W12: =+V12*(1+(W$5/100)*4) -> 0.116112 | X12: =+W12 -> 0.116112 | Z12: =+X12 -> 0.116112 | AA12: =+Z12 -> 0.116112 | AB12: =+AA12*(1+(AB$5/100)*4) -> 0.12355478 | AC12: =+AB12 -> 0.12355478 | AE12: =+AC12 -> 0.12355478 | AF12: =+AE12 -> 0.12355478 | AG12: =+AF12*(1+(AG$5/100)*4) -> 0.13591026 | AH12: =+AG12 -> 0.13591026 | AJ12: =+AH12 -> 0.13591026 | AK12: =+AJ12 -> 0.13591026 | AL12: =+AK12*(1+(AL$5/100)*4) -> 0.14460851 | AM12: =+AL12 -> 0.14460851 | AO12: =+AM12 -> 0.14460851 | AP12: =+AO12 -> 0.14460851 | AQ12: =+AP12*(1+(AQ$5/100)*4) -> 0.15183894 | AR12: =+AQ12 -> 0.15183894 | AT12: =+AR12 -> 0.15183894 | AU12: =+AT12 -> 0.15183894 | AV12: =+AU12*(1+(AV$5/100)*4) -> 0.15943089 | AW12: =+AV12 -> 0.15943089 | AY12: =+AW12 -> 0.15943089 | AZ12: =+AY12 -> 0.15943089 | BA12: =+AZ12*(1+(BA$5/100)*4) -> 0.16660528 | BB12: =+BA12 -> 0.16660528 | BD12: =+BB12 -> 0.16660528 | BE12: =+BD12 -> 0.16660528 | BF12: =+BE12*(1+(BF$5/100)*4) -> 0.17410251 | BG12: =+BF12 -> 0.17410251 | BI12: =+BG12 -> 0.17410251 | BJ12: =+BI12 -> 0.17410251 | BK12: =+BJ12*(1+(BK$5/100)*4) -> 0.18193713 | BL12: =+BK12 -> 0.18193713 | BN12: =+BL12 -> 0.18193713 | BO12: =+BN12 -> 0.18193713 | BP12: =+BO12*(1+(BP$5/100)*4) -> 0.1901243 | BQ12: =+BP12 -> 0.1901243 | BS12: =+BQ12 -> 0.1901243 | BT12: =+BS12 -> 0.1901243 | BU12: =+BT12*(1+(BU$5/100)*4) -> 0.19867989 | BV12: =+BU12 -> 0.19867989 | BX12: =+BV12 -> 0.19867989 | BY12: =+BX12 -> 0.19867989 | BZ12: =+BY12*(1+(BZ$5/100)*4) -> 0.20762049 | CA12: =+BZ12 -> 0.20762049 | CC12: =+CA12 -> 0.20762049 | CD12: =+CC12 -> 0.20762049 | CE12: =+CD12*(1+(CE$5/100)*4) -> 0.21696341 | CF12: =+CE12 -> 0.21696341 | CH12: =+CF12 -> 0.21696341 | CI12: =+CH12 -> 0.21696341 | CJ12: =+CI12*(1+(CJ$5/100)*4) -> 0.22672676 | CK12: =+CJ12 -> 0.22672676 | CM12: =+CK12 -> 0.22672676 | CN12: =+CM12 -> 0.22672676 | CO12: =+CN12*(1+(CO$5/100)*4) -> 0.23692947 | CP12: =+CO12 -> 0.23692947 | CR12: =+CP12 -> 0.23692947 | CS12: =+CR12 -> 0.23692947 | CT12: =+CS12*(1+(CT$5/100)*4) -> 0.24759129 | CU12: =+CT12 -> 0.24759129
A14: Dados Operacionais | B14: 2T09 | C14: 3T09 | D14: 4T09 | E14: =E3 -> 2009 | F14: =F3 -> 1T10 | G14: =G3 -> 2T10 | H14: =H3 -> 3T10 | I14: =I3 -> 4T10 | J14: =J3 -> 2010 | K14: =K3 -> 1T11 | L14: =L3 -> 2T11 | ... CV14: =CV3 -> 2028E
A15: Consolidado
A16: Tarifa (R$) | J16: =+J35*1000/J31 -> 3.5306709 | K16: =+K35*1000/K31 -> 3.6037024 | L16: =+L35*1000/L31 -> 3.5994226 | M16: =+M35*1000/M31 -> 3.9045793 | N16: =+N35*1000/N31 -> 3.9207041 | O16: =+O35*1000/O31 -> 3.7630187 | P16: =+P35*1000/P31 -> 3.918603 | Q16: =+Q35*1000/Q31 -> 3.8893874 | ... CV16: =+CV35*1000/CV31 -> 9.1961709
A17: Y/Y (%) | O17: =+O16/J16-1 -> 0.065808408 | P17: =+P16/K16-1 -> 0.08738252 | Q17: =+Q16/L16-1 -> 0.080558682 | R17: =+R16/M16-1 -> 0.050691189 | S17: =+S16/N16-1 -> 0.046436979 | T17: =+T16/O16-1 -> 0.065162719 | U17: =+U16/P16-1 -> 0.048984036 | V17: =+V16/Q16-1 -> 0.029285433 | ... CV17: =+CV16/CQ16-1 -> 0.044980984
A19: Distância Total (km) | T19: =+U19 -> 406.34 | U19: =+U20+U21 -> 406.34 | V19: =+V20+V21 -> 406.265 | W19: =+W20+W21 -> 406.265 | X19: =+X20+X21 -> 406.265 | Y19: =+Y20+Y21 -> 406.265 | Z19: =+Z20+Z21 -> 406.265 | AA19: =+AA20+AA21 -> 406.265 | AB19: =+AB20+AB21 -> 406.265 | ... CV19: =+CV20+CV21 -> 415.145
A20: -- Pista Simples | T20: =+U20 -> 276.59 | U20: =+U50+U66+U82+U98+U114+U130+U146+U162+U178 -> 276.59 | V20: =+V50+V66+V82+V98+V114+V130+V146+V162+V178 -> 276.615 | W20: =+W50+W66+W82+W98+W114+W130+W146+W162+W178 -> 276.615 | X20: =+X50+X66+X82+X98+X114+X130+X146+X162+X178 -> 276.615 | Y20: =+Y50+Y66+Y82+Y98+Y114+Y130+Y146+Y162+Y178 -> 276.615 | Z20: =+Z50+Z66+Z82+Z98+Z114+Z130+Z146+Z162+Z178 -> 276.615 | AA20: =+AA50+AA66+AA82+AA98+AA114+AA130+AA146+AA162+AA178 -> 276.615 | AB20: =+AB50+AB66+AB82+AB98+AB114+AB130+AB146+AB162+AB178 -> 276.615 | ... CV20: =+CV50+CV66+CV82+CV98+CV114+CV130+CV146+CV162+CV178 -> 189.465
A21: -- Pista Dupla | T21: =+U21 -> 129.75 | U21: =+U51+U67+U83+U99+U115+U131+U147+U163+U179 -> 129.75 | V21: =+V51+V67+V83+V99+V115+V131+V147+V163+V179 -> 129.65 | W21: =+W51+W67+W83+W99+W115+W131+W147+W163+W179 -> 129.65 | X21: =+X51+X67+X83+X99+X115+X131+X147+X163+X179 -> 129.65 | Y21: =+Y51+Y67+Y83+Y99+Y115+Y131+Y147+Y163+Y179 -> 129.65 | Z21: =+Z51+Z67+Z83+Z99+Z115+Z131+Z147+Z163+Z179 -> 129.65 | AA21: =+AA51+AA67+AA83+AA99+AA115+AA131+AA147+AA163+AA179 -> 129.65 | AB21: =+AB51+AB67+AB83+AB99+AB115+AB131+AB147+AB163+AB179 -> 129.65 | ... CV21: =+CV51+CV67+CV83+CV99+CV115+CV131+CV147+CV163+CV179 -> 225.68
A22: % Pista Dupla | T22: =+U22 -> 0.31931388 | U22: =+U21/U19 -> 0.31931388 | V22: =+V21/V19 -> 0.31912668 | W22: =+W21/W19 -> 0.31912668 | X22: =+X21/X19 -> 0.31912668 | Y22: =+Y21/Y19 -> 0.31912668 | Z22: =+Z21/Z19 -> 0.31912668 | AA22: =+AA21/AA19 -> 0.31912668 | AB22: =+AB21/AB19 -> 0.31912668 | ... CV22: =+CV21/CV19 -> 0.54361729
