Workbook
Name _1Excel_BuiltIn_Print_Area_1_1: RPA!$A$1:$K$32
Name Excel_BuiltIn_Print_Area_1_1: RPA!$A$1:$K$32

Sheet RPA
A1: RPA – RECIBO DE PAGAMENTO A AUTÔNOMO
A2: DADOS DO EMITENTE
A3: Nome ou Razão Social: | K3: 1ª Via
A4: Matrícula (CNPJ/INSS): | I4: Recibo Nº ou Mês/Ano:
A5: Endereço:
A6: DADOS DO PRESTADOR DE SERVIÇOS
A7: Nome:
A8: Nº do CPF: | H8: Nº do RG:
A9: Endereço:
A10: BASE DE CÁLCULO | H10: CÁLCULO DO ISS
A11: Valor dos Serviços Prestados........ | E11: R$ | F11: 0 | H11: Base de Cálculo........................ | J11: R$ | K11: =F14 -> 0
A12: Valor dos Serviços Prestados........ | E12: R$ | F12: 0 | H12: Alíquota.................................... | J12: % | K12: 5
A13: Valor dos Serviços Prestados........ | E13: R$ | F13: 0 | H13: Valor a Recolher........................ | J13: R$ | K13: =0+K11*K12% -> 0
A14: Soma....................................... | E14: R$ | F14: =SUM(F11:F13) -> 0
A16: CÁLCULO DO INSS: | H16: DESCONTOS
A17: Base de Cálculo........................... | E17: R$ | F17: =F14 -> 0 | H17: Base de Cálculo........................ | J17: R$ | K17: =F14 -> 0
A18: Alíquota....................................... | E18: % | F18: 11 | H18: IRPF Retido.............................. | J18: R$ | K18: =F25 -> 0
A19: Valor a Recolher.......................... | E19: R$ | F19: =0+F17*F18% -> 0 | H19: ISS Retido................................ | J19: R$ | K19: =K13 -> 0
H20: INSS Retido.............................. | J20: R$ | K20: =F19 -> 0
A21: CALCULO DO IRPF | H21: Valor Líquido a Receber | J21: R$ | K21: =K17-(SUM(K18:K20)) -> 0
A22: Base de Calculo | E22: R$ | F22: =Imposto_de_Renda!B1 -> 0 | H22: SERVIÇO PRESTADO
A23: Alíquota | E23: % | F23: =Imposto_de_Renda!G10 -> 0
A24: Dedução | E24: R$ | F24: =Imposto_de_Renda!H10 -> 0
A25: Valor a Recolher | F25: =Imposto_de_Renda!B2 -> 0
A27: Recebi do ente acima identificado pela prestação dos serviços a importância de: | J27: R$ | K27: =K21 -> 0
A29: Local: | H29: Data:
A31: Assinatura:
A32: ------------------------------------------------------------------------------------------------------------------------------------------------------------------
A33: =A1 -> RPA – RECIBO DE PAGAMENTO A AUTÔNOMO
A34: =A2 -> DADOS DO EMITENTE
A35: =A3 -> Nome ou Razão Social: | D35: =D3 -> 0 | K35: 1ª Via
A36: =A4 -> Matrícula (CNPJ/INSS): | D36: =D4 -> 0 | I36: =I4 -> Recibo Nº ou Mês/Ano: | K36: =K4 -> 0
A37: =A5 -> Endereço: | B37: =B5 -> 0
A38: =A6 -> DADOS DO PRESTADOR DE SERVIÇOS
A39: =A7 -> Nome: | B39: =B7 -> 0
A40: =A8 -> Nº do CPF: | B40: =B8 -> 0 | H40: =H8 -> Nº do RG: | I40: =I8 -> 0
A41: =A9 -> Endereço: | B41: =B9 -> 0
A42: =A10 -> BASE DE CÁLCULO | H42: =H10 -> CÁLCULO DO ISS
A43: =A11 -> Valor dos Serviços Prestados........ | E43: =E11 -> R$ | F43: =F11 -> 0 | H43: =H11 -> Base de Cálculo........................ | J43: =J11 -> R$ | K43: =K11 -> 0
A44: =A12 -> Valor dos Serviços Prestados........ | E44: =E12 -> R$ | F44: =F12 -> 0 | H44: =H12 -> Alíquota.................................... | J44: =J12 -> % | K44: =K12 -> 5
...

Sheet Imposto_de_Renda
A1: Base de Cálculo | B1: =RPA!F14 -> 0
A2: Valor IRPF | B2: =F10 -> 0
A4: VALOR MIN | B4: VALOR MAX | C4: VALOR | D4: TAXA | E4: DEDUCAO | F4: IMPOSTO | G4: TRANSPORTAR RPA
A5: 0 | B5: 1434.59 | C5: =IF(AND($B$1>$A5,$B$1<=$B5),$B$1,0) -> 0 | D5: 0 | E5: 0 | F5: 0 | G5: 0 | H5: 0
A6: =B5 -> 1434.59 | B6: 2150 | C6: =IF(AND($B$1>$A6,$B$1<=$B6),$B$1,0) -> 0 | D6: 0.075 | E6: 107.59 | F6: =IF(((D6*C6)-E6)<=0,0,(D6*C6)-E6) -> 0 | G6: =IF(F6<>0,D6,0) -> 0 | H6: =IF(F6<>0,E6,0) -> 0
A7: =B6 -> 2150 | B7: 2866.7 | C7: =IF(AND($B$1>$A7,$B$1<=$B7),$B$1,0) -> 0 | D7: 0.15 | E7: 268.84 | F7: =IF(((D7*C7)-E7)<=0,0,(D7*C7)-E7) -> 0 | G7: =IF(F7<>0,D7,0) -> 0 | H7: =IF(F7<>0,E7,0) -> 0
A8: =B7 -> 2866.7 | B8: 3582 | C8: =IF(AND($B$1>$A8,$B$1<=$B8),$B$1,0) -> 0 | D8: 0.225 | E8: 483.84 | F8: =IF(((D8*C8)-E8)<=0,0,(D8*C8)-E8) -> 0 | G8: =IF(F8<>0,D8,0) -> 0 | H8: =IF(F8<>0,E8,0) -> 0
A9: =B8 -> 3582 | B9: 999999 | C9: =IF(AND($B$1>$A9,$B$1<=$B9),$B$1,0) -> 0 | D9: 0.275 | E9: 662.94 | F9: =IF(((D9*C9)-E9)<=0,0,(D9*C9)-E9) -> 0 | G9: =IF(F9<>0,D9,0) -> 0 | H9: =IF(F9<>0,E9,0) -> 0
E10: Totais | F10: =SUM(F5:F9) -> 0 | G10: =SUM(G5:G9) -> 0 | H10: =SUM(H5:H9) -> 0
