Workbook

Sheet Simples Nacional 2017
A1: SIMPLES NACIONAL 2017
A2: Anexo III
A4: Receita Bruta em 12 meses (em R$) | B4: Alíquota | C4: IRPJ | D4: CSLL | E4: Cofins | F4: PIS/Pasep | G4: CPP | H4: ISS
A5: Até 180.000,00 | B5: 0.06 | C5: 0 | D5: 0 | E5: 0 | F5: 0 | G5: 0.04 | H5: 0.02
A6: De 180.000,01 a 360.000,00 | B6: 0.0821 | C6: 0 | D6: 0 | E6: 0.0142 | F6: 0 | G6: 0.04 | H6: 0.0279
A7: De 360.000,01 a 540.000,00 | B7: 0.1026 | C7: 0.0048 | D7: 0.0043 | E7: 0.0143 | F7: 0.0035 | G7: 0.0407 | H7: 0.035
A8: De 540.000,01 a 720.000,00 | B8: 0.1131 | C8: 0.0053 | D8: 0.0053 | E8: 0.0156 | F8: 0.0038 | G8: 0.0447 | H8: 0.0384
A9: De 720.000,01 a 900.000,00 | B9: 0.114 | C9: 0.0053 | D9: 0.0052 | E9: 0.0158 | F9: 0.0038 | G9: 0.0452 | H9: 0.0387
A10: De 900.000,01 a 1.080.000,00 | B10: 0.1242 | C10: 0.0057 | D10: 0.0057 | E10: 0.0173 | F10: 0.004 | G10: 0.0492 | H10: 0.0423
A11: De 1.080.000,01 a 1.260.000,00 | B11: 0.1254 | C11: 0.0059 | D11: 0.0056 | E11: 0.0174 | F11: 0.0042 | G11: 0.0497 | H11: 0.0426
A12: De 1.260.000,01 a 1.440.000,00 | B12: 0.1268 | C12: 0.0059 | D12: 0.0057 | E12: 0.0176 | F12: 0.0042 | G12: 0.0503 | H12: 0.0431
A13: De 1.440.000,01 a 1.620.000,00 | B13: 0.1355 | C13: 0.0063 | D13: 0.0061 | E13: 0.0188 | F13: 0.0045 | G13: 0.0537 | H13: 0.0461
A14: De 1.620.000,01 a 1.800.000,00 | B14: 0.1368 | C14: 0.0063 | D14: 0.0064 | E14: 0.0189 | F14: 0.0045 | G14: 0.0542 | H14: 0.0465
A15: De 1.800.000,01 a 1.980.000,00 | B15: 0.1493 | C15: 0.0069 | D15: 0.0069 | E15: 0.0207 | F15: 0.005 | G15: 0.0598 | H15: 0.05
A16: De 1.980.000,01 a 2.160.000,00 | B16: 0.1506 | C16: 0.0069 | D16: 0.0069 | E16: 0.0209 | F16: 0.005 | G16: 0.0609 | H16: 0.05
... A24: De 3.420.000,01 a 3.600.000,00 | B24: 0.1742 | C24: 0.0081 | D24: 0.0079 | E24: 0.0242 | F24: 0.0057 | G24: 0.0783 | H24: 0.05

Sheet SIMULAÇÃO
A1: Empresa:
A2: CNPJ:
A4: Empresa prestadora de serviços
A5: Atividade: 5212-5/00 CARGA E DESCARGA
A7: SIMPLES NACIONAL 2018
A8: Anexo III
A10: Receita Bruta em 12 Meses (em R$) | C10: Alíquota | D10: Valor a Deduzir (em R$)
A11: 1ª Faixa | B11: Até 180.000,00 | C11: 0.06 | D11: -
A12: 2ª Faixa | B12: De 180.000,01 a 360.000,00 | C12: 0.112 | D12: 9360
A13: 3ª Faixa | B13: De 360.000,01 a 720.000,00 | C13: 0.135 | D13: 17640
A14: 4ª Faixa | B14: De 720.000,01 a 1.800.000,00 | C14: 0.16 | D14: 35640
A15: 5ª Faixa | B15: De 1.800.000,01 a 3.600.000,00 | C15: 0.21 | D15: 125640
A16: 6ª Faixa | B16: De 3.600.000,01 a 4.800.000,00 | C16: 0.33 | D16: 648000
A18: VALORES FATURAMENTO 2017
A19: 42736 | B19: 42767 | C19: 42795 | D19: 42826 | E19: 42856 | F19: 42887 | H19: *** PESSOAL PREENCHER COM OS VALORES DE 2017, PARA ENCONTRAR A FAIXA PARA 2018
A21: 42917 | B21: 42948 | C21: 42979 | D21: 43009 | E21: 43040 | F21: 43070
A24: RECEITA BRUTA ACUMULADA 12 MESES - 2017 | D24: =SUM(A20,B20,C20,D20,E20,F20,A22,B22,C22,D22,E22,F22) -> 0
A27: SIMULAÇÃO SIMPLES NACIONAL 2018
A28: MÊS | B28: RECEITA MENSAL | C28: RBT ÚLTIMOS 12 MESES | D28: Alíquota nominal | E28: Dedução | F28: Alíquota Efetiva | G28: Alíquota 2017 DAS | H28: Vl DAS 2018 | I28: VL DAS LEGISLAÇÃO 2017 | J28: Legislação 2018 - 2017
A29: Janeiro | C29: =SUM(A20,B20,C20,D20,E20,F20,A22,B22,C22,D22,E22,F22) -> 0 | D29: =IF(C29<=180000,$C$11,IF(AND(C29>180000,C29<=360000),$C$12,IF(AND(C29<=720000,C29>=360000.01),$C$13,IF(AND(C29<=1800000,C29>=720000.01),$C$14,IF(AND(C29<=3600000,C29>=1800000.01),$C$15,IF(AND(C29<=4800000,C29>=3600000.01),$C$16)))))) -> 0.06 | E29: =LOOKUP(D29,$C$11:$C$16,$D$11:$D$16) -> - | F29: =((C29*D29)-E29)/C29 -> #VALUE! | G29: =IF(C29<=180000,'Simples Nacional 2017'!$B$5,IF(AND(C29>180000,C29<=360000),'Simples Nacional 2017'!$B$6,IF(AND(C29<=540000,C29>=360000.01),'Simples Nacional 2017'!$B$7,IF(AND(C29<=720000,C29>=540000.01),'Simples Nacional 2017'!$B$8,IF(AND(C29<=900000,C29>=720000.01),'Simples Nacional 2017'!$B$9, IF(AND(C29<=1080000,C29>=900000.01),'Simples Nacional 2017'!$B$10,IF(AND(C29<=1260000,C29>=1080000.01),'Simples Nacional 2017'!$B$11,IF(AND(C29<=1440000,C29>=1260000.01),'Simples Nacional 2017'!$B$12,IF(AND(C29<=1620000,C29>=1440000.01),'Simples Nacional 2017'!$B$13,IF(AND(C29<=1800000,C29>=1620000.01),'Simples Nacional 2017'!$B$14,IF(AND(C29<=1980000,C29>=1800000.01),'Simples Nacional 2017'!$B$15,IF(AND(C29<=2160000,C29>=1980000.01),'Simples Nacional 2017'!$B$16,IF(AND(C29<=2340000,C29>=2160000.01),'Simples Nacional 2017'!$B$17,IF(AND(C29<=2520000,C29>=2340000.01),'Simples Nacional 2017'!$B$18,IF(AND(C29<=2700000,C29>=2520000.01),'Simples Nacional 2017'!$B$19,IF(AND(C29<=2880000,C29>=2700000.01),'Simples Nacional 2017'!$B$20,IF(AND(C29<=3060000,C29>=2880000.01),'Simples Nacional 2017'!$B$21,IF(AND(C29<=3240000,C29>=3060000.01),'Simples Nacional 2017'!$B$22,IF(AND(C29<=3420000,C29>=3240000.01),'Simples Nacional 2017'!$B$23,IF(AND(C29<=3600000,C29>=3420000.01),'Simples Nacional 2017'!$B$24)))))))))))))))))))) -> 0.06 | H29: =B29*F29 -> #VALUE! | I29: =B29*G29 -> 0 | J29: =H29-I29 -> #VALUE!
A30: Fevereiro | C30: =SUM(B20,C20,D20,E20,F20,A22,B22,C22,D22,E22,F22,B29) -> 0 | D30: =IF(C30<=180000,$C$11,IF(AND(C30>180000,C30<=360000),$C$12,IF(AND(C30<=720000,C30>=360000.01),$C$13,IF(AND(C30<=1800000,C30>=720000.01),$C$14,IF(AND(C30<=3600000,C30>=1800000.01),$C$15,IF(AND(C30<=4800000,C30>=3600000.01),$C$16)))))) -> 0.06 | E30: =LOOKUP(D30,$C$11:$C$16,$D$11:$D$16) -> - | F30: =((C30*D30)-E30)/C30 -> #VALUE! | G30: =IF(C30<=180000,'Simples Nacional 2017'!$B$5,IF(AND(C30>180000,C30<=360000),'Simples Nacional 2017'!$B$6,IF(AND(C30<=540000,C30>=360000.01),'Simples Nacional 2017'!$B$7,IF(AND(C30<=720000,C30>=540000.01),'Simples Nacional 2017'!$B$8,IF(AND(C30<=900000,C30>=720000.01),'Simples Nacional 2017'!$B$9, IF(AND(C30<=1080000,C30>=900000.01),'Simples Nacional 2017'!$B$10,IF(AND(C30<=1260000,C30>=1080000.01),'Simples Nacional 2017'!$B$11,IF(AND(C30<=1440000,C30>=1260000.01),'Simples Nacional 2017'!$B$12,IF(AND(C30<=1620000,C30>=1440000.01),'Simples Nacional 2017'!$B$13,IF(AND(C30<=1800000,C30>=1620000.01),'Simples Nacional 2017'!$B$14,IF(AND(C30<=1980000,C30>=1800000.01),'Simples Nacional 2017'!$B$15,IF(AND(C30<=2160000,C30>=1980000.01),'Simples Nacional 2017'!$B$16,IF(AND(C30<=2340000,C30>=2160000.01),'Simples Nacional 2017'!$B$17,IF(AND(C30<=2520000,C30>=2340000.01),'Simples Nacional 2017'!$B$18,IF(AND(C30<=2700000,C30>=2520000.01),'Simples Nacional 2017'!$B$19,IF(AND(C30<=2880000,C30>=2700000.01),'Simples Nacional 2017'!$B$20,IF(AND(C30<=3060000,C30>=2880000.01),'Simples Nacional 2017'!$B$21,IF(AND(C30<=3240000,C30>=3060000.01),'Simples Nacional 2017'!$B$22,IF(AND(C30<=3420000,C30>=3240000.01),'Simples Nacional 2017'!$B$23,IF(AND(C30<=3600000,C30>=3420000.01),'Simples Nacional 2017'!$B$24)))))))))))))))))))) -> 0.06 | H30: =B30*F30 -> #VALUE! | I30: =B30*G30 -> 0 | J30: =H30-I30 -> #VALUE!
A31: Março | C31: =SUM(C20,D20,E20,F20,A22,B22,C22,D22,E22,F22,B29,B30) -> 0 | D31: =IF(C31<=180000,$C$11,IF(AND(C31>180000,C31<=360000),$C$12,IF(AND(C31<=720000,C31>=360000.01),$C$13,IF(AND(C31<=1800000,C31>=720000.01),$C$14,IF(AND(C31<=3600000,C31>=1800000.01),$C$15,IF(AND(C31<=4800000,C31>=3600000.01),$C$16)))))) -> 0.06 | E31: =LOOKUP(D31,$C$11:$C$16,$D$11:$D$16) -> - | F31: =((C31*D31)-E31)/C31 -> #VALUE! | G31: =IF(C31<=180000,'Simples Nacional 2017'!$B$5,IF(AND(C31>180000,C31<=360000),'Simples Nacional 2017'!$B$6,IF(AND(C31<=540000,C31>=360000.01),'Simples Nacional 2017'!$B$7,IF(AND(C31<=720000,C31>=540000.01),'Simples Nacional 2017'!$B$8,IF(AND(C31<=900000,C31>=720000.01),'Simples Nacional 2017'!$B$9, IF(AND(C31<=1080000,C31>=900000.01),'Simples Nacional 2017'!$B$10,IF(AND(C31<=1260000,C31>=1080000.01),'Simples Nacional 2017'!$B$11,IF(AND(C31<=1440000,C31>=1260000.01),'Simples Nacional 2017'!$B$12,IF(AND(C31<=1620000,C31>=1440000.01),'Simples Nacional 2017'!$B$13,IF(AND(C31<=1800000,C31>=1620000.01),'Simples Nacional 2017'!$B$14,IF(AND(C31<=1980000,C31>=1800000.01),'Simples Nacional 2017'!$B$15,IF(AND(C31<=2160000,C31>=1980000.01),'Simples Nacional 2017'!$B$16,IF(AND(C31<=2340000,C31>=2160000.01),'Simples Nacional 2017'!$B$17,IF(AND(C31<=2520000,C31>=2340000.01),'Simples Nacional 2017'!$B$18,IF(AND(C31<=2700000,C31>=2520000.01),'Simples Nacional 2017'!$B$19,IF(AND(C31<=2880000,C31>=2700000.01),'Simples Nacional 2017'!$B$20,IF(AND(C31<=3060000,C31>=2880000.01),'Simples Nacional 2017'!$B$21,IF(AND(C31<=3240000,C31>=3060000.01),'Simples Nacional 2017'!$B$22,IF(AND(C31<=3420000,C31>=3240000.01),'Simples Nacional 2017'!$B$23,IF(AND(C31<=3600000,C31>=3420000.01),'Simples Nacional 2017'!$B$24)))))))))))))))))))) -> 0.06 | H31: =B31*F31 -> #VALUE! | I31: =B31*G31 -> 0 | J31: =H31-I31 -> #VALUE!
A32: Abril | C32: =SUM(D20,E20,F20,A22,B22,C22,D22,E22,F22,B29,B30,B31) -> 0 | D32: =IF(C32<=180000,$C$11,IF(AND(C32>180000,C32<=360000),$C$12,IF(AND(C32<=720000,C32>=360000.01),$C$13,IF(AND(C32<=1800000,C32>=720000.01),$C$14,IF(AND(C32<=3600000,C32>=1800000.01),$C$15,IF(AND(C32<=4800000,C32>=3600000.01),$C$16)))))) -> 0.06 | E32: =LOOKUP(D32,$C$11:$C$16,$D$11:$D$16) -> - | F32: =((C32*D32)-E32)/C32 -> #VALUE! | G32: =IF(C32<=180000,'Simples Nacional 2017'!$B$5,IF(AND(C32>180000,C32<=360000),'Simples Nacional 2017'!$B$6,IF(AND(C32<=540000,C32>=360000.01),'Simples Nacional 2017'!$B$7,IF(AND(C32<=720000,C32>=540000.01),'Simples Nacional 2017'!$B$8,IF(AND(C32<=900000,C32>=720000.01),'Simples Nacional 2017'!$B$9, IF(AND(C32<=1080000,C32>=900000.01),'Simples Nacional 2017'!$B$10,IF(AND(C32<=1260000,C32>=1080000.01),'Simples Nacional 2017'!$B$11,IF(AND(C32<=1440000,C32>=1260000.01),'Simples Nacional 2017'!$B$12,IF(AND(C32<=1620000,C32>=1440000.01),'Simples Nacional 2017'!$B$13,IF(AND(C32<=1800000,C32>=1620000.01),'Simples Nacional 2017'!$B$14,IF(AND(C32<=1980000,C32>=1800000.01),'Simples Nacional 2017'!$B$15,IF(AND(C32<=2160000,C32>=1980000.01),'Simples Nacional 2017'!$B$16,IF(AND(C32<=2340000,C32>=2160000.01),'Simples Nacional 2017'!$B$17,IF(AND(C32<=2520000,C32>=2340000.01),'Simples Nacional 2017'!$B$18,IF(AND(C32<=2700000,C32>=2520000.01),'Simples Nacional 2017'!$B$19,IF(AND(C32<=2880000,C32>=2700000.01),'Simples Nacional 2017'!$B$20,IF(AND(C32<=3060000,C32>=2880000.01),'Simples Nacional 2017'!$B$21,IF(AND(C32<=3240000,C32>=3060000.01),'Simples Nacional 2017'!$B$22,IF(AND(C32<=3420000,C32>=3240000.01),'Simples Nacional 2017'!$B$23,IF(AND(C32<=3600000,C32>=3420000.01),'Simples Nacional 2017'!$B$24)))))))))))))))))))) -> 0.06 | H32: =B32*F32 -> #VALUE! | I32: =B32*G32 -> 0 | J32: =H32-I32 -> #VALUE! | L32: *** PESSOAL PREENCHER A RECEITA MENSAL
A33: Maio | C33: =SUM(E20,F20,A22,B22,C22,D22,E22,F22,B29,B30,B31,B32) -> 0 | D33: =IF(C33<=180000,$C$11,IF(AND(C33>180000,C33<=360000),$C$12,IF(AND(C33<=720000,C33>=360000.01),$C$13,IF(AND(C33<=1800000,C33>=720000.01),$C$14,IF(AND(C33<=3600000,C33>=1800000.01),$C$15,IF(AND(C33<=4800000,C33>=3600000.01),$C$16)))))) -> 0.06 | E33: =LOOKUP(D33,$C$11:$C$16,$D$11:$D$16) -> - | F33: =((C33*D33)-E33)/C33 -> #VALUE! | G33: =IF(C33<=180000,'Simples Nacional 2017'!$B$5,IF(AND(C33>180000,C33<=360000),'Simples Nacional 2017'!$B$6,IF(AND(C33<=540000,C33>=360000.01),'Simples Nacional 2017'!$B$7,IF(AND(C33<=720000,C33>=540000.01),'Simples Nacional 2017'!$B$8,IF(AND(C33<=900000,C33>=720000.01),'Simples Nacional 2017'!$B$9, IF(AND(C33<=1080000,C33>=900000.01),'Simples Nacional 2017'!$B$10,IF(AND(C33<=1260000,C33>=1080000.01),'Simples Nacional 2017'!$B$11,IF(AND(C33<=1440000,C33>=1260000.01),'Simples Nacional 2017'!$B$12,IF(AND(C33<=1620000,C33>=1440000.01),'Simples Nacional 2017'!$B$13,IF(AND(C33<=1800000,C33>=1620000.01),'Simples Nacional 2017'!$B$14,IF(AND(C33<=1980000,C33>=1800000.01),'Simples Nacional 2017'!$B$15,IF(AND(C33<=2160000,C33>=1980000.01),'Simples Nacional 2017'!$B$16,IF(AND(C33<=2340000,C33>=2160000.01),'Simples Nacional 2017'!$B$17,IF(AND(C33<=2520000,C33>=2340000.01),'Simples Nacional 2017'!$B$18,IF(AND(C33<=2700000,C33>=2520000.01),'Simples Nacional 2017'!$B$19,IF(AND(C33<=2880000,C33>=2700000.01),'Simples Nacional 2017'!$B$20,IF(AND(C33<=3060000,C33>=2880000.01),'Simples Nacional 2017'!$B$21,IF(AND(C33<=3240000,C33>=3060000.01),'Simples Nacional 2017'!$B$22,IF(AND(C33<=3420000,C33>=3240000.01),'Simples Nacional 2017'!$B$23,IF(AND(C33<=3600000,C33>=3420000.01),'Simples Nacional 2017'!$B$24)))))))))))))))))))) -> 0.06 | H33: =B33*F33 -> #VALUE! | I33: =B33*G33 -> 0 | J33: =H33-I33 -> #VALUE!
A34: Junho | C34: =SUM(F20,A22,B22,C22,D22,E22,F22,B29,B30,B31,B32,B33) -> 0 | D34: =IF(C34<=180000,$C$11,IF(AND(C34>180000,C34<=360000),$C$12,IF(AND(C34<=720000,C34>=360000.01),$C$13,IF(AND(C34<=1800000,C34>=720000.01),$C$14,IF(AND(C34<=3600000,C34>=1800000.01),$C$15,IF(AND(C34<=4800000,C34>=3600000.01),$C$16)))))) -> 0.06 | E34: =LOOKUP(D34,$C$11:$C$16,$D$11:$D$16) -> - | F34: =((C34*D34)-E34)/C34 -> #VALUE! | G34: =IF(C34<=180000,'Simples Nacional 2017'!$B$5,IF(AND(C34>180000,C34<=360000),'Simples Nacional 2017'!$B$6,IF(AND(C34<=540000,C34>=360000.01),'Simples Nacional 2017'!$B$7,IF(AND(C34<=720000,C34>=540000.01),'Simples Nacional 2017'!$B$8,IF(AND(C34<=900000,C34>=720000.01),'Simples Nacional 2017'!$B$9, IF(AND(C34<=1080000,C34>=900000.01),'Simples Nacional 2017'!$B$10,IF(AND(C34<=1260000,C34>=1080000.01),'Simples Nacional 2017'!$B$11,IF(AND(C34<=1440000,C34>=1260000.01),'Simples Nacional 2017'!$B$12,IF(AND(C34<=1620000,C34>=1440000.01),'Simples Nacional 2017'!$B$13,IF(AND(C34<=1800000,C34>=1620000.01),'Simples Nacional 2017'!$B$14,IF(AND(C34<=1980000,C34>=1800000.01),'Simples Nacional 2017'!$B$15,IF(AND(C34<=2160000,C34>=1980000.01),'Simples Nacional 2017'!$B$16,IF(AND(C34<=2340000,C34>=2160000.01),'Simples Nacional 2017'!$B$17,IF(AND(C34<=2520000,C34>=2340000.01),'Simples Nacional 2017'!$B$18,IF(AND(C34<=2700000,C34>=2520000.01),'Simples Nacional 2017'!$B$19,IF(AND(C34<=2880000,C34>=2700000.01),'Simples Nacional 2017'!$B$20,IF(AND(C34<=3060000,C34>=2880000.01),'Simples Nacional 2017'!$B$21,IF(AND(C34<=3240000,C34>=3060000.01),'Simples Nacional 2017'!$B$22,IF(AND(C34<=3420000,C34>=3240000.01),'Simples Nacional 2017'!$B$23,IF(AND(C34<=3600000,C34>=3420000.01),'Simples Nacional 2017'!$B$24)))))))))))))))))))) -> 0.06 | H34: =B34*F34 -> #VALUE! | I34: =B34*G34 -> 0 | J34: =H34-I34 -> #VALUE!
A35: Julho | C35: =SUM(A22,B22,C22,D22,E22,F22,B29,B30,B31,B32,B33,B34) -> 0 | D35: =IF(C35<=180000,$C$11,IF(AND(C35>180000,C35<=360000),$C$12,IF(AND(C35<=720000,C35>=360000.01),$C$13,IF(AND(C35<=1800000,C35>=720000.01),$C$14,IF(AND(C35<=3600000,C35>=1800000.01),$C$15,IF(AND(C35<=4800000,C35>=3600000.01),$C$16)))))) -> 0.06 | E35: =LOOKUP(D35,$C$11:$C$16,$D$11:$D$16) -> - | F35: =((C35*D35)-E35)/C35 -> #VALUE! | G35: =IF(C35<=180000,'Simples Nacional 2017'!$B$5,IF(AND(C35>180000,C35<=360000),'Simples Nacional 2017'!$B$6,IF(AND(C35<=540000,C35>=360000.01),'Simples Nacional 2017'!$B$7,IF(AND(C35<=720000,C35>=540000.01),'Simples Nacional 2017'!$B$8,IF(AND(C35<=900000,C35>=720000.01),'Simples Nacional 2017'!$B$9, IF(AND(C35<=1080000,C35>=900000.01),'Simples Nacional 2017'!$B$10,IF(AND(C35<=1260000,C35>=1080000.01),'Simples Nacional 2017'!$B$11,IF(AND(C35<=1440000,C35>=1260000.01),'Simples Nacional 2017'!$B$12,IF(AND(C35<=1620000,C35>=1440000.01),'Simples Nacional 2017'!$B$13,IF(AND(C35<=1800000,C35>=1620000.01),'Simples Nacional 2017'!$B$14,IF(AND(C35<=1980000,C35>=1800000.01),'Simples Nacional 2017'!$B$15,IF(AND(C35<=2160000,C35>=1980000.01),'Simples Nacional 2017'!$B$16,IF(AND(C35<=2340000,C35>=2160000.01),'Simples Nacional 2017'!$B$17,IF(AND(C35<=2520000,C35>=2340000.01),'Simples Nacional 2017'!$B$18,IF(AND(C35<=2700000,C35>=2520000.01),'Simples Nacional 2017'!$B$19,IF(AND(C35<=2880000,C35>=2700000.01),'Simples Nacional 2017'!$B$20,IF(AND(C35<=3060000,C35>=2880000.01),'Simples Nacional 2017'!$B$21,IF(AND(C35<=3240000,C35>=3060000.01),'Simples Nacional 2017'!$B$22,IF(AND(C35<=3420000,C35>=3240000.01),'Simples Nacional 2017'!$B$23,IF(AND(C35<=3600000,C35>=3420000.01),'Simples Nacional 2017'!$B$24)))))))))))))))))))) -> 0.06 | H35: =B35*F35 -> #VALUE! | I35: =B35*G35 -> 0 | J35: =H35-I35 -> #VALUE!
A36: Agosto | C36: =SUM(B22,C22,D22,E22,F22,B29,B30,B31,B32,B33,B34,B35) -> 0 | D36: =IF(C36<=180000,$C$11,IF(AND(C36>180000,C36<=360000),$C$12,IF(AND(C36<=720000,C36>=360000.01),$C$13,IF(AND(C36<=1800000,C36>=720000.01),$C$14,IF(AND(C36<=3600000,C36>=1800000.01),$C$15,IF(AND(C36<=4800000,C36>=3600000.01),$C$16)))))) -> 0.06 | E36: =LOOKUP(D36,$C$11:$C$16,$D$11:$D$16) -> - | F36: =((C36*D36)-E36)/C36 -> #VALUE! | G36: =IF(C36<=180000,'Simples Nacional 2017'!$B$5,IF(AND(C36>180000,C36<=360000),'Simples Nacional 2017'!$B$6,IF(AND(C36<=540000,C36>=360000.01),'Simples Nacional 2017'!$B$7,IF(AND(C36<=720000,C36>=540000.01),'Simples Nacional 2017'!$B$8,IF(AND(C36<=900000,C36>=720000.01),'Simples Nacional 2017'!$B$9, IF(AND(C36<=1080000,C36>=900000.01),'Simples Nacional 2017'!$B$10,IF(AND(C36<=1260000,C36>=1080000.01),'Simples Nacional 2017'!$B$11,IF(AND(C36<=1440000,C36>=1260000.01),'Simples Nacional 2017'!$B$12,IF(AND(C36<=1620000,C36>=1440000.01),'Simples Nacional 2017'!$B$13,IF(AND(C36<=1800000,C36>=1620000.01),'Simples Nacional 2017'!$B$14,IF(AND(C36<=1980000,C36>=1800000.01),'Simples Nacional 2017'!$B$15,IF(AND(C36<=2160000,C36>=1980000.01),'Simples Nacional 2017'!$B$16,IF(AND(C36<=2340000,C36>=2160000.01),'Simples Nacional 2017'!$B$17,IF(AND(C36<=2520000,C36>=2340000.01),'Simples Nacional 2017'!$B$18,IF(AND(C36<=2700000,C36>=2520000.01),'Simples Nacional 2017'!$B$19,IF(AND(C36<=2880000,C36>=2700000.01),'Simples Nacional 2017'!$B$20,IF(AND(C36<=3060000,C36>=2880000.01),'Simples Nacional 2017'!$B$21,IF(AND(C36<=3240000,C36>=3060000.01),'Simples Nacional 2017'!$B$22,IF(AND(C36<=3420000,C36>=3240000.01),'Simples Nacional 2017'!$B$23,IF(AND(C36<=3600000,C36>=3420000.01),'Simples Nacional 2017'!$B$24)))))))))))))))))))) -> 0.06 | H36: =B36*F36 -> #VALUE! | I36: =B36*G36 -> 0 | J36: =H36-I36 -> #VALUE!
A37: Setembro | C37: =SUM(C22,D22,E22,F22,B29,B30,B31,B32,B33,B34,B35,B36) -> 0 | D37: =IF(C37<=180000,$C$11,IF(AND(C37>180000,C37<=360000),$C$12,IF(AND(C37<=720000,C37>=360000.01),$C$13,IF(AND(C37<=1800000,C37>=720000.01),$C$14,IF(AND(C37<=3600000,C37>=1800000.01),$C$15,IF(AND(C37<=4800000,C37>=3600000.01),$C$16)))))) -> 0.06 | E37: =LOOKUP(D37,$C$11:$C$16,$D$11:$D$16) -> - | F37: =((C37*D37)-E37)/C37 -> #VALUE! | G37: =IF(C37<=180000,'Simples Nacional 2017'!$B$5,IF(AND(C37>180000,C37<=360000),'Simples Nacional 2017'!$B$6,IF(AND(C37<=540000,C37>=360000.01),'Simples Nacional 2017'!$B$7,IF(AND(C37<=720000,C37>=540000.01),'Simples Nacional 2017'!$B$8,IF(AND(C37<=900000,C37>=720000.01),'Simples Nacional 2017'!$B$9, IF(AND(C37<=1080000,C37>=900000.01),'Simples Nacional 2017'!$B$10,IF(AND(C37<=1260000,C37>=1080000.01),'Simples Nacional 2017'!$B$11,IF(AND(C37<=1440000,C37>=1260000.01),'Simples Nacional 2017'!$B$12,IF(AND(C37<=1620000,C37>=1440000.01),'Simples Nacional 2017'!$B$13,IF(AND(C37<=1800000,C37>=1620000.01),'Simples Nacional 2017'!$B$14,IF(AND(C37<=1980000,C37>=1800000.01),'Simples Nacional 2017'!$B$15,IF(AND(C37<=2160000,C37>=1980000.01),'Simples Nacional 2017'!$B$16,IF(AND(C37<=2340000,C37>=2160000.01),'Simples Nacional 2017'!$B$17,IF(AND(C37<=2520000,C37>=2340000.01),'Simples Nacional 2017'!$B$18,IF(AND(C37<=2700000,C37>=2520000.01),'Simples Nacional 2017'!$B$19,IF(AND(C37<=2880000,C37>=2700000.01),'Simples Nacional 2017'!$B$20,IF(AND(C37<=3060000,C37>=2880000.01),'Simples Nacional 2017'!$B$21,IF(AND(C37<=3240000,C37>=3060000.01),'Simples Nacional 2017'!$B$22,IF(AND(C37<=3420000,C37>=3240000.01),'Simples Nacional 2017'!$B$23,IF(AND(C37<=3600000,C37>=3420000.01),'Simples Nacional 2017'!$B$24)))))))))))))))))))) -> 0.06 | H37: =B37*F37 -> #VALUE! | I37: =B37*G37 -> 0 | J37: =H37-I37 -> #VALUE!
A38: Outubro | C38: =SUM(D22,E22,F22,B29,B30,B31,B32,B33,B34,B35,B36,B37) -> 0 | D38: =IF(C38<=180000,$C$11,IF(AND(C38>180000,C38<=360000),$C$12,IF(AND(C38<=720000,C38>=360000.01),$C$13,IF(AND(C38<=1800000,C38>=720000.01),$C$14,IF(AND(C38<=3600000,C38>=1800000.01),$C$15,IF(AND(C38<=4800000,C38>=3600000.01),$C$16)))))) -> 0.06 | E38: =LOOKUP(D38,$C$11:$C$16,$D$11:$D$16) -> - | F38: =((C38*D38)-E38)/C38 -> #VALUE! | G38: =IF(C38<=180000,'Simples Nacional 2017'!$B$5,IF(AND(C38>180000,C38<=360000),'Simples Nacional 2017'!$B$6,IF(AND(C38<=540000,C38>=360000.01),'Simples Nacional 2017'!$B$7,IF(AND(C38<=720000,C38>=540000.01),'Simples Nacional 2017'!$B$8,IF(AND(C38<=900000,C38>=720000.01),'Simples Nacional 2017'!$B$9, IF(AND(C38<=1080000,C38>=900000.01),'Simples Nacional 2017'!$B$10,IF(AND(C38<=1260000,C38>=1080000.01),'Simples Nacional 2017'!$B$11,IF(AND(C38<=1440000,C38>=1260000.01),'Simples Nacional 2017'!$B$12,IF(AND(C38<=1620000,C38>=1440000.01),'Simples Nacional 2017'!$B$13,IF(AND(C38<=1800000,C38>=1620000.01),'Simples Nacional 2017'!$B$14,IF(AND(C38<=1980000,C38>=1800000.01),'Simples Nacional 2017'!$B$15,IF(AND(C38<=2160000,C38>=1980000.01),'Simples Nacional 2017'!$B$16,IF(AND(C38<=2340000,C38>=2160000.01),'Simples Nacional 2017'!$B$17,IF(AND(C38<=2520000,C38>=2340000.01),'Simples Nacional 2017'!$B$18,IF(AND(C38<=2700000,C38>=2520000.01),'Simples Nacional 2017'!$B$19,IF(AND(C38<=2880000,C38>=2700000.01),'Simples Nacional 2017'!$B$20,IF(AND(C38<=3060000,C38>=2880000.01),'Simples Nacional 2017'!$B$21,IF(AND(C38<=3240000,C38>=3060000.01),'Simples Nacional 2017'!$B$22,IF(AND(C38<=3420000,C38>=3240000.01),'Simples Nacional 2017'!$B$23,IF(AND(C38<=3600000,C38>=3420000.01),'Simples Nacional 2017'!$B$24)))))))))))))))))))) -> 0.06 | H38: =B38*F38 -> #VALUE! | I38: =B38*G38 -> 0 | J38: =H38-I38 -> #VALUE!
A39: Novembro | C39: =SUM(E22,F22,B29,B30,B31,B32,B33,B34,B35,B36,B37,B38) -> 0 | D39: =IF(C39<=180000,$C$11,IF(AND(C39>180000,C39<=360000),$C$12,IF(AND(C39<=720000,C39>=360000.01),$C$13,IF(AND(C39<=1800000,C39>=720000.01),$C$14,IF(AND(C39<=3600000,C39>=1800000.01),$C$15,IF(AND(C39<=4800000,C39>=3600000.01),$C$16)))))) -> 0.06 | E39: =LOOKUP(D39,$C$11:$C$16,$D$11:$D$16) -> - | F39: =((C39*D39)-E39)/C39 -> #VALUE! | G39: =IF(C39<=180000,'Simples Nacional 2017'!$B$5,IF(AND(C39>180000,C39<=360000),'Simples Nacional 2017'!$B$6,IF(AND(C39<=540000,C39>=360000.01),'Simples Nacional 2017'!$B$7,IF(AND(C39<=720000,C39>=540000.01),'Simples Nacional 2017'!$B$8,IF(AND(C39<=900000,C39>=720000.01),'Simples Nacional 2017'!$B$9, IF(AND(C39<=1080000,C39>=900000.01),'Simples Nacional 2017'!$B$10,IF(AND(C39<=1260000,C39>=1080000.01),'Simples Nacional 2017'!$B$11,IF(AND(C39<=1440000,C39>=1260000.01),'Simples Nacional 2017'!$B$12,IF(AND(C39<=1620000,C39>=1440000.01),'Simples Nacional 2017'!$B$13,IF(AND(C39<=1800000,C39>=1620000.01),'Simples Nacional 2017'!$B$14,IF(AND(C39<=1980000,C39>=1800000.01),'Simples Nacional 2017'!$B$15,IF(AND(C39<=2160000,C39>=1980000.01),'Simples Nacional 2017'!$B$16,IF(AND(C39<=2340000,C39>=2160000.01),'Simples Nacional 2017'!$B$17,IF(AND(C39<=2520000,C39>=2340000.01),'Simples Nacional 2017'!$B$18,IF(AND(C39<=2700000,C39>=2520000.01),'Simples Nacional 2017'!$B$19,IF(AND(C39<=2880000,C39>=2700000.01),'Simples Nacional 2017'!$B$20,IF(AND(C39<=3060000,C39>=2880000.01),'Simples Nacional 2017'!$B$21,IF(AND(C39<=3240000,C39>=3060000.01),'Simples Nacional 2017'!$B$22,IF(AND(C39<=3420000,C39>=3240000.01),'Simples Nacional 2017'!$B$23,IF(AND(C39<=3600000,C39>=3420000.01),'Simples Nacional 2017'!$B$24)))))))))))))))))))) -> 0.06 | H39: =B39*F39 -> #VALUE! | I39: =B39*G39 -> 0 | J39: =H39-I39 -> #VALUE!
A40: Dezembro | C40: =SUM(F22,B29,B30,B31,B32,B33,B34,B35,B36,B37,B38,B39) -> 0 | D40: =IF(C40<=180000,$C$11,IF(AND(C40>180000,C40<=360000),$C$12,IF(AND(C40<=720000,C40>=360000.01),$C$13,IF(AND(C40<=1800000,C40>=720000.01),$C$14,IF(AND(C40<=3600000,C40>=1800000.01),$C$15,IF(AND(C40<=4800000,C40>=3600000.01),$C$16)))))) -> 0.06 | E40: =LOOKUP(D40,$C$11:$C$16,$D$11:$D$16) -> - | F40: =((C40*D40)-E40)/C40 -> #VALUE! | G40: =IF(C40<=180000,'Simples Nacional 2017'!$B$5,IF(AND(C40>180000,C40<=360000),'Simples Nacional 2017'!$B$6,IF(AND(C40<=540000,C40>=360000.01),'Simples Nacional 2017'!$B$7,IF(AND(C40<=720000,C40>=540000.01),'Simples Nacional 2017'!$B$8,IF(AND(C40<=900000,C40>=720000.01),'Simples Nacional 2017'!$B$9, IF(AND(C40<=1080000,C40>=900000.01),'Simples Nacional 2017'!$B$10,IF(AND(C40<=1260000,C40>=1080000.01),'Simples Nacional 2017'!$B$11,IF(AND(C40<=1440000,C40>=1260000.01),'Simples Nacional 2017'!$B$12,IF(AND(C40<=1620000,C40>=1440000.01),'Simples Nacional 2017'!$B$13,IF(AND(C40<=1800000,C40>=1620000.01),'Simples Nacional 2017'!$B$14,IF(AND(C40<=1980000,C40>=1800000.01),'Simples Nacional 2017'!$B$15,IF(AND(C40<=2160000,C40>=1980000.01),'Simples Nacional 2017'!$B$16,IF(AND(C40<=2340000,C40>=2160000.01),'Simples Nacional 2017'!$B$17,IF(AND(C40<=2520000,C40>=2340000.01),'Simples Nacional 2017'!$B$18,IF(AND(C40<=2700000,C40>=2520000.01),'Simples Nacional 2017'!$B$19,IF(AND(C40<=2880000,C40>=2700000.01),'Simples Nacional 2017'!$B$20,IF(AND(C40<=3060000,C40>=2880000.01),'Simples Nacional 2017'!$B$21,IF(AND(C40<=3240000,C40>=3060000.01),'Simples Nacional 2017'!$B$22,IF(AND(C40<=3420000,C40>=3240000.01),'Simples Nacional 2017'!$B$23,IF(AND(C40<=3600000,C40>=3420000.01),'Simples Nacional 2017'!$B$24)))))))))))))))))))) -> 0.06 | H40: =B40*F40 -> #VALUE! | I40: =B40*G40 -> 0 | J40: =H40-I40 -> #VALUE!
A41: TOTAL | H41: =SUM(H29:H40) -> #VALUE! | I41: =SUM(I29:I40) -> 0 | J41: =SUM(J29:J40) -> #VALUE!
A43: SIMULAÇÃO LUCRO PRESUMIDO 2018
A44: MÊS | B44: FATURAMENTO | C44: ISS | D44: PIS | E44: COFINS | F44: IRPJ | G44: ADIC. DE IRPJ | H44: CSLL | I44: TOTAL IMPOSTOS
A45: Janeiro | B45: =B29 -> 0 | C45: =B45*5% -> 0 | D45: =B45*0.65% -> 0 | E45: =B45*3% -> 0 | F45: =(B45*32%)*15% -> 0 | G45: =((B45*32%)-20000)*10% -> -2000 | H45: =B45*32%*9% -> 0 | I45: =C45+D45+E45+F45+G45+H45 -> -2000
A46: Fevereiro | B46: =B30 -> 0 | C46: =B46*5% -> 0 | D46: =B46*0.65% -> 0 | E46: =B46*3% -> 0 | F46: =(B46*32%)*15% -> 0 | G46: =((B46*32%)-20000)*10% -> -2000 | H46: =B46*32%*9% -> 0 | I46: =C46+D46+E46+F46+G46+H46 -> -2000
A47: Março | B47: =B31 -> 0 | C47: =B47*5% -> 0 | D47: =B47*0.65% -> 0 | E47: =B47*3% -> 0 | F47: =(B47*32%)*15% -> 0 | G47: =((B47*32%)-20000)*10% -> -2000 | H47: =B47*32%*9% -> 0 | I47: =C47+D47+E47+F47+G47+H47 -> -2000
A48: Abril | B48: =B32 -> 0 | C48: =B48*5% -> 0 | D48: =B48*0.65% -> 0 | E48: =B48*3% -> 0 | F48: =(B48*32%)*15% -> 0 | G48: =((B48*32%)-20000)*10% -> -2000 | H48: =B48*32%*9% -> 0 | I48: =C48+D48+E48+F48+G48+H48 -> -2000
A49: Maio | B49: =B33 -> 0 | C49: =B49*5% -> 0 | D49: =B49*0.65% -> 0 | E49: =B49*3% -> 0 | F49: =(B49*32%)*15% -> 0 | G49: =((B49*32%)-20000)*10% -> -2000 | H49: =B49*32%*9% -> 0 | I49: =C49+D49+E49+F49+G49+H49 -> -2000
A50: Junho | B50: =B34 -> 0 | C50: =B50*5% -> 0 | D50: =B50*0.65% -> 0 | E50: =B50*3% -> 0 | F50: =(B50*32%)*15% -> 0 | G50: =((B50*32%)-20000)*10% -> -2000 | H50: =B50*32%*9% -> 0 | I50: =C50+D50+E50+F50+G50+H50 -> -2000
...
