Workbook

Sheet DIARIO
A1: DATA | B1: DESCRIÇÃO | C1: DEBITO | D1: CREDITO
A2: 42737 | B2: CAPITAL A INTEGRALIZAR | C2: 10000000
B3: CAPITAL SOCIAL | D3: 10000000
B5: BANCO | C5: 8581875
B6: DESP. C EMISSOES DE AÇOES dre | C6: 43125
B7: CAPITAL A INTEGRALIZAR | D7: 7500000
B8: AGIO NA EMISSÃO AÇOES | D8: 1125000
A10: 42740 | B10: VEICULO | C10: 100000 | G10: 14765.48
B11: JUROS APROPRIAR | C11: 25000 | G11: =G8-G10 -> -14765.48
B12: FINANCIAMENTO C. PRAZO | D12: 30000
B13: FINANCIAMENTO L. PRAZO | D13: 95000
B15: DESPESAS COM DEPRECIAÇÃO | C15: =(C10*20%)/12*11 -> 18333.333
B16: (-) DEPRECIAÇÃO ACUMULADA | D16: =C15 -> 18333.333
A18: 42772 | B18: INSTALAÇOES | C18: 50000
B19: BANCO | D19: =C18 -> 50000
B21: DESPESAS COM DEPRECIAÇÃO | C21: =(C18*10%)/12*11 -> 4583.3333
B22: =B16 -> (-) DEPRECIAÇÃO ACUMULADA | D22: =C21 -> 4583.3333
A24: 42772 | B24: ESTQOUE | C24: =D28-C27-C26-C25 -> 2910000
B25: ICMS A RECUPERAR | C25: =D28*18% -> 720000
B26: PIS A RECUPERAR | C26: =D28*1.65% -> 66000
B27: COFINS A RECUPERAR | C27: =D28*7.6% -> 304000
B28: FORNECEDOR | D28: 4000000
A30: 42801 | B30: PARTICIPAÇÃO SOCIETARIA DORA | C30: 1360000
B31: AGIO NA AQUISIÇÃO DE PART. SOCIETARIA | C31: 240000
B32: BANCO | D32: =C30+C31 -> 1600000
A34: 42835 | B34: DESPESAS FINANCEIRAS | C34: 200000
B35: BANCO | D35: =C34 -> 200000
A37: 42865 | B37: DESPESAS COMERCIAS | C37: =300000-C38-C39 -> 272250
B38: PIS A RECUPERA | C38: 4950
B39: COFINS A RECUPERA | C39: 22800
B40: IRRF A RECOLHER | D40: =300000*1.5% -> 4500
B41: PCC A RECOLHER | D41: =300000*4.65% -> 13950
B42: BANCO | D42: =300000-D40-D41 -> 281550
A44: 42896 | B44: TITULO A RECEBR ( EMPRESTIMO LADA) | C44: 730000
B45: BANCO | D45: =C44 -> 730000
A47: 42926 | B47: CLIENTE ( dupl. A receber ) | C47: 5000000
B48: RECEITA DE VENDA | D48: =C47 -> 5000000
B50: ICMS S/ VENDAS | C50: =C47*18% -> 900000
B51: ICMS A RECOLHER | D51: =C50 -> 900000
B53: PIS S/ FATURAMETNO | C53: =C47*1.65% -> 82500
...

Sheet FOLHA DE PAG.
B4: FUNCÃO | C4: SALARIO | D4: INSS | E4: INSS PATRONAL | F4: FGTS | G4: DEPENDENTES | H4: PENSÃO | I4: BASE DO IR | J4: IRRF RETIDO | K4: SALARIOS A PAGAR
B6: FOLHA DE 12/2016 | C6: 300000 | D6: 20000 | E6: =C6*32% -> 96000 | F6: =C6*8% -> 24000 | H6: 0 | I6: =C6-D6-G6-H6 -> 280000 | J6: 25000 | K6: =C6-D6-H6-J6 -> 255000
C7: 0 | D7: =C7*9% -> 0 | E7: =C7*32% -> 0 | F7: =C7*8% -> 0 | G7: 0 | I7: =C7-D7-G7-H7 -> 0 | J7: 0 | K7: =C7-D7-H7-J7 -> 0
C8: 0 | D8: =C8*11% -> 0 | E8: =C8*32% -> 0 | F8: =C8*8% -> 0 | I8: =C8-D8-G8-H8 -> 0 | J8: 0 | K8: =C8-D8-H8-J8 -> 0
C9: 0 | D9: =C9*11% -> 0 | E9: =C9*32% -> 0 | F9: =C9*8% -> 0 | I9: =C9-D9-G9-H9 -> 0 | J9: 0 | K9: =C9-D9-H9-J9 -> 0
C10: 0 | D10: =C10*11% -> 0 | E10: =C10*32% -> 0 | F10: =C10*8% -> 0 | I10: =C10-D10-G10-H10 -> 0 | J10: 0 | K10: =C10-D10-H10-J10 -> 0
C11: 0 | D11: =C11*8% -> 0 | E11: =C11*32% -> 0 | F11: =C11*8% -> 0 | G11: 0 | I11: =C11-D11-G11-H11 -> 0 | J11: 0 | K11: =C11-D11-H11-J11 -> 0
B12: TOTAL | C12: =SUM(C6:C11) -> 300000 | D12: =SUM(D6:D11) -> 20000 | E12: =SUM(E6:E11) -> 96000 | F12: =SUM(F6:F11) -> 24000 | J12: =SUM(J6:J11) -> 25000 | K12: =SUM(K6:K11) -> 255000
B15: PROVISAO DE FÉRIAS | C15: =C12/12 -> 25000 | D15: PROVISAO 13.SALARIO | E15: =C15 -> 25000
B16: PROVISAO DE 1/3 DE FÉRIAS | C16: =C15/3 -> 8333.3333
B17: TOTAL | C17: =C15+C16 -> 33333.333
B20: FGTS S/PROVISOES | C20: =(C17+E15)*8% -> 4666.6667 | D20: =F12+C20 -> 28666.667 | E20: =E19*8% -> 0
B21: INSS S/PROVISOES | C21: =(C17+E15)*26.8% -> 15633.333
C22: =C17*26.8% -> 8933.3333
F24: =C20-C25 -> 2666.6667
B25: FGTS A RECOLHER | C25: =C15*8% -> 2000

Sheet RAZÃO ATIVO
A1: D | B1: =DIARIO!B5 -> BANCO | D1: C | F1: D | G1: =DIARIO!B7 -> CAPITAL A INTEGRALIZAR | I1: C | J1: D | K1: CAPITAL SOCIAL | M1: C
B2: =DIARIO!C5 -> 8581875 | C2: =DIARIO!D19 -> 50000 | G2: =DIARIO!C2 -> 10000000 | H2: =DIARIO!D7 -> 7500000 | K2: =DIARIO!G2 -> 0 | L2: =DIARIO!D3 -> 10000000
B3: =DIARIO!C92 -> 4560000 | C3: =DIARIO!D32 -> 1600000
C4: =DIARIO!D35 -> 200000
C5: =DIARIO!D42 -> 281550 | G5: =SUM(G2:G4) -> 10000000 | H5: =SUM(H2:H4) -> 7500000 | K5: =SUM(K2:K4) -> 0 | L5: =SUM(L2:L4) -> 10000000
C6: =DIARIO!D45 -> 730000 | G6: =G5-H5 -> 2500000 | K6: 0 | L6: =L5 -> 10000000
C7: =DIARIO!D65 -> 50000
C8: =DIARIO!D87 -> 469250
C9: =DIARIO!D90 -> 800000
C10: =DIARIO!D98 -> 3130000
C11: =DIARIO!D101 -> 250000
C12: =DIARIO!D126 -> 2000
C13: =DIARIO!D132 -> 3905352.5
C14: =DIARIO!D150 -> 22750
B18: =SUM(B2:B17) -> 13141875 | C18: =SUM(C2:C17) -> 11490902
B19: =B18-C18 -> 1650972.5
A22: D | B22: PROVISÃO P/ GARANTIAS - PC | D22: C | F22: D | G22: =DIARIO!B16 -> (-) DEPRECIAÇÃO ACUMULADA | I22: C
C23: 40000 | H23: =DIARIO!D16 -> 18333.333 | J23: Instalação
H24: =DIARIO!D22 -> 4583.3333 | J24: Veiculo
B27: =SUM(B23:B26) -> 0 | C27: =SUM(C23:C26) -> 40000 | G27: =SUM(G23:G26) -> 0 | H27: =SUM(H23:H26) -> 22916.667
B28: =B27-C27 -> -40000 | G28: 0 | H28: =H27 -> 22916.667
A30: D | B30: =DIARIO!B18 -> INSTALAÇOES | D30: C
B31: =DIARIO!C18 -> 50000 | F31: D | G31: =DIARIO!B24 -> ESTQOUE | I31: C
G32: =DIARIO!C24 -> 2910000 | H32: =DIARIO!D60 -> 2037000
H33: =DIARIO!D116 -> 61500
H34: =DIARIO!D80 -> 750000
B35: =SUM(B31:B34) -> 50000 | C35: =SUM(C31:C34) -> 0
B36: =B35-C35 -> 50000 | G36: =SUM(G32:G35) -> 2910000 | H36: =SUM(H32:H35) -> 2848500
G37: =G36-H36 -> 61500
A40: D | B40: =DIARIO!B25 -> ICMS A RECUPERAR | D40: C | F40: D | G40: =DIARIO!B26 -> PIS A RECUPERAR | I40: C
B41: =DIARIO!C25 -> 720000 | C41: =B41 -> 720000 | G41: =DIARIO!C26 -> 66000 | H41: =G45 -> 80025
G42: =DIARIO!C64 -> 825
G43: =DIARIO!C86 -> 8250
G44: =DIARIO!C38 -> 4950
B45: =SUM(B41:B44) -> 720000 | C45: =SUM(C41:C44) -> 720000 | G45: =SUM(G41:G44) -> 80025 | H45: =SUM(H41:H44) -> 80025
B46: =B45-C45 -> 0 | G46: =G45-H45 -> 0
A49: D | B49: =DIARIO!B27 -> COFINS A RECUPERAR | D49: C | F49: D | G49: =DIARIO!B30 -> PARTICIPAÇÃO SOCIETARIA DORA | I49: C
B50: =DIARIO!C27 -> 304000 | C50: =B54 -> 368600 | G50: =DIARIO!C30 -> 1360000
B51: =DIARIO!C63 -> 3800 | G51: =DIARIO!C155 -> 536178
B52: =DIARIO!C85 -> 38000
...

Sheet RAZÃO PASSIVO
A1: D | B1: =DIARIO!B11 -> JUROS APROPRIAR | D1: C | F1: D | G1: =DIARIO!B12 -> FINANCIAMENTO C. PRAZO | I1: C
B2: =DIARIO!C11 -> 25000 | C2: =DIARIO!D125 -> 500 | H2: =DIARIO!D12 -> 30000
G3: =DIARIO!C124 -> 2500
B6: =SUM(B2:B5) -> 25000 | C6: =SUM(C2:C5) -> 500 | G6: =SUM(G2:G5) -> 2500 | H6: =SUM(H2:H5) -> 30000
B7: =B6-C6 -> 24500 | G7: 0 | H7: =H6-G6 -> 27500
A10: D | B10: =DIARIO!B28 -> FORNECEDOR | D10: C | F10: D | G10: =DIARIO!B40 -> IRRF A RECOLHER | I10: C
B11: =DIARIO!C96 -> 3100000 | C11: =DIARIO!D28 -> 4000000 | H11: =DIARIO!D40 -> 4500
H12: =DIARIO!D84 -> 7500
H13: =DIARIO!D139 -> 25000
H14: =DIARIO!D176 -> 84375
B15: =SUM(B11:B14) -> 3100000 | C15: =SUM(C11:C14) -> 4000000
B16: 0 | C16: =C15-B15 -> 900000 | G16: =SUM(G11:G15) -> 0 | H16: =SUM(H11:H15) -> 121375
A18: D | B18: =DIARIO!B41 -> PCC A RECOLHER | D18: C
C19: =DIARIO!D41 -> 13950 | F19: D | G19: =DIARIO!B51 -> ICMS A RECOLHER | I19: C
C20: =DIARIO!D83 -> 23250 | G20: ='RAZÃO ATIVO'!B41 -> 720000 | H20: =DIARIO!D51 -> 900000
H21: =DIARIO!C106 -> 24000
H22: =DIARIO!D71 -> 108000
B24: =SUM(B19:B23) -> 0 | C24: =SUM(C19:C23) -> 37200 | G24: =SUM(G20:G23) -> 720000 | H24: =SUM(H20:H23) -> 1032000
G25: 0 | H25: =H24-G24 -> 312000
A28: D | B28: =DIARIO!B54 -> PIS A RECOLHER | D28: C | F28: D | G28: =DIARIO!B57 -> COFINS A RECOLHER | I28: C
B29: ='RAZÃO ATIVO'!G45 -> 80025 | C29: =DIARIO!D54 -> 82500 | G29: ='RAZÃO ATIVO'!B54 -> 368600 | H29: =DIARIO!D57 -> 380000
C30: =DIARIO!D74 -> 14850 | H30: =DIARIO!D77 -> 68400
C31: =DIARIO!C109 -> 3300 | H31: =DIARIO!C112 -> 15200
H32: =3800+38000 -> 41800
B33: =SUM(B29:B32) -> 80025 | C33: =SUM(C29:C32) -> 100650 | G33: =SUM(G29:G32) -> 368600 | H33: =SUM(H29:H32) -> 505400
B34: 0 | C34: =C33-B33 -> 20625 | G34: 0 | H34: =H33-G33 -> 136800
A37: D | B37: =DIARIO!B140 -> SALARIOS A PAGAR | D37: C | F37: D | G37: =DIARIO!B71 -> ICMS A RECOLHER | I37: C
C38: =DIARIO!D140 -> 255000 | G38: ='RAZÃO ATIVO'!B45 -> 720000 | H38: 900000
H39: 108000
H40: 24000
C42: =SUM(C38:C41) -> 255000 | G42: =SUM(G38:G41) -> 720000 | H42: =SUM(H38:H41) -> 1032000
B43: =SUM(B38:B42) -> 0 | C43: 0 | G43: 0 | H43: =H42-G42 -> 312000
A46: D | B46: =DIARIO!B138 -> INSS A RECOLHER | D46: C | F46: D | G46: =DIARIO!B143 -> FGTS A RECOLHER | I46: C
C47: =DIARIO!D146 -> 96000 | H47: =DIARIO!D143 -> 24000
C48: =DIARIO!D138 -> 20000 | H48: =DIARIO!D180 -> 2000
C49: =DIARIO!D149 -> 2250
B52: =SUM(B47:B51) -> 0 | C52: =SUM(C47:C51) -> 118250 | G52: =SUM(G47:G51) -> 0 | H52: =SUM(H47:H51) -> 26000
A55: D | B55: =DIARIO!B13 -> FINANCIAMENTO L. PRAZO | D55: C | F55: D | G55: =DIARIO!B150 -> 13º A PAGAR | I55: C
C56: =DIARIO!D13 -> 95000 | H56: =DIARIO!D150 -> 22750
B61: =SUM(B56:B60) -> 0 | C61: =SUM(C56:C60) -> 95000 | G61: =SUM(G56:G60) -> 0 | H61: =SUM(H56:H60) -> 22750
...

Sheet RAZÃO DESPESAS
A1: D | B1: =DIARIO!B15 -> DESPESAS COM DEPRECIAÇÃO | D1: C | F1: D | G1: =DIARIO!B34 -> DESPESAS FINANCEIRAS | I1: C
B2: =DIARIO!C188 -> 0 | G2: =DIARIO!C34 -> 200000
B6: =SUM(B2:B5) -> 0 | G6: =SUM(G2:G5) -> 200000
B7: 0 | C7: =SUM(C2:C6) -> 0 | G7: 0 | H7: =SUM(H2:H6) -> 0
A10: D | B10: =DIARIO!B37 -> DESPESAS COMERCIAS | D10: C | F10: D | G10: =DIARIO!B48 -> RECEITA DE VENDA | I10: C
B11: =DIARIO!C37 -> 272250 | G11: 0 | H11: =DIARIO!D48 -> 5000000
H12: =DIARIO!D68 -> 900000
H13: =DIARIO!C103 -> 200000
B15: =SUM(B11:B14) -> 272250 | G15: 0 | H15: =SUM(H11:H14) -> 6100000
B16: 0 | C16: =SUM(C11:C15) -> 0 | G16: 0 | H16: 0
A18: D | B18: =DIARIO!B50 -> ICMS S/ VENDAS | D18: C
B19: =DIARIO!C50 -> 900000 | F19: D | G19: =DIARIO!B53 -> PIS S/ FATURAMETNO | I19: C
B20: =DIARIO!C70 -> 108000 | G20: =DIARIO!C53 -> 82500
B21: =DIARIO!D107 -> 24000 | G21: =DIARIO!C73 -> 14850
G22: =DIARIO!D110 -> 3300
B24: =SUM(B19:B23) -> 1032000 | C24: =SUM(C19:C23) -> 0
G25: =SUM(G20:G24) -> 100650 | H25: =SUM(H20:H24) -> 0
A28: D | B28: =DIARIO!B56 -> COFINS S/ FATURAMENTO | D28: C | F28: D | G28: =DIARIO!B59 -> CMV | I28: C
B29: =DIARIO!C56 -> 380000 | G29: =DIARIO!C59 -> 2037000
B30: =DIARIO!C76 -> 68400 | G30: =DIARIO!C79 -> 750000
B31: =DIARIO!D113 -> 15200 | G31: =DIARIO!C115 -> 61500
B32: =3800+38000 -> 41800
B34: =SUM(B29:B33) -> 505400 | C34: =SUM(C29:C33) -> 0 | G34: =SUM(G29:G33) -> 2848500 | H34: =SUM(H29:H33) -> 0
A37: D | B37: =DIARIO!B62 -> DESP. C/ ALUGUEL LADA | D37: C | F37: D | G37: =DIARIO!B82 -> DESPESAS ASSESSORIA TEC. | I37: C
B38: =DIARIO!C62 -> 45375 | G38: =DIARIO!C82 -> 453750
B42: =SUM(B38:B41) -> 45375 | G42: =SUM(G38:G41) -> 453750
B43: 0 | C43: =SUM(C38:C42) -> 0 | G43: 0 | H43: =SUM(H38:H42) -> 0
A46: D | B46: =DIARIO!B89 -> DESPESAS ADMINISTRATIVAS | D46: C | F46: D | G46: =DIARIO!B93 -> RECEITAS (JUROS) | I46: C
B47: =DIARIO!C89 -> 800000 | H47: =DIARIO!D93 -> 60000
B51: =SUM(B47:B50) -> 800000 | H51: =SUM(H47:H50) -> 60000
B52: 0 | C52: =SUM(C47:C51) -> 0 | G52: 0 | H52: 0
A55: D | B55: =DIARIO!B97 -> DESP. C/ JUROS | D55: C | F55: D | G55: =DIARIO!B100 -> DEPESAS COM MULTAS (IRPJ) | I55: C
B56: =DIARIO!C97 -> 30000 | G56: =DIARIO!C100 -> 250000
B60: =SUM(B56:B59) -> 30000 | G60: =SUM(G56:G59) -> 250000
B61: 0 | C61: =SUM(C56:C60) -> 0 | G61: 0 | H61: =SUM(H56:H60) -> 0
A64: D | B64: =DIARIO!B135 -> RECEITA DE SERVICOS | D64: C | F64: D | G64: =DIARIO!B142 -> DESPESAS COM FGTS | I64: C
C65: =DIARIO!D135 -> 14765.48 | G65: =DIARIO!C142 -> 24000
G66: ='FOLHA DE PAG.'!C20 -> 4666.6667
C69: =SUM(C65:C68) -> 14765.48 | G69: =SUM(G65:G68) -> 28666.667
B70: 0 | C70: 0 | G70: 0 | H70: =SUM(H65:H69) -> 0
...

Sheet EQUIVALENCIA PATRIMONIAL
A1: RESULTADO DO EXERCICIO CONTROLADA DORA
A2: LUCRO ACUMULADO | D2: 67022.5
A3: PARTICIPAÇÃO 80% | D3: 0.8
A4: RESULTADO DE EQUIVALENCIA | D4: =D2*D3 -> 53618
D7: DEBITO | E7: CRÉDITO
A8: =DIARIO!B30 -> PARTICIPAÇÃO SOCIETARIA DORA
J15: 67022.5
