Workbook

Sheet Tutorial
A1: VALIDAÇÃO DE DESLIGAMENTO DE ACORDO A NOVA LEI DO AVISO PRÉVIO
A3: O objeto desta planilha é analisar individualmente se a data sugerida para desligamento do ocorre ocorre no período de 30 (trinta) dias que antecede a data de sua correção salarial. Assim, poderá evitar o pagamento à indenização adicional equivalente a um salário mensal, seja ele optante ou não pelo Fundo de Garantia do Tempo de Serviço - FGTS.
A5: Para que análise seja correta, é necessário que o usuário siga os passos abaixo:
A7: Na planilha DADOS, digite/copie somente nas células na cor OURO, ÊNFASE 4.
A8: As informações necessárias são:
A9: Filial | B9: Item obrigatório
A10: Matricula | B10: Item obrigatório
A11: Centro Custo | B11: Não é obrigatório
A12: Nome completo | B12: Não é obrigatório, mas é bom ter o nome do colaborador.
A13: Data Admis. | B13: Item obrigatório
A14: C. Sindicato | B14: Item obrigatório (sugiro colocar o número do sindicato)
A15: Salário | B15: Item obrigatório
A16: Função | B16: Não é obrigatório, mas é bom ter a descrição do cargo.
A17: Descrição Centro de Custo | B17: Não é obrigatório
A20: Na planilha ANÁLISE, digite somente nas células na cor OURO, ÊNFASE 4. | J20: Mas antes, deve copiar na coluna W e X o código e a descrição de cada sindicato.
A21: Na coluna Y, em DATA BASE, deve digitar a data base de cada sindicato.
A22: Obs: caso a data base de 2016 ainda não tem saído, é fundamente que coloque a data do ano atual (2017).
A24: Para analisar, basta digitar no campos indicados o código da filial + código da matrícula + data sugerida.
A25: No item RESULTADO,indicará se pode ou não ser desligado na data informada.
A26: No item MELHOR DATA, indicará a melhor data que poderá ser desligada de modo a não pagar a multa do art. 9º da Lei 7238/84.
A27: E, se estiver em contrato de experiência, mesmo que 30 dias antes da data base, será informado esta data na qual não haverá impeditivo para desligamento.
A29: Na planilha CÁLCULO, basta digitar nos seguintes campos:
A30: Coluna W (informar SIM ou NÃO para férias vencidas)
A31: Coluna Y (informar o saldo do FGTS mediante consulta no conectividade)
A33: Nesta planilha (cálculo) trará o resultado da rescisão do colaborador, considerando os seguintes eventos e como se a rescisão fosse com aviso prévio indenizado:
A34: Saldo de Salários
A35: Aviso Prévio Indenizado
... A41: Multa FGTS

Sheet Análise
A1: VALIDAÇÃO DE DESLIGAMENTO DE ACORDO A NOVA LEI DO AVISO PRÉVIO
X2: v.2017.1
Y3: =YEAR(Y5) -> 2017 | BN3: -1 | BO3: Pode ser desligado
A4: Filial | B4: 101 | D4: RESULTADO | W4: Sind. | X4: Descrição Sindicato | Y4: DATA BASE | BN4: =BN3-1 -> -2 | BO4: Pode ser desligado
A5: Matrícula | B5: 615 | D5: =IFERROR(IF(B17="SIM","Período de Experiência",B21),"") -> Não pode ser desligado | W5: 1 | X5: SINDICATO DOS COMERCIARIOS DE SAO PAULO | Y5: 42979 | BN5: =BN4-1 -> -3 | BO5: Pode ser desligado
A6: CPF | B6: =IFERROR(VLOOKUP(B4&B5,Dados!1:1048576,15,0),"") -> 0 | W6: 2 | X6: SINDICATO DOS EMPREG DO COM DE JUNDIAI | Y6: 42979 | BN6: =BN5-1 -> -4 | BO6: Pode ser desligado
A7: Função | B7: =IFERROR(VLOOKUP(B4&B5,Dados!$1:$1048576,9,0),"") -> TECNICO ANALISES CLINICAS I | W7: 3 | X7: SIND DOS EMP NO COM DO RIO DE JANEIRO | Y7: 42867 | BN7: =BN6-1 -> -5 | BO7: Pode ser desligado
A8: Descrição Filial/Centro Custo | B8: =IFERROR(VLOOKUP(B4&B5,Dados!$1:$1048576,10,0),"") -> Hematologia | W8: 4 | X8: SIND DOS EMP DO COM DE DUQUE DE CAXIAS | Y8: 42736 | BN8: =BN7-1 -> -6 | BO8: Pode ser desligado
A9: Data Desligamento | B9: 42917 | W9: 5 | X9: SIND DOS EMPR NO COM DE SANTO ANDRE | Y9: 43009 | BN9: =BN8-1 -> -7 | BO9: Pode ser desligado
A10: Nome do colaborador | B10: =IFERROR(VLOOKUP($B$4&$B$5,Cálculo!$A:$AH,5,0),"") -> ADAILZA FERREIRA DOS ANJOS | W10: 6 | X10: SINDICATO DOS EMPR COMERCIO DE NITEROI | Y10: 42795 | BN10: =BN9-1 -> -8 | BO10: Pode ser desligado
A11: Sindicato | B11: =IFERROR(VLOOKUP($B$4&$B$5,Cálculo!$A:$AH,34,0),"") -> 1 | W11: 7 | X11: SIND EMP DO COM DE SAO JOSE DO RIO PRETO | Y11: 42979 | BN11: =BN10-1 -> -9 | BO11: Pode ser desligado
A12: Data Base | B12: =IFERROR(VLOOKUP(B11,W4:$Y$23,3,0),"") -> 42979 | D12: MELHOR DATA (a partir de) | W12: 8 | X12: SINDICATO DOS EMPR NO COM DE BAURU | Y12: 42979 | BN12: =BN11-1 -> -10 | BO12: Pode ser desligado
A13: Data admissão | B13: =IFERROR(VLOOKUP($B$4&$B$5,Cálculo!$A:$BI,7,0),"") -> 40665 | D13: =IFERROR(IF(D5="Não pode ser desligado",B20,""),"") -> 42932 | W13: 9 | X13: SINDICATO DOS EMPR NO COM DE CAMPINAS | Y13: 42979 | BN13: =BN12-1 -> -11 | BO13: Pode ser desligado
A14: Quant. dias avisos | B14: =IFERROR(VLOOKUP($B$4&$B$5,Cálculo!$A:$BI,36,0),"") -> 48 | W14: 10 | X14: SINDICATO DOS EMP NO COM DE PIRACICABA | Y14: 42979 | BN14: =BN13-1 -> -12 | BO14: Pode ser desligado
A15: Data projetada do aviso | B15: =IFERROR(VLOOKUP($B$4&$B$5,Cálculo!$A:$BI,37,0),"") -> 42965 | W15: 11 | X15: SIND EMP NO COM DE PRESIDENTE PRUDENTE | Y15: 42979 | BN15: =BN14-1 -> -13 | BO15: Pode ser desligado
B16: =INT((B9-B13))+1 -> 2253 | W16: 12 | X16: SIND EMP DO COM DE SAO JOSE DOS CAMPOS | Y16: 42979 | BN16: =BN15-1 -> -14 | BO16: Pode ser desligado
A17: Está em período de Experiência? | B17: =IF(B16<=90,"SIM","NÃO") -> NÃO | W17: 13 | X17: SINDICATO DOS EMP DO COM DE SOROCABA | Y17: 42979 | BN17: =BN16-1 -> -15 | BO17: Pode ser desligado
B18: =INT(B9-B13)/365.25 -> 6.16564 | D18: TÉRMINO EXPERIÊNCIA | W18: 14 | X18: SINDICATO EMPREG COMERCIO DE GUARULHOS | Y18: 42979 | BN18: =BN17-1 -> -16 | BO18: Pode ser desligado
A19: Dias diferença | B19: =IF(ISERROR((B12-B15)),"",(B12-B15)) -> 14 | D19: =IFERROR(IF(D5="Período de Experiência",SUM(B13+90-1),""),"") | W19: 15 | X19: SIND DOS EMPREG COMER DE RIBEIRAO PRETO | Y19: 42979 | BN19: =BN18-1 -> -17 | BO19: Pode ser desligado
A20: Melhor data | B20: =IF(ISERROR((B12-B14)+1),"",(B12-B14)+1) -> 42932 | W20: 16 | X20: SIND. TRAB. COMERCIO NOVA IGUACU | Y20: 42866 | BN20: =BN19-1 -> -18 | BO20: Pode ser desligado
A21: Resultado | B21: =IF(ISERROR(VLOOKUP(B19,BN:BO,2,0)),"",VLOOKUP(B19,BN:BO,2,0)) -> Não pode ser desligado | W21: 17 | X21: SIND DOS EMP COM DE SAO JOAO DO MERITI | Y21: 43040 | BN21: =BN20-1 -> -19 | BO21: Pode ser desligado
A22: =IF(Y3<>YEAR(B9),"Planilha não pode ser utilizada","") | W22: 18 | X22: SIND DOS EMPREG NO COMERCIO DE MARILIA | Y22: 42979
W23: 19 | X23: SIND EMPREG NO COM DE OSASCO E REGIAO | Y23: 42979
BN24: =BN21-1 -> -20 | BO24: Pode ser desligado
A25: Obs: esta validação se enquadra apenas para desligamentos com 30 dias antes da data base e com projeção da nova Lei do Aviso Prévio. As demais validações como CIPA, aposentadoria, férias, licença maternidade e licença INSS devem ser realizadas, conforme instruções anteriores. | BN25: =BN24-1 -> -21 | BO25: Pode ser desligado
BN26: =BN25-1 -> -22 | BO26: Pode ser desligado
BN27: =BN26-1 -> -23 | BO27: Pode ser desligado
BN28: =BN27-1 -> -24 | BO28: Pode ser desligado
BN29: =BN28-1 -> -25 | BO29: Pode ser desligado
BN30: =BN29-1 -> -26 | BO30: Pode ser desligado
BN31: =BN30-1 -> -27 | BO31: Pode ser desligado
BN32: =BN31-1 -> -28 | BO32: Pode ser desligado
BN33: =BN32-1 -> -29 | BO33: Pode ser desligado
BN34: =BN33-1 -> -30 | BO34: Pode ser desligado
BN35: =BN34-1 -> -31 | BO35: Pode ser desligado
BN36: =BN35-1 -> -32 | BO36: Pode ser desligado
BN37: =BN36-1 -> -33 | BO37: Pode ser desligado
... BN304: =BN303-1 -> -300 | BO304: Pode ser desligado
BN305: 1 | BO305: Não pode ser desligado
BN306: 2 | BO306: Não pode ser desligado
...

Sheet Config
E2: Tabela de contagem do acréscimo ao tempo de aviso prévio - Lei nº 12.506 de 11 de outubro de 2011
E4: Parâmetro: | H4: Ano + 1 dia
E6: Tempo de serviço, Ano completo | I6: Aviso Prévio, dias
E7: 0 | I7: 30 | M7: =E7 -> 0
E8: 1 | I8: 33 | M8: =E8 -> 1
E9: 2 | I9: 36 | M9: =E9 -> 2
E10: 3 | I10: =IF((I9-I8)+(I9)<90,(I9-I8)+(I9),90) -> 39 | M10: =E10 -> 3
E11: 4 | I11: =IF((I10-I9)+(I10)<90,(I10-I9)+(I10),90) -> 42 | M11: =E11 -> 4
E12: 5 | I12: =IF((I11-I10)+(I11)<90,(I11-I10)+(I11),90) -> 45 | M12: =E12 -> 5
E13: 6 | I13: =IF((I12-I11)+(I12)<90,(I12-I11)+(I12),90) -> 48 | M13: =E13 -> 6
E14: 7 | I14: =IF((I13-I12)+(I13)<90,(I13-I12)+(I13),90) -> 51 | M14: =E14 -> 7
E15: 8 | I15: =IF((I14-I13)+(I14)<90,(I14-I13)+(I14),90) -> 54 | M15: =E15 -> 8
E16: 9 | I16: =IF((I15-I14)+(I15)<90,(I15-I14)+(I15),90) -> 57 | M16: =E16 -> 9
E17: 10 | I17: =IF((I16-I15)+(I16)<90,(I16-I15)+(I16),90) -> 60 | M17: =E17 -> 10
E18: 11 | I18: =IF((I17-I16)+(I17)<90,(I17-I16)+(I17),90) -> 63 | M18: =E18 -> 11
E19: 12 | I19: =IF((I18-I17)+(I18)<90,(I18-I17)+(I18),90) -> 66 | M19: =E19 -> 12
E20: 13 | I20: =IF((I19-I18)+(I19)<90,(I19-I18)+(I19),90) -> 69 | M20: =E20 -> 13
E21: 14 | I21: =IF((I20-I19)+(I20)<90,(I20-I19)+(I20),90) -> 72 | M21: =E21 -> 14
... E28: 21 | I28: =IF((I27-I26)+(I27)<90,(I27-I26)+(I27),90) -> 90 | M28: =E28 -> 21
L29: =VLOOKUP(90,I7:M28,5,FALSE) -> 20

Sheet Cálculo
B2: Filial | C2: Matricula | D2: Centro Custo | E2: Nome do colaborador | F2: Cargo | G2: Data Admis. | H2: SAL + CF | I2: Afastamento | J2: Data Desligamento | K2: Tipo de Desligamento | L2: Saldo de Salários | M2: Aviso Prévio Indenizado | N2: Férias Vencidas | O2: Férias Proporcionais | P2: 1/3 Férias | Q2: 13º Salário | R2: Multa , Lei Nº 7.238/84 | S2: Multa FGTS | T2: Estabilidade | U2: VALOR TOTAL | W2: Férias Vencidas | X2: Validação FÉRIAS VENCIDAS | Y2: SALDO FGTS | Z2: FGTS 03e04 | AA2: FGTS na rescisão | AB2: TOTAL FGTS | AC2: Médias | AD2: P.I.S. | AE2: CPF | AF2: Data Nasc. | AG2: Data Base | AH2: Sind | AI2: Saldo de dias trabalhados | AJ2: Dias Direito Aviso | AK2: Dt Projeção Aviso I | AL2: Dt Projeção Aviso II | AM2: Dt Projeção Aviso III | AN2: Anos Trab. I | AO2: Anos Trab. II | AP2: Anos Trab. III | AQ2: Anos Trab | AR2: Anos Trab | AS2: Anos Trab | AT2: Ana Atual I | AU2: Ana Atual II | AV2: Mese Trab. Ano I | AW2: Mese Trab. Ano II | AX2: Mese Trab. Ano III | AY2: Férias Propor. I | AZ2: Férias Propor. II | BA2: Fim mês | BB2: Valor Dia | BC2: Valor Mês | BD2: 13º Meses ano | BE2: 13º Dias | BF2: 13º Resultado | BG2: Dia Data Base | BH2: Mês Data Base | BI2: Multa Data Base
A3: =B3&C3 -> 101615 | B3: =Análise!B4 -> 101 | C3: =Análise!B5 -> 615 | D3: =VLOOKUP($B3&$C3,Dados!1:1048576,4,0) -> 70120 | E3: =VLOOKUP($B3&$C3,Dados!1:1048576,5,0) -> ADAILZA FERREIRA DOS ANJOS | F3: =VLOOKUP($B3&$C3,Dados!1:1048576,9,0) -> TECNICO ANALISES CLINICAS I | G3: =VLOOKUP($B3&$C3,Dados!1:1048576,6,0) -> 40665 | H3: =VLOOKUP($B3&$C3,Dados!1:1048576,8,0) -> 4958.2335 | J3: =Análise!B9 -> 42917 | K3: Dispensa sem justa causa | L3: =AI3*BB3 -> 165.27445 | M3: =IF(K3="Dispensa sem justa causa",IF(AJ3>0,AJ3*BB3+AC3,0)+0*BB3+AC3,0) -> 7933.1736 | N3: =IF(W3="sim",(H3+AC3),0) -> 4958.2335 | O3: =(AY3*BC3) -> 1652.7445 | P3: =(N3+O3)/3 -> 2203.6593 | Q3: =(BF3*BC3) -> 3305.489 | R3: =IF(BI3>0,BI3,0) -> 4958.2335 | S3: =(AB3*0.5) -> 24754.072 | T3: 0 | U3: =SUM(L3:T3) -> 49930.88 | W3: SIM | X3: =IF(G3>0,IF(J3>0,IF(W3="sim",IF(AO3>=1,"","Atenção: Não há férias vencidas"),""),""),"") | Y3: 48199.17 | Z3: 0 | AA3: =(L3+M3+Q3+R3)*0.08 -> 1308.9736 | AB3: =Y3+Z3+AA3 -> 49508.144 | AC3: 0 | AD3: =VLOOKUP($B3&$C3,Dados!1:1048576,12,0) -> 0 | AE3: =VLOOKUP($B3&$C3,Dados!1:1048576,15,0) -> 0 | AF3: =VLOOKUP($B3&$C3,Dados!1:1048576,72,0) -> 0 | AG3: =VLOOKUP(AH3,Análise!$W$4:$Y$21,3,0) -> 42979 | AH3: =VLOOKUP($B3&$C3,Dados!1:1048576,7,0) -> 1 | AI3: =IF(MONTH(J3)=MONTH(G3),IF(YEAR(J3)=YEAR(G3),DAY(J3)-DAY(G3),DAY(J3)),DAY(J3)) -> 1 | AJ3: =IF(K3="Dispensa sem justa causa",IF(G3>0,IF(J3>0,IF(AN3+30<=90,AN3+30,90),""),""),"") -> 48 | AK3: =IF(K3="Dispensa sem justa causa",J3+AJ3,J3) -> 42965 | AL3: =IF(K3="Dispensa sem justa causa",J3+30,J3) -> 42947 | AM3: =AL3-1 -> 42946 | AN3: =IF(K3="Dispensa sem justa causa",IF(AP3>=Config!$L$29,60,VLOOKUP(AP3,Config!$E$7:L52,5,FALSE)-30),0) -> 18 | AO3: =IF(YEAR(AL3)>YEAR(G3),(YEAR(AL3)-YEAR(G3))-AS3,0) -> 6 | AP3: =IF(Config!H4="ano completo",IF(YEAR(AL3)>YEAR(G3),(YEAR(AL3)-YEAR(G3))-AS3,0),IF(YEAR(AM3)>YEAR(G3),(YEAR(AM3)-YEAR(G3))-AS3,0)) -> 6 | AQ3: =IF(AR3<=0,DAY(AL3)-DAY(G3),0) -> 0 | AR3: =MONTH(AL3)-MONTH(G3) -> 2 | AS3: =IF(AR3<0,1,IF(AQ3<0,1,0)) -> 0 | AT3: =YEAR(J3) -> 2017 | AU3: =DATE(AT3,1,1) -> 42736 | AV3: =MONTH(AK3)+AX3 -> 8 | AW3: =DAY(AK3) -> 18 | AX3: =IF(AW3<15,-1,0) -> 0 | AY3: =IF(AZ3>=15,DATEDIF(G3,AK3,"Ym")+1,DATEDIF(G3,AK3,"Ym")) -> 4 | AZ3: =IF(DAY(AK3)>=DAY(G3),DAY(AK3)-DAY(G3)+1,(DATEDIF(G3,BA3,"md")+1)+DAY(AK3)) -> 17 | BA3: =EOMONTH(AK3,-1) -> 42947 | BB3: =(H3)/30 -> 165.27445 | BC3: =(H3+AC3)/12 -> 413.18612 | BD3: =IF(BE3>=15,DATEDIF(G3,AK3,"YM")+1,DATEDIF(G3,AK3,"YM")) -> 4 | BE3: =IF(DAY(AK3)>=DAY(G3),DAY(AK3)-DAY(G3)+1,(DATEDIF(G3,BA3,"md")+1)+DAY(AK3)) -> 17 | BF3: =IF(YEAR(AK3)>YEAR(G3),IF(DAY(AK3)>=15,MONTH(AK3),MONTH(AK3)-1),BD3) -> 8 | BG3: =DAY(AG3) -> 1 | BH3: =MONTH(AG3) -> 9 | BI3: =IF(K3="Dispensa sem justa causa",IF(AK3<DATE(YEAR(AK3),BH3,BG3),IF(AK3>=DATE(YEAR(AK3),BH3,BG3)-30,H3,0),0),0) -> 4958.2335

Sheet Dados
A1: Chave | B1: Filial | C1: Matricula | D1: Centro Custo | E1: Nome completo | F1: Data Admis. | G1: C. Sindicato | H1: Salário | I1: Função | J1: Descrição Centro de Custo
A2: =B2&C2 -> 101615 | B2: 101 | C2: 615 | D2: 70120 | E2: ADAILZA FERREIRA DOS ANJOS | F2: 40665 | G2: 1 | H2: 4958.2335 | I2: TECNICO ANALISES CLINICAS I | J2: Hematologia
A3: =B3&C3 -> 101631 | B3: 101 | C3: 631 | D3: 24200 | E3: ADELAIDE MOREIRA SILVA RIBEIRO | F3: 40604 | G3: 1 | H3: 9939.9795 | I3: CONFERENTE I | J3: Almoxarifado
A4: =B4&C4 -> 1012002 | B4: 101 | C4: 2002 | D4: 24600 | E4: ADELIA KARLA SANTIAGO | F4: 37137 | G4: 1 | H4: 10400.197 | I4: COPEIRA | J4: Suporte Administrativo
A5: =B5&C5 -> 1012003 | B5: 101 | C5: 2003 | D5: 24200 | E5: ADELSON PASSOS DE LIMA | F5: 37137 | G5: 1 | H5: 41736.073 | I5: SUPERVISOR ARMAZEM | J5: Almoxarifado
A6: =B6&C6 -> 1012009 | B6: 101 | C6: 2009 | D6: 24200 | E6: ADEMAR ROBERTO MENDES | F6: 37501 | G6: 1 | H6: 4958.2335 | I6: CONFERENTE II | J6: Almoxarifado
A7: =B7&C7 -> 1012017 | B7: 101 | C7: 2017 | D7: 24200 | E7: ADENISE SANTOS DE OLIVEIRA | F7: 38026 | G7: 1 | H7: 4722.1185 | I7: ASSISTENTE ADMINISTRATIVO | J7: Almoxarifado
A8: =B8&C8 -> 1012028 | B8: 101 | C8: 2028 | D8: 24600 | E8: ADILSON LEVINDO DIAS | F8: 38131 | G8: 1 | H8: 6873.174 | I8: ANALISTA ADMINISTRATIVO I | J8: Suporte Administrativo
A9: =B9&C9 -> 1012034 | B9: 101 | C9: 2034 | D9: 70140 | E9: ADRIANA DA CONCEICAO CEZAR FERREIRA | F9: 38231 | G9: 1 | H9: 17678.578 | I9: AUXILIAR ANALISES CLINICAS I | J9: Microbiologia
A10: =B10&C10 -> 1012085 | B10: 101 | C10: 2085 | D10: 24700 | E10: ADRIANA FERREIRA DA COSTA RAMOS | F10: 38452 | G10: 1 | H10: 4910.994 | I10: MOTORISTA I | J10: Transporte
A11: =B11&C11 -> 1012086 | B11: 101 | C11: 2086 | D11: 70190 | E11: ADRIANA FERREIRA TEIXEIRA | F11: 38453 | G11: 1 | H11: 3380.6025 | I11: AUXILIAR ANALISES CLINICAS II | J11: Exames Terceirizados
A12: =B12&C12 -> 1012087 | B12: 101 | C12: 2087 | D12: 70101 | E12: ADRIANA SANTORO DE MORAES | F12: 38453 | G12: 1 | H12: 4282.113 | I12: AUXILIAR ANALISES CLINICAS I | J12: Lavagem e Esterilizacao - AC
A13: =B13&C13 -> 1012100 | B13: 101 | C13: 2100 | D13: 24200 | E13: ADRIANA VITALINO DA SILVA SANTOS | F13: 38504 | G13: 1 | H13: 2704.482 | I13: ANALISTA ARMAZEM I | J13: Almoxarifado
... A1001: =B1001&C1001 -> 7018725 | B1001: 701 | C1001: 8725 | D1001: 50002 | E1001: YOLE MACEDO CAVALCANTE | F1001: 41800 | G1001: 1 | H1001: 9579.405 | I1001: TECNICO ANALISES CLINICAS I | J1001: Coleta
