Workbook

Sheet Ini
C2: PLANILHA DE
C3: INDICADORES DE RH 3.0
C4: Seja bem-vindo(a). Com esta planilha, é possível ter o controle sobre os indicadores de RH da empresa. Tenha indicadores importantes para tomar decisões acertivas direcionadas.
C5: IMPORTANTE: LEIA OS PASSOS E ENTENDA A PLANILHA
C6: Dúvidas? Clique nos Links presentes em toda a planilha para ver vídeos explicativos sobre o método, preenchimento e análise de cada aba!
C7: Passo 1 | D7: CADASTRO
C8: Inicialmente, você irá realizar alguns cadastros necessários para serem utilizados posteriormente nas etapas de lançamentos.
C9: 1.1. Cadastros iniciais: Cadastrar o nome da empresa e o ano de vigência para a planilha apurar os resultados consolidados.
C10: 1.2. Cadastro de cargos: Cadastrar os cargos da empresa e classificá-los em grupos para posteriormente serem analisados.
C11: 1.3. Funcionários: Registrar funcionários com alguns dados necessários para análise posterior.
C12: 1.4. Outros cadastros: Esta parte já vem toda preenchida com informações padronizadas, mas é possível alterá-las caso seja necessário.
C14: Passo 2 | D14: LANÇAMENTOS
C15: Nesta etapa você irá realizar os lançamentos da movimentação da sua equipe e o registro das receitas e custos de RH.
C16: 2.1. Receitas e custos: Registrar a receita bruta da sua empresa, os custos de RH e os custos dos benefícios oferecidos aos seus funcionários.
C17: 2.2. Férias e licenças: Lançar as movimentações de férias, licenças e faltas não justificadas.
C18: 2.3. Demissões: Lançar as demissões e classificá-las (motivo da demissão).
C19: 2.4. Treinamentos: Registrar os treinamentos oferecidos à equipe, carga horária, custo e número de funcionários participantes.
C20: 2.5. Promoções: Registrar as mudanças de cargo oferecidas aos funcionários.
C22: Passo 3 | D22: RESULTADOS CONSOLIDADOS
C23: Aqui você poderá conferir os resultados consolidados, calculados automaticamente com base nas informações fornecidas anteriormente.
C24: 3.1. Geral: Visão geral de alguns indicadores calculados com base nos registros feitos anteriormente.
C25: 3.2. Rotatividade: Visão mensal da análise da rotatividade da equipe e a taxa de turnover.
C26: 3.3. Perfil da equipe: Visão mensal da sua equipe agrupada de acordo com os cadastros realizados anteriormente.
C27: 3.4. Eventos de RH: Visão mensal dos treinamentos oferecidos à equipe, das promoções, férias e licenças.
C28: 3.5. Receitas e custos: Visão mensal das receitas, despesas com benefícios oferecidos e custos de RH.
C30: Passo 4 | D30: GRÁFICOS
C31: Faça uma análise gráfica de forma rápida e eficiente dos resultados da sua planilha.
C33: Passo 5 | D33: ALERTAS E DICAS
C34: Esta planilha avaliará todos os dados preenchidos por você e retornará com dicas importantes para sua análise. Este retorno será exibido através da análise da performance mensal de alguns pontos específicos.
C36: Passo 6 | D36: RELATÓRIO PARA IMPRESSÃO
C37: Imprima o relatório dos seus indicadores. Apenas o que importa, com formatação econômica para gastar menos tinta e ter um melhor aproveitamento do papel.

Sheet Cad
C1: 1. CADASTRO | U1: Operacional
U2: Gerencial
U3: Diretoria
C6: Cadastro de cargos
C7: Nome do cargo | D7: Tipo do cargo | E7: Salário
C8: Designer I | D8: Operacional | E8: 1500
C9: Designer II | D9: Operacional | E9: 2000
C10: Designer III | D10: Operacional | E10: 2500
C11: Dir de Arte | D11: Gerencial | E11: 3000
C12: Dir de Criação | D12: Diretoria | E12: 3500
C13: Sócio | D13: Diretoria | E13: 5000

Sheet Cad_Inicial
C1: 1. CADASTRO
C6: Cadastros iniciais
C7: Nome da empresa | D7: LUZ Planilhas Empresariais
C8: Ano de vigência da planilha | D8: 2015

Sheet Lanç
C1: 2. LANÇAMENTOS | T1: =IF(ISERROR(IF(Cad_Outros!C9="","",Cad_Outros!C9)),"",IF(Cad_Outros!C9="","",Cad_Outros!C9)) -> Pedido de demissão | U1: =IF(ISERROR(IF(Cad_Func!C8="","",Cad_Func!C8)),"",IF(Cad_Func!C8="","",Cad_Func!C8)) -> ze 1
T2: =IF(ISERROR(IF(Cad_Outros!C10="","",Cad_Outros!C10)),"",IF(Cad_Outros!C10="","",Cad_Outros!C10)) -> Dispensa sem justa causa | U2: =IF(ISERROR(IF(Cad_Func!C9="","",Cad_Func!C9)),"",IF(Cad_Func!C9="","",Cad_Func!C9)) -> ze 2
T3: =IF(ISERROR(IF(Cad_Outros!C11="","",Cad_Outros!C11)),"",IF(Cad_Outros!C11="","",Cad_Outros!C11)) -> Dispensa com justa causa | U3: =IF(ISERROR(IF(Cad_Func!C10="","",Cad_Func!C10)),"",IF(Cad_Func!C10="","",Cad_Func!C10)) -> ze 3
T5: =IF(ISERROR(IF(Cad_Outros!C12="","",Cad_Outros!C12)),"",IF(Cad_Outros!C12="","",Cad_Outros!C12)) -> Término de contrato de experiência | U5: =IF(ISERROR(IF(Cad_Func!C11="","",Cad_Func!C11)),"",IF(Cad_Func!C11="","",Cad_Func!C11)) -> ze 4
C6: Registro das demissões | T6: =IF(ISERROR(IF(Cad_Outros!C13="","",Cad_Outros!C13)),"",IF(Cad_Outros!C13="","",Cad_Outros!C13)) -> Rescisão antecipada do contrato de experiência por iniciativa do empregador | U6: =IF(ISERROR(IF(Cad_Func!C12="","",Cad_Func!C12)),"",IF(Cad_Func!C12="","",Cad_Func!C12)) -> ze 5
C7: Nome do funcionário | D7: Data de demissão | E7: Motivo da demissão | F7: Observações | T7: =IF(ISERROR(IF(Cad_Outros!C14="","",Cad_Outros!C14)),"",IF(Cad_Outros!C14="","",Cad_Outros!C14)) -> Rescisão antecipada do contrato de experiência por iniciativa do empregado | U7: =IF(ISERROR(IF(Cad_Func!C13="","",Cad_Func!C13)),"",IF(Cad_Func!C13="","",Cad_Func!C13)) -> ze 6
C8: ze 1 | D8: 42075 | E8: Pedido de demissão | T8: =IF(ISERROR(IF(Cad_Outros!C15="","",Cad_Outros!C15)),"",IF(Cad_Outros!C15="","",Cad_Outros!C15)) -> Falecimento do empregado | U8: =IF(ISERROR(IF(Cad_Func!C14="","",Cad_Func!C14)),"",IF(Cad_Func!C14="","",Cad_Func!C14)) -> ze 7
T9: =IF(ISERROR(IF(Cad_Outros!C16="","",Cad_Outros!C16)),"",IF(Cad_Outros!C16="","",Cad_Outros!C16)) -> Outro | U9: =IF(ISERROR(IF(Cad_Func!C15="","",Cad_Func!C15)),"",IF(Cad_Func!C15="","",Cad_Func!C15)) -> ze 8
U10: =IF(ISERROR(IF(Cad_Func!C16="","",Cad_Func!C16)),"",IF(Cad_Func!C16="","",Cad_Func!C16)) -> ze 9
U11: =IF(ISERROR(IF(Cad_Func!C17="","",Cad_Func!C17)),"",IF(Cad_Func!C17="","",Cad_Func!C17)) -> ze 10
U12: =IF(ISERROR(IF(Cad_Func!C18="","",Cad_Func!C18)),"",IF(Cad_Func!C18="","",Cad_Func!C18)) -> ze 11
U13: =IF(ISERROR(IF(Cad_Func!C19="","",Cad_Func!C19)),"",IF(Cad_Func!C19="","",Cad_Func!C19)) -> ze 12
U14: =IF(ISERROR(IF(Cad_Func!C20="","",Cad_Func!C20)),"",IF(Cad_Func!C20="","",Cad_Func!C20))
U15: =IF(ISERROR(IF(Cad_Func!C21="","",Cad_Func!C21)),"",IF(Cad_Func!C21="","",Cad_Func!C21))
U16: =IF(ISERROR(IF(Cad_Func!C22="","",Cad_Func!C22)),"",IF(Cad_Func!C22="","",Cad_Func!C22))
U17: =IF(ISERROR(IF(Cad_Func!C23="","",Cad_Func!C23)),"",IF(Cad_Func!C23="","",Cad_Func!C23))
U18: =IF(ISERROR(IF(Cad_Func!C24="","",Cad_Func!C24)),"",IF(Cad_Func!C24="","",Cad_Func!C24))
U19: =IF(ISERROR(IF(Cad_Func!C25="","",Cad_Func!C25)),"",IF(Cad_Func!C25="","",Cad_Func!C25))
U20: =IF(ISERROR(IF(Cad_Func!C26="","",Cad_Func!C26)),"",IF(Cad_Func!C26="","",Cad_Func!C26))
U21: =IF(ISERROR(IF(Cad_Func!C27="","",Cad_Func!C27)),"",IF(Cad_Func!C27="","",Cad_Func!C27))
... U202: =IF(ISERROR(IF(Cad_Func!C208="","",Cad_Func!C208)),"",IF(Cad_Func!C208="","",Cad_Func!C208))

Sheet RC
C1: 3. RESULTADOS CONSOLIDADOS
C6: ="Indicadores de rotatividade para "&Cad_Inicial!$D$8 -> Indicadores de rotatividade para 2015 | F6: Resultado
C7: Média de permanência de funcionários na empresa | F7: =IF(ISERROR(ROUND(AVERAGEIF(Cad_Func!$U$8:$U$208,"SIM",Cad_Func!$T$8:$T$208),0)&" meses"),"",ROUND(AVERAGEIF(Cad_Func!$U$8:$U$208,"SIM",Cad_Func!$T$8:$T$208),0)&" meses") -> 86 meses
C8: ="Admissões em "&Cad_Inicial!$D$8 -> Admissões em 2015 | F8: =IF(ISERROR(COUNTIF(Cad_Func!$W$8:$W$208,Cad_Inicial!$D$8)),"",COUNTIF(Cad_Func!$W$8:$W$208,Cad_Inicial!$D$8)) -> 3
C9: ="Demissões em "&Cad_Inicial!$D$8 -> Demissões em 2015 | F9: =IF(ISERROR(COUNTIF(Cad_Func!$Y$8:$Y$208,Cad_Inicial!$D$8)),"",COUNTIF(Cad_Func!$Y$8:$Y$208,Cad_Inicial!$D$8)) -> 1
C10: ="Total de funcionários em "&Cad_Inicial!$D$8 -> Total de funcionários em 2015 | F10: =IF(ISERROR(SUM(Cad_Func!$AA$8:$AA$208)),"",SUM(Cad_Func!$AA$8:$AA$208)) -> 11
C11: Índice de aprovação após período de experiência | F11: =IF(ISERROR(COUNTIF(Cad_Func!$V$8:$V$208,"SIM")/COUNTIF(Cad_Func!$W$8:$W$208,Cad_Inicial!$D$8)),"",COUNTIF(Cad_Func!$V$8:$V$208,"SIM")/COUNTIF(Cad_Func!$W$8:$W$208,Cad_Inicial!$D$8)) -> 1
C12: Índice de Turnover (rotatividade) | F12: =IF(ISERROR((F8+F9)/2/F10),"",(F8+F9)/2/F10) -> 0.18181818
C14: ="Indicadores de treinamento para "&Cad_Inicial!$D$8 -> Indicadores de treinamento para 2015 | F14: Resultado
C15: Total de horas de treinamento | F15: =IF(ISERROR(SUMIF(Lanç_Terinamentos!$U$8:$U$2008,Cad_Inicial!$D$8,Lanç_Terinamentos!$D$8:$D$2008)&" horas"),"",SUMIF(Lanç_Terinamentos!$U$8:$U$2008,Cad_Inicial!$D$8,Lanç_Terinamentos!$D$8:$D$2008)&" horas") -> 140 horas
C16: Média de horas de treinamento por funcionário treinado | F16: =IF(ISERROR(ROUND(SUMIF(Lanç_Terinamentos!$U$8:$U$2008,Cad_Inicial!$D$8,Lanç_Terinamentos!$D$8:$D$2008)/SUMIF(Lanç_Terinamentos!$U$8:$U$2008,Cad_Inicial!$D$8,Lanç_Terinamentos!$G$8:$G$2008),0)&" horas"),"",ROUND(SUMIF(Lanç_Terinamentos!$U$8:$U$2008,Cad_Inicial!$D$8,Lanç_Terinamentos!$D$8:$D$2008)/SUMIF(Lanç_Terinamentos!$U$8:$U$2008,Cad_Inicial!$D$8,Lanç_Terinamentos!$G$8:$G$2008),0)&" horas") -> 18 horas
C17: Número de funcionários treinados | F17: =IF(ISERROR(SUMIF(Lanç_Terinamentos!$U$8:$U$2008,Cad_Inicial!$D$8,Lanç_Terinamentos!$G$8:$G$2008)&" funcionários"),"",SUMIF(Lanç_Terinamentos!$U$8:$U$2008,Cad_Inicial!$D$8,Lanç_Terinamentos!$G$8:$G$2008)&" funcionários") -> 8 funcionários
C19: ="Custos para "&Cad_Inicial!$D$8 -> Custos para 2015 | F19: Resultado
C20: Custo total com hora extra | F20: =IF(ISERROR(SUMIF(Lanç_Receitas!$C$9:$C$20,"Hora extra",Lanç_Receitas!$P$9:$P$20)),"",SUMIF(Lanç_Receitas!$C$9:$C$20,"Hora extra",Lanç_Receitas!$P$9:$P$20)) -> 3012
C21: Custo total com folha de pagamento (benefícios + custos) | F21: =IF(ISERROR(SUM(Lanç_Receitas!$P$9:$P$20,Lanç_Receitas!$P$22:$P$33)),"",SUM(Lanç_Receitas!$P$9:$P$20,Lanç_Receitas!$P$22:$P$33)) -> 315142
C22: % do custo total de treinamentos sobre o total da folha de pagamento | F22: =IF(ISERROR(SUMIF(Lanç_Terinamentos!$U$8:$U$2008,Cad_Inicial!$D$8,Lanç_Terinamentos!$Q$8:$Q$2008)/F21),"",SUMIF(Lanç_Terinamentos!$U$8:$U$2008,Cad_Inicial!$D$8,Lanç_Terinamentos!$Q$8:$Q$2008)/F21) -> 0
C23: Custo médio por funcionário treinado | F23: =IF(ISERROR(SUMIF(Lanç_Terinamentos!$U$8:$U$2008,Cad_Inicial!$D$8,Lanç_Terinamentos!$Q$8:$Q$2008)/SUMIF(Lanç_Terinamentos!$U$8:$U$2008,Cad_Inicial!$D$8,Lanç_Terinamentos!$G$8:$G$2008)),"",SUMIF(Lanç_Terinamentos!$U$8:$U$2008,Cad_Inicial!$D$8,Lanç_Terinamentos!$Q$8:$Q$2008)/SUMIF(Lanç_Terinamentos!$U$8:$U$2008,Cad_Inicial!$D$8,Lanç_Terinamentos!$G$8:$G$2008)) -> 0
C24: % dos benefícios sobre a folha de pagamento | F24: =F25/F21 -> 0.066655666
C25: Custo dos benefícios sobre a folha de pagamento | F25: =IF(ISERROR(SUM(Lanç_Receitas!$P$22:$P$33)),"",SUM(Lanç_Receitas!$P$22:$P$33)) -> 21006
C26: Custo médio dos benefícios para cada funcionário | F26: =IF(ISERROR(F25/F10),"",F25/F10) -> 1909.6364
C27: Receita gerada por cada funcionário | F27: =IF(ISERROR(Lanç_Receitas!P7/F10),"",Lanç_Receitas!P7/F10) -> 163636.91
C28: Custo médio da folha gerado por cada funcionário | F28: =IF(ISERROR(SUM(Lanç_Receitas!$P$9:$P$20)/F10),"",SUM(Lanç_Receitas!$P$9:$P$20)/F10) -> 26739.636

Sheet Graf
C1: 4. GRÁFICOS
C6: 1. Rotatividade
C17: 1.1. Motivos de desligamento | J17: 1.2. Funcionários no fim do mês
C32: 2.Equipe
C33: 2.1. Nível de escolaridade | J33: 2.1. Tipos de cargos
C44: 2.3. Sexo | J44: 2.4. Faixa etária
C52: Total no fim do ano | E52: Total no fim do ano
C53: ='Graf Aux'!N38&" homens" -> 7 homens | E53: ='Graf Aux'!N39&" mulheres" -> 4 mulheres
C55: 3.Treinamentos
C66: 4. Receitas e Custos
C74: Total no fim do ano | J74: Total no fim do ano
C75: ='Graf Aux'!N49 -> 163636.91 | J75: ='Graf Aux'!N50 -> 29513
C77: 4.1. Custos | J77: 4.2. Benefícios

Sheet Graf Aux
A1: Ano | B1: =Cad_Inicial!$D$8 -> 2015
B2: 1 | C2: 2 | D2: 3 | E2: 4 | F2: 5 | G2: 6 | H2: 7 | I2: 8 | J2: 9 | K2: 10 | L2: 11 | M2: 12
A3: ="<"&B1 -> <2015 | B3: ="<="&B2 -> <=1 | C3: ="<="&C2 -> <=2 | D3: ="<="&D2 -> <=3 | E3: ="<="&E2 -> <=4 | F3: ="<="&F2 -> <=5 | G3: ="<="&G2 -> <=6 | H3: ="<="&H2 -> <=7 | I3: ="<="&I2 -> <=8 | ... M3: ="<="&M2 -> <=12
B4: =">="&B2 -> >=1 | C4: =">="&C2 -> >=2 | D4: =">="&D2 -> >=3 | E4: =">="&E2 -> >=4 | F4: =">="&F2 -> >=5 | G4: =">="&G2 -> >=6 | H4: =">="&H2 -> >=7 | I4: =">="&I2 -> >=8 | ... M4: =">="&M2 -> >=12
A5: Indicador | B5: Jan | C5: Fev | D5: Mar | E5: Abr | F5: Mai | G5: Jun | H5: Jul | I5: Ago | J5: Set | K5: Out | L5: Nov | M5: Dez
A6: Admissões | B6: =RC_Rotatividade!E9 -> 1 | C6: =RC_Rotatividade!F9 -> 2 | D6: =RC_Rotatividade!G9 -> 0 | E6: =RC_Rotatividade!H9 -> 0 | F6: =RC_Rotatividade!I9 -> 0 | G6: =RC_Rotatividade!J9 -> 0 | H6: =RC_Rotatividade!K9 -> 0 | I6: =RC_Rotatividade!L9 -> 0 | ... M6: =RC_Rotatividade!P9 -> 0
A7: Demissões | B7: =RC_Rotatividade!E10 -> 0 | C7: =RC_Rotatividade!F10 -> 0 | D7: =RC_Rotatividade!G10 -> 1 | E7: =RC_Rotatividade!H10 -> 0 | F7: =RC_Rotatividade!I10 -> 0 | G7: =RC_Rotatividade!J10 -> 0 | H7: =RC_Rotatividade!K10 -> 0 | I7: =RC_Rotatividade!L10 -> 0 | ... M7: =RC_Rotatividade!P10 -> 0
A8: Funcionários no início do mês | B8: =RC_Rotatividade!E12 -> 9 | C8: =RC_Rotatividade!F12 -> 10 | D8: =RC_Rotatividade!G12 -> 12 | E8: =RC_Rotatividade!H12 -> 11 | F8: =RC_Rotatividade!I12 -> 11 | G8: =RC_Rotatividade!J12 -> 11 | H8: =RC_Rotatividade!K12 -> 11 | I8: =RC_Rotatividade!L12 -> 11 | ... M8: =RC_Rotatividade!P12 -> 11
A9: Funcionários no fim do mês | B9: =RC_Rotatividade!E13 -> 10 | C9: =RC_Rotatividade!F13 -> 12 | D9: =RC_Rotatividade!G13 -> 11 | E9: =RC_Rotatividade!H13 -> 11 | F9: =RC_Rotatividade!I13 -> 11 | G9: =RC_Rotatividade!J13 -> 11 | H9: =RC_Rotatividade!K13 -> 11 | I9: =RC_Rotatividade!L13 -> 11 | ... M9: =RC_Rotatividade!P13 -> 11 | N9: =IF(ISERROR(IF(C9="",B9,IF(D9="",C9,IF(E9="",D9,IF(F9="",E9,IF(G9="",F9,IF(H9="",G9,IF(I9="",H9,IF(J9="",I9,IF(K9="",J9,IF(L9="",K9,IF(M9="",L9,M9)))))))))))),"",IF(C9="",B9,IF(D9="",C9,IF(E9="",D9,IF(F9="",E9,IF(G9="",F9,IF(H9="",G9,IF(I9="",H9,IF(J9="",I9,IF(K9="",J9,IF(L9="",K9,IF(M9="",L9,M9)))))))))))) -> 11
A10: Turnover | B10: =RC_Rotatividade!E14 -> 0.05 | C10: =RC_Rotatividade!F14 -> 0.083333333 | D10: =RC_Rotatividade!G14 -> 0.045454545 | E10: =RC_Rotatividade!H14 -> 0 | F10: =RC_Rotatividade!I14 -> 0 | G10: =RC_Rotatividade!J14 -> 0 | H10: =RC_Rotatividade!K14 -> 0 | I10: =RC_Rotatividade!L14 -> 0 | ... M10: =RC_Rotatividade!P14 -> 0
A12: Indicador | B12: Jan | C12: Fev | D12: Mar | E12: Abr | F12: Mai | G12: Jun | H12: Jul | I12: Ago | J12: Set | K12: Out | L12: Nov | M12: Dez | N12: Total
A13: Pedido de demissão | B13: =RC_Rotatividade!E16 -> 0 | C13: =RC_Rotatividade!F16 -> 0 | D13: =RC_Rotatividade!G16 -> 1 | E13: =RC_Rotatividade!H16 -> 0 | F13: =RC_Rotatividade!I16 -> 0 | G13: =RC_Rotatividade!J16 -> 0 | H13: =RC_Rotatividade!K16 -> 0 | I13: =RC_Rotatividade!L16 -> 0 | ... M13: =RC_Rotatividade!P16 -> 0 | N13: =SUM(B13:M13) -> 1
A14: Dispensa sem justa causa | B14: =RC_Rotatividade!E17 -> 0 | C14: =RC_Rotatividade!F17 -> 0 | D14: =RC_Rotatividade!G17 -> 0 | E14: =RC_Rotatividade!H17 -> 0 | F14: =RC_Rotatividade!I17 -> 0 | G14: =RC_Rotatividade!J17 -> 0 | H14: =RC_Rotatividade!K17 -> 0 | I14: =RC_Rotatividade!L17 -> 0 | ... M14: =RC_Rotatividade!P17 -> 0 | N14: =SUM(B14:M14) -> 0
A15: Dispensa com justa causa | B15: =RC_Rotatividade!E18 -> 0 | C15: =RC_Rotatividade!F18 -> 0 | D15: =RC_Rotatividade!G18 -> 0 | E15: =RC_Rotatividade!H18 -> 0 | F15: =RC_Rotatividade!I18 -> 0 | G15: =RC_Rotatividade!J18 -> 0 | H15: =RC_Rotatividade!K18 -> 0 | I15: =RC_Rotatividade!L18 -> 0 | ... M15: =RC_Rotatividade!P18 -> 0 | N15: =SUM(B15:M15) -> 0
A16: Término de contrato de experiêcia | B16: =RC_Rotatividade!E19 -> 0 | C16: =RC_Rotatividade!F19 -> 0 | D16: =RC_Rotatividade!G19 -> 0 | E16: =RC_Rotatividade!H19 -> 0 | F16: =RC_Rotatividade!I19 -> 0 | G16: =RC_Rotatividade!J19 -> 0 | H16: =RC_Rotatividade!K19 -> 0 | I16: =RC_Rotatividade!L19 -> 0 | ... M16: =RC_Rotatividade!P19 -> 0 | N16: =SUM(B16:M16) -> 0
A17: Rescisão antecipada do contrato de experiêcia por iniciativa do empregador | B17: =RC_Rotatividade!E20 -> 0 | C17: =RC_Rotatividade!F20 -> 0 | D17: =RC_Rotatividade!G20 -> 0 | E17: =RC_Rotatividade!H20 -> 0 | F17: =RC_Rotatividade!I20 -> 0 | G17: =RC_Rotatividade!J20 -> 0 | H17: =RC_Rotatividade!K20 -> 0 | I17: =RC_Rotatividade!L20 -> 0 | ... M17: =RC_Rotatividade!P20 -> 0 | N17: =SUM(B17:M17) -> 0
A18: Rescisão antecipada do contrato de experiêcia por iniciativa do empregado | B18: =RC_Rotatividade!E21 -> 0 | C18: =RC_Rotatividade!F21 -> 0 | D18: =RC_Rotatividade!G21 -> 0 | E18: =RC_Rotatividade!H21 -> 0 | F18: =RC_Rotatividade!I21 -> 0 | G18: =RC_Rotatividade!J21 -> 0 | H18: =RC_Rotatividade!K21 -> 0 | I18: =RC_Rotatividade!L21 -> 0 | ... M18: =RC_Rotatividade!P21 -> 0 | N18: =SUM(B18:M18) -> 0
A19: Falecimento do empregado | B19: =RC_Rotatividade!E22 -> 0 | C19: =RC_Rotatividade!F22 -> 0 | D19: =RC_Rotatividade!G22 -> 0 | E19: =RC_Rotatividade!H22 -> 0 | F19: =RC_Rotatividade!I22 -> 0 | G19: =RC_Rotatividade!J22 -> 0 | H19: =RC_Rotatividade!K22 -> 0 | I19: =RC_Rotatividade!L22 -> 0 | ... M19: =RC_Rotatividade!P22 -> 0 | N19: =SUM(B19:M19) -> 0
A20: Outro | B20: =RC_Rotatividade!E23 -> 0 | C20: =RC_Rotatividade!F23 -> 0 | D20: =RC_Rotatividade!G23 -> 0 | E20: =RC_Rotatividade!H23 -> 0 | F20: =RC_Rotatividade!I23 -> 0 | G20: =RC_Rotatividade!J23 -> 0 | H20: =RC_Rotatividade!K23 -> 0 | I20: =RC_Rotatividade!L23 -> 0 | ... M20: =RC_Rotatividade!P23 -> 0 | N20: =SUM(B20:M20) -> 0
A22: Indicador | B22: Jan | C22: Fev | D22: Mar | E22: Abr | F22: Mai | G22: Jun | H22: Jul | I22: Ago | J22: Set | K22: Out | L22: Nov | M22: Dez | N22: Total
A23: =RC_Perfil!C11 -> Ensino fundamental | B23: =RC_Perfil!E11 -> 2 | C23: =RC_Perfil!F11 -> 2 | D23: =RC_Perfil!G11 -> 1 | E23: =RC_Perfil!H11 -> 1 | F23: =RC_Perfil!I11 -> 1 | G23: =RC_Perfil!J11 -> 1 | H23: =RC_Perfil!K11 -> 1 | I23: =RC_Perfil!L11 -> 1 | ... M23: =RC_Perfil!P11 -> 1 | N23: =SUM(B23:M23) -> 14
A24: =RC_Perfil!C12 -> Ensino médio | B24: =RC_Perfil!E12 -> 0 | C24: =RC_Perfil!F12 -> 0 | D24: =RC_Perfil!G12 -> 0 | E24: =RC_Perfil!H12 -> 0 | F24: =RC_Perfil!I12 -> 0 | G24: =RC_Perfil!J12 -> 0 | H24: =RC_Perfil!K12 -> 0 | I24: =RC_Perfil!L12 -> 0 | ... M24: =RC_Perfil!P12 -> 0 | N24: =SUM(B24:M24) -> 0
A25: =RC_Perfil!C13 -> Superior completo | B25: =RC_Perfil!E13 -> 4 | C25: =RC_Perfil!F13 -> 6 | D25: =RC_Perfil!G13 -> 6 | E25: =RC_Perfil!H13 -> 6 | F25: =RC_Perfil!I13 -> 6 | G25: =RC_Perfil!J13 -> 6 | H25: =RC_Perfil!K13 -> 6 | I25: =RC_Perfil!L13 -> 6 | ... M25: =RC_Perfil!P13 -> 6 | N25: =SUM(B25:M25) -> 70
A26: =RC_Perfil!C14 -> Superior incompleto | B26: =RC_Perfil!E14 -> 2 | C26: =RC_Perfil!F14 -> 2 | D26: =RC_Perfil!G14 -> 2 | E26: =RC_Perfil!H14 -> 2 | F26: =RC_Perfil!I14 -> 2 | G26: =RC_Perfil!J14 -> 2 | H26: =RC_Perfil!K14 -> 2 | I26: =RC_Perfil!L14 -> 2 | ... M26: =RC_Perfil!P14 -> 2 | N26: =SUM(B26:M26) -> 24
A27: =RC_Perfil!C15 -> Pós-graduação completa | B27: =RC_Perfil!E15 -> 2 | C27: =RC_Perfil!F15 -> 2 | D27: =RC_Perfil!G15 -> 2 | E27: =RC_Perfil!H15 -> 2 | F27: =RC_Perfil!I15 -> 2 | G27: =RC_Perfil!J15 -> 2 | H27: =RC_Perfil!K15 -> 2 | I27: =RC_Perfil!L15 -> 2 | ... M27: =RC_Perfil!P15 -> 2 | N27: =SUM(B27:M27) -> 24
A28: =RC_Perfil!C16 -> Pós-graduação incompleta | B28: =RC_Perfil!E16 -> 0 | C28: =RC_Perfil!F16 -> 0 | D28: =RC_Perfil!G16 -> 0 | E28: =RC_Perfil!H16 -> 0 | F28: =RC_Perfil!I16 -> 0 | G28: =RC_Perfil!J16 -> 0 | H28: =RC_Perfil!K16 -> 0 | I28: =RC_Perfil!L16 -> 0 | ... M28: =RC_Perfil!P16 -> 0 | N28: =SUM(B28:M28) -> 0
A29: =RC_Perfil!C17 -> Mestre | B29: =RC_Perfil!E17 -> 0 | C29: =RC_Perfil!F17 -> 0 | D29: =RC_Perfil!G17 -> 0 | E29: =RC_Perfil!H17 -> 0 | F29: =RC_Perfil!I17 -> 0 | G29: =RC_Perfil!J17 -> 0 | H29: =RC_Perfil!K17 -> 0 | I29: =RC_Perfil!L17 -> 0 | ... M29: =RC_Perfil!P17 -> 0 | N29: =SUM(B29:M29) -> 0
A30: =RC_Perfil!C18 -> Doutor | B30: =RC_Perfil!E18 -> 0 | C30: =RC_Perfil!F18 -> 0 | D30: =RC_Perfil!G18 -> 0 | E30: =RC_Perfil!H18 -> 0 | F30: =RC_Perfil!I18 -> 0 | G30: =RC_Perfil!J18 -> 0 | H30: =RC_Perfil!K18 -> 0 | I30: =RC_Perfil!L18 -> 0 | ... M30: =RC_Perfil!P18 -> 0 | N30: =SUM(B30:M30) -> 0
A32: Indicador | B32: Jan | C32: Fev | D32: Mar | E32: Abr | F32: Mai | G32: Jun | H32: Jul | I32: Ago | J32: Set | K32: Out | L32: Nov | M32: Dez | N32: Total
A33: Operacional | B33: =RC_Perfil!E20 -> 6 | C33: =RC_Perfil!F20 -> 7 | D33: =RC_Perfil!G20 -> 6 | E33: =RC_Perfil!H20 -> 6 | F33: =RC_Perfil!I20 -> 6 | G33: =RC_Perfil!J20 -> 6 | H33: =RC_Perfil!K20 -> 6 | I33: =RC_Perfil!L20 -> 6 | ... M33: =RC_Perfil!P20 -> 6 | N33: =SUM(B33:M33) -> 73
A34: Gerencial | B34: =RC_Perfil!E21 -> 1 | C34: =RC_Perfil!F21 -> 1 | D34: =RC_Perfil!G21 -> 1 | E34: =RC_Perfil!H21 -> 1 | F34: =RC_Perfil!I21 -> 1 | G34: =RC_Perfil!J21 -> 1 | H34: =RC_Perfil!K21 -> 1 | I34: =RC_Perfil!L21 -> 1 | ... M34: =RC_Perfil!P21 -> 1 | N34: =SUM(B34:M34) -> 12
A35: Diretoria | B35: =RC_Perfil!E22 -> 3 | C35: =RC_Perfil!F22 -> 4 | D35: =RC_Perfil!G22 -> 4 | E35: =RC_Perfil!H22 -> 4 | F35: =RC_Perfil!I22 -> 4 | G35: =RC_Perfil!J22 -> 4 | H35: =RC_Perfil!K22 -> 4 | I35: =RC_Perfil!L22 -> 4 | ... M35: =RC_Perfil!P22 -> 4 | N35: =SUM(B35:M35) -> 47
A37: Indicador | B37: Jan | C37: Fev | D37: Mar | E37: Abr | F37: Mai | G37: Jun | H37: Jul | I37: Ago | J37: Set | K37: Out | L37: Nov | M37: Dez | N37: Total
A38: Masculino | B38: =RC_Perfil!E24 -> 7 | C38: =RC_Perfil!F24 -> 8 | D38: =RC_Perfil!G24 -> 7 | E38: =RC_Perfil!H24 -> 7 | F38: =RC_Perfil!I24 -> 7 | G38: =RC_Perfil!J24 -> 7 | H38: =RC_Perfil!K24 -> 7 | I38: =RC_Perfil!L24 -> 7 | ... M38: =RC_Perfil!P24 -> 7 | N38: =IF(ISERROR(IF(C38="",B38,IF(D38="",C38,IF(E38="",D38,IF(F38="",E38,IF(G38="",F38,IF(H38="",G38,IF(I38="",H38,IF(J38="",I38,IF(K38="",J38,IF(L38="",K38,IF(M38="",L38,M38)))))))))))),"",IF(C38="",B38,IF(D38="",C38,IF(E38="",D38,IF(F38="",E38,IF(G38="",F38,IF(H38="",G38,IF(I38="",H38,IF(J38="",I38,IF(K38="",J38,IF(L38="",K38,IF(M38="",L38,M38)))))))))))) -> 7
A39: Feminino | B39: =RC_Perfil!E25 -> 3 | C39: =RC_Perfil!F25 -> 4 | D39: =RC_Perfil!G25 -> 4 | E39: =RC_Perfil!H25 -> 4 | F39: =RC_Perfil!I25 -> 4 | G39: =RC_Perfil!J25 -> 4 | H39: =RC_Perfil!K25 -> 4 | I39: =RC_Perfil!L25 -> 4 | ... M39: =RC_Perfil!P25 -> 4 | N39: =IF(ISERROR(IF(C39="",B39,IF(D39="",C39,IF(E39="",D39,IF(F39="",E39,IF(G39="",F39,IF(H39="",G39,IF(I39="",H39,IF(J39="",I39,IF(K39="",J39,IF(L39="",K39,IF(M39="",L39,M39)))))))))))),"",IF(C39="",B39,IF(D39="",C39,IF(E39="",D39,IF(F39="",E39,IF(G39="",F39,IF(H39="",G39,IF(I39="",H39,IF(J39="",I39,IF(K39="",J39,IF(L39="",K39,IF(M39="",L39,M39)))))))))))) -> 4
A41: Indicador | B41: Jan | C41: Fev | D41: Mar | E41: Abr | F41: Mai | G41: Jun | H41: Jul | I41: Ago | J41: Set | K41: Out | L41: Nov | M41: Dez | N41: Total
A42: Custo total | B42: =RC_Eventos!E14 -> 900 | C42: =RC_Eventos!F14 -> 501 | D42: =RC_Eventos!G14 -> 600 | E42: =RC_Eventos!H14 -> 400 | F42: =RC_Eventos!I14 -> 100 | G42: =RC_Eventos!J14 -> 0 | H42: =RC_Eventos!K14 -> 0 | I42: =RC_Eventos!L14 -> 0 | ... M42: =RC_Eventos!P14 -> 0 | N42: =SUM(B42:M42) -> 2501
A43: Horas totais | B43: =RC_Eventos!E15 -> 0 | C43: =RC_Eventos!F15 -> 20 | D43: =RC_Eventos!G15 -> 140 | E43: =RC_Eventos!H15 -> 120 | F43: =RC_Eventos!I15 -> 0 | G43: =RC_Eventos!J15 -> 0 | H43: =RC_Eventos!K15 -> 0 | I43: =RC_Eventos!L15 -> 0 | ... M43: =RC_Eventos!P15 -> 0 | N43: =SUM(B43:M43) -> 280
A44: Funcionários em treinamento | B44: =RC_Eventos!E13 -> 0 | C44: =RC_Eventos!F13 -> 3 | D44: =RC_Eventos!G13 -> 8 | E44: =RC_Eventos!H13 -> 5 | F44: =RC_Eventos!I13 -> 0 | G44: =RC_Eventos!J13 -> 0 | H44: =RC_Eventos!K13 -> 0 | I44: =RC_Eventos!L13 -> 0 | ... M44: =RC_Eventos!P13 -> 0 | N44: =IF(ISERROR(SUMIFS(Lanç_Terinamentos!$G$8:$G$2008,Lanç_Terinamentos!$X$8:$X$2008,$B$1)),"",SUMIFS(Lanç_Terinamentos!$G$8:$G$2008,Lanç_Terinamentos!$X$8:$X$2008,$B$1)) -> 8
A46: Indicador | B46: Jan | C46: Fev | D46: Mar | E46: Abr | F46: Mai | G46: Jun | H46: Jul | I46: Ago | J46: Set | K46: Out | L46: Nov | M46: Dez | N46: Total
...

Sheet AD
C1: 5. ALERTAS E DICAS | T1: Janeiro | U1: 1
T2: Fevereiro | U2: 2
T3: Março | U3: 3
T5: Abril | U5: 4
C6: Indique o mês | D6: Fevereiro | I6: =VLOOKUP(D6,$T$1:$U$13,2,0) -> 2 | T6: Maio | U6: 5
T7: Junho | U7: 6
C8: Alertas e dicas sobre os pontos analisados com base nas informações lançadas | T8: Julho | U8: 7
C9: Turnover | E9: Treinamentos | G9: Retorno | T9: Agosto | U9: 8
C10: =IF(ISERROR(IF(D17="",D20,IF(D17>0,D18,D19))),"",IF(D17="",D20,IF(D17>0,D18,D19))) -> A Taxa de Turnover aumentou em relação ao mês anterior em 67%. O que houve para que esta taxa tenha aumentado? Houve maior número de demissões? Faltou valorização do profissional? É importante manter essa taxa a menor possível. Isso pode ser um indicador de uma boa equipe, logo, bons resultados. | E10: =IF(ISERROR(IF(OR(D22=0,D22=""),D25,IF(D22>0,D23,D24))),"",IF(OR(D22=0,D22=""),D25,IF(D22>0,D23,D24))) -> Não foi possível comparar com o mês anterior por falta de dados. Ou seja, não há comentários a serem exibidos para este item. | G10: =IF(ISERROR(IF(D27="",D30,IF(D27>0,D28,D29))),"",IF(D27="",D30,IF(D27>0,D28,D29))) -> Notícias não muito boas para este mês. A receita média gerada por cada funcionário foi 100% menor em relação ao mês anterior. É importante procurar extrair uma receita maior por cada funcionário. Isso pode ser um dos indicadores de resultados mais lucrativos. A Planilha de Fluxo de Caixa LUZ ajuda a controlar melhor esses indicadores de resultados financeiros. | T10: Setembro | U10: 9
T11: Outubro | U11: 10
T12: Novembro | U12: 11
T13: Dezembro | U13: 12
C17: Turnover | D17: =IF(ISERROR(ROUND(INDEX('AD Aux'!$B$11:$N$11,1,MATCH(AD!$I$6,'AD Aux'!$C$2:$N$2,0)+1),2)*100),"",ROUND(INDEX('AD Aux'!$B$11:$N$11,1,MATCH(AD!$I$6,'AD Aux'!$C$2:$N$2,0)+1),2)*100) -> 67
C18: Negativo: | D18: ="A Taxa de Turnover aumentou em relação ao mês anterior em "&D17&"%. O que houve para que esta taxa tenha aumentado? Houve maior número de demissões? Faltou valorização do profissional? É importante manter essa taxa a menor possível. Isso pode ser um indicador de uma boa equipe, logo, bons resultados." -> A Taxa de Turnover aumentou em relação ao mês anterior em 67%. O que houve para que esta taxa tenha aumentado? Houve maior número de demissões? Faltou valorização do profissional? É importante manter essa taxa a menor possível. Isso pode ser um indicador de uma boa equipe, logo, bons resultados.
C19: Positivo: | D19: A Taxa de Turnover diminuiu ou se manteve estável em relação ao mês anterior. Isso pode ser um bom sinal de satisfação dos funcionários em relação a empresa e da empresa em relação aos funcionários. É importante manter essa taxa a menor possível. Isso pode ser um indicador de uma boa equipe, logo, bons resultados.
C20: Neutro: | D20: Não foi possível comparar com o mês anterior por falta de dados. Ou seja, não há comentários a serem exibidos para este item.
C22: Treinamentos | D22: =IF(ISERROR(ROUND(INDEX('AD Aux'!$B$15:$N$15,1,MATCH(AD!$I$6,'AD Aux'!$C$2:$N$2,0)+1),2)),"",ROUND(INDEX('AD Aux'!$B$15:$N$15,1,MATCH(AD!$I$6,'AD Aux'!$C$2:$N$2,0)+1),2)) -> 0
C23: Negativo: | D23: Seu custo com treinamentos aumentou em relação ao mês anterior. Isso é ruim no ponto de vista "redução de custos", porém, não é motivo para alarde. É importante se dedicar a equipe através de treinamentos, pois eles podem diminuir outros custos muito mais significativos para a empresa. Cerifique-se do retorno que o investimento traz para o cotidiano da empresa.
C24: Positivo: | D24: Seu custo com treinamentos diminuiu em relação ao mês anterior. Isso é bom no ponto de vista "redução de custos", porém, fique atento, pois é importante se dedicar a equipe através de treinamentos, pois eles podem diminuir outros custos muito mais significativos para a empresa.
C25: Neutro: | D25: Não foi possível comparar com o mês anterior por falta de dados. Ou seja, não há comentários a serem exibidos para este item.
C27: Receita | D27: =IF(ISERROR(ROUND(INDEX('AD Aux'!$B$20:$N$20,1,MATCH(AD!$I$6,'AD Aux'!$C$2:$N$2,0)+1),2)*100),"",ROUND(INDEX('AD Aux'!$B$20:$N$20,1,MATCH(AD!$I$6,'AD Aux'!$C$2:$N$2,0)+1),2)*100) -> 100
C28: Negativo: | D28: ="Notícias não muito boas para este mês. A receita média gerada por cada funcionário foi "&D27&"% menor em relação ao mês anterior. É importante procurar extrair uma receita maior por cada funcionário. Isso pode ser um dos indicadores de resultados mais lucrativos."&" A Planilha de Fluxo de Caixa LUZ ajuda a controlar melhor esses indicadores de resultados financeiros." -> Notícias não muito boas para este mês. A receita média gerada por cada funcionário foi 100% menor em relação ao mês anterior. É importante procurar extrair uma receita maior por cada funcionário. Isso pode ser um dos indicadores de resultados mais lucrativos. A Planilha de Fluxo de Caixa LUZ ajuda a controlar melhor esses indicadores de resultados financeiros.
C29: Positivo: | D29: ="Boas notícias para este mês! A receita média gerada por cada funcionário foi "&D27&"% maior em relação ao mês anterior. Se os gastos totais da empresa (incluindo custos diretos, fixos, impostos, folha, etc) for menor que a receita bruta gerada, significa que a empresa está lucrativa."&" A Planilha de Fluxo de Caixa LUZ ajuda a controlar melhor esses indicadores de resultados financeiros." -> Boas notícias para este mês! A receita média gerada por cada funcionário foi 100% maior em relação ao mês anterior. Se os gastos totais da empresa (incluindo custos diretos, fixos, impostos, folha, etc) for menor que a receita bruta gerada, significa que a empresa está lucrativa. A Planilha de Fluxo de Caixa LUZ ajuda a controlar melhor esses indicadores de resultados financeiros.
C30: Neutro: | D30: Não foi possível comparar com o mês anterior por falta de dados. Ou seja, não há comentários a serem exibidos para este item.

Sheet AD Aux
A1: Ano | B1: =C1-1 -> 2014 | C1: =Cad_Inicial!$D$8 -> 2015
B2: 12 | C2: 1 | D2: 2 | E2: 3 | F2: 4 | G2: 5 | H2: 6 | I2: 7 | J2: 8 | K2: 9 | L2: 10 | M2: 11 | N2: 12
A3: ="<"&C1 -> <2015 | B3: ="<="&B2 -> <=12 | C3: ="<="&C2 -> <=1 | D3: ="<="&D2 -> <=2 | E3: ="<="&E2 -> <=3 | F3: ="<="&F2 -> <=4 | G3: ="<="&G2 -> <=5 | H3: ="<="&H2 -> <=6 | I3: ="<="&I2 -> <=7 | ... N3: ="<="&N2 -> <=12
B4: =">="&B2 -> >=12 | C4: =">="&C2 -> >=1 | D4: =">="&D2 -> >=2 | E4: =">="&E2 -> >=3 | F4: =">="&F2 -> >=4 | G4: =">="&G2 -> >=5 | H4: =">="&H2 -> >=6 | I4: =">="&I2 -> >=7 | ... N4: =">="&N2 -> >=12
A5: Indicador | B5: ="Dez "&B1 -> Dez 2014 | C5: Jan | D5: Fev | E5: Mar | F5: Abr | G5: Mai | H5: Jun | I5: Jul | J5: Ago | K5: Set | L5: Out | M5: Nov | N5: Dez
A6: Admissões | B6: =IF(ISERROR(IF(AND($B$1>=YEAR(TODAY()),MONTH(TODAY())<B$2),"",COUNTIFS(Cad_Func!$W$8:$W$208,$B$1,Cad_Func!$X$8:$X$208,B$2))),"",IF(AND($B$1>=YEAR(TODAY()),MONTH(TODAY())<B$2),"",COUNTIFS(Cad_Func!$W$8:$W$208,$B$1,Cad_Func!$X$8:$X$208,B$2))) -> 1 | C6: =IF(ISERROR(IF(AND($C$1>=YEAR(TODAY()),MONTH(TODAY())<C$2),"",COUNTIFS(Cad_Func!$W$8:$W$208,$C$1,Cad_Func!$X$8:$X$208,C$2))),"",IF(AND($C$1>=YEAR(TODAY()),MONTH(TODAY())<C$2),"",COUNTIFS(Cad_Func!$W$8:$W$208,$C$1,Cad_Func!$X$8:$X$208,C$2))) -> 1 | D6: =IF(ISERROR(IF(AND($C$1>=YEAR(TODAY()),MONTH(TODAY())<D$2),"",COUNTIFS(Cad_Func!$W$8:$W$208,$C$1,Cad_Func!$X$8:$X$208,D$2))),"",IF(AND($C$1>=YEAR(TODAY()),MONTH(TODAY())<D$2),"",COUNTIFS(Cad_Func!$W$8:$W$208,$C$1,Cad_Func!$X$8:$X$208,D$2))) -> 2 | E6: =IF(ISERROR(IF(AND($C$1>=YEAR(TODAY()),MONTH(TODAY())<E$2),"",COUNTIFS(Cad_Func!$W$8:$W$208,$C$1,Cad_Func!$X$8:$X$208,E$2))),"",IF(AND($C$1>=YEAR(TODAY()),MONTH(TODAY())<E$2),"",COUNTIFS(Cad_Func!$W$8:$W$208,$C$1,Cad_Func!$X$8:$X$208,E$2))) -> 0 | F6: =IF(ISERROR(IF(AND($C$1>=YEAR(TODAY()),MONTH(TODAY())<F$2),"",COUNTIFS(Cad_Func!$W$8:$W$208,$C$1,Cad_Func!$X$8:$X$208,F$2))),"",IF(AND($C$1>=YEAR(TODAY()),MONTH(TODAY())<F$2),"",COUNTIFS(Cad_Func!$W$8:$W$208,$C$1,Cad_Func!$X$8:$X$208,F$2))) -> 0 | G6: =IF(ISERROR(IF(AND($C$1>=YEAR(TODAY()),MONTH(TODAY())<G$2),"",COUNTIFS(Cad_Func!$W$8:$W$208,$C$1,Cad_Func!$X$8:$X$208,G$2))),"",IF(AND($C$1>=YEAR(TODAY()),MONTH(TODAY())<G$2),"",COUNTIFS(Cad_Func!$W$8:$W$208,$C$1,Cad_Func!$X$8:$X$208,G$2))) -> 0 | H6: =IF(ISERROR(IF(AND($C$1>=YEAR(TODAY()),MONTH(TODAY())<H$2),"",COUNTIFS(Cad_Func!$W$8:$W$208,$C$1,Cad_Func!$X$8:$X$208,H$2))),"",IF(AND($C$1>=YEAR(TODAY()),MONTH(TODAY())<H$2),"",COUNTIFS(Cad_Func!$W$8:$W$208,$C$1,Cad_Func!$X$8:$X$208,H$2))) -> 0 | I6: =IF(ISERROR(IF(AND($C$1>=YEAR(TODAY()),MONTH(TODAY())<I$2),"",COUNTIFS(Cad_Func!$W$8:$W$208,$C$1,Cad_Func!$X$8:$X$208,I$2))),"",IF(AND($C$1>=YEAR(TODAY()),MONTH(TODAY())<I$2),"",COUNTIFS(Cad_Func!$W$8:$W$208,$C$1,Cad_Func!$X$8:$X$208,I$2))) -> 0 | J6: =IF(ISERROR(IF(AND($C$1>=YEAR(TODAY()),MONTH(TODAY())<J$2),"",COUNTIFS(Cad_Func!$W$8:$W$208,$C$1,Cad_Func!$X$8:$X$208,J$2))),"",IF(AND($C$1>=YEAR(TODAY()),MONTH(TODAY())<J$2),"",COUNTIFS(Cad_Func!$W$8:$W$208,$C$1,Cad_Func!$X$8:$X$208,J$2))) -> 0 | ... N6: =IF(ISERROR(IF(AND($C$1>=YEAR(TODAY()),MONTH(TODAY())<N$2),"",COUNTIFS(Cad_Func!$W$8:$W$208,$C$1,Cad_Func!$X$8:$X$208,N$2))),"",IF(AND($C$1>=YEAR(TODAY()),MONTH(TODAY())<N$2),"",COUNTIFS(Cad_Func!$W$8:$W$208,$C$1,Cad_Func!$X$8:$X$208,N$2))) -> 0
A7: Demissões | B7: =IF(ISERROR(IF(AND($B$1>=YEAR(TODAY()),MONTH(TODAY())<B$2),"",COUNTIFS(Cad_Func!$Y$8:$Y$208,RC_Rotatividade!#REF!,Cad_Func!$Z$8:$Z$208,RC_Rotatividade!D$6))),"",IF(AND($B$1>=YEAR(TODAY()),MONTH(TODAY())<B$2),"",COUNTIFS(Cad_Func!$Y$8:$Y$208,RC_Rotatividade!#REF!,Cad_Func!$Z$8:$Z$208,RC_Rotatividade!D$6))) -> 0 | C7: =IF(ISERROR(IF(AND($C$1>=YEAR(TODAY()),MONTH(TODAY())<C$2),"",COUNTIFS(Cad_Func!$Y$8:$Y$208,RC_Rotatividade!#REF!,Cad_Func!$Z$8:$Z$208,RC_Rotatividade!E$6))),"",IF(AND($C$1>=YEAR(TODAY()),MONTH(TODAY())<C$2),"",COUNTIFS(Cad_Func!$Y$8:$Y$208,RC_Rotatividade!#REF!,Cad_Func!$Z$8:$Z$208,RC_Rotatividade!E$6))) -> 0 | D7: =IF(ISERROR(IF(AND($C$1>=YEAR(TODAY()),MONTH(TODAY())<D$2),"",COUNTIFS(Cad_Func!$Y$8:$Y$208,RC_Rotatividade!#REF!,Cad_Func!$Z$8:$Z$208,RC_Rotatividade!F$6))),"",IF(AND($C$1>=YEAR(TODAY()),MONTH(TODAY())<D$2),"",COUNTIFS(Cad_Func!$Y$8:$Y$208,RC_Rotatividade!#REF!,Cad_Func!$Z$8:$Z$208,RC_Rotatividade!F$6))) -> 0 | E7: =IF(ISERROR(IF(AND($C$1>=YEAR(TODAY()),MONTH(TODAY())<E$2),"",COUNTIFS(Cad_Func!$Y$8:$Y$208,RC_Rotatividade!#REF!,Cad_Func!$Z$8:$Z$208,RC_Rotatividade!G$6))),"",IF(AND($C$1>=YEAR(TODAY()),MONTH(TODAY())<E$2),"",COUNTIFS(Cad_Func!$Y$8:$Y$208,RC_Rotatividade!#REF!,Cad_Func!$Z$8:$Z$208,RC_Rotatividade!G$6))) -> 0 | F7: =IF(ISERROR(IF(AND($C$1>=YEAR(TODAY()),MONTH(TODAY())<F$2),"",COUNTIFS(Cad_Func!$Y$8:$Y$208,RC_Rotatividade!#REF!,Cad_Func!$Z$8:$Z$208,RC_Rotatividade!H$6))),"",IF(AND($C$1>=YEAR(TODAY()),MONTH(TODAY())<F$2),"",COUNTIFS(Cad_Func!$Y$8:$Y$208,RC_Rotatividade!#REF!,Cad_Func!$Z$8:$Z$208,RC_Rotatividade!H$6))) -> 0 | G7: =IF(ISERROR(IF(AND($C$1>=YEAR(TODAY()),MONTH(TODAY())<G$2),"",COUNTIFS(Cad_Func!$Y$8:$Y$208,RC_Rotatividade!#REF!,Cad_Func!$Z$8:$Z$208,RC_Rotatividade!I$6))),"",IF(AND($C$1>=YEAR(TODAY()),MONTH(TODAY())<G$2),"",COUNTIFS(Cad_Func!$Y$8:$Y$208,RC_Rotatividade!#REF!,Cad_Func!$Z$8:$Z$208,RC_Rotatividade!I$6))) -> 0 | H7: =IF(ISERROR(IF(AND($C$1>=YEAR(TODAY()),MONTH(TODAY())<H$2),"",COUNTIFS(Cad_Func!$Y$8:$Y$208,RC_Rotatividade!#REF!,Cad_Func!$Z$8:$Z$208,RC_Rotatividade!J$6))),"",IF(AND($C$1>=YEAR(TODAY()),MONTH(TODAY())<H$2),"",COUNTIFS(Cad_Func!$Y$8:$Y$208,RC_Rotatividade!#REF!,Cad_Func!$Z$8:$Z$208,RC_Rotatividade!J$6))) -> 0 | I7: =IF(ISERROR(IF(AND($C$1>=YEAR(TODAY()),MONTH(TODAY())<I$2),"",COUNTIFS(Cad_Func!$Y$8:$Y$208,RC_Rotatividade!#REF!,Cad_Func!$Z$8:$Z$208,RC_Rotatividade!K$6))),"",IF(AND($C$1>=YEAR(TODAY()),MONTH(TODAY())<I$2),"",COUNTIFS(Cad_Func!$Y$8:$Y$208,RC_Rotatividade!#REF!,Cad_Func!$Z$8:$Z$208,RC_Rotatividade!K$6))) -> 0 | J7: =IF(ISERROR(IF(AND($C$1>=YEAR(TODAY()),MONTH(TODAY())<J$2),"",COUNTIFS(Cad_Func!$Y$8:$Y$208,RC_Rotatividade!#REF!,Cad_Func!$Z$8:$Z$208,RC_Rotatividade!L$6))),"",IF(AND($C$1>=YEAR(TODAY()),MONTH(TODAY())<J$2),"",COUNTIFS(Cad_Func!$Y$8:$Y$208,RC_Rotatividade!#REF!,Cad_Func!$Z$8:$Z$208,RC_Rotatividade!L$6))) -> 0 | ... N7: =IF(ISERROR(IF(AND($C$1>=YEAR(TODAY()),MONTH(TODAY())<N$2),"",COUNTIFS(Cad_Func!$Y$8:$Y$208,RC_Rotatividade!#REF!,Cad_Func!$Z$8:$Z$208,RC_Rotatividade!P$6))),"",IF(AND($C$1>=YEAR(TODAY()),MONTH(TODAY())<N$2),"",COUNTIFS(Cad_Func!$Y$8:$Y$208,RC_Rotatividade!#REF!,Cad_Func!$Z$8:$Z$208,RC_Rotatividade!P$6))) -> 0
A8: Funcionários no início do mês | B8: =IF(ISERROR(SUM(Cad_Func!$Q$8:$Q$208)),"",SUM(Cad_Func!$Q$8:$Q$208)) -> 9 | C8: =IF(ISERROR(SUM(Cad_Func!$Q$8:$Q$208)),"",SUM(Cad_Func!$Q$8:$Q$208)) -> 9 | D8: =IF(ISERROR(IF(AND($C$1>=YEAR(TODAY()),MONTH(TODAY())<D$2),"",C9)),"",IF(AND($C$1>=YEAR(TODAY()),MONTH(TODAY())<D$2),"",C9)) -> 10 | E8: =IF(ISERROR(IF(AND($C$1>=YEAR(TODAY()),MONTH(TODAY())<E$2),"",D9)),"",IF(AND($C$1>=YEAR(TODAY()),MONTH(TODAY())<E$2),"",D9)) -> 12 | F8: =IF(ISERROR(IF(AND($C$1>=YEAR(TODAY()),MONTH(TODAY())<F$2),"",E9)),"",IF(AND($C$1>=YEAR(TODAY()),MONTH(TODAY())<F$2),"",E9)) -> 12 | G8: =IF(ISERROR(IF(AND($C$1>=YEAR(TODAY()),MONTH(TODAY())<G$2),"",F9)),"",IF(AND($C$1>=YEAR(TODAY()),MONTH(TODAY())<G$2),"",F9)) -> 12 | H8: =IF(ISERROR(IF(AND($C$1>=YEAR(TODAY()),MONTH(TODAY())<H$2),"",G9)),"",IF(AND($C$1>=YEAR(TODAY()),MONTH(TODAY())<H$2),"",G9)) -> 12 | I8: =IF(ISERROR(IF(AND($C$1>=YEAR(TODAY()),MONTH(TODAY())<I$2),"",H9)),"",IF(AND($C$1>=YEAR(TODAY()),MONTH(TODAY())<I$2),"",H9)) -> 12 | J8: =IF(ISERROR(IF(AND($C$1>=YEAR(TODAY()),MONTH(TODAY())<J$2),"",I9)),"",IF(AND($C$1>=YEAR(TODAY()),MONTH(TODAY())<J$2),"",I9)) -> 12 | K8: =IF(ISERROR(IF(AND($C$1>=YEAR(TODAY()),MONTH(TODAY())<K$2),"",J9)),"",IF(AND($C$1>=YEAR(TODAY()),MONTH(TODAY())<K$2),"",J9)) -> 12 | ... N8: =IF(ISERROR(IF(AND($C$1>=YEAR(TODAY()),MONTH(TODAY())<N$2),"",M9)),"",IF(AND($C$1>=YEAR(TODAY()),MONTH(TODAY())<N$2),"",M9)) -> 12
A9: Funcionários no fim do mês | B9: =IF(ISERROR(B8+B6-B7),"",B8+B6-B7) -> 10 | C9: =IF(ISERROR(C8+C6-C7),"",C8+C6-C7) -> 10 | D9: =IF(ISERROR(D8+D6-D7),"",D8+D6-D7) -> 12 | E9: =IF(ISERROR(E8+E6-E7),"",E8+E6-E7) -> 12 | F9: =IF(ISERROR(F8+F6-F7),"",F8+F6-F7) -> 12 | G9: =IF(ISERROR(G8+G6-G7),"",G8+G6-G7) -> 12 | H9: =IF(ISERROR(H8+H6-H7),"",H8+H6-H7) -> 12 | I9: =IF(ISERROR(I8+I6-I7),"",I8+I6-I7) -> 12 | ... N9: =IF(ISERROR(N8+N6-N7),"",N8+N6-N7) -> 12 | O9: =IF(ISERROR(IF(D9="",C9,IF(E9="",D9,IF(F9="",E9,IF(G9="",F9,IF(H9="",G9,IF(I9="",H9,IF(J9="",I9,IF(K9="",J9,IF(L9="",K9,IF(M9="",L9,IF(N9="",M9,N9)))))))))))),"",IF(D9="",C9,IF(E9="",D9,IF(F9="",E9,IF(G9="",F9,IF(H9="",G9,IF(I9="",H9,IF(J9="",I9,IF(K9="",J9,IF(L9="",K9,IF(M9="",L9,IF(N9="",M9,N9)))))))))))) -> 12
A10: Turnover | B10: =IF(ISERROR(IF((B6+B7)/2/B9=0,"",(B6+B7)/2/B9)),"",IF((B6+B7)/2/B9=0,"",(B6+B7)/2/B9)) -> 0.05 | C10: =IF(ISERROR(IF((C6+C7)/2/C9=0,"",(C6+C7)/2/C9)),"",IF((C6+C7)/2/C9=0,"",(C6+C7)/2/C9)) -> 0.05 | D10: =IF(ISERROR(IF((D6+D7)/2/D9=0,"",(D6+D7)/2/D9)),"",IF((D6+D7)/2/D9=0,"",(D6+D7)/2/D9)) -> 0.083333333 | E10: =IF(ISERROR(IF((E6+E7)/2/E9=0,"",(E6+E7)/2/E9)),"",IF((E6+E7)/2/E9=0,"",(E6+E7)/2/E9)) | F10: =IF(ISERROR(IF((F6+F7)/2/F9=0,"",(F6+F7)/2/F9)),"",IF((F6+F7)/2/F9=0,"",(F6+F7)/2/F9)) | G10: =IF(ISERROR(IF((G6+G7)/2/G9=0,"",(G6+G7)/2/G9)),"",IF((G6+G7)/2/G9=0,"",(G6+G7)/2/G9)) | H10: =IF(ISERROR(IF((H6+H7)/2/H9=0,"",(H6+H7)/2/H9)),"",IF((H6+H7)/2/H9=0,"",(H6+H7)/2/H9)) | I10: =IF(ISERROR(IF((I6+I7)/2/I9=0,"",(I6+I7)/2/I9)),"",IF((I6+I7)/2/I9=0,"",(I6+I7)/2/I9)) | ... N10: =IF(ISERROR(IF((N6+N7)/2/N9=0,"",(N6+N7)/2/N9)),"",IF((N6+N7)/2/N9=0,"",(N6+N7)/2/N9))
A11: Variação % | C11: =IF(ISERROR(C10/B10-1),C10,C10/B10-1) -> 0 | D11: =IF(ISERROR(D10/C10-1),D10,D10/C10-1) -> 0.66666667 | E11: =IF(ISERROR(E10/D10-1),E10,E10/D10-1) | F11: =IF(ISERROR(F10/E10-1),F10,F10/E10-1) | G11: =IF(ISERROR(G10/F10-1),G10,G10/F10-1) | H11: =IF(ISERROR(H10/G10-1),H10,H10/G10-1) | I11: =IF(ISERROR(I10/H10-1),I10,I10/H10-1) | J11: =IF(ISERROR(J10/I10-1),J10,J10/I10-1) | ... N11: =IF(ISERROR(N10/M10-1),N10,N10/M10-1)
A13: Indicador | B13: ="Dez "&$B$1 -> Dez 2014 | C13: Jan | D13: Fev | E13: Mar | F13: Abr | G13: Mai | H13: Jun | I13: Jul | J13: Ago | K13: Set | L13: Out | M13: Nov | N13: Dez | O13: Total
A14: Custo total | B14: =IF(ISERROR(IF(AND($B$1>=YEAR(TODAY()),MONTH(TODAY())<B$2),"",ROUND(SUMIFS(Lanç_Terinamentos!$AA$8:$AA$2008,Lanç_Terinamentos!$X$8:$X$2008,$B$1,Lanç_Terinamentos!$W$8:$W$2008,B$4,Lanç_Terinamentos!$V$8:$V$2008,B$3),2))),"",IF(AND($B$1>=YEAR(TODAY()),MONTH(TODAY())<B$2),"",ROUND(SUMIFS(Lanç_Terinamentos!$AA$8:$AA$2008,Lanç_Terinamentos!$X$8:$X$2008,$B$1,Lanç_Terinamentos!$W$8:$W$2008,B$4,Lanç_Terinamentos!$V$8:$V$2008,B$3),2))) -> 0 | C14: =IF(ISERROR(IF(AND($C$1>=YEAR(TODAY()),MONTH(TODAY())<C$2),"",ROUND(SUMIFS(Lanç_Terinamentos!$AA$8:$AA$2008,Lanç_Terinamentos!$X$8:$X$2008,$C$1,Lanç_Terinamentos!$W$8:$W$2008,C$4,Lanç_Terinamentos!$V$8:$V$2008,C$3),2))),"",IF(AND($C$1>=YEAR(TODAY()),MONTH(TODAY())<C$2),"",ROUND(SUMIFS(Lanç_Terinamentos!$AA$8:$AA$2008,Lanç_Terinamentos!$X$8:$X$2008,$C$1,Lanç_Terinamentos!$W$8:$W$2008,C$4,Lanç_Terinamentos!$V$8:$V$2008,C$3),2))) -> 0 | D14: =IF(ISERROR(IF(AND($C$1>=YEAR(TODAY()),MONTH(TODAY())<D$2),"",ROUND(SUMIFS(Lanç_Terinamentos!$AA$8:$AA$2008,Lanç_Terinamentos!$X$8:$X$2008,$C$1,Lanç_Terinamentos!$W$8:$W$2008,D$4,Lanç_Terinamentos!$V$8:$V$2008,D$3),2))),"",IF(AND($C$1>=YEAR(TODAY()),MONTH(TODAY())<D$2),"",ROUND(SUMIFS(Lanç_Terinamentos!$AA$8:$AA$2008,Lanç_Terinamentos!$X$8:$X$2008,$C$1,Lanç_Terinamentos!$W$8:$W$2008,D$4,Lanç_Terinamentos!$V$8:$V$2008,D$3),2))) -> 0 | E14: =IF(ISERROR(IF(AND($C$1>=YEAR(TODAY()),MONTH(TODAY())<E$2),"",ROUND(SUMIFS(Lanç_Terinamentos!$AA$8:$AA$2008,Lanç_Terinamentos!$X$8:$X$2008,$C$1,Lanç_Terinamentos!$W$8:$W$2008,E$4,Lanç_Terinamentos!$V$8:$V$2008,E$3),2))),"",IF(AND($C$1>=YEAR(TODAY()),MONTH(TODAY())<E$2),"",ROUND(SUMIFS(Lanç_Terinamentos!$AA$8:$AA$2008,Lanç_Terinamentos!$X$8:$X$2008,$C$1,Lanç_Terinamentos!$W$8:$W$2008,E$4,Lanç_Terinamentos!$V$8:$V$2008,E$3),2))) -> 0 | F14: =IF(ISERROR(IF(AND($C$1>=YEAR(TODAY()),MONTH(TODAY())<F$2),"",ROUND(SUMIFS(Lanç_Terinamentos!$AA$8:$AA$2008,Lanç_Terinamentos!$X$8:$X$2008,$C$1,Lanç_Terinamentos!$W$8:$W$2008,F$4,Lanç_Terinamentos!$V$8:$V$2008,F$3),2))),"",IF(AND($C$1>=YEAR(TODAY()),MONTH(TODAY())<F$2),"",ROUND(SUMIFS(Lanç_Terinamentos!$AA$8:$AA$2008,Lanç_Terinamentos!$X$8:$X$2008,$C$1,Lanç_Terinamentos!$W$8:$W$2008,F$4,Lanç_Terinamentos!$V$8:$V$2008,F$3),2))) -> 0 | G14: =IF(ISERROR(IF(AND($C$1>=YEAR(TODAY()),MONTH(TODAY())<G$2),"",ROUND(SUMIFS(Lanç_Terinamentos!$AA$8:$AA$2008,Lanç_Terinamentos!$X$8:$X$2008,$C$1,Lanç_Terinamentos!$W$8:$W$2008,G$4,Lanç_Terinamentos!$V$8:$V$2008,G$3),2))),"",IF(AND($C$1>=YEAR(TODAY()),MONTH(TODAY())<G$2),"",ROUND(SUMIFS(Lanç_Terinamentos!$AA$8:$AA$2008,Lanç_Terinamentos!$X$8:$X$2008,$C$1,Lanç_Terinamentos!$W$8:$W$2008,G$4,Lanç_Terinamentos!$V$8:$V$2008,G$3),2))) -> 0 | H14: =IF(ISERROR(IF(AND($C$1>=YEAR(TODAY()),MONTH(TODAY())<H$2),"",ROUND(SUMIFS(Lanç_Terinamentos!$AA$8:$AA$2008,Lanç_Terinamentos!$X$8:$X$2008,$C$1,Lanç_Terinamentos!$W$8:$W$2008,H$4,Lanç_Terinamentos!$V$8:$V$2008,H$3),2))),"",IF(AND($C$1>=YEAR(TODAY()),MONTH(TODAY())<H$2),"",ROUND(SUMIFS(Lanç_Terinamentos!$AA$8:$AA$2008,Lanç_Terinamentos!$X$8:$X$2008,$C$1,Lanç_Terinamentos!$W$8:$W$2008,H$4,Lanç_Terinamentos!$V$8:$V$2008,H$3),2))) -> 0 | I14: =IF(ISERROR(IF(AND($C$1>=YEAR(TODAY()),MONTH(TODAY())<I$2),"",ROUND(SUMIFS(Lanç_Terinamentos!$AA$8:$AA$2008,Lanç_Terinamentos!$X$8:$X$2008,$C$1,Lanç_Terinamentos!$W$8:$W$2008,I$4,Lanç_Terinamentos!$V$8:$V$2008,I$3),2))),"",IF(AND($C$1>=YEAR(TODAY()),MONTH(TODAY())<I$2),"",ROUND(SUMIFS(Lanç_Terinamentos!$AA$8:$AA$2008,Lanç_Terinamentos!$X$8:$X$2008,$C$1,Lanç_Terinamentos!$W$8:$W$2008,I$4,Lanç_Terinamentos!$V$8:$V$2008,I$3),2))) -> 0 | J14: =IF(ISERROR(IF(AND($C$1>=YEAR(TODAY()),MONTH(TODAY())<J$2),"",ROUND(SUMIFS(Lanç_Terinamentos!$AA$8:$AA$2008,Lanç_Terinamentos!$X$8:$X$2008,$C$1,Lanç_Terinamentos!$W$8:$W$2008,J$4,Lanç_Terinamentos!$V$8:$V$2008,J$3),2))),"",IF(AND($C$1>=YEAR(TODAY()),MONTH(TODAY())<J$2),"",ROUND(SUMIFS(Lanç_Terinamentos!$AA$8:$AA$2008,Lanç_Terinamentos!$X$8:$X$2008,$C$1,Lanç_Terinamentos!$W$8:$W$2008,J$4,Lanç_Terinamentos!$V$8:$V$2008,J$3),2))) -> 0 | ... N14: =IF(ISERROR(IF(AND($C$1>=YEAR(TODAY()),MONTH(TODAY())<N$2),"",ROUND(SUMIFS(Lanç_Terinamentos!$AA$8:$AA$2008,Lanç_Terinamentos!$X$8:$X$2008,$C$1,Lanç_Terinamentos!$W$8:$W$2008,N$4,Lanç_Terinamentos!$V$8:$V$2008,N$3),2))),"",IF(AND($C$1>=YEAR(TODAY()),MONTH(TODAY())<N$2),"",ROUND(SUMIFS(Lanç_Terinamentos!$AA$8:$AA$2008,Lanç_Terinamentos!$X$8:$X$2008,$C$1,Lanç_Terinamentos!$W$8:$W$2008,N$4,Lanç_Terinamentos!$V$8:$V$2008,N$3),2))) -> 0
A15: Variação | C15: =IF(ISERROR(C14-B14),"",C14-B14) -> 0 | D15: =IF(ISERROR(D14-C14),"",D14-C14) -> 0 | E15: =IF(ISERROR(E14-D14),"",E14-D14) -> 0 | F15: =IF(ISERROR(F14-E14),"",F14-E14) -> 0 | G15: =IF(ISERROR(G14-F14),"",G14-F14) -> 0 | H15: =IF(ISERROR(H14-G14),"",H14-G14) -> 0 | I15: =IF(ISERROR(I14-H14),"",I14-H14) -> 0 | J15: =IF(ISERROR(J14-I14),"",J14-I14) -> 0 | ... N15: =IF(ISERROR(N14-M14),"",N14-M14) -> 0
A17: Indicador | B17: ="Dez "&$B$1 -> Dez 2014 | C17: Jan | D17: Fev | E17: Mar | F17: Abr | G17: Mai | H17: Jun | I17: Jul | J17: Ago | K17: Set | L17: Out | M17: Nov | N17: Dez | O17: Total
A18: Receita Bruta | B18: =IF(ISERROR(IF(AND($B$1>=YEAR(TODAY()),MONTH(TODAY())<B$2),"",SUMIFS(Lanç_Receitas!$C$6:$C$33,Lanç_Receitas!$E$6:$E$33,$B$1,Lanç_Receitas!$O$6:$O$33,B$2))),"",IF(AND($B$1>=YEAR(TODAY()),MONTH(TODAY())<B$2),"",SUMIFS(Lanç_Receitas!$C$6:$C$33,Lanç_Receitas!$E$6:$E$33,$B$1,Lanç_Receitas!$O$6:$O$33,B$2))) -> 0 | C18: =IF(ISERROR(IF(AND($C$1>=YEAR(TODAY()),MONTH(TODAY())<C$2),"",SUMIFS(Lanç_Receitas!$C$6:$C$33,Lanç_Receitas!$E$6:$E$33,$C$1,Lanç_Receitas!$O$6:$O$33,C$2))),"",IF(AND($C$1>=YEAR(TODAY()),MONTH(TODAY())<C$2),"",SUMIFS(Lanç_Receitas!$C$6:$C$33,Lanç_Receitas!$E$6:$E$33,$C$1,Lanç_Receitas!$O$6:$O$33,C$2))) -> 0 | D18: =IF(ISERROR(IF(AND($C$1>=YEAR(TODAY()),MONTH(TODAY())<D$2),"",SUMIFS(Lanç_Receitas!$C$6:$C$33,Lanç_Receitas!$E$6:$E$33,$C$1,Lanç_Receitas!$O$6:$O$33,D$2))),"",IF(AND($C$1>=YEAR(TODAY()),MONTH(TODAY())<D$2),"",SUMIFS(Lanç_Receitas!$C$6:$C$33,Lanç_Receitas!$E$6:$E$33,$C$1,Lanç_Receitas!$O$6:$O$33,D$2))) -> 0 | E18: =IF(ISERROR(IF(AND($C$1>=YEAR(TODAY()),MONTH(TODAY())<E$2),"",SUMIFS(Lanç_Receitas!$C$6:$C$33,Lanç_Receitas!$E$6:$E$33,$C$1,Lanç_Receitas!$O$6:$O$33,E$2))),"",IF(AND($C$1>=YEAR(TODAY()),MONTH(TODAY())<E$2),"",SUMIFS(Lanç_Receitas!$C$6:$C$33,Lanç_Receitas!$E$6:$E$33,$C$1,Lanç_Receitas!$O$6:$O$33,E$2))) -> 0 | F18: =IF(ISERROR(IF(AND($C$1>=YEAR(TODAY()),MONTH(TODAY())<F$2),"",SUMIFS(Lanç_Receitas!$C$6:$C$33,Lanç_Receitas!$E$6:$E$33,$C$1,Lanç_Receitas!$O$6:$O$33,F$2))),"",IF(AND($C$1>=YEAR(TODAY()),MONTH(TODAY())<F$2),"",SUMIFS(Lanç_Receitas!$C$6:$C$33,Lanç_Receitas!$E$6:$E$33,$C$1,Lanç_Receitas!$O$6:$O$33,F$2))) -> 0 | G18: =IF(ISERROR(IF(AND($C$1>=YEAR(TODAY()),MONTH(TODAY())<G$2),"",SUMIFS(Lanç_Receitas!$C$6:$C$33,Lanç_Receitas!$E$6:$E$33,$C$1,Lanç_Receitas!$O$6:$O$33,G$2))),"",IF(AND($C$1>=YEAR(TODAY()),MONTH(TODAY())<G$2),"",SUMIFS(Lanç_Receitas!$C$6:$C$33,Lanç_Receitas!$E$6:$E$33,$C$1,Lanç_Receitas!$O$6:$O$33,G$2))) -> 0 | H18: =IF(ISERROR(IF(AND($C$1>=YEAR(TODAY()),MONTH(TODAY())<H$2),"",SUMIFS(Lanç_Receitas!$C$6:$C$33,Lanç_Receitas!$E$6:$E$33,$C$1,Lanç_Receitas!$O$6:$O$33,H$2))),"",IF(AND($C$1>=YEAR(TODAY()),MONTH(TODAY())<H$2),"",SUMIFS(Lanç_Receitas!$C$6:$C$33,Lanç_Receitas!$E$6:$E$33,$C$1,Lanç_Receitas!$O$6:$O$33,H$2))) -> 0 | I18: =IF(ISERROR(IF(AND($C$1>=YEAR(TODAY()),MONTH(TODAY())<I$2),"",SUMIFS(Lanç_Receitas!$C$6:$C$33,Lanç_Receitas!$E$6:$E$33,$C$1,Lanç_Receitas!$O$6:$O$33,I$2))),"",IF(AND($C$1>=YEAR(TODAY()),MONTH(TODAY())<I$2),"",SUMIFS(Lanç_Receitas!$C$6:$C$33,Lanç_Receitas!$E$6:$E$33,$C$1,Lanç_Receitas!$O$6:$O$33,I$2))) -> 0 | J18: =IF(ISERROR(IF(AND($C$1>=YEAR(TODAY()),MONTH(TODAY())<J$2),"",SUMIFS(Lanç_Receitas!$C$6:$C$33,Lanç_Receitas!$E$6:$E$33,$C$1,Lanç_Receitas!$O$6:$O$33,J$2))),"",IF(AND($C$1>=YEAR(TODAY()),MONTH(TODAY())<J$2),"",SUMIFS(Lanç_Receitas!$C$6:$C$33,Lanç_Receitas!$E$6:$E$33,$C$1,Lanç_Receitas!$O$6:$O$33,J$2))) -> 0 | ... N18: =IF(ISERROR(IF(AND($C$1>=YEAR(TODAY()),MONTH(TODAY())<N$2),"",SUMIFS(Lanç_Receitas!$C$6:$C$33,Lanç_Receitas!$E$6:$E$33,$C$1,Lanç_Receitas!$O$6:$O$33,N$2))),"",IF(AND($C$1>=YEAR(TODAY()),MONTH(TODAY())<N$2),"",SUMIFS(Lanç_Receitas!$C$6:$C$33,Lanç_Receitas!$E$6:$E$33,$C$1,Lanç_Receitas!$O$6:$O$33,N$2))) -> 0
A19: Receita média por funcionário | B19: =B18/B26 -> 0 | C19: =C18/C26 -> 0 | D19: =D18/D26 -> 0 | E19: =E18/E26 -> 0 | F19: =IF(ISERROR(F18/F26),"",F18/F26) -> 0 | G19: =IF(ISERROR(G18/G26),"",G18/G26) -> 0 | H19: =IF(ISERROR(H18/H26),"",H18/H26) -> 0 | I19: =IF(ISERROR(I18/I26),"",I18/I26) -> 0 | J19: =IF(ISERROR(J18/J26),"",J18/J26) -> 0 | K19: =IF(ISERROR(K18/K26),"",K18/K26) -> 0 | L19: =IF(ISERROR(L18/L26),"",L18/L26) -> 0 | M19: =IF(ISERROR(M18/M26),"",M18/M26) -> 0 | N19: =IF(ISERROR(N18/N26),"",N18/N26) -> 0
A20: Variação % | C20: =IF(ISERROR(IF(C19="","",C19/B19-1)),1,IF(C19="","",C19/B19-1)) -> 1 | D20: =IF(ISERROR(IF(D19="","",D19/C19-1)),1,IF(D19="","",D19/C19-1)) -> 1 | E20: =IF(ISERROR(IF(E19="","",E19/D19-1)),1,IF(E19="","",E19/D19-1)) -> 1 | F20: =IF(ISERROR(IF(F19="","",F19/E19-1)),1,IF(F19="","",F19/E19-1)) -> 1 | G20: =IF(ISERROR(IF(G19="","",G19/F19-1)),1,IF(G19="","",G19/F19-1)) -> 1 | H20: =IF(ISERROR(IF(H19="","",H19/G19-1)),1,IF(H19="","",H19/G19-1)) -> 1 | I20: =IF(ISERROR(IF(I19="","",I19/H19-1)),1,IF(I19="","",I19/H19-1)) -> 1 | J20: =IF(ISERROR(IF(J19="","",J19/I19-1)),1,IF(J19="","",J19/I19-1)) -> 1 | ... N20: =IF(ISERROR(IF(N19="","",N19/M19-1)),1,IF(N19="","",N19/M19-1)) -> 1
A22: Indicador | B22: ="Dez "&$B$1 -> Dez 2014 | C22: Jan | D22: Fev | E22: Mar | F22: Abr | G22: Mai | H22: Jun | I22: Jul | J22: Ago | K22: Set | L22: Out | M22: Nov | N22: Dez | O22: Total
A23: Admissões | B23: =IF(ISERROR(IF(AND($B$1>=YEAR(TODAY()),MONTH(TODAY())<B$2),"",COUNTIFS(Cad_Func!$W$8:$W$208,$B$1,Cad_Func!$X$8:$X$208,B$2))),"",IF(AND($B$1>=YEAR(TODAY()),MONTH(TODAY())<B$2),"",COUNTIFS(Cad_Func!$W$8:$W$208,$B$1,Cad_Func!$X$8:$X$208,B$2))) -> 1 | C23: =IF(ISERROR(IF(AND($C$1>=YEAR(TODAY()),MONTH(TODAY())<C$2),"",COUNTIFS(Cad_Func!$W$8:$W$208,$C$1,Cad_Func!$X$8:$X$208,C$2))),"",IF(AND($C$1>=YEAR(TODAY()),MONTH(TODAY())<C$2),"",COUNTIFS(Cad_Func!$W$8:$W$208,$C$1,Cad_Func!$X$8:$X$208,C$2))) -> 1 | D23: =IF(ISERROR(IF(AND($C$1>=YEAR(TODAY()),MONTH(TODAY())<D$2),"",COUNTIFS(Cad_Func!$W$8:$W$208,$C$1,Cad_Func!$X$8:$X$208,D$2))),"",IF(AND($C$1>=YEAR(TODAY()),MONTH(TODAY())<D$2),"",COUNTIFS(Cad_Func!$W$8:$W$208,$C$1,Cad_Func!$X$8:$X$208,D$2))) -> 2 | E23: =IF(ISERROR(IF(AND($C$1>=YEAR(TODAY()),MONTH(TODAY())<E$2),"",COUNTIFS(Cad_Func!$W$8:$W$208,$C$1,Cad_Func!$X$8:$X$208,E$2))),"",IF(AND($C$1>=YEAR(TODAY()),MONTH(TODAY())<E$2),"",COUNTIFS(Cad_Func!$W$8:$W$208,$C$1,Cad_Func!$X$8:$X$208,E$2))) -> 0 | F23: =IF(ISERROR(IF(AND($C$1>=YEAR(TODAY()),MONTH(TODAY())<F$2),"",COUNTIFS(Cad_Func!$W$8:$W$208,$C$1,Cad_Func!$X$8:$X$208,F$2))),"",IF(AND($C$1>=YEAR(TODAY()),MONTH(TODAY())<F$2),"",COUNTIFS(Cad_Func!$W$8:$W$208,$C$1,Cad_Func!$X$8:$X$208,F$2))) -> 0 | G23: =IF(ISERROR(IF(AND($C$1>=YEAR(TODAY()),MONTH(TODAY())<G$2),"",COUNTIFS(Cad_Func!$W$8:$W$208,$C$1,Cad_Func!$X$8:$X$208,G$2))),"",IF(AND($C$1>=YEAR(TODAY()),MONTH(TODAY())<G$2),"",COUNTIFS(Cad_Func!$W$8:$W$208,$C$1,Cad_Func!$X$8:$X$208,G$2))) -> 0 | H23: =IF(ISERROR(IF(AND($C$1>=YEAR(TODAY()),MONTH(TODAY())<H$2),"",COUNTIFS(Cad_Func!$W$8:$W$208,$C$1,Cad_Func!$X$8:$X$208,H$2))),"",IF(AND($C$1>=YEAR(TODAY()),MONTH(TODAY())<H$2),"",COUNTIFS(Cad_Func!$W$8:$W$208,$C$1,Cad_Func!$X$8:$X$208,H$2))) -> 0 | I23: =IF(ISERROR(IF(AND($C$1>=YEAR(TODAY()),MONTH(TODAY())<I$2),"",COUNTIFS(Cad_Func!$W$8:$W$208,$C$1,Cad_Func!$X$8:$X$208,I$2))),"",IF(AND($C$1>=YEAR(TODAY()),MONTH(TODAY())<I$2),"",COUNTIFS(Cad_Func!$W$8:$W$208,$C$1,Cad_Func!$X$8:$X$208,I$2))) -> 0 | J23: =IF(ISERROR(IF(AND($C$1>=YEAR(TODAY()),MONTH(TODAY())<J$2),"",COUNTIFS(Cad_Func!$W$8:$W$208,$C$1,Cad_Func!$X$8:$X$208,J$2))),"",IF(AND($C$1>=YEAR(TODAY()),MONTH(TODAY())<J$2),"",COUNTIFS(Cad_Func!$W$8:$W$208,$C$1,Cad_Func!$X$8:$X$208,J$2))) -> 0 | ... N23: =IF(ISERROR(IF(AND($C$1>=YEAR(TODAY()),MONTH(TODAY())<N$2),"",COUNTIFS(Cad_Func!$W$8:$W$208,$C$1,Cad_Func!$X$8:$X$208,N$2))),"",IF(AND($C$1>=YEAR(TODAY()),MONTH(TODAY())<N$2),"",COUNTIFS(Cad_Func!$W$8:$W$208,$C$1,Cad_Func!$X$8:$X$208,N$2))) -> 0
A24: Demissões | B24: =IF(ISERROR(IF(AND($B$1>=YEAR(TODAY()),MONTH(TODAY())<B$2),"",COUNTIFS(Cad_Func!$Y$8:$Y$208,RC_Rotatividade!#REF!,Cad_Func!$Z$8:$Z$208,RC_Rotatividade!E$6))),"",IF(AND($B$1>=YEAR(TODAY()),MONTH(TODAY())<B$2),"",COUNTIFS(Cad_Func!$Y$8:$Y$208,RC_Rotatividade!#REF!,Cad_Func!$Z$8:$Z$208,RC_Rotatividade!E$6))) -> 0 | C24: =IF(ISERROR(IF(AND($C$1>=YEAR(TODAY()),MONTH(TODAY())<C$2),"",COUNTIFS(Cad_Func!$Y$8:$Y$208,RC_Rotatividade!#REF!,Cad_Func!$Z$8:$Z$208,RC_Rotatividade!F$6))),"",IF(AND($C$1>=YEAR(TODAY()),MONTH(TODAY())<C$2),"",COUNTIFS(Cad_Func!$Y$8:$Y$208,RC_Rotatividade!#REF!,Cad_Func!$Z$8:$Z$208,RC_Rotatividade!F$6))) -> 0 | D24: =IF(ISERROR(IF(AND($C$1>=YEAR(TODAY()),MONTH(TODAY())<D$2),"",COUNTIFS(Cad_Func!$Y$8:$Y$208,RC_Rotatividade!#REF!,Cad_Func!$Z$8:$Z$208,RC_Rotatividade!G$6))),"",IF(AND($C$1>=YEAR(TODAY()),MONTH(TODAY())<D$2),"",COUNTIFS(Cad_Func!$Y$8:$Y$208,RC_Rotatividade!#REF!,Cad_Func!$Z$8:$Z$208,RC_Rotatividade!G$6))) -> 0 | E24: =IF(ISERROR(IF(AND($C$1>=YEAR(TODAY()),MONTH(TODAY())<E$2),"",COUNTIFS(Cad_Func!$Y$8:$Y$208,RC_Rotatividade!#REF!,Cad_Func!$Z$8:$Z$208,RC_Rotatividade!H$6))),"",IF(AND($C$1>=YEAR(TODAY()),MONTH(TODAY())<E$2),"",COUNTIFS(Cad_Func!$Y$8:$Y$208,RC_Rotatividade!#REF!,Cad_Func!$Z$8:$Z$208,RC_Rotatividade!H$6))) -> 0 | F24: =IF(ISERROR(IF(AND($C$1>=YEAR(TODAY()),MONTH(TODAY())<F$2),"",COUNTIFS(Cad_Func!$Y$8:$Y$208,RC_Rotatividade!#REF!,Cad_Func!$Z$8:$Z$208,RC_Rotatividade!I$6))),"",IF(AND($C$1>=YEAR(TODAY()),MONTH(TODAY())<F$2),"",COUNTIFS(Cad_Func!$Y$8:$Y$208,RC_Rotatividade!#REF!,Cad_Func!$Z$8:$Z$208,RC_Rotatividade!I$6))) -> 0 | G24: =IF(ISERROR(IF(AND($C$1>=YEAR(TODAY()),MONTH(TODAY())<G$2),"",COUNTIFS(Cad_Func!$Y$8:$Y$208,RC_Rotatividade!#REF!,Cad_Func!$Z$8:$Z$208,RC_Rotatividade!J$6))),"",IF(AND($C$1>=YEAR(TODAY()),MONTH(TODAY())<G$2),"",COUNTIFS(Cad_Func!$Y$8:$Y$208,RC_Rotatividade!#REF!,Cad_Func!$Z$8:$Z$208,RC_Rotatividade!J$6))) -> 0 | H24: =IF(ISERROR(IF(AND($C$1>=YEAR(TODAY()),MONTH(TODAY())<H$2),"",COUNTIFS(Cad_Func!$Y$8:$Y$208,RC_Rotatividade!#REF!,Cad_Func!$Z$8:$Z$208,RC_Rotatividade!K$6))),"",IF(AND($C$1>=YEAR(TODAY()),MONTH(TODAY())<H$2),"",COUNTIFS(Cad_Func!$Y$8:$Y$208,RC_Rotatividade!#REF!,Cad_Func!$Z$8:$Z$208,RC_Rotatividade!K$6))) -> 0 | I24: =IF(ISERROR(IF(AND($C$1>=YEAR(TODAY()),MONTH(TODAY())<I$2),"",COUNTIFS(Cad_Func!$Y$8:$Y$208,RC_Rotatividade!#REF!,Cad_Func!$Z$8:$Z$208,RC_Rotatividade!L$6))),"",IF(AND($C$1>=YEAR(TODAY()),MONTH(TODAY())<I$2),"",COUNTIFS(Cad_Func!$Y$8:$Y$208,RC_Rotatividade!#REF!,Cad_Func!$Z$8:$Z$208,RC_Rotatividade!L$6))) -> 0 | J24: =IF(ISERROR(IF(AND($C$1>=YEAR(TODAY()),MONTH(TODAY())<J$2),"",COUNTIFS(Cad_Func!$Y$8:$Y$208,RC_Rotatividade!#REF!,Cad_Func!$Z$8:$Z$208,RC_Rotatividade!M$6))),"",IF(AND($C$1>=YEAR(TODAY()),MONTH(TODAY())<J$2),"",COUNTIFS(Cad_Func!$Y$8:$Y$208,RC_Rotatividade!#REF!,Cad_Func!$Z$8:$Z$208,RC_Rotatividade!M$6))) -> 0 | ... N24: =IF(ISERROR(IF(AND($C$1>=YEAR(TODAY()),MONTH(TODAY())<N$2),"",COUNTIFS(Cad_Func!$Y$8:$Y$208,RC_Rotatividade!#REF!,Cad_Func!$Z$8:$Z$208,RC_Rotatividade!Q$6))),"",IF(AND($C$1>=YEAR(TODAY()),MONTH(TODAY())<N$2),"",COUNTIFS(Cad_Func!$Y$8:$Y$208,RC_Rotatividade!#REF!,Cad_Func!$Z$8:$Z$208,RC_Rotatividade!Q$6))) -> 0
A25: Funcionários no início do mês | C25: =IF(ISERROR(IF(AND($C$1>=YEAR(TODAY()),MONTH(TODAY())<C$2),"",B26)),"",IF(AND($C$1>=YEAR(TODAY()),MONTH(TODAY())<C$2),"",B26)) -> 9 | D25: =IF(ISERROR(IF(AND($C$1>=YEAR(TODAY()),MONTH(TODAY())<D$2),"",C26)),"",IF(AND($C$1>=YEAR(TODAY()),MONTH(TODAY())<D$2),"",C26)) -> 10 | E25: =IF(ISERROR(IF(AND($C$1>=YEAR(TODAY()),MONTH(TODAY())<E$2),"",D26)),"",IF(AND($C$1>=YEAR(TODAY()),MONTH(TODAY())<E$2),"",D26)) -> 12 | F25: =IF(ISERROR(IF(AND($C$1>=YEAR(TODAY()),MONTH(TODAY())<F$2),"",E26)),"",IF(AND($C$1>=YEAR(TODAY()),MONTH(TODAY())<F$2),"",E26)) -> 12 | G25: =IF(ISERROR(IF(AND($C$1>=YEAR(TODAY()),MONTH(TODAY())<G$2),"",F26)),"",IF(AND($C$1>=YEAR(TODAY()),MONTH(TODAY())<G$2),"",F26)) -> 12 | H25: =IF(ISERROR(IF(AND($C$1>=YEAR(TODAY()),MONTH(TODAY())<H$2),"",G26)),"",IF(AND($C$1>=YEAR(TODAY()),MONTH(TODAY())<H$2),"",G26)) -> 12 | I25: =IF(ISERROR(IF(AND($C$1>=YEAR(TODAY()),MONTH(TODAY())<I$2),"",H26)),"",IF(AND($C$1>=YEAR(TODAY()),MONTH(TODAY())<I$2),"",H26)) -> 12 | J25: =IF(ISERROR(IF(AND($C$1>=YEAR(TODAY()),MONTH(TODAY())<J$2),"",I26)),"",IF(AND($C$1>=YEAR(TODAY()),MONTH(TODAY())<J$2),"",I26)) -> 12 | ... N25: =IF(ISERROR(IF(AND($C$1>=YEAR(TODAY()),MONTH(TODAY())<N$2),"",M26)),"",IF(AND($C$1>=YEAR(TODAY()),MONTH(TODAY())<N$2),"",M26)) -> 12
A26: Funcionários no fim do mês | B26: =IF(ISERROR(SUM(Cad_Func!$Q$8:$Q$208)),"",SUM(Cad_Func!$Q$8:$Q$208)) -> 9 | C26: =IF(ISERROR(C25+C23-C24),"",C25+C23-C24) -> 10 | D26: =IF(ISERROR(D25+D23-D24),"",D25+D23-D24) -> 12 | E26: =IF(ISERROR(E25+E23-E24),"",E25+E23-E24) -> 12 | F26: =IF(ISERROR(F25+F23-F24),"",F25+F23-F24) -> 12 | G26: =IF(ISERROR(G25+G23-G24),"",G25+G23-G24) -> 12 | H26: =IF(ISERROR(H25+H23-H24),"",H25+H23-H24) -> 12 | I26: =IF(ISERROR(I25+I23-I24),"",I25+I23-I24) -> 12 | J26: =IF(ISERROR(J25+J23-J24),"",J25+J23-J24) -> 12 | ... N26: =IF(ISERROR(N25+N23-N24),"",N25+N23-N24) -> 12

Sheet RI
C1: 6. RELATÓRIO PARA IMPRESSÃO
C6: RELATÓRIO IMPRESSO
C7: PLANILHA DE INDICADORES DE RH 3.0
C9: =Cad_Inicial!D7&" - "&Cad_Inicial!D8 -> LUZ Planilhas Empresariais - 2015
C11: 1. Geral
C12: 2. Rotatividade
C13: 3. Perfil da equipe
C14: 4. Eventos de RH
C15: 5. Receitas e Custos
C16: 6. Gráficos
C17: 7. Alertas e dicas
C19: 1. Geral
C20: ='RC'!C6:E6 -> Indicadores de rotatividade para 2015 | F20: Resultado
C21: Média de permanência de funcionários na empresa | F21: ='RC'!F7 -> 86 meses
C22: ='RC'!C8:E8 -> Admissões em 2015 | F22: ='RC'!F8 -> 3
C23: ='RC'!C9:E9 -> Demissões em 2015 | F23: ='RC'!F9 -> 1
C24: ='RC'!C10:E10 -> Total de funcionários em 2015 | F24: ='RC'!F10 -> 11
C25: Índice de aprovação após período de experiência | F25: ='RC'!F11 -> 1
C26: Índice de Turnover (rotatividade) | F26: ='RC'!F12 -> 0.18181818
C28: ='RC'!C14:E14 -> Indicadores de treinamento para 2015 | F28: Resultado
C29: Total de horas de treinamento | F29: ='RC'!F15 -> 140 horas
C30: Média de horas de treinamento por funcionário treinado | F30: ='RC'!F16 -> 18 horas
C31: Número de funcionários treinados | F31: ='RC'!F17 -> 8 funcionários
C33: ='RC'!C19:E19 -> Custos para 2015 | F33: Resultado
C34: Custo total com hora extra | F34: ='RC'!F20 -> 3012
C35: Custo total com folha de pagamento (benefícios + custos) | F35: ='RC'!F21 -> 315142
C36: % do custo total de treinamentos sobre o total da folha de pagamento | F36: ='RC'!F22 -> 0
C37: Custo médio por funcionário treinado | F37: ='RC'!F23 -> 0
C38: % dos benefícios sobre a folha de pagamento | F38: ='RC'!F24 -> 0.066655666
C39: Custo dos benefícios sobre a folha de pagamento | F39: ='RC'!F25 -> 21006
C40: Custo médio dos benefícios para cada funcionário | F40: ='RC'!F26 -> 1909.6364
C41: Receita gerada por cada funcionário | F41: ='RC'!F27 -> 163636.91
C42: Custo gerado por cada funcionário | F42: ='RC'!F28 -> 26739.636
C44: 2. Rotatividade
C45: =RC_Rotatividade!C7 -> Resumo de indicadores de rotatividade (mensal) para 2015
C46: Indicador | E46: Jan | F46: Fev | G46: Mar | H46: Abr | I46: Mai | L46: Jun | M46: Jul | N46: Ago | O46: Set | P46: Out | Q46: Nov | S46: Dez | T46: Média | U46: Total
