Workbook

Sheet Previsão Orçamentária 
B1: Orçamento de Junho de 2018 até junho de 2019
B3: Condomínio
B4: DESPESAS ORDINÁRIAS | C4: Valor | D4: índice de reajuste | E4: Prev. Orç Mensal | F4: N° | G4: Prev. Orç Anual
B5: CONSELHEIROS (3)/SUBSINDICO | C5: 584 | D5: 50% DA TAXA | E5: 876 | F5: 12 | G5: =(E5*F5) -> 10512 | L5: Descrição | M5: Gasto Real | N5: Previsto | O5: Variação
B6: PROLABORE/ISENÇÃO SÍNDICO | C6: 2144.2 | D6: 0.05 | E6: =(C6*D6)+C6 -> 2251.41 | F6: 12 | G6: =(E6*F6) -> 27016.92 | L6: Cto Portaria | M6: 60808.717 | N6: 60900 | O6: =N6-M6 -> 91.2826
B7: INSS PATRONAL 20% | C7: =(C6+C5)*20% -> 545.64 | E7: =C7 -> 545.64 | F7: 12 | G7: =E7*F7 -> 6547.68
B8: FOLHA DE PAGAMENTO | C8: ='Folha de Pagamento'!L24 -> 15990.42 | D8: 0.05 | E8: =(C8*D8)+C8 -> 16789.941 | F8: 12 | G8: =E8*F8 -> 201479.29 | L8: Cto Limpeza | M8: 36840.718 | N8: 30900 | O8: =N8-M8 -> -5940.718
B9: PROVISÕES DA FOLHA + FERIADOS | C9: ='Folha de Pagamento'!L23+300 -> 1658.97 | D9: 0.05 | E9: =(C9*D9)+C9 -> 1741.9185 | F9: 12 | G9: =E9*F9 -> 20903.022
B10: PMSO/PPRA/LTCAT/CIPA/NR35 | C10: =800+180+120 -> 1100 | E10: =(C10*D10)+C10 -> 1100 | F10: 1 | G10: =E10*F10 -> 1100
B11: UNIFORMES/EPI | C11: 300 | E11: =(C11*D11)+C11 -> 300 | F11: 1 | G11: =E11*F11 -> 300
B12: SINDICATO | C12: 0 | E12: =(C12*D12)+C12 -> 0 | F12: 12 | G12: =E12*F12 -> 0
B13: CONVÊNIO MÉDICO | C13: 0 | E13: =(C13*D13)+C13 -> 0 | F13: 12 | G13: =E13*F13 -> 0
B14: CESTA BÁSICA | C14: =60*8 -> 480 | E14: =(C14*D14)+C14 -> 480 | F14: 12 | G14: =E14*F14 -> 5760
B15: CONTABILIDADE | C15: 983.85 | D15: 0.05 | E15: =(C15*D15)+C15 -> 1033.0425 | F15: 12 | G15: =E15*F15 -> 12396.51
B16: DESPESAS COPIAS | C16: 50 | E16: =(C16*D16)+C16 -> 50 | F16: 1 | G16: =E16*F16 -> 50
B17: ALUGUEL DE RETROPROJETOR | C17: 300 | E17: =(C17*D17)+C17 -> 300 | F17: 2 | G17: =E17*F17 -> 600
B18: DESPESAS COM PROCESSOS COBRANÇA | C18: 3000 | E18: =(C18*D18)+C18 -> 3000 | F18: 1 | G18: =E18*F18 -> 3000
B19: TARIFA BANCARIA | C19: =50+90 -> 140 | E19: =(C19*D19)+C19 -> 140 | F19: 12 | G19: =E19*F19 -> 1680
B20: CERTIFICADO DIGITAL ( ANUAL) | C20: 385 | E20: =(C20*D20)+C20 -> 385 | F20: 1 | G20: =E20*F20 -> 385
B21: CARTORIO | C21: 300 | E21: =(C21*D21)+C21 -> 300 | F21: 1 | G21: =E21*F21 -> 300
B22: ENERGIA ELÉTRICA | C22: 5500 | E22: =(C22*D22)+C22 -> 5500 | F22: 12 | G22: =E22*F22 -> 66000
B23: ÁGUA E ESGOTO | C23: 1550 | E23: =(C23*D23)+C23 -> 1550 | F23: 12 | G23: =E23*F23 -> 18600
B24: TELEFONE FIXO/MÓVEL E INTERNET | C24: =400 -> 400 | E24: =(C24*D24)+C24 -> 400 | F24: 12 | G24: =E24*F24 -> 4800
B25: MATERIAL DE ESCRITÓRIO | C25: =150 -> 150 | E25: =(C25*D25)+C25 -> 150 | F25: 6 | G25: =E25*F25 -> 900
B26: SEGUROS PATRIMONIAIS | C26: =620 -> 620 | D26: 0.05 | E26: =(C26*D26)+C26 -> 651 | F26: =12/3 -> 4 | G26: =E26*F26 -> 2604
B27: CONTRATO PORTARIA | E27: =(C27*D27)+C27 -> 0 | G27: =E27*F27 -> 0
B28: CONTRATO LIMPEZA | E28: =(C28*D28)+C28 -> 0 | G28: =E28*F28 -> 0
B29: CONTRATO PORTARIA/LIMPEZA | E29: =SUM(E30:E45) -> 7238 | F29: =SUM(F30:F41) -> 55 | G29: =SUM(G30:G45) -> 17480 | L29: Admin | M29: 5979.07 | N29: 5880 | O29: =N29-M29 -> -99.07
B30: CTO QUIMICA PISCINA/JARDIM | C30: 300 | E30: =(C30*D30)+C30 -> 300 | F30: 12 | G30: =E30*F30 -> 3600 | L30: Tubulação-Fiação | M30: 0 | N30: 0 | O30: =N30-M30 -> 0
B31: MANUTENÇÃO CAIXA DE ÁGUA | C31: =200*8 -> 1600 | E31: =(C31*D31)+C31 -> 1600 | F31: 1 | G31: =E31*F31 -> 1600 | L31: Extintores | M31: 1470 | N31: 360 | O31: =N31-M31 -> -1110
B32: DESINSETIZAÇÃO E DESRATIFICAÇÃO | C32: =600 -> 600 | E32: =(C32*D32)+C32 -> 600 | F32: 1 | G32: =E32*F32 -> 600
B33: MANUTENÇÃO BOMBAS E FILTROS ( PAINEL CAIXA DE ÁGUA E MOTOR PISCINA) | C33: =200*8 -> 1600 | E33: =C33 -> 1600 | F33: 1 | G33: =E33*F33 -> 1600
B34: MANUTENÇÃO PORTÃO GARAGEM | C34: 350 | E34: =(C34*D34)+C34 -> 350 | F34: 4 | G34: =E34*F34 -> 1400 | L34: Móveis | M34: 230 | N34: 0 | O34: =N34-M34 -> -230
B35: COMPRA DE LÂMPADAS E MAT ELÊTRICOS ( LED)/PEÇAS | C35: =18+50 -> 68 | E35: =(C35*D35)+C35 -> 68 | F35: 20 | G35: =E35*F35 -> 1360 | L35: Lixeiras | M35: 0 | N35: 0 | O35: =N35-M35 -> 0
B36: MATERIAL DE LIMPEZA PISCINA | C36: 300 | E36: =(C36*D36)+C36 -> 300 | F36: 6 | G36: =E36*F36 -> 1800 | L36: Hidrômetros | M36: 0 | N36: 0 | O36: =N36-M36 -> 0
B37: MATERIAL DE LIMPEZA | C37: 500 | E37: =(C37*D37)+C37 -> 500 | F37: 6 | G37: =E37*F37 -> 3000
B38: RECARGA DOS EXTINTORES/MANUTENÇÃO DAS MANGUEIRAS | C38: =720 -> 720 | E38: =(C38*D38)+C38 -> 720 | F38: 1 | G38: =C38*F38 -> 720 | L38: Locação | M38: 0 | N38: 0 | O38: =N38-M38 -> 0
B39: LIMPEZA DE AR CONDICIONADO SALÃO DE FESTAS/PORTARIA | C39: 400 | E39: =(C39*D39)+C39 -> 400 | F39: 1 | G39: =E39*F39 -> 400 | L39: Devolução pgto a maior | M39: 269.04 | N39: 0 | O39: =N39-M39 -> -269.04
B40: PLANO DE COMBATE Á INCÊNDIO- CURSO BRIGADISTA 4 em 4 anos | E40: =(C40*D40)+C40 -> 0 | F40: 1 | G40: =E40*F40 -> 0 | L40: Material Psicina | M40: 644 | N40: 0 | O40: =N40-M40 -> -644
B41: RENOVAÇÃO ALVARÁ PPCI ( 2 EM 2 ANOS) | E41: =(C41*D41)+C41 -> 0 | F41: 1 | G41: =E41*F41 -> 0 | L41: Desinsetização | M41: 445 | N41: 0 | O41: =N41-M41 -> -445
...

Sheet taxa distribuidia por n de apto
C1: 2018 | D1: 64 | E1: número de aptos
A2: SUBTOTAL | C2: =SUM(B3:C6) -> 704.85374
A3: Fundo de reserva (fixo) | C3: =('Previsão Orçamentária '!G68/'taxa distribuidia por n de apto'!$D$1)/12 -> 40.640587
A4: Fundo de obras | C4: =('Previsão Orçamentária '!G69/'taxa distribuidia por n de apto'!$D$1)/12 -> 0
A5: Fundo | C5: =('Previsão Orçamentária '!G70/'taxa distribuidia por n de apto'!$D$1)/12 -> 0
A6: Taxa sem fundo ( principal) | C6: =(('Previsão Orçamentária '!G75-'Previsão Orçamentária '!G71)/'taxa distribuidia por n de apto'!$D$1)/12 -> 664.21315
A8: TAXA | C8: =C2+C7 -> 704.85374

Sheet taxa distribuidia por fração
A1: TOTAL DA PREVISÃO ORÇAMENTÁRIA (SEM FUNDOS) | D1: ='Previsão Orçamentária '!G65+'Previsão Orçamentária '!G74 -> 510115.7
A2: TOTAL DA PREVISÃO ORÇAMENTÁRIA FUNDOS DE RESERVA | D2: ='Previsão Orçamentária '!G68 -> 31211.971
A3: TOTAL DA PREVISÃO ORÇAMENTÁRIA FUNDOS DE OBRAS | D3: ='Previsão Orçamentária '!$G$69 -> 0
A4: TOTAL DA PREVISÃO ORÇAMENTÁRIA FUNDOS | D4: ='Previsão Orçamentária '!G70 -> 0
D5: =SUM(D1:D3) -> 541327.67
A7: ECONOMIA | B7: FRAÇÃO | C7: TAXA | D7: FUNDO 1 | E7: FUNDO 2 | F7: TOTAL | H7: ECONOMIA | I7: FRAÇÃO | J7: TAXA | K7: FUNDO 1 | L7: FUNDO 2 | M7: TOTAL | O7: ECONOMIA | P7: FRAÇÃO | Q7: TAXA | R7: FUNDO 1 | S7: FUNDO 2 | T7: TOTAL | V7: ECONOMIA | W7: FRAÇÃO | X7: TAXA | Y7: FUNDO 1 | Z7: FUNDO 2 | AA7: TOTAL | AC7: BOXES | AD7: FRAÇÃO | AE7: VALOR | AF7: FUNDO 1 | AG7: FUNDO 2 | AH7: TOTAL | AJ7: BOXES | AK7: FRAÇÃO | AL7: VALOR | AM7: FUNDO 1 | AN7: FUNDO 2 | AO7: TOTAL | AQ7: BOXES | AR7: FRAÇÃO | AS7: VALOR | AT7: FUNDO 1 | AU7: FUNDO 2 | AV7: TOTAL | AX7: BOXES | AY7: FRAÇÃO | AZ7: VALOR | BA7: FUNDO 1 | BB7: FUNDO 2 | BC7: TOTAL
A8: 101 | B8: 0.00614 | C8: =(B8*$D$1)/12 -> 261.0092 | D8: =($D$2*B8)/12 -> 15.970125 | E8: =($D$3*B8)/12 -> 0 | F8: =SUM(C8:E8) -> 276.97932 | H8: 501 | I8: 0.005892 | J8: =(I8*$D$1)/12 -> 250.46681 | K8: =($D$2*I8)/12 -> 15.325078 | L8: =($D$3*I8)/12 -> 0 | M8: =SUM(J8:L8) -> 265.79189 | O8: 101 | P8: 0.00614 | Q8: =(P8*$D$1)/12 -> 261.0092 | R8: =($D$2*P8)/12 -> 15.970125 | S8: =($D$3*P8)/12 -> 0 | T8: =SUM(Q8:S8) -> 276.97932 | V8: 501 | W8: 0.005892 | X8: =(W8*$D$1)/12 -> 250.46681 | Y8: =($D$2*W8)/12 -> 15.325078 | Z8: =($D$3*W8)/12 -> 0 | AA8: =SUM(X8:Z8) -> 265.79189 | AC8: 1 | AD8: 0.000767 | AE8: =(AD8*$D$1)/12 -> 32.604895 | AF8: =($D$2*AD8)/12 -> 1.9949651 | AG8: =($D$3*AD8)/12 -> 0 | AH8: =SUM(AE8:AG8) -> 34.59986 | AJ8: 67 | AK8: 0.000767 | AL8: =(AK8*$D$1)/12 -> 32.604895 | AM8: =($D$2*AK8)/12 -> 1.9949651 | AN8: =($D$3*AK8)/12 -> 0 | AO8: =SUM(AL8:AN8) -> 34.59986 | AQ8: 131 | AR8: 0.000767 | AS8: =(AR8*$D$1)/12 -> 32.604895 | AT8: =($D$2*AR8)/12 -> 1.9949651 | AU8: =($D$3*AR8)/12 -> 0 | AV8: =SUM(AS8:AU8) -> 34.59986 | AX8: 195 | AY8: 0.000767 | AZ8: =(AY8*$D$1)/12 -> 32.604895 | BA8: =($D$2*AY8)/12 -> 1.9949651 | BB8: =($D$3*AY8)/12 -> 0 | BC8: =SUM(AZ8:BB8) -> 34.59986
A9: 102 | B9: 0.007002 | C9: =(B9*$D$1)/12 -> 297.65251 | D9: =($D$2*B9)/12 -> 18.212185 | E9: =($D$3*B9)/12 -> 0 | F9: =SUM(C9:E9) -> 315.8647 | H9: 502 | I9: 0.006749 | J9: =(I9*$D$1)/12 -> 286.89757 | K9: =($D$2*I9)/12 -> 17.554133 | L9: =($D$3*I9)/12 -> 0 | M9: =SUM(J9:L9) -> 304.4517 | O9: 102 | P9: 0.007002 | Q9: =(P9*$D$1)/12 -> 297.65251 | R9: =($D$2*P9)/12 -> 18.212185 | S9: =($D$3*P9)/12 -> 0 | T9: =SUM(Q9:S9) -> 315.8647 | V9: 502 | W9: 0.006749 | X9: =(W9*$D$1)/12 -> 286.89757 | Y9: =($D$2*W9)/12 -> 17.554133 | Z9: =($D$3*W9)/12 -> 0 | AA9: =SUM(X9:Z9) -> 304.4517 | AC9: 2 | AD9: 0.000767 | AE9: =(AD9*$D$1)/12 -> 32.604895 | AF9: =($D$2*AD9)/12 -> 1.9949651 | AG9: =($D$3*AD9)/12 -> 0 | AH9: =SUM(AE9:AG9) -> 34.59986 | AJ9: 68 | AK9: 0.000767 | AL9: =(AK9*$D$1)/12 -> 32.604895 | AM9: =($D$2*AK9)/12 -> 1.9949651 | AN9: =($D$3*AK9)/12 -> 0 | AO9: =SUM(AL9:AN9) -> 34.59986 | AQ9: 132 | AR9: 0.000767 | AS9: =(AR9*$D$1)/12 -> 32.604895 | AT9: =($D$2*AR9)/12 -> 1.9949651 | AU9: =($D$3*AR9)/12 -> 0 | AV9: =SUM(AS9:AU9) -> 34.59986 | AX9: 196 | AY9: 0.000767 | AZ9: =(AY9*$D$1)/12 -> 32.604895 | BA9: =($D$2*AY9)/12 -> 1.9949651 | BB9: =($D$3*AY9)/12 -> 0 | BC9: =SUM(AZ9:BB9) -> 34.59986
A10: 103 | B10: 0.007002 | C10: =(B10*$D$1)/12 -> 297.65251 | D10: =($D$2*B10)/12 -> 18.212185 | E10: =($D$3*B10)/12 -> 0 | F10: =SUM(C10:E10) -> 315.8647 | H10: 503 | I10: 0.006749 | J10: =(I10*$D$1)/12 -> 286.89757 | K10: =($D$2*I10)/12 -> 17.554133 | L10: =($D$3*I10)/12 -> 0 | M10: =SUM(J10:L10) -> 304.4517 | O10: 103 | P10: 0.007002 | Q10: =(P10*$D$1)/12 -> 297.65251 | R10: =($D$2*P10)/12 -> 18.212185 | S10: =($D$3*P10)/12 -> 0 | T10: =SUM(Q10:S10) -> 315.8647 | V10: 503 | W10: 0.006749 | X10: =(W10*$D$1)/12 -> 286.89757 | Y10: =($D$2*W10)/12 -> 17.554133 | Z10: =($D$3*W10)/12 -> 0 | AA10: =SUM(X10:Z10) -> 304.4517 | AC10: 3 | AD10: 0.000767 | AE10: =(AD10*$D$1)/12 -> 32.604895 | AF10: =($D$2*AD10)/12 -> 1.9949651 | AG10: =($D$3*AD10)/12 -> 0 | AH10: =SUM(AE10:AG10) -> 34.59986 | AJ10: 69 | AK10: 0.000767 | AL10: =(AK10*$D$1)/12 -> 32.604895 | AM10: =($D$2*AK10)/12 -> 1.9949651 | AN10: =($D$3*AK10)/12 -> 0 | AO10: =SUM(AL10:AN10) -> 34.59986 | AQ10: 133 | AR10: 0.000767 | AS10: =(AR10*$D$1)/12 -> 32.604895 | AT10: =($D$2*AR10)/12 -> 1.9949651 | AU10: =($D$3*AR10)/12 -> 0 | AV10: =SUM(AS10:AU10) -> 34.59986 | AX10: 197 | AY10: 0.000767 | AZ10: =(AY10*$D$1)/12 -> 32.604895 | BA10: =($D$2*AY10)/12 -> 1.9949651 | BB10: =($D$3*AY10)/12 -> 0 | BC10: =SUM(AZ10:BB10) -> 34.59986
A11: 104 | B11: 0.006272 | C11: =(B11*$D$1)/12 -> 266.62047 | D11: =($D$2*B11)/12 -> 16.313457 | E11: =($D$3*B11)/12 -> 0 | F11: =SUM(C11:E11) -> 282.93393 | H11: 504 | I11: 0.005892 | J11: =(I11*$D$1)/12 -> 250.46681 | K11: =($D$2*I11)/12 -> 15.325078 | L11: =($D$3*I11)/12 -> 0 | M11: =SUM(J11:L11) -> 265.79189 | O11: 104 | P11: 0.006272 | Q11: =(P11*$D$1)/12 -> 266.62047 | R11: =($D$2*P11)/12 -> 16.313457 | S11: =($D$3*P11)/12 -> 0 | T11: =SUM(Q11:S11) -> 282.93393 | V11: 504 | W11: 0.005892 | X11: =(W11*$D$1)/12 -> 250.46681 | Y11: =($D$2*W11)/12 -> 15.325078 | Z11: =($D$3*W11)/12 -> 0 | AA11: =SUM(X11:Z11) -> 265.79189 | AC11: 4 | AD11: 0.000767 | AE11: =(AD11*$D$1)/12 -> 32.604895 | AF11: =($D$2*AD11)/12 -> 1.9949651 | AG11: =($D$3*AD11)/12 -> 0 | AH11: =SUM(AE11:AG11) -> 34.59986 | AJ11: 70 | AK11: 0.000767 | AL11: =(AK11*$D$1)/12 -> 32.604895 | AM11: =($D$2*AK11)/12 -> 1.9949651 | AN11: =($D$3*AK11)/12 -> 0 | AO11: =SUM(AL11:AN11) -> 34.59986 | AQ11: 134 | AR11: 0.000767 | AS11: =(AR11*$D$1)/12 -> 32.604895 | AT11: =($D$2*AR11)/12 -> 1.9949651 | AU11: =($D$3*AR11)/12 -> 0 | AV11: =SUM(AS11:AU11) -> 34.59986 | AX11: 198 | AY11: 0.000767 | AZ11: =(AY11*$D$1)/12 -> 32.604895 | BA11: =($D$2*AY11)/12 -> 1.9949651 | BB11: =($D$3*AY11)/12 -> 0 | BC11: =SUM(AZ11:BB11) -> 34.59986
A12: 105 | B12: 0.006272 | C12: =(B12*$D$1)/12 -> 266.62047 | D12: =($D$2*B12)/12 -> 16.313457 | E12: =($D$3*B12)/12 -> 0 | F12: =SUM(C12:E12) -> 282.93393 | H12: 505 | I12: 0.005895 | J12: =(I12*$D$1)/12 -> 250.59434 | K12: =($D$2*I12)/12 -> 15.332881 | L12: =($D$3*I12)/12 -> 0 | M12: =SUM(J12:L12) -> 265.92722 | O12: 105 | P12: 0.006272 | Q12: =(P12*$D$1)/12 -> 266.62047 | R12: =($D$2*P12)/12 -> 16.313457 | S12: =($D$3*P12)/12 -> 0 | T12: =SUM(Q12:S12) -> 282.93393 | V12: 505 | W12: 0.005895 | X12: =(W12*$D$1)/12 -> 250.59434 | Y12: =($D$2*W12)/12 -> 15.332881 | Z12: =($D$3*W12)/12 -> 0 | AA12: =SUM(X12:Z12) -> 265.92722 | AC12: 5 | AD12: 0.000767 | AE12: =(AD12*$D$1)/12 -> 32.604895 | AF12: =($D$2*AD12)/12 -> 1.9949651 | AG12: =($D$3*AD12)/12 -> 0 | AH12: =SUM(AE12:AG12) -> 34.59986 | AJ12: 71 | AK12: 0.000767 | AL12: =(AK12*$D$1)/12 -> 32.604895 | AM12: =($D$2*AK12)/12 -> 1.9949651 | AN12: =($D$3*AK12)/12 -> 0 | AO12: =SUM(AL12:AN12) -> 34.59986 | AQ12: 135 | AR12: 0.000767 | AS12: =(AR12*$D$1)/12 -> 32.604895 | AT12: =($D$2*AR12)/12 -> 1.9949651 | AU12: =($D$3*AR12)/12 -> 0 | AV12: =SUM(AS12:AU12) -> 34.59986 | AX12: 199 | AY12: 0.000767 | AZ12: =(AY12*$D$1)/12 -> 32.604895 | BA12: =($D$2*AY12)/12 -> 1.9949651 | BB12: =($D$3*AY12)/12 -> 0 | BC12: =SUM(AZ12:BB12) -> 34.59986
A13: 106 | B13: 0.007002 | C13: =(B13*$D$1)/12 -> 297.65251 | D13: =($D$2*B13)/12 -> 18.212185 | E13: =($D$3*B13)/12 -> 0 | F13: =SUM(C13:E13) -> 315.8647 | H13: 506 | I13: 0.006749 | J13: =(I13*$D$1)/12 -> 286.89757 | K13: =($D$2*I13)/12 -> 17.554133 | L13: =($D$3*I13)/12 -> 0 | M13: =SUM(J13:L13) -> 304.4517 | O13: 106 | P13: 0.007002 | Q13: =(P13*$D$1)/12 -> 297.65251 | R13: =($D$2*P13)/12 -> 18.212185 | S13: =($D$3*P13)/12 -> 0 | T13: =SUM(Q13:S13) -> 315.8647 | V13: 506 | W13: 0.006749 | X13: =(W13*$D$1)/12 -> 286.89757 | Y13: =($D$2*W13)/12 -> 17.554133 | Z13: =($D$3*W13)/12 -> 0 | AA13: =SUM(X13:Z13) -> 304.4517 | AC13: 6 | AD13: 0.000767 | AE13: =(AD13*$D$1)/12 -> 32.604895 | AF13: =($D$2*AD13)/12 -> 1.9949651 | AG13: =($D$3*AD13)/12 -> 0 | AH13: =SUM(AE13:AG13) -> 34.59986 | AJ13: 72 | AK13: 0.000767 | AL13: =(AK13*$D$1)/12 -> 32.604895 | AM13: =($D$2*AK13)/12 -> 1.9949651 | AN13: =($D$3*AK13)/12 -> 0 | AO13: =SUM(AL13:AN13) -> 34.59986 | AQ13: 136 | AR13: 0.000767 | AS13: =(AR13*$D$1)/12 -> 32.604895 | AT13: =($D$2*AR13)/12 -> 1.9949651 | AU13: =($D$3*AR13)/12 -> 0 | AV13: =SUM(AS13:AU13) -> 34.59986 | AX13: 200 | AY13: 0.000767 | AZ13: =(AY13*$D$1)/12 -> 32.604895 | BA13: =($D$2*AY13)/12 -> 1.9949651 | BB13: =($D$3*AY13)/12 -> 0 | BC13: =SUM(AZ13:BB13) -> 34.59986
A14: 107 | B14: 0.007002 | C14: =(B14*$D$1)/12 -> 297.65251 | D14: =($D$2*B14)/12 -> 18.212185 | E14: =($D$3*B14)/12 -> 0 | F14: =SUM(C14:E14) -> 315.8647 | H14: 507 | I14: 0.006749 | J14: =(I14*$D$1)/12 -> 286.89757 | K14: =($D$2*I14)/12 -> 17.554133 | L14: =($D$3*I14)/12 -> 0 | M14: =SUM(J14:L14) -> 304.4517 | O14: 107 | P14: 0.007002 | Q14: =(P14*$D$1)/12 -> 297.65251 | R14: =($D$2*P14)/12 -> 18.212185 | S14: =($D$3*P14)/12 -> 0 | T14: =SUM(Q14:S14) -> 315.8647 | V14: 507 | W14: 0.006749 | X14: =(W14*$D$1)/12 -> 286.89757 | Y14: =($D$2*W14)/12 -> 17.554133 | Z14: =($D$3*W14)/12 -> 0 | AA14: =SUM(X14:Z14) -> 304.4517 | AC14: 7 | AD14: 0.000767 | AE14: =(AD14*$D$1)/12 -> 32.604895 | AF14: =($D$2*AD14)/12 -> 1.9949651 | AG14: =($D$3*AD14)/12 -> 0 | AH14: =SUM(AE14:AG14) -> 34.59986 | AJ14: 73 | AK14: 0.000767 | AL14: =(AK14*$D$1)/12 -> 32.604895 | AM14: =($D$2*AK14)/12 -> 1.9949651 | AN14: =($D$3*AK14)/12 -> 0 | AO14: =SUM(AL14:AN14) -> 34.59986 | AQ14: 137 | AR14: 0.000767 | AS14: =(AR14*$D$1)/12 -> 32.604895 | AT14: =($D$2*AR14)/12 -> 1.9949651 | AU14: =($D$3*AR14)/12 -> 0 | AV14: =SUM(AS14:AU14) -> 34.59986 | AX14: 201 | AY14: 0.000767 | AZ14: =(AY14*$D$1)/12 -> 32.604895 | BA14: =($D$2*AY14)/12 -> 1.9949651 | BB14: =($D$3*AY14)/12 -> 0 | BC14: =SUM(AZ14:BB14) -> 34.59986
A15: 108 | B15: 0.006142 | C15: =(B15*$D$1)/12 -> 261.09422 | D15: =($D$2*B15)/12 -> 15.975327 | E15: =($D$3*B15)/12 -> 0 | F15: =SUM(C15:E15) -> 277.06955 | H15: 508 | I15: 0.005895 | J15: =(I15*$D$1)/12 -> 250.59434 | K15: =($D$2*I15)/12 -> 15.332881 | L15: =($D$3*I15)/12 -> 0 | M15: =SUM(J15:L15) -> 265.92722 | O15: 108 | P15: 0.006142 | Q15: =(P15*$D$1)/12 -> 261.09422 | R15: =($D$2*P15)/12 -> 15.975327 | S15: =($D$3*P15)/12 -> 0 | T15: =SUM(Q15:S15) -> 277.06955 | V15: 508 | W15: 0.005895 | X15: =(W15*$D$1)/12 -> 250.59434 | Y15: =($D$2*W15)/12 -> 15.332881 | Z15: =($D$3*W15)/12 -> 0 | AA15: =SUM(X15:Z15) -> 265.92722 | AC15: 8 | AD15: 0.000767 | AE15: =(AD15*$D$1)/12 -> 32.604895 | AF15: =($D$2*AD15)/12 -> 1.9949651 | AG15: =($D$3*AD15)/12 -> 0 | AH15: =SUM(AE15:AG15) -> 34.59986 | AJ15: 74 | AK15: 0.000767 | AL15: =(AK15*$D$1)/12 -> 32.604895 | AM15: =($D$2*AK15)/12 -> 1.9949651 | AN15: =($D$3*AK15)/12 -> 0 | AO15: =SUM(AL15:AN15) -> 34.59986 | AQ15: 138 | AR15: 0.000767 | AS15: =(AR15*$D$1)/12 -> 32.604895 | AT15: =($D$2*AR15)/12 -> 1.9949651 | AU15: =($D$3*AR15)/12 -> 0 | AV15: =SUM(AS15:AU15) -> 34.59986 | AX15: 202 | AY15: 0.000767 | AZ15: =(AY15*$D$1)/12 -> 32.604895 | BA15: =($D$2*AY15)/12 -> 1.9949651 | BB15: =($D$3*AY15)/12 -> 0 | BC15: =SUM(AZ15:BB15) -> 34.59986
A16: 201 | B16: 0.005892 | C16: =(B16*$D$1)/12 -> 250.46681 | D16: =($D$2*B16)/12 -> 15.325078 | E16: =($D$3*B16)/12 -> 0 | F16: =SUM(C16:E16) -> 265.79189 | H16: 601 | I16: 0.005892 | J16: =(I16*$D$1)/12 -> 250.46681 | K16: =($D$2*I16)/12 -> 15.325078 | L16: =($D$3*I16)/12 -> 0 | M16: =SUM(J16:L16) -> 265.79189 | O16: 201 | P16: 0.005892 | Q16: =(P16*$D$1)/12 -> 250.46681 | R16: =($D$2*P16)/12 -> 15.325078 | S16: =($D$3*P16)/12 -> 0 | T16: =SUM(Q16:S16) -> 265.79189 | V16: 601 | W16: 0.005892 | X16: =(W16*$D$1)/12 -> 250.46681 | Y16: =($D$2*W16)/12 -> 15.325078 | Z16: =($D$3*W16)/12 -> 0 | AA16: =SUM(X16:Z16) -> 265.79189 | AC16: 9 | AD16: 0.000767 | AE16: =(AD16*$D$1)/12 -> 32.604895 | AF16: =($D$2*AD16)/12 -> 1.9949651 | AG16: =($D$3*AD16)/12 -> 0 | AH16: =SUM(AE16:AG16) -> 34.59986 | AJ16: 75 | AK16: 0.000767 | AL16: =(AK16*$D$1)/12 -> 32.604895 | AM16: =($D$2*AK16)/12 -> 1.9949651 | AN16: =($D$3*AK16)/12 -> 0 | AO16: =SUM(AL16:AN16) -> 34.59986 | AQ16: 139 | AR16: 0.000767 | AS16: =(AR16*$D$1)/12 -> 32.604895 | AT16: =($D$2*AR16)/12 -> 1.9949651 | AU16: =($D$3*AR16)/12 -> 0 | AV16: =SUM(AS16:AU16) -> 34.59986 | AX16: 203 | AY16: 0.000767 | AZ16: =(AY16*$D$1)/12 -> 32.604895 | BA16: =($D$2*AY16)/12 -> 1.9949651 | BB16: =($D$3*AY16)/12 -> 0 | BC16: =SUM(AZ16:BB16) -> 34.59986
A17: 202 | B17: 0.006749 | C17: =(B17*$D$1)/12 -> 286.89757 | D17: =($D$2*B17)/12 -> 17.554133 | E17: =($D$3*B17)/12 -> 0 | F17: =SUM(C17:E17) -> 304.4517 | H17: 602 | I17: 0.006749 | J17: =(I17*$D$1)/12 -> 286.89757 | K17: =($D$2*I17)/12 -> 17.554133 | L17: =($D$3*I17)/12 -> 0 | M17: =SUM(J17:L17) -> 304.4517 | O17: 202 | P17: 0.006749 | Q17: =(P17*$D$1)/12 -> 286.89757 | R17: =($D$2*P17)/12 -> 17.554133 | S17: =($D$3*P17)/12 -> 0 | T17: =SUM(Q17:S17) -> 304.4517 | V17: 602 | W17: 0.006749 | X17: =(W17*$D$1)/12 -> 286.89757 | Y17: =($D$2*W17)/12 -> 17.554133 | Z17: =($D$3*W17)/12 -> 0 | AA17: =SUM(X17:Z17) -> 304.4517 | AC17: 10 | AD17: 0.000767 | AE17: =(AD17*$D$1)/12 -> 32.604895 | AF17: =($D$2*AD17)/12 -> 1.9949651 | AG17: =($D$3*AD17)/12 -> 0 | AH17: =SUM(AE17:AG17) -> 34.59986 | AJ17: 76 | AK17: 0.000767 | AL17: =(AK17*$D$1)/12 -> 32.604895 | AM17: =($D$2*AK17)/12 -> 1.9949651 | AN17: =($D$3*AK17)/12 -> 0 | AO17: =SUM(AL17:AN17) -> 34.59986 | AQ17: 140 | AR17: 0.000767 | AS17: =(AR17*$D$1)/12 -> 32.604895 | AT17: =($D$2*AR17)/12 -> 1.9949651 | AU17: =($D$3*AR17)/12 -> 0 | AV17: =SUM(AS17:AU17) -> 34.59986 | AX17: 204 | AY17: 0.000767 | AZ17: =(AY17*$D$1)/12 -> 32.604895 | BA17: =($D$2*AY17)/12 -> 1.9949651 | BB17: =($D$3*AY17)/12 -> 0 | BC17: =SUM(AZ17:BB17) -> 34.59986
A18: 203 | B18: 0.006749 | C18: =(B18*$D$1)/12 -> 286.89757 | D18: =($D$2*B18)/12 -> 17.554133 | E18: =($D$3*B18)/12 -> 0 | F18: =SUM(C18:E18) -> 304.4517 | H18: 603 | I18: 0.006749 | J18: =(I18*$D$1)/12 -> 286.89757 | K18: =($D$2*I18)/12 -> 17.554133 | L18: =($D$3*I18)/12 -> 0 | M18: =SUM(J18:L18) -> 304.4517 | O18: 203 | P18: 0.006749 | Q18: =(P18*$D$1)/12 -> 286.89757 | R18: =($D$2*P18)/12 -> 17.554133 | S18: =($D$3*P18)/12 -> 0 | T18: =SUM(Q18:S18) -> 304.4517 | V18: 603 | W18: 0.006749 | X18: =(W18*$D$1)/12 -> 286.89757 | Y18: =($D$2*W18)/12 -> 17.554133 | Z18: =($D$3*W18)/12 -> 0 | AA18: =SUM(X18:Z18) -> 304.4517 | AC18: 11 | AD18: 0.000767 | AE18: =(AD18*$D$1)/12 -> 32.604895 | AF18: =($D$2*AD18)/12 -> 1.9949651 | AG18: =($D$3*AD18)/12 -> 0 | AH18: =SUM(AE18:AG18) -> 34.59986 | AJ18: 77 | AK18: 0.000767 | AL18: =(AK18*$D$1)/12 -> 32.604895 | AM18: =($D$2*AK18)/12 -> 1.9949651 | AN18: =($D$3*AK18)/12 -> 0 | AO18: =SUM(AL18:AN18) -> 34.59986 | AQ18: 141 | AR18: 0.000767 | AS18: =(AR18*$D$1)/12 -> 32.604895 | AT18: =($D$2*AR18)/12 -> 1.9949651 | AU18: =($D$3*AR18)/12 -> 0 | AV18: =SUM(AS18:AU18) -> 34.59986 | AX18: 205 | AY18: 0.000767 | AZ18: =(AY18*$D$1)/12 -> 32.604895 | BA18: =($D$2*AY18)/12 -> 1.9949651 | BB18: =($D$3*AY18)/12 -> 0 | BC18: =SUM(AZ18:BB18) -> 34.59986
A19: 204 | B19: 0.005892 | C19: =(B19*$D$1)/12 -> 250.46681 | D19: =($D$2*B19)/12 -> 15.325078 | E19: =($D$3*B19)/12 -> 0 | F19: =SUM(C19:E19) -> 265.79189 | H19: 604 | I19: 0.005892 | J19: =(I19*$D$1)/12 -> 250.46681 | K19: =($D$2*I19)/12 -> 15.325078 | L19: =($D$3*I19)/12 -> 0 | M19: =SUM(J19:L19) -> 265.79189 | O19: 204 | P19: 0.005892 | Q19: =(P19*$D$1)/12 -> 250.46681 | R19: =($D$2*P19)/12 -> 15.325078 | S19: =($D$3*P19)/12 -> 0 | T19: =SUM(Q19:S19) -> 265.79189 | V19: 604 | W19: 0.005892 | X19: =(W19*$D$1)/12 -> 250.46681 | Y19: =($D$2*W19)/12 -> 15.325078 | Z19: =($D$3*W19)/12 -> 0 | AA19: =SUM(X19:Z19) -> 265.79189 | AC19: 12 | AD19: 0.000767 | AE19: =(AD19*$D$1)/12 -> 32.604895 | AF19: =($D$2*AD19)/12 -> 1.9949651 | AG19: =($D$3*AD19)/12 -> 0 | AH19: =SUM(AE19:AG19) -> 34.59986 | AJ19: 78 | AK19: 0.000767 | AL19: =(AK19*$D$1)/12 -> 32.604895 | AM19: =($D$2*AK19)/12 -> 1.9949651 | AN19: =($D$3*AK19)/12 -> 0 | AO19: =SUM(AL19:AN19) -> 34.59986 | AQ19: 142 | AR19: 0.000767 | AS19: =(AR19*$D$1)/12 -> 32.604895 | AT19: =($D$2*AR19)/12 -> 1.9949651 | AU19: =($D$3*AR19)/12 -> 0 | AV19: =SUM(AS19:AU19) -> 34.59986 | AX19: 206 | AY19: 0.000767 | AZ19: =(AY19*$D$1)/12 -> 32.604895 | BA19: =($D$2*AY19)/12 -> 1.9949651 | BB19: =($D$3*AY19)/12 -> 0 | BC19: =SUM(AZ19:BB19) -> 34.59986
... A39: 408 | B39: 0.005895 | C39: =(B39*$D$1)/12 -> 250.59434 | D39: =($D$2*B39)/12 -> 15.332881 | E39: =($D$3*B39)/12 -> 0 | F39: =SUM(C39:E39) -> 265.92722 | H39: 808 | I39: 0.005895 | J39: =(I39*$D$1)/12 -> 250.59434 | K39: =($D$2*I39)/12 -> 15.332881 | L39: =($D$3*I39)/12 -> 0 | M39: =SUM(J39:L39) -> 265.92722 | O39: 408 | P39: 0.005895 | Q39: =(P39*$D$1)/12 -> 250.59434 | R39: =($D$2*P39)/12 -> 15.332881 | S39: =($D$3*P39)/12 -> 0 | T39: =SUM(Q39:S39) -> 265.92722 | V39: 808 | W39: 0.005895 | X39: =(W39*$D$1)/12 -> 250.59434 | Y39: =($D$2*W39)/12 -> 15.332881 | Z39: =($D$3*W39)/12 -> 0 | AA39: =SUM(X39:Z39) -> 265.92722 | AC39: 32 | AD39: 0.000767 | AE39: =(AD39*$D$1)/12 -> 32.604895 | AF39: =($D$2*AD39)/12 -> 1.9949651 | AG39: =($D$3*AD39)/12 -> 0 | AH39: =SUM(AE39:AG39) -> 34.59986 | AJ39: 98 | AK39: 0.000767 | AL39: =(AK39*$D$1)/12 -> 32.604895 | AM39: =($D$2*AK39)/12 -> 1.9949651 | AN39: =($D$3*AK39)/12 -> 0 | AO39: =SUM(AL39:AN39) -> 34.59986 | AQ39: 162 | AR39: 0.000767 | AS39: =(AR39*$D$1)/12 -> 32.604895 | AT39: =($D$2*AR39)/12 -> 1.9949651 | AU39: =($D$3*AR39)/12 -> 0 | AV39: =SUM(AS39:AU39) -> 34.59986 | AX39: 226 | AY39: 0.000353 | AZ39: =(AY39*$D$1)/12 -> 15.005903 | BA39: =($D$2*AY39)/12 -> 0.91815215 | BB39: =($D$3*AY39)/12 -> 0 | BC39: =SUM(AZ39:BB39) -> 15.924056
B40: =SUM(B8:B39) -> 0.204544 | C40: =SUM(C8:C39) -> 8695.0921 | D40: =SUM(D8:D39) -> 532.01845 | E40: =SUM(E8:E39) -> 0 | F40: =SUM(F8:F39) -> 9227.1106 | I40: =SUM(I8:I39) -> 0.20228 | J40: =SUM(J8:J39) -> 8598.8503 | K40: =SUM(K8:K39) -> 526.12979 | L40: =SUM(L8:L39) -> 0 | M40: =SUM(M8:M39) -> 9124.9801 | P40: =SUM(P8:P39) -> 0.204544 | Q40: =SUM(Q8:Q39) -> 8695.0921 | R40: =SUM(R8:R39) -> 532.01845 | S40: =SUM(S8:S39) -> 0 | T40: =SUM(T8:T39) -> 9227.1106 | W40: =SUM(W8:W39) -> 0.20228 | X40: =SUM(X8:X39) -> 8598.8503 | Y40: =SUM(Y8:Y39) -> 526.12979 | Z40: =SUM(Z8:Z39) -> 0 | AA40: =SUM(AA8:AA39) -> 9124.9801 | AC40: 33 | AD40: 0.000767 | AE40: =(AD40*$D$1)/12 -> 32.604895 | AF40: =($D$2*AD40)/12 -> 1.9949651 | AG40: =($D$3*AD40)/12 -> 0 | AH40: =SUM(AE40:AG40) -> 34.59986 | AJ40: 99 | AK40: 0.000767 | AL40: =(AK40*$D$1)/12 -> 32.604895 | AM40: =($D$2*AK40)/12 -> 1.9949651 | AN40: =($D$3*AK40)/12 -> 0 | AO40: =SUM(AL40:AN40) -> 34.59986 | AQ40: 163 | AR40: 0.000767 | AS40: =(AR40*$D$1)/12 -> 32.604895 | AT40: =($D$2*AR40)/12 -> 1.9949651 | AU40: =($D$3*AR40)/12 -> 0 | AV40: =SUM(AS40:AU40) -> 34.59986 | AX40: 227 | AY40: 0.000353 | AZ40: =(AY40*$D$1)/12 -> 15.005903 | BA40: =($D$2*AY40)/12 -> 0.91815215 | BB40: =($D$3*AY40)/12 -> 0 | BC40: =SUM(AZ40:BB40) -> 15.924056
AC41: 34 | AD41: 0.000767 | AE41: =(AD41*$D$1)/12 -> 32.604895 | AF41: =($D$2*AD41)/12 -> 1.9949651 | AG41: =($D$3*AD41)/12 -> 0 | AH41: =SUM(AE41:AG41) -> 34.59986 | AJ41: 100 | AK41: 0.000767 | AL41: =(AK41*$D$1)/12 -> 32.604895 | AM41: =($D$2*AK41)/12 -> 1.9949651 | AN41: =($D$3*AK41)/12 -> 0 | AO41: =SUM(AL41:AN41) -> 34.59986 | AQ41: 164 | AR41: 0.000767 | AS41: =(AR41*$D$1)/12 -> 32.604895 | AT41: =($D$2*AR41)/12 -> 1.9949651 | AU41: =($D$3*AR41)/12 -> 0 | AV41: =SUM(AS41:AU41) -> 34.59986 | AX41: 228 | AY41: 0.000353 | AZ41: =(AY41*$D$1)/12 -> 15.005903 | BA41: =($D$2*AY41)/12 -> 0.91815215 | BB41: =($D$3*AY41)/12 -> 0 | BC41: =SUM(AZ41:BB41) -> 15.924056
AC42: 35 | AD42: 0.001533 | AE42: =(AD42*$D$1)/12 -> 65.167281 | AF42: =($D$2*AD42)/12 -> 3.9873293 | AG42: =($D$3*AD42)/12 -> 0 | AH42: =SUM(AE42:AG42) -> 69.15461 | AJ42: 101 | AK42: 0.000767 | AL42: =(AK42*$D$1)/12 -> 32.604895 | AM42: =($D$2*AK42)/12 -> 1.9949651 | AN42: =($D$3*AK42)/12 -> 0 | AO42: =SUM(AL42:AN42) -> 34.59986 | AQ42: 165 | AR42: 0.000767 | AS42: =(AR42*$D$1)/12 -> 32.604895 | AT42: =($D$2*AR42)/12 -> 1.9949651 | AU42: =($D$3*AR42)/12 -> 0 | AV42: =SUM(AS42:AU42) -> 34.59986 | AX42: 229 | AY42: 0.000353 | AZ42: =(AY42*$D$1)/12 -> 15.005903 | BA42: =($D$2*AY42)/12 -> 0.91815215 | BB42: =($D$3*AY42)/12 -> 0 | BC42: =SUM(AZ42:BB42) -> 15.924056
AC43: 36 | AD43: 0.001533 | AE43: =(AD43*$D$1)/12 -> 65.167281 | AF43: =($D$2*AD43)/12 -> 3.9873293 | AG43: =($D$3*AD43)/12 -> 0 | AH43: =SUM(AE43:AG43) -> 69.15461 | AJ43: 102 | AK43: 0.000767 | AL43: =(AK43*$D$1)/12 -> 32.604895 | AM43: =($D$2*AK43)/12 -> 1.9949651 | AN43: =($D$3*AK43)/12 -> 0 | AO43: =SUM(AL43:AN43) -> 34.59986 | AQ43: 166 | AR43: 0.000767 | AS43: =(AR43*$D$1)/12 -> 32.604895 | AT43: =($D$2*AR43)/12 -> 1.9949651 | AU43: =($D$3*AR43)/12 -> 0 | AV43: =SUM(AS43:AU43) -> 34.59986 | AX43: 230 | AY43: 0.000353 | AZ43: =(AY43*$D$1)/12 -> 15.005903 | BA43: =($D$2*AY43)/12 -> 0.91815215 | BB43: =($D$3*AY43)/12 -> 0 | BC43: =SUM(AZ43:BB43) -> 15.924056
AC44: 37 | AD44: 0.000767 | AE44: =(AD44*$D$1)/12 -> 32.604895 | AF44: =($D$2*AD44)/12 -> 1.9949651 | AG44: =($D$3*AD44)/12 -> 0 | AH44: =SUM(AE44:AG44) -> 34.59986 | AJ44: 103 | AK44: 0.000767 | AL44: =(AK44*$D$1)/12 -> 32.604895 | AM44: =($D$2*AK44)/12 -> 1.9949651 | AN44: =($D$3*AK44)/12 -> 0 | AO44: =SUM(AL44:AN44) -> 34.59986 | AQ44: 167 | AR44: 0.000767 | AS44: =(AR44*$D$1)/12 -> 32.604895 | AT44: =($D$2*AR44)/12 -> 1.9949651 | AU44: =($D$3*AR44)/12 -> 0 | AV44: =SUM(AS44:AU44) -> 34.59986 | AX44: 231 | AY44: 0.000353 | AZ44: =(AY44*$D$1)/12 -> 15.005903 | BA44: =($D$2*AY44)/12 -> 0.91815215 | BB44: =($D$3*AY44)/12 -> 0 | BC44: =SUM(AZ44:BB44) -> 15.924056
AC45: 38 | AD45: 0.000767 | AE45: =(AD45*$D$1)/12 -> 32.604895 | AF45: =($D$2*AD45)/12 -> 1.9949651 | AG45: =($D$3*AD45)/12 -> 0 | AH45: =SUM(AE45:AG45) -> 34.59986 | AJ45: 104 | AK45: 0.000767 | AL45: =(AK45*$D$1)/12 -> 32.604895 | AM45: =($D$2*AK45)/12 -> 1.9949651 | AN45: =($D$3*AK45)/12 -> 0 | AO45: =SUM(AL45:AN45) -> 34.59986 | AQ45: 168 | AR45: 0.000767 | AS45: =(AR45*$D$1)/12 -> 32.604895 | AT45: =($D$2*AR45)/12 -> 1.9949651 | AU45: =($D$3*AR45)/12 -> 0 | AV45: =SUM(AS45:AU45) -> 34.59986 | AX45: 232 | AY45: 0.000353 | AZ45: =(AY45*$D$1)/12 -> 15.005903 | BA45: =($D$2*AY45)/12 -> 0.91815215 | BB45: =($D$3*AY45)/12 -> 0 | BC45: =SUM(AZ45:BB45) -> 15.924056
AC46: 39 | AD46: 0.000767 | AE46: =(AD46*$D$1)/12 -> 32.604895 | AF46: =($D$2*AD46)/12 -> 1.9949651 | AG46: =($D$3*AD46)/12 -> 0 | AH46: =SUM(AE46:AG46) -> 34.59986 | AJ46: 105 | AK46: 0.000767 | AL46: =(AK46*$D$1)/12 -> 32.604895 | AM46: =($D$2*AK46)/12 -> 1.9949651 | AN46: =($D$3*AK46)/12 -> 0 | AO46: =SUM(AL46:AN46) -> 34.59986 | AQ46: 169 | AR46: 0.000767 | AS46: =(AR46*$D$1)/12 -> 32.604895 | AT46: =($D$2*AR46)/12 -> 1.9949651 | AU46: =($D$3*AR46)/12 -> 0 | AV46: =SUM(AS46:AU46) -> 34.59986 | AX46: 233 | AY46: 0.000353 | AZ46: =(AY46*$D$1)/12 -> 15.005903 | BA46: =($D$2*AY46)/12 -> 0.91815215 | BB46: =($D$3*AY46)/12 -> 0 | BC46: =SUM(AZ46:BB46) -> 15.924056
A47: CHECK PERCENTUAIS | B47: =B40+I40+P40+W40+AD74+AK72+AR72+AY72 -> 1 | AC47: 40 | AD47: 0.000767 | AE47: =(AD47*$D$1)/12 -> 32.604895 | AF47: =($D$2*AD47)/12 -> 1.9949651 | AG47: =($D$3*AD47)/12 -> 0 | AH47: =SUM(AE47:AG47) -> 34.59986 | AJ47: 106 | AK47: 0.000767 | AL47: =(AK47*$D$1)/12 -> 32.604895 | AM47: =($D$2*AK47)/12 -> 1.9949651 | AN47: =($D$3*AK47)/12 -> 0 | AO47: =SUM(AL47:AN47) -> 34.59986 | AQ47: 170 | AR47: 0.000767 | AS47: =(AR47*$D$1)/12 -> 32.604895 | AT47: =($D$2*AR47)/12 -> 1.9949651 | AU47: =($D$3*AR47)/12 -> 0 | AV47: =SUM(AS47:AU47) -> 34.59986 | AX47: 234 | AY47: 0.000353 | AZ47: =(AY47*$D$1)/12 -> 15.005903 | BA47: =($D$2*AY47)/12 -> 0.91815215 | BB47: =($D$3*AY47)/12 -> 0 | BC47: =SUM(AZ47:BB47) -> 15.924056
A48: TAXA C/ FUNDO | B48: =(F40+M40+T40+AA40+AH74+AO72+AV72+BC72)*12 -> 541327.67 | AC48: 41 | AD48: 0.000767 | AE48: =(AD48*$D$1)/12 -> 32.604895 | AF48: =($D$2*AD48)/12 -> 1.9949651 | AG48: =($D$3*AD48)/12 -> 0 | AH48: =SUM(AE48:AG48) -> 34.59986 | AJ48: 107 | AK48: 0.000767 | AL48: =(AK48*$D$1)/12 -> 32.604895 | AM48: =($D$2*AK48)/12 -> 1.9949651 | AN48: =($D$3*AK48)/12 -> 0 | AO48: =SUM(AL48:AN48) -> 34.59986 | AQ48: 171 | AR48: 0.000767 | AS48: =(AR48*$D$1)/12 -> 32.604895 | AT48: =($D$2*AR48)/12 -> 1.9949651 | AU48: =($D$3*AR48)/12 -> 0 | AV48: =SUM(AS48:AU48) -> 34.59986 | AX48: 235 | AY48: 0.000353 | AZ48: =(AY48*$D$1)/12 -> 15.005903 | BA48: =($D$2*AY48)/12 -> 0.91815215 | BB48: =($D$3*AY48)/12 -> 0 | BC48: =SUM(AZ48:BB48) -> 15.924056
AC49: 42 | AD49: 0.000767 | AE49: =(AD49*$D$1)/12 -> 32.604895 | AF49: =($D$2*AD49)/12 -> 1.9949651 | AG49: =($D$3*AD49)/12 -> 0 | AH49: =SUM(AE49:AG49) -> 34.59986 | AJ49: 108 | AK49: 0.001533 | AL49: =(AK49*$D$1)/12 -> 65.167281 | AM49: =($D$2*AK49)/12 -> 3.9873293 | AN49: =($D$3*AK49)/12 -> 0 | AO49: =SUM(AL49:AN49) -> 69.15461 | AQ49: 172 | AR49: 0.000767 | AS49: =(AR49*$D$1)/12 -> 32.604895 | AT49: =($D$2*AR49)/12 -> 1.9949651 | AU49: =($D$3*AR49)/12 -> 0 | AV49: =SUM(AS49:AU49) -> 34.59986 | AX49: 236 | AY49: 0.000353 | AZ49: =(AY49*$D$1)/12 -> 15.005903 | BA49: =($D$2*AY49)/12 -> 0.91815215 | BB49: =($D$3*AY49)/12 -> 0 | BC49: =SUM(AZ49:BB49) -> 15.924056
A50: ORÇAMENTO | B50: =D5 -> 541327.67 | AC50: 43 | AD50: 0.000767 | AE50: =(AD50*$D$1)/12 -> 32.604895 | AF50: =($D$2*AD50)/12 -> 1.9949651 | AG50: =($D$3*AD50)/12 -> 0 | AH50: =SUM(AE50:AG50) -> 34.59986 | AJ50: 109 | AK50: 0.001533 | AL50: =(AK50*$D$1)/12 -> 65.167281 | AM50: =($D$2*AK50)/12 -> 3.9873293 | AN50: =($D$3*AK50)/12 -> 0 | AO50: =SUM(AL50:AN50) -> 69.15461 | AQ50: 173 | AR50: 0.000767 | AS50: =(AR50*$D$1)/12 -> 32.604895 | AT50: =($D$2*AR50)/12 -> 1.9949651 | AU50: =($D$3*AR50)/12 -> 0 | AV50: =SUM(AS50:AU50) -> 34.59986 | AX50: 237 | AY50: 0.000709 | AZ50: =(AY50*$D$1)/12 -> 30.139336 | BA50: =($D$2*AY50)/12 -> 1.8441073 | BB50: =($D$3*AY50)/12 -> 0 | BC50: =SUM(AZ50:BB50) -> 31.983443
AC51: 44 | AD51: 0.000767 | AE51: =(AD51*$D$1)/12 -> 32.604895 | AF51: =($D$2*AD51)/12 -> 1.9949651 | AG51: =($D$3*AD51)/12 -> 0 | AH51: =SUM(AE51:AG51) -> 34.59986 | AJ51: 110 | AK51: 0.000767 | AL51: =(AK51*$D$1)/12 -> 32.604895 | AM51: =($D$2*AK51)/12 -> 1.9949651 | AN51: =($D$3*AK51)/12 -> 0 | AO51: =SUM(AL51:AN51) -> 34.59986 | AQ51: 174 | AR51: 0.000767 | AS51: =(AR51*$D$1)/12 -> 32.604895 | AT51: =($D$2*AR51)/12 -> 1.9949651 | AU51: =($D$3*AR51)/12 -> 0 | AV51: =SUM(AS51:AU51) -> 34.59986 | AX51: 238 | AY51: 0.000709 | AZ51: =(AY51*$D$1)/12 -> 30.139336 | BA51: =($D$2*AY51)/12 -> 1.8441073 | BB51: =($D$3*AY51)/12 -> 0 | BC51: =SUM(AZ51:BB51) -> 31.983443
AC52: 45 | AD52: 0.000767 | AE52: =(AD52*$D$1)/12 -> 32.604895 | AF52: =($D$2*AD52)/12 -> 1.9949651 | AG52: =($D$3*AD52)/12 -> 0 | AH52: =SUM(AE52:AG52) -> 34.59986 | AJ52: 111 | AK52: 0.000767 | AL52: =(AK52*$D$1)/12 -> 32.604895 | AM52: =($D$2*AK52)/12 -> 1.9949651 | AN52: =($D$3*AK52)/12 -> 0 | AO52: =SUM(AL52:AN52) -> 34.59986 | AQ52: 175 | AR52: 0.000767 | AS52: =(AR52*$D$1)/12 -> 32.604895 | AT52: =($D$2*AR52)/12 -> 1.9949651 | AU52: =($D$3*AR52)/12 -> 0 | AV52: =SUM(AS52:AU52) -> 34.59986 | AX52: 239 | AY52: 0.000353 | AZ52: =(AY52*$D$1)/12 -> 15.005903 | BA52: =($D$2*AY52)/12 -> 0.91815215 | BB52: =($D$3*AY52)/12 -> 0 | BC52: =SUM(AZ52:BB52) -> 15.924056
AC53: 46 | AD53: 0.000767 | AE53: =(AD53*$D$1)/12 -> 32.604895 | AF53: =($D$2*AD53)/12 -> 1.9949651 | AG53: =($D$3*AD53)/12 -> 0 | AH53: =SUM(AE53:AG53) -> 34.59986 | AJ53: 112 | AK53: 0.000767 | AL53: =(AK53*$D$1)/12 -> 32.604895 | AM53: =($D$2*AK53)/12 -> 1.9949651 | AN53: =($D$3*AK53)/12 -> 0 | AO53: =SUM(AL53:AN53) -> 34.59986 | AQ53: 176 | AR53: 0.000767 | AS53: =(AR53*$D$1)/12 -> 32.604895 | AT53: =($D$2*AR53)/12 -> 1.9949651 | AU53: =($D$3*AR53)/12 -> 0 | AV53: =SUM(AS53:AU53) -> 34.59986 | AX53: 240 | AY53: 0.000353 | AZ53: =(AY53*$D$1)/12 -> 15.005903 | BA53: =($D$2*AY53)/12 -> 0.91815215 | BB53: =($D$3*AY53)/12 -> 0 | BC53: =SUM(AZ53:BB53) -> 15.924056
AC54: 47 | AD54: 0.001533 | AE54: =(AD54*$D$1)/12 -> 65.167281 | AF54: =($D$2*AD54)/12 -> 3.9873293 | AG54: =($D$3*AD54)/12 -> 0 | AH54: =SUM(AE54:AG54) -> 69.15461 | AJ54: 113 | AK54: 0.000767 | AL54: =(AK54*$D$1)/12 -> 32.604895 | AM54: =($D$2*AK54)/12 -> 1.9949651 | AN54: =($D$3*AK54)/12 -> 0 | AO54: =SUM(AL54:AN54) -> 34.59986 | AQ54: 177 | AR54: 0.000767 | AS54: =(AR54*$D$1)/12 -> 32.604895 | AT54: =($D$2*AR54)/12 -> 1.9949651 | AU54: =($D$3*AR54)/12 -> 0 | AV54: =SUM(AS54:AU54) -> 34.59986 | AX54: 241 | AY54: 0.000353 | AZ54: =(AY54*$D$1)/12 -> 15.005903 | BA54: =($D$2*AY54)/12 -> 0.91815215 | BB54: =($D$3*AY54)/12 -> 0 | BC54: =SUM(AZ54:BB54) -> 15.924056
AC55: 48 | AD55: 0.001533 | AE55: =(AD55*$D$1)/12 -> 65.167281 | AF55: =($D$2*AD55)/12 -> 3.9873293 | AG55: =($D$3*AD55)/12 -> 0 | AH55: =SUM(AE55:AG55) -> 69.15461 | AJ55: 114 | AK55: 0.000767 | AL55: =(AK55*$D$1)/12 -> 32.604895 | AM55: =($D$2*AK55)/12 -> 1.9949651 | AN55: =($D$3*AK55)/12 -> 0 | AO55: =SUM(AL55:AN55) -> 34.59986 | AQ55: 178 | AR55: 0.000767 | AS55: =(AR55*$D$1)/12 -> 32.604895 | AT55: =($D$2*AR55)/12 -> 1.9949651 | AU55: =($D$3*AR55)/12 -> 0 | AV55: =SUM(AS55:AU55) -> 34.59986 | AX55: 242 | AY55: 0.000353 | AZ55: =(AY55*$D$1)/12 -> 15.005903 | BA55: =($D$2*AY55)/12 -> 0.91815215 | BB55: =($D$3*AY55)/12 -> 0 | BC55: =SUM(AZ55:BB55) -> 15.924056
AC56: 49 | AD56: 0.000767 | AE56: =(AD56*$D$1)/12 -> 32.604895 | AF56: =($D$2*AD56)/12 -> 1.9949651 | AG56: =($D$3*AD56)/12 -> 0 | AH56: =SUM(AE56:AG56) -> 34.59986 | AJ56: 115 | AK56: 0.000767 | AL56: =(AK56*$D$1)/12 -> 32.604895 | AM56: =($D$2*AK56)/12 -> 1.9949651 | AN56: =($D$3*AK56)/12 -> 0 | AO56: =SUM(AL56:AN56) -> 34.59986 | AQ56: 179 | AR56: 0.000767 | AS56: =(AR56*$D$1)/12 -> 32.604895 | AT56: =($D$2*AR56)/12 -> 1.9949651 | AU56: =($D$3*AR56)/12 -> 0 | AV56: =SUM(AS56:AU56) -> 34.59986 | AZ56: =(AY56*$D$1)/12 -> 0 | BA56: =($D$2*AY56)/12 -> 0 | BB56: =($D$3*AY56)/12 -> 0 | BC56: =SUM(AZ56:BB56) -> 0
AC57: 50 | AD57: 0.000767 | AE57: =(AD57*$D$1)/12 -> 32.604895 | AF57: =($D$2*AD57)/12 -> 1.9949651 | AG57: =($D$3*AD57)/12 -> 0 | AH57: =SUM(AE57:AG57) -> 34.59986 | AJ57: 116 | AK57: 0.000767 | AL57: =(AK57*$D$1)/12 -> 32.604895 | AM57: =($D$2*AK57)/12 -> 1.9949651 | AN57: =($D$3*AK57)/12 -> 0 | AO57: =SUM(AL57:AN57) -> 34.59986 | AQ57: 180 | AR57: 0.000767 | AS57: =(AR57*$D$1)/12 -> 32.604895 | AT57: =($D$2*AR57)/12 -> 1.9949651 | AU57: =($D$3*AR57)/12 -> 0 | AV57: =SUM(AS57:AU57) -> 34.59986 | AZ57: =(AY57*$D$1)/12 -> 0 | BA57: =($D$2*AY57)/12 -> 0 | BB57: =($D$3*AY57)/12 -> 0 | BC57: =SUM(AZ57:BB57) -> 0
AC58: 51 | AD58: 0.000767 | AE58: =(AD58*$D$1)/12 -> 32.604895 | AF58: =($D$2*AD58)/12 -> 1.9949651 | AG58: =($D$3*AD58)/12 -> 0 | AH58: =SUM(AE58:AG58) -> 34.59986 | AJ58: 117 | AK58: 0.000767 | AL58: =(AK58*$D$1)/12 -> 32.604895 | AM58: =($D$2*AK58)/12 -> 1.9949651 | AN58: =($D$3*AK58)/12 -> 0 | AO58: =SUM(AL58:AN58) -> 34.59986 | AQ58: 181 | AR58: 0.001533 | AS58: =(AR58*$D$1)/12 -> 65.167281 | AT58: =($D$2*AR58)/12 -> 3.9873293 | AU58: =($D$3*AR58)/12 -> 0 | AV58: =SUM(AS58:AU58) -> 69.15461 | AZ58: =(AY58*$D$1)/12 -> 0 | BA58: =($D$2*AY58)/12 -> 0 | BB58: =($D$3*AY58)/12 -> 0 | BC58: =SUM(AZ58:BB58) -> 0
AC59: 52 | AD59: 0.000767 | AE59: =(AD59*$D$1)/12 -> 32.604895 | AF59: =($D$2*AD59)/12 -> 1.9949651 | AG59: =($D$3*AD59)/12 -> 0 | AH59: =SUM(AE59:AG59) -> 34.59986 | AJ59: 118 | AK59: 0.000767 | AL59: =(AK59*$D$1)/12 -> 32.604895 | AM59: =($D$2*AK59)/12 -> 1.9949651 | AN59: =($D$3*AK59)/12 -> 0 | AO59: =SUM(AL59:AN59) -> 34.59986 | AQ59: 182 | AR59: 0.001533 | AS59: =(AR59*$D$1)/12 -> 65.167281 | AT59: =($D$2*AR59)/12 -> 3.9873293 | AU59: =($D$3*AR59)/12 -> 0 | AV59: =SUM(AS59:AU59) -> 69.15461 | AZ59: =(AY59*$D$1)/12 -> 0 | BA59: =($D$2*AY59)/12 -> 0 | BB59: =($D$3*AY59)/12 -> 0 | BC59: =SUM(AZ59:BB59) -> 0
AC60: 53 | AD60: 0.000767 | AE60: =(AD60*$D$1)/12 -> 32.604895 | AF60: =($D$2*AD60)/12 -> 1.9949651 | AG60: =($D$3*AD60)/12 -> 0 | AH60: =SUM(AE60:AG60) -> 34.59986 | AJ60: 119 | AK60: 0.000767 | AL60: =(AK60*$D$1)/12 -> 32.604895 | AM60: =($D$2*AK60)/12 -> 1.9949651 | AN60: =($D$3*AK60)/12 -> 0 | AO60: =SUM(AL60:AN60) -> 34.59986 | AQ60: 183 | AR60: 0.000767 | AS60: =(AR60*$D$1)/12 -> 32.604895 | AT60: =($D$2*AR60)/12 -> 1.9949651 | AU60: =($D$3*AR60)/12 -> 0 | AV60: =SUM(AS60:AU60) -> 34.59986 | AZ60: =(AY60*$D$1)/12 -> 0 | BA60: =($D$2*AY60)/12 -> 0 | BB60: =($D$3*AY60)/12 -> 0 | BC60: =SUM(AZ60:BB60) -> 0
...

Sheet Folha de Pagamento
B1: Vale alimentação | C1: =330 -> 330 | D1: 0.03 | E1: 0.05 | G1: 0.05 | H1: 0.05 | I1: 0.02 | J1: 0.05 | P1: 0.2 | Q1: inss patronal
B2: Vale Transporte | C2: 4 | D2: porteiro noturno | E2: porteiro noturno | F2: Camareira | G2: Eletricista | H2: Governanta | I2: Auxiliar de manutenção predial | J2: Recepcionista | K2: Auxiliar adm
B3: Referência | C3: Salário | D3: 1078.95 | E3: 1078.95 | F3: 983.85 | G3: 1105.98 | H3: 1078.95 | I3: 1078.95 | J3: 1131.99 | K3: 1078.94 | L3: Referência | M3: Salário | P3: 0.045 | Q3: outras entidades
C4: Anuênio | D4: =D3*D1 -> 32.3685 | E4: =E3*E1 -> 53.9475 | F4: =F3*F1 -> 0 | G4: =G3*G1 -> 55.299 | H4: =H3*H1 -> 53.9475 | I4: =I3*I1 -> 21.579 | J4: =J3*J1 -> 56.5995 | K4: =K3*K1 -> 0 | L4: 0.4 | M4: Insalubridade | P4: 0.01 | Q4: fap
B5: 0.25 | C5: AD Noturno | D5: =((D3/220)*120)*$B$5 -> 147.12955 | E5: =((E3/220)*120)*$B$5 -> 147.12955 | F5: 0 | G5: 0 | H5: 0 | I5: 0 | J5: 0 | K5: 0 | L5: 0.25 | M5: AD Noturno
B6: 32 | C6: VT | D6: =$B$6*$C$2 -> 128 | E6: =$B$6*$C$2 -> 128 | F6: =$L$6*$C$2 -> 208 | G6: =$L$6*$C$2 -> 208 | H6: =$L$6*$C$2 -> 208 | I6: =$L$6*$C$2 -> 208 | J6: =$L$6*$C$2 -> 208 | K6: =$L$6*$C$2 -> 208 | L6: 52 | M6: VT | P6: =SUM(P1:P4) -> 0.255
B7: -0.06 | C7: Desconto VT | D7: =(D3*$B$7) -> -64.737 | E7: =(E3*$B$7) -> -64.737 | F7: =(F3*$B$7) -> -59.031 | G7: =(G3*$B$7) -> -66.3588 | H7: =(H3*$B$7) -> -64.737 | I7: =(I3*$B$7) -> -64.737 | J7: =(J3*$B$7) -> -67.9194 | K7: =(K3*$B$7) -> -64.7364 | L7: -0.06 | M7: Desconto VT
B8: 1 | C8: VR | D8: =$B$8*$C$1 -> 330 | E8: =$B$8*$C$1 -> 330 | F8: =$B$8*$C$1 -> 330 | G8: =$B$8*$C$1 -> 330 | H8: =$B$8*$C$1 -> 330 | I8: =$B$8*$C$1 -> 330 | J8: =$B$8*$C$1 -> 330 | K8: =$B$8*$C$1 -> 330 | L8: 22 | M8: VR
B9: 12 | C9: Provisão 13° | D9: =(D3+D5+D4)/$B$9 -> 104.87067 | E9: =(E3+E5+E4)/$B$9 -> 106.66892 | F9: =(F3+F5+F4)/$B$9 -> 81.9875 | G9: =(G3+G5+G4)/$B$9 -> 96.77325 | H9: =(H3+H5+H4)/$B$9 -> 94.408125 | I9: =(I3+I5+I4)/$B$9 -> 91.71075 | J9: =(J3+J5+J4)/$B$9 -> 99.049125 | K9: =(K3+K5+K4)/$B$9 -> 89.911667 | L9: 12 | M9: Provisão 13°
B10: =P6 -> 0.255 | C10: Provisão inss 13° | D10: =D9*$B$10 -> 26.742021 | E10: =E9*$B$10 -> 27.200575 | F10: =F9*$B$10 -> 20.906813 | G10: =G9*$B$10 -> 24.677179 | H10: =H9*$B$10 -> 24.074072 | I10: =I9*$B$10 -> 23.386241 | J10: =J9*$B$10 -> 25.257527 | K10: =K9*$B$10 -> 22.927475 | L10: =Z5 -> 0 | M10: Provisão inss 13°
B11: 0.08 | C11: Provisão fgts 13° | D11: =D9*$B$11 -> 8.3896536 | E11: =E9*$B$11 -> 8.5335136 | F11: =F9*$B$11 -> 6.559 | G11: =G9*$B$11 -> 7.74186 | H11: =H9*$B$11 -> 7.55265 | I11: =I9*$B$11 -> 7.33686 | J11: =J9*$B$11 -> 7.92393 | K11: =K9*$B$11 -> 7.1929333 | L11: 0.08 | M11: Provisão fgts 13°
B12: 0.33 | C12: Provisão 1/3 Férias | D12: =((D3+D5+D4)*$B$12)/12 -> 34.607321 | E12: =((E3+E5+E4)*$B$12)/12 -> 35.200744 | F12: =((F3+F5+F4)*$B$12)/12 -> 27.055875 | G12: =((G3+G5+G4)*$B$12)/12 -> 31.935173 | H12: =((H3+H5+H4)*$B$12)/12 -> 31.154681 | I12: =((I3+I5+I4)*$B$12)/12 -> 30.264548 | J12: =((J3+J5+J4)*$B$12)/12 -> 32.686211 | K12: =((K3+K5+K4)*$B$12)/12 -> 29.67085 | L12: 0.33 | M12: Provisão 1/3 Férias
B13: =P6 -> 0.255 | C13: Provisão Inss 1/3 Férias | D13: =D12*$B$13 -> 8.8248669 | E13: =E12*$B$13 -> 8.9761897 | F13: =F12*$B$13 -> 6.8992481 | G13: =G12*$B$13 -> 8.143469 | H13: =H12*$B$13 -> 7.9444437 | I13: =I12*$B$13 -> 7.7174596 | J13: =J12*$B$13 -> 8.3349839 | K13: =K12*$B$13 -> 7.5660668 | L13: =Z5 -> 0 | M13: Provisão Inss 1/3 Férias
B14: 0.08 | C14: Provisão fgts 1/3 Férias | D14: =D12*$B$14 -> 2.7685857 | E14: =E12*$B$14 -> 2.8160595 | F14: =F12*$B$14 -> 2.16447 | G14: =G12*$B$14 -> 2.5548138 | H14: =H12*$B$14 -> 2.4923745 | I14: =I12*$B$14 -> 2.4211638 | J14: =J12*$B$14 -> 2.6148969 | K14: =K12*$B$14 -> 2.373668 | L14: 0.08 | M14: Provisão fgts 1/3 Férias
B15: 0.08 | C15: Fgts | D15: =(D3+D4+D5)*$B$15 -> 100.67584 | E15: =(E3+E4+E5)*$B$15 -> 102.40216 | F15: =(F3+F4+F5)*$B$15 -> 78.708 | G15: =(G3+G4+G5)*$B$15 -> 92.90232 | H15: =(H3+H4+H5)*$B$15 -> 90.6318 | I15: =(I3+I4+I5)*$B$15 -> 88.04232 | J15: =(J3+J4+J5)*$B$15 -> 95.08716 | K15: =(K3+K4+K5)*$B$15 -> 86.3152 | L15: 0.08 | M15: Fgts
B16: =P6 -> 0.255 | C16: inss | D16: =(D3+D4+D5)*$B$16 -> 320.90425 | E16: =(E3+E4+E5)*$B$16 -> 326.4069 | F16: =(F3+F4+F5)*$B$16 -> 250.88175 | G16: =(G3+G4+G5)*$B$16 -> 296.12615 | H16: =(H3+H4+H5)*$B$16 -> 288.88886 | I16: =(I3+I4+I5)*$B$16 -> 280.6349 | J16: =(J3+J4+J5)*$B$16 -> 303.09032 | K16: =(K3+K4+K5)*$B$16 -> 275.1297 | L16: =Z5 -> 0 | M16: inss
B17: 0.4 | C17: Provisão Rescisão | D17: =((D3+D4+D5)*$B$17)/12*0 -> 0 | E17: =((E3+E4+E5)*$B$17)/12*0 -> 0 | F17: =((F3+F4+F5)*$B$17)/12*0 -> 0 | G17: =((G3+G4+G5)*$B$17)/12*0 -> 0 | H17: =((H3+H4+H5)*$B$17)/12*0 -> 0 | I17: =((I3+I4+I5)*$B$17)/12*0 -> 0 | J17: =((J3+J4+J5)*$B$17)/12*0 -> 0 | K17: =((K3+K4+K5)*$B$17)/12*0 -> 0 | L17: 0.4 | M17: Provisão Rescisão
B18: 0.01 | C18: Pis sobre a Folha | D18: =(D3+D4+D5+D9+D12)*$B$18 -> 13.97926 | E18: =(E3+E4+E5+E9+E12)*$B$18 -> 14.218967 | F18: =(F3+F4+F5+F9+F12)*$B$18 -> 10.928934 | G18: =(G3+G4+G5+G9+G12)*$B$18 -> 12.899874 | H18: =(H3+H4+H5+H9+H12)*$B$18 -> 12.584603 | I18: =(I3+I4+I5+I9+I12)*$B$18 -> 12.225043 | J18: =(J3+J4+J5+J9+J12)*$B$18 -> 13.203248 | K18: =(K3+K4+K5+K9+K12)*$B$18 -> 11.985225 | L18: 0.01 | M18: Pis sobre a Folha
B19: 12 | C19: Provisão aviso prévio | D19: =(D3+D4+D5)/12*0 -> 0 | E19: =(E3+E4+E5)/12*0 -> 0 | F19: =(F3+F4+F5)/12*0 -> 0 | G19: =(G3+G4+G5)/12*0 -> 0 | H19: =(H3+H4+H5)/12*0 -> 0 | I19: =(I3+I4+I5)/12*0 -> 0 | J19: =(J3+J4+J5)/12*0 -> 0 | K19: =(K3+K4+K5)/12*0 -> 0 | L19: 12 | M19: Provisão aviso prévio
D20: =SUM(D3:D19) -> 2273.4735 | E20: =SUM(E3:E19) -> 2305.7141 | F20: =SUM(F3:F19) -> 1948.9106 | G20: =SUM(G3:G19) -> 2206.6743 | H20: =SUM(H3:H19) -> 2165.8921 | I20: =SUM(I3:I19) -> 2117.5313 | J20: =SUM(J3:J19) -> 2245.9175 | K20: =SUM(K3:K19) -> 2085.2764
D21: 1 | E21: 1 | F21: 1 | G21: 1 | H21: 1 | I21: 1 | J21: 1 | K21: 1 | L21: =SUM(D21:K21) -> 8 | M21: Funcionários
D22: =D20*D21 -> 2273.4735 | E22: =E20*E21 -> 2305.7141 | F22: =F20*F21 -> 1948.9106 | G22: =G20*G21 -> 2206.6743 | H22: =H20*H21 -> 2165.8921 | I22: =I20*I21 -> 2117.5313 | J22: =J20*J21 -> 2245.9175 | K22: =K20*K21 -> 2085.2764 | L22: =SUM(D22:K22) -> 17349.39
L23: 1358.97 | M23: provisões
L24: =L22-L23 -> 15990.42 | M24: folha
B32: [16:47, 7/5/2018] +55 73 8151-4214: 1 - Camareira | F32: 1
B33: [16:47, 7/5/2018] +55 73 8151-4214: 2 Eletricista | F33: 2
B34: [16:48, 7/5/2018] +55 73 8151-4214: 3 Governanta de hotelaria | F34: 3
B35: [16:49, 7/5/2018] +55 73 8151-4214: 4 Porteiro de Edificios | F35: 4
B36: [16:50, 7/5/2018] +55 73 8151-4214: 5 Auxiliar de Manutenção Predial | F36: 5
B37: [16:50, 7/5/2018] +55 73 8151-4214: 6 Recepcionista | F37: 6
B38: [16:51, 7/5/2018] +55 73 8151-4214: 7 Auxiliar administrativo | F38: 7
F39: =SUM(F32:F38) -> 28
