Workbook

Sheet Ini
A1: 3.0.2 | C1: PLANILHA DE
C2: CÁLCULO DE PONTO DE EQUILÍBRIO 3.0
C3: Seja bem-vindo(a). Com esta planilha você poderá ter o total controle sobre o cálculo do faturamento mínimo necessário para cobrir os custos (fixos e variáveis) da sua empresa.
C4: IMPORTANTE: LEIA OS PASSOS E ENTENDA A PLANILHA
C5: Dúvidas? Clique nos Links presentes em toda a planilha para ver vídeos explicativos sobre o método, preenchimento e análise de cada aba!
C6: Passo 1 | D6: PREMISSAS GERAIS
C7: Inicialmento você irá realizar o registro de uma projeção de venda e o custo diretamente associado aos produtos vendidos.
C8: 1.1. Produtos: Aqui você irá registrar uma projeção de suas vendas, produto a produto.
C9: 1.2. Custos Diretos: Aqui você irá registrar os custos relacionados aos produtos vendidos. O valor da Matéria-prima, Impostos, Comissões e outros custos diretos.
C11: Passo 2 | D11: PONTO DE EQUILÍBRIO
C12: Nesta etapa do processo você irá registrar os seus Custos Fixos de sua empresa e a partir daí iremos iniciar os cálculos do Índice de Margem de Contribuição (IMC) para descobrirmos a sua Receita necessária para cobrir seus Custos.
C13: 2.1. Margem de Contribuição: Aqui você irá relacionar os seus Custos Fixos com seus respectivos valores mensais. Com base nestes números iremos calcular a sua Margem de Contribuição.
C14: 2.2. Ponto de Equilíbrio por Produto: Aqui você poderá selecionar um produto e observar a quantidade mínima necessária a ser vendida deste para atingir a Receita necessária para cobrir os custos com este produto.
C16: Passo 3 | D16: ANÁLISE DA CONCORRÊNCIA
C17: Aqui você irá inserir uma pesquisa de mercado em relação à sua concorrência. A partir desta análise, é possível identificar oportunidades para elevar o seu markup ou diminuir para se tornar mais competitivo no mercado.
C19: Passo 4 | D19: RESULTADOS CONSOLIDADOS
C20: Aqui você poderá conferir os resultados consolidados, calculados automáticamente com base nas informações fornecidas anteriormente, do Ponto de Equilíbrio de seus produtos.
C22: Passo 5 | D22: GRÁFICOS
C23: Faça uma análise gráfica de forma rápida e eficiente dos resultados de sua planilha.
C25: Passo 6 | D25: RELATÓRIO DE IMPRESSÃO
C26: Imprima o relatório da sua análise de Ponto de Equilíbrio. Apenas o que importa, com formatação econômica para gastar menos tinta e ter melhor aproveitamento do papel.

Sheet PG
A1: 3.0.2 | C1: 1. PREMISSAS GERAIS
C5: Produto | D5: Preço de Venda | E5: Projeções de vendas mensais | F5: Receita bruta mensal | G5: % de Participação
C6: Ex.: Camisa | D6: Ex.: R$ 100,00 | E6: Ex.: 50 | F6: Ex.: R$ 5.000,00 | G6: Ex.: 100%
F7: =IF(ISERROR( IF(C7="","",D7*E7)),"",IF(C7="","",D7*E7)) | G7: =IF(ISERROR( $F7/SUM($F$7:$F$507)),"",$F7/SUM($F$7:$F$507))
F8: =IF(ISERROR( IF(C8="","",D8*E8)),"",IF(C8="","",D8*E8)) | G8: =IF(ISERROR( $F8/SUM($F$7:$F$507)),"",$F8/SUM($F$7:$F$507))
F9: =IF(ISERROR( IF(C9="","",D9*E9)),"",IF(C9="","",D9*E9)) | G9: =IF(ISERROR( $F9/SUM($F$7:$F$507)),"",$F9/SUM($F$7:$F$507))
F10: =IF(ISERROR( IF(C10="","",D10*E10)),"",IF(C10="","",D10*E10)) | G10: =IF(ISERROR( $F10/SUM($F$7:$F$507)),"",$F10/SUM($F$7:$F$507))
F11: =IF(ISERROR( IF(C11="","",D11*E11)),"",IF(C11="","",D11*E11)) | G11: =IF(ISERROR( $F11/SUM($F$7:$F$507)),"",$F11/SUM($F$7:$F$507))
F12: =IF(ISERROR( IF(C12="","",D12*E12)),"",IF(C12="","",D12*E12)) | G12: =IF(ISERROR( $F12/SUM($F$7:$F$507)),"",$F12/SUM($F$7:$F$507))
F13: =IF(ISERROR( IF(C13="","",D13*E13)),"",IF(C13="","",D13*E13)) | G13: =IF(ISERROR( $F13/SUM($F$7:$F$507)),"",$F13/SUM($F$7:$F$507))
F14: =IF(ISERROR( IF(C14="","",D14*E14)),"",IF(C14="","",D14*E14)) | G14: =IF(ISERROR( $F14/SUM($F$7:$F$507)),"",$F14/SUM($F$7:$F$507))
F15: =IF(ISERROR( IF(C15="","",D15*E15)),"",IF(C15="","",D15*E15)) | G15: =IF(ISERROR( $F15/SUM($F$7:$F$507)),"",$F15/SUM($F$7:$F$507))
F16: =IF(ISERROR( IF(C16="","",D16*E16)),"",IF(C16="","",D16*E16)) | G16: =IF(ISERROR( $F16/SUM($F$7:$F$507)),"",$F16/SUM($F$7:$F$507))
F17: =IF(ISERROR( IF(C17="","",D17*E17)),"",IF(C17="","",D17*E17)) | G17: =IF(ISERROR( $F17/SUM($F$7:$F$507)),"",$F17/SUM($F$7:$F$507))
F18: =IF(ISERROR( IF(C18="","",D18*E18)),"",IF(C18="","",D18*E18)) | G18: =IF(ISERROR( $F18/SUM($F$7:$F$507)),"",$F18/SUM($F$7:$F$507))
... F507: =IF(ISERROR( IF(C507="","",D507*E507)),"",IF(C507="","",D507*E507)) | G507: =IF(ISERROR( $F507/SUM($F$7:$F$507)),"",$F507/SUM($F$7:$F$507))

Sheet PEq
A1: 3.0.2 | C1: 2. PONTO DE EQUILÍBRIO
C5: Custo Fixo | D5: Valor (R$) | F5: Margem de contribuição
C6: Pró Labore e salários | F6: Descrição | G6: Valor (R$)
C7: Taxa de propriedade (águal e luz) | F7: Preço de venda médio dos seus produtos | G7: =IF(ISERROR(SUMPRODUCT(PG!D7:D507,PG!E7:E507)/SUM(PG!E7:E507)),"",SUMPRODUCT(PG!D7:D507,PG!E7:E507)/SUM(PG!E7:E507))
C8: Telefone e internet
C9: Aluguel
C10: Marketing | F10: Margem de contribuição média dos seus produtos | G10: =IF(ISERROR(SUMPRODUCT(PG_CD!L6:L506,PG!E7:E507)/SUM(PG!E7:E507)),"",SUMPRODUCT(PG_CD!L6:L506,PG!E7:E507)/SUM(PG!E7:E507))
C11: Empréstimos
C12: Legais e Jurídicos
C13: Outros Custos | F13: Custos diretos totais | G13: =IF(ISERROR(SUMPRODUCT(PG_CD!$H$6:$H$506,PG!E7:E507)),"",SUMPRODUCT(PG_CD!$H$6:$H$506,PG!E7:E507)) -> 0
F14: Custos diretos médio por produto | G14: =G13/SUM(PG!C7:E507) -> #DIV/0!
F16: Ponto de Equilíbrio (Break Even Point)
F17: Descrição | G17: Valor (R$)
F18: Qual o valor total dos seus custos fixos? | G18: =SUM(D6:D50) -> 0
F19: Qual deve ser o faturamento para não ter prejuízo? | G19: =IF(ISERROR(G18/(G10/G7)),"",G18/(G10/G7))
F20: Quantos produtos você precisa vender para não ter prejuízo? | G20: =IF(ISERROR(G19/G7),"",G19/G7)

Sheet PG_CD
A1: 3.0.2 | C1: 1. PREMISSAS GERAIS
C5: Produto | D5: Matéria - Prima | E5: Comissões (%) | F5: Impostos (%) | G5: Outros gastos | H5: Total custo por produto | J5: Comissões (%) | K5: Impostos (%) | L5: Margem de contribuição unitária | M5: IMC (%) | N5: Receita no ponto de equilíbrio | O5: Quantidade a ser vendida | P5: Outros Gastos | Q5: Matéria Prima
C6: =PG!C7 -> 0 | H6: =D6+PG!D7*(E6+F6)+G6 -> 0 | J6: =IF(ISERROR( PG!F7*E6),"",PG!F7*E6) | K6: =IF(ISERROR( PG!F7*F6),"",PG!F7*F6) | L6: =IF(ISERROR( PG!D7-H6),"",PG!D7-H6) -> 0 | M6: =IF(ISERROR( L6/PG!D7),"",L6/PG!D7) | N6: =IF(ISERROR( (O6*PG!D7)),"",(O6*PG!D7)) | O6: =IF(ISERROR( PEq!$G$20*PG!G7),"",PEq!$G$20*PG!G7) | P6: =IF(ISERROR( PG!E7*G6),"",PG!E7*G6) -> 0 | Q6: =IF(ISERROR( PG!E7*D6),"",PG!E7*D6) -> 0
C7: =PG!C8 -> 0 | H7: =D7+PG!D8*(E7+F7)+G7 -> 0 | J7: =IF(ISERROR( PG!F8*E7),"",PG!F8*E7) | K7: =IF(ISERROR( PG!F8*F7),"",PG!F8*F7) | L7: =IF(ISERROR( PG!D8-H7),"",PG!D8-H7) -> 0 | M7: =IF(ISERROR( L7/PG!D8),"",L7/PG!D8) | N7: =IF(ISERROR( (O7*PG!D8)),"",(O7*PG!D8)) | O7: =IF(ISERROR( PEq!$G$20*PG!G8),"",PEq!$G$20*PG!G8) | P7: =IF(ISERROR( PG!E8*G7),"",PG!E8*G7) -> 0 | Q7: =IF(ISERROR( PG!E8*D7),"",PG!E8*D7) -> 0
C8: =PG!C9 -> 0 | H8: =D8+PG!D9*(E8+F8)+G8 -> 0 | J8: =IF(ISERROR( PG!F9*E8),"",PG!F9*E8) | K8: =IF(ISERROR( PG!F9*F8),"",PG!F9*F8) | L8: =IF(ISERROR( PG!D9-H8),"",PG!D9-H8) -> 0 | M8: =IF(ISERROR( L8/PG!D9),"",L8/PG!D9) | N8: =IF(ISERROR( (O8*PG!D9)),"",(O8*PG!D9)) | O8: =IF(ISERROR( PEq!$G$20*PG!G9),"",PEq!$G$20*PG!G9) | P8: =IF(ISERROR( PG!E9*G8),"",PG!E9*G8) -> 0 | Q8: =IF(ISERROR( PG!E9*D8),"",PG!E9*D8) -> 0
C9: =PG!C10 -> 0 | H9: =D9+PG!D10*(E9+F9)+G9 -> 0 | J9: =IF(ISERROR( PG!F10*E9),"",PG!F10*E9) | K9: =IF(ISERROR( PG!F10*F9),"",PG!F10*F9) | L9: =IF(ISERROR( PG!D10-H9),"",PG!D10-H9) -> 0 | M9: =IF(ISERROR( L9/PG!D10),"",L9/PG!D10) | N9: =IF(ISERROR( (O9*PG!D10)),"",(O9*PG!D10)) | O9: =IF(ISERROR( PEq!$G$20*PG!G10),"",PEq!$G$20*PG!G10) | P9: =IF(ISERROR( PG!E10*G9),"",PG!E10*G9) -> 0 | Q9: =IF(ISERROR( PG!E10*D9),"",PG!E10*D9) -> 0
C10: =PG!C11 -> 0 | H10: =D10+PG!D11*(E10+F10)+G10 -> 0 | J10: =IF(ISERROR( PG!F11*E10),"",PG!F11*E10) | K10: =IF(ISERROR( PG!F11*F10),"",PG!F11*F10) | L10: =IF(ISERROR( PG!D11-H10),"",PG!D11-H10) -> 0 | M10: =IF(ISERROR( L10/PG!D11),"",L10/PG!D11) | N10: =IF(ISERROR( (O10*PG!D11)),"",(O10*PG!D11)) | O10: =IF(ISERROR( PEq!$G$20*PG!G11),"",PEq!$G$20*PG!G11) | P10: =IF(ISERROR( PG!E11*G10),"",PG!E11*G10) -> 0 | Q10: =IF(ISERROR( PG!E11*D10),"",PG!E11*D10) -> 0
C11: =PG!C12 -> 0 | H11: =D11+PG!D12*(E11+F11)+G11 -> 0 | J11: =IF(ISERROR( PG!F12*E11),"",PG!F12*E11) | K11: =IF(ISERROR( PG!F12*F11),"",PG!F12*F11) | L11: =IF(ISERROR( PG!D12-H11),"",PG!D12-H11) -> 0 | M11: =IF(ISERROR( L11/PG!D12),"",L11/PG!D12) | N11: =IF(ISERROR( (O11*PG!D12)),"",(O11*PG!D12)) | O11: =IF(ISERROR( PEq!$G$20*PG!G12),"",PEq!$G$20*PG!G12) | P11: =IF(ISERROR( PG!E12*G11),"",PG!E12*G11) -> 0 | Q11: =IF(ISERROR( PG!E12*D11),"",PG!E12*D11) -> 0
C12: =PG!C13 -> 0 | H12: =D12+PG!D13*(E12+F12)+G12 -> 0 | J12: =IF(ISERROR( PG!F13*E12),"",PG!F13*E12) | K12: =IF(ISERROR( PG!F13*F12),"",PG!F13*F12) | L12: =IF(ISERROR( PG!D13-H12),"",PG!D13-H12) -> 0 | M12: =IF(ISERROR( L12/PG!D13),"",L12/PG!D13) | N12: =IF(ISERROR( (O12*PG!D13)),"",(O12*PG!D13)) | O12: =IF(ISERROR( PEq!$G$20*PG!G13),"",PEq!$G$20*PG!G13) | P12: =IF(ISERROR( PG!E13*G12),"",PG!E13*G12) -> 0 | Q12: =IF(ISERROR( PG!E13*D12),"",PG!E13*D12) -> 0
C13: =PG!C14 -> 0 | H13: =D13+PG!D14*(E13+F13)+G13 -> 0 | J13: =IF(ISERROR( PG!F14*E13),"",PG!F14*E13) | K13: =IF(ISERROR( PG!F14*F13),"",PG!F14*F13) | L13: =IF(ISERROR( PG!D14-H13),"",PG!D14-H13) -> 0 | M13: =IF(ISERROR( L13/PG!D14),"",L13/PG!D14) | N13: =IF(ISERROR( (O13*PG!D14)),"",(O13*PG!D14)) | O13: =IF(ISERROR( PEq!$G$20*PG!G14),"",PEq!$G$20*PG!G14) | P13: =IF(ISERROR( PG!E14*G13),"",PG!E14*G13) -> 0 | Q13: =IF(ISERROR( PG!E14*D13),"",PG!E14*D13) -> 0
C14: =PG!C15 -> 0 | H14: =D14+PG!D15*(E14+F14)+G14 -> 0 | J14: =IF(ISERROR( PG!F15*E14),"",PG!F15*E14) | K14: =IF(ISERROR( PG!F15*F14),"",PG!F15*F14) | L14: =IF(ISERROR( PG!D15-H14),"",PG!D15-H14) -> 0 | M14: =IF(ISERROR( L14/PG!D15),"",L14/PG!D15) | N14: =IF(ISERROR( (O14*PG!D15)),"",(O14*PG!D15)) | O14: =IF(ISERROR( PEq!$G$20*PG!G15),"",PEq!$G$20*PG!G15) | P14: =IF(ISERROR( PG!E15*G14),"",PG!E15*G14) -> 0 | Q14: =IF(ISERROR( PG!E15*D14),"",PG!E15*D14) -> 0
C15: =PG!C16 -> 0 | H15: =D15+PG!D16*(E15+F15)+G15 -> 0 | J15: =IF(ISERROR( PG!F16*E15),"",PG!F16*E15) | K15: =IF(ISERROR( PG!F16*F15),"",PG!F16*F15) | L15: =IF(ISERROR( PG!D16-H15),"",PG!D16-H15) -> 0 | M15: =IF(ISERROR( L15/PG!D16),"",L15/PG!D16) | N15: =IF(ISERROR( (O15*PG!D16)),"",(O15*PG!D16)) | O15: =IF(ISERROR( PEq!$G$20*PG!G16),"",PEq!$G$20*PG!G16) | P15: =IF(ISERROR( PG!E16*G15),"",PG!E16*G15) -> 0 | Q15: =IF(ISERROR( PG!E16*D15),"",PG!E16*D15) -> 0
C16: =PG!C17 -> 0 | H16: =D16+PG!D17*(E16+F16)+G16 -> 0 | J16: =IF(ISERROR( PG!F17*E16),"",PG!F17*E16) | K16: =IF(ISERROR( PG!F17*F16),"",PG!F17*F16) | L16: =IF(ISERROR( PG!D17-H16),"",PG!D17-H16) -> 0 | M16: =IF(ISERROR( L16/PG!D17),"",L16/PG!D17) | N16: =IF(ISERROR( (O16*PG!D17)),"",(O16*PG!D17)) | O16: =IF(ISERROR( PEq!$G$20*PG!G17),"",PEq!$G$20*PG!G17) | P16: =IF(ISERROR( PG!E17*G16),"",PG!E17*G16) -> 0 | Q16: =IF(ISERROR( PG!E17*D16),"",PG!E17*D16) -> 0
C17: =PG!C18 -> 0 | H17: =D17+PG!D18*(E17+F17)+G17 -> 0 | J17: =IF(ISERROR( PG!F18*E17),"",PG!F18*E17) | K17: =IF(ISERROR( PG!F18*F17),"",PG!F18*F17) | L17: =IF(ISERROR( PG!D18-H17),"",PG!D18-H17) -> 0 | M17: =IF(ISERROR( L17/PG!D18),"",L17/PG!D18) | N17: =IF(ISERROR( (O17*PG!D18)),"",(O17*PG!D18)) | O17: =IF(ISERROR( PEq!$G$20*PG!G18),"",PEq!$G$20*PG!G18) | P17: =IF(ISERROR( PG!E18*G17),"",PG!E18*G17) -> 0 | Q17: =IF(ISERROR( PG!E18*D17),"",PG!E18*D17) -> 0
... C507: =PG!C508 -> 0 | H507: =D507+PG!D508*(E507+F507)+G507 -> 0 | J507: =IF(ISERROR( PG!F508*E507),"",PG!F508*E507) -> 0 | K507: =IF(ISERROR( PG!F508*F507),"",PG!F508*F507) -> 0 | L507: =IF(ISERROR( PG!D508-H507),"",PG!D508-H507) -> 0 | M507: =IF(ISERROR( L507/PG!D508),"",L507/PG!D508) | N507: =IF(ISERROR( (O507*PG!D508)),"",(O507*PG!D508)) | O507: =IF(ISERROR( PEq!$G$20*PG!G508),"",PEq!$G$20*PG!G508) | P507: =IF(ISERROR( PG!E508*G507),"",PG!E508*G507) -> 0 | Q507: =IF(ISERROR( PG!E508*D507),"",PG!E508*D507) -> 0

Sheet Peq_Pro
A1: 3.0.2 | C1: 2. PONTO DE EQUILÍBRIO
T3: Produto
T4: =IF(ISERR( IF(PG!C7="","",PG!C7)),"",IF(PG!C7="","",PG!C7))
C5: Selecione o seu produto | T5: =IF(ISERR( IF(PG!C8="","",PG!C8)),"",IF(PG!C8="","",PG!C8))
T6: =IF(ISERR( IF(PG!C9="","",PG!C9)),"",IF(PG!C9="","",PG!C9))
C7: ="Receita do(a) "&D5&" no Ponto de Equilíbrio" -> Receita do(a) _x000D_no Ponto de Equilíbrio | D7: =IF(ISERROR( IFERROR(VLOOKUP($D$5,PG_CD!$C$6:$O$507,12,0),"")),"",IFERROR(VLOOKUP($D$5,PG_CD!$C$6:$O$507,12,0),"")) | T7: =IF(ISERR( IF(PG!C10="","",PG!C10)),"",IF(PG!C10="","",PG!C10))
C8: Unidades | D8: =IF(ISERROR( IFERROR(VLOOKUP($D$5,PG_CD!$C$6:$O$507,13,0),"")),"",IFERROR(VLOOKUP($D$5,PG_CD!$C$6:$O$507,13,0),"")) | T8: =IF(ISERR( IF(PG!C11="","",PG!C11)),"",IF(PG!C11="","",PG!C11))
C9: Total de despesas diretas | D9: =IF(ISERROR( VLOOKUP($D$5,PG_CD!$C$6:$M$507,6,0)*D8),"",VLOOKUP($D$5,PG_CD!$C$6:$M$507,6,0)*D8) | T9: =IF(ISERR( IF(PG!C12="","",PG!C12)),"",IF(PG!C12="","",PG!C12))
C10: MC unitária | D10: =IF(ISERROR( VLOOKUP($D$5,PG_CD!$C$6:$L$507,10,0)),"",VLOOKUP($D$5,PG_CD!$C$6:$L$507,10,0)) -> 0 | T10: =IF(ISERR( IF(PG!C13="","",PG!C13)),"",IF(PG!C13="","",PG!C13))
C11: MC ponderada | D11: =IF(ISERROR( D10*VLOOKUP($D$5,PG!$C$7:$G$507,5,0)),"",D10*VLOOKUP($D$5,PG!$C$7:$G$507,5,0)) | T11: =IF(ISERR( IF(PG!C14="","",PG!C14)),"",IF(PG!C14="","",PG!C14))
T12: =IF(ISERR( IF(PG!C15="","",PG!C15)),"",IF(PG!C15="","",PG!C15))
T13: =IF(ISERR( IF(PG!C16="","",PG!C16)),"",IF(PG!C16="","",PG!C16))
T14: =IF(ISERR( IF(PG!C17="","",PG!C17)),"",IF(PG!C17="","",PG!C17))
T15: =IF(ISERR( IF(PG!C18="","",PG!C18)),"",IF(PG!C18="","",PG!C18))
T16: =IF(ISERR( IF(PG!C19="","",PG!C19)),"",IF(PG!C19="","",PG!C19))
T17: =IF(ISERR( IF(PG!C20="","",PG!C20)),"",IF(PG!C20="","",PG!C20))
T18: =IF(ISERR( IF(PG!C21="","",PG!C21)),"",IF(PG!C21="","",PG!C21))
T19: =IF(ISERR( IF(PG!C22="","",PG!C22)),"",IF(PG!C22="","",PG!C22))
T20: =IF(ISERR( IF(PG!C23="","",PG!C23)),"",IF(PG!C23="","",PG!C23))
T21: =IF(ISERR( IF(PG!C24="","",PG!C24)),"",IF(PG!C24="","",PG!C24))
T22: =IF(ISERR( IF(PG!C25="","",PG!C25)),"",IF(PG!C25="","",PG!C25))
T23: =IF(ISERR( IF(PG!C26="","",PG!C26)),"",IF(PG!C26="","",PG!C26))
... T504: =IF(ISERR( IF(PG!C507="","",PG!C507)),"",IF(PG!C507="","",PG!C507))

Sheet AC
A1: 3.0.2 | C1: 3. ANÁLISE DA CONCORRÊNCIA | P1: Preço | Q1: =IF(ISERR( IF(PG!C7="","",PG!C7)),"",IF(PG!C7="","",PG!C7))
P2: Qualidade | Q2: =IF(ISERR( IF(PG!C8="","",PG!C8)),"",IF(PG!C8="","",PG!C8))
P3: Localização Geográfica | Q3: =IF(ISERR( IF(PG!C9="","",PG!C9)),"",IF(PG!C9="","",PG!C9))
P4: Posicionamento no mercado | Q4: =IF(ISERR( IF(PG!C10="","",PG!C10)),"",IF(PG!C10="","",PG!C10))
C5: Importante: Faça uma pesquisa com seus principais concorrentes. Recomendamos que você inclua sempre a empresa top de mercado na sua pesquisa. | Q5: =IF(ISERR( IF(PG!C11="","",PG!C11)),"",IF(PG!C11="","",PG!C11))
Q6: =IF(ISERR( IF(PG!C12="","",PG!C12)),"",IF(PG!C12="","",PG!C12))
C7: Análise dos concorrentes | Q7: =IF(ISERR( IF(PG!C13="","",PG!C13)),"",IF(PG!C13="","",PG!C13))
C8: Empresa | D8: Diferencial | E8: Produto | F8: Preço Concorrente | G8: Seu Preço | H8: Orientação | Q8: =IF(ISERR( IF(PG!C14="","",PG!C14)),"",IF(PG!C14="","",PG!C14))
G9: =IF(ISERROR( IF(C9="","",IFERROR(VLOOKUP(E9,PG!$C$7:$D$507,2,0),""))),"",IF(C9="","",IFERROR(VLOOKUP(E9,PG!$C$7:$D$507,2,0),""))) | H9: =IF(ISERROR( IF(C9="","", IF(F9<G9,"Seu preço está acima de um dos seus concorrentes. Você precisa encontrar meios como qualidade, localização, etc, para justificar esta diferença.",IF(F9>G9,"Seu preço está abaixo de um dos seus concorrentes. Mas ele se posiciona pelo(a) "&D9&". Fique atento sobre este detalhe, pois preço baixo não é garantia de sucesso.","Seu preço está igual a de um dos seus concorrentes. Mas ele se posiciona pela "&D9&". Se você conseguir este mesmo benefício, poderá estar em vantagem.")))),"", IF(C9="","", IF(F9<G9,"Seu preço está acima de um dos seus concorrentes. Você precisa encontrar meios como qualidade, localização, etc, para justificar esta diferença.",IF(F9>G9,"Seu preço está abaixo de um dos seus concorrentes. Mas ele se posiciona pelo(a) "&D9&". Fique atento sobre este detalhe, pois preço baixo não é garantia de sucesso.","Seu preço está igual a de um dos seus concorrentes. Mas ele se posiciona pela "&D9&". Se você conseguir este mesmo benefício, poderá estar em vantagem.")))) | Q9: =IF(ISERR( IF(PG!C15="","",PG!C15)),"",IF(PG!C15="","",PG!C15))
G10: =IF(ISERROR( IF(C10="","",IFERROR(VLOOKUP(E10,PG!$C$7:$D$507,2,0),""))),"",IF(C10="","",IFERROR(VLOOKUP(E10,PG!$C$7:$D$507,2,0),""))) | H10: =IF(ISERROR( IF(C10="","", IF(F10<G10,"Seu preço está acima de um dos seus concorrentes. Você precisa encontrar meios como qualidade, localização, etc, para justificar esta diferença.",IF(F10>G10,"Seu preço está abaixo de um dos seus concorrentes. Mas ele se posiciona pelo(a) "&D10&". Fique atento sobre este detalhe, pois preço baixo não é garantia de sucesso.","Seu preço está igual a de um dos seus concorrentes. Mas ele se posiciona pela "&D10&". Se você conseguir este mesmo benefício, poderá estar em vantagem.")))),"", IF(C10="","", IF(F10<G10,"Seu preço está acima de um dos seus concorrentes. Você precisa encontrar meios como qualidade, localização, etc, para justificar esta diferença.",IF(F10>G10,"Seu preço está abaixo de um dos seus concorrentes. Mas ele se posiciona pelo(a) "&D10&". Fique atento sobre este detalhe, pois preço baixo não é garantia de sucesso.","Seu preço está igual a de um dos seus concorrentes. Mas ele se posiciona pela "&D10&". Se você conseguir este mesmo benefício, poderá estar em vantagem.")))) | Q10: =IF(ISERR( IF(PG!C16="","",PG!C16)),"",IF(PG!C16="","",PG!C16))
G11: =IF(ISERROR( IF(C11="","",IFERROR(VLOOKUP(E11,PG!$C$7:$D$507,2,0),""))),"",IF(C11="","",IFERROR(VLOOKUP(E11,PG!$C$7:$D$507,2,0),""))) | H11: =IF(ISERROR( IF(C11="","", IF(F11<G11,"Seu preço está acima de um dos seus concorrentes. Você precisa encontrar meios como qualidade, localização, etc, para justificar esta diferença.",IF(F11>G11,"Seu preço está abaixo de um dos seus concorrentes. Mas ele se posiciona pelo(a) "&D11&". Fique atento sobre este detalhe, pois preço baixo não é garantia de sucesso.","Seu preço está igual a de um dos seus concorrentes. Mas ele se posiciona pela "&D11&". Se você conseguir este mesmo benefício, poderá estar em vantagem.")))),"", IF(C11="","", IF(F11<G11,"Seu preço está acima de um dos seus concorrentes. Você precisa encontrar meios como qualidade, localização, etc, para justificar esta diferença.",IF(F11>G11,"Seu preço está abaixo de um dos seus concorrentes. Mas ele se posiciona pelo(a) "&D11&". Fique atento sobre este detalhe, pois preço baixo não é garantia de sucesso.","Seu preço está igual a de um dos seus concorrentes. Mas ele se posiciona pela "&D11&". Se você conseguir este mesmo benefício, poderá estar em vantagem.")))) | Q11: =IF(ISERR( IF(PG!C17="","",PG!C17)),"",IF(PG!C17="","",PG!C17))
G12: =IF(ISERROR( IF(C12="","",IFERROR(VLOOKUP(E12,PG!$C$7:$D$507,2,0),""))),"",IF(C12="","",IFERROR(VLOOKUP(E12,PG!$C$7:$D$507,2,0),""))) | H12: =IF(ISERROR( IF(C12="","", IF(F12<G12,"Seu preço está acima de um dos seus concorrentes. Você precisa encontrar meios como qualidade, localização, etc, para justificar esta diferença.",IF(F12>G12,"Seu preço está abaixo de um dos seus concorrentes. Mas ele se posiciona pelo(a) "&D12&". Fique atento sobre este detalhe, pois preço baixo não é garantia de sucesso.","Seu preço está igual a de um dos seus concorrentes. Mas ele se posiciona pela "&D12&". Se você conseguir este mesmo benefício, poderá estar em vantagem.")))),"", IF(C12="","", IF(F12<G12,"Seu preço está acima de um dos seus concorrentes. Você precisa encontrar meios como qualidade, localização, etc, para justificar esta diferença.",IF(F12>G12,"Seu preço está abaixo de um dos seus concorrentes. Mas ele se posiciona pelo(a) "&D12&". Fique atento sobre este detalhe, pois preço baixo não é garantia de sucesso.","Seu preço está igual a de um dos seus concorrentes. Mas ele se posiciona pela "&D12&". Se você conseguir este mesmo benefício, poderá estar em vantagem.")))) | Q12: =IF(ISERR( IF(PG!C18="","",PG!C18)),"",IF(PG!C18="","",PG!C18))
G13: =IF(ISERROR( IF(C13="","",IFERROR(VLOOKUP(E13,PG!$C$7:$D$507,2,0),""))),"",IF(C13="","",IFERROR(VLOOKUP(E13,PG!$C$7:$D$507,2,0),""))) | H13: =IF(ISERROR( IF(C13="","", IF(F13<G13,"Seu preço está acima de um dos seus concorrentes. Você precisa encontrar meios como qualidade, localização, etc, para justificar esta diferença.",IF(F13>G13,"Seu preço está abaixo de um dos seus concorrentes. Mas ele se posiciona pelo(a) "&D13&". Fique atento sobre este detalhe, pois preço baixo não é garantia de sucesso.","Seu preço está igual a de um dos seus concorrentes. Mas ele se posiciona pela "&D13&". Se você conseguir este mesmo benefício, poderá estar em vantagem.")))),"", IF(C13="","", IF(F13<G13,"Seu preço está acima de um dos seus concorrentes. Você precisa encontrar meios como qualidade, localização, etc, para justificar esta diferença.",IF(F13>G13,"Seu preço está abaixo de um dos seus concorrentes. Mas ele se posiciona pelo(a) "&D13&". Fique atento sobre este detalhe, pois preço baixo não é garantia de sucesso.","Seu preço está igual a de um dos seus concorrentes. Mas ele se posiciona pela "&D13&". Se você conseguir este mesmo benefício, poderá estar em vantagem.")))) | Q13: =IF(ISERR( IF(PG!C19="","",PG!C19)),"",IF(PG!C19="","",PG!C19))
G14: =IF(ISERROR( IF(C14="","",IFERROR(VLOOKUP(E14,PG!$C$7:$D$507,2,0),""))),"",IF(C14="","",IFERROR(VLOOKUP(E14,PG!$C$7:$D$507,2,0),""))) | H14: =IF(ISERROR( IF(C14="","", IF(F14<G14,"Seu preço está acima de um dos seus concorrentes. Você precisa encontrar meios como qualidade, localização, etc, para justificar esta diferença.",IF(F14>G14,"Seu preço está abaixo de um dos seus concorrentes. Mas ele se posiciona pelo(a) "&D14&". Fique atento sobre este detalhe, pois preço baixo não é garantia de sucesso.","Seu preço está igual a de um dos seus concorrentes. Mas ele se posiciona pela "&D14&". Se você conseguir este mesmo benefício, poderá estar em vantagem.")))),"", IF(C14="","", IF(F14<G14,"Seu preço está acima de um dos seus concorrentes. Você precisa encontrar meios como qualidade, localização, etc, para justificar esta diferença.",IF(F14>G14,"Seu preço está abaixo de um dos seus concorrentes. Mas ele se posiciona pelo(a) "&D14&". Fique atento sobre este detalhe, pois preço baixo não é garantia de sucesso.","Seu preço está igual a de um dos seus concorrentes. Mas ele se posiciona pela "&D14&". Se você conseguir este mesmo benefício, poderá estar em vantagem.")))) | Q14: =IF(ISERR( IF(PG!C20="","",PG!C20)),"",IF(PG!C20="","",PG!C20))
G15: =IF(ISERROR( IF(C15="","",IFERROR(VLOOKUP(E15,PG!$C$7:$D$507,2,0),""))),"",IF(C15="","",IFERROR(VLOOKUP(E15,PG!$C$7:$D$507,2,0),""))) | H15: =IF(ISERROR( IF(C15="","", IF(F15<G15,"Seu preço está acima de um dos seus concorrentes. Você precisa encontrar meios como qualidade, localização, etc, para justificar esta diferença.",IF(F15>G15,"Seu preço está abaixo de um dos seus concorrentes. Mas ele se posiciona pelo(a) "&D15&". Fique atento sobre este detalhe, pois preço baixo não é garantia de sucesso.","Seu preço está igual a de um dos seus concorrentes. Mas ele se posiciona pela "&D15&". Se você conseguir este mesmo benefício, poderá estar em vantagem.")))),"", IF(C15="","", IF(F15<G15,"Seu preço está acima de um dos seus concorrentes. Você precisa encontrar meios como qualidade, localização, etc, para justificar esta diferença.",IF(F15>G15,"Seu preço está abaixo de um dos seus concorrentes. Mas ele se posiciona pelo(a) "&D15&". Fique atento sobre este detalhe, pois preço baixo não é garantia de sucesso.","Seu preço está igual a de um dos seus concorrentes. Mas ele se posiciona pela "&D15&". Se você conseguir este mesmo benefício, poderá estar em vantagem.")))) | Q15: =IF(ISERR( IF(PG!C21="","",PG!C21)),"",IF(PG!C21="","",PG!C21))
G16: =IF(ISERROR( IF(C16="","",IFERROR(VLOOKUP(E16,PG!$C$7:$D$507,2,0),""))),"",IF(C16="","",IFERROR(VLOOKUP(E16,PG!$C$7:$D$507,2,0),""))) | H16: =IF(ISERROR( IF(C16="","", IF(F16<G16,"Seu preço está acima de um dos seus concorrentes. Você precisa encontrar meios como qualidade, localização, etc, para justificar esta diferença.",IF(F16>G16,"Seu preço está abaixo de um dos seus concorrentes. Mas ele se posiciona pelo(a) "&D16&". Fique atento sobre este detalhe, pois preço baixo não é garantia de sucesso.","Seu preço está igual a de um dos seus concorrentes. Mas ele se posiciona pela "&D16&". Se você conseguir este mesmo benefício, poderá estar em vantagem.")))),"", IF(C16="","", IF(F16<G16,"Seu preço está acima de um dos seus concorrentes. Você precisa encontrar meios como qualidade, localização, etc, para justificar esta diferença.",IF(F16>G16,"Seu preço está abaixo de um dos seus concorrentes. Mas ele se posiciona pelo(a) "&D16&". Fique atento sobre este detalhe, pois preço baixo não é garantia de sucesso.","Seu preço está igual a de um dos seus concorrentes. Mas ele se posiciona pela "&D16&". Se você conseguir este mesmo benefício, poderá estar em vantagem.")))) | Q16: =IF(ISERR( IF(PG!C22="","",PG!C22)),"",IF(PG!C22="","",PG!C22))
G17: =IF(ISERROR( IF(C17="","",IFERROR(VLOOKUP(E17,PG!$C$7:$D$507,2,0),""))),"",IF(C17="","",IFERROR(VLOOKUP(E17,PG!$C$7:$D$507,2,0),""))) | H17: =IF(ISERROR( IF(C17="","", IF(F17<G17,"Seu preço está acima de um dos seus concorrentes. Você precisa encontrar meios como qualidade, localização, etc, para justificar esta diferença.",IF(F17>G17,"Seu preço está abaixo de um dos seus concorrentes. Mas ele se posiciona pelo(a) "&D17&". Fique atento sobre este detalhe, pois preço baixo não é garantia de sucesso.","Seu preço está igual a de um dos seus concorrentes. Mas ele se posiciona pela "&D17&". Se você conseguir este mesmo benefício, poderá estar em vantagem.")))),"", IF(C17="","", IF(F17<G17,"Seu preço está acima de um dos seus concorrentes. Você precisa encontrar meios como qualidade, localização, etc, para justificar esta diferença.",IF(F17>G17,"Seu preço está abaixo de um dos seus concorrentes. Mas ele se posiciona pelo(a) "&D17&". Fique atento sobre este detalhe, pois preço baixo não é garantia de sucesso.","Seu preço está igual a de um dos seus concorrentes. Mas ele se posiciona pela "&D17&". Se você conseguir este mesmo benefício, poderá estar em vantagem.")))) | Q17: =IF(ISERR( IF(PG!C23="","",PG!C23)),"",IF(PG!C23="","",PG!C23))
G18: =IF(ISERROR( IF(C18="","",IFERROR(VLOOKUP(E18,PG!$C$7:$D$507,2,0),""))),"",IF(C18="","",IFERROR(VLOOKUP(E18,PG!$C$7:$D$507,2,0),""))) | H18: =IF(ISERROR( IF(C18="","", IF(F18<G18,"Seu preço está acima de um dos seus concorrentes. Você precisa encontrar meios como qualidade, localização, etc, para justificar esta diferença.",IF(F18>G18,"Seu preço está abaixo de um dos seus concorrentes. Mas ele se posiciona pelo(a) "&D18&". Fique atento sobre este detalhe, pois preço baixo não é garantia de sucesso.","Seu preço está igual a de um dos seus concorrentes. Mas ele se posiciona pela "&D18&". Se você conseguir este mesmo benefício, poderá estar em vantagem.")))),"", IF(C18="","", IF(F18<G18,"Seu preço está acima de um dos seus concorrentes. Você precisa encontrar meios como qualidade, localização, etc, para justificar esta diferença.",IF(F18>G18,"Seu preço está abaixo de um dos seus concorrentes. Mas ele se posiciona pelo(a) "&D18&". Fique atento sobre este detalhe, pois preço baixo não é garantia de sucesso.","Seu preço está igual a de um dos seus concorrentes. Mas ele se posiciona pela "&D18&". Se você conseguir este mesmo benefício, poderá estar em vantagem.")))) | Q18: =IF(ISERR( IF(PG!C24="","",PG!C24)),"",IF(PG!C24="","",PG!C24))
G19: =IF(ISERROR( IF(C19="","",IFERROR(VLOOKUP(E19,PG!$C$7:$D$507,2,0),""))),"",IF(C19="","",IFERROR(VLOOKUP(E19,PG!$C$7:$D$507,2,0),""))) | H19: =IF(ISERROR( IF(C19="","", IF(F19<G19,"Seu preço está acima de um dos seus concorrentes. Você precisa encontrar meios como qualidade, localização, etc, para justificar esta diferença.",IF(F19>G19,"Seu preço está abaixo de um dos seus concorrentes. Mas ele se posiciona pelo(a) "&D19&". Fique atento sobre este detalhe, pois preço baixo não é garantia de sucesso.","Seu preço está igual a de um dos seus concorrentes. Mas ele se posiciona pela "&D19&". Se você conseguir este mesmo benefício, poderá estar em vantagem.")))),"", IF(C19="","", IF(F19<G19,"Seu preço está acima de um dos seus concorrentes. Você precisa encontrar meios como qualidade, localização, etc, para justificar esta diferença.",IF(F19>G19,"Seu preço está abaixo de um dos seus concorrentes. Mas ele se posiciona pelo(a) "&D19&". Fique atento sobre este detalhe, pois preço baixo não é garantia de sucesso.","Seu preço está igual a de um dos seus concorrentes. Mas ele se posiciona pela "&D19&". Se você conseguir este mesmo benefício, poderá estar em vantagem.")))) | Q19: =IF(ISERR( IF(PG!C25="","",PG!C25)),"",IF(PG!C25="","",PG!C25))
G20: =IF(ISERROR( IF(C20="","",IFERROR(VLOOKUP(E20,PG!$C$7:$D$507,2,0),""))),"",IF(C20="","",IFERROR(VLOOKUP(E20,PG!$C$7:$D$507,2,0),""))) | H20: =IF(ISERROR( IF(C20="","", IF(F20<G20,"Seu preço está acima de um dos seus concorrentes. Você precisa encontrar meios como qualidade, localização, etc, para justificar esta diferença.",IF(F20>G20,"Seu preço está abaixo de um dos seus concorrentes. Mas ele se posiciona pelo(a) "&D20&". Fique atento sobre este detalhe, pois preço baixo não é garantia de sucesso.","Seu preço está igual a de um dos seus concorrentes. Mas ele se posiciona pela "&D20&". Se você conseguir este mesmo benefício, poderá estar em vantagem.")))),"", IF(C20="","", IF(F20<G20,"Seu preço está acima de um dos seus concorrentes. Você precisa encontrar meios como qualidade, localização, etc, para justificar esta diferença.",IF(F20>G20,"Seu preço está abaixo de um dos seus concorrentes. Mas ele se posiciona pelo(a) "&D20&". Fique atento sobre este detalhe, pois preço baixo não é garantia de sucesso.","Seu preço está igual a de um dos seus concorrentes. Mas ele se posiciona pela "&D20&". Se você conseguir este mesmo benefício, poderá estar em vantagem.")))) | Q20: =IF(ISERR( IF(PG!C26="","",PG!C26)),"",IF(PG!C26="","",PG!C26))
... G28: =IF(ISERROR( IF(C28="","",IFERROR(VLOOKUP(E28,PG!$C$7:$D$507,2,0),""))),"",IF(C28="","",IFERROR(VLOOKUP(E28,PG!$C$7:$D$507,2,0),""))) | H28: =IF(ISERROR( IF(C28="","", IF(F28<G28,"Seu preço está acima de um dos seus concorrentes. Você precisa encontrar meios como qualidade, localização, etc, para justificar esta diferença.",IF(F28>G28,"Seu preço está abaixo de um dos seus concorrentes. Mas ele se posiciona pelo(a) "&D28&". Fique atento sobre este detalhe, pois preço baixo não é garantia de sucesso.","Seu preço está igual a de um dos seus concorrentes. Mas ele se posiciona pela "&D28&". Se você conseguir este mesmo benefício, poderá estar em vantagem.")))),"", IF(C28="","", IF(F28<G28,"Seu preço está acima de um dos seus concorrentes. Você precisa encontrar meios como qualidade, localização, etc, para justificar esta diferença.",IF(F28>G28,"Seu preço está abaixo de um dos seus concorrentes. Mas ele se posiciona pelo(a) "&D28&". Fique atento sobre este detalhe, pois preço baixo não é garantia de sucesso.","Seu preço está igual a de um dos seus concorrentes. Mas ele se posiciona pela "&D28&". Se você conseguir este mesmo benefício, poderá estar em vantagem.")))) | Q28: =IF(ISERR( IF(PG!C34="","",PG!C34)),"",IF(PG!C34="","",PG!C34))
Q29: =IF(ISERR( IF(PG!C35="","",PG!C35)),"",IF(PG!C35="","",PG!C35))
Q30: =IF(ISERR( IF(PG!C36="","",PG!C36)),"",IF(PG!C36="","",PG!C36))
Q31: =IF(ISERR( IF(PG!C37="","",PG!C37)),"",IF(PG!C37="","",PG!C37))
Q32: =IF(ISERR( IF(PG!C38="","",PG!C38)),"",IF(PG!C38="","",PG!C38))
Q33: =IF(ISERR( IF(PG!C39="","",PG!C39)),"",IF(PG!C39="","",PG!C39))
Q34: =IF(ISERR( IF(PG!C40="","",PG!C40)),"",IF(PG!C40="","",PG!C40))
Q35: =IF(ISERR( IF(PG!C41="","",PG!C41)),"",IF(PG!C41="","",PG!C41))
Q36: =IF(ISERR( IF(PG!C42="","",PG!C42)),"",IF(PG!C42="","",PG!C42))
Q37: =IF(ISERR( IF(PG!C43="","",PG!C43)),"",IF(PG!C43="","",PG!C43))
Q38: =IF(ISERR( IF(PG!C44="","",PG!C44)),"",IF(PG!C44="","",PG!C44))
Q39: =IF(ISERR( IF(PG!C45="","",PG!C45)),"",IF(PG!C45="","",PG!C45))
Q40: =IF(ISERR( IF(PG!C46="","",PG!C46)),"",IF(PG!C46="","",PG!C46))
... Q501: =IF(ISERR( IF(PG!C507="","",PG!C507)),"",IF(PG!C507="","",PG!C507))

Sheet RC
A1: 3.0.2 | C1: 4. RESULTADOS CONSOLIDADOS
C5: Resumo dos Custos Diretos
C6: Matéria - prima | E6: =IF(ISERROR( SUM(PG_CD!$Q$6:$Q$507)),"",SUM(PG_CD!$Q$6:$Q$507)) -> 0
C7: Impostos | E7: =IF(ISERROR( SUM(PG_CD!$K$6:$K$507)),"",SUM(PG_CD!$K$6:$K$507)) -> 0
C8: Comissões | E8: =IF(ISERROR( SUM(PG_CD!$J$6:$J$507)),"",SUM(PG_CD!$J$6:$J$507)) -> 0
C9: Outros gastos | E9: =IF(ISERROR( SUM(PG_CD!$P$6:$P$507)),"",SUM(PG_CD!$P$6:$P$507)) -> 0
C10: Total dos gastos | E10: =SUM(E6:F9) -> 0
C12: Top 5 Custos Fixos
C13: =IF(ISERR( IF(E13=E12,INDEX(OFFSET(PEq!$C$6:$C$50,MATCH('RC'!E13,PEq!$D$6:$D$50,0),0),MATCH('RC'!E13,OFFSET(PEq!$D$6:$D$50,MATCH('RC'!E13,PEq!$D$6:$D$50,0),0),0),1),INDEX(PEq!$C$6:$C$50,MATCH('RC'!E13,PEq!$D$6:$D$50,0),1))),"", IF(E13=E12,INDEX(OFFSET(PEq!$C$6:$C$50,MATCH('RC'!E13,PEq!$D$6:$D$50,0),0),MATCH('RC'!E13,OFFSET(PEq!$D$6:$D$50,MATCH('RC'!E13,PEq!$D$6:$D$50,0),0),0),1),INDEX(PEq!$C$6:$C$50,MATCH('RC'!E13,PEq!$D$6:$D$50,0),1))) -> #N/A | E13: =IF(ISERROR( LARGE(PEq!$D$6:$D$50,1)),"",LARGE(PEq!$D$6:$D$50,1))
C14: =IF(ISERR( IF(E14=E13,INDEX(OFFSET(PEq!$C$6:$C$50,MATCH('RC'!E14,PEq!$D$6:$D$50,0),0),MATCH('RC'!E14,OFFSET(PEq!$D$6:$D$50,MATCH('RC'!E14,PEq!$D$6:$D$50,0),0),0),1),INDEX(PEq!$C$6:$C$50,MATCH('RC'!E14,PEq!$D$6:$D$50,0),1))),"", IF(E14=E13,INDEX(OFFSET(PEq!$C$6:$C$50,MATCH('RC'!E14,PEq!$D$6:$D$50,0),0),MATCH('RC'!E14,OFFSET(PEq!$D$6:$D$50,MATCH('RC'!E14,PEq!$D$6:$D$50,0),0),0),1),INDEX(PEq!$C$6:$C$50,MATCH('RC'!E14,PEq!$D$6:$D$50,0),1))) -> #N/A | E14: =IF(ISERROR( LARGE(PEq!$D$6:$D$50,2)),"",LARGE(PEq!$D$6:$D$50,2))
C15: =IF(ISERR( IF(E15=E14,INDEX(OFFSET(PEq!$C$6:$C$50,MATCH('RC'!E15,PEq!$D$6:$D$50,0),0),MATCH('RC'!E15,OFFSET(PEq!$D$6:$D$50,MATCH('RC'!E15,PEq!$D$6:$D$50,0),0),0),1),INDEX(PEq!$C$6:$C$50,MATCH('RC'!E15,PEq!$D$6:$D$50,0),1))),"", IF(E15=E14,INDEX(OFFSET(PEq!$C$6:$C$50,MATCH('RC'!E15,PEq!$D$6:$D$50,0),0),MATCH('RC'!E15,OFFSET(PEq!$D$6:$D$50,MATCH('RC'!E15,PEq!$D$6:$D$50,0),0),0),1),INDEX(PEq!$C$6:$C$50,MATCH('RC'!E15,PEq!$D$6:$D$50,0),1))) -> #N/A | E15: =IF(ISERROR( LARGE(PEq!$D$6:$D$50,3)),"",LARGE(PEq!$D$6:$D$50,3))
C16: =IF(ISERR( IF(E16=E15,INDEX(OFFSET(PEq!$C$6:$C$50,MATCH('RC'!E16,PEq!$D$6:$D$50,0),0),MATCH('RC'!E16,OFFSET(PEq!$D$6:$D$50,MATCH('RC'!E16,PEq!$D$6:$D$50,0),0),0),1),INDEX(PEq!$C$6:$C$50,MATCH('RC'!E16,PEq!$D$6:$D$50,0),1))),"", IF(E16=E15,INDEX(OFFSET(PEq!$C$6:$C$50,MATCH('RC'!E16,PEq!$D$6:$D$50,0),0),MATCH('RC'!E16,OFFSET(PEq!$D$6:$D$50,MATCH('RC'!E16,PEq!$D$6:$D$50,0),0),0),1),INDEX(PEq!$C$6:$C$50,MATCH('RC'!E16,PEq!$D$6:$D$50,0),1))) -> #N/A | E16: =IF(ISERROR( LARGE(PEq!$D$6:$D$50,4)),"",LARGE(PEq!$D$6:$D$50,4))
C17: =IF(ISERR( IF(E17=E16,INDEX(OFFSET(PEq!$C$6:$C$50,MATCH('RC'!E17,PEq!$D$6:$D$50,0),0),MATCH('RC'!E17,OFFSET(PEq!$D$6:$D$50,MATCH('RC'!E17,PEq!$D$6:$D$50,0),0),0),1),INDEX(PEq!$C$6:$C$50,MATCH('RC'!E17,PEq!$D$6:$D$50,0),1))),"", IF(E17=E16,INDEX(OFFSET(PEq!$C$6:$C$50,MATCH('RC'!E17,PEq!$D$6:$D$50,0),0),MATCH('RC'!E17,OFFSET(PEq!$D$6:$D$50,MATCH('RC'!E17,PEq!$D$6:$D$50,0),0),0),1),INDEX(PEq!$C$6:$C$50,MATCH('RC'!E17,PEq!$D$6:$D$50,0),1))) -> #N/A | E17: =IF(ISERROR( LARGE(PEq!$D$6:$D$50,5)),"",LARGE(PEq!$D$6:$D$50,5))
C18: Total dos custos fixos | E18: =IF(ISERROR( SUM(PEq!$D$6:$D$50)),"",SUM(PEq!$D$6:$D$50)) -> 0
C20: Análise da concorrência (máximo de 5 produtos comparados)
C21: Produtos | D21: Preço médio de mercado | E21: Preço praticado por você | F21: Diferença | G21: Comentário
C22: =IF(ISERROR( IF(E22="","",IF(E22=E21,INDEX(OFFSET(AC!$E$9:$E$28,MATCH('RC'!E22,AC!$G$9:$G$28,0),0),MATCH('RC'!E22,OFFSET(AC!$G$9:$G$28,MATCH('RC'!E22,AC!$G$9:$G$28,0),0),0),1),INDEX(AC!$E$9:$E$28,MATCH('RC'!E22,AC!$G$9:$G$28,0),1)))),"", IF(E22="","",IF(E22=E21,INDEX(OFFSET(AC!$E$9:$E$28,MATCH('RC'!E22,AC!$G$9:$G$28,0),0),MATCH('RC'!E22,OFFSET(AC!$G$9:$G$28,MATCH('RC'!E22,AC!$G$9:$G$28,0),0),0),1),INDEX(AC!$E$9:$E$28,MATCH('RC'!E22,AC!$G$9:$G$28,0),1)))) | D22: =IF(ISERROR( IFERROR(VLOOKUP(C22,AC!$E$9:$F$28,2,0),"")),"",IFERROR(VLOOKUP(C22,AC!$E$9:$F$28,2,0),"")) | E22: =IF(ISERROR( LARGE(AC!$G$9:$G$28,1)),"",LARGE(AC!$G$9:$G$28,1)) | F22: =IF(ISERROR( IF(C22="","",E22-D22)),"",IF(C22="","",E22-D22)) | G22: =IF(ISERROR( IF(F22<0,"Seu preço está "&-H22*100&" % mais barato. Vale aumentar?",IF(F22>0,"Seu preço está "&H22*100&"% mais caro. Diminuir preço?","Seu preço está igual ao de mercado. Manter o preço?"))),"",IF(F22<0,"Seu preço está "&-H22*100&" % mais barato. Vale aumentar?",IF(F22>0,"Seu preço está "&H22*100&"% mais caro. Diminuir preço?","Seu preço está igual ao de mercado. Manter o preço?"))) | H22: =IF(ISERR( IFERROR(ROUND(E22/D22-1,2),"")),"",IFERROR(ROUND(E22/D22-1,2),""))
C23: =IF(ISERROR( IF(E23="","",IF(E23=E22,INDEX(OFFSET(AC!$E$9:$E$28,MATCH('RC'!E23,AC!$G$9:$G$28,0),0),MATCH('RC'!E23,OFFSET(AC!$G$9:$G$28,MATCH('RC'!E23,AC!$G$9:$G$28,0),0),0),1),INDEX(AC!$E$9:$E$28,MATCH('RC'!E23,AC!$G$9:$G$28,0),1)))),"", IF(E23="","",IF(E23=E22,INDEX(OFFSET(AC!$E$9:$E$28,MATCH('RC'!E23,AC!$G$9:$G$28,0),0),MATCH('RC'!E23,OFFSET(AC!$G$9:$G$28,MATCH('RC'!E23,AC!$G$9:$G$28,0),0),0),1),INDEX(AC!$E$9:$E$28,MATCH('RC'!E23,AC!$G$9:$G$28,0),1)))) | D23: =IF(ISERROR( IFERROR(VLOOKUP(C23,AC!$E$9:$F$28,2,0),"")),"",IFERROR(VLOOKUP(C23,AC!$E$9:$F$28,2,0),"")) | E23: =IF(ISERROR( LARGE(AC!$G$9:$G$28,2)),"",LARGE(AC!$G$9:$G$28,2)) | F23: =IF(ISERROR( IF(C23="","",E23-D23)),"",IF(C23="","",E23-D23)) | G23: =IF(ISERROR( IF(F23<0,"Seu preço está "&-H23*100&" % mais barato. Vale aumentar?",IF(F23>0,"Seu preço está "&H23*100&"% mais caro. Diminuir preço?","Seu preço está igual ao de mercado. Manter o preço?"))),"",IF(F23<0,"Seu preço está "&-H23*100&" % mais barato. Vale aumentar?",IF(F23>0,"Seu preço está "&H23*100&"% mais caro. Diminuir preço?","Seu preço está igual ao de mercado. Manter o preço?"))) | H23: =IF(ISERR( IFERROR(ROUND(E23/D23-1,2),"")),"",IFERROR(ROUND(E23/D23-1,2),""))
C24: =IF(ISERROR( IF(E24="","",IF(E24=E23,INDEX(OFFSET(AC!$E$9:$E$28,MATCH('RC'!E24,AC!$G$9:$G$28,0),0),MATCH('RC'!E24,OFFSET(AC!$G$9:$G$28,MATCH('RC'!E24,AC!$G$9:$G$28,0),0),0),1),INDEX(AC!$E$9:$E$28,MATCH('RC'!E24,AC!$G$9:$G$28,0),1)))),"", IF(E24="","",IF(E24=E23,INDEX(OFFSET(AC!$E$9:$E$28,MATCH('RC'!E24,AC!$G$9:$G$28,0),0),MATCH('RC'!E24,OFFSET(AC!$G$9:$G$28,MATCH('RC'!E24,AC!$G$9:$G$28,0),0),0),1),INDEX(AC!$E$9:$E$28,MATCH('RC'!E24,AC!$G$9:$G$28,0),1)))) | D24: =IF(ISERROR( IFERROR(VLOOKUP(C24,AC!$E$9:$F$28,2,0),"")),"",IFERROR(VLOOKUP(C24,AC!$E$9:$F$28,2,0),"")) | E24: =IF(ISERROR( LARGE(AC!$G$9:$G$28,3)),"",LARGE(AC!$G$9:$G$28,3)) | F24: =IF(ISERROR( IF(C24="","",E24-D24)),"",IF(C24="","",E24-D24)) | G24: =IF(ISERROR( IF(F24<0,"Seu preço está "&-H24*100&" % mais barato. Vale aumentar?",IF(F24>0,"Seu preço está "&H24*100&"% mais caro. Diminuir preço?","Seu preço está igual ao de mercado. Manter o preço?"))),"",IF(F24<0,"Seu preço está "&-H24*100&" % mais barato. Vale aumentar?",IF(F24>0,"Seu preço está "&H24*100&"% mais caro. Diminuir preço?","Seu preço está igual ao de mercado. Manter o preço?"))) | H24: =IF(ISERR( IFERROR(ROUND(E24/D24-1,2),"")),"",IFERROR(ROUND(E24/D24-1,2),""))
C25: =IF(ISERROR( IF(E25="","",IF(E25=E24,INDEX(OFFSET(AC!$E$9:$E$28,MATCH('RC'!E25,AC!$G$9:$G$28,0),0),MATCH('RC'!E25,OFFSET(AC!$G$9:$G$28,MATCH('RC'!E25,AC!$G$9:$G$28,0),0),0),1),INDEX(AC!$E$9:$E$28,MATCH('RC'!E25,AC!$G$9:$G$28,0),1)))),"", IF(E25="","",IF(E25=E24,INDEX(OFFSET(AC!$E$9:$E$28,MATCH('RC'!E25,AC!$G$9:$G$28,0),0),MATCH('RC'!E25,OFFSET(AC!$G$9:$G$28,MATCH('RC'!E25,AC!$G$9:$G$28,0),0),0),1),INDEX(AC!$E$9:$E$28,MATCH('RC'!E25,AC!$G$9:$G$28,0),1)))) | D25: =IF(ISERROR( IFERROR(VLOOKUP(C25,AC!$E$9:$F$28,2,0),"")),"",IFERROR(VLOOKUP(C25,AC!$E$9:$F$28,2,0),"")) | E25: =IF(ISERROR( LARGE(AC!$G$9:$G$28,4)),"",LARGE(AC!$G$9:$G$28,4)) | F25: =IF(ISERROR( IF(C25="","",E25-D25)),"",IF(C25="","",E25-D25)) | G25: =IF(ISERROR( IF(F25<0,"Seu preço está "&-H25*100&" % mais barato. Vale aumentar?",IF(F25>0,"Seu preço está "&H25*100&"% mais caro. Diminuir preço?","Seu preço está igual ao de mercado. Manter o preço?"))),"",IF(F25<0,"Seu preço está "&-H25*100&" % mais barato. Vale aumentar?",IF(F25>0,"Seu preço está "&H25*100&"% mais caro. Diminuir preço?","Seu preço está igual ao de mercado. Manter o preço?"))) | H25: =IF(ISERR( IFERROR(ROUND(E25/D25-1,2),"")),"",IFERROR(ROUND(E25/D25-1,2),""))
C26: =IF(ISERROR( IF(E26="","",IF(E26=E25,INDEX(OFFSET(AC!$E$9:$E$28,MATCH('RC'!E26,AC!$G$9:$G$28,0),0),MATCH('RC'!E26,OFFSET(AC!$G$9:$G$28,MATCH('RC'!E26,AC!$G$9:$G$28,0),0),0),1),INDEX(AC!$E$9:$E$28,MATCH('RC'!E26,AC!$G$9:$G$28,0),1)))),"", IF(E26="","",IF(E26=E25,INDEX(OFFSET(AC!$E$9:$E$28,MATCH('RC'!E26,AC!$G$9:$G$28,0),0),MATCH('RC'!E26,OFFSET(AC!$G$9:$G$28,MATCH('RC'!E26,AC!$G$9:$G$28,0),0),0),1),INDEX(AC!$E$9:$E$28,MATCH('RC'!E26,AC!$G$9:$G$28,0),1)))) | D26: =IF(ISERROR( IFERROR(VLOOKUP(C26,AC!$E$9:$F$28,2,0),"")),"",IFERROR(VLOOKUP(C26,AC!$E$9:$F$28,2,0),"")) | E26: =IF(ISERROR( LARGE(AC!$G$9:$G$28,5)),"",LARGE(AC!$G$9:$G$28,5)) | F26: =IF(ISERROR( IF(C26="","",E26-D26)),"",IF(C26="","",E26-D26)) | G26: =IF(ISERROR( IF(F26<0,"Seu preço está "&-H26*100&" % mais barato. Vale aumentar?",IF(F26>0,"Seu preço está "&H26*100&"% mais caro. Diminuir preço?","Seu preço está igual ao de mercado. Manter o preço?"))),"",IF(F26<0,"Seu preço está "&-H26*100&" % mais barato. Vale aumentar?",IF(F26>0,"Seu preço está "&H26*100&"% mais caro. Diminuir preço?","Seu preço está igual ao de mercado. Manter o preço?"))) | H26: =IF(ISERR( IFERROR(ROUND(E26/D26-1,2),"")),"",IFERROR(ROUND(E26/D26-1,2),""))
C28: Top 10 Mix de Produtos - Receita Gerada
C29: Produtos | E29: Quantidade a ser vendida | F29: Receita gerada
C30: =IF(ISERROR( IF(F30="","",IF(F30=F29,INDEX(OFFSET(PG_CD!$C$6:$C$507,MATCH('RC'!F30,PG_CD!$N$6:$N$507,0),0),MATCH('RC'!F30,OFFSET(PG_CD!$N$6:$N$507,MATCH('RC'!F30,PG_CD!$N$6:$N$507,0),0),0),1),INDEX(PG_CD!$C$6:$C$507,MATCH('RC'!F30,PG_CD!$N$6:$N$507,0),1)))),"", IF(F30="","",IF(F30=F29,INDEX(OFFSET(PG_CD!$C$6:$C$507,MATCH('RC'!F30,PG_CD!$N$6:$N$507,0),0),MATCH('RC'!F30,OFFSET(PG_CD!$N$6:$N$507,MATCH('RC'!F30,PG_CD!$N$6:$N$507,0),0),0),1),INDEX(PG_CD!$C$6:$C$507,MATCH('RC'!F30,PG_CD!$N$6:$N$507,0),1)))) | E30: =IF(ISERROR( IF(F30="","",IF(F30=F29,INDEX(OFFSET(PG_CD!$O$6:$O$507,MATCH('RC'!F30,PG_CD!$N$6:$N$507,0),0),MATCH('RC'!F30,OFFSET(PG_CD!$N$6:$N$507,MATCH('RC'!F30,PG_CD!$N$6:$N$507,0),0),0),1),INDEX(PG_CD!$O$6:$O$507,MATCH('RC'!F30,PG_CD!$N$6:$N$507,0),1)))),"", IF(F30="","",IF(F30=F29,INDEX(OFFSET(PG_CD!$O$6:$O$507,MATCH('RC'!F30,PG_CD!$N$6:$N$507,0),0),MATCH('RC'!F30,OFFSET(PG_CD!$N$6:$N$507,MATCH('RC'!F30,PG_CD!$N$6:$N$507,0),0),0),1),INDEX(PG_CD!$O$6:$O$507,MATCH('RC'!F30,PG_CD!$N$6:$N$507,0),1)))) | F30: =IF(ISERROR( IF(LARGE(PG_CD!$N$6:$N$507,H30)=0,"",LARGE(PG_CD!$N$6:$N$507,H30))),"",IF(LARGE(PG_CD!$N$6:$N$507,H30)=0,"",LARGE(PG_CD!$N$6:$N$507,H30))) | H30: 1
C31: =IF(ISERROR( IF(F31="","",IF(F31=F30,INDEX(OFFSET(PG_CD!$C$6:$C$507,MATCH('RC'!F31,PG_CD!$N$6:$N$507,0),0),MATCH('RC'!F31,OFFSET(PG_CD!$N$6:$N$507,MATCH('RC'!F31,PG_CD!$N$6:$N$507,0),0),0),1),INDEX(PG_CD!$C$6:$C$507,MATCH('RC'!F31,PG_CD!$N$6:$N$507,0),1)))),"", IF(F31="","",IF(F31=F30,INDEX(OFFSET(PG_CD!$C$6:$C$507,MATCH('RC'!F31,PG_CD!$N$6:$N$507,0),0),MATCH('RC'!F31,OFFSET(PG_CD!$N$6:$N$507,MATCH('RC'!F31,PG_CD!$N$6:$N$507,0),0),0),1),INDEX(PG_CD!$C$6:$C$507,MATCH('RC'!F31,PG_CD!$N$6:$N$507,0),1)))) | E31: =IF(ISERROR( IF(F31="","",IF(F31=F30,INDEX(OFFSET(PG_CD!$O$6:$O$507,MATCH('RC'!F31,PG_CD!$N$6:$N$507,0),0),MATCH('RC'!F31,OFFSET(PG_CD!$N$6:$N$507,MATCH('RC'!F31,PG_CD!$N$6:$N$507,0),0),0),1),INDEX(PG_CD!$O$6:$O$507,MATCH('RC'!F31,PG_CD!$N$6:$N$507,0),1)))),"", IF(F31="","",IF(F31=F30,INDEX(OFFSET(PG_CD!$O$6:$O$507,MATCH('RC'!F31,PG_CD!$N$6:$N$507,0),0),MATCH('RC'!F31,OFFSET(PG_CD!$N$6:$N$507,MATCH('RC'!F31,PG_CD!$N$6:$N$507,0),0),0),1),INDEX(PG_CD!$O$6:$O$507,MATCH('RC'!F31,PG_CD!$N$6:$N$507,0),1)))) | F31: =IF(ISERROR( IF(LARGE(PG_CD!$N$6:$N$507,H31)=0,"",LARGE(PG_CD!$N$6:$N$507,H31))),"",IF(LARGE(PG_CD!$N$6:$N$507,H31)=0,"",LARGE(PG_CD!$N$6:$N$507,H31))) | H31: 2
C32: =IF(ISERROR( IF(F32="","",IF(F32=F31,INDEX(OFFSET(PG_CD!$C$6:$C$507,MATCH('RC'!F32,PG_CD!$N$6:$N$507,0),0),MATCH('RC'!F32,OFFSET(PG_CD!$N$6:$N$507,MATCH('RC'!F32,PG_CD!$N$6:$N$507,0),0),0),1),INDEX(PG_CD!$C$6:$C$507,MATCH('RC'!F32,PG_CD!$N$6:$N$507,0),1)))),"", IF(F32="","",IF(F32=F31,INDEX(OFFSET(PG_CD!$C$6:$C$507,MATCH('RC'!F32,PG_CD!$N$6:$N$507,0),0),MATCH('RC'!F32,OFFSET(PG_CD!$N$6:$N$507,MATCH('RC'!F32,PG_CD!$N$6:$N$507,0),0),0),1),INDEX(PG_CD!$C$6:$C$507,MATCH('RC'!F32,PG_CD!$N$6:$N$507,0),1)))) | E32: =IF(ISERROR( IF(F32="","",IF(F32=F31,INDEX(OFFSET(PG_CD!$O$6:$O$507,MATCH('RC'!F32,PG_CD!$N$6:$N$507,0),0),MATCH('RC'!F32,OFFSET(PG_CD!$N$6:$N$507,MATCH('RC'!F32,PG_CD!$N$6:$N$507,0),0),0),1),INDEX(PG_CD!$O$6:$O$507,MATCH('RC'!F32,PG_CD!$N$6:$N$507,0),1)))),"", IF(F32="","",IF(F32=F31,INDEX(OFFSET(PG_CD!$O$6:$O$507,MATCH('RC'!F32,PG_CD!$N$6:$N$507,0),0),MATCH('RC'!F32,OFFSET(PG_CD!$N$6:$N$507,MATCH('RC'!F32,PG_CD!$N$6:$N$507,0),0),0),1),INDEX(PG_CD!$O$6:$O$507,MATCH('RC'!F32,PG_CD!$N$6:$N$507,0),1)))) | F32: =IF(ISERROR( IF(LARGE(PG_CD!$N$6:$N$507,H32)=0,"",LARGE(PG_CD!$N$6:$N$507,H32))),"",IF(LARGE(PG_CD!$N$6:$N$507,H32)=0,"",LARGE(PG_CD!$N$6:$N$507,H32))) | H32: 3
C33: =IF(ISERROR( IF(F33="","",IF(F33=F32,INDEX(OFFSET(PG_CD!$C$6:$C$507,MATCH('RC'!F33,PG_CD!$N$6:$N$507,0),0),MATCH('RC'!F33,OFFSET(PG_CD!$N$6:$N$507,MATCH('RC'!F33,PG_CD!$N$6:$N$507,0),0),0),1),INDEX(PG_CD!$C$6:$C$507,MATCH('RC'!F33,PG_CD!$N$6:$N$507,0),1)))),"", IF(F33="","",IF(F33=F32,INDEX(OFFSET(PG_CD!$C$6:$C$507,MATCH('RC'!F33,PG_CD!$N$6:$N$507,0),0),MATCH('RC'!F33,OFFSET(PG_CD!$N$6:$N$507,MATCH('RC'!F33,PG_CD!$N$6:$N$507,0),0),0),1),INDEX(PG_CD!$C$6:$C$507,MATCH('RC'!F33,PG_CD!$N$6:$N$507,0),1)))) | E33: =IF(ISERROR( IF(F33="","",IF(F33=F32,INDEX(OFFSET(PG_CD!$O$6:$O$507,MATCH('RC'!F33,PG_CD!$N$6:$N$507,0),0),MATCH('RC'!F33,OFFSET(PG_CD!$N$6:$N$507,MATCH('RC'!F33,PG_CD!$N$6:$N$507,0),0),0),1),INDEX(PG_CD!$O$6:$O$507,MATCH('RC'!F33,PG_CD!$N$6:$N$507,0),1)))),"", IF(F33="","",IF(F33=F32,INDEX(OFFSET(PG_CD!$O$6:$O$507,MATCH('RC'!F33,PG_CD!$N$6:$N$507,0),0),MATCH('RC'!F33,OFFSET(PG_CD!$N$6:$N$507,MATCH('RC'!F33,PG_CD!$N$6:$N$507,0),0),0),1),INDEX(PG_CD!$O$6:$O$507,MATCH('RC'!F33,PG_CD!$N$6:$N$507,0),1)))) | F33: =IF(ISERROR( IF(LARGE(PG_CD!$N$6:$N$507,H33)=0,"",LARGE(PG_CD!$N$6:$N$507,H33))),"",IF(LARGE(PG_CD!$N$6:$N$507,H33)=0,"",LARGE(PG_CD!$N$6:$N$507,H33))) | H33: 4
C34: =IF(ISERROR( IF(F34="","",IF(F34=F33,INDEX(OFFSET(PG_CD!$C$6:$C$507,MATCH('RC'!F34,PG_CD!$N$6:$N$507,0),0),MATCH('RC'!F34,OFFSET(PG_CD!$N$6:$N$507,MATCH('RC'!F34,PG_CD!$N$6:$N$507,0),0),0),1),INDEX(PG_CD!$C$6:$C$507,MATCH('RC'!F34,PG_CD!$N$6:$N$507,0),1)))),"", IF(F34="","",IF(F34=F33,INDEX(OFFSET(PG_CD!$C$6:$C$507,MATCH('RC'!F34,PG_CD!$N$6:$N$507,0),0),MATCH('RC'!F34,OFFSET(PG_CD!$N$6:$N$507,MATCH('RC'!F34,PG_CD!$N$6:$N$507,0),0),0),1),INDEX(PG_CD!$C$6:$C$507,MATCH('RC'!F34,PG_CD!$N$6:$N$507,0),1)))) | E34: =IF(ISERROR( IF(F34="","",IF(F34=F33,INDEX(OFFSET(PG_CD!$O$6:$O$507,MATCH('RC'!F34,PG_CD!$N$6:$N$507,0),0),MATCH('RC'!F34,OFFSET(PG_CD!$N$6:$N$507,MATCH('RC'!F34,PG_CD!$N$6:$N$507,0),0),0),1),INDEX(PG_CD!$O$6:$O$507,MATCH('RC'!F34,PG_CD!$N$6:$N$507,0),1)))),"", IF(F34="","",IF(F34=F33,INDEX(OFFSET(PG_CD!$O$6:$O$507,MATCH('RC'!F34,PG_CD!$N$6:$N$507,0),0),MATCH('RC'!F34,OFFSET(PG_CD!$N$6:$N$507,MATCH('RC'!F34,PG_CD!$N$6:$N$507,0),0),0),1),INDEX(PG_CD!$O$6:$O$507,MATCH('RC'!F34,PG_CD!$N$6:$N$507,0),1)))) | F34: =IF(ISERROR( IF(LARGE(PG_CD!$N$6:$N$507,H34)=0,"",LARGE(PG_CD!$N$6:$N$507,H34))),"",IF(LARGE(PG_CD!$N$6:$N$507,H34)=0,"",LARGE(PG_CD!$N$6:$N$507,H34))) | H34: 5
C35: =IF(ISERROR( IF(F35="","",IF(F35=F34,INDEX(OFFSET(PG_CD!$C$6:$C$507,MATCH('RC'!F35,PG_CD!$N$6:$N$507,0),0),MATCH('RC'!F35,OFFSET(PG_CD!$N$6:$N$507,MATCH('RC'!F35,PG_CD!$N$6:$N$507,0),0),0),1),INDEX(PG_CD!$C$6:$C$507,MATCH('RC'!F35,PG_CD!$N$6:$N$507,0),1)))),"", IF(F35="","",IF(F35=F34,INDEX(OFFSET(PG_CD!$C$6:$C$507,MATCH('RC'!F35,PG_CD!$N$6:$N$507,0),0),MATCH('RC'!F35,OFFSET(PG_CD!$N$6:$N$507,MATCH('RC'!F35,PG_CD!$N$6:$N$507,0),0),0),1),INDEX(PG_CD!$C$6:$C$507,MATCH('RC'!F35,PG_CD!$N$6:$N$507,0),1)))) | E35: =IF(ISERROR( IF(F35="","",IF(F35=F34,INDEX(OFFSET(PG_CD!$O$6:$O$507,MATCH('RC'!F35,PG_CD!$N$6:$N$507,0),0),MATCH('RC'!F35,OFFSET(PG_CD!$N$6:$N$507,MATCH('RC'!F35,PG_CD!$N$6:$N$507,0),0),0),1),INDEX(PG_CD!$O$6:$O$507,MATCH('RC'!F35,PG_CD!$N$6:$N$507,0),1)))),"", IF(F35="","",IF(F35=F34,INDEX(OFFSET(PG_CD!$O$6:$O$507,MATCH('RC'!F35,PG_CD!$N$6:$N$507,0),0),MATCH('RC'!F35,OFFSET(PG_CD!$N$6:$N$507,MATCH('RC'!F35,PG_CD!$N$6:$N$507,0),0),0),1),INDEX(PG_CD!$O$6:$O$507,MATCH('RC'!F35,PG_CD!$N$6:$N$507,0),1)))) | F35: =IF(ISERROR( IF(LARGE(PG_CD!$N$6:$N$507,H35)=0,"",LARGE(PG_CD!$N$6:$N$507,H35))),"",IF(LARGE(PG_CD!$N$6:$N$507,H35)=0,"",LARGE(PG_CD!$N$6:$N$507,H35))) | H35: 6
C36: =IF(ISERROR( IF(F36="","",IF(F36=F35,INDEX(OFFSET(PG_CD!$C$6:$C$507,MATCH('RC'!F36,PG_CD!$N$6:$N$507,0),0),MATCH('RC'!F36,OFFSET(PG_CD!$N$6:$N$507,MATCH('RC'!F36,PG_CD!$N$6:$N$507,0),0),0),1),INDEX(PG_CD!$C$6:$C$507,MATCH('RC'!F36,PG_CD!$N$6:$N$507,0),1)))),"", IF(F36="","",IF(F36=F35,INDEX(OFFSET(PG_CD!$C$6:$C$507,MATCH('RC'!F36,PG_CD!$N$6:$N$507,0),0),MATCH('RC'!F36,OFFSET(PG_CD!$N$6:$N$507,MATCH('RC'!F36,PG_CD!$N$6:$N$507,0),0),0),1),INDEX(PG_CD!$C$6:$C$507,MATCH('RC'!F36,PG_CD!$N$6:$N$507,0),1)))) | E36: =IF(ISERROR( IF(F36="","",IF(F36=F35,INDEX(OFFSET(PG_CD!$O$6:$O$507,MATCH('RC'!F36,PG_CD!$N$6:$N$507,0),0),MATCH('RC'!F36,OFFSET(PG_CD!$N$6:$N$507,MATCH('RC'!F36,PG_CD!$N$6:$N$507,0),0),0),1),INDEX(PG_CD!$O$6:$O$507,MATCH('RC'!F36,PG_CD!$N$6:$N$507,0),1)))),"", IF(F36="","",IF(F36=F35,INDEX(OFFSET(PG_CD!$O$6:$O$507,MATCH('RC'!F36,PG_CD!$N$6:$N$507,0),0),MATCH('RC'!F36,OFFSET(PG_CD!$N$6:$N$507,MATCH('RC'!F36,PG_CD!$N$6:$N$507,0),0),0),1),INDEX(PG_CD!$O$6:$O$507,MATCH('RC'!F36,PG_CD!$N$6:$N$507,0),1)))) | F36: =IF(ISERROR( IF(LARGE(PG_CD!$N$6:$N$507,H36)=0,"",LARGE(PG_CD!$N$6:$N$507,H36))),"",IF(LARGE(PG_CD!$N$6:$N$507,H36)=0,"",LARGE(PG_CD!$N$6:$N$507,H36))) | H36: 7
C37: =IF(ISERR( IF(F37="","",IF(F37=F36,INDEX(OFFSET(PG_CD!$C$6:$C$507,MATCH('RC'!F37,PG_CD!$N$6:$N$507,0),0),MATCH('RC'!F37,OFFSET(PG_CD!$N$6:$N$507,MATCH('RC'!F37,PG_CD!$N$6:$N$507,0),0),0),1),INDEX(PG_CD!$C$6:$C$507,MATCH('RC'!F37,PG_CD!$N$6:$N$507,0),1)))),"", IF(F37="","",IF(F37=F36,INDEX(OFFSET(PG_CD!$C$6:$C$507,MATCH('RC'!F37,PG_CD!$N$6:$N$507,0),0),MATCH('RC'!F37,OFFSET(PG_CD!$N$6:$N$507,MATCH('RC'!F37,PG_CD!$N$6:$N$507,0),0),0),1),INDEX(PG_CD!$C$6:$C$507,MATCH('RC'!F37,PG_CD!$N$6:$N$507,0),1)))) | E37: =IF(ISERR( IF(F37="","",IF(F37=F36,INDEX(OFFSET(PG_CD!$O$6:$O$507,MATCH('RC'!F37,PG_CD!$N$6:$N$507,0),0),MATCH('RC'!F37,OFFSET(PG_CD!$N$6:$N$507,MATCH('RC'!F37,PG_CD!$N$6:$N$507,0),0),0),1),INDEX(PG_CD!$O$6:$O$507,MATCH('RC'!F37,PG_CD!$N$6:$N$507,0),1)))),"", IF(F37="","",IF(F37=F36,INDEX(OFFSET(PG_CD!$O$6:$O$507,MATCH('RC'!F37,PG_CD!$N$6:$N$507,0),0),MATCH('RC'!F37,OFFSET(PG_CD!$N$6:$N$507,MATCH('RC'!F37,PG_CD!$N$6:$N$507,0),0),0),1),INDEX(PG_CD!$O$6:$O$507,MATCH('RC'!F37,PG_CD!$N$6:$N$507,0),1)))) | F37: =IF(ISERR( IF(LARGE(PG_CD!$N$6:$N$507,H37)=0,"",LARGE(PG_CD!$N$6:$N$507,H37))),"",IF(LARGE(PG_CD!$N$6:$N$507,H37)=0,"",LARGE(PG_CD!$N$6:$N$507,H37))) | H37: 8
C38: =IF(ISERR( IF(F38="","",IF(F38=F37,INDEX(OFFSET(PG_CD!$C$6:$C$507,MATCH('RC'!F38,PG_CD!$N$6:$N$507,0),0),MATCH('RC'!F38,OFFSET(PG_CD!$N$6:$N$507,MATCH('RC'!F38,PG_CD!$N$6:$N$507,0),0),0),1),INDEX(PG_CD!$C$6:$C$507,MATCH('RC'!F38,PG_CD!$N$6:$N$507,0),1)))),"", IF(F38="","",IF(F38=F37,INDEX(OFFSET(PG_CD!$C$6:$C$507,MATCH('RC'!F38,PG_CD!$N$6:$N$507,0),0),MATCH('RC'!F38,OFFSET(PG_CD!$N$6:$N$507,MATCH('RC'!F38,PG_CD!$N$6:$N$507,0),0),0),1),INDEX(PG_CD!$C$6:$C$507,MATCH('RC'!F38,PG_CD!$N$6:$N$507,0),1)))) | E38: =IF(ISERR( IF(F38="","",IF(F38=F37,INDEX(OFFSET(PG_CD!$O$6:$O$507,MATCH('RC'!F38,PG_CD!$N$6:$N$507,0),0),MATCH('RC'!F38,OFFSET(PG_CD!$N$6:$N$507,MATCH('RC'!F38,PG_CD!$N$6:$N$507,0),0),0),1),INDEX(PG_CD!$O$6:$O$507,MATCH('RC'!F38,PG_CD!$N$6:$N$507,0),1)))),"", IF(F38="","",IF(F38=F37,INDEX(OFFSET(PG_CD!$O$6:$O$507,MATCH('RC'!F38,PG_CD!$N$6:$N$507,0),0),MATCH('RC'!F38,OFFSET(PG_CD!$N$6:$N$507,MATCH('RC'!F38,PG_CD!$N$6:$N$507,0),0),0),1),INDEX(PG_CD!$O$6:$O$507,MATCH('RC'!F38,PG_CD!$N$6:$N$507,0),1)))) | F38: =IF(ISERR( IF(LARGE(PG_CD!$N$6:$N$507,H38)=0,"",LARGE(PG_CD!$N$6:$N$507,H38))),"",IF(LARGE(PG_CD!$N$6:$N$507,H38)=0,"",LARGE(PG_CD!$N$6:$N$507,H38))) | H38: 9
C39: =IF(ISERR( IF(F39="","",IF(F39=F38,INDEX(OFFSET(PG_CD!$C$6:$C$507,MATCH('RC'!F39,PG_CD!$N$6:$N$507,0),0),MATCH('RC'!F39,OFFSET(PG_CD!$N$6:$N$507,MATCH('RC'!F39,PG_CD!$N$6:$N$507,0),0),0),1),INDEX(PG_CD!$C$6:$C$507,MATCH('RC'!F39,PG_CD!$N$6:$N$507,0),1)))),"", IF(F39="","",IF(F39=F38,INDEX(OFFSET(PG_CD!$C$6:$C$507,MATCH('RC'!F39,PG_CD!$N$6:$N$507,0),0),MATCH('RC'!F39,OFFSET(PG_CD!$N$6:$N$507,MATCH('RC'!F39,PG_CD!$N$6:$N$507,0),0),0),1),INDEX(PG_CD!$C$6:$C$507,MATCH('RC'!F39,PG_CD!$N$6:$N$507,0),1)))) | E39: =IF(ISERR( IF(F39="","",IF(F39=F38,INDEX(OFFSET(PG_CD!$O$6:$O$507,MATCH('RC'!F39,PG_CD!$N$6:$N$507,0),0),MATCH('RC'!F39,OFFSET(PG_CD!$N$6:$N$507,MATCH('RC'!F39,PG_CD!$N$6:$N$507,0),0),0),1),INDEX(PG_CD!$O$6:$O$507,MATCH('RC'!F39,PG_CD!$N$6:$N$507,0),1)))),"", IF(F39="","",IF(F39=F38,INDEX(OFFSET(PG_CD!$O$6:$O$507,MATCH('RC'!F39,PG_CD!$N$6:$N$507,0),0),MATCH('RC'!F39,OFFSET(PG_CD!$N$6:$N$507,MATCH('RC'!F39,PG_CD!$N$6:$N$507,0),0),0),1),INDEX(PG_CD!$O$6:$O$507,MATCH('RC'!F39,PG_CD!$N$6:$N$507,0),1)))) | F39: =IF(ISERR( IF(LARGE(PG_CD!$N$6:$N$507,H39)=0,"",LARGE(PG_CD!$N$6:$N$507,H39))),"",IF(LARGE(PG_CD!$N$6:$N$507,H39)=0,"",LARGE(PG_CD!$N$6:$N$507,H39))) | H39: 10

Sheet Graf
A1: 3.0.2 | C1: 5. GRÁFICOS
C5: Importante: Confira seus dados em gráficos e conte com o auxílio dos comentários que ajudam na interpretação dos dados.
C7: Gráfico Top 10 Mix de Produtos - Receita Gerada
D8: ="O produto que mais gerou receita para atingir o ponto de equilíbrio foi: "&" "&'RC'!C30 -> O produto que mais gerou receita para atingir o ponto de equilíbrio foi: _x000D_
C16: Gráfico Top 10 Mix de Produtos - Quantidade
D17: ="O produto que tem mais participação no ponto de equilíbrio é "&Graf_Sup!A3&"."&" "&" A quantidade vendida de "&Graf_Sup!A3&" é de "&Graf_Sup!E3&" unidades." -> O produto que tem mais participação no ponto de equilíbrio é ._x000D_ A quantidade vendida de é de unidades.
C25: Gráfico Top 10 Margem de Contribuição
D26: ="O produto que tem o maior índice de margem de contribuição é "&Graf_Sup!A16&"."&" "&" O IMC de "&Graf_Sup!A16&" é de "&Graf_Sup!C16*100&" %." -> #VALUE!
C34: Gráfico Top 10 Custos Fixos
D35: =IF(G36>H36,J36,K36) -> Parabéns! Seu lucro é maior que os seus custos fixos. Mantenha esse processo para não deixar que seus custos ultrapassem o seu lucro. | G35: Custos fixos | H35: lucro | J35: custos maior que lucro | K35: custo menor que lucro
G36: =PEq!G18 -> 0 | H36: =SUM(PG!F7:F507)-'RC'!E10+'RC'!E18 -> 0 | J36: A soma dos seus custos diretos e custos fixos fazem com que eles sejam maiores que seu lucro. Significa que o lucro obtido não paga seus custos com o volume de vendas que foi estipulado. Dica: Faça uma revisão na operação do seu negócio com o intuito de reduzir todos os seus custos para se tornar mais competitivo sem deixar de obter lucro. | K36: Parabéns! Seu lucro é maior que os seus custos fixos. Mantenha esse processo para não deixar que seus custos ultrapassem o seu lucro.
C43: Gráfico Top 10 Custos Diretos
D44: ="Os custos diretos são aqueles que variam de acordo com o volume de vendas. Sua média de custos diretos é de R$ "&Graf_Sup!C44&" e o seu custo mais elevado está "&Graf_Sup!D48*100&"% acima da média."&" "&"Dica:"&" "&"É muito comum esquecer de alguns itens dessa parte de custos diretos. Por isso, faça uma avaliação mais criteriosa para entender quais são os itens que ainda podem estar sendo esquecidos." -> #DIV/0!
C52: Gráfico - Análise dos Concorrentes
D53: ="Você tem "&Graf_Sup!C52&" concorrentes analisados e seu preço médio está inferior à média de mercado. Isso pode ser um bom sinal, mas não é algo para se animar muito."&" "&"Dica:"&" "&"Existem muitas formas de se diferenciar em um negócio. Fatores como qualidade, posicionamento, localização geográfica (e outros fatores) são tão importantes quanto o preço. Faça uma avaliação para saber se o preço é a única diferenciação que você precisa." -> Você tem 0 concorrentes analisados e seu preço médio está inferior à média de mercado. Isso pode ser um bom sinal, mas não é algo para se animar muito._x000D__x000D_Dica:_x000D__x000D_Existem muitas formas de se diferenciar em um negócio. Fatores como qualidade, posicionamento, localização geográfica (e outros fatores) são tão importantes quanto o preço. Faça uma avaliação para saber se o preço é a única diferenciação que você precisa.

Sheet RI
A1: 3.0.2 | C1: 6. RELATÓRIO DE IMPRESSÃO
C5: RELATÓRIO IMPRESSO
C6: PLANILHA DE CÁLCULO DE PONTO DE EQUILÍBRIO 3.0
C8: 1. Margem de Contribuição
C9: 2. Resultados Consolidados
C10: 3. Graficos
C12: 1. Margem de Contribuição
C13: Margem de contribuição
C14: Descrição | E14: Valor (R$)
C15: Preço de venda médio dos seus produtos | E15: =PEq!G7
C18: Margem de contribuição média dos seus produtos | E18: =PEq!G10
C21: Custos diretos totais | E21: =PEq!G13 -> 0
C22: Custos diretos médio por produto | E22: =PEq!G14 -> #DIV/0!
C24: Ponto de Equilíbrio (Break Even Point)
C25: Descrição | E25: Valor (R$)
C26: Qual o valor total dos seus custos fixos? | E26: =PEq!G18 -> 0
C27: Qual deve ser o faturamento para não ter prejuízo? | E27: =PEq!G19
C28: Quantos produtos você precisa vender para não ter prejuízo? | E28: =PEq!G20
C30: 2. Resultados Consolidados
C31: Resumo dos Custos Diretos
C32: Matéria - prima | E32: ='RC'!E6 -> 0
C33: Impostos | E33: ='RC'!E7 -> 0
C34: Comissões | E34: ='RC'!E8 -> 0
C35: Outros gastos | E35: ='RC'!E9 -> 0
C36: Total dos gastos | E36: =SUM(E32:F35) -> 0
C38: Top 5 Custos Fixos
C39: ='RC'!C13 -> #N/A | E39: ='RC'!E13
C40: ='RC'!C14 -> #N/A | E40: ='RC'!E14
C41: ='RC'!C15 -> #N/A | E41: ='RC'!E15
C42: ='RC'!C16 -> #N/A | E42: ='RC'!E16
C43: ='RC'!C17 -> #N/A | E43: ='RC'!E17
C44: Total dos custos fixos | E44: ='RC'!E18 -> 0
C46: Análise da concorrência (máximo de 5 produtos comparados)
C47: Produtos | D47: Preço médio de mercado | E47: Preço praticado por você | F47: Diferença | G47: Comentário
C48: ='RC'!C22 | D48: ='RC'!D22 | E48: ='RC'!E22 | F48: =IF(ISERR( IF(C48="","",E48-D48)),"",IF(C48="","",E48-D48)) | G48: =IF(ISERR( IF(F48<0,"Seu preço está "&-H48*100&" % mais barato. Vale aumentar?",IF(F48>0,"Seu preço está "&H48*100&"% mais caro. Diminuir preço?","Seu preço está igual ao de mercado. Manter o preço?"))),"",IF(F48<0,"Seu preço está "&-H48*100&" % mais barato. Vale aumentar?",IF(F48>0,"Seu preço está "&H48*100&"% mais caro. Diminuir preço?","Seu preço está igual ao de mercado. Manter o preço?"))) -> Seu preço está 0% mais caro. Diminuir preço?
C49: ='RC'!C23 | D49: ='RC'!D23 | E49: ='RC'!E23 | F49: =IF(ISERR( IF(C49="","",E49-D49)),"",IF(C49="","",E49-D49)) | G49: =IF(ISERR( IF(F49<0,"Seu preço está "&-H49*100&" % mais barato. Vale aumentar?",IF(F49>0,"Seu preço está "&H49*100&"% mais caro. Diminuir preço?","Seu preço está igual ao de mercado. Manter o preço?"))),"",IF(F49<0,"Seu preço está "&-H49*100&" % mais barato. Vale aumentar?",IF(F49>0,"Seu preço está "&H49*100&"% mais caro. Diminuir preço?","Seu preço está igual ao de mercado. Manter o preço?"))) -> Seu preço está 0% mais caro. Diminuir preço?
