Workbook

Sheet Início
A1: ACOMPANHAMENTO DE PROJETOS - INÍCIO

Sheet Cadastro
A1: ACOMPANHAMENTO DE PROJETOS - CADASTRO
F5: SOLUÇÕES OFERECIDAS | H5: SETORES
H7: Agropecuária
H8: Água, gás e saneamento
H9: Alimentos processados
H10: Atacado
F11: - | H11: Bancos
F12: - | H12: Carnes e derivados
F13: - | H13: Comércio
F14: - | H14: Construção civil e intermediação
F15: - | H15: Construção pesada e engenharia
F16: - | H16: Energia elétrica
F17: - | H17: Equipamentos, máquinas e peças
H18: Holdings
H19: Hospitais
H20: Hotelaria e Restaurantes
H21: Imóveis comerciais e shoppings
H22: Industria digital
H23: Industrias de alimentos
H24: Industria em geral
H25: Logística
H26: Materiais diversos
H27: Mineração
H28: Negócios de lazer e eventos
H29: Papel e madeira
... H46: Varejo

Sheet Acompanhamento Geral
A1: ACOMPANHAMENTO DE PROJETOS - ACOMPANHAMENTO
X2: =#REF!+1 -> #REF!
X3: =X2+1 -> #REF! | Y3: 41608 | Z3: 41639 | AA3: 41670 | AB3: 41698 | AC3: 41729 | AD3: 41759 | AE3: 41790 | AF3: 41820 | AG3: 41851 | AH3: 41882 | AI3: 41912 | AJ3: 41943 | AK3: 41973 | AL3: 42004 | AM3: 42035 | AN3: 42063 | AO3: 42094 | AP3: 42124 | AQ3: 42155 | AR3: 42185 | AS3: 42216 | AT3: 42247 | AU3: 42277 | AV3: 42308 | AW3: 42338 | AX3: 42369
B4: Cliente | C4: Setor da Empresa | D4: Projeto | E4: Solução | F4: Início Projeto | G4: Fim Projeto | H4: Prazo Projeto (meses) | I4: Ganho Anual Projetado | J4: Investimento | K4: Líder Projeto | L4: Gestor do Projeto (Cliente) | M4: % Aderência a Meta Acumulada | X4: =X3+1 -> #REF! | Y4: 41579 | Z4: 41609 | AA4: 41640 | AB4: 41671 | AC4: 41699 | AD4: 41730 | AE4: 41760 | AF4: 41791 | AG4: 41821 | AH4: 41852 | AI4: 41883 | AJ4: 41913 | AK4: 41944 | AL4: 41974 | AM4: 42005 | AN4: 42036 | AO4: 42064 | AP4: 42095 | AQ4: 42125 | AR4: 42156 | AS4: 42186 | AT4: 42217 | AU4: 42248 | AV4: 42278 | AW4: 42309 | AX4: 42339
B5: ='Projeto 1'!C2 -> 0 | C5: ='Projeto 1'!E2 -> 0 | D5: ='Projeto 1'!G2 -> 0 | E5: ='Projeto 1'!H2 -> FÁBRICA E LAYOUT | F5: ='Projeto 1'!I5 -> 0 | G5: ='Projeto 1'!I7 -> 0 | H5: =IFERROR((G5-F5)/30,"") -> 0 | I5: ='Projeto 1'!P7 -> 0 | J5: ='Projeto 1'!P5 -> 0 | K5: ='Projeto 1'!$D$7 -> 0 | L5: ='Projeto 1'!A5 -> 0 | M5: ='Projeto 1'!CE16 -> - | N5: =IF(M5>=100%,"s","n") -> s | X5: =X4+1 -> #REF! | Y5: =IF($G5>=$Y$3,IF($F5<=$Y$4,$X$1,"")) -> FALSE | Z5: =IF($G5>=$Z$3,IF($F5<=$Z$4,#REF!,"")) -> FALSE | AA5: =IF($G5>=$AA$3,IF($F5<=$AA$4,$X$2,"")) -> FALSE | AB5: =IF($G5>=$AB$3,IF($F5<=$AB$4,$X$3,"")) -> FALSE | AC5: =IF($G5>=$AC$3,IF($F5<=$AC$4,$X$4,"")) -> FALSE | AD5: =IF($G5>=$AD$3,IF($F5<=$AD$4,$X$5,"")) -> FALSE | AE5: =IF($G5>=$AE$3,IF($F5<=$AE$4,$X$6,"")) -> FALSE | AF5: =IF($G5>=$AF$3,IF($F5<=$AF$4,$X$7,"")) -> FALSE | AG5: =IF($G5>=$AG$3,IF($F5<=$AG$4,$X$8,"")) -> FALSE | AH5: =IF($G5>=$AH$3,IF($F5<=$AH$4,$X$9,"")) -> FALSE | AI5: =IF($G5>=$AI$3,IF($F5<=$AI$4,#REF!,"")) -> FALSE | AJ5: =IF($G5>=$AJ$3,IF($F5<=$AJ$4,#REF!,"")) -> FALSE | AK5: =IF($G5>=$AK$3,IF($F5<=$AK$4,#REF!,"")) -> FALSE | AL5: =IF($G5>=$AL$3,IF($F5<=$AL$4,#REF!,"")) -> FALSE | AM5: =IF($G5>=$AM$3,IF($F5<=$AM$4,#REF!,"")) -> FALSE | AN5: =IF($G5>=$AN$3,IF($F5<=$AN$4,#REF!,"")) -> FALSE | AO5: =IF($G5>=$AO$3,IF($F5<=$AO$4,#REF!,"")) -> FALSE | AP5: =IF($G5>=$AP$3,IF($F5<=$AP$4,#REF!,"")) -> FALSE | AQ5: =IF($G5>=$AQ$3,IF($F5<=$AQ$4,#REF!,"")) -> FALSE | AR5: =IF($G5>=$AR$3,IF($F5<=$AR$4,#REF!,"")) -> FALSE | AS5: =IF($G5>=$AS$3,IF($F5<=$AS$4,#REF!,"")) -> FALSE | AT5: =IF($G5>=$AT$3,IF($F5<=$AT$4,#REF!,"")) -> FALSE | AU5: =IF($G5>=$AU$3,IF($F5<=$AU$4,#REF!,"")) -> FALSE | AV5: =IF($G5>=$AV$3,IF($F5<=$AV$4,#REF!,"")) -> FALSE | AW5: =IF($G5>=$AW$3,IF($F5<=$AW$4,#REF!,"")) -> FALSE | AX5: =IF($G5>=$AX$3,IF($F5<=$AX$4,#REF!,"")) -> FALSE
B6: ='Projeto 2'!B2 -> 0 | C6: ='Projeto 2'!D2 -> 0 | D6: ='Projeto 2'!G2 -> 0 | E6: ='Projeto 2'!H2 -> FÁBRICA E LAYOUT | F6: ='Projeto 2'!I5 -> 0 | G6: ='Projeto 2'!I7 -> 0 | H6: =IFERROR((G6-F6)/30,"") -> 0 | I6: ='Projeto 2'!P7 -> 0 | J6: ='Projeto 2'!P5 -> 0 | K6: ='Projeto 2'!A7 -> 0 | L6: ='Projeto 2'!A5 -> 0 | M6: ='Projeto 2'!CE16 -> - | N6: =IF(M6>=100%,"s","n") -> s | X6: =X5+1 -> #REF! | Y6: =IF($G6>=$Y$3,IF($F6<=$Y$4,$X$1,"")) -> FALSE | Z6: =IF($G6>=$Z$3,IF($F6<=$Z$4,#REF!,"")) -> FALSE | AA6: =IF($G6>=$AA$3,IF($F6<=$AA$4,$X$2,"")) -> FALSE | AB6: =IF($G6>=$AB$3,IF($F6<=$AB$4,$X$3,"")) -> FALSE | AC6: =IF($G6>=$AC$3,IF($F6<=$AC$4,$X$4,"")) -> FALSE | AD6: =IF($G6>=$AD$3,IF($F6<=$AD$4,$X$5,"")) -> FALSE | AE6: =IF($G6>=$AE$3,IF($F6<=$AE$4,$X$6,"")) -> FALSE | AF6: =IF($G6>=$AF$3,IF($F6<=$AF$4,$X$7,"")) -> FALSE | AG6: =IF($G6>=$AG$3,IF($F6<=$AG$4,$X$8,"")) -> FALSE | AH6: =IF($G6>=$AH$3,IF($F6<=$AH$4,$X$9,"")) -> FALSE | AI6: =IF($G6>=$AI$3,IF($F6<=$AI$4,#REF!,"")) -> FALSE | AJ6: =IF($G6>=$AJ$3,IF($F6<=$AJ$4,#REF!,"")) -> FALSE | AK6: =IF($G6>=$AK$3,IF($F6<=$AK$4,#REF!,"")) -> FALSE | AL6: =IF($G6>=$AL$3,IF($F6<=$AL$4,#REF!,"")) -> FALSE | AM6: =IF($G6>=$AM$3,IF($F6<=$AM$4,#REF!,"")) -> FALSE | AN6: =IF($G6>=$AN$3,IF($F6<=$AN$4,#REF!,"")) -> FALSE | AO6: =IF($G6>=$AO$3,IF($F6<=$AO$4,#REF!,"")) -> FALSE | AP6: =IF($G6>=$AP$3,IF($F6<=$AP$4,#REF!,"")) -> FALSE | AQ6: =IF($G6>=$AQ$3,IF($F6<=$AQ$4,#REF!,"")) -> FALSE | AR6: =IF($G6>=$AR$3,IF($F6<=$AR$4,#REF!,"")) -> FALSE | AS6: =IF($G6>=$AS$3,IF($F6<=$AS$4,#REF!,"")) -> FALSE | AT6: =IF($G6>=$AT$3,IF($F6<=$AT$4,#REF!,"")) -> FALSE | AU6: =IF($G6>=$AU$3,IF($F6<=$AU$4,#REF!,"")) -> FALSE | AV6: =IF($G6>=$AV$3,IF($F6<=$AV$4,#REF!,"")) -> FALSE | AW6: =IF($G6>=$AW$3,IF($F6<=$AW$4,#REF!,"")) -> FALSE | AX6: =IF($G6>=$AX$3,IF($F6<=$AX$4,#REF!,"")) -> FALSE
A7: =IF(F7>0,IF(F7<=TODAY(),IF(G7>=TODAY(),"Em Andamento","Concluído"))) -> FALSE | B7: ='Projeto 3'!B2 -> 0 | C7: ='Projeto 3'!D2 -> 0 | D7: ='Projeto 3'!G2 -> 0 | E7: ='Projeto 3'!H2 -> PRECIFICAÇÃO DE PROJETOS | F7: ='Projeto 3'!I5 -> 0 | G7: ='Projeto 3'!I7 -> 0 | H7: =IFERROR((G7-F7)/30,"") -> 0 | I7: ='Projeto 3'!P7 -> 0 | J7: ='Projeto 3'!P5 -> 0 | K7: ='Projeto 3'!A7 -> 0 | L7: ='Projeto 3'!A5 -> 0 | M7: ='Projeto 3'!CE16 -> - | N7: =IF(M7>=100%,"s","n") -> s | X7: =X6+1 -> #REF! | Y7: =IF($G7>=$Y$3,IF($F7<=$Y$4,$X$1,"")) -> FALSE | Z7: =IF($G7>=$Z$3,IF($F7<=$Z$4,#REF!,"")) -> FALSE | AA7: =IF($G7>=$AA$3,IF($F7<=$AA$4,$X$2,"")) -> FALSE | AB7: =IF($G7>=$AB$3,IF($F7<=$AB$4,$X$3,"")) -> FALSE | AC7: =IF($G7>=$AC$3,IF($F7<=$AC$4,$X$4,"")) -> FALSE | AD7: =IF($G7>=$AD$3,IF($F7<=$AD$4,$X$5,"")) -> FALSE | AE7: =IF($G7>=$AE$3,IF($F7<=$AE$4,$X$6,"")) -> FALSE | AF7: =IF($G7>=$AF$3,IF($F7<=$AF$4,$X$7,"")) -> FALSE | AG7: =IF($G7>=$AG$3,IF($F7<=$AG$4,$X$8,"")) -> FALSE | AH7: =IF($G7>=$AH$3,IF($F7<=$AH$4,$X$9,"")) -> FALSE | AI7: =IF($G7>=$AI$3,IF($F7<=$AI$4,#REF!,"")) -> FALSE | AJ7: =IF($G7>=$AJ$3,IF($F7<=$AJ$4,#REF!,"")) -> FALSE | AK7: =IF($G7>=$AK$3,IF($F7<=$AK$4,#REF!,"")) -> FALSE | AL7: =IF($G7>=$AL$3,IF($F7<=$AL$4,#REF!,"")) -> FALSE | AM7: =IF($G7>=$AM$3,IF($F7<=$AM$4,#REF!,"")) -> FALSE | AN7: =IF($G7>=$AN$3,IF($F7<=$AN$4,#REF!,"")) -> FALSE | AO7: =IF($G7>=$AO$3,IF($F7<=$AO$4,#REF!,"")) -> FALSE | AP7: =IF($G7>=$AP$3,IF($F7<=$AP$4,#REF!,"")) -> FALSE | AQ7: =IF($G7>=$AQ$3,IF($F7<=$AQ$4,#REF!,"")) -> FALSE | AR7: =IF($G7>=$AR$3,IF($F7<=$AR$4,#REF!,"")) -> FALSE | AS7: =IF($G7>=$AS$3,IF($F7<=$AS$4,#REF!,"")) -> FALSE | AT7: =IF($G7>=$AT$3,IF($F7<=$AT$4,#REF!,"")) -> FALSE | AU7: =IF($G7>=$AU$3,IF($F7<=$AU$4,#REF!,"")) -> FALSE | AV7: =IF($G7>=$AV$3,IF($F7<=$AV$4,#REF!,"")) -> FALSE | AW7: =IF($G7>=$AW$3,IF($F7<=$AW$4,#REF!,"")) -> FALSE | AX7: =IF($G7>=$AX$3,IF($F7<=$AX$4,#REF!,"")) -> FALSE
A8: =IF(F8>0,IF(F8<=TODAY(),IF(G8>=TODAY(),"Em Andamento","Concluído"))) -> FALSE | B8: ='Projeto 4'!B2 -> 0 | C8: ='Projeto 4'!D2 -> 0 | D8: ='Projeto 4'!G2 -> 0 | E8: ='Projeto 4'!H2 -> PRECIFICAÇÃO DE PROJETOS | F8: ='Projeto 4'!I5 -> 0 | G8: ='Projeto 4'!I7 -> 0 | H8: =IFERROR((G8-F8)/30,"") -> 0 | I8: ='Projeto 4'!P7 -> 0 | J8: ='Projeto 4'!P5 -> 0 | K8: ='Projeto 4'!A7 -> 0 | L8: ='Projeto 4'!A5 -> 0 | M8: ='Projeto 4'!CE16 -> - | N8: =IF(M8>=100%,"s","n") -> s | X8: =X7+1 -> #REF! | Y8: =IF($G8>=$Y$3,IF($F8<=$Y$4,$X$1,"")) -> FALSE | Z8: =IF($G8>=$Z$3,IF($F8<=$Z$4,#REF!,"")) -> FALSE | AA8: =IF($G8>=$AA$3,IF($F8<=$AA$4,$X$2,"")) -> FALSE | AB8: =IF($G8>=$AB$3,IF($F8<=$AB$4,$X$3,"")) -> FALSE | AC8: =IF($G8>=$AC$3,IF($F8<=$AC$4,$X$4,"")) -> FALSE | AD8: =IF($G8>=$AD$3,IF($F8<=$AD$4,$X$5,"")) -> FALSE | AE8: =IF($G8>=$AE$3,IF($F8<=$AE$4,$X$6,"")) -> FALSE | AF8: =IF($G8>=$AF$3,IF($F8<=$AF$4,$X$7,"")) -> FALSE | AG8: =IF($G8>=$AG$3,IF($F8<=$AG$4,$X$8,"")) -> FALSE | AH8: =IF($G8>=$AH$3,IF($F8<=$AH$4,$X$9,"")) -> FALSE | AI8: =IF($G8>=$AI$3,IF($F8<=$AI$4,#REF!,"")) -> FALSE | AJ8: =IF($G8>=$AJ$3,IF($F8<=$AJ$4,#REF!,"")) -> FALSE | AK8: =IF($G8>=$AK$3,IF($F8<=$AK$4,#REF!,"")) -> FALSE | AL8: =IF($G8>=$AL$3,IF($F8<=$AL$4,#REF!,"")) -> FALSE | AM8: =IF($G8>=$AM$3,IF($F8<=$AM$4,#REF!,"")) -> FALSE | AN8: =IF($G8>=$AN$3,IF($F8<=$AN$4,#REF!,"")) -> FALSE | AO8: =IF($G8>=$AO$3,IF($F8<=$AO$4,#REF!,"")) -> FALSE | AP8: =IF($G8>=$AP$3,IF($F8<=$AP$4,#REF!,"")) -> FALSE | AQ8: =IF($G8>=$AQ$3,IF($F8<=$AQ$4,#REF!,"")) -> FALSE | AR8: =IF($G8>=$AR$3,IF($F8<=$AR$4,#REF!,"")) -> FALSE | AS8: =IF($G8>=$AS$3,IF($F8<=$AS$4,#REF!,"")) -> FALSE | AT8: =IF($G8>=$AT$3,IF($F8<=$AT$4,#REF!,"")) -> FALSE | AU8: =IF($G8>=$AU$3,IF($F8<=$AU$4,#REF!,"")) -> FALSE | AV8: =IF($G8>=$AV$3,IF($F8<=$AV$4,#REF!,"")) -> FALSE | AW8: =IF($G8>=$AW$3,IF($F8<=$AW$4,#REF!,"")) -> FALSE | AX8: =IF($G8>=$AX$3,IF($F8<=$AX$4,#REF!,"")) -> FALSE
A9: =IF(F9>0,IF(F9<=TODAY(),IF(G9>=TODAY(),"Em Andamento","Concluído"))) -> FALSE | B9: ='Projeto 5'!B2 -> 0 | C9: ='Projeto 5'!D2 -> 0 | D9: ='Projeto 5'!G2 -> 0 | E9: ='Projeto 5'!H2 -> Gestão para Resultados | F9: ='Projeto 5'!I5 -> 0 | G9: ='Projeto 5'!I7 -> 0 | H9: =IFERROR((G9-F9)/30,"") -> 0 | I9: ='Projeto 5'!P7 -> 0 | J9: ='Projeto 5'!P5 -> 0 | K9: ='Projeto 5'!A7 -> 0 | L9: ='Projeto 5'!A5 -> 0 | M9: ='Projeto 5'!CE16 -> - | N9: =IF(M9>=100%,"s","n") -> s | X9: =X8+1 -> #REF! | Y9: =IF($G9>=$Y$3,IF($F9<=$Y$4,$X$1,"")) -> FALSE | Z9: =IF($G9>=$Z$3,IF($F9<=$Z$4,#REF!,"")) -> FALSE | AA9: =IF($G9>=$AA$3,IF($F9<=$AA$4,$X$2,"")) -> FALSE | AB9: =IF($G9>=$AB$3,IF($F9<=$AB$4,$X$3,"")) -> FALSE | AC9: =IF($G9>=$AC$3,IF($F9<=$AC$4,$X$4,"")) -> FALSE | AD9: =IF($G9>=$AD$3,IF($F9<=$AD$4,$X$5,"")) -> FALSE | AE9: =IF($G9>=$AE$3,IF($F9<=$AE$4,$X$6,"")) -> FALSE | AF9: =IF($G9>=$AF$3,IF($F9<=$AF$4,$X$7,"")) -> FALSE | AG9: =IF($G9>=$AG$3,IF($F9<=$AG$4,$X$8,"")) -> FALSE | AH9: =IF($G9>=$AH$3,IF($F9<=$AH$4,$X$9,"")) -> FALSE | AI9: =IF($G9>=$AI$3,IF($F9<=$AI$4,#REF!,"")) -> FALSE | AJ9: =IF($G9>=$AJ$3,IF($F9<=$AJ$4,#REF!,"")) -> FALSE | AK9: =IF($G9>=$AK$3,IF($F9<=$AK$4,#REF!,"")) -> FALSE | AL9: =IF($G9>=$AL$3,IF($F9<=$AL$4,#REF!,"")) -> FALSE | AM9: =IF($G9>=$AM$3,IF($F9<=$AM$4,#REF!,"")) -> FALSE | AN9: =IF($G9>=$AN$3,IF($F9<=$AN$4,#REF!,"")) -> FALSE | AO9: =IF($G9>=$AO$3,IF($F9<=$AO$4,#REF!,"")) -> FALSE | AP9: =IF($G9>=$AP$3,IF($F9<=$AP$4,#REF!,"")) -> FALSE | AQ9: =IF($G9>=$AQ$3,IF($F9<=$AQ$4,#REF!,"")) -> FALSE | AR9: =IF($G9>=$AR$3,IF($F9<=$AR$4,#REF!,"")) -> FALSE | AS9: =IF($G9>=$AS$3,IF($F9<=$AS$4,#REF!,"")) -> FALSE | AT9: =IF($G9>=$AT$3,IF($F9<=$AT$4,#REF!,"")) -> FALSE | AU9: =IF($G9>=$AU$3,IF($F9<=$AU$4,#REF!,"")) -> FALSE | AV9: =IF($G9>=$AV$3,IF($F9<=$AV$4,#REF!,"")) -> FALSE | AW9: =IF($G9>=$AW$3,IF($F9<=$AW$4,#REF!,"")) -> FALSE | AX9: =IF($G9>=$AX$3,IF($F9<=$AX$4,#REF!,"")) -> FALSE

Sheet Projeto 1
A1: ACOMPANHAMENTO DE PROJETOS - PROJETO 1
C2: =C3 -> 0 | E2: =I3 -> 0 | G2: =B13 -> 0 | H2: =E9 -> FÁBRICA E LAYOUT
B3: CLIENTE: | H3: SETOR: | CT3: 2. Gestão Financeira | CY3: Gerenciamento pelas Diretrizes | DC3: Bancos
CT4: 2.1. Redução de Despesas | CY4: Gestão para Resultados | DC4: Carnes e derivados
A5: =D5 -> 0 | B5: GESTOR DO PROJETO: | H5: DATA INÍCIO: | K5: INVESTIMENTO PROJETADO: | P5: =N5 -> 0 | CT5: 2.2. Redução de Custos | CY5: Implantação do Programa 5S | DC5: Comércio
CT6: 2.3. Aumento de Receita | CY6: Método de Análise e Solução de Problemas (MASP) | DC6: Construção civil e intermediação
A7: =D7 -> 0 | B7: LÍDER PROJETO: | H7: DATA FIM: | K7: GANHO FINANCEIRO PROJETADO: | P7: =N7 -> 0 | CT7: 3. Capacitação | CY7: Redução de Custos | DC7: Construção pesada e engenharia
CT8: 3.1. Gestão para Resultados | CY8: Redução de Despesas | DC8: Energia elétrica
B9: SOLUÇÃO | E9: FÁBRICA E LAYOUT | S9: ANÁLISE TEMPORAL | CD9: ANÁLISE FINANCEIRA | CT9: 3.2. Gerenciamento de Diretrizes | CY9: Reestruturação Organizacional e de Processos | DC9: Equipamentos, máquinas e peças
CT10: 3.3. Método de Análise e Solução de Problemas (MASP) | DC10: Holdings
CT11: 3.4. Implantação do programa 5S | DC11: Hospitais
B12: PROJETO | S12: CRONOGRAMA | CD12: Situação Meta | DC12: Hotelaria e Restaurantes
S13: ETAPAS DO PROJETO | AD13: 1 | AH13: 2 | AL13: 3 | AP13: 4 | AT13: 5 | AX13: 6 | BB13: 7 | BF13: 8 | BJ13: 9 | BN13: 10 | BR13: 11 | BV13: 12 | CE13: TOTAL | CF13: =AD14 -> JAN | CG13: =AH14 -> FEV | CH13: =AL14 -> MAR | CI13: =AP14 -> ABR | CJ13: =AT14 -> MAI | CK13: =AX14 -> JUN | CL13: =BB14 -> JUL | CM13: =BF14 -> AGO | CN13: =BJ14 -> SET | CO13: =BN14 -> OUT | CP13: =BR14 -> NOV | CQ13: =BV14 -> DEZ | DC13: Imóveis comerciais e shoppings
AD14: JAN | AH14: FEV | AL14: MAR | AP14: ABR | AT14: MAI | AX14: JUN | BB14: JUL | BF14: AGO | BJ14: SET | BN14: OUT | BR14: NOV | BV14: DEZ | CD14: Meta | CE14: =SUM(CF14:CQ14) -> 0 | DC14: Industria digital
CD15: Real | CE15: =SUM(CF15:CQ15) -> 0 | DC15: Industrias de alimentos
CD16: Aderência | CE16: =IFERROR(CE15/CE14,"-") -> - | CF16: =IFERROR(CF15/CF14,"-") -> - | CG16: =IFERROR(CG15/CG14,"-") -> - | CH16: =IFERROR(CH15/CH14,"-") -> - | CI16: =IFERROR(CI15/CI14,"-") -> - | CJ16: =IFERROR(CJ15/CJ14,"-") -> - | CK16: =IFERROR(CK15/CK14,"-") -> - | CL16: =IFERROR(CL15/CL14,"-") -> - | ... CQ16: =IFERROR(CQ15/CQ14,"-") -> - | DC16: Industria em geral
B17: META DO PROJETO | CD17: Situação Investimento | DC17: Logística
CE18: TOTAL | CF18: =CF13 -> JAN | CG18: =CG13 -> FEV | CH18: =CH13 -> MAR | CI18: =CI13 -> ABR | CJ18: =CJ13 -> MAI | CK18: =CK13 -> JUN | CL18: =CL13 -> JUL | CM18: =CM13 -> AGO | ... CQ18: =CQ13 -> DEZ | DC18: Materiais diversos
CD19: Meta | CE19: =SUM(CF19:CQ19) -> 0 | DC19: Mineração
CD20: Real | CE20: =SUM(CF20:CQ20) -> 0 | DC20: Negócios de lazer e eventos
CD21: Aderência | CE21: =IFERROR(CE20/CE19,"-") -> - | CF21: =IFERROR(CF20/CF19,"-") -> - | CG21: =IFERROR(CG20/CG19,"-") -> - | CH21: =IFERROR(CH20/CH19,"-") -> - | CI21: =IFERROR(CI20/CI19,"-") -> - | CJ21: =IFERROR(CJ20/CJ19,"-") -> - | CK21: =IFERROR(CK20/CK19,"-") -> - | CL21: =IFERROR(CL20/CL19,"-") -> - | ... CQ21: =IFERROR(CQ20/CQ19,"-") -> - | DC21: Papel e madeira
B22: DESCRIÇÃO DO PROBLEMA | DC22: Petróleo, gás e combustíveis
DC23: Prestação de Serviços
DC24: Química e petroquímica
DC25: Roupas, calçados e acessórios
B26: EQUIPE DE TRABALHO | DC26: Serviços diversos
B27: Nome | I27: Cargo | DC27: Serviços financeiros
B28: Líder: | C28: Cintia Ferreira | I28: Consultora Sênior | DC28: Setor de educação
DC29: Setor de saúde
B30: Pleno: | DC30: Setor de seguros
DC31: Setor de transporte
B32: Analista: | DC32: Siderurgia e metalurgia
DC33: Supermercados
DC34: Tecnologia da informação
B35: Estagiário: | DC35: Telecomunicações
DC36: Têxteis
DC37: Utilidades domésticas
B38: Aprovação da Diretoria em: | I38: Responsável Aprovação: | DC38: Varejo

Sheet Projeto 2
A1: ACOMPANHAMENTO DE PROJETOS - PROJETO 2
B2: =C3 -> 0 | D2: =I3 -> 0 | G2: =B13 -> 0 | H2: =E9 -> FÁBRICA E LAYOUT
B3: CLIENTE: | H3: SETOR: | CT3: 2. Gestão Financeira | CY3: Gerenciamento pelas Diretrizes | DC3: Bancos
CT4: 2.1. Redução de Despesas | CY4: Gestão para Resultados | DC4: Carnes e derivados
A5: =D5 -> 0 | B5: GESTOR DO PROJETO: | H5: DATA INÍCIO: | K5: INVESTIMENTO PROJETADO: | P5: =N5 -> 0 | CT5: 2.2. Redução de Custos | CY5: Implantação do Programa 5S | DC5: Comércio
CT6: 2.3. Aumento de Receita | CY6: Método de Análise e Solução de Problemas (MASP) | DC6: Construção civil e intermediação
A7: =D7 -> 0 | B7: LÍDER PROJETO: | H7: DATA FIM: | K7: GANHO FINANCEIRO PROJETADO: | P7: =N7 -> 0 | CT7: 3. Capacitação | CY7: Redução de Custos | DC7: Construção pesada e engenharia
CT8: 3.1. Gestão para Resultados | CY8: Redução de Despesas | DC8: Energia elétrica
B9: SOLUÇÃO | E9: FÁBRICA E LAYOUT | S9: ANÁLISE TEMPORAL | CD9: ANÁLISE FINANCEIRA | CT9: 3.2. Gerenciamento de Diretrizes | CY9: Reestruturação Organizacional e de Processos | DC9: Equipamentos, máquinas e peças
CT10: 3.3. Método de Análise e Solução de Problemas (MASP) | DC10: Holdings
CT11: 3.4. Implantação do programa 5S | DC11: Hospitais
B12: PROJETO | S12: CRONOGRAMA | CD12: Situação Meta | DC12: Hotelaria e Restaurantes
S13: ETAPAS DO PROJETO | AD13: 1 | AH13: 2 | AL13: 3 | AP13: 4 | AT13: 5 | AX13: 6 | BB13: 7 | BF13: 8 | BJ13: 9 | BN13: 10 | BR13: 11 | BV13: 12 | CE13: TOTAL | CF13: =AD14 -> JAN | CG13: =AH14 -> FEV | CH13: =AL14 -> MAR | CI13: =AP14 -> ABR | CJ13: =AT14 -> MAI | CK13: =AX14 -> JUN | CL13: =BB14 -> JUL | CM13: =BF14 -> AGO | CN13: =BJ14 -> SET | CO13: =BN14 -> OUT | CP13: =BR14 -> NOV | CQ13: =BV14 -> DEZ | DC13: Imóveis comerciais e shoppings
AD14: JAN | AH14: FEV | AL14: MAR | AP14: ABR | AT14: MAI | AX14: JUN | BB14: JUL | BF14: AGO | BJ14: SET | BN14: OUT | BR14: NOV | BV14: DEZ | CD14: Meta | CE14: =SUM(CF14:CQ14) -> 0 | DC14: Industria digital
CD15: Real | CE15: =SUM(CF15:CQ15) -> 0 | DC15: Industrias de alimentos
CD16: Aderência | CE16: =IFERROR(CE15/CE14,"-") -> - | CF16: =IFERROR(CF15/CF14,"-") -> - | CG16: =IFERROR(CG15/CG14,"-") -> - | CH16: =IFERROR(CH15/CH14,"-") -> - | CI16: =IFERROR(CI15/CI14,"-") -> - | CJ16: =IFERROR(CJ15/CJ14,"-") -> - | CK16: =IFERROR(CK15/CK14,"-") -> - | CL16: =IFERROR(CL15/CL14,"-") -> - | ... CQ16: =IFERROR(CQ15/CQ14,"-") -> - | DC16: Industria em geral
B17: META DO PROJETO | CD17: Situação Investimento | DC17: Logística
CE18: TOTAL | CF18: =CF13 -> JAN | CG18: =CG13 -> FEV | CH18: =CH13 -> MAR | CI18: =CI13 -> ABR | CJ18: =CJ13 -> MAI | CK18: =CK13 -> JUN | CL18: =CL13 -> JUL | CM18: =CM13 -> AGO | ... CQ18: =CQ13 -> DEZ | DC18: Materiais diversos
CD19: Meta | CE19: =SUM(CF19:CQ19) -> 0 | DC19: Mineração
CD20: Real | CE20: =SUM(CF20:CQ20) -> 0 | DC20: Negócios de lazer e eventos
CD21: Aderência | CE21: =IFERROR(CE20/CE19,"-") -> - | CF21: =IFERROR(CF20/CF19,"-") -> - | CG21: =IFERROR(CG20/CG19,"-") -> - | CH21: =IFERROR(CH20/CH19,"-") -> - | CI21: =IFERROR(CI20/CI19,"-") -> - | CJ21: =IFERROR(CJ20/CJ19,"-") -> - | CK21: =IFERROR(CK20/CK19,"-") -> - | CL21: =IFERROR(CL20/CL19,"-") -> - | ... CQ21: =IFERROR(CQ20/CQ19,"-") -> - | DC21: Papel e madeira
B22: DESCRIÇÃO DO PROBLEMA | DC22: Petróleo, gás e combustíveis
DC23: Prestação de Serviços
DC24: Química e petroquímica
DC25: Roupas, calçados e acessórios
B26: EQUIPE DE TRABALHO | DC26: Serviços diversos
B27: Nome | I27: Cargo | DC27: Serviços financeiros
B28: Líder: | C28: Cintia Ferreira | I28: Consultora Sênior | DC28: Setor de educação
DC29: Setor de saúde
B30: Pleno: | DC30: Setor de seguros
DC31: Setor de transporte
B32: Analista: | DC32: Siderurgia e metalurgia
DC33: Supermercados
DC34: Tecnologia da informação
B35: Estagiário: | DC35: Telecomunicações
DC36: Têxteis
DC37: Utilidades domésticas
B38: Aprovação da Diretoria em: | I38: Responsável Aprovação: | DC38: Varejo

Sheet Projeto 3
A1: ACOMPANHAMENTO DE PROJETOS - PROJETO 3
B2: =C3 -> 0 | D2: =I3 -> 0 | G2: =B13 -> 0 | H2: =E9 -> PRECIFICAÇÃO DE PROJETOS
B3: CLIENTE: | H3: SETOR: | CT3: 2. Gestão Financeira | CY3: Gerenciamento pelas Diretrizes | DC3: Bancos
CT4: 2.1. Redução de Despesas | CY4: Gestão para Resultados | DC4: Carnes e derivados
A5: =D5 -> 0 | B5: GESTOR DO PROJETO: | H5: DATA INÍCIO: | K5: INVESTIMENTO PROJETADO: | P5: =N5 -> 0 | CT5: 2.2. Redução de Custos | CY5: Implantação do Programa 5S | DC5: Comércio
CT6: 2.3. Aumento de Receita | CY6: Método de Análise e Solução de Problemas (MASP) | DC6: Construção civil e intermediação
A7: =D7 -> 0 | B7: LÍDER PROJETO: | H7: DATA FIM: | K7: GANHO FINANCEIRO PROJETADO: | P7: =N7 -> 0 | CT7: 3. Capacitação | CY7: Redução de Custos | DC7: Construção pesada e engenharia
CT8: 3.1. Gestão para Resultados | CY8: Redução de Despesas | DC8: Energia elétrica
B9: SOLUÇÃO | E9: PRECIFICAÇÃO DE PROJETOS | S9: ANÁLISE TEMPORAL | CD9: ANÁLISE FINANCEIRA | CT9: 3.2. Gerenciamento de Diretrizes | CY9: Reestruturação Organizacional e de Processos | DC9: Equipamentos, máquinas e peças
CT10: 3.3. Método de Análise e Solução de Problemas (MASP) | DC10: Holdings
CT11: 3.4. Implantação do programa 5S | DC11: Hospitais
B12: PROJETO | S12: CRONOGRAMA | CD12: Situação Meta | DC12: Hotelaria e Restaurantes
S13: ETAPAS DO PROJETO | AD13: 1 | AH13: 2 | AL13: 3 | AP13: 4 | AT13: 5 | AX13: 6 | BB13: 7 | BF13: 8 | BJ13: 9 | BN13: 10 | BR13: 11 | BV13: 12 | CE13: TOTAL | CF13: =AD14 -> JAN | CG13: =AH14 -> FEV | CH13: =AL14 -> MAR | CI13: =AP14 -> ABR | CJ13: =AT14 -> MAI | CK13: =AX14 -> JUN | CL13: =BB14 -> JUL | CM13: =BF14 -> AGO | CN13: =BJ14 -> SET | CO13: =BN14 -> OUT | CP13: =BR14 -> NOV | CQ13: =BV14 -> DEZ | DC13: Imóveis comerciais e shoppings
AD14: JAN | AH14: FEV | AL14: MAR | AP14: ABR | AT14: MAI | AX14: JUN | BB14: JUL | BF14: AGO | BJ14: SET | BN14: OUT | BR14: NOV | BV14: DEZ | CD14: Meta | CE14: =SUM(CF14:CQ14) -> 0 | DC14: Industria digital
CD15: Real | CE15: =SUM(CF15:CQ15) -> 0 | DC15: Industrias de alimentos
CD16: Aderência | CE16: =IFERROR(CE15/CE14,"-") -> - | CF16: =IFERROR(CF15/CF14,"-") -> - | CG16: =IFERROR(CG15/CG14,"-") -> - | CH16: =IFERROR(CH15/CH14,"-") -> - | CI16: =IFERROR(CI15/CI14,"-") -> - | CJ16: =IFERROR(CJ15/CJ14,"-") -> - | CK16: =IFERROR(CK15/CK14,"-") -> - | CL16: =IFERROR(CL15/CL14,"-") -> - | ... CQ16: =IFERROR(CQ15/CQ14,"-") -> - | DC16: Industria em geral
B17: META DO PROJETO | CD17: Situação Investimento | DC17: Logística
CE18: TOTAL | CF18: =CF13 -> JAN | CG18: =CG13 -> FEV | CH18: =CH13 -> MAR | CI18: =CI13 -> ABR | CJ18: =CJ13 -> MAI | CK18: =CK13 -> JUN | CL18: =CL13 -> JUL | CM18: =CM13 -> AGO | ... CQ18: =CQ13 -> DEZ | DC18: Materiais diversos
CD19: Meta | CE19: =SUM(CF19:CQ19) -> 0 | DC19: Mineração
CD20: Real | CE20: =SUM(CF20:CQ20) -> 0 | DC20: Negócios de lazer e eventos
CD21: Aderência | CE21: =IFERROR(CE20/CE19,"-") -> - | CF21: =IFERROR(CF20/CF19,"-") -> - | CG21: =IFERROR(CG20/CG19,"-") -> - | CH21: =IFERROR(CH20/CH19,"-") -> - | CI21: =IFERROR(CI20/CI19,"-") -> - | CJ21: =IFERROR(CJ20/CJ19,"-") -> - | CK21: =IFERROR(CK20/CK19,"-") -> - | CL21: =IFERROR(CL20/CL19,"-") -> - | ... CQ21: =IFERROR(CQ20/CQ19,"-") -> - | DC21: Papel e madeira
B22: DESCRIÇÃO DO PROBLEMA | DC22: Petróleo, gás e combustíveis
DC23: Prestação de Serviços
DC24: Química e petroquímica
DC25: Roupas, calçados e acessórios
B26: EQUIPE DE TRABALHO | DC26: Serviços diversos
B27: Nome | I27: Cargo | DC27: Serviços financeiros
B28: Líder: | C28: Cintia Ferreira | I28: Consultora Sênior | DC28: Setor de educação
DC29: Setor de saúde
B30: Pleno: | DC30: Setor de seguros
DC31: Setor de transporte
B32: Analista: | DC32: Siderurgia e metalurgia
DC33: Supermercados
DC34: Tecnologia da informação
B35: Estagiário: | DC35: Telecomunicações
DC36: Têxteis
DC37: Utilidades domésticas
B38: Aprovação da Diretoria em: | I38: Responsável Aprovação: | DC38: Varejo

Sheet Projeto 4
A1: ACOMPANHAMENTO DE PROJETOS - PROJETO 4
B2: =C3 -> 0 | D2: =I3 -> 0 | G2: =B13 -> 0 | H2: =E9 -> PRECIFICAÇÃO DE PROJETOS
B3: CLIENTE: | H3: SETOR: | CT3: 2. Gestão Financeira | CY3: Gerenciamento pelas Diretrizes | DC3: Bancos
CT4: 2.1. Redução de Despesas | CY4: Gestão para Resultados | DC4: Carnes e derivados
A5: =D5 -> 0 | B5: GESTOR DO PROJETO: | H5: DATA INÍCIO: | K5: INVESTIMENTO PROJETADO: | P5: =N5 -> 0 | CT5: 2.2. Redução de Custos | CY5: Implantação do Programa 5S | DC5: Comércio
CT6: 2.3. Aumento de Receita | CY6: Método de Análise e Solução de Problemas (MASP) | DC6: Construção civil e intermediação
A7: =D7 -> 0 | B7: LÍDER PROJETO: | H7: DATA FIM: | K7: GANHO FINANCEIRO PROJETADO: | P7: =N7 -> 0 | CT7: 3. Capacitação | CY7: Redução de Custos | DC7: Construção pesada e engenharia
CT8: 3.1. Gestão para Resultados | CY8: Redução de Despesas | DC8: Energia elétrica
B9: SOLUÇÃO | E9: PRECIFICAÇÃO DE PROJETOS | S9: ANÁLISE TEMPORAL | CD9: ANÁLISE FINANCEIRA | CT9: 3.2. Gerenciamento de Diretrizes | CY9: Reestruturação Organizacional e de Processos | DC9: Equipamentos, máquinas e peças
CT10: 3.3. Método de Análise e Solução de Problemas (MASP) | DC10: Holdings
CT11: 3.4. Implantação do programa 5S | DC11: Hospitais
B12: PROJETO | S12: CRONOGRAMA | CD12: Situação Meta | DC12: Hotelaria e Restaurantes
S13: ETAPAS DO PROJETO | AD13: 1 | AH13: 2 | AL13: 3 | AP13: 4 | AT13: 5 | AX13: 6 | BB13: 7 | BF13: 8 | BJ13: 9 | BN13: 10 | BR13: 11 | BV13: 12 | CE13: TOTAL | CF13: =AD14 -> JAN | CG13: =AH14 -> FEV | CH13: =AL14 -> MAR | CI13: =AP14 -> ABR | CJ13: =AT14 -> MAI | CK13: =AX14 -> JUN | CL13: =BB14 -> JUL | CM13: =BF14 -> AGO | CN13: =BJ14 -> SET | CO13: =BN14 -> OUT | CP13: =BR14 -> NOV | CQ13: =BV14 -> DEZ | DC13: Imóveis comerciais e shoppings
AD14: JAN | AH14: FEV | AL14: MAR | AP14: ABR | AT14: MAI | AX14: JUN | BB14: JUL | BF14: AGO | BJ14: SET | BN14: OUT | BR14: NOV | BV14: DEZ | CD14: Meta | CE14: =SUM(CF14:CQ14) -> 0 | DC14: Industria digital
CD15: Real | CE15: =SUM(CF15:CQ15) -> 0 | DC15: Industrias de alimentos
CD16: Aderência | CE16: =IFERROR(CE15/CE14,"-") -> - | CF16: =IFERROR(CF15/CF14,"-") -> - | CG16: =IFERROR(CG15/CG14,"-") -> - | CH16: =IFERROR(CH15/CH14,"-") -> - | CI16: =IFERROR(CI15/CI14,"-") -> - | CJ16: =IFERROR(CJ15/CJ14,"-") -> - | CK16: =IFERROR(CK15/CK14,"-") -> - | CL16: =IFERROR(CL15/CL14,"-") -> - | ... CQ16: =IFERROR(CQ15/CQ14,"-") -> - | DC16: Industria em geral
B17: META DO PROJETO | CD17: Situação Investimento | DC17: Logística
CE18: TOTAL | CF18: =CF13 -> JAN | CG18: =CG13 -> FEV | CH18: =CH13 -> MAR | CI18: =CI13 -> ABR | CJ18: =CJ13 -> MAI | CK18: =CK13 -> JUN | CL18: =CL13 -> JUL | CM18: =CM13 -> AGO | ... CQ18: =CQ13 -> DEZ | DC18: Materiais diversos
CD19: Meta | CE19: =SUM(CF19:CQ19) -> 0 | DC19: Mineração
CD20: Real | CE20: =SUM(CF20:CQ20) -> 0 | DC20: Negócios de lazer e eventos
CD21: Aderência | CE21: =IFERROR(CE20/CE19,"-") -> - | CF21: =IFERROR(CF20/CF19,"-") -> - | CG21: =IFERROR(CG20/CG19,"-") -> - | CH21: =IFERROR(CH20/CH19,"-") -> - | CI21: =IFERROR(CI20/CI19,"-") -> - | CJ21: =IFERROR(CJ20/CJ19,"-") -> - | CK21: =IFERROR(CK20/CK19,"-") -> - | CL21: =IFERROR(CL20/CL19,"-") -> - | ... CQ21: =IFERROR(CQ20/CQ19,"-") -> - | DC21: Papel e madeira
B22: DESCRIÇÃO DO PROBLEMA | DC22: Petróleo, gás e combustíveis
DC23: Prestação de Serviços
DC24: Química e petroquímica
DC25: Roupas, calçados e acessórios
B26: EQUIPE DE TRABALHO | DC26: Serviços diversos
B27: Nome | I27: Cargo | DC27: Serviços financeiros
B28: Líder: | C28: Cintia Ferreira | I28: Consultora Sênior | DC28: Setor de educação
DC29: Setor de saúde
B30: Pleno: | DC30: Setor de seguros
DC31: Setor de transporte
B32: Analista: | DC32: Siderurgia e metalurgia
DC33: Supermercados
DC34: Tecnologia da informação
B35: Estagiário: | DC35: Telecomunicações
DC36: Têxteis
DC37: Utilidades domésticas
B38: Aprovação da Diretoria em: | I38: Responsável Aprovação: | DC38: Varejo

Sheet Projeto 5
A1: ACOMPANHAMENTO DE PROJETOS - PROJETO 5
B2: =C3 -> 0 | D2: =I3 -> 0 | G2: =B13 -> 0 | H2: =E9 -> Gestão para Resultados
B3: CLIENTE: | H3: SETOR: | CT3: 2. Gestão Financeira | CY3: Gerenciamento pelas Diretrizes | DC3: Bancos
CT4: 2.1. Redução de Despesas | CY4: Gestão para Resultados | DC4: Carnes e derivados
A5: =D5 -> 0 | B5: GESTOR DO PROJETO: | H5: DATA INÍCIO: | K5: INVESTIMENTO PROJETADO: | P5: =N5 -> 0 | CT5: 2.2. Redução de Custos | CY5: Implantação do Programa 5S | DC5: Comércio
CT6: 2.3. Aumento de Receita | CY6: Método de Análise e Solução de Problemas (MASP) | DC6: Construção civil e intermediação
A7: =D7 -> 0 | B7: LÍDER PROJETO: | H7: DATA FIM: | K7: GANHO FINANCEIRO PROJETADO: | P7: =N7 -> 0 | CT7: 3. Capacitação | CY7: Redução de Custos | DC7: Construção pesada e engenharia
CT8: 3.1. Gestão para Resultados | CY8: Redução de Despesas | DC8: Energia elétrica
B9: SOLUÇÃO | E9: Gestão para Resultados | S9: ANÁLISE TEMPORAL | CD9: ANÁLISE FINANCEIRA | CT9: 3.2. Gerenciamento de Diretrizes | CY9: Reestruturação Organizacional e de Processos | DC9: Equipamentos, máquinas e peças
CT10: 3.3. Método de Análise e Solução de Problemas (MASP) | DC10: Holdings
CT11: 3.4. Implantação do programa 5S | DC11: Hospitais
B12: PROJETO | S12: CRONOGRAMA | CD12: Situação Meta | DC12: Hotelaria e Restaurantes
S13: ETAPAS DO PROJETO | AD13: 1 | AH13: 2 | AL13: 3 | AP13: 4 | AT13: 5 | AX13: 6 | BB13: 7 | BF13: 8 | BJ13: 9 | BN13: 10 | BR13: 11 | BV13: 12 | CE13: TOTAL | CF13: =AD14 -> JAN | CG13: =AH14 -> FEV | CH13: =AL14 -> MAR | CI13: =AP14 -> ABR | CJ13: =AT14 -> MAI | CK13: =AX14 -> JUN | CL13: =BB14 -> JUL | CM13: =BF14 -> AGO | CN13: =BJ14 -> SET | CO13: =BN14 -> OUT | CP13: =BR14 -> NOV | CQ13: =BV14 -> DEZ | DC13: Imóveis comerciais e shoppings
AD14: JAN | AH14: FEV | AL14: MAR | AP14: ABR | AT14: MAI | AX14: JUN | BB14: JUL | BF14: AGO | BJ14: SET | BN14: OUT | BR14: NOV | BV14: DEZ | CD14: Meta | CE14: =SUM(CF14:CQ14) -> 0 | DC14: Industria digital
CD15: Real | CE15: =SUM(CF15:CQ15) -> 0 | DC15: Industrias de alimentos
CD16: Aderência | CE16: =IFERROR(CE15/CE14,"-") -> - | CF16: =IFERROR(CF15/CF14,"-") -> - | CG16: =IFERROR(CG15/CG14,"-") -> - | CH16: =IFERROR(CH15/CH14,"-") -> - | CI16: =IFERROR(CI15/CI14,"-") -> - | CJ16: =IFERROR(CJ15/CJ14,"-") -> - | CK16: =IFERROR(CK15/CK14,"-") -> - | CL16: =IFERROR(CL15/CL14,"-") -> - | ... CQ16: =IFERROR(CQ15/CQ14,"-") -> - | DC16: Industria em geral
B17: META DO PROJETO | CD17: Situação Investimento | DC17: Logística
CE18: TOTAL | CF18: =CF13 -> JAN | CG18: =CG13 -> FEV | CH18: =CH13 -> MAR | CI18: =CI13 -> ABR | CJ18: =CJ13 -> MAI | CK18: =CK13 -> JUN | CL18: =CL13 -> JUL | CM18: =CM13 -> AGO | ... CQ18: =CQ13 -> DEZ | DC18: Materiais diversos
CD19: Meta | CE19: =SUM(CF19:CQ19) -> 0 | DC19: Mineração
CD20: Real | CE20: =SUM(CF20:CQ20) -> 0 | DC20: Negócios de lazer e eventos
CD21: Aderência | CE21: =IFERROR(CE20/CE19,"-") -> - | CF21: =IFERROR(CF20/CF19,"-") -> - | CG21: =IFERROR(CG20/CG19,"-") -> - | CH21: =IFERROR(CH20/CH19,"-") -> - | CI21: =IFERROR(CI20/CI19,"-") -> - | CJ21: =IFERROR(CJ20/CJ19,"-") -> - | CK21: =IFERROR(CK20/CK19,"-") -> - | CL21: =IFERROR(CL20/CL19,"-") -> - | ... CQ21: =IFERROR(CQ20/CQ19,"-") -> - | DC21: Papel e madeira
B22: DESCRIÇÃO DO PROBLEMA | DC22: Petróleo, gás e combustíveis
DC23: Prestação de Serviços
DC24: Química e petroquímica
DC25: Roupas, calçados e acessórios
B26: EQUIPE DE TRABALHO | DC26: Serviços diversos
B27: Nome | I27: Cargo | DC27: Serviços financeiros
B28: Líder: | C28: Cintia Ferreira | I28: Consultora Sênior | DC28: Setor de educação
DC29: Setor de saúde
B30: Pleno: | DC30: Setor de seguros
DC31: Setor de transporte
B32: Analista: | DC32: Siderurgia e metalurgia
DC33: Supermercados
DC34: Tecnologia da informação
B35: Estagiário: | DC35: Telecomunicações
DC36: Têxteis
DC37: Utilidades domésticas
B38: Aprovação da Diretoria em: | I38: Responsável Aprovação: | DC38: Varejo

Sheet Base Painel Gerencial
B4: Solução | C4: % Aderência a Meta Acumulada | D4: Setor | F4: Evolução Projetos
B5: ='Acompanhamento Geral'!E5 -> FÁBRICA E LAYOUT | C5: ='Acompanhamento Geral'!M5 -> - | D5: ='Acompanhamento Geral'!C5 -> 0 | G5: jan | H5: fev | I5: mar | J5: abr | K5: mai | L5: jun | M5: jul | N5: ago | O5: set | P5: out | Q5: nov | R5: dez
B6: ='Acompanhamento Geral'!E6 -> FÁBRICA E LAYOUT | C6: ='Acompanhamento Geral'!M6 -> - | D6: ='Acompanhamento Geral'!C6 -> 0 | F6: Quantidade | G6: =COUNTIF('Acompanhamento Geral'!Y:Y,G8) -> 0 | H6: =COUNTIF('Acompanhamento Geral'!Z:Z,H8) -> 0 | I6: =COUNTIF('Acompanhamento Geral'!AA:AA,I8) -> 0 | J6: =COUNTIF('Acompanhamento Geral'!AB:AB,J8) -> 0 | K6: =COUNTIF('Acompanhamento Geral'!AC:AC,K8) -> 0 | L6: =COUNTIF('Acompanhamento Geral'!AD:AD,L8) -> 0 | M6: =COUNTIF('Acompanhamento Geral'!AE:AE,M8) -> 0 | N6: =COUNTIF('Acompanhamento Geral'!AF:AF,N8) -> 0 | O6: =COUNTIF('Acompanhamento Geral'!AG:AG,O8) -> 0 | P6: =COUNTIF('Acompanhamento Geral'!AH:AH,P8) -> 0 | Q6: =COUNTIF('Acompanhamento Geral'!AI:AI,Q8) -> 0 | R6: =COUNTIF('Acompanhamento Geral'!AJ:AJ,R8) -> 0
B7: ='Acompanhamento Geral'!E7 -> PRECIFICAÇÃO DE PROJETOS | C7: ='Acompanhamento Geral'!M7 -> - | D7: ='Acompanhamento Geral'!C7 -> 0 | F7: % Evolução | G7: =IFERROR(G6/G6,1) -> 1 | H7: =IFERROR(H6/G6,1) -> 1 | I7: =IFERROR(I6/H6,1) -> 1 | J7: =IFERROR(J6/I6,1) -> 1 | K7: =IFERROR(K6/J6,1) -> 1 | L7: =IFERROR(L6/K6,1) -> 1 | M7: =IFERROR(M6/L6,1) -> 1 | N7: =IFERROR(N6/M6,1) -> 1 | O7: =IFERROR(O6/N6,N7) -> 1 | P7: =IFERROR(P6/O6,O7) -> 1 | Q7: =IFERROR(Q6/P6,P7) -> 1 | R7: =IFERROR(R6/Q6,Q7) -> 1
B8: ='Acompanhamento Geral'!E8 -> PRECIFICAÇÃO DE PROJETOS | C8: ='Acompanhamento Geral'!M8 -> - | D8: ='Acompanhamento Geral'!C8 -> 0 | G8: 1 | H8: =G8+1 -> 2 | I8: =H8+1 -> 3 | J8: =I8+1 -> 4 | K8: =J8+1 -> 5 | L8: =K8+1 -> 6 | M8: =L8+1 -> 7 | N8: =M8+1 -> 8 | O8: =N8+1 -> 9 | ... AF8: =AE8+1 -> 26
B9: ='Acompanhamento Geral'!E9 -> Gestão para Resultados | C9: ='Acompanhamento Geral'!M9 -> - | D9: ='Acompanhamento Geral'!C9 -> 0 | F9: Projetos/Solução
G10: Quantidade | H10: Porcentagem
F11: =Cadastro!F7 -> 0 | G11: =COUNTIF($B$5:$B$9,'Base Painel Gerencial'!F11) -> 0 | H11: =IFERROR(G11/SUM($G$11:$G$21),0) -> 0
F12: =Cadastro!F8 -> 0 | G12: =COUNTIF($B$5:$B$9,'Base Painel Gerencial'!F12) -> 0 | H12: =IFERROR(G12/SUM($G$11:$G$21),0) -> 0
F13: =Cadastro!F9 -> 0 | G13: =COUNTIF($B$5:$B$9,'Base Painel Gerencial'!F13) -> 0 | H13: =IFERROR(G13/SUM($G$11:$G$21),0) -> 0
F14: =Cadastro!F10 -> 0 | G14: =COUNTIF($B$5:$B$9,'Base Painel Gerencial'!F14) -> 0 | H14: =IFERROR(G14/SUM($G$11:$G$21),0) -> 0
F15: =Cadastro!F11 -> - | G15: =COUNTIF($B$5:$B$9,'Base Painel Gerencial'!F15) -> 0 | H15: =IFERROR(G15/SUM($G$11:$G$21),0) -> 0
F16: =Cadastro!F12 -> - | G16: =COUNTIF($B$5:$B$9,'Base Painel Gerencial'!F16) -> 0 | H16: =IFERROR(G16/SUM($G$11:$G$21),0) -> 0
F17: =Cadastro!F13 -> - | G17: =COUNTIF($B$5:$B$9,'Base Painel Gerencial'!F17) -> 0 | H17: =IFERROR(G17/SUM($G$11:$G$21),0) -> 0
F18: =Cadastro!F14 -> - | G18: =COUNTIF($B$5:$B$9,'Base Painel Gerencial'!F18) -> 0 | H18: =IFERROR(G18/SUM($G$11:$G$21),0) -> 0
F19: =Cadastro!F15 -> - | G19: =COUNTIF($B$5:$B$9,'Base Painel Gerencial'!F19) -> 0 | H19: =IFERROR(G19/SUM($G$11:$G$21),0) -> 0
F20: =Cadastro!F16 -> - | G20: =COUNTIF($B$5:$B$9,'Base Painel Gerencial'!F20) -> 0 | H20: =IFERROR(G20/SUM($G$11:$G$21),0) -> 0
F21: =Cadastro!F17 -> - | G21: =COUNTIF($B$5:$B$9,'Base Painel Gerencial'!F21) -> 0 | H21: =IFERROR(G21/SUM($G$11:$G$21),0) -> 0
F23: Porcentagem Meta
G24: Quantidade | H24: Porcentagem
F25: Projetos batendo meta | G25: =COUNTIF('Acompanhamento Geral'!$N$5:$N$9,"s") -> 5 | H25: =IFERROR(G25/SUM($G$25:$G$26),0) -> 1
F26: Projetos não batendo meta | G26: =COUNTIF('Acompanhamento Geral'!$N$5:$N$9,"n") -> 0 | H26: =IFERROR(G26/SUM($G$25:$G$26),0) -> 0
F28: Setor | J28: Aderência Meta
G29: Quantidade | H29: Porcentagem | J29: ='Acompanhamento Geral'!B5 -> 0 | K29: ='Acompanhamento Geral'!M5 -> - | L29: =K29 -> -
F30: =Cadastro!H7 -> Agropecuária | G30: =COUNTIF('Acompanhamento Geral'!$C:$C,F30) -> 0 | H30: =IFERROR(G30/SUM($G$30:$G$69),0) -> 0 | J30: ='Acompanhamento Geral'!B6 -> 0 | K30: ='Acompanhamento Geral'!M6 -> - | L30: =K30 -> -
F31: =Cadastro!H8 -> Água, gás e saneamento | G31: =COUNTIF('Acompanhamento Geral'!$C:$C,F31) -> 0 | H31: =IFERROR(G31/SUM($G$30:$G$69),0) -> 0 | J31: ='Acompanhamento Geral'!B7 -> 0 | K31: ='Acompanhamento Geral'!M7 -> - | L31: =K31 -> -
F32: =Cadastro!H9 -> Alimentos processados | G32: =COUNTIF('Acompanhamento Geral'!$C:$C,F32) -> 0 | H32: =IFERROR(G32/SUM($G$30:$G$69),0) -> 0 | J32: ='Acompanhamento Geral'!B8 -> 0 | K32: ='Acompanhamento Geral'!M8 -> - | L32: =K32 -> -
F33: =Cadastro!H10 -> Atacado | G33: =COUNTIF('Acompanhamento Geral'!$C:$C,F33) -> 0 | H33: =IFERROR(G33/SUM($G$30:$G$69),0) -> 0 | J33: ='Acompanhamento Geral'!B9 -> 0 | K33: ='Acompanhamento Geral'!M9 -> - | L33: =K33 -> -
F34: =Cadastro!H11 -> Bancos | G34: =COUNTIF('Acompanhamento Geral'!$C:$C,F34) -> 0 | H34: =IFERROR(G34/SUM($G$30:$G$69),0) -> 0
F35: =Cadastro!H12 -> Carnes e derivados | G35: =COUNTIF('Acompanhamento Geral'!$C:$C,F35) -> 0 | H35: =IFERROR(G35/SUM($G$30:$G$69),0) -> 0
F36: =Cadastro!H13 -> Comércio | G36: =COUNTIF('Acompanhamento Geral'!$C:$C,F36) -> 0 | H36: =IFERROR(G36/SUM($G$30:$G$69),0) -> 0
F37: =Cadastro!H14 -> Construção civil e intermediação | G37: =COUNTIF('Acompanhamento Geral'!$C:$C,F37) -> 0 | H37: =IFERROR(G37/SUM($G$30:$G$69),0) -> 0
F38: =Cadastro!H15 -> Construção pesada e engenharia | G38: =COUNTIF('Acompanhamento Geral'!$C:$C,F38) -> 0 | H38: =IFERROR(G38/SUM($G$30:$G$69),0) -> 0
F39: =Cadastro!H16 -> Energia elétrica | G39: =COUNTIF('Acompanhamento Geral'!$C:$C,F39) -> 0 | H39: =IFERROR(G39/SUM($G$30:$G$69),0) -> 0
F40: =Cadastro!H17 -> Equipamentos, máquinas e peças | G40: =COUNTIF('Acompanhamento Geral'!$C:$C,F40) -> 0 | H40: =IFERROR(G40/SUM($G$30:$G$69),0) -> 0
F41: =Cadastro!H18 -> Holdings | G41: =COUNTIF('Acompanhamento Geral'!$C:$C,F41) -> 0 | H41: =IFERROR(G41/SUM($G$30:$G$69),0) -> 0
F42: =Cadastro!H19 -> Hospitais | G42: =COUNTIF('Acompanhamento Geral'!$C:$C,F42) -> 0 | H42: =IFERROR(G42/SUM($G$30:$G$69),0) -> 0
F43: =Cadastro!H20 -> Hotelaria e Restaurantes | G43: =COUNTIF('Acompanhamento Geral'!$C:$C,F43) -> 0 | H43: =IFERROR(G43/SUM($G$30:$G$69),0) -> 0
F44: =Cadastro!H21 -> Imóveis comerciais e shoppings | G44: =COUNTIF('Acompanhamento Geral'!$C:$C,F44) -> 0 | H44: =IFERROR(G44/SUM($G$30:$G$69),0) -> 0
F45: =Cadastro!H22 -> Industria digital | G45: =COUNTIF('Acompanhamento Geral'!$C:$C,F45) -> 0 | H45: =IFERROR(G45/SUM($G$30:$G$69),0) -> 0
...

Sheet Panorama
A1: ACOMPANHAMENTO DE PROJETOS - PANORAMA
