Workbook

Sheet inicio
B3: PLANILHA DE LUCRO REAL - IR e CS
C5: 1 | D5: Cadastro: | E5: Na aba de cadastro de tabelas com as alíquotas do lucro real (imposto de renda e contribuição social), lucro acumulado e compensações de impostos ;
C7: 2 | D7: Lançamentos: | E7: Na aba de lançamentos automáticos dos cálculos mensais dos impostos;
C9: 3 | D9: Resultados: | E9: Na aba de resultados consta o resumo do anual do impostos de renda, contribuição social e média;
C11: 4 | D11: Gráficos: | E11: Na aba de gráficos representa a evolução dos impostos por mês;
C13: 5 | D13: Impressão: | E13: Na aba de impressão dos relatórios do lucro real;
C15: 6 | D15: Sobre: | E15: Na aba sobre é destinado para publicação do site do desenvolvedor e formas de contato.

Sheet tab
B4: # | C4: Parâmetros | D4: % | E4: Jan | F4: Fev | G4: Mar | H4: Abr | I4: Mai | J4: Jun | K4: Jul | L4: Ago | M4: Set | N4: Out | O4: Nov | P4: Dez
B5: = | C5: Lucro Acumulado | E5: 1000 | F5: =E5+25000 -> 26000 | G5: =F5+25000 -> 51000 | H5: =G5+25000 -> 76000 | I5: =H5+25000 -> 101000 | J5: =I5+25000 -> 126000 | K5: =J5+25000 -> 151000 | L5: =K5+25000 -> 176000 | M5: =L5+25000 -> 201000 | ... P5: =O5+25000 -> 276000
B6: = | C6: Adições
B7: + | C7: Ajustes Devedores de Qualquer Natureza
B8: + | C8: Despesas de Variação Cambial
B9: + | C9: Despesas Particulares dos Sócios e Dirigentes;
B10: + | C10: Doações e Brindes; | E10: 100 | F10: 100 | G10: 100 | H10: 100 | I10: 100 | J10: 100 | K10: 100 | L10: 100 | M10: 100 | N10: 100 | O10: 100 | P10: 100
B11: + | C11: Impostos Não Pagos em Discussão Judicial;
B12: + | C12: Impostos Não Pagos por Iniciativa da Empresa;
B13: + | C13: Lucro Inflacionário apurado até 31/12/1995;
B14: + | C14: Multas Contratuais
B15: + | C15: Multas Punitivas (Transito, Imetro, Ibama, Multas sobre ação fiscal) | E15: 500 | F15: 500 | G15: 500 | H15: 500 | I15: 500 | J15: 500 | K15: 500 | L15: 500 | M15: 500 | N15: 500 | O15: 500 | P15: 500
B16: + | C16: Orçamentos, Pedidos e qualquer documento não idôneo;
B17: + | C17: Provisões Indedutíveis (perdas, frete, propaganda)
B18: + | C18: Recibos sem especificação da fonte recebedora;
B19: + | C19: Verbas Rescisórias em desacordo com a legislação trabalhista vigente
B20: = | C20: Exclusões
B21: - | C21: Ajustes credores de qualquer natureza
B22: - | C22: Decisão Favorável - Processos Judiciais Tributários
B23: - | C23: Despesas de Ágios
B24: - | C24: Distribuição de Lucros e Dividendos;
B25: - | C25: Dividendos Coligadas e Controladas
B26: - | C26: Pagamento de Impostos em Atraso por iniciativa da Empresa | E26: -1000 | F26: -1000 | G26: -1000 | H26: -1000 | I26: -1000 | J26: -1000 | K26: -1000 | L26: -1000 | M26: -1000 | N26: -1000 | O26: -1000 | P26: -1000
B27: - | C27: Pagamento de Impostos sobre discussão judicial,
B28: - | C28: Receita de Variação Cambial
B29: - | C29: Receitas Obtidas com Tributação Exclusiva ou Isenta de IR
B30: - | C30: Receitas que poderiam ser diferidas;
B31: - | C31: Resultado Positivo de Equivalência Patrimonial
B32: - | C32: Reversão de Provisões Indedutíveis
B33: - | C33: Vendas Não Expedidas do Período
B34: = | C34: Base de Cálculo
B35: = | C35: Saldo Prejuízo Fiscal | E35: 45000
B36: % | C36: Compensação de Prejuízo Fiscal | D36: 0.3
B37: % | C37: Adicional de Imposto de Renda | D37: 0.1
B38: % | C38: Imposto de Renda | D38: 0.15
B39: % | C39: Contribuição Social | D39: 0.09
B40: = | C40: Compensações
B41: - | C41: IR Base Negativa Exercícios Anteriores
B42: - | C42: IR s/ Aplicações Financeiras | E42: -100 | F42: -100 | G42: -100 | H42: -100 | I42: -100 | J42: -100 | K42: -100 | L42: -100 | M42: -100 | N42: -100 | O42: -100 | P42: -100
B43: - | C43: IR Retida s/ Notas Fiscais | E43: -2000 | F43: -2000 | G43: -2000 | H43: -2000 | I43: -2000 | J43: -2000 | K43: -2000 | L43: -2000 | M43: -2000 | N43: -2000 | O43: -2000 | P43: -2000
...

Sheet jan
B3: 2018
A4: 1 | B4: # | C4: Parâmetros | D4: % | E4: Jan | F4: Fev | G4: Mar | H4: Abr | I4: Mai | J4: Jun | K4: Jul | L4: Ago | M4: Set | N4: Out | O4: Nov | P4: Dez
A5: 2018 | B5: =tab!B5 -> = | C5: =tab!C5 -> Lucro Acumulado | E5: =HLOOKUP(E$4,tab!$E$4:$P$33,MATCH($C5,$C$4:$C$33,0),0) -> 1000
A6: 2019 | B6: =tab!B6 -> = | C6: =tab!C6 -> Adições | E6: =SUM(E7:E19) -> 600
A7: 2020 | B7: =tab!B7 -> + | C7: =tab!C7 -> Ajustes Devedores de Qualquer Natureza | E7: =HLOOKUP(E$4,tab!$E$4:$P$33,MATCH($C7,$C$4:$C$33,0),0) -> 0
A8: 2021 | B8: =tab!B8 -> + | C8: =tab!C8 -> Despesas de Variação Cambial | E8: =HLOOKUP(E$4,tab!$E$4:$P$33,MATCH($C8,$C$4:$C$33,0),0) -> 0
A9: 2022 | B9: =tab!B9 -> + | C9: =tab!C9 -> Despesas Particulares dos Sócios e Dirigentes; | E9: =HLOOKUP(E$4,tab!$E$4:$P$33,MATCH($C9,$C$4:$C$33,0),0) -> 0
A10: 2023 | B10: =tab!B10 -> + | C10: =tab!C10 -> Doações e Brindes; | E10: =HLOOKUP(E$4,tab!$E$4:$P$33,MATCH($C10,$C$4:$C$33,0),0) -> 100
A11: 2024 | B11: =tab!B11 -> + | C11: =tab!C11 -> Impostos Não Pagos em Discussão Judicial; | E11: =HLOOKUP(E$4,tab!$E$4:$P$33,MATCH($C11,$C$4:$C$33,0),0) -> 0
A12: 2025 | B12: =tab!B12 -> + | C12: =tab!C12 -> Impostos Não Pagos por Iniciativa da Empresa; | E12: =HLOOKUP(E$4,tab!$E$4:$P$33,MATCH($C12,$C$4:$C$33,0),0) -> 0
A13: 2026 | B13: =tab!B13 -> + | C13: =tab!C13 -> Lucro Inflacionário apurado até 31/12/1995; | E13: =HLOOKUP(E$4,tab!$E$4:$P$33,MATCH($C13,$C$4:$C$33,0),0) -> 0
A14: 2027 | B14: =tab!B14 -> + | C14: =tab!C14 -> Multas Contratuais | E14: =HLOOKUP(E$4,tab!$E$4:$P$33,MATCH($C14,$C$4:$C$33,0),0) -> 0
A15: 2028 | B15: =tab!B15 -> + | C15: =tab!C15 -> Multas Punitivas (Transito, Imetro, Ibama, Multas sobre ação fiscal) | E15: =HLOOKUP(E$4,tab!$E$4:$P$33,MATCH($C15,$C$4:$C$33,0),0) -> 500
A16: 2029 | B16: =tab!B16 -> + | C16: =tab!C16 -> Orçamentos, Pedidos e qualquer documento não idôneo; | E16: =HLOOKUP(E$4,tab!$E$4:$P$33,MATCH($C16,$C$4:$C$33,0),0) -> 0
A17: 2030 | B17: =tab!B17 -> + | C17: =tab!C17 -> Provisões Indedutíveis (perdas, frete, propaganda) | E17: =HLOOKUP(E$4,tab!$E$4:$P$33,MATCH($C17,$C$4:$C$33,0),0) -> 0
B18: =tab!B18 -> + | C18: =tab!C18 -> Recibos sem especificação da fonte recebedora; | E18: =HLOOKUP(E$4,tab!$E$4:$P$33,MATCH($C18,$C$4:$C$33,0),0) -> 0
B19: =tab!B19 -> + | C19: =tab!C19 -> Verbas Rescisórias em desacordo com a legislação trabalhista vigente | E19: =HLOOKUP(E$4,tab!$E$4:$P$33,MATCH($C19,$C$4:$C$33,0),0) -> 0
B20: =tab!B20 -> = | C20: =tab!C20 -> Exclusões | E20: =SUM(E21:E33) -> -1000
B21: =tab!B21 -> - | C21: =tab!C21 -> Ajustes credores de qualquer natureza | E21: =HLOOKUP(E$4,tab!$E$4:$P$33,MATCH($C21,$C$4:$C$33,0),0) -> 0
B22: =tab!B22 -> - | C22: =tab!C22 -> Decisão Favorável - Processos Judiciais Tributários | E22: =HLOOKUP(E$4,tab!$E$4:$P$33,MATCH($C22,$C$4:$C$33,0),0) -> 0
B23: =tab!B23 -> - | C23: =tab!C23 -> Despesas de Ágios | E23: =HLOOKUP(E$4,tab!$E$4:$P$33,MATCH($C23,$C$4:$C$33,0),0) -> 0
B24: =tab!B24 -> - | C24: =tab!C24 -> Distribuição de Lucros e Dividendos; | E24: =HLOOKUP(E$4,tab!$E$4:$P$33,MATCH($C24,$C$4:$C$33,0),0) -> 0
B25: =tab!B25 -> - | C25: =tab!C25 -> Dividendos Coligadas e Controladas | E25: =HLOOKUP(E$4,tab!$E$4:$P$33,MATCH($C25,$C$4:$C$33,0),0) -> 0
B26: =tab!B26 -> - | C26: =tab!C26 -> Pagamento de Impostos em Atraso por iniciativa da Empresa | E26: =HLOOKUP(E$4,tab!$E$4:$P$33,MATCH($C26,$C$4:$C$33,0),0) -> -1000
B27: =tab!B27 -> - | C27: =tab!C27 -> Pagamento de Impostos sobre discussão judicial, | E27: =HLOOKUP(E$4,tab!$E$4:$P$33,MATCH($C27,$C$4:$C$33,0),0) -> 0
B28: =tab!B28 -> - | C28: =tab!C28 -> Receita de Variação Cambial | E28: =HLOOKUP(E$4,tab!$E$4:$P$33,MATCH($C28,$C$4:$C$33,0),0) -> 0
B29: =tab!B29 -> - | C29: =tab!C29 -> Receitas Obtidas com Tributação Exclusiva ou Isenta de IR | E29: =HLOOKUP(E$4,tab!$E$4:$P$33,MATCH($C29,$C$4:$C$33,0),0) -> 0
B30: =tab!B30 -> - | C30: =tab!C30 -> Receitas que poderiam ser diferidas; | E30: =HLOOKUP(E$4,tab!$E$4:$P$33,MATCH($C30,$C$4:$C$33,0),0) -> 0
B31: =tab!B31 -> - | C31: =tab!C31 -> Resultado Positivo de Equivalência Patrimonial | E31: =HLOOKUP(E$4,tab!$E$4:$P$33,MATCH($C31,$C$4:$C$33,0),0) -> 0
B32: =tab!B32 -> - | C32: =tab!C32 -> Reversão de Provisões Indedutíveis | E32: =HLOOKUP(E$4,tab!$E$4:$P$33,MATCH($C32,$C$4:$C$33,0),0) -> 0
B33: =tab!B33 -> - | C33: =tab!C33 -> Vendas Não Expedidas do Período | E33: =HLOOKUP(E$4,tab!$E$4:$P$33,MATCH($C33,$C$4:$C$33,0),0) -> 0
B34: =tab!B34 -> = | C34: =tab!C34 -> Base de Cálculo | E34: =SUM(E5,E6,E20) -> 600
B35: =tab!B35 -> = | C35: =tab!C35 -> Saldo Prejuízo Fiscal | E35: =tab!E35 -> 45000
B36: =tab!B36 -> % | C36: =tab!C36 -> Compensação de Prejuízo Fiscal | D36: =tab!D36 -> 0.3 | E36: =-IF(AND(E35>0,E34*$D$36<E35),E34*$D$36,E35) -> -180
B37: =tab!B37 -> % | C37: =tab!C37 -> Adicional de Imposto de Renda | D37: =tab!D37 -> 0.1 | E37: =IF(SUM(E34,E36)>20000*$A$4,(SUM(E34,E36)-20000*$A$4)*$D$37,0) -> 0
B38: =tab!B38 -> % | C38: =tab!C38 -> Imposto de Renda | D38: =tab!D38 -> 0.15 | E38: =SUM(E34,E36)*$D$38 -> 63
B39: =tab!B39 -> % | C39: =tab!C39 -> Contribuição Social | D39: =tab!D39 -> 0.09 | E39: =SUM(E34,E36)*$D$39 -> 37.8
B40: =tab!B40 -> = | C40: =tab!C40 -> Compensações | E40: =SUM(E42:E47) -> -3600
B41: =tab!B41 -> - | C41: =tab!C41 -> IR Base Negativa Exercícios Anteriores | D41: =LEFT(C41,2) -> IR | E41: =HLOOKUP(E$4,tab!$E$4:$P$49,MATCH($C41,$C$4:$C$49,0),0) -> 0
B42: =tab!B42 -> - | C42: =tab!C42 -> IR s/ Aplicações Financeiras | D42: =LEFT(C42,2) -> IR | E42: =HLOOKUP(E$4,tab!$E$4:$P$49,MATCH($C42,$C$4:$C$49,0),0) -> -100
...

Sheet fev
B3: 2018
A4: 2 | B4: # | C4: Parâmetros | D4: % | E4: Jan | F4: Fev | G4: Mar | H4: Abr | I4: Mai | J4: Jun | K4: Jul | L4: Ago | M4: Set | N4: Out | O4: Nov | P4: Dez
A5: 2018 | B5: =tab!B5 -> = | C5: =tab!C5 -> Lucro Acumulado | E5: =HLOOKUP(E$4,tab!$E$4:$P$33,MATCH($C5,$C$4:$C$33,0),0) -> 1000 | F5: =HLOOKUP(F$4,tab!$E$4:$P$33,MATCH($C5,$C$4:$C$33,0),0) -> 26000
A6: 2019 | B6: =tab!B6 -> = | C6: =tab!C6 -> Adições | E6: =SUM(E7:E19) -> 600 | F6: =SUM(F7:F19) -> 600
A7: 2020 | B7: =tab!B7 -> + | C7: =tab!C7 -> Ajustes Devedores de Qualquer Natureza | E7: =HLOOKUP(E$4,tab!$E$4:$P$49,MATCH($C7,$C$4:$C$49,0),0) -> 0 | F7: =HLOOKUP(F$4,tab!$E$4:$P$49,MATCH($C7,$C$4:$C$49,0),0) -> 0
A8: 2021 | B8: =tab!B8 -> + | C8: =tab!C8 -> Despesas de Variação Cambial | E8: =HLOOKUP(E$4,tab!$E$4:$P$49,MATCH($C8,$C$4:$C$49,0),0) -> 0 | F8: =HLOOKUP(F$4,tab!$E$4:$P$49,MATCH($C8,$C$4:$C$49,0),0) -> 0
A9: 2022 | B9: =tab!B9 -> + | C9: =tab!C9 -> Despesas Particulares dos Sócios e Dirigentes; | E9: =HLOOKUP(E$4,tab!$E$4:$P$49,MATCH($C9,$C$4:$C$49,0),0) -> 0 | F9: =HLOOKUP(F$4,tab!$E$4:$P$49,MATCH($C9,$C$4:$C$49,0),0) -> 0
A10: 2023 | B10: =tab!B10 -> + | C10: =tab!C10 -> Doações e Brindes; | E10: =HLOOKUP(E$4,tab!$E$4:$P$49,MATCH($C10,$C$4:$C$49,0),0) -> 100 | F10: =HLOOKUP(F$4,tab!$E$4:$P$49,MATCH($C10,$C$4:$C$49,0),0) -> 100
A11: 2024 | B11: =tab!B11 -> + | C11: =tab!C11 -> Impostos Não Pagos em Discussão Judicial; | E11: =HLOOKUP(E$4,tab!$E$4:$P$49,MATCH($C11,$C$4:$C$49,0),0) -> 0 | F11: =HLOOKUP(F$4,tab!$E$4:$P$49,MATCH($C11,$C$4:$C$49,0),0) -> 0
A12: 2025 | B12: =tab!B12 -> + | C12: =tab!C12 -> Impostos Não Pagos por Iniciativa da Empresa; | E12: =HLOOKUP(E$4,tab!$E$4:$P$49,MATCH($C12,$C$4:$C$49,0),0) -> 0 | F12: =HLOOKUP(F$4,tab!$E$4:$P$49,MATCH($C12,$C$4:$C$49,0),0) -> 0
A13: 2026 | B13: =tab!B13 -> + | C13: =tab!C13 -> Lucro Inflacionário apurado até 31/12/1995; | E13: =HLOOKUP(E$4,tab!$E$4:$P$49,MATCH($C13,$C$4:$C$49,0),0) -> 0 | F13: =HLOOKUP(F$4,tab!$E$4:$P$49,MATCH($C13,$C$4:$C$49,0),0) -> 0
A14: 2027 | B14: =tab!B14 -> + | C14: =tab!C14 -> Multas Contratuais | E14: =HLOOKUP(E$4,tab!$E$4:$P$49,MATCH($C14,$C$4:$C$49,0),0) -> 0 | F14: =HLOOKUP(F$4,tab!$E$4:$P$49,MATCH($C14,$C$4:$C$49,0),0) -> 0
A15: 2028 | B15: =tab!B15 -> + | C15: =tab!C15 -> Multas Punitivas (Transito, Imetro, Ibama, Multas sobre ação fiscal) | E15: =HLOOKUP(E$4,tab!$E$4:$P$49,MATCH($C15,$C$4:$C$49,0),0) -> 500 | F15: =HLOOKUP(F$4,tab!$E$4:$P$49,MATCH($C15,$C$4:$C$49,0),0) -> 500
A16: 2029 | B16: =tab!B16 -> + | C16: =tab!C16 -> Orçamentos, Pedidos e qualquer documento não idôneo; | E16: =HLOOKUP(E$4,tab!$E$4:$P$49,MATCH($C16,$C$4:$C$49,0),0) -> 0 | F16: =HLOOKUP(F$4,tab!$E$4:$P$49,MATCH($C16,$C$4:$C$49,0),0) -> 0
A17: 2030 | B17: =tab!B17 -> + | C17: =tab!C17 -> Provisões Indedutíveis (perdas, frete, propaganda) | E17: =HLOOKUP(E$4,tab!$E$4:$P$49,MATCH($C17,$C$4:$C$49,0),0) -> 0 | F17: =HLOOKUP(F$4,tab!$E$4:$P$49,MATCH($C17,$C$4:$C$49,0),0) -> 0
B18: =tab!B18 -> + | C18: =tab!C18 -> Recibos sem especificação da fonte recebedora; | E18: =HLOOKUP(E$4,tab!$E$4:$P$49,MATCH($C18,$C$4:$C$49,0),0) -> 0 | F18: =HLOOKUP(F$4,tab!$E$4:$P$49,MATCH($C18,$C$4:$C$49,0),0) -> 0
B19: =tab!B19 -> + | C19: =tab!C19 -> Verbas Rescisórias em desacordo com a legislação trabalhista vigente | E19: =HLOOKUP(E$4,tab!$E$4:$P$49,MATCH($C19,$C$4:$C$49,0),0) -> 0 | F19: =HLOOKUP(F$4,tab!$E$4:$P$49,MATCH($C19,$C$4:$C$49,0),0) -> 0
B20: =tab!B20 -> = | C20: =tab!C20 -> Exclusões | E20: =SUM(E21:E33) -> -1000 | F20: =SUM(F21:F33) -> -1000
B21: =tab!B21 -> - | C21: =tab!C21 -> Ajustes credores de qualquer natureza | E21: =HLOOKUP(E$4,tab!$E$4:$P$49,MATCH($C21,$C$4:$C$49,0),0) -> 0 | F21: =HLOOKUP(F$4,tab!$E$4:$P$49,MATCH($C21,$C$4:$C$49,0),0) -> 0
B22: =tab!B22 -> - | C22: =tab!C22 -> Decisão Favorável - Processos Judiciais Tributários | E22: =HLOOKUP(E$4,tab!$E$4:$P$49,MATCH($C22,$C$4:$C$49,0),0) -> 0 | F22: =HLOOKUP(F$4,tab!$E$4:$P$49,MATCH($C22,$C$4:$C$49,0),0) -> 0
B23: =tab!B23 -> - | C23: =tab!C23 -> Despesas de Ágios | E23: =HLOOKUP(E$4,tab!$E$4:$P$49,MATCH($C23,$C$4:$C$49,0),0) -> 0 | F23: =HLOOKUP(F$4,tab!$E$4:$P$49,MATCH($C23,$C$4:$C$49,0),0) -> 0
B24: =tab!B24 -> - | C24: =tab!C24 -> Distribuição de Lucros e Dividendos; | E24: =HLOOKUP(E$4,tab!$E$4:$P$49,MATCH($C24,$C$4:$C$49,0),0) -> 0 | F24: =HLOOKUP(F$4,tab!$E$4:$P$49,MATCH($C24,$C$4:$C$49,0),0) -> 0
B25: =tab!B25 -> - | C25: =tab!C25 -> Dividendos Coligadas e Controladas | E25: =HLOOKUP(E$4,tab!$E$4:$P$49,MATCH($C25,$C$4:$C$49,0),0) -> 0 | F25: =HLOOKUP(F$4,tab!$E$4:$P$49,MATCH($C25,$C$4:$C$49,0),0) -> 0
B26: =tab!B26 -> - | C26: =tab!C26 -> Pagamento de Impostos em Atraso por iniciativa da Empresa | E26: =HLOOKUP(E$4,tab!$E$4:$P$49,MATCH($C26,$C$4:$C$49,0),0) -> -1000 | F26: =HLOOKUP(F$4,tab!$E$4:$P$49,MATCH($C26,$C$4:$C$49,0),0) -> -1000
B27: =tab!B27 -> - | C27: =tab!C27 -> Pagamento de Impostos sobre discussão judicial, | E27: =HLOOKUP(E$4,tab!$E$4:$P$49,MATCH($C27,$C$4:$C$49,0),0) -> 0 | F27: =HLOOKUP(F$4,tab!$E$4:$P$49,MATCH($C27,$C$4:$C$49,0),0) -> 0
B28: =tab!B28 -> - | C28: =tab!C28 -> Receita de Variação Cambial | E28: =HLOOKUP(E$4,tab!$E$4:$P$49,MATCH($C28,$C$4:$C$49,0),0) -> 0 | F28: =HLOOKUP(F$4,tab!$E$4:$P$49,MATCH($C28,$C$4:$C$49,0),0) -> 0
B29: =tab!B29 -> - | C29: =tab!C29 -> Receitas Obtidas com Tributação Exclusiva ou Isenta de IR | E29: =HLOOKUP(E$4,tab!$E$4:$P$49,MATCH($C29,$C$4:$C$49,0),0) -> 0 | F29: =HLOOKUP(F$4,tab!$E$4:$P$49,MATCH($C29,$C$4:$C$49,0),0) -> 0
B30: =tab!B30 -> - | C30: =tab!C30 -> Receitas que poderiam ser diferidas; | E30: =HLOOKUP(E$4,tab!$E$4:$P$49,MATCH($C30,$C$4:$C$49,0),0) -> 0 | F30: =HLOOKUP(F$4,tab!$E$4:$P$49,MATCH($C30,$C$4:$C$49,0),0) -> 0
B31: =tab!B31 -> - | C31: =tab!C31 -> Resultado Positivo de Equivalência Patrimonial | E31: =HLOOKUP(E$4,tab!$E$4:$P$49,MATCH($C31,$C$4:$C$49,0),0) -> 0 | F31: =HLOOKUP(F$4,tab!$E$4:$P$49,MATCH($C31,$C$4:$C$49,0),0) -> 0
B32: =tab!B32 -> - | C32: =tab!C32 -> Reversão de Provisões Indedutíveis | E32: =HLOOKUP(E$4,tab!$E$4:$P$49,MATCH($C32,$C$4:$C$49,0),0) -> 0 | F32: =HLOOKUP(F$4,tab!$E$4:$P$49,MATCH($C32,$C$4:$C$49,0),0) -> 0
B33: =tab!B33 -> - | C33: =tab!C33 -> Vendas Não Expedidas do Período | E33: =HLOOKUP(E$4,tab!$E$4:$P$49,MATCH($C33,$C$4:$C$49,0),0) -> 0 | F33: =HLOOKUP(F$4,tab!$E$4:$P$49,MATCH($C33,$C$4:$C$49,0),0) -> 0
B34: =tab!B34 -> = | C34: =tab!C34 -> Base de Cálculo | E34: =SUM(E5,E6,E20) -> 600 | F34: =SUM(F5,F6,F20) -> 25600
B35: =tab!B35 -> = | C35: =tab!C35 -> Saldo Prejuízo Fiscal | E35: =tab!E35 -> 45000 | F35: =SUM(E35:E36) -> 44820
B36: =tab!B36 -> % | C36: =tab!C36 -> Compensação de Prejuízo Fiscal | D36: =tab!D36 -> 0.3 | E36: =-IF(AND(E35>0,E34*$D$36<E35),E34*$D$36,E35) -> -180 | F36: =-IF(AND(F35>0,F34*$D$36<F35),F34*$D$36,F35) -> -7680
B37: =tab!B37 -> % | C37: =tab!C37 -> Adicional de Imposto de Renda | D37: =tab!D37 -> 0.1 | E37: =HLOOKUP($E$4,INDIRECT($E$4&"!$E$4:$O$49"),MATCH(C37,INDIRECT($E$4&"!$C$4:$C$49"),0),0) -> 0 | F37: =IF(SUM(F34,F36)>20000*$A$4,(SUM(F34,F36)-20000*$A$4)*$D$37,0) -> 0
B38: =tab!B38 -> % | C38: =tab!C38 -> Imposto de Renda | D38: =tab!D38 -> 0.15 | E38: =SUM(E34,E36)*$D$38 -> 63 | F38: =SUM(F34,F36)*$D$38 -> 2688
B39: =tab!B39 -> % | C39: =tab!C39 -> Contribuição Social | D39: =tab!D39 -> 0.09 | E39: =SUM(E34,E36)*$D$39 -> 37.8 | F39: =SUM(F34,F36)*$D$39 -> 1612.8
B40: =tab!B40 -> = | C40: =tab!C40 -> Compensações | E40: =SUM(E42:E47) -> -3600 | F40: =SUM(F42:F47) -> -3600
B41: =tab!B41 -> - | C41: =tab!C41 -> IR Base Negativa Exercícios Anteriores | D41: =LEFT(C41,2) -> IR | E41: =HLOOKUP(E$4,tab!$E$4:$P$49,MATCH($C41,$C$4:$C$49,0),0) -> 0 | F41: =HLOOKUP(F$4,tab!$E$4:$P$49,MATCH($C41,$C$4:$C$49,0),0) -> 0
B42: =tab!B42 -> - | C42: =tab!C42 -> IR s/ Aplicações Financeiras | D42: =LEFT(C42,2) -> IR | E42: =HLOOKUP(E$4,tab!$E$4:$P$49,MATCH($C42,$C$4:$C$49,0),0) -> -100 | F42: =HLOOKUP(F$4,tab!$E$4:$P$49,MATCH($C42,$C$4:$C$49,0),0) -> -100
...

Sheet mar
B3: 2018
A4: 3 | B4: # | C4: Parâmetros | D4: % | E4: Jan | F4: Fev | G4: Mar | H4: Abr | I4: Mai | J4: Jun | K4: Jul | L4: Ago | M4: Set | N4: Out | O4: Nov | P4: Dez
A5: 2018 | B5: =tab!B5 -> = | C5: =tab!C5 -> Lucro Acumulado | E5: =HLOOKUP(E$4,tab!$E$4:$P$33,MATCH($C5,$C$4:$C$33,0),0) -> 1000 | F5: =HLOOKUP(F$4,tab!$E$4:$P$33,MATCH($C5,$C$4:$C$33,0),0) -> 26000 | G5: =HLOOKUP(G$4,tab!$E$4:$P$33,MATCH($C5,$C$4:$C$33,0),0) -> 51000
A6: 2019 | B6: =tab!B6 -> = | C6: =tab!C6 -> Adições | E6: =SUM(E7:E19) -> 600 | F6: =SUM(F7:F19) -> 600 | G6: =SUM(G7:G19) -> 600
A7: 2020 | B7: =tab!B7 -> + | C7: =tab!C7 -> Ajustes Devedores de Qualquer Natureza | E7: =HLOOKUP(E$4,tab!$E$4:$P$49,MATCH($C7,$C$4:$C$49,0),0) -> 0 | F7: =HLOOKUP(F$4,tab!$E$4:$P$49,MATCH($C7,$C$4:$C$49,0),0) -> 0 | G7: =HLOOKUP(G$4,tab!$E$4:$P$49,MATCH($C7,$C$4:$C$49,0),0) -> 0
A8: 2021 | B8: =tab!B8 -> + | C8: =tab!C8 -> Despesas de Variação Cambial | E8: =HLOOKUP(E$4,tab!$E$4:$P$49,MATCH($C8,$C$4:$C$49,0),0) -> 0 | F8: =HLOOKUP(F$4,tab!$E$4:$P$49,MATCH($C8,$C$4:$C$49,0),0) -> 0 | G8: =HLOOKUP(G$4,tab!$E$4:$P$49,MATCH($C8,$C$4:$C$49,0),0) -> 0
A9: 2022 | B9: =tab!B9 -> + | C9: =tab!C9 -> Despesas Particulares dos Sócios e Dirigentes; | E9: =HLOOKUP(E$4,tab!$E$4:$P$49,MATCH($C9,$C$4:$C$49,0),0) -> 0 | F9: =HLOOKUP(F$4,tab!$E$4:$P$49,MATCH($C9,$C$4:$C$49,0),0) -> 0 | G9: =HLOOKUP(G$4,tab!$E$4:$P$49,MATCH($C9,$C$4:$C$49,0),0) -> 0
A10: 2023 | B10: =tab!B10 -> + | C10: =tab!C10 -> Doações e Brindes; | E10: =HLOOKUP(E$4,tab!$E$4:$P$49,MATCH($C10,$C$4:$C$49,0),0) -> 100 | F10: =HLOOKUP(F$4,tab!$E$4:$P$49,MATCH($C10,$C$4:$C$49,0),0) -> 100 | G10: =HLOOKUP(G$4,tab!$E$4:$P$49,MATCH($C10,$C$4:$C$49,0),0) -> 100
A11: 2024 | B11: =tab!B11 -> + | C11: =tab!C11 -> Impostos Não Pagos em Discussão Judicial; | E11: =HLOOKUP(E$4,tab!$E$4:$P$49,MATCH($C11,$C$4:$C$49,0),0) -> 0 | F11: =HLOOKUP(F$4,tab!$E$4:$P$49,MATCH($C11,$C$4:$C$49,0),0) -> 0 | G11: =HLOOKUP(G$4,tab!$E$4:$P$49,MATCH($C11,$C$4:$C$49,0),0) -> 0
A12: 2025 | B12: =tab!B12 -> + | C12: =tab!C12 -> Impostos Não Pagos por Iniciativa da Empresa; | E12: =HLOOKUP(E$4,tab!$E$4:$P$49,MATCH($C12,$C$4:$C$49,0),0) -> 0 | F12: =HLOOKUP(F$4,tab!$E$4:$P$49,MATCH($C12,$C$4:$C$49,0),0) -> 0 | G12: =HLOOKUP(G$4,tab!$E$4:$P$49,MATCH($C12,$C$4:$C$49,0),0) -> 0
A13: 2026 | B13: =tab!B13 -> + | C13: =tab!C13 -> Lucro Inflacionário apurado até 31/12/1995; | E13: =HLOOKUP(E$4,tab!$E$4:$P$49,MATCH($C13,$C$4:$C$49,0),0) -> 0 | F13: =HLOOKUP(F$4,tab!$E$4:$P$49,MATCH($C13,$C$4:$C$49,0),0) -> 0 | G13: =HLOOKUP(G$4,tab!$E$4:$P$49,MATCH($C13,$C$4:$C$49,0),0) -> 0
A14: 2027 | B14: =tab!B14 -> + | C14: =tab!C14 -> Multas Contratuais | E14: =HLOOKUP(E$4,tab!$E$4:$P$49,MATCH($C14,$C$4:$C$49,0),0) -> 0 | F14: =HLOOKUP(F$4,tab!$E$4:$P$49,MATCH($C14,$C$4:$C$49,0),0) -> 0 | G14: =HLOOKUP(G$4,tab!$E$4:$P$49,MATCH($C14,$C$4:$C$49,0),0) -> 0
A15: 2028 | B15: =tab!B15 -> + | C15: =tab!C15 -> Multas Punitivas (Transito, Imetro, Ibama, Multas sobre ação fiscal) | E15: =HLOOKUP(E$4,tab!$E$4:$P$49,MATCH($C15,$C$4:$C$49,0),0) -> 500 | F15: =HLOOKUP(F$4,tab!$E$4:$P$49,MATCH($C15,$C$4:$C$49,0),0) -> 500 | G15: =HLOOKUP(G$4,tab!$E$4:$P$49,MATCH($C15,$C$4:$C$49,0),0) -> 500
A16: 2029 | B16: =tab!B16 -> + | C16: =tab!C16 -> Orçamentos, Pedidos e qualquer documento não idôneo; | E16: =HLOOKUP(E$4,tab!$E$4:$P$49,MATCH($C16,$C$4:$C$49,0),0) -> 0 | F16: =HLOOKUP(F$4,tab!$E$4:$P$49,MATCH($C16,$C$4:$C$49,0),0) -> 0 | G16: =HLOOKUP(G$4,tab!$E$4:$P$49,MATCH($C16,$C$4:$C$49,0),0) -> 0
A17: 2030 | B17: =tab!B17 -> + | C17: =tab!C17 -> Provisões Indedutíveis (perdas, frete, propaganda) | E17: =HLOOKUP(E$4,tab!$E$4:$P$49,MATCH($C17,$C$4:$C$49,0),0) -> 0 | F17: =HLOOKUP(F$4,tab!$E$4:$P$49,MATCH($C17,$C$4:$C$49,0),0) -> 0 | G17: =HLOOKUP(G$4,tab!$E$4:$P$49,MATCH($C17,$C$4:$C$49,0),0) -> 0
B18: =tab!B18 -> + | C18: =tab!C18 -> Recibos sem especificação da fonte recebedora; | E18: =HLOOKUP(E$4,tab!$E$4:$P$49,MATCH($C18,$C$4:$C$49,0),0) -> 0 | F18: =HLOOKUP(F$4,tab!$E$4:$P$49,MATCH($C18,$C$4:$C$49,0),0) -> 0 | G18: =HLOOKUP(G$4,tab!$E$4:$P$49,MATCH($C18,$C$4:$C$49,0),0) -> 0
B19: =tab!B19 -> + | C19: =tab!C19 -> Verbas Rescisórias em desacordo com a legislação trabalhista vigente | E19: =HLOOKUP(E$4,tab!$E$4:$P$49,MATCH($C19,$C$4:$C$49,0),0) -> 0 | F19: =HLOOKUP(F$4,tab!$E$4:$P$49,MATCH($C19,$C$4:$C$49,0),0) -> 0 | G19: =HLOOKUP(G$4,tab!$E$4:$P$49,MATCH($C19,$C$4:$C$49,0),0) -> 0
B20: =tab!B20 -> = | C20: =tab!C20 -> Exclusões | E20: =SUM(E21:E33) -> -1000 | F20: =SUM(F21:F33) -> -1000 | G20: =SUM(G21:G33) -> -1000
B21: =tab!B21 -> - | C21: =tab!C21 -> Ajustes credores de qualquer natureza | E21: =HLOOKUP(E$4,tab!$E$4:$P$49,MATCH($C21,$C$4:$C$49,0),0) -> 0 | F21: =HLOOKUP(F$4,tab!$E$4:$P$49,MATCH($C21,$C$4:$C$49,0),0) -> 0 | G21: =HLOOKUP(G$4,tab!$E$4:$P$49,MATCH($C21,$C$4:$C$49,0),0) -> 0
B22: =tab!B22 -> - | C22: =tab!C22 -> Decisão Favorável - Processos Judiciais Tributários | E22: =HLOOKUP(E$4,tab!$E$4:$P$49,MATCH($C22,$C$4:$C$49,0),0) -> 0 | F22: =HLOOKUP(F$4,tab!$E$4:$P$49,MATCH($C22,$C$4:$C$49,0),0) -> 0 | G22: =HLOOKUP(G$4,tab!$E$4:$P$49,MATCH($C22,$C$4:$C$49,0),0) -> 0
B23: =tab!B23 -> - | C23: =tab!C23 -> Despesas de Ágios | E23: =HLOOKUP(E$4,tab!$E$4:$P$49,MATCH($C23,$C$4:$C$49,0),0) -> 0 | F23: =HLOOKUP(F$4,tab!$E$4:$P$49,MATCH($C23,$C$4:$C$49,0),0) -> 0 | G23: =HLOOKUP(G$4,tab!$E$4:$P$49,MATCH($C23,$C$4:$C$49,0),0) -> 0
B24: =tab!B24 -> - | C24: =tab!C24 -> Distribuição de Lucros e Dividendos; | E24: =HLOOKUP(E$4,tab!$E$4:$P$49,MATCH($C24,$C$4:$C$49,0),0) -> 0 | F24: =HLOOKUP(F$4,tab!$E$4:$P$49,MATCH($C24,$C$4:$C$49,0),0) -> 0 | G24: =HLOOKUP(G$4,tab!$E$4:$P$49,MATCH($C24,$C$4:$C$49,0),0) -> 0
B25: =tab!B25 -> - | C25: =tab!C25 -> Dividendos Coligadas e Controladas | E25: =HLOOKUP(E$4,tab!$E$4:$P$49,MATCH($C25,$C$4:$C$49,0),0) -> 0 | F25: =HLOOKUP(F$4,tab!$E$4:$P$49,MATCH($C25,$C$4:$C$49,0),0) -> 0 | G25: =HLOOKUP(G$4,tab!$E$4:$P$49,MATCH($C25,$C$4:$C$49,0),0) -> 0
B26: =tab!B26 -> - | C26: =tab!C26 -> Pagamento de Impostos em Atraso por iniciativa da Empresa | E26: =HLOOKUP(E$4,tab!$E$4:$P$49,MATCH($C26,$C$4:$C$49,0),0) -> -1000 | F26: =HLOOKUP(F$4,tab!$E$4:$P$49,MATCH($C26,$C$4:$C$49,0),0) -> -1000 | G26: =HLOOKUP(G$4,tab!$E$4:$P$49,MATCH($C26,$C$4:$C$49,0),0) -> -1000
B27: =tab!B27 -> - | C27: =tab!C27 -> Pagamento de Impostos sobre discussão judicial, | E27: =HLOOKUP(E$4,tab!$E$4:$P$49,MATCH($C27,$C$4:$C$49,0),0) -> 0 | F27: =HLOOKUP(F$4,tab!$E$4:$P$49,MATCH($C27,$C$4:$C$49,0),0) -> 0 | G27: =HLOOKUP(G$4,tab!$E$4:$P$49,MATCH($C27,$C$4:$C$49,0),0) -> 0
B28: =tab!B28 -> - | C28: =tab!C28 -> Receita de Variação Cambial | E28: =HLOOKUP(E$4,tab!$E$4:$P$49,MATCH($C28,$C$4:$C$49,0),0) -> 0 | F28: =HLOOKUP(F$4,tab!$E$4:$P$49,MATCH($C28,$C$4:$C$49,0),0) -> 0 | G28: =HLOOKUP(G$4,tab!$E$4:$P$49,MATCH($C28,$C$4:$C$49,0),0) -> 0
B29: =tab!B29 -> - | C29: =tab!C29 -> Receitas Obtidas com Tributação Exclusiva ou Isenta de IR | E29: =HLOOKUP(E$4,tab!$E$4:$P$49,MATCH($C29,$C$4:$C$49,0),0) -> 0 | F29: =HLOOKUP(F$4,tab!$E$4:$P$49,MATCH($C29,$C$4:$C$49,0),0) -> 0 | G29: =HLOOKUP(G$4,tab!$E$4:$P$49,MATCH($C29,$C$4:$C$49,0),0) -> 0
B30: =tab!B30 -> - | C30: =tab!C30 -> Receitas que poderiam ser diferidas; | E30: =HLOOKUP(E$4,tab!$E$4:$P$49,MATCH($C30,$C$4:$C$49,0),0) -> 0 | F30: =HLOOKUP(F$4,tab!$E$4:$P$49,MATCH($C30,$C$4:$C$49,0),0) -> 0 | G30: =HLOOKUP(G$4,tab!$E$4:$P$49,MATCH($C30,$C$4:$C$49,0),0) -> 0
B31: =tab!B31 -> - | C31: =tab!C31 -> Resultado Positivo de Equivalência Patrimonial | E31: =HLOOKUP(E$4,tab!$E$4:$P$49,MATCH($C31,$C$4:$C$49,0),0) -> 0 | F31: =HLOOKUP(F$4,tab!$E$4:$P$49,MATCH($C31,$C$4:$C$49,0),0) -> 0 | G31: =HLOOKUP(G$4,tab!$E$4:$P$49,MATCH($C31,$C$4:$C$49,0),0) -> 0
B32: =tab!B32 -> - | C32: =tab!C32 -> Reversão de Provisões Indedutíveis | E32: =HLOOKUP(E$4,tab!$E$4:$P$49,MATCH($C32,$C$4:$C$49,0),0) -> 0 | F32: =HLOOKUP(F$4,tab!$E$4:$P$49,MATCH($C32,$C$4:$C$49,0),0) -> 0 | G32: =HLOOKUP(G$4,tab!$E$4:$P$49,MATCH($C32,$C$4:$C$49,0),0) -> 0
B33: =tab!B33 -> - | C33: =tab!C33 -> Vendas Não Expedidas do Período | E33: =HLOOKUP(E$4,tab!$E$4:$P$49,MATCH($C33,$C$4:$C$49,0),0) -> 0 | F33: =HLOOKUP(F$4,tab!$E$4:$P$49,MATCH($C33,$C$4:$C$49,0),0) -> 0 | G33: =HLOOKUP(G$4,tab!$E$4:$P$49,MATCH($C33,$C$4:$C$49,0),0) -> 0
B34: =tab!B34 -> = | C34: =tab!C34 -> Base de Cálculo | E34: =SUM(E5,E6,E20) -> 600 | F34: =SUM(F5,F6,F20) -> 25600 | G34: =SUM(G5,G6,G20) -> 50600
B35: =tab!B35 -> = | C35: =tab!C35 -> Saldo Prejuízo Fiscal | E35: =tab!E35 -> 45000 | F35: =SUM(E35:E36) -> 44820 | G35: =SUM(F35:F36) -> 37140
B36: =tab!B36 -> % | C36: =tab!C36 -> Compensação de Prejuízo Fiscal | D36: =tab!D36 -> 0.3 | E36: =-IF(AND(E35>0,E34*$D$36<E35),E34*$D$36,E35) -> -180 | F36: =-IF(AND(F35>0,F34*$D$36<F35),F34*$D$36,F35) -> -7680 | G36: =-IF(AND(G35>0,G34*$D$36<G35),G34*$D$36,G35) -> -15180
B37: =tab!B37 -> % | C37: =tab!C37 -> Adicional de Imposto de Renda | D37: =tab!D37 -> 0.1 | E37: =HLOOKUP($E$4,INDIRECT($E$4&"!$E$4:$O$49"),MATCH(C37,INDIRECT($E$4&"!$C$4:$C$49"),0),0) -> 0 | F37: =IF(SUM(F34,F36)>20000*$A$4,(SUM(F34,F36)-20000*$A$4)*$D$37,0) -> 0 | G37: =IF(SUM(G34,G36)>20000*$A$4,(SUM(G34,G36)-20000*$A$4)*$D$37,0) -> 0
B38: =tab!B38 -> % | C38: =tab!C38 -> Imposto de Renda | D38: =tab!D38 -> 0.15 | E38: =SUM(E34,E36)*$D$38 -> 63 | F38: =SUM(F34,F36)*$D$38 -> 2688 | G38: =SUM(G34,G36)*$D$38 -> 5313
B39: =tab!B39 -> % | C39: =tab!C39 -> Contribuição Social | D39: =tab!D39 -> 0.09 | E39: =SUM(E34,E36)*$D$39 -> 37.8 | F39: =SUM(F34,F36)*$D$39 -> 1612.8 | G39: =SUM(G34,G36)*$D$39 -> 3187.8
B40: =tab!B40 -> = | C40: =tab!C40 -> Compensações | E40: =SUM(E42:E47) -> -3600 | F40: =SUM(F42:F47) -> -3600 | G40: =SUM(G42:G47) -> -4300.8
B41: =tab!B41 -> - | C41: =tab!C41 -> IR Base Negativa Exercícios Anteriores | D41: =LEFT(C41,2) -> IR | E41: =HLOOKUP(E$4,tab!$E$4:$P$49,MATCH($C41,$C$4:$C$49,0),0) -> 0 | F41: =HLOOKUP(F$4,tab!$E$4:$P$49,MATCH($C41,$C$4:$C$49,0),0) -> 0 | G41: =HLOOKUP(G$4,tab!$E$4:$P$49,MATCH($C41,$C$4:$C$49,0),0) -> 0
B42: =tab!B42 -> - | C42: =tab!C42 -> IR s/ Aplicações Financeiras | D42: =LEFT(C42,2) -> IR | E42: =HLOOKUP(E$4,tab!$E$4:$P$49,MATCH($C42,$C$4:$C$49,0),0) -> -100 | F42: =HLOOKUP(F$4,tab!$E$4:$P$49,MATCH($C42,$C$4:$C$49,0),0) -> -100 | G42: =HLOOKUP(G$4,tab!$E$4:$P$49,MATCH($C42,$C$4:$C$49,0),0) -> -100
...

Sheet abr
B3: 2018
A4: 4 | B4: # | C4: Parâmetros | D4: % | E4: Jan | F4: Fev | G4: Mar | H4: Abr | I4: Mai | J4: Jun | K4: Jul | L4: Ago | M4: Set | N4: Out | O4: Nov | P4: Dez
A5: 2018 | B5: =tab!B5 -> = | C5: =tab!C5 -> Lucro Acumulado | E5: =HLOOKUP(E$4,tab!$E$4:$P$33,MATCH($C5,$C$4:$C$33,0),0) -> 1000 | F5: =HLOOKUP(F$4,tab!$E$4:$P$33,MATCH($C5,$C$4:$C$33,0),0) -> 26000 | G5: =HLOOKUP(G$4,tab!$E$4:$P$33,MATCH($C5,$C$4:$C$33,0),0) -> 51000 | H5: =HLOOKUP(H$4,tab!$E$4:$P$33,MATCH($C5,$C$4:$C$33,0),0) -> 76000
A6: 2019 | B6: =tab!B6 -> = | C6: =tab!C6 -> Adições | E6: =SUM(E7:E19) -> 600 | F6: =SUM(F7:F19) -> 600 | G6: =SUM(G7:G19) -> 600 | H6: =SUM(H7:H19) -> 600
A7: 2020 | B7: =tab!B7 -> + | C7: =tab!C7 -> Ajustes Devedores de Qualquer Natureza | E7: =HLOOKUP(E$4,tab!$E$4:$P$49,MATCH($C7,$C$4:$C$49,0),0) -> 0 | F7: =HLOOKUP(F$4,tab!$E$4:$P$49,MATCH($C7,$C$4:$C$49,0),0) -> 0 | G7: =HLOOKUP(G$4,tab!$E$4:$P$49,MATCH($C7,$C$4:$C$49,0),0) -> 0 | H7: =HLOOKUP(H$4,tab!$E$4:$P$49,MATCH($C7,$C$4:$C$49,0),0) -> 0
A8: 2021 | B8: =tab!B8 -> + | C8: =tab!C8 -> Despesas de Variação Cambial | E8: =HLOOKUP(E$4,tab!$E$4:$P$49,MATCH($C8,$C$4:$C$49,0),0) -> 0 | F8: =HLOOKUP(F$4,tab!$E$4:$P$49,MATCH($C8,$C$4:$C$49,0),0) -> 0 | G8: =HLOOKUP(G$4,tab!$E$4:$P$49,MATCH($C8,$C$4:$C$49,0),0) -> 0 | H8: =HLOOKUP(H$4,tab!$E$4:$P$49,MATCH($C8,$C$4:$C$49,0),0) -> 0
A9: 2022 | B9: =tab!B9 -> + | C9: =tab!C9 -> Despesas Particulares dos Sócios e Dirigentes; | E9: =HLOOKUP(E$4,tab!$E$4:$P$49,MATCH($C9,$C$4:$C$49,0),0) -> 0 | F9: =HLOOKUP(F$4,tab!$E$4:$P$49,MATCH($C9,$C$4:$C$49,0),0) -> 0 | G9: =HLOOKUP(G$4,tab!$E$4:$P$49,MATCH($C9,$C$4:$C$49,0),0) -> 0 | H9: =HLOOKUP(H$4,tab!$E$4:$P$49,MATCH($C9,$C$4:$C$49,0),0) -> 0
A10: 2023 | B10: =tab!B10 -> + | C10: =tab!C10 -> Doações e Brindes; | E10: =HLOOKUP(E$4,tab!$E$4:$P$49,MATCH($C10,$C$4:$C$49,0),0) -> 100 | F10: =HLOOKUP(F$4,tab!$E$4:$P$49,MATCH($C10,$C$4:$C$49,0),0) -> 100 | G10: =HLOOKUP(G$4,tab!$E$4:$P$49,MATCH($C10,$C$4:$C$49,0),0) -> 100 | H10: =HLOOKUP(H$4,tab!$E$4:$P$49,MATCH($C10,$C$4:$C$49,0),0) -> 100
A11: 2024 | B11: =tab!B11 -> + | C11: =tab!C11 -> Impostos Não Pagos em Discussão Judicial; | E11: =HLOOKUP(E$4,tab!$E$4:$P$49,MATCH($C11,$C$4:$C$49,0),0) -> 0 | F11: =HLOOKUP(F$4,tab!$E$4:$P$49,MATCH($C11,$C$4:$C$49,0),0) -> 0 | G11: =HLOOKUP(G$4,tab!$E$4:$P$49,MATCH($C11,$C$4:$C$49,0),0) -> 0 | H11: =HLOOKUP(H$4,tab!$E$4:$P$49,MATCH($C11,$C$4:$C$49,0),0) -> 0
A12: 2025 | B12: =tab!B12 -> + | C12: =tab!C12 -> Impostos Não Pagos por Iniciativa da Empresa; | E12: =HLOOKUP(E$4,tab!$E$4:$P$49,MATCH($C12,$C$4:$C$49,0),0) -> 0 | F12: =HLOOKUP(F$4,tab!$E$4:$P$49,MATCH($C12,$C$4:$C$49,0),0) -> 0 | G12: =HLOOKUP(G$4,tab!$E$4:$P$49,MATCH($C12,$C$4:$C$49,0),0) -> 0 | H12: =HLOOKUP(H$4,tab!$E$4:$P$49,MATCH($C12,$C$4:$C$49,0),0) -> 0
A13: 2026 | B13: =tab!B13 -> + | C13: =tab!C13 -> Lucro Inflacionário apurado até 31/12/1995; | E13: =HLOOKUP(E$4,tab!$E$4:$P$49,MATCH($C13,$C$4:$C$49,0),0) -> 0 | F13: =HLOOKUP(F$4,tab!$E$4:$P$49,MATCH($C13,$C$4:$C$49,0),0) -> 0 | G13: =HLOOKUP(G$4,tab!$E$4:$P$49,MATCH($C13,$C$4:$C$49,0),0) -> 0 | H13: =HLOOKUP(H$4,tab!$E$4:$P$49,MATCH($C13,$C$4:$C$49,0),0) -> 0
A14: 2027 | B14: =tab!B14 -> + | C14: =tab!C14 -> Multas Contratuais | E14: =HLOOKUP(E$4,tab!$E$4:$P$49,MATCH($C14,$C$4:$C$49,0),0) -> 0 | F14: =HLOOKUP(F$4,tab!$E$4:$P$49,MATCH($C14,$C$4:$C$49,0),0) -> 0 | G14: =HLOOKUP(G$4,tab!$E$4:$P$49,MATCH($C14,$C$4:$C$49,0),0) -> 0 | H14: =HLOOKUP(H$4,tab!$E$4:$P$49,MATCH($C14,$C$4:$C$49,0),0) -> 0
A15: 2028 | B15: =tab!B15 -> + | C15: =tab!C15 -> Multas Punitivas (Transito, Imetro, Ibama, Multas sobre ação fiscal) | E15: =HLOOKUP(E$4,tab!$E$4:$P$49,MATCH($C15,$C$4:$C$49,0),0) -> 500 | F15: =HLOOKUP(F$4,tab!$E$4:$P$49,MATCH($C15,$C$4:$C$49,0),0) -> 500 | G15: =HLOOKUP(G$4,tab!$E$4:$P$49,MATCH($C15,$C$4:$C$49,0),0) -> 500 | H15: =HLOOKUP(H$4,tab!$E$4:$P$49,MATCH($C15,$C$4:$C$49,0),0) -> 500
A16: 2029 | B16: =tab!B16 -> + | C16: =tab!C16 -> Orçamentos, Pedidos e qualquer documento não idôneo; | E16: =HLOOKUP(E$4,tab!$E$4:$P$49,MATCH($C16,$C$4:$C$49,0),0) -> 0 | F16: =HLOOKUP(F$4,tab!$E$4:$P$49,MATCH($C16,$C$4:$C$49,0),0) -> 0 | G16: =HLOOKUP(G$4,tab!$E$4:$P$49,MATCH($C16,$C$4:$C$49,0),0) -> 0 | H16: =HLOOKUP(H$4,tab!$E$4:$P$49,MATCH($C16,$C$4:$C$49,0),0) -> 0
A17: 2030 | B17: =tab!B17 -> + | C17: =tab!C17 -> Provisões Indedutíveis (perdas, frete, propaganda) | E17: =HLOOKUP(E$4,tab!$E$4:$P$49,MATCH($C17,$C$4:$C$49,0),0) -> 0 | F17: =HLOOKUP(F$4,tab!$E$4:$P$49,MATCH($C17,$C$4:$C$49,0),0) -> 0 | G17: =HLOOKUP(G$4,tab!$E$4:$P$49,MATCH($C17,$C$4:$C$49,0),0) -> 0 | H17: =HLOOKUP(H$4,tab!$E$4:$P$49,MATCH($C17,$C$4:$C$49,0),0) -> 0
B18: =tab!B18 -> + | C18: =tab!C18 -> Recibos sem especificação da fonte recebedora; | E18: =HLOOKUP(E$4,tab!$E$4:$P$49,MATCH($C18,$C$4:$C$49,0),0) -> 0 | F18: =HLOOKUP(F$4,tab!$E$4:$P$49,MATCH($C18,$C$4:$C$49,0),0) -> 0 | G18: =HLOOKUP(G$4,tab!$E$4:$P$49,MATCH($C18,$C$4:$C$49,0),0) -> 0 | H18: =HLOOKUP(H$4,tab!$E$4:$P$49,MATCH($C18,$C$4:$C$49,0),0) -> 0
B19: =tab!B19 -> + | C19: =tab!C19 -> Verbas Rescisórias em desacordo com a legislação trabalhista vigente | E19: =HLOOKUP(E$4,tab!$E$4:$P$49,MATCH($C19,$C$4:$C$49,0),0) -> 0 | F19: =HLOOKUP(F$4,tab!$E$4:$P$49,MATCH($C19,$C$4:$C$49,0),0) -> 0 | G19: =HLOOKUP(G$4,tab!$E$4:$P$49,MATCH($C19,$C$4:$C$49,0),0) -> 0 | H19: =HLOOKUP(H$4,tab!$E$4:$P$49,MATCH($C19,$C$4:$C$49,0),0) -> 0
B20: =tab!B20 -> = | C20: =tab!C20 -> Exclusões | E20: =SUM(E21:E33) -> -1000 | F20: =SUM(F21:F33) -> -1000 | G20: =SUM(G21:G33) -> -1000 | H20: =SUM(H21:H33) -> -1000
B21: =tab!B21 -> - | C21: =tab!C21 -> Ajustes credores de qualquer natureza | E21: =HLOOKUP(E$4,tab!$E$4:$P$49,MATCH($C21,$C$4:$C$49,0),0) -> 0 | F21: =HLOOKUP(F$4,tab!$E$4:$P$49,MATCH($C21,$C$4:$C$49,0),0) -> 0 | G21: =HLOOKUP(G$4,tab!$E$4:$P$49,MATCH($C21,$C$4:$C$49,0),0) -> 0 | H21: =HLOOKUP(H$4,tab!$E$4:$P$49,MATCH($C21,$C$4:$C$49,0),0) -> 0
B22: =tab!B22 -> - | C22: =tab!C22 -> Decisão Favorável - Processos Judiciais Tributários | E22: =HLOOKUP(E$4,tab!$E$4:$P$49,MATCH($C22,$C$4:$C$49,0),0) -> 0 | F22: =HLOOKUP(F$4,tab!$E$4:$P$49,MATCH($C22,$C$4:$C$49,0),0) -> 0 | G22: =HLOOKUP(G$4,tab!$E$4:$P$49,MATCH($C22,$C$4:$C$49,0),0) -> 0 | H22: =HLOOKUP(H$4,tab!$E$4:$P$49,MATCH($C22,$C$4:$C$49,0),0) -> 0
B23: =tab!B23 -> - | C23: =tab!C23 -> Despesas de Ágios | E23: =HLOOKUP(E$4,tab!$E$4:$P$49,MATCH($C23,$C$4:$C$49,0),0) -> 0 | F23: =HLOOKUP(F$4,tab!$E$4:$P$49,MATCH($C23,$C$4:$C$49,0),0) -> 0 | G23: =HLOOKUP(G$4,tab!$E$4:$P$49,MATCH($C23,$C$4:$C$49,0),0) -> 0 | H23: =HLOOKUP(H$4,tab!$E$4:$P$49,MATCH($C23,$C$4:$C$49,0),0) -> 0
B24: =tab!B24 -> - | C24: =tab!C24 -> Distribuição de Lucros e Dividendos; | E24: =HLOOKUP(E$4,tab!$E$4:$P$49,MATCH($C24,$C$4:$C$49,0),0) -> 0 | F24: =HLOOKUP(F$4,tab!$E$4:$P$49,MATCH($C24,$C$4:$C$49,0),0) -> 0 | G24: =HLOOKUP(G$4,tab!$E$4:$P$49,MATCH($C24,$C$4:$C$49,0),0) -> 0 | H24: =HLOOKUP(H$4,tab!$E$4:$P$49,MATCH($C24,$C$4:$C$49,0),0) -> 0
B25: =tab!B25 -> - | C25: =tab!C25 -> Dividendos Coligadas e Controladas | E25: =HLOOKUP(E$4,tab!$E$4:$P$49,MATCH($C25,$C$4:$C$49,0),0) -> 0 | F25: =HLOOKUP(F$4,tab!$E$4:$P$49,MATCH($C25,$C$4:$C$49,0),0) -> 0 | G25: =HLOOKUP(G$4,tab!$E$4:$P$49,MATCH($C25,$C$4:$C$49,0),0) -> 0 | H25: =HLOOKUP(H$4,tab!$E$4:$P$49,MATCH($C25,$C$4:$C$49,0),0) -> 0
B26: =tab!B26 -> - | C26: =tab!C26 -> Pagamento de Impostos em Atraso por iniciativa da Empresa | E26: =HLOOKUP(E$4,tab!$E$4:$P$49,MATCH($C26,$C$4:$C$49,0),0) -> -1000 | F26: =HLOOKUP(F$4,tab!$E$4:$P$49,MATCH($C26,$C$4:$C$49,0),0) -> -1000 | G26: =HLOOKUP(G$4,tab!$E$4:$P$49,MATCH($C26,$C$4:$C$49,0),0) -> -1000 | H26: =HLOOKUP(H$4,tab!$E$4:$P$49,MATCH($C26,$C$4:$C$49,0),0) -> -1000
B27: =tab!B27 -> - | C27: =tab!C27 -> Pagamento de Impostos sobre discussão judicial, | E27: =HLOOKUP(E$4,tab!$E$4:$P$49,MATCH($C27,$C$4:$C$49,0),0) -> 0 | F27: =HLOOKUP(F$4,tab!$E$4:$P$49,MATCH($C27,$C$4:$C$49,0),0) -> 0 | G27: =HLOOKUP(G$4,tab!$E$4:$P$49,MATCH($C27,$C$4:$C$49,0),0) -> 0 | H27: =HLOOKUP(H$4,tab!$E$4:$P$49,MATCH($C27,$C$4:$C$49,0),0) -> 0
B28: =tab!B28 -> - | C28: =tab!C28 -> Receita de Variação Cambial | E28: =HLOOKUP(E$4,tab!$E$4:$P$49,MATCH($C28,$C$4:$C$49,0),0) -> 0 | F28: =HLOOKUP(F$4,tab!$E$4:$P$49,MATCH($C28,$C$4:$C$49,0),0) -> 0 | G28: =HLOOKUP(G$4,tab!$E$4:$P$49,MATCH($C28,$C$4:$C$49,0),0) -> 0 | H28: =HLOOKUP(H$4,tab!$E$4:$P$49,MATCH($C28,$C$4:$C$49,0),0) -> 0
B29: =tab!B29 -> - | C29: =tab!C29 -> Receitas Obtidas com Tributação Exclusiva ou Isenta de IR | E29: =HLOOKUP(E$4,tab!$E$4:$P$49,MATCH($C29,$C$4:$C$49,0),0) -> 0 | F29: =HLOOKUP(F$4,tab!$E$4:$P$49,MATCH($C29,$C$4:$C$49,0),0) -> 0 | G29: =HLOOKUP(G$4,tab!$E$4:$P$49,MATCH($C29,$C$4:$C$49,0),0) -> 0 | H29: =HLOOKUP(H$4,tab!$E$4:$P$49,MATCH($C29,$C$4:$C$49,0),0) -> 0
B30: =tab!B30 -> - | C30: =tab!C30 -> Receitas que poderiam ser diferidas; | E30: =HLOOKUP(E$4,tab!$E$4:$P$49,MATCH($C30,$C$4:$C$49,0),0) -> 0 | F30: =HLOOKUP(F$4,tab!$E$4:$P$49,MATCH($C30,$C$4:$C$49,0),0) -> 0 | G30: =HLOOKUP(G$4,tab!$E$4:$P$49,MATCH($C30,$C$4:$C$49,0),0) -> 0 | H30: =HLOOKUP(H$4,tab!$E$4:$P$49,MATCH($C30,$C$4:$C$49,0),0) -> 0
B31: =tab!B31 -> - | C31: =tab!C31 -> Resultado Positivo de Equivalência Patrimonial | E31: =HLOOKUP(E$4,tab!$E$4:$P$49,MATCH($C31,$C$4:$C$49,0),0) -> 0 | F31: =HLOOKUP(F$4,tab!$E$4:$P$49,MATCH($C31,$C$4:$C$49,0),0) -> 0 | G31: =HLOOKUP(G$4,tab!$E$4:$P$49,MATCH($C31,$C$4:$C$49,0),0) -> 0 | H31: =HLOOKUP(H$4,tab!$E$4:$P$49,MATCH($C31,$C$4:$C$49,0),0) -> 0
B32: =tab!B32 -> - | C32: =tab!C32 -> Reversão de Provisões Indedutíveis | E32: =HLOOKUP(E$4,tab!$E$4:$P$49,MATCH($C32,$C$4:$C$49,0),0) -> 0 | F32: =HLOOKUP(F$4,tab!$E$4:$P$49,MATCH($C32,$C$4:$C$49,0),0) -> 0 | G32: =HLOOKUP(G$4,tab!$E$4:$P$49,MATCH($C32,$C$4:$C$49,0),0) -> 0 | H32: =HLOOKUP(H$4,tab!$E$4:$P$49,MATCH($C32,$C$4:$C$49,0),0) -> 0
B33: =tab!B33 -> - | C33: =tab!C33 -> Vendas Não Expedidas do Período | E33: =HLOOKUP(E$4,tab!$E$4:$P$49,MATCH($C33,$C$4:$C$49,0),0) -> 0 | F33: =HLOOKUP(F$4,tab!$E$4:$P$49,MATCH($C33,$C$4:$C$49,0),0) -> 0 | G33: =HLOOKUP(G$4,tab!$E$4:$P$49,MATCH($C33,$C$4:$C$49,0),0) -> 0 | H33: =HLOOKUP(H$4,tab!$E$4:$P$49,MATCH($C33,$C$4:$C$49,0),0) -> 0
B34: =tab!B34 -> = | C34: =tab!C34 -> Base de Cálculo | E34: =SUM(E5,E6,E20) -> 600 | F34: =SUM(F5,F6,F20) -> 25600 | G34: =SUM(G5,G6,G20) -> 50600 | H34: =SUM(H5,H6,H20) -> 75600
B35: =tab!B35 -> = | C35: =tab!C35 -> Saldo Prejuízo Fiscal | E35: =tab!E35 -> 45000 | F35: =SUM(E35:E36) -> 44820 | G35: =SUM(F35:F36) -> 37140 | H35: =SUM(G35:G36) -> 21960
B36: =tab!B36 -> % | C36: =tab!C36 -> Compensação de Prejuízo Fiscal | D36: =tab!D36 -> 0.3 | E36: =-IF(AND(E35>0,E34*$D$36<E35),E34*$D$36,E35) -> -180 | F36: =-IF(AND(F35>0,F34*$D$36<F35),F34*$D$36,F35) -> -7680 | G36: =-IF(AND(G35>0,G34*$D$36<G35),G34*$D$36,G35) -> -15180 | H36: =-IF(AND(H35>0,H34*$D$36<H35),H34*$D$36,H35) -> -21960
B37: =tab!B37 -> % | C37: =tab!C37 -> Adicional de Imposto de Renda | D37: =tab!D37 -> 0.1 | E37: =HLOOKUP($E$4,INDIRECT($E$4&"!$E$4:$O$49"),MATCH(C37,INDIRECT($E$4&"!$C$4:$C$49"),0),0) -> 0 | F37: =IF(SUM(F34,F36)>20000*$A$4,(SUM(F34,F36)-20000*$A$4)*$D$37,0) -> 0 | G37: =IF(SUM(G34,G36)>20000*$A$4,(SUM(G34,G36)-20000*$A$4)*$D$37,0) -> 0 | H37: =IF(SUM(H34,H36)>20000*$A$4,(SUM(H34,H36)-20000*$A$4)*$D$37,0) -> 0
B38: =tab!B38 -> % | C38: =tab!C38 -> Imposto de Renda | D38: =tab!D38 -> 0.15 | E38: =SUM(E34,E36)*$D$38 -> 63 | F38: =SUM(F34,F36)*$D$38 -> 2688 | G38: =SUM(G34,G36)*$D$38 -> 5313 | H38: =SUM(H34,H36)*$D$38 -> 8046
B39: =tab!B39 -> % | C39: =tab!C39 -> Contribuição Social | D39: =tab!D39 -> 0.09 | E39: =SUM(E34,E36)*$D$39 -> 37.8 | F39: =SUM(F34,F36)*$D$39 -> 1612.8 | G39: =SUM(G34,G36)*$D$39 -> 3187.8 | H39: =SUM(H34,H36)*$D$39 -> 4827.6
B40: =tab!B40 -> = | C40: =tab!C40 -> Compensações | E40: =SUM(E42:E47) -> -3600 | F40: =SUM(F42:F47) -> -3600 | G40: =SUM(G42:G47) -> -4300.8 | H40: =SUM(H42:H47) -> -8500.8
B41: =tab!B41 -> - | C41: =tab!C41 -> IR Base Negativa Exercícios Anteriores | D41: =LEFT(C41,2) -> IR | E41: =HLOOKUP(E$4,tab!$E$4:$P$49,MATCH($C41,$C$4:$C$49,0),0) -> 0 | F41: =HLOOKUP(F$4,tab!$E$4:$P$49,MATCH($C41,$C$4:$C$49,0),0) -> 0 | G41: =HLOOKUP(G$4,tab!$E$4:$P$49,MATCH($C41,$C$4:$C$49,0),0) -> 0 | H41: =HLOOKUP(H$4,tab!$E$4:$P$49,MATCH($C41,$C$4:$C$49,0),0) -> 0
B42: =tab!B42 -> - | C42: =tab!C42 -> IR s/ Aplicações Financeiras | D42: =LEFT(C42,2) -> IR | E42: =HLOOKUP(E$4,tab!$E$4:$P$49,MATCH($C42,$C$4:$C$49,0),0) -> -100 | F42: =HLOOKUP(F$4,tab!$E$4:$P$49,MATCH($C42,$C$4:$C$49,0),0) -> -100 | G42: =HLOOKUP(G$4,tab!$E$4:$P$49,MATCH($C42,$C$4:$C$49,0),0) -> -100 | H42: =HLOOKUP(H$4,tab!$E$4:$P$49,MATCH($C42,$C$4:$C$49,0),0) -> -100
...

Sheet mai
B3: 2018
A4: 5 | B4: # | C4: Parâmetros | D4: % | E4: Jan | F4: Fev | G4: Mar | H4: Abr | I4: Mai | J4: Jun | K4: Jul | L4: Ago | M4: Set | N4: Out | O4: Nov | P4: Dez
A5: 2018 | B5: =tab!B5 -> = | C5: =tab!C5 -> Lucro Acumulado | E5: =HLOOKUP(E$4,tab!$E$4:$P$33,MATCH($C5,$C$4:$C$33,0),0) -> 1000 | F5: =HLOOKUP(F$4,tab!$E$4:$P$33,MATCH($C5,$C$4:$C$33,0),0) -> 26000 | G5: =HLOOKUP(G$4,tab!$E$4:$P$33,MATCH($C5,$C$4:$C$33,0),0) -> 51000 | H5: =HLOOKUP(H$4,tab!$E$4:$P$33,MATCH($C5,$C$4:$C$33,0),0) -> 76000 | I5: =HLOOKUP(I$4,tab!$E$4:$P$33,MATCH($C5,$C$4:$C$33,0),0) -> 101000
A6: 2019 | B6: =tab!B6 -> = | C6: =tab!C6 -> Adições | E6: =SUM(E7:E19) -> 600 | F6: =SUM(F7:F19) -> 600 | G6: =SUM(G7:G19) -> 600 | H6: =SUM(H7:H19) -> 600 | I6: =SUM(I7:I19) -> 600
A7: 2020 | B7: =tab!B7 -> + | C7: =tab!C7 -> Ajustes Devedores de Qualquer Natureza | E7: =HLOOKUP(E$4,tab!$E$4:$P$49,MATCH($C7,$C$4:$C$49,0),0) -> 0 | F7: =HLOOKUP(F$4,tab!$E$4:$P$49,MATCH($C7,$C$4:$C$49,0),0) -> 0 | G7: =HLOOKUP(G$4,tab!$E$4:$P$49,MATCH($C7,$C$4:$C$49,0),0) -> 0 | H7: =HLOOKUP(H$4,tab!$E$4:$P$49,MATCH($C7,$C$4:$C$49,0),0) -> 0 | I7: =HLOOKUP(I$4,tab!$E$4:$P$49,MATCH($C7,$C$4:$C$49,0),0) -> 0
A8: 2021 | B8: =tab!B8 -> + | C8: =tab!C8 -> Despesas de Variação Cambial | E8: =HLOOKUP(E$4,tab!$E$4:$P$49,MATCH($C8,$C$4:$C$49,0),0) -> 0 | F8: =HLOOKUP(F$4,tab!$E$4:$P$49,MATCH($C8,$C$4:$C$49,0),0) -> 0 | G8: =HLOOKUP(G$4,tab!$E$4:$P$49,MATCH($C8,$C$4:$C$49,0),0) -> 0 | H8: =HLOOKUP(H$4,tab!$E$4:$P$49,MATCH($C8,$C$4:$C$49,0),0) -> 0 | I8: =HLOOKUP(I$4,tab!$E$4:$P$49,MATCH($C8,$C$4:$C$49,0),0) -> 0
A9: 2022 | B9: =tab!B9 -> + | C9: =tab!C9 -> Despesas Particulares dos Sócios e Dirigentes; | E9: =HLOOKUP(E$4,tab!$E$4:$P$49,MATCH($C9,$C$4:$C$49,0),0) -> 0 | F9: =HLOOKUP(F$4,tab!$E$4:$P$49,MATCH($C9,$C$4:$C$49,0),0) -> 0 | G9: =HLOOKUP(G$4,tab!$E$4:$P$49,MATCH($C9,$C$4:$C$49,0),0) -> 0 | H9: =HLOOKUP(H$4,tab!$E$4:$P$49,MATCH($C9,$C$4:$C$49,0),0) -> 0 | I9: =HLOOKUP(I$4,tab!$E$4:$P$49,MATCH($C9,$C$4:$C$49,0),0) -> 0
A10: 2023 | B10: =tab!B10 -> + | C10: =tab!C10 -> Doações e Brindes; | E10: =HLOOKUP(E$4,tab!$E$4:$P$49,MATCH($C10,$C$4:$C$49,0),0) -> 100 | F10: =HLOOKUP(F$4,tab!$E$4:$P$49,MATCH($C10,$C$4:$C$49,0),0) -> 100 | G10: =HLOOKUP(G$4,tab!$E$4:$P$49,MATCH($C10,$C$4:$C$49,0),0) -> 100 | H10: =HLOOKUP(H$4,tab!$E$4:$P$49,MATCH($C10,$C$4:$C$49,0),0) -> 100 | I10: =HLOOKUP(I$4,tab!$E$4:$P$49,MATCH($C10,$C$4:$C$49,0),0) -> 100
A11: 2024 | B11: =tab!B11 -> + | C11: =tab!C11 -> Impostos Não Pagos em Discussão Judicial; | E11: =HLOOKUP(E$4,tab!$E$4:$P$49,MATCH($C11,$C$4:$C$49,0),0) -> 0 | F11: =HLOOKUP(F$4,tab!$E$4:$P$49,MATCH($C11,$C$4:$C$49,0),0) -> 0 | G11: =HLOOKUP(G$4,tab!$E$4:$P$49,MATCH($C11,$C$4:$C$49,0),0) -> 0 | H11: =HLOOKUP(H$4,tab!$E$4:$P$49,MATCH($C11,$C$4:$C$49,0),0) -> 0 | I11: =HLOOKUP(I$4,tab!$E$4:$P$49,MATCH($C11,$C$4:$C$49,0),0) -> 0
A12: 2025 | B12: =tab!B12 -> + | C12: =tab!C12 -> Impostos Não Pagos por Iniciativa da Empresa; | E12: =HLOOKUP(E$4,tab!$E$4:$P$49,MATCH($C12,$C$4:$C$49,0),0) -> 0 | F12: =HLOOKUP(F$4,tab!$E$4:$P$49,MATCH($C12,$C$4:$C$49,0),0) -> 0 | G12: =HLOOKUP(G$4,tab!$E$4:$P$49,MATCH($C12,$C$4:$C$49,0),0) -> 0 | H12: =HLOOKUP(H$4,tab!$E$4:$P$49,MATCH($C12,$C$4:$C$49,0),0) -> 0 | I12: =HLOOKUP(I$4,tab!$E$4:$P$49,MATCH($C12,$C$4:$C$49,0),0) -> 0
A13: 2026 | B13: =tab!B13 -> + | C13: =tab!C13 -> Lucro Inflacionário apurado até 31/12/1995; | E13: =HLOOKUP(E$4,tab!$E$4:$P$49,MATCH($C13,$C$4:$C$49,0),0) -> 0 | F13: =HLOOKUP(F$4,tab!$E$4:$P$49,MATCH($C13,$C$4:$C$49,0),0) -> 0 | G13: =HLOOKUP(G$4,tab!$E$4:$P$49,MATCH($C13,$C$4:$C$49,0),0) -> 0 | H13: =HLOOKUP(H$4,tab!$E$4:$P$49,MATCH($C13,$C$4:$C$49,0),0) -> 0 | I13: =HLOOKUP(I$4,tab!$E$4:$P$49,MATCH($C13,$C$4:$C$49,0),0) -> 0
A14: 2027 | B14: =tab!B14 -> + | C14: =tab!C14 -> Multas Contratuais | E14: =HLOOKUP(E$4,tab!$E$4:$P$49,MATCH($C14,$C$4:$C$49,0),0) -> 0 | F14: =HLOOKUP(F$4,tab!$E$4:$P$49,MATCH($C14,$C$4:$C$49,0),0) -> 0 | G14: =HLOOKUP(G$4,tab!$E$4:$P$49,MATCH($C14,$C$4:$C$49,0),0) -> 0 | H14: =HLOOKUP(H$4,tab!$E$4:$P$49,MATCH($C14,$C$4:$C$49,0),0) -> 0 | I14: =HLOOKUP(I$4,tab!$E$4:$P$49,MATCH($C14,$C$4:$C$49,0),0) -> 0
A15: 2028 | B15: =tab!B15 -> + | C15: =tab!C15 -> Multas Punitivas (Transito, Imetro, Ibama, Multas sobre ação fiscal) | E15: =HLOOKUP(E$4,tab!$E$4:$P$49,MATCH($C15,$C$4:$C$49,0),0) -> 500 | F15: =HLOOKUP(F$4,tab!$E$4:$P$49,MATCH($C15,$C$4:$C$49,0),0) -> 500 | G15: =HLOOKUP(G$4,tab!$E$4:$P$49,MATCH($C15,$C$4:$C$49,0),0) -> 500 | H15: =HLOOKUP(H$4,tab!$E$4:$P$49,MATCH($C15,$C$4:$C$49,0),0) -> 500 | I15: =HLOOKUP(I$4,tab!$E$4:$P$49,MATCH($C15,$C$4:$C$49,0),0) -> 500
A16: 2029 | B16: =tab!B16 -> + | C16: =tab!C16 -> Orçamentos, Pedidos e qualquer documento não idôneo; | E16: =HLOOKUP(E$4,tab!$E$4:$P$49,MATCH($C16,$C$4:$C$49,0),0) -> 0 | F16: =HLOOKUP(F$4,tab!$E$4:$P$49,MATCH($C16,$C$4:$C$49,0),0) -> 0 | G16: =HLOOKUP(G$4,tab!$E$4:$P$49,MATCH($C16,$C$4:$C$49,0),0) -> 0 | H16: =HLOOKUP(H$4,tab!$E$4:$P$49,MATCH($C16,$C$4:$C$49,0),0) -> 0 | I16: =HLOOKUP(I$4,tab!$E$4:$P$49,MATCH($C16,$C$4:$C$49,0),0) -> 0
A17: 2030 | B17: =tab!B17 -> + | C17: =tab!C17 -> Provisões Indedutíveis (perdas, frete, propaganda) | E17: =HLOOKUP(E$4,tab!$E$4:$P$49,MATCH($C17,$C$4:$C$49,0),0) -> 0 | F17: =HLOOKUP(F$4,tab!$E$4:$P$49,MATCH($C17,$C$4:$C$49,0),0) -> 0 | G17: =HLOOKUP(G$4,tab!$E$4:$P$49,MATCH($C17,$C$4:$C$49,0),0) -> 0 | H17: =HLOOKUP(H$4,tab!$E$4:$P$49,MATCH($C17,$C$4:$C$49,0),0) -> 0 | I17: =HLOOKUP(I$4,tab!$E$4:$P$49,MATCH($C17,$C$4:$C$49,0),0) -> 0
B18: =tab!B18 -> + | C18: =tab!C18 -> Recibos sem especificação da fonte recebedora; | E18: =HLOOKUP(E$4,tab!$E$4:$P$49,MATCH($C18,$C$4:$C$49,0),0) -> 0 | F18: =HLOOKUP(F$4,tab!$E$4:$P$49,MATCH($C18,$C$4:$C$49,0),0) -> 0 | G18: =HLOOKUP(G$4,tab!$E$4:$P$49,MATCH($C18,$C$4:$C$49,0),0) -> 0 | H18: =HLOOKUP(H$4,tab!$E$4:$P$49,MATCH($C18,$C$4:$C$49,0),0) -> 0 | I18: =HLOOKUP(I$4,tab!$E$4:$P$49,MATCH($C18,$C$4:$C$49,0),0) -> 0
B19: =tab!B19 -> + | C19: =tab!C19 -> Verbas Rescisórias em desacordo com a legislação trabalhista vigente | E19: =HLOOKUP(E$4,tab!$E$4:$P$49,MATCH($C19,$C$4:$C$49,0),0) -> 0 | F19: =HLOOKUP(F$4,tab!$E$4:$P$49,MATCH($C19,$C$4:$C$49,0),0) -> 0 | G19: =HLOOKUP(G$4,tab!$E$4:$P$49,MATCH($C19,$C$4:$C$49,0),0) -> 0 | H19: =HLOOKUP(H$4,tab!$E$4:$P$49,MATCH($C19,$C$4:$C$49,0),0) -> 0 | I19: =HLOOKUP(I$4,tab!$E$4:$P$49,MATCH($C19,$C$4:$C$49,0),0) -> 0
B20: =tab!B20 -> = | C20: =tab!C20 -> Exclusões | E20: =SUM(E21:E33) -> -1000 | F20: =SUM(F21:F33) -> -1000 | G20: =SUM(G21:G33) -> -1000 | H20: =SUM(H21:H33) -> -1000 | I20: =SUM(I21:I33) -> -1000
B21: =tab!B21 -> - | C21: =tab!C21 -> Ajustes credores de qualquer natureza | E21: =HLOOKUP(E$4,tab!$E$4:$P$49,MATCH($C21,$C$4:$C$49,0),0) -> 0 | F21: =HLOOKUP(F$4,tab!$E$4:$P$49,MATCH($C21,$C$4:$C$49,0),0) -> 0 | G21: =HLOOKUP(G$4,tab!$E$4:$P$49,MATCH($C21,$C$4:$C$49,0),0) -> 0 | H21: =HLOOKUP(H$4,tab!$E$4:$P$49,MATCH($C21,$C$4:$C$49,0),0) -> 0 | I21: =HLOOKUP(I$4,tab!$E$4:$P$49,MATCH($C21,$C$4:$C$49,0),0) -> 0
B22: =tab!B22 -> - | C22: =tab!C22 -> Decisão Favorável - Processos Judiciais Tributários | E22: =HLOOKUP(E$4,tab!$E$4:$P$49,MATCH($C22,$C$4:$C$49,0),0) -> 0 | F22: =HLOOKUP(F$4,tab!$E$4:$P$49,MATCH($C22,$C$4:$C$49,0),0) -> 0 | G22: =HLOOKUP(G$4,tab!$E$4:$P$49,MATCH($C22,$C$4:$C$49,0),0) -> 0 | H22: =HLOOKUP(H$4,tab!$E$4:$P$49,MATCH($C22,$C$4:$C$49,0),0) -> 0 | I22: =HLOOKUP(I$4,tab!$E$4:$P$49,MATCH($C22,$C$4:$C$49,0),0) -> 0
B23: =tab!B23 -> - | C23: =tab!C23 -> Despesas de Ágios | E23: =HLOOKUP(E$4,tab!$E$4:$P$49,MATCH($C23,$C$4:$C$49,0),0) -> 0 | F23: =HLOOKUP(F$4,tab!$E$4:$P$49,MATCH($C23,$C$4:$C$49,0),0) -> 0 | G23: =HLOOKUP(G$4,tab!$E$4:$P$49,MATCH($C23,$C$4:$C$49,0),0) -> 0 | H23: =HLOOKUP(H$4,tab!$E$4:$P$49,MATCH($C23,$C$4:$C$49,0),0) -> 0 | I23: =HLOOKUP(I$4,tab!$E$4:$P$49,MATCH($C23,$C$4:$C$49,0),0) -> 0
B24: =tab!B24 -> - | C24: =tab!C24 -> Distribuição de Lucros e Dividendos; | E24: =HLOOKUP(E$4,tab!$E$4:$P$49,MATCH($C24,$C$4:$C$49,0),0) -> 0 | F24: =HLOOKUP(F$4,tab!$E$4:$P$49,MATCH($C24,$C$4:$C$49,0),0) -> 0 | G24: =HLOOKUP(G$4,tab!$E$4:$P$49,MATCH($C24,$C$4:$C$49,0),0) -> 0 | H24: =HLOOKUP(H$4,tab!$E$4:$P$49,MATCH($C24,$C$4:$C$49,0),0) -> 0 | I24: =HLOOKUP(I$4,tab!$E$4:$P$49,MATCH($C24,$C$4:$C$49,0),0) -> 0
B25: =tab!B25 -> - | C25: =tab!C25 -> Dividendos Coligadas e Controladas | E25: =HLOOKUP(E$4,tab!$E$4:$P$49,MATCH($C25,$C$4:$C$49,0),0) -> 0 | F25: =HLOOKUP(F$4,tab!$E$4:$P$49,MATCH($C25,$C$4:$C$49,0),0) -> 0 | G25: =HLOOKUP(G$4,tab!$E$4:$P$49,MATCH($C25,$C$4:$C$49,0),0) -> 0 | H25: =HLOOKUP(H$4,tab!$E$4:$P$49,MATCH($C25,$C$4:$C$49,0),0) -> 0 | I25: =HLOOKUP(I$4,tab!$E$4:$P$49,MATCH($C25,$C$4:$C$49,0),0) -> 0
B26: =tab!B26 -> - | C26: =tab!C26 -> Pagamento de Impostos em Atraso por iniciativa da Empresa | E26: =HLOOKUP(E$4,tab!$E$4:$P$49,MATCH($C26,$C$4:$C$49,0),0) -> -1000 | F26: =HLOOKUP(F$4,tab!$E$4:$P$49,MATCH($C26,$C$4:$C$49,0),0) -> -1000 | G26: =HLOOKUP(G$4,tab!$E$4:$P$49,MATCH($C26,$C$4:$C$49,0),0) -> -1000 | H26: =HLOOKUP(H$4,tab!$E$4:$P$49,MATCH($C26,$C$4:$C$49,0),0) -> -1000 | I26: =HLOOKUP(I$4,tab!$E$4:$P$49,MATCH($C26,$C$4:$C$49,0),0) -> -1000
B27: =tab!B27 -> - | C27: =tab!C27 -> Pagamento de Impostos sobre discussão judicial, | E27: =HLOOKUP(E$4,tab!$E$4:$P$49,MATCH($C27,$C$4:$C$49,0),0) -> 0 | F27: =HLOOKUP(F$4,tab!$E$4:$P$49,MATCH($C27,$C$4:$C$49,0),0) -> 0 | G27: =HLOOKUP(G$4,tab!$E$4:$P$49,MATCH($C27,$C$4:$C$49,0),0) -> 0 | H27: =HLOOKUP(H$4,tab!$E$4:$P$49,MATCH($C27,$C$4:$C$49,0),0) -> 0 | I27: =HLOOKUP(I$4,tab!$E$4:$P$49,MATCH($C27,$C$4:$C$49,0),0) -> 0
B28: =tab!B28 -> - | C28: =tab!C28 -> Receita de Variação Cambial | E28: =HLOOKUP(E$4,tab!$E$4:$P$49,MATCH($C28,$C$4:$C$49,0),0) -> 0 | F28: =HLOOKUP(F$4,tab!$E$4:$P$49,MATCH($C28,$C$4:$C$49,0),0) -> 0 | G28: =HLOOKUP(G$4,tab!$E$4:$P$49,MATCH($C28,$C$4:$C$49,0),0) -> 0 | H28: =HLOOKUP(H$4,tab!$E$4:$P$49,MATCH($C28,$C$4:$C$49,0),0) -> 0 | I28: =HLOOKUP(I$4,tab!$E$4:$P$49,MATCH($C28,$C$4:$C$49,0),0) -> 0
B29: =tab!B29 -> - | C29: =tab!C29 -> Receitas Obtidas com Tributação Exclusiva ou Isenta de IR | E29: =HLOOKUP(E$4,tab!$E$4:$P$49,MATCH($C29,$C$4:$C$49,0),0) -> 0 | F29: =HLOOKUP(F$4,tab!$E$4:$P$49,MATCH($C29,$C$4:$C$49,0),0) -> 0 | G29: =HLOOKUP(G$4,tab!$E$4:$P$49,MATCH($C29,$C$4:$C$49,0),0) -> 0 | H29: =HLOOKUP(H$4,tab!$E$4:$P$49,MATCH($C29,$C$4:$C$49,0),0) -> 0 | I29: =HLOOKUP(I$4,tab!$E$4:$P$49,MATCH($C29,$C$4:$C$49,0),0) -> 0
B30: =tab!B30 -> - | C30: =tab!C30 -> Receitas que poderiam ser diferidas; | E30: =HLOOKUP(E$4,tab!$E$4:$P$49,MATCH($C30,$C$4:$C$49,0),0) -> 0 | F30: =HLOOKUP(F$4,tab!$E$4:$P$49,MATCH($C30,$C$4:$C$49,0),0) -> 0 | G30: =HLOOKUP(G$4,tab!$E$4:$P$49,MATCH($C30,$C$4:$C$49,0),0) -> 0 | H30: =HLOOKUP(H$4,tab!$E$4:$P$49,MATCH($C30,$C$4:$C$49,0),0) -> 0 | I30: =HLOOKUP(I$4,tab!$E$4:$P$49,MATCH($C30,$C$4:$C$49,0),0) -> 0
B31: =tab!B31 -> - | C31: =tab!C31 -> Resultado Positivo de Equivalência Patrimonial | E31: =HLOOKUP(E$4,tab!$E$4:$P$49,MATCH($C31,$C$4:$C$49,0),0) -> 0 | F31: =HLOOKUP(F$4,tab!$E$4:$P$49,MATCH($C31,$C$4:$C$49,0),0) -> 0 | G31: =HLOOKUP(G$4,tab!$E$4:$P$49,MATCH($C31,$C$4:$C$49,0),0) -> 0 | H31: =HLOOKUP(H$4,tab!$E$4:$P$49,MATCH($C31,$C$4:$C$49,0),0) -> 0 | I31: =HLOOKUP(I$4,tab!$E$4:$P$49,MATCH($C31,$C$4:$C$49,0),0) -> 0
B32: =tab!B32 -> - | C32: =tab!C32 -> Reversão de Provisões Indedutíveis | E32: =HLOOKUP(E$4,tab!$E$4:$P$49,MATCH($C32,$C$4:$C$49,0),0) -> 0 | F32: =HLOOKUP(F$4,tab!$E$4:$P$49,MATCH($C32,$C$4:$C$49,0),0) -> 0 | G32: =HLOOKUP(G$4,tab!$E$4:$P$49,MATCH($C32,$C$4:$C$49,0),0) -> 0 | H32: =HLOOKUP(H$4,tab!$E$4:$P$49,MATCH($C32,$C$4:$C$49,0),0) -> 0 | I32: =HLOOKUP(I$4,tab!$E$4:$P$49,MATCH($C32,$C$4:$C$49,0),0) -> 0
B33: =tab!B33 -> - | C33: =tab!C33 -> Vendas Não Expedidas do Período | E33: =HLOOKUP(E$4,tab!$E$4:$P$49,MATCH($C33,$C$4:$C$49,0),0) -> 0 | F33: =HLOOKUP(F$4,tab!$E$4:$P$49,MATCH($C33,$C$4:$C$49,0),0) -> 0 | G33: =HLOOKUP(G$4,tab!$E$4:$P$49,MATCH($C33,$C$4:$C$49,0),0) -> 0 | H33: =HLOOKUP(H$4,tab!$E$4:$P$49,MATCH($C33,$C$4:$C$49,0),0) -> 0 | I33: =HLOOKUP(I$4,tab!$E$4:$P$49,MATCH($C33,$C$4:$C$49,0),0) -> 0
B34: =tab!B34 -> = | C34: =tab!C34 -> Base de Cálculo | E34: =SUM(E5,E6,E20) -> 600 | F34: =SUM(F5,F6,F20) -> 25600 | G34: =SUM(G5,G6,G20) -> 50600 | H34: =SUM(H5,H6,H20) -> 75600 | I34: =SUM(I5,I6,I20) -> 100600
B35: =tab!B35 -> = | C35: =tab!C35 -> Saldo Prejuízo Fiscal | E35: =tab!E35 -> 45000 | F35: =SUM(E35:E36) -> 44820 | G35: =SUM(F35:F36) -> 37140 | H35: =SUM(G35:G36) -> 21960 | I35: =SUM(H35:H36) -> 0
B36: =tab!B36 -> % | C36: =tab!C36 -> Compensação de Prejuízo Fiscal | D36: =tab!D36 -> 0.3 | E36: =-IF(AND(E35>0,E34*$D$36<E35),E34*$D$36,E35) -> -180 | F36: =-IF(AND(F35>0,F34*$D$36<F35),F34*$D$36,F35) -> -7680 | G36: =-IF(AND(G35>0,G34*$D$36<G35),G34*$D$36,G35) -> -15180 | H36: =-IF(AND(H35>0,H34*$D$36<H35),H34*$D$36,H35) -> -21960 | I36: =-IF(AND(I35>0,I34*$D$36<I35),I34*$D$36,I35) -> 0
B37: =tab!B37 -> % | C37: =tab!C37 -> Adicional de Imposto de Renda | D37: =tab!D37 -> 0.1 | E37: =HLOOKUP($E$4,INDIRECT($E$4&"!$E$4:$O$49"),MATCH(C37,INDIRECT($E$4&"!$C$4:$C$49"),0),0) -> 0 | F37: =IF(SUM(F34,F36)>20000*$A$4,(SUM(F34,F36)-20000*$A$4)*$D$37,0) -> 0 | G37: =IF(SUM(G34,G36)>20000*$A$4,(SUM(G34,G36)-20000*$A$4)*$D$37,0) -> 0 | H37: =IF(SUM(H34,H36)>20000*$A$4,(SUM(H34,H36)-20000*$A$4)*$D$37,0) -> 0 | I37: =IF(SUM(I34,I36)>20000*$A$4,(SUM(I34,I36)-20000*$A$4)*$D$37,0) -> 60
B38: =tab!B38 -> % | C38: =tab!C38 -> Imposto de Renda | D38: =tab!D38 -> 0.15 | E38: =SUM(E34,E36)*$D$38 -> 63 | F38: =SUM(F34,F36)*$D$38 -> 2688 | G38: =SUM(G34,G36)*$D$38 -> 5313 | H38: =SUM(H34,H36)*$D$38 -> 8046 | I38: =SUM(I34,I36)*$D$38 -> 15090
B39: =tab!B39 -> % | C39: =tab!C39 -> Contribuição Social | D39: =tab!D39 -> 0.09 | E39: =SUM(E34,E36)*$D$39 -> 37.8 | F39: =SUM(F34,F36)*$D$39 -> 1612.8 | G39: =SUM(G34,G36)*$D$39 -> 3187.8 | H39: =SUM(H34,H36)*$D$39 -> 4827.6 | I39: =SUM(I34,I36)*$D$39 -> 9054
B40: =tab!B40 -> = | C40: =tab!C40 -> Compensações | E40: =SUM(E42:E47) -> -3600 | F40: =SUM(F42:F47) -> -3600 | G40: =SUM(G42:G47) -> -4300.8 | H40: =SUM(H42:H47) -> -8500.8 | I40: =SUM(I42:I47) -> -12873.6
B41: =tab!B41 -> - | C41: =tab!C41 -> IR Base Negativa Exercícios Anteriores | D41: =LEFT(C41,2) -> IR | E41: =HLOOKUP(E$4,tab!$E$4:$P$49,MATCH($C41,$C$4:$C$49,0),0) -> 0 | F41: =HLOOKUP(F$4,tab!$E$4:$P$49,MATCH($C41,$C$4:$C$49,0),0) -> 0 | G41: =HLOOKUP(G$4,tab!$E$4:$P$49,MATCH($C41,$C$4:$C$49,0),0) -> 0 | H41: =HLOOKUP(H$4,tab!$E$4:$P$49,MATCH($C41,$C$4:$C$49,0),0) -> 0 | I41: =HLOOKUP(I$4,tab!$E$4:$P$49,MATCH($C41,$C$4:$C$49,0),0) -> 0
B42: =tab!B42 -> - | C42: =tab!C42 -> IR s/ Aplicações Financeiras | D42: =LEFT(C42,2) -> IR | E42: =HLOOKUP(E$4,tab!$E$4:$P$49,MATCH($C42,$C$4:$C$49,0),0) -> -100 | F42: =HLOOKUP(F$4,tab!$E$4:$P$49,MATCH($C42,$C$4:$C$49,0),0) -> -100 | G42: =HLOOKUP(G$4,tab!$E$4:$P$49,MATCH($C42,$C$4:$C$49,0),0) -> -100 | H42: =HLOOKUP(H$4,tab!$E$4:$P$49,MATCH($C42,$C$4:$C$49,0),0) -> -100 | I42: =HLOOKUP(I$4,tab!$E$4:$P$49,MATCH($C42,$C$4:$C$49,0),0) -> -100
...

Sheet jun
B3: 2018
A4: 6 | B4: # | C4: Parâmetros | D4: % | E4: Jan | F4: Fev | G4: Mar | H4: Abr | I4: Mai | J4: Jun | K4: Jul | L4: Ago | M4: Set | N4: Out | O4: Nov | P4: Dez
A5: 2018 | B5: =tab!B5 -> = | C5: =tab!C5 -> Lucro Acumulado | E5: =HLOOKUP(E$4,tab!$E$4:$P$33,MATCH($C5,$C$4:$C$33,0),0) -> 1000 | F5: =HLOOKUP(F$4,tab!$E$4:$P$33,MATCH($C5,$C$4:$C$33,0),0) -> 26000 | G5: =HLOOKUP(G$4,tab!$E$4:$P$33,MATCH($C5,$C$4:$C$33,0),0) -> 51000 | H5: =HLOOKUP(H$4,tab!$E$4:$P$33,MATCH($C5,$C$4:$C$33,0),0) -> 76000 | I5: =HLOOKUP(I$4,tab!$E$4:$P$33,MATCH($C5,$C$4:$C$33,0),0) -> 101000 | J5: =HLOOKUP(J$4,tab!$E$4:$P$33,MATCH($C5,$C$4:$C$33,0),0) -> 126000
A6: 2019 | B6: =tab!B6 -> = | C6: =tab!C6 -> Adições | E6: =SUM(E7:E19) -> 600 | F6: =SUM(F7:F19) -> 600 | G6: =SUM(G7:G19) -> 600 | H6: =SUM(H7:H19) -> 600 | I6: =SUM(I7:I19) -> 600 | J6: =SUM(J7:J19) -> 600
A7: 2020 | B7: =tab!B7 -> + | C7: =tab!C7 -> Ajustes Devedores de Qualquer Natureza | E7: =HLOOKUP(E$4,tab!$E$4:$P$49,MATCH($C7,$C$4:$C$49,0),0) -> 0 | F7: =HLOOKUP(F$4,tab!$E$4:$P$49,MATCH($C7,$C$4:$C$49,0),0) -> 0 | G7: =HLOOKUP(G$4,tab!$E$4:$P$49,MATCH($C7,$C$4:$C$49,0),0) -> 0 | H7: =HLOOKUP(H$4,tab!$E$4:$P$49,MATCH($C7,$C$4:$C$49,0),0) -> 0 | I7: =HLOOKUP(I$4,tab!$E$4:$P$49,MATCH($C7,$C$4:$C$49,0),0) -> 0 | J7: =HLOOKUP(J$4,tab!$E$4:$P$49,MATCH($C7,$C$4:$C$49,0),0) -> 0
A8: 2021 | B8: =tab!B8 -> + | C8: =tab!C8 -> Despesas de Variação Cambial | E8: =HLOOKUP(E$4,tab!$E$4:$P$49,MATCH($C8,$C$4:$C$49,0),0) -> 0 | F8: =HLOOKUP(F$4,tab!$E$4:$P$49,MATCH($C8,$C$4:$C$49,0),0) -> 0 | G8: =HLOOKUP(G$4,tab!$E$4:$P$49,MATCH($C8,$C$4:$C$49,0),0) -> 0 | H8: =HLOOKUP(H$4,tab!$E$4:$P$49,MATCH($C8,$C$4:$C$49,0),0) -> 0 | I8: =HLOOKUP(I$4,tab!$E$4:$P$49,MATCH($C8,$C$4:$C$49,0),0) -> 0 | J8: =HLOOKUP(J$4,tab!$E$4:$P$49,MATCH($C8,$C$4:$C$49,0),0) -> 0
A9: 2022 | B9: =tab!B9 -> + | C9: =tab!C9 -> Despesas Particulares dos Sócios e Dirigentes; | E9: =HLOOKUP(E$4,tab!$E$4:$P$49,MATCH($C9,$C$4:$C$49,0),0) -> 0 | F9: =HLOOKUP(F$4,tab!$E$4:$P$49,MATCH($C9,$C$4:$C$49,0),0) -> 0 | G9: =HLOOKUP(G$4,tab!$E$4:$P$49,MATCH($C9,$C$4:$C$49,0),0) -> 0 | H9: =HLOOKUP(H$4,tab!$E$4:$P$49,MATCH($C9,$C$4:$C$49,0),0) -> 0 | I9: =HLOOKUP(I$4,tab!$E$4:$P$49,MATCH($C9,$C$4:$C$49,0),0) -> 0 | J9: =HLOOKUP(J$4,tab!$E$4:$P$49,MATCH($C9,$C$4:$C$49,0),0) -> 0
A10: 2023 | B10: =tab!B10 -> + | C10: =tab!C10 -> Doações e Brindes; | E10: =HLOOKUP(E$4,tab!$E$4:$P$49,MATCH($C10,$C$4:$C$49,0),0) -> 100 | F10: =HLOOKUP(F$4,tab!$E$4:$P$49,MATCH($C10,$C$4:$C$49,0),0) -> 100 | G10: =HLOOKUP(G$4,tab!$E$4:$P$49,MATCH($C10,$C$4:$C$49,0),0) -> 100 | H10: =HLOOKUP(H$4,tab!$E$4:$P$49,MATCH($C10,$C$4:$C$49,0),0) -> 100 | I10: =HLOOKUP(I$4,tab!$E$4:$P$49,MATCH($C10,$C$4:$C$49,0),0) -> 100 | J10: =HLOOKUP(J$4,tab!$E$4:$P$49,MATCH($C10,$C$4:$C$49,0),0) -> 100
A11: 2024 | B11: =tab!B11 -> + | C11: =tab!C11 -> Impostos Não Pagos em Discussão Judicial; | E11: =HLOOKUP(E$4,tab!$E$4:$P$49,MATCH($C11,$C$4:$C$49,0),0) -> 0 | F11: =HLOOKUP(F$4,tab!$E$4:$P$49,MATCH($C11,$C$4:$C$49,0),0) -> 0 | G11: =HLOOKUP(G$4,tab!$E$4:$P$49,MATCH($C11,$C$4:$C$49,0),0) -> 0 | H11: =HLOOKUP(H$4,tab!$E$4:$P$49,MATCH($C11,$C$4:$C$49,0),0) -> 0 | I11: =HLOOKUP(I$4,tab!$E$4:$P$49,MATCH($C11,$C$4:$C$49,0),0) -> 0 | J11: =HLOOKUP(J$4,tab!$E$4:$P$49,MATCH($C11,$C$4:$C$49,0),0) -> 0
A12: 2025 | B12: =tab!B12 -> + | C12: =tab!C12 -> Impostos Não Pagos por Iniciativa da Empresa; | E12: =HLOOKUP(E$4,tab!$E$4:$P$49,MATCH($C12,$C$4:$C$49,0),0) -> 0 | F12: =HLOOKUP(F$4,tab!$E$4:$P$49,MATCH($C12,$C$4:$C$49,0),0) -> 0 | G12: =HLOOKUP(G$4,tab!$E$4:$P$49,MATCH($C12,$C$4:$C$49,0),0) -> 0 | H12: =HLOOKUP(H$4,tab!$E$4:$P$49,MATCH($C12,$C$4:$C$49,0),0) -> 0 | I12: =HLOOKUP(I$4,tab!$E$4:$P$49,MATCH($C12,$C$4:$C$49,0),0) -> 0 | J12: =HLOOKUP(J$4,tab!$E$4:$P$49,MATCH($C12,$C$4:$C$49,0),0) -> 0
A13: 2026 | B13: =tab!B13 -> + | C13: =tab!C13 -> Lucro Inflacionário apurado até 31/12/1995; | E13: =HLOOKUP(E$4,tab!$E$4:$P$49,MATCH($C13,$C$4:$C$49,0),0) -> 0 | F13: =HLOOKUP(F$4,tab!$E$4:$P$49,MATCH($C13,$C$4:$C$49,0),0) -> 0 | G13: =HLOOKUP(G$4,tab!$E$4:$P$49,MATCH($C13,$C$4:$C$49,0),0) -> 0 | H13: =HLOOKUP(H$4,tab!$E$4:$P$49,MATCH($C13,$C$4:$C$49,0),0) -> 0 | I13: =HLOOKUP(I$4,tab!$E$4:$P$49,MATCH($C13,$C$4:$C$49,0),0) -> 0 | J13: =HLOOKUP(J$4,tab!$E$4:$P$49,MATCH($C13,$C$4:$C$49,0),0) -> 0
A14: 2027 | B14: =tab!B14 -> + | C14: =tab!C14 -> Multas Contratuais | E14: =HLOOKUP(E$4,tab!$E$4:$P$49,MATCH($C14,$C$4:$C$49,0),0) -> 0 | F14: =HLOOKUP(F$4,tab!$E$4:$P$49,MATCH($C14,$C$4:$C$49,0),0) -> 0 | G14: =HLOOKUP(G$4,tab!$E$4:$P$49,MATCH($C14,$C$4:$C$49,0),0) -> 0 | H14: =HLOOKUP(H$4,tab!$E$4:$P$49,MATCH($C14,$C$4:$C$49,0),0) -> 0 | I14: =HLOOKUP(I$4,tab!$E$4:$P$49,MATCH($C14,$C$4:$C$49,0),0) -> 0 | J14: =HLOOKUP(J$4,tab!$E$4:$P$49,MATCH($C14,$C$4:$C$49,0),0) -> 0
