Workbook
Name ano: 'DIA UTEIS'!$H$3
Name CONSULTA: CONSULTAS!$B$4
Name Dias_úteis: 'DIA UTEIS'!$B$2:$M$6
Name Feriados: FERIADOS!$B$2:$M$10
Name Reduzido: 'DIAS FRACIONADOS'!$B$2:$M$12

Sheet MENU

Sheet RELATORIO
A1: ="Controle de Banco de Horas "&ano -> Controle de Banco de Horas 2019
A3: Chapa: | B3: =VLOOKUP(B4,'QUADRO DE FUNC'!B3:D20,2,FALSE) -> #N/A
A4: Servidor: | B4: Camila
B6: Jornada de trabalho / dia: | C6: =VLOOKUP(B4,carga_horaria[[NOME]:[CARGA HORARIA DIA]],2,FALSE) -> #N/A
B7: ="Saldo até 31/12/"&ano-1 -> Saldo até 31/12/2018 | C7: =VLOOKUP(B4,BANCO_HR[[NOME]:[SALDO ANTERIOR]],2,FALSE) -> #N/A
B9: Dias trabalhados | C9: Carga horária mensal | D9: Horas trabalhadas | E9: Saldo mensal | F9: Saldo total
A10: JANEIRO | B10: =HLOOKUP(A10,'DIA UTEIS'!$B$4:$M$6,3,FALSE) -> 21 | C10: =VLOOKUP($B$4,HR_A_FAZER[#All],2,FALSE) -> #N/A | D10: =VLOOKUP($B$4,HR_FEITAS[#All],2,FALSE) -> #N/A | E10: =IF(D10=0,"",ABS(D10-C10)) -> #N/A | F10: =IF(D10=0,"",IF(D10<C10,$C$7-E10,ABS($C$7+E10))) -> #N/A
A11: FEVEREIRO | B11: =HLOOKUP(A11,'DIA UTEIS'!$B$4:$M$6,3,FALSE) -> 20 | C11: 6.5625 | D11: =VLOOKUP($B$4,HR_FEITAS[#All],3,FALSE) -> #N/A | E11: =IF(D11=0,"",ABS(D11-C11)) -> #N/A | F11: =IF(D11=0,"",ABS($C$7+E11+F10)) -> #N/A
A12: MARÇO | B12: =HLOOKUP(A12,'DIA UTEIS'!$B$4:$M$6,3,FALSE) -> 18 | C12: =VLOOKUP($B$4,HR_A_FAZER[#All],4,FALSE) -> #N/A | D12: =VLOOKUP($B$4,HR_FEITAS[#All],4,FALSE) -> #N/A | E12: =IF(D12=0,"",ABS(D12-C12)) -> #N/A | F12: =IF(D12=0,"",ABS($C$7+E12+F11)) -> #N/A
A13: ABRIL | B13: =HLOOKUP(A13,'DIA UTEIS'!$B$4:$M$6,3,FALSE) -> 21 | C13: =VLOOKUP($B$4,HR_A_FAZER[#All],5,FALSE) -> #N/A | D13: =VLOOKUP($B$4,HR_FEITAS[#All],5,FALSE) -> #N/A | E13: =IF(D13=0,"",ABS(D13-C13)) -> #N/A | F13: =IF(D13=0,"",ABS($C$7+E13+F12)) -> #N/A
A14: MAIO | B14: =HLOOKUP(A14,'DIA UTEIS'!$B$4:$M$6,3,FALSE) -> 22 | C14: =VLOOKUP($B$4,HR_A_FAZER[#All],6,FALSE) -> #N/A | D14: =VLOOKUP($B$4,HR_FEITAS[#All],6,FALSE) -> #N/A | E14: =IF(D14=0,"",ABS(D14-C14)) -> #N/A | F14: =IF(D14=0,"",ABS($C$7+E14+F13)) -> #N/A
A15: JUNHO | B15: =HLOOKUP(A15,'DIA UTEIS'!$B$4:$M$6,3,FALSE) -> 19 | C15: =VLOOKUP($B$4,HR_A_FAZER[#All],7,FALSE) -> #N/A | D15: =VLOOKUP($B$4,HR_FEITAS[#All],7,FALSE) -> #N/A | E15: =IF(D15=0,"",ABS(D15-C15)) -> #N/A | F15: =IF(D15=0,"",ABS($C$7+E15+F14)) -> #N/A
A16: JULHO | B16: =HLOOKUP(A16,'DIA UTEIS'!$B$4:$M$6,3,FALSE) -> 22 | C16: =VLOOKUP($B$4,HR_A_FAZER[#All],8,FALSE) -> #N/A | D16: =VLOOKUP($B$4,HR_FEITAS[#All],8,FALSE) -> #N/A | E16: =IF(D16=0,"",ABS(D16-C16)) -> #N/A | F16: =IF(D16=0,"",ABS($C$7+E16+F15)) -> #N/A
A17: AGOSTO | B17: =HLOOKUP(A17,'DIA UTEIS'!$B$4:$M$6,3,FALSE) -> 22 | C17: =VLOOKUP($B$4,HR_A_FAZER[#All],9,FALSE) -> #N/A | D17: =VLOOKUP($B$4,HR_FEITAS[#All],9,FALSE) -> #N/A | E17: =IF(D17=0,"",ABS(D17-C17)) -> #N/A | F17: =IF(D17=0,"",ABS($C$7+E17+F16)) -> #N/A
A18: SETEMBRO | B18: =HLOOKUP(A18,'DIA UTEIS'!$B$4:$M$6,3,FALSE) -> 20 | C18: =VLOOKUP($B$4,HR_A_FAZER[#All],10,FALSE) -> #N/A | D18: =VLOOKUP($B$4,HR_FEITAS[#All],10,FALSE) -> #N/A | E18: =IF(D18=0,"",ABS(D18-C18)) -> #N/A | F18: =IF(D18=0,"",ABS($C$7+E18+F17)) -> #N/A
A19: OUTUBRO | B19: =HLOOKUP(A19,'DIA UTEIS'!$B$4:$M$6,3,FALSE) -> 23 | C19: =VLOOKUP($B$4,HR_A_FAZER[#All],11,FALSE) -> #N/A | D19: =VLOOKUP($B$4,HR_FEITAS[#All],11,FALSE) -> #N/A | E19: =IF(D19=0,"",ABS(D19-C19)) -> #N/A | F19: =IF(D19=0,"",ABS($C$7+E19+F18)) -> #N/A
A20: NOVEMBRO | B20: =HLOOKUP(A20,'DIA UTEIS'!$B$4:$M$6,3,FALSE) -> 20 | C20: =VLOOKUP($B$4,HR_A_FAZER[#All],12,FALSE) -> #N/A | D20: =VLOOKUP($B$4,HR_FEITAS[#All],12,FALSE) -> #N/A | E20: =IF(D20=0,"",ABS(D20-C20)) -> #N/A | F20: =IF(D20=0,"",ABS($C$7+E20+F19)) -> #N/A
A21: DEZEMBRO | B21: =HLOOKUP(A21,'DIA UTEIS'!$B$4:$M$6,3,FALSE) -> 21 | C21: =VLOOKUP($B$4,HR_A_FAZER[#All],13,FALSE) -> #N/A | D21: =VLOOKUP($B$4,HR_FEITAS[#All],13,FALSE) -> #N/A | E21: =IF(D21=0,"",ABS(D21-C21)) -> #N/A | F21: =IF(D21=0,"",ABS($C$7+E21+F20)) -> #N/A
D31: Franca, | E31: =TODAY() -> 43656
A36: =B4 -> Camila | D36: CHEFIA

Sheet CONSULTAS
B2: CONSULTA POR NOME
B3: FUNCIONARIO | C3: TOTAL DE HORAS | D3: COMPENSAÇÃO
B4: Camila | C4: =IF(B4="","",VLOOKUP(B4,Compensação[#All],2,FALSE)) -> #N/A | D4: =IF(B4="","",VLOOKUP(B4,Compensação[#All],3,FALSE)) -> #N/A

Sheet COMPENSAÇÃO
B2: COMPENSAÇÃO DE HORAS | I2: 1
B3: NOME | C3: BANCO DE HR. | D3: COMPENSAÇÃO
B4: =quadro_de_func[[#This Row],[NOME]] -> Amanda | C4: =SUM(BD!D4:O4) -> 0 | D4: =FLOOR(C4,1/$I$2*VLOOKUP(Compensação[[#This Row],[NOME]],carga_horaria[[NOME]:[CARGA HORARIA DIA]],2,FALSE))*3+(C4-FLOOR(C4,1/$I$2*VLOOKUP(Compensação[[#This Row],[NOME]],carga_horaria[[NOME]:[CARGA HORARIA DIA]],2,FALSE))) -> 0
B5: =quadro_de_func[[#This Row],[NOME]] -> Bruna | C5: =SUM(BD!D5:O5) -> 2.1729167 | D5: =FLOOR(C5,1/$I$2*VLOOKUP(Compensação[[#This Row],[NOME]],carga_horaria[[NOME]:[CARGA HORARIA DIA]],2,FALSE))*3+(C5-FLOOR(C5,1/$I$2*VLOOKUP(Compensação[[#This Row],[NOME]],carga_horaria[[NOME]:[CARGA HORARIA DIA]],2,FALSE))) -> 5.9229167
B6: =quadro_de_func[[#This Row],[NOME]] -> Daiani | C6: =SUM(BD!D6:O6) -> 6.8861111 | D6: =FLOOR(C6,1/$I$2*VLOOKUP(Compensação[[#This Row],[NOME]],carga_horaria[[NOME]:[CARGA HORARIA DIA]],2,FALSE))*3+(C6-FLOOR(C6,1/$I$2*VLOOKUP(Compensação[[#This Row],[NOME]],carga_horaria[[NOME]:[CARGA HORARIA DIA]],2,FALSE))) -> 20.011111
B7: =quadro_de_func[[#This Row],[NOME]] -> Érica | C7: =SUM(BD!D7:O7) -> 0 | D7: =FLOOR(C7,1/$I$2*VLOOKUP(Compensação[[#This Row],[NOME]],carga_horaria[[NOME]:[CARGA HORARIA DIA]],2,FALSE))*3+(C7-FLOOR(C7,1/$I$2*VLOOKUP(Compensação[[#This Row],[NOME]],carga_horaria[[NOME]:[CARGA HORARIA DIA]],2,FALSE))) -> 0
B8: =quadro_de_func[[#This Row],[NOME]] -> func 5 | C8: =SUM(BD!D8:O8) -> 0 | D8: =FLOOR(C8,1/$I$2*VLOOKUP(Compensação[[#This Row],[NOME]],carga_horaria[[NOME]:[CARGA HORARIA DIA]],2,FALSE))*3+(C8-FLOOR(C8,1/$I$2*VLOOKUP(Compensação[[#This Row],[NOME]],carga_horaria[[NOME]:[CARGA HORARIA DIA]],2,FALSE))) -> 0
B9: =quadro_de_func[[#This Row],[NOME]] -> func 6 | C9: =SUM(BD!D9:O9) -> 0 | D9: =FLOOR(C9,1/$I$2*VLOOKUP(Compensação[[#This Row],[NOME]],carga_horaria[[NOME]:[CARGA HORARIA DIA]],2,FALSE))*3+(C9-FLOOR(C9,1/$I$2*VLOOKUP(Compensação[[#This Row],[NOME]],carga_horaria[[NOME]:[CARGA HORARIA DIA]],2,FALSE))) -> 0
B10: =quadro_de_func[[#This Row],[NOME]] -> func 7 | C10: =SUM(BD!D10:O10) -> 0 | D10: =FLOOR(C10,1/$I$2*VLOOKUP(Compensação[[#This Row],[NOME]],carga_horaria[[NOME]:[CARGA HORARIA DIA]],2,FALSE))*3+(C10-FLOOR(C10,1/$I$2*VLOOKUP(Compensação[[#This Row],[NOME]],carga_horaria[[NOME]:[CARGA HORARIA DIA]],2,FALSE))) -> 0
B11: =quadro_de_func[[#This Row],[NOME]] -> func 8 | C11: =SUM(BD!D11:O11) -> 0 | D11: =FLOOR(C11,1/$I$2*VLOOKUP(Compensação[[#This Row],[NOME]],carga_horaria[[NOME]:[CARGA HORARIA DIA]],2,FALSE))*3+(C11-FLOOR(C11,1/$I$2*VLOOKUP(Compensação[[#This Row],[NOME]],carga_horaria[[NOME]:[CARGA HORARIA DIA]],2,FALSE))) -> 0
B12: =quadro_de_func[[#This Row],[NOME]] -> func 9 | C12: =SUM(BD!D12:O12) -> 0 | D12: =FLOOR(C12,1/$I$2*VLOOKUP(Compensação[[#This Row],[NOME]],carga_horaria[[NOME]:[CARGA HORARIA DIA]],2,FALSE))*3+(C12-FLOOR(C12,1/$I$2*VLOOKUP(Compensação[[#This Row],[NOME]],carga_horaria[[NOME]:[CARGA HORARIA DIA]],2,FALSE))) -> 0
B13: =quadro_de_func[[#This Row],[NOME]] -> func 10 | C13: =SUM(BD!D13:O13) -> 0 | D13: =FLOOR(C13,1/$I$2*VLOOKUP(Compensação[[#This Row],[NOME]],carga_horaria[[NOME]:[CARGA HORARIA DIA]],2,FALSE))*3+(C13-FLOOR(C13,1/$I$2*VLOOKUP(Compensação[[#This Row],[NOME]],carga_horaria[[NOME]:[CARGA HORARIA DIA]],2,FALSE))) -> 0
B14: =quadro_de_func[[#This Row],[NOME]] -> func 11 | C14: =SUM(BD!D14:O14) -> 0 | D14: =FLOOR(C14,1/$I$2*VLOOKUP(Compensação[[#This Row],[NOME]],carga_horaria[[NOME]:[CARGA HORARIA DIA]],2,FALSE))*3+(C14-FLOOR(C14,1/$I$2*VLOOKUP(Compensação[[#This Row],[NOME]],carga_horaria[[NOME]:[CARGA HORARIA DIA]],2,FALSE))) -> 0
B15: =quadro_de_func[[#This Row],[NOME]] -> func 12 | C15: =SUM(BD!D15:O15) -> 0 | D15: =FLOOR(C15,1/$I$2*VLOOKUP(Compensação[[#This Row],[NOME]],carga_horaria[[NOME]:[CARGA HORARIA DIA]],2,FALSE))*3+(C15-FLOOR(C15,1/$I$2*VLOOKUP(Compensação[[#This Row],[NOME]],carga_horaria[[NOME]:[CARGA HORARIA DIA]],2,FALSE))) -> 0
... B20: =quadro_de_func[[#This Row],[NOME]] -> func 17 | C20: =SUM(BD!D20:O20) -> 0 | D20: =FLOOR(C20,1/$I$2*VLOOKUP(Compensação[[#This Row],[NOME]],carga_horaria[[NOME]:[CARGA HORARIA DIA]],2,FALSE))*3+(C20-FLOOR(C20,1/$I$2*VLOOKUP(Compensação[[#This Row],[NOME]],carga_horaria[[NOME]:[CARGA HORARIA DIA]],2,FALSE))) -> 0

Sheet HR FEITAS
B2: HORAS FEITAS
B3: NOME | C3: JANEIRO | D3: FEVEREIRO | E3: MARÇO | F3: ABRIL | G3: MAIO | H3: JUNHO | I3: JULHO | J3: AGOSTO | K3: SETEMBRO | L3: OUTUBRO | M3: NOVEMBRO | N3: DEZEMBRO
B4: =quadro_de_func[[#This Row],[NOME]] -> Amanda
B5: =quadro_de_func[[#This Row],[NOME]] -> Bruna | D5: 6.8458333 | E5: 8.51875
B6: =quadro_de_func[[#This Row],[NOME]] -> Daiani | C6: 7.55 | D6: 7.1159722 | E6: 0.41666667
B7: =quadro_de_func[[#This Row],[NOME]] -> Érica
B8: =quadro_de_func[[#This Row],[NOME]] -> func 5
B9: =quadro_de_func[[#This Row],[NOME]] -> func 6
B10: =quadro_de_func[[#This Row],[NOME]] -> func 7
B11: =quadro_de_func[[#This Row],[NOME]] -> func 8
B12: =quadro_de_func[[#This Row],[NOME]] -> func 9
B13: =quadro_de_func[[#This Row],[NOME]] -> func 10
B14: =quadro_de_func[[#This Row],[NOME]] -> func 11
B15: =quadro_de_func[[#This Row],[NOME]] -> func 12
B16: =quadro_de_func[[#This Row],[NOME]] -> func 13
B17: =quadro_de_func[[#This Row],[NOME]] -> func 14
B18: =quadro_de_func[[#This Row],[NOME]] -> func 15
... B20: =quadro_de_func[[#This Row],[NOME]] -> func 17

Sheet HR À FAZER
B2: HORAS À FAZER
B3: NOME | C3: JANEIRO | D3: FEVEREIRO | E3: MARÇO | F3: ABRIL | G3: MAIO | H3: JUNHO | I3: JULHO | J3: AGOSTO | K3: SETEMBRO | L3: OUTUBRO | M3: NOVEMBRO | N3: DEZEMBRO
B4: =quadro_de_func[[#This Row],[NOME]] -> Amanda | C4: =IF(VLOOKUP($B4,quadro_de_func[#All],3,FALSE)="MENOR APRENDIZ",VLOOKUP($B4,carga_horaria[],2,FALSE)*(HLOOKUP(C$3,'DIA UTEIS'!$B$4:$M$6,3,FALSE)+COUNTA('DIAS FRACIONADOS'!$B$6:$B$12)),IF(VLOOKUP($B4,quadro_de_func[#All],3,FALSE)="ESTAGIÁRIO",((VLOOKUP($B4,carga_horaria[],2,FALSE)*HLOOKUP(C$3,'DIA UTEIS'!$B$4:$M$6,3,FALSE))-(HLOOKUP($B4,'EST. PROVAS'!$B$3:$Z$4,2,FALSE)*(VLOOKUP($B4,carga_horaria[],2,FALSE)/2)))+HLOOKUP(HR_A_FAZER[[#Headers],[JANEIRO]],'DIAS FRACIONADOS'!$B$3:$Y$4,2,FALSE),(VLOOKUP($B4,carga_horaria[],2,FALSE)*(HLOOKUP(C$3,'DIA UTEIS'!$B$4:$M$6,3,FALSE)))+HLOOKUP(HR_A_FAZER[[#Headers],[JANEIRO]],'DIAS FRACIONADOS'!$B$3:$Y$4,2,FALSE))) -> 7.8645833 | D4: =IF(VLOOKUP($B4,quadro_de_func[#All],3,FALSE)="MENOR APRENDIZ",VLOOKUP($B4,carga_horaria[],2,FALSE)*(HLOOKUP(D$3,'DIA UTEIS'!$B$4:$M$6,3,FALSE)+COUNTA('DIAS FRACIONADOS'!$B$6:$B$12)),IF(VLOOKUP($B4,quadro_de_func[#All],3,FALSE)="ESTAGIÁRIO",((VLOOKUP($B4,carga_horaria[],2,FALSE)*HLOOKUP(D$3,'DIA UTEIS'!$B$4:$M$6,3,FALSE))-(HLOOKUP($B4,'EST. PROVAS'!$B$3:$Z$4,2,FALSE)*(VLOOKUP($B4,carga_horaria[],2,FALSE)/2)))+HLOOKUP(HR_A_FAZER[[#Headers],[FEVEREIRO]],'DIAS FRACIONADOS'!$B$3:$Y$4,2,FALSE),(VLOOKUP($B4,carga_horaria[],2,FALSE)*(HLOOKUP(D$3,'DIA UTEIS'!$B$4:$M$6,3,FALSE)))+HLOOKUP(HR_A_FAZER[[#Headers],[FEVEREIRO]],'DIAS FRACIONADOS'!$B$3:$Y$4,2,FALSE))) -> 7.2916667 | E4: =IF(VLOOKUP($B4,quadro_de_func[#All],3,FALSE)="MENOR APRENDIZ",VLOOKUP($B4,carga_horaria[],2,FALSE)*(HLOOKUP(E$3,'DIA UTEIS'!$B$4:$M$6,3,FALSE)+COUNTA('DIAS FRACIONADOS'!$B$6:$B$12)),IF(VLOOKUP($B4,quadro_de_func[#All],3,FALSE)="ESTAGIÁRIO",((VLOOKUP($B4,carga_horaria[],2,FALSE)*HLOOKUP(E$3,'DIA UTEIS'!$B$4:$M$6,3,FALSE))-(HLOOKUP($B4,'EST. PROVAS'!$B$3:$Z$4,2,FALSE)*(VLOOKUP($B4,carga_horaria[],2,FALSE)/2)))+HLOOKUP(HR_A_FAZER[[#Headers],[MARÇO]],'DIAS FRACIONADOS'!$B$3:$Y$4,2,FALSE),(VLOOKUP($B4,carga_horaria[],2,FALSE)*(HLOOKUP(E$3,'DIA UTEIS'!$B$4:$M$6,3,FALSE)))+HLOOKUP(HR_A_FAZER[[#Headers],[MARÇO]],'DIAS FRACIONADOS'!$B$3:$Y$4,2,FALSE))) -> 6.8125 | F4: =IF(VLOOKUP($B4,quadro_de_func[#All],3,FALSE)="MENOR APRENDIZ",VLOOKUP($B4,carga_horaria[],2,FALSE)*(HLOOKUP(F$3,'DIA UTEIS'!$B$4:$M$6,3,FALSE)+COUNTA('DIAS FRACIONADOS'!$B$6:$B$12)),IF(VLOOKUP($B4,quadro_de_func[#All],3,FALSE)="ESTAGIÁRIO",((VLOOKUP($B4,carga_horaria[],2,FALSE)*HLOOKUP(F$3,'DIA UTEIS'!$B$4:$M$6,3,FALSE))-(HLOOKUP($B4,'EST. PROVAS'!$B$3:$Z$4,2,FALSE)*(VLOOKUP($B4,carga_horaria[],2,FALSE)/2)))+HLOOKUP(HR_A_FAZER[[#Headers],[ABRIL]],'DIAS FRACIONADOS'!$B$3:$Y$4,2,FALSE),(VLOOKUP($B4,carga_horaria[],2,FALSE)*(HLOOKUP(F$3,'DIA UTEIS'!$B$4:$M$6,3,FALSE)))+HLOOKUP(HR_A_FAZER[[#Headers],[ABRIL]],'DIAS FRACIONADOS'!$B$3:$Y$4,2,FALSE))) -> 7.65625 | G4: =IF(VLOOKUP($B4,quadro_de_func[#All],3,FALSE)="MENOR APRENDIZ",VLOOKUP($B4,carga_horaria[],2,FALSE)*(HLOOKUP(G$3,'DIA UTEIS'!$B$4:$M$6,3,FALSE)+COUNTA('DIAS FRACIONADOS'!$B$6:$B$12)),IF(VLOOKUP($B4,quadro_de_func[#All],3,FALSE)="ESTAGIÁRIO",((VLOOKUP($B4,carga_horaria[],2,FALSE)*HLOOKUP(G$3,'DIA UTEIS'!$B$4:$M$6,3,FALSE))-(HLOOKUP($B4,'EST. PROVAS'!$B$3:$Z$4,2,FALSE)*(VLOOKUP($B4,carga_horaria[],2,FALSE)/2)))+HLOOKUP(HR_A_FAZER[[#Headers],[MAIO]],'DIAS FRACIONADOS'!$B$3:$Y$4,2,FALSE),(VLOOKUP($B4,carga_horaria[],2,FALSE)*(HLOOKUP(G$3,'DIA UTEIS'!$B$4:$M$6,3,FALSE)))+HLOOKUP(HR_A_FAZER[[#Headers],[MAIO]],'DIAS FRACIONADOS'!$B$3:$Y$4,2,FALSE))) -> 8.0208333 | H4: =IF(VLOOKUP($B4,quadro_de_func[#All],3,FALSE)="MENOR APRENDIZ",VLOOKUP($B4,carga_horaria[],2,FALSE)*(HLOOKUP(H$3,'DIA UTEIS'!$B$4:$M$6,3,FALSE)+COUNTA('DIAS FRACIONADOS'!$B$6:$B$12)),IF(VLOOKUP($B4,quadro_de_func[#All],3,FALSE)="ESTAGIÁRIO",((VLOOKUP($B4,carga_horaria[],2,FALSE)*HLOOKUP(H$3,'DIA UTEIS'!$B$4:$M$6,3,FALSE))-(HLOOKUP($B4,'EST. PROVAS'!$B$3:$Z$4,2,FALSE)*(VLOOKUP($B4,carga_horaria[],2,FALSE)/2)))+HLOOKUP(HR_A_FAZER[[#Headers],[JUNHO]],'DIAS FRACIONADOS'!$B$3:$Y$4,2,FALSE),(VLOOKUP($B4,carga_horaria[],2,FALSE)*(HLOOKUP(H$3,'DIA UTEIS'!$B$4:$M$6,3,FALSE)))+HLOOKUP(HR_A_FAZER[[#Headers],[JUNHO]],'DIAS FRACIONADOS'!$B$3:$Y$4,2,FALSE))) -> 6.9270833 | I4: =IF(VLOOKUP($B4,quadro_de_func[#All],3,FALSE)="MENOR APRENDIZ",VLOOKUP($B4,carga_horaria[],2,FALSE)*(HLOOKUP(I$3,'DIA UTEIS'!$B$4:$M$6,3,FALSE)+COUNTA('DIAS FRACIONADOS'!$B$6:$B$12)),IF(VLOOKUP($B4,quadro_de_func[#All],3,FALSE)="ESTAGIÁRIO",((VLOOKUP($B4,carga_horaria[],2,FALSE)*HLOOKUP(I$3,'DIA UTEIS'!$B$4:$M$6,3,FALSE))-(HLOOKUP($B4,'EST. PROVAS'!$B$3:$Z$4,2,FALSE)*(VLOOKUP($B4,carga_horaria[],2,FALSE)/2)))+HLOOKUP(HR_A_FAZER[[#Headers],[JULHO]],'DIAS FRACIONADOS'!$B$3:$Y$4,2,FALSE),(VLOOKUP($B4,carga_horaria[],2,FALSE)*(HLOOKUP(I$3,'DIA UTEIS'!$B$4:$M$6,3,FALSE)))+HLOOKUP(HR_A_FAZER[[#Headers],[JULHO]],'DIAS FRACIONADOS'!$B$3:$Y$4,2,FALSE))) -> 8.0208333 | J4: =IF(VLOOKUP($B4,quadro_de_func[#All],3,FALSE)="MENOR APRENDIZ",VLOOKUP($B4,carga_horaria[],2,FALSE)*(HLOOKUP(J$3,'DIA UTEIS'!$B$4:$M$6,3,FALSE)+COUNTA('DIAS FRACIONADOS'!$B$6:$B$12)),IF(VLOOKUP($B4,quadro_de_func[#All],3,FALSE)="ESTAGIÁRIO",((VLOOKUP($B4,carga_horaria[],2,FALSE)*HLOOKUP(J$3,'DIA UTEIS'!$B$4:$M$6,3,FALSE))-(HLOOKUP($B4,'EST. PROVAS'!$B$3:$Z$4,2,FALSE)*(VLOOKUP($B4,carga_horaria[],2,FALSE)/2)))+HLOOKUP(HR_A_FAZER[[#Headers],[AGOSTO]],'DIAS FRACIONADOS'!$B$3:$Y$4,2,FALSE),(VLOOKUP($B4,carga_horaria[],2,FALSE)*(HLOOKUP(J$3,'DIA UTEIS'!$B$4:$M$6,3,FALSE)))+HLOOKUP(HR_A_FAZER[[#Headers],[AGOSTO]],'DIAS FRACIONADOS'!$B$3:$Y$4,2,FALSE))) -> 8.0208333 | K4: =IF(VLOOKUP($B4,quadro_de_func[#All],3,FALSE)="MENOR APRENDIZ",VLOOKUP($B4,carga_horaria[],2,FALSE)*(HLOOKUP(K$3,'DIA UTEIS'!$B$4:$M$6,3,FALSE)+COUNTA('DIAS FRACIONADOS'!$B$6:$B$12)),IF(VLOOKUP($B4,quadro_de_func[#All],3,FALSE)="ESTAGIÁRIO",((VLOOKUP($B4,carga_horaria[],2,FALSE)*HLOOKUP(K$3,'DIA UTEIS'!$B$4:$M$6,3,FALSE))-(HLOOKUP($B4,'EST. PROVAS'!$B$3:$Z$4,2,FALSE)*(VLOOKUP($B4,carga_horaria[],2,FALSE)/2)))+HLOOKUP(HR_A_FAZER[[#Headers],[SETEMBRO]],'DIAS FRACIONADOS'!$B$3:$Y$4,2,FALSE),(VLOOKUP($B4,carga_horaria[],2,FALSE)*(HLOOKUP(K$3,'DIA UTEIS'!$B$4:$M$6,3,FALSE)))+HLOOKUP(HR_A_FAZER[[#Headers],[SETEMBRO]],'DIAS FRACIONADOS'!$B$3:$Y$4,2,FALSE))) -> 7.2916667 | L4: =IF(VLOOKUP($B4,quadro_de_func[#All],3,FALSE)="MENOR APRENDIZ",VLOOKUP($B4,carga_horaria[],2,FALSE)*(HLOOKUP(L$3,'DIA UTEIS'!$B$4:$M$6,3,FALSE)+COUNTA('DIAS FRACIONADOS'!$B$6:$B$12)),IF(VLOOKUP($B4,quadro_de_func[#All],3,FALSE)="ESTAGIÁRIO",((VLOOKUP($B4,carga_horaria[],2,FALSE)*HLOOKUP(L$3,'DIA UTEIS'!$B$4:$M$6,3,FALSE))-(HLOOKUP($B4,'EST. PROVAS'!$B$3:$Z$4,2,FALSE)*(VLOOKUP($B4,carga_horaria[],2,FALSE)/2)))+HLOOKUP(HR_A_FAZER[[#Headers],[OUTUBRO]],'DIAS FRACIONADOS'!$B$3:$Y$4,2,FALSE),(VLOOKUP($B4,carga_horaria[],2,FALSE)*(HLOOKUP(L$3,'DIA UTEIS'!$B$4:$M$6,3,FALSE)))+HLOOKUP(HR_A_FAZER[[#Headers],[OUTUBRO]],'DIAS FRACIONADOS'!$B$3:$Y$4,2,FALSE))) -> 8.3854167 | M4: =IF(VLOOKUP($B4,quadro_de_func[#All],3,FALSE)="MENOR APRENDIZ",VLOOKUP($B4,carga_horaria[],2,FALSE)*(HLOOKUP(M$3,'DIA UTEIS'!$B$4:$M$6,3,FALSE)+COUNTA('DIAS FRACIONADOS'!$B$6:$B$12)),IF(VLOOKUP($B4,quadro_de_func[#All],3,FALSE)="ESTAGIÁRIO",((VLOOKUP($B4,carga_horaria[],2,FALSE)*HLOOKUP(M$3,'DIA UTEIS'!$B$4:$M$6,3,FALSE))-(HLOOKUP($B4,'EST. PROVAS'!$B$3:$Z$4,2,FALSE)*(VLOOKUP($B4,carga_horaria[],2,FALSE)/2)))+HLOOKUP(HR_A_FAZER[[#Headers],[NOVEMBRO]],'DIAS FRACIONADOS'!$B$3:$Y$4,2,FALSE),(VLOOKUP($B4,carga_horaria[],2,FALSE)*(HLOOKUP(M$3,'DIA UTEIS'!$B$4:$M$6,3,FALSE)))+HLOOKUP(HR_A_FAZER[[#Headers],[NOVEMBRO]],'DIAS FRACIONADOS'!$B$3:$Y$4,2,FALSE))) -> 7.2916667 | N4: =IF(VLOOKUP($B4,quadro_de_func[#All],3,FALSE)="MENOR APRENDIZ",VLOOKUP($B4,carga_horaria[],2,FALSE)*(HLOOKUP(N$3,'DIA UTEIS'!$B$4:$M$6,3,FALSE)+COUNTA('DIAS FRACIONADOS'!$B$6:$B$12)),IF(VLOOKUP($B4,quadro_de_func[#All],3,FALSE)="ESTAGIÁRIO",((VLOOKUP($B4,carga_horaria[],2,FALSE)*HLOOKUP(N$3,'DIA UTEIS'!$B$4:$M$6,3,FALSE))-(HLOOKUP($B4,'EST. PROVAS'!$B$3:$Z$4,2,FALSE)*(VLOOKUP($B4,carga_horaria[],2,FALSE)/2)))+HLOOKUP(HR_A_FAZER[[#Headers],[DEZEMBRO]],'DIAS FRACIONADOS'!$B$3:$Y$4,2,FALSE),(VLOOKUP($B4,carga_horaria[],2,FALSE)*(HLOOKUP(N$3,'DIA UTEIS'!$B$4:$M$6,3,FALSE)))+HLOOKUP(HR_A_FAZER[[#Headers],[DEZEMBRO]],'DIAS FRACIONADOS'!$B$3:$Y$4,2,FALSE))) -> 7.65625
B5: =quadro_de_func[[#This Row],[NOME]] -> Bruna | C5: =IF(VLOOKUP($B5,quadro_de_func[#All],3,FALSE)="MENOR APRENDIZ",VLOOKUP($B5,carga_horaria[],2,FALSE)*(HLOOKUP(C$3,'DIA UTEIS'!$B$4:$M$6,3,FALSE)+COUNTA('DIAS FRACIONADOS'!$B$6:$B$12)),IF(VLOOKUP($B5,quadro_de_func[#All],3,FALSE)="ESTAGIÁRIO",((VLOOKUP($B5,carga_horaria[],2,FALSE)*HLOOKUP(C$3,'DIA UTEIS'!$B$4:$M$6,3,FALSE))-(HLOOKUP($B5,'EST. PROVAS'!$B$3:$Z$4,2,FALSE)*(VLOOKUP($B5,carga_horaria[],2,FALSE)/2)))+HLOOKUP(HR_A_FAZER[[#Headers],[JANEIRO]],'DIAS FRACIONADOS'!$B$3:$Y$4,2,FALSE),(VLOOKUP($B5,carga_horaria[],2,FALSE)*(HLOOKUP(C$3,'DIA UTEIS'!$B$4:$M$6,3,FALSE)))+HLOOKUP(HR_A_FAZER[[#Headers],[JANEIRO]],'DIAS FRACIONADOS'!$B$3:$Y$4,2,FALSE))) -> 8.0833333 | D5: =IF(VLOOKUP($B5,quadro_de_func[#All],3,FALSE)="MENOR APRENDIZ",VLOOKUP($B5,carga_horaria[],2,FALSE)*(HLOOKUP(D$3,'DIA UTEIS'!$B$4:$M$6,3,FALSE)+COUNTA('DIAS FRACIONADOS'!$B$6:$B$12)),IF(VLOOKUP($B5,quadro_de_func[#All],3,FALSE)="ESTAGIÁRIO",((VLOOKUP($B5,carga_horaria[],2,FALSE)*HLOOKUP(D$3,'DIA UTEIS'!$B$4:$M$6,3,FALSE))-(HLOOKUP($B5,'EST. PROVAS'!$B$3:$Z$4,2,FALSE)*(VLOOKUP($B5,carga_horaria[],2,FALSE)/2)))+HLOOKUP(HR_A_FAZER[[#Headers],[FEVEREIRO]],'DIAS FRACIONADOS'!$B$3:$Y$4,2,FALSE),(VLOOKUP($B5,carga_horaria[],2,FALSE)*(HLOOKUP(D$3,'DIA UTEIS'!$B$4:$M$6,3,FALSE)))+HLOOKUP(HR_A_FAZER[[#Headers],[FEVEREIRO]],'DIAS FRACIONADOS'!$B$3:$Y$4,2,FALSE))) -> 7.5 | E5: =IF(VLOOKUP($B5,quadro_de_func[#All],3,FALSE)="MENOR APRENDIZ",VLOOKUP($B5,carga_horaria[],2,FALSE)*(HLOOKUP(E$3,'DIA UTEIS'!$B$4:$M$6,3,FALSE)+COUNTA('DIAS FRACIONADOS'!$B$6:$B$12)),IF(VLOOKUP($B5,quadro_de_func[#All],3,FALSE)="ESTAGIÁRIO",((VLOOKUP($B5,carga_horaria[],2,FALSE)*HLOOKUP(E$3,'DIA UTEIS'!$B$4:$M$6,3,FALSE))-(HLOOKUP($B5,'EST. PROVAS'!$B$3:$Z$4,2,FALSE)*(VLOOKUP($B5,carga_horaria[],2,FALSE)/2)))+HLOOKUP(HR_A_FAZER[[#Headers],[MARÇO]],'DIAS FRACIONADOS'!$B$3:$Y$4,2,FALSE),(VLOOKUP($B5,carga_horaria[],2,FALSE)*(HLOOKUP(E$3,'DIA UTEIS'!$B$4:$M$6,3,FALSE)))+HLOOKUP(HR_A_FAZER[[#Headers],[MARÇO]],'DIAS FRACIONADOS'!$B$3:$Y$4,2,FALSE))) -> 7 | F5: =IF(VLOOKUP($B5,quadro_de_func[#All],3,FALSE)="MENOR APRENDIZ",VLOOKUP($B5,carga_horaria[],2,FALSE)*(HLOOKUP(F$3,'DIA UTEIS'!$B$4:$M$6,3,FALSE)+COUNTA('DIAS FRACIONADOS'!$B$6:$B$12)),IF(VLOOKUP($B5,quadro_de_func[#All],3,FALSE)="ESTAGIÁRIO",((VLOOKUP($B5,carga_horaria[],2,FALSE)*HLOOKUP(F$3,'DIA UTEIS'!$B$4:$M$6,3,FALSE))-(HLOOKUP($B5,'EST. PROVAS'!$B$3:$Z$4,2,FALSE)*(VLOOKUP($B5,carga_horaria[],2,FALSE)/2)))+HLOOKUP(HR_A_FAZER[[#Headers],[ABRIL]],'DIAS FRACIONADOS'!$B$3:$Y$4,2,FALSE),(VLOOKUP($B5,carga_horaria[],2,FALSE)*(HLOOKUP(F$3,'DIA UTEIS'!$B$4:$M$6,3,FALSE)))+HLOOKUP(HR_A_FAZER[[#Headers],[ABRIL]],'DIAS FRACIONADOS'!$B$3:$Y$4,2,FALSE))) -> 7.875 | G5: =IF(VLOOKUP($B5,quadro_de_func[#All],3,FALSE)="MENOR APRENDIZ",VLOOKUP($B5,carga_horaria[],2,FALSE)*(HLOOKUP(G$3,'DIA UTEIS'!$B$4:$M$6,3,FALSE)+COUNTA('DIAS FRACIONADOS'!$B$6:$B$12)),IF(VLOOKUP($B5,quadro_de_func[#All],3,FALSE)="ESTAGIÁRIO",((VLOOKUP($B5,carga_horaria[],2,FALSE)*HLOOKUP(G$3,'DIA UTEIS'!$B$4:$M$6,3,FALSE))-(HLOOKUP($B5,'EST. PROVAS'!$B$3:$Z$4,2,FALSE)*(VLOOKUP($B5,carga_horaria[],2,FALSE)/2)))+HLOOKUP(HR_A_FAZER[[#Headers],[MAIO]],'DIAS FRACIONADOS'!$B$3:$Y$4,2,FALSE),(VLOOKUP($B5,carga_horaria[],2,FALSE)*(HLOOKUP(G$3,'DIA UTEIS'!$B$4:$M$6,3,FALSE)))+HLOOKUP(HR_A_FAZER[[#Headers],[MAIO]],'DIAS FRACIONADOS'!$B$3:$Y$4,2,FALSE))) -> 8.25 | H5: =IF(VLOOKUP($B5,quadro_de_func[#All],3,FALSE)="MENOR APRENDIZ",VLOOKUP($B5,carga_horaria[],2,FALSE)*(HLOOKUP(H$3,'DIA UTEIS'!$B$4:$M$6,3,FALSE)+COUNTA('DIAS FRACIONADOS'!$B$6:$B$12)),IF(VLOOKUP($B5,quadro_de_func[#All],3,FALSE)="ESTAGIÁRIO",((VLOOKUP($B5,carga_horaria[],2,FALSE)*HLOOKUP(H$3,'DIA UTEIS'!$B$4:$M$6,3,FALSE))-(HLOOKUP($B5,'EST. PROVAS'!$B$3:$Z$4,2,FALSE)*(VLOOKUP($B5,carga_horaria[],2,FALSE)/2)))+HLOOKUP(HR_A_FAZER[[#Headers],[JUNHO]],'DIAS FRACIONADOS'!$B$3:$Y$4,2,FALSE),(VLOOKUP($B5,carga_horaria[],2,FALSE)*(HLOOKUP(H$3,'DIA UTEIS'!$B$4:$M$6,3,FALSE)))+HLOOKUP(HR_A_FAZER[[#Headers],[JUNHO]],'DIAS FRACIONADOS'!$B$3:$Y$4,2,FALSE))) -> 7.125 | I5: =IF(VLOOKUP($B5,quadro_de_func[#All],3,FALSE)="MENOR APRENDIZ",VLOOKUP($B5,carga_horaria[],2,FALSE)*(HLOOKUP(I$3,'DIA UTEIS'!$B$4:$M$6,3,FALSE)+COUNTA('DIAS FRACIONADOS'!$B$6:$B$12)),IF(VLOOKUP($B5,quadro_de_func[#All],3,FALSE)="ESTAGIÁRIO",((VLOOKUP($B5,carga_horaria[],2,FALSE)*HLOOKUP(I$3,'DIA UTEIS'!$B$4:$M$6,3,FALSE))-(HLOOKUP($B5,'EST. PROVAS'!$B$3:$Z$4,2,FALSE)*(VLOOKUP($B5,carga_horaria[],2,FALSE)/2)))+HLOOKUP(HR_A_FAZER[[#Headers],[JULHO]],'DIAS FRACIONADOS'!$B$3:$Y$4,2,FALSE),(VLOOKUP($B5,carga_horaria[],2,FALSE)*(HLOOKUP(I$3,'DIA UTEIS'!$B$4:$M$6,3,FALSE)))+HLOOKUP(HR_A_FAZER[[#Headers],[JULHO]],'DIAS FRACIONADOS'!$B$3:$Y$4,2,FALSE))) -> 8.25 | J5: =IF(VLOOKUP($B5,quadro_de_func[#All],3,FALSE)="MENOR APRENDIZ",VLOOKUP($B5,carga_horaria[],2,FALSE)*(HLOOKUP(J$3,'DIA UTEIS'!$B$4:$M$6,3,FALSE)+COUNTA('DIAS FRACIONADOS'!$B$6:$B$12)),IF(VLOOKUP($B5,quadro_de_func[#All],3,FALSE)="ESTAGIÁRIO",((VLOOKUP($B5,carga_horaria[],2,FALSE)*HLOOKUP(J$3,'DIA UTEIS'!$B$4:$M$6,3,FALSE))-(HLOOKUP($B5,'EST. PROVAS'!$B$3:$Z$4,2,FALSE)*(VLOOKUP($B5,carga_horaria[],2,FALSE)/2)))+HLOOKUP(HR_A_FAZER[[#Headers],[AGOSTO]],'DIAS FRACIONADOS'!$B$3:$Y$4,2,FALSE),(VLOOKUP($B5,carga_horaria[],2,FALSE)*(HLOOKUP(J$3,'DIA UTEIS'!$B$4:$M$6,3,FALSE)))+HLOOKUP(HR_A_FAZER[[#Headers],[AGOSTO]],'DIAS FRACIONADOS'!$B$3:$Y$4,2,FALSE))) -> 8.25 | K5: =IF(VLOOKUP($B5,quadro_de_func[#All],3,FALSE)="MENOR APRENDIZ",VLOOKUP($B5,carga_horaria[],2,FALSE)*(HLOOKUP(K$3,'DIA UTEIS'!$B$4:$M$6,3,FALSE)+COUNTA('DIAS FRACIONADOS'!$B$6:$B$12)),IF(VLOOKUP($B5,quadro_de_func[#All],3,FALSE)="ESTAGIÁRIO",((VLOOKUP($B5,carga_horaria[],2,FALSE)*HLOOKUP(K$3,'DIA UTEIS'!$B$4:$M$6,3,FALSE))-(HLOOKUP($B5,'EST. PROVAS'!$B$3:$Z$4,2,FALSE)*(VLOOKUP($B5,carga_horaria[],2,FALSE)/2)))+HLOOKUP(HR_A_FAZER[[#Headers],[SETEMBRO]],'DIAS FRACIONADOS'!$B$3:$Y$4,2,FALSE),(VLOOKUP($B5,carga_horaria[],2,FALSE)*(HLOOKUP(K$3,'DIA UTEIS'!$B$4:$M$6,3,FALSE)))+HLOOKUP(HR_A_FAZER[[#Headers],[SETEMBRO]],'DIAS FRACIONADOS'!$B$3:$Y$4,2,FALSE))) -> 7.5 | L5: =IF(VLOOKUP($B5,quadro_de_func[#All],3,FALSE)="MENOR APRENDIZ",VLOOKUP($B5,carga_horaria[],2,FALSE)*(HLOOKUP(L$3,'DIA UTEIS'!$B$4:$M$6,3,FALSE)+COUNTA('DIAS FRACIONADOS'!$B$6:$B$12)),IF(VLOOKUP($B5,quadro_de_func[#All],3,FALSE)="ESTAGIÁRIO",((VLOOKUP($B5,carga_horaria[],2,FALSE)*HLOOKUP(L$3,'DIA UTEIS'!$B$4:$M$6,3,FALSE))-(HLOOKUP($B5,'EST. PROVAS'!$B$3:$Z$4,2,FALSE)*(VLOOKUP($B5,carga_horaria[],2,FALSE)/2)))+HLOOKUP(HR_A_FAZER[[#Headers],[OUTUBRO]],'DIAS FRACIONADOS'!$B$3:$Y$4,2,FALSE),(VLOOKUP($B5,carga_horaria[],2,FALSE)*(HLOOKUP(L$3,'DIA UTEIS'!$B$4:$M$6,3,FALSE)))+HLOOKUP(HR_A_FAZER[[#Headers],[OUTUBRO]],'DIAS FRACIONADOS'!$B$3:$Y$4,2,FALSE))) -> 8.625 | M5: =IF(VLOOKUP($B5,quadro_de_func[#All],3,FALSE)="MENOR APRENDIZ",VLOOKUP($B5,carga_horaria[],2,FALSE)*(HLOOKUP(M$3,'DIA UTEIS'!$B$4:$M$6,3,FALSE)+COUNTA('DIAS FRACIONADOS'!$B$6:$B$12)),IF(VLOOKUP($B5,quadro_de_func[#All],3,FALSE)="ESTAGIÁRIO",((VLOOKUP($B5,carga_horaria[],2,FALSE)*HLOOKUP(M$3,'DIA UTEIS'!$B$4:$M$6,3,FALSE))-(HLOOKUP($B5,'EST. PROVAS'!$B$3:$Z$4,2,FALSE)*(VLOOKUP($B5,carga_horaria[],2,FALSE)/2)))+HLOOKUP(HR_A_FAZER[[#Headers],[NOVEMBRO]],'DIAS FRACIONADOS'!$B$3:$Y$4,2,FALSE),(VLOOKUP($B5,carga_horaria[],2,FALSE)*(HLOOKUP(M$3,'DIA UTEIS'!$B$4:$M$6,3,FALSE)))+HLOOKUP(HR_A_FAZER[[#Headers],[NOVEMBRO]],'DIAS FRACIONADOS'!$B$3:$Y$4,2,FALSE))) -> 7.5 | N5: =IF(VLOOKUP($B5,quadro_de_func[#All],3,FALSE)="MENOR APRENDIZ",VLOOKUP($B5,carga_horaria[],2,FALSE)*(HLOOKUP(N$3,'DIA UTEIS'!$B$4:$M$6,3,FALSE)+COUNTA('DIAS FRACIONADOS'!$B$6:$B$12)),IF(VLOOKUP($B5,quadro_de_func[#All],3,FALSE)="ESTAGIÁRIO",((VLOOKUP($B5,carga_horaria[],2,FALSE)*HLOOKUP(N$3,'DIA UTEIS'!$B$4:$M$6,3,FALSE))-(HLOOKUP($B5,'EST. PROVAS'!$B$3:$Z$4,2,FALSE)*(VLOOKUP($B5,carga_horaria[],2,FALSE)/2)))+HLOOKUP(HR_A_FAZER[[#Headers],[DEZEMBRO]],'DIAS FRACIONADOS'!$B$3:$Y$4,2,FALSE),(VLOOKUP($B5,carga_horaria[],2,FALSE)*(HLOOKUP(N$3,'DIA UTEIS'!$B$4:$M$6,3,FALSE)))+HLOOKUP(HR_A_FAZER[[#Headers],[DEZEMBRO]],'DIAS FRACIONADOS'!$B$3:$Y$4,2,FALSE))) -> 7.875
B6: =quadro_de_func[[#This Row],[NOME]] -> Daiani | C6: =IF(VLOOKUP($B6,quadro_de_func[#All],3,FALSE)="MENOR APRENDIZ",VLOOKUP($B6,carga_horaria[],2,FALSE)*(HLOOKUP(C$3,'DIA UTEIS'!$B$4:$M$6,3,FALSE)+COUNTA('DIAS FRACIONADOS'!$B$6:$B$12)),IF(VLOOKUP($B6,quadro_de_func[#All],3,FALSE)="ESTAGIÁRIO",((VLOOKUP($B6,carga_horaria[],2,FALSE)*HLOOKUP(C$3,'DIA UTEIS'!$B$4:$M$6,3,FALSE))-(HLOOKUP($B6,'EST. PROVAS'!$B$3:$Z$4,2,FALSE)*(VLOOKUP($B6,carga_horaria[],2,FALSE)/2)))+HLOOKUP(HR_A_FAZER[[#Headers],[JANEIRO]],'DIAS FRACIONADOS'!$B$3:$Y$4,2,FALSE),(VLOOKUP($B6,carga_horaria[],2,FALSE)*(HLOOKUP(C$3,'DIA UTEIS'!$B$4:$M$6,3,FALSE)))+HLOOKUP(HR_A_FAZER[[#Headers],[JANEIRO]],'DIAS FRACIONADOS'!$B$3:$Y$4,2,FALSE))) -> 7.8645833 | D6: =IF(VLOOKUP($B6,quadro_de_func[#All],3,FALSE)="MENOR APRENDIZ",VLOOKUP($B6,carga_horaria[],2,FALSE)*(HLOOKUP(D$3,'DIA UTEIS'!$B$4:$M$6,3,FALSE)+COUNTA('DIAS FRACIONADOS'!$B$6:$B$12)),IF(VLOOKUP($B6,quadro_de_func[#All],3,FALSE)="ESTAGIÁRIO",((VLOOKUP($B6,carga_horaria[],2,FALSE)*HLOOKUP(D$3,'DIA UTEIS'!$B$4:$M$6,3,FALSE))-(HLOOKUP($B6,'EST. PROVAS'!$B$3:$Z$4,2,FALSE)*(VLOOKUP($B6,carga_horaria[],2,FALSE)/2)))+HLOOKUP(HR_A_FAZER[[#Headers],[FEVEREIRO]],'DIAS FRACIONADOS'!$B$3:$Y$4,2,FALSE),(VLOOKUP($B6,carga_horaria[],2,FALSE)*(HLOOKUP(D$3,'DIA UTEIS'!$B$4:$M$6,3,FALSE)))+HLOOKUP(HR_A_FAZER[[#Headers],[FEVEREIRO]],'DIAS FRACIONADOS'!$B$3:$Y$4,2,FALSE))) -> 7.2916667 | E6: =IF(VLOOKUP($B6,quadro_de_func[#All],3,FALSE)="MENOR APRENDIZ",VLOOKUP($B6,carga_horaria[],2,FALSE)*(HLOOKUP(E$3,'DIA UTEIS'!$B$4:$M$6,3,FALSE)+COUNTA('DIAS FRACIONADOS'!$B$6:$B$12)),IF(VLOOKUP($B6,quadro_de_func[#All],3,FALSE)="ESTAGIÁRIO",((VLOOKUP($B6,carga_horaria[],2,FALSE)*HLOOKUP(E$3,'DIA UTEIS'!$B$4:$M$6,3,FALSE))-(HLOOKUP($B6,'EST. PROVAS'!$B$3:$Z$4,2,FALSE)*(VLOOKUP($B6,carga_horaria[],2,FALSE)/2)))+HLOOKUP(HR_A_FAZER[[#Headers],[MARÇO]],'DIAS FRACIONADOS'!$B$3:$Y$4,2,FALSE),(VLOOKUP($B6,carga_horaria[],2,FALSE)*(HLOOKUP(E$3,'DIA UTEIS'!$B$4:$M$6,3,FALSE)))+HLOOKUP(HR_A_FAZER[[#Headers],[MARÇO]],'DIAS FRACIONADOS'!$B$3:$Y$4,2,FALSE))) -> 6.8125 | F6: =IF(VLOOKUP($B6,quadro_de_func[#All],3,FALSE)="MENOR APRENDIZ",VLOOKUP($B6,carga_horaria[],2,FALSE)*(HLOOKUP(F$3,'DIA UTEIS'!$B$4:$M$6,3,FALSE)+COUNTA('DIAS FRACIONADOS'!$B$6:$B$12)),IF(VLOOKUP($B6,quadro_de_func[#All],3,FALSE)="ESTAGIÁRIO",((VLOOKUP($B6,carga_horaria[],2,FALSE)*HLOOKUP(F$3,'DIA UTEIS'!$B$4:$M$6,3,FALSE))-(HLOOKUP($B6,'EST. PROVAS'!$B$3:$Z$4,2,FALSE)*(VLOOKUP($B6,carga_horaria[],2,FALSE)/2)))+HLOOKUP(HR_A_FAZER[[#Headers],[ABRIL]],'DIAS FRACIONADOS'!$B$3:$Y$4,2,FALSE),(VLOOKUP($B6,carga_horaria[],2,FALSE)*(HLOOKUP(F$3,'DIA UTEIS'!$B$4:$M$6,3,FALSE)))+HLOOKUP(HR_A_FAZER[[#Headers],[ABRIL]],'DIAS FRACIONADOS'!$B$3:$Y$4,2,FALSE))) -> 7.65625 | G6: =IF(VLOOKUP($B6,quadro_de_func[#All],3,FALSE)="MENOR APRENDIZ",VLOOKUP($B6,carga_horaria[],2,FALSE)*(HLOOKUP(G$3,'DIA UTEIS'!$B$4:$M$6,3,FALSE)+COUNTA('DIAS FRACIONADOS'!$B$6:$B$12)),IF(VLOOKUP($B6,quadro_de_func[#All],3,FALSE)="ESTAGIÁRIO",((VLOOKUP($B6,carga_horaria[],2,FALSE)*HLOOKUP(G$3,'DIA UTEIS'!$B$4:$M$6,3,FALSE))-(HLOOKUP($B6,'EST. PROVAS'!$B$3:$Z$4,2,FALSE)*(VLOOKUP($B6,carga_horaria[],2,FALSE)/2)))+HLOOKUP(HR_A_FAZER[[#Headers],[MAIO]],'DIAS FRACIONADOS'!$B$3:$Y$4,2,FALSE),(VLOOKUP($B6,carga_horaria[],2,FALSE)*(HLOOKUP(G$3,'DIA UTEIS'!$B$4:$M$6,3,FALSE)))+HLOOKUP(HR_A_FAZER[[#Headers],[MAIO]],'DIAS FRACIONADOS'!$B$3:$Y$4,2,FALSE))) -> 8.0208333 | H6: =IF(VLOOKUP($B6,quadro_de_func[#All],3,FALSE)="MENOR APRENDIZ",VLOOKUP($B6,carga_horaria[],2,FALSE)*(HLOOKUP(H$3,'DIA UTEIS'!$B$4:$M$6,3,FALSE)+COUNTA('DIAS FRACIONADOS'!$B$6:$B$12)),IF(VLOOKUP($B6,quadro_de_func[#All],3,FALSE)="ESTAGIÁRIO",((VLOOKUP($B6,carga_horaria[],2,FALSE)*HLOOKUP(H$3,'DIA UTEIS'!$B$4:$M$6,3,FALSE))-(HLOOKUP($B6,'EST. PROVAS'!$B$3:$Z$4,2,FALSE)*(VLOOKUP($B6,carga_horaria[],2,FALSE)/2)))+HLOOKUP(HR_A_FAZER[[#Headers],[JUNHO]],'DIAS FRACIONADOS'!$B$3:$Y$4,2,FALSE),(VLOOKUP($B6,carga_horaria[],2,FALSE)*(HLOOKUP(H$3,'DIA UTEIS'!$B$4:$M$6,3,FALSE)))+HLOOKUP(HR_A_FAZER[[#Headers],[JUNHO]],'DIAS FRACIONADOS'!$B$3:$Y$4,2,FALSE))) -> 6.9270833 | I6: =IF(VLOOKUP($B6,quadro_de_func[#All],3,FALSE)="MENOR APRENDIZ",VLOOKUP($B6,carga_horaria[],2,FALSE)*(HLOOKUP(I$3,'DIA UTEIS'!$B$4:$M$6,3,FALSE)+COUNTA('DIAS FRACIONADOS'!$B$6:$B$12)),IF(VLOOKUP($B6,quadro_de_func[#All],3,FALSE)="ESTAGIÁRIO",((VLOOKUP($B6,carga_horaria[],2,FALSE)*HLOOKUP(I$3,'DIA UTEIS'!$B$4:$M$6,3,FALSE))-(HLOOKUP($B6,'EST. PROVAS'!$B$3:$Z$4,2,FALSE)*(VLOOKUP($B6,carga_horaria[],2,FALSE)/2)))+HLOOKUP(HR_A_FAZER[[#Headers],[JULHO]],'DIAS FRACIONADOS'!$B$3:$Y$4,2,FALSE),(VLOOKUP($B6,carga_horaria[],2,FALSE)*(HLOOKUP(I$3,'DIA UTEIS'!$B$4:$M$6,3,FALSE)))+HLOOKUP(HR_A_FAZER[[#Headers],[JULHO]],'DIAS FRACIONADOS'!$B$3:$Y$4,2,FALSE))) -> 8.0208333 | J6: =IF(VLOOKUP($B6,quadro_de_func[#All],3,FALSE)="MENOR APRENDIZ",VLOOKUP($B6,carga_horaria[],2,FALSE)*(HLOOKUP(J$3,'DIA UTEIS'!$B$4:$M$6,3,FALSE)+COUNTA('DIAS FRACIONADOS'!$B$6:$B$12)),IF(VLOOKUP($B6,quadro_de_func[#All],3,FALSE)="ESTAGIÁRIO",((VLOOKUP($B6,carga_horaria[],2,FALSE)*HLOOKUP(J$3,'DIA UTEIS'!$B$4:$M$6,3,FALSE))-(HLOOKUP($B6,'EST. PROVAS'!$B$3:$Z$4,2,FALSE)*(VLOOKUP($B6,carga_horaria[],2,FALSE)/2)))+HLOOKUP(HR_A_FAZER[[#Headers],[AGOSTO]],'DIAS FRACIONADOS'!$B$3:$Y$4,2,FALSE),(VLOOKUP($B6,carga_horaria[],2,FALSE)*(HLOOKUP(J$3,'DIA UTEIS'!$B$4:$M$6,3,FALSE)))+HLOOKUP(HR_A_FAZER[[#Headers],[AGOSTO]],'DIAS FRACIONADOS'!$B$3:$Y$4,2,FALSE))) -> 8.0208333 | K6: =IF(VLOOKUP($B6,quadro_de_func[#All],3,FALSE)="MENOR APRENDIZ",VLOOKUP($B6,carga_horaria[],2,FALSE)*(HLOOKUP(K$3,'DIA UTEIS'!$B$4:$M$6,3,FALSE)+COUNTA('DIAS FRACIONADOS'!$B$6:$B$12)),IF(VLOOKUP($B6,quadro_de_func[#All],3,FALSE)="ESTAGIÁRIO",((VLOOKUP($B6,carga_horaria[],2,FALSE)*HLOOKUP(K$3,'DIA UTEIS'!$B$4:$M$6,3,FALSE))-(HLOOKUP($B6,'EST. PROVAS'!$B$3:$Z$4,2,FALSE)*(VLOOKUP($B6,carga_horaria[],2,FALSE)/2)))+HLOOKUP(HR_A_FAZER[[#Headers],[SETEMBRO]],'DIAS FRACIONADOS'!$B$3:$Y$4,2,FALSE),(VLOOKUP($B6,carga_horaria[],2,FALSE)*(HLOOKUP(K$3,'DIA UTEIS'!$B$4:$M$6,3,FALSE)))+HLOOKUP(HR_A_FAZER[[#Headers],[SETEMBRO]],'DIAS FRACIONADOS'!$B$3:$Y$4,2,FALSE))) -> 7.2916667 | L6: =IF(VLOOKUP($B6,quadro_de_func[#All],3,FALSE)="MENOR APRENDIZ",VLOOKUP($B6,carga_horaria[],2,FALSE)*(HLOOKUP(L$3,'DIA UTEIS'!$B$4:$M$6,3,FALSE)+COUNTA('DIAS FRACIONADOS'!$B$6:$B$12)),IF(VLOOKUP($B6,quadro_de_func[#All],3,FALSE)="ESTAGIÁRIO",((VLOOKUP($B6,carga_horaria[],2,FALSE)*HLOOKUP(L$3,'DIA UTEIS'!$B$4:$M$6,3,FALSE))-(HLOOKUP($B6,'EST. PROVAS'!$B$3:$Z$4,2,FALSE)*(VLOOKUP($B6,carga_horaria[],2,FALSE)/2)))+HLOOKUP(HR_A_FAZER[[#Headers],[OUTUBRO]],'DIAS FRACIONADOS'!$B$3:$Y$4,2,FALSE),(VLOOKUP($B6,carga_horaria[],2,FALSE)*(HLOOKUP(L$3,'DIA UTEIS'!$B$4:$M$6,3,FALSE)))+HLOOKUP(HR_A_FAZER[[#Headers],[OUTUBRO]],'DIAS FRACIONADOS'!$B$3:$Y$4,2,FALSE))) -> 8.3854167 | M6: =IF(VLOOKUP($B6,quadro_de_func[#All],3,FALSE)="MENOR APRENDIZ",VLOOKUP($B6,carga_horaria[],2,FALSE)*(HLOOKUP(M$3,'DIA UTEIS'!$B$4:$M$6,3,FALSE)+COUNTA('DIAS FRACIONADOS'!$B$6:$B$12)),IF(VLOOKUP($B6,quadro_de_func[#All],3,FALSE)="ESTAGIÁRIO",((VLOOKUP($B6,carga_horaria[],2,FALSE)*HLOOKUP(M$3,'DIA UTEIS'!$B$4:$M$6,3,FALSE))-(HLOOKUP($B6,'EST. PROVAS'!$B$3:$Z$4,2,FALSE)*(VLOOKUP($B6,carga_horaria[],2,FALSE)/2)))+HLOOKUP(HR_A_FAZER[[#Headers],[NOVEMBRO]],'DIAS FRACIONADOS'!$B$3:$Y$4,2,FALSE),(VLOOKUP($B6,carga_horaria[],2,FALSE)*(HLOOKUP(M$3,'DIA UTEIS'!$B$4:$M$6,3,FALSE)))+HLOOKUP(HR_A_FAZER[[#Headers],[NOVEMBRO]],'DIAS FRACIONADOS'!$B$3:$Y$4,2,FALSE))) -> 7.2916667 | N6: =IF(VLOOKUP($B6,quadro_de_func[#All],3,FALSE)="MENOR APRENDIZ",VLOOKUP($B6,carga_horaria[],2,FALSE)*(HLOOKUP(N$3,'DIA UTEIS'!$B$4:$M$6,3,FALSE)+COUNTA('DIAS FRACIONADOS'!$B$6:$B$12)),IF(VLOOKUP($B6,quadro_de_func[#All],3,FALSE)="ESTAGIÁRIO",((VLOOKUP($B6,carga_horaria[],2,FALSE)*HLOOKUP(N$3,'DIA UTEIS'!$B$4:$M$6,3,FALSE))-(HLOOKUP($B6,'EST. PROVAS'!$B$3:$Z$4,2,FALSE)*(VLOOKUP($B6,carga_horaria[],2,FALSE)/2)))+HLOOKUP(HR_A_FAZER[[#Headers],[DEZEMBRO]],'DIAS FRACIONADOS'!$B$3:$Y$4,2,FALSE),(VLOOKUP($B6,carga_horaria[],2,FALSE)*(HLOOKUP(N$3,'DIA UTEIS'!$B$4:$M$6,3,FALSE)))+HLOOKUP(HR_A_FAZER[[#Headers],[DEZEMBRO]],'DIAS FRACIONADOS'!$B$3:$Y$4,2,FALSE))) -> 7.65625
B7: =quadro_de_func[[#This Row],[NOME]] -> Érica | C7: =IF(VLOOKUP($B7,quadro_de_func[#All],3,FALSE)="MENOR APRENDIZ",VLOOKUP($B7,carga_horaria[],2,FALSE)*(HLOOKUP(C$3,'DIA UTEIS'!$B$4:$M$6,3,FALSE)+COUNTA('DIAS FRACIONADOS'!$B$6:$B$12)),IF(VLOOKUP($B7,quadro_de_func[#All],3,FALSE)="ESTAGIÁRIO",((VLOOKUP($B7,carga_horaria[],2,FALSE)*HLOOKUP(C$3,'DIA UTEIS'!$B$4:$M$6,3,FALSE))-(HLOOKUP($B7,'EST. PROVAS'!$B$3:$Z$4,2,FALSE)*(VLOOKUP($B7,carga_horaria[],2,FALSE)/2)))+HLOOKUP(HR_A_FAZER[[#Headers],[JANEIRO]],'DIAS FRACIONADOS'!$B$3:$Y$4,2,FALSE),(VLOOKUP($B7,carga_horaria[],2,FALSE)*(HLOOKUP(C$3,'DIA UTEIS'!$B$4:$M$6,3,FALSE)))+HLOOKUP(HR_A_FAZER[[#Headers],[JANEIRO]],'DIAS FRACIONADOS'!$B$3:$Y$4,2,FALSE))) -> 7.8645833 | D7: =IF(VLOOKUP($B7,quadro_de_func[#All],3,FALSE)="MENOR APRENDIZ",VLOOKUP($B7,carga_horaria[],2,FALSE)*(HLOOKUP(D$3,'DIA UTEIS'!$B$4:$M$6,3,FALSE)+COUNTA('DIAS FRACIONADOS'!$B$6:$B$12)),IF(VLOOKUP($B7,quadro_de_func[#All],3,FALSE)="ESTAGIÁRIO",((VLOOKUP($B7,carga_horaria[],2,FALSE)*HLOOKUP(D$3,'DIA UTEIS'!$B$4:$M$6,3,FALSE))-(HLOOKUP($B7,'EST. PROVAS'!$B$3:$Z$4,2,FALSE)*(VLOOKUP($B7,carga_horaria[],2,FALSE)/2)))+HLOOKUP(HR_A_FAZER[[#Headers],[FEVEREIRO]],'DIAS FRACIONADOS'!$B$3:$Y$4,2,FALSE),(VLOOKUP($B7,carga_horaria[],2,FALSE)*(HLOOKUP(D$3,'DIA UTEIS'!$B$4:$M$6,3,FALSE)))+HLOOKUP(HR_A_FAZER[[#Headers],[FEVEREIRO]],'DIAS FRACIONADOS'!$B$3:$Y$4,2,FALSE))) -> 7.2916667 | E7: =IF(VLOOKUP($B7,quadro_de_func[#All],3,FALSE)="MENOR APRENDIZ",VLOOKUP($B7,carga_horaria[],2,FALSE)*(HLOOKUP(E$3,'DIA UTEIS'!$B$4:$M$6,3,FALSE)+COUNTA('DIAS FRACIONADOS'!$B$6:$B$12)),IF(VLOOKUP($B7,quadro_de_func[#All],3,FALSE)="ESTAGIÁRIO",((VLOOKUP($B7,carga_horaria[],2,FALSE)*HLOOKUP(E$3,'DIA UTEIS'!$B$4:$M$6,3,FALSE))-(HLOOKUP($B7,'EST. PROVAS'!$B$3:$Z$4,2,FALSE)*(VLOOKUP($B7,carga_horaria[],2,FALSE)/2)))+HLOOKUP(HR_A_FAZER[[#Headers],[MARÇO]],'DIAS FRACIONADOS'!$B$3:$Y$4,2,FALSE),(VLOOKUP($B7,carga_horaria[],2,FALSE)*(HLOOKUP(E$3,'DIA UTEIS'!$B$4:$M$6,3,FALSE)))+HLOOKUP(HR_A_FAZER[[#Headers],[MARÇO]],'DIAS FRACIONADOS'!$B$3:$Y$4,2,FALSE))) -> 6.8125 | F7: =IF(VLOOKUP($B7,quadro_de_func[#All],3,FALSE)="MENOR APRENDIZ",VLOOKUP($B7,carga_horaria[],2,FALSE)*(HLOOKUP(F$3,'DIA UTEIS'!$B$4:$M$6,3,FALSE)+COUNTA('DIAS FRACIONADOS'!$B$6:$B$12)),IF(VLOOKUP($B7,quadro_de_func[#All],3,FALSE)="ESTAGIÁRIO",((VLOOKUP($B7,carga_horaria[],2,FALSE)*HLOOKUP(F$3,'DIA UTEIS'!$B$4:$M$6,3,FALSE))-(HLOOKUP($B7,'EST. PROVAS'!$B$3:$Z$4,2,FALSE)*(VLOOKUP($B7,carga_horaria[],2,FALSE)/2)))+HLOOKUP(HR_A_FAZER[[#Headers],[ABRIL]],'DIAS FRACIONADOS'!$B$3:$Y$4,2,FALSE),(VLOOKUP($B7,carga_horaria[],2,FALSE)*(HLOOKUP(F$3,'DIA UTEIS'!$B$4:$M$6,3,FALSE)))+HLOOKUP(HR_A_FAZER[[#Headers],[ABRIL]],'DIAS FRACIONADOS'!$B$3:$Y$4,2,FALSE))) -> 7.65625 | G7: =IF(VLOOKUP($B7,quadro_de_func[#All],3,FALSE)="MENOR APRENDIZ",VLOOKUP($B7,carga_horaria[],2,FALSE)*(HLOOKUP(G$3,'DIA UTEIS'!$B$4:$M$6,3,FALSE)+COUNTA('DIAS FRACIONADOS'!$B$6:$B$12)),IF(VLOOKUP($B7,quadro_de_func[#All],3,FALSE)="ESTAGIÁRIO",((VLOOKUP($B7,carga_horaria[],2,FALSE)*HLOOKUP(G$3,'DIA UTEIS'!$B$4:$M$6,3,FALSE))-(HLOOKUP($B7,'EST. PROVAS'!$B$3:$Z$4,2,FALSE)*(VLOOKUP($B7,carga_horaria[],2,FALSE)/2)))+HLOOKUP(HR_A_FAZER[[#Headers],[MAIO]],'DIAS FRACIONADOS'!$B$3:$Y$4,2,FALSE),(VLOOKUP($B7,carga_horaria[],2,FALSE)*(HLOOKUP(G$3,'DIA UTEIS'!$B$4:$M$6,3,FALSE)))+HLOOKUP(HR_A_FAZER[[#Headers],[MAIO]],'DIAS FRACIONADOS'!$B$3:$Y$4,2,FALSE))) -> 8.0208333 | H7: =IF(VLOOKUP($B7,quadro_de_func[#All],3,FALSE)="MENOR APRENDIZ",VLOOKUP($B7,carga_horaria[],2,FALSE)*(HLOOKUP(H$3,'DIA UTEIS'!$B$4:$M$6,3,FALSE)+COUNTA('DIAS FRACIONADOS'!$B$6:$B$12)),IF(VLOOKUP($B7,quadro_de_func[#All],3,FALSE)="ESTAGIÁRIO",((VLOOKUP($B7,carga_horaria[],2,FALSE)*HLOOKUP(H$3,'DIA UTEIS'!$B$4:$M$6,3,FALSE))-(HLOOKUP($B7,'EST. PROVAS'!$B$3:$Z$4,2,FALSE)*(VLOOKUP($B7,carga_horaria[],2,FALSE)/2)))+HLOOKUP(HR_A_FAZER[[#Headers],[JUNHO]],'DIAS FRACIONADOS'!$B$3:$Y$4,2,FALSE),(VLOOKUP($B7,carga_horaria[],2,FALSE)*(HLOOKUP(H$3,'DIA UTEIS'!$B$4:$M$6,3,FALSE)))+HLOOKUP(HR_A_FAZER[[#Headers],[JUNHO]],'DIAS FRACIONADOS'!$B$3:$Y$4,2,FALSE))) -> 6.9270833 | I7: =IF(VLOOKUP($B7,quadro_de_func[#All],3,FALSE)="MENOR APRENDIZ",VLOOKUP($B7,carga_horaria[],2,FALSE)*(HLOOKUP(I$3,'DIA UTEIS'!$B$4:$M$6,3,FALSE)+COUNTA('DIAS FRACIONADOS'!$B$6:$B$12)),IF(VLOOKUP($B7,quadro_de_func[#All],3,FALSE)="ESTAGIÁRIO",((VLOOKUP($B7,carga_horaria[],2,FALSE)*HLOOKUP(I$3,'DIA UTEIS'!$B$4:$M$6,3,FALSE))-(HLOOKUP($B7,'EST. PROVAS'!$B$3:$Z$4,2,FALSE)*(VLOOKUP($B7,carga_horaria[],2,FALSE)/2)))+HLOOKUP(HR_A_FAZER[[#Headers],[JULHO]],'DIAS FRACIONADOS'!$B$3:$Y$4,2,FALSE),(VLOOKUP($B7,carga_horaria[],2,FALSE)*(HLOOKUP(I$3,'DIA UTEIS'!$B$4:$M$6,3,FALSE)))+HLOOKUP(HR_A_FAZER[[#Headers],[JULHO]],'DIAS FRACIONADOS'!$B$3:$Y$4,2,FALSE))) -> 8.0208333 | J7: =IF(VLOOKUP($B7,quadro_de_func[#All],3,FALSE)="MENOR APRENDIZ",VLOOKUP($B7,carga_horaria[],2,FALSE)*(HLOOKUP(J$3,'DIA UTEIS'!$B$4:$M$6,3,FALSE)+COUNTA('DIAS FRACIONADOS'!$B$6:$B$12)),IF(VLOOKUP($B7,quadro_de_func[#All],3,FALSE)="ESTAGIÁRIO",((VLOOKUP($B7,carga_horaria[],2,FALSE)*HLOOKUP(J$3,'DIA UTEIS'!$B$4:$M$6,3,FALSE))-(HLOOKUP($B7,'EST. PROVAS'!$B$3:$Z$4,2,FALSE)*(VLOOKUP($B7,carga_horaria[],2,FALSE)/2)))+HLOOKUP(HR_A_FAZER[[#Headers],[AGOSTO]],'DIAS FRACIONADOS'!$B$3:$Y$4,2,FALSE),(VLOOKUP($B7,carga_horaria[],2,FALSE)*(HLOOKUP(J$3,'DIA UTEIS'!$B$4:$M$6,3,FALSE)))+HLOOKUP(HR_A_FAZER[[#Headers],[AGOSTO]],'DIAS FRACIONADOS'!$B$3:$Y$4,2,FALSE))) -> 8.0208333 | K7: =IF(VLOOKUP($B7,quadro_de_func[#All],3,FALSE)="MENOR APRENDIZ",VLOOKUP($B7,carga_horaria[],2,FALSE)*(HLOOKUP(K$3,'DIA UTEIS'!$B$4:$M$6,3,FALSE)+COUNTA('DIAS FRACIONADOS'!$B$6:$B$12)),IF(VLOOKUP($B7,quadro_de_func[#All],3,FALSE)="ESTAGIÁRIO",((VLOOKUP($B7,carga_horaria[],2,FALSE)*HLOOKUP(K$3,'DIA UTEIS'!$B$4:$M$6,3,FALSE))-(HLOOKUP($B7,'EST. PROVAS'!$B$3:$Z$4,2,FALSE)*(VLOOKUP($B7,carga_horaria[],2,FALSE)/2)))+HLOOKUP(HR_A_FAZER[[#Headers],[SETEMBRO]],'DIAS FRACIONADOS'!$B$3:$Y$4,2,FALSE),(VLOOKUP($B7,carga_horaria[],2,FALSE)*(HLOOKUP(K$3,'DIA UTEIS'!$B$4:$M$6,3,FALSE)))+HLOOKUP(HR_A_FAZER[[#Headers],[SETEMBRO]],'DIAS FRACIONADOS'!$B$3:$Y$4,2,FALSE))) -> 7.2916667 | L7: =IF(VLOOKUP($B7,quadro_de_func[#All],3,FALSE)="MENOR APRENDIZ",VLOOKUP($B7,carga_horaria[],2,FALSE)*(HLOOKUP(L$3,'DIA UTEIS'!$B$4:$M$6,3,FALSE)+COUNTA('DIAS FRACIONADOS'!$B$6:$B$12)),IF(VLOOKUP($B7,quadro_de_func[#All],3,FALSE)="ESTAGIÁRIO",((VLOOKUP($B7,carga_horaria[],2,FALSE)*HLOOKUP(L$3,'DIA UTEIS'!$B$4:$M$6,3,FALSE))-(HLOOKUP($B7,'EST. PROVAS'!$B$3:$Z$4,2,FALSE)*(VLOOKUP($B7,carga_horaria[],2,FALSE)/2)))+HLOOKUP(HR_A_FAZER[[#Headers],[OUTUBRO]],'DIAS FRACIONADOS'!$B$3:$Y$4,2,FALSE),(VLOOKUP($B7,carga_horaria[],2,FALSE)*(HLOOKUP(L$3,'DIA UTEIS'!$B$4:$M$6,3,FALSE)))+HLOOKUP(HR_A_FAZER[[#Headers],[OUTUBRO]],'DIAS FRACIONADOS'!$B$3:$Y$4,2,FALSE))) -> 8.3854167 | M7: =IF(VLOOKUP($B7,quadro_de_func[#All],3,FALSE)="MENOR APRENDIZ",VLOOKUP($B7,carga_horaria[],2,FALSE)*(HLOOKUP(M$3,'DIA UTEIS'!$B$4:$M$6,3,FALSE)+COUNTA('DIAS FRACIONADOS'!$B$6:$B$12)),IF(VLOOKUP($B7,quadro_de_func[#All],3,FALSE)="ESTAGIÁRIO",((VLOOKUP($B7,carga_horaria[],2,FALSE)*HLOOKUP(M$3,'DIA UTEIS'!$B$4:$M$6,3,FALSE))-(HLOOKUP($B7,'EST. PROVAS'!$B$3:$Z$4,2,FALSE)*(VLOOKUP($B7,carga_horaria[],2,FALSE)/2)))+HLOOKUP(HR_A_FAZER[[#Headers],[NOVEMBRO]],'DIAS FRACIONADOS'!$B$3:$Y$4,2,FALSE),(VLOOKUP($B7,carga_horaria[],2,FALSE)*(HLOOKUP(M$3,'DIA UTEIS'!$B$4:$M$6,3,FALSE)))+HLOOKUP(HR_A_FAZER[[#Headers],[NOVEMBRO]],'DIAS FRACIONADOS'!$B$3:$Y$4,2,FALSE))) -> 7.2916667 | N7: =IF(VLOOKUP($B7,quadro_de_func[#All],3,FALSE)="MENOR APRENDIZ",VLOOKUP($B7,carga_horaria[],2,FALSE)*(HLOOKUP(N$3,'DIA UTEIS'!$B$4:$M$6,3,FALSE)+COUNTA('DIAS FRACIONADOS'!$B$6:$B$12)),IF(VLOOKUP($B7,quadro_de_func[#All],3,FALSE)="ESTAGIÁRIO",((VLOOKUP($B7,carga_horaria[],2,FALSE)*HLOOKUP(N$3,'DIA UTEIS'!$B$4:$M$6,3,FALSE))-(HLOOKUP($B7,'EST. PROVAS'!$B$3:$Z$4,2,FALSE)*(VLOOKUP($B7,carga_horaria[],2,FALSE)/2)))+HLOOKUP(HR_A_FAZER[[#Headers],[DEZEMBRO]],'DIAS FRACIONADOS'!$B$3:$Y$4,2,FALSE),(VLOOKUP($B7,carga_horaria[],2,FALSE)*(HLOOKUP(N$3,'DIA UTEIS'!$B$4:$M$6,3,FALSE)))+HLOOKUP(HR_A_FAZER[[#Headers],[DEZEMBRO]],'DIAS FRACIONADOS'!$B$3:$Y$4,2,FALSE))) -> 7.65625
B8: =quadro_de_func[[#This Row],[NOME]] -> func 5 | C8: =IF(VLOOKUP($B8,quadro_de_func[#All],3,FALSE)="MENOR APRENDIZ",VLOOKUP($B8,carga_horaria[],2,FALSE)*(HLOOKUP(C$3,'DIA UTEIS'!$B$4:$M$6,3,FALSE)+COUNTA('DIAS FRACIONADOS'!$B$6:$B$12)),IF(VLOOKUP($B8,quadro_de_func[#All],3,FALSE)="ESTAGIÁRIO",((VLOOKUP($B8,carga_horaria[],2,FALSE)*HLOOKUP(C$3,'DIA UTEIS'!$B$4:$M$6,3,FALSE))-(HLOOKUP($B8,'EST. PROVAS'!$B$3:$Z$4,2,FALSE)*(VLOOKUP($B8,carga_horaria[],2,FALSE)/2)))+HLOOKUP(HR_A_FAZER[[#Headers],[JANEIRO]],'DIAS FRACIONADOS'!$B$3:$Y$4,2,FALSE),(VLOOKUP($B8,carga_horaria[],2,FALSE)*(HLOOKUP(C$3,'DIA UTEIS'!$B$4:$M$6,3,FALSE)))+HLOOKUP(HR_A_FAZER[[#Headers],[JANEIRO]],'DIAS FRACIONADOS'!$B$3:$Y$4,2,FALSE))) -> 7.2083333 | D8: =IF(VLOOKUP($B8,quadro_de_func[#All],3,FALSE)="MENOR APRENDIZ",VLOOKUP($B8,carga_horaria[],2,FALSE)*(HLOOKUP(D$3,'DIA UTEIS'!$B$4:$M$6,3,FALSE)+COUNTA('DIAS FRACIONADOS'!$B$6:$B$12)),IF(VLOOKUP($B8,quadro_de_func[#All],3,FALSE)="ESTAGIÁRIO",((VLOOKUP($B8,carga_horaria[],2,FALSE)*HLOOKUP(D$3,'DIA UTEIS'!$B$4:$M$6,3,FALSE))-(HLOOKUP($B8,'EST. PROVAS'!$B$3:$Z$4,2,FALSE)*(VLOOKUP($B8,carga_horaria[],2,FALSE)/2)))+HLOOKUP(HR_A_FAZER[[#Headers],[FEVEREIRO]],'DIAS FRACIONADOS'!$B$3:$Y$4,2,FALSE),(VLOOKUP($B8,carga_horaria[],2,FALSE)*(HLOOKUP(D$3,'DIA UTEIS'!$B$4:$M$6,3,FALSE)))+HLOOKUP(HR_A_FAZER[[#Headers],[FEVEREIRO]],'DIAS FRACIONADOS'!$B$3:$Y$4,2,FALSE))) -> 6.6666667 | E8: =IF(VLOOKUP($B8,quadro_de_func[#All],3,FALSE)="MENOR APRENDIZ",VLOOKUP($B8,carga_horaria[],2,FALSE)*(HLOOKUP(E$3,'DIA UTEIS'!$B$4:$M$6,3,FALSE)+COUNTA('DIAS FRACIONADOS'!$B$6:$B$12)),IF(VLOOKUP($B8,quadro_de_func[#All],3,FALSE)="ESTAGIÁRIO",((VLOOKUP($B8,carga_horaria[],2,FALSE)*HLOOKUP(E$3,'DIA UTEIS'!$B$4:$M$6,3,FALSE))-(HLOOKUP($B8,'EST. PROVAS'!$B$3:$Z$4,2,FALSE)*(VLOOKUP($B8,carga_horaria[],2,FALSE)/2)))+HLOOKUP(HR_A_FAZER[[#Headers],[MARÇO]],'DIAS FRACIONADOS'!$B$3:$Y$4,2,FALSE),(VLOOKUP($B8,carga_horaria[],2,FALSE)*(HLOOKUP(E$3,'DIA UTEIS'!$B$4:$M$6,3,FALSE)))+HLOOKUP(HR_A_FAZER[[#Headers],[MARÇO]],'DIAS FRACIONADOS'!$B$3:$Y$4,2,FALSE))) -> 6.25 | F8: =IF(VLOOKUP($B8,quadro_de_func[#All],3,FALSE)="MENOR APRENDIZ",VLOOKUP($B8,carga_horaria[],2,FALSE)*(HLOOKUP(F$3,'DIA UTEIS'!$B$4:$M$6,3,FALSE)+COUNTA('DIAS FRACIONADOS'!$B$6:$B$12)),IF(VLOOKUP($B8,quadro_de_func[#All],3,FALSE)="ESTAGIÁRIO",((VLOOKUP($B8,carga_horaria[],2,FALSE)*HLOOKUP(F$3,'DIA UTEIS'!$B$4:$M$6,3,FALSE))-(HLOOKUP($B8,'EST. PROVAS'!$B$3:$Z$4,2,FALSE)*(VLOOKUP($B8,carga_horaria[],2,FALSE)/2)))+HLOOKUP(HR_A_FAZER[[#Headers],[ABRIL]],'DIAS FRACIONADOS'!$B$3:$Y$4,2,FALSE),(VLOOKUP($B8,carga_horaria[],2,FALSE)*(HLOOKUP(F$3,'DIA UTEIS'!$B$4:$M$6,3,FALSE)))+HLOOKUP(HR_A_FAZER[[#Headers],[ABRIL]],'DIAS FRACIONADOS'!$B$3:$Y$4,2,FALSE))) -> 7 | G8: =IF(VLOOKUP($B8,quadro_de_func[#All],3,FALSE)="MENOR APRENDIZ",VLOOKUP($B8,carga_horaria[],2,FALSE)*(HLOOKUP(G$3,'DIA UTEIS'!$B$4:$M$6,3,FALSE)+COUNTA('DIAS FRACIONADOS'!$B$6:$B$12)),IF(VLOOKUP($B8,quadro_de_func[#All],3,FALSE)="ESTAGIÁRIO",((VLOOKUP($B8,carga_horaria[],2,FALSE)*HLOOKUP(G$3,'DIA UTEIS'!$B$4:$M$6,3,FALSE))-(HLOOKUP($B8,'EST. PROVAS'!$B$3:$Z$4,2,FALSE)*(VLOOKUP($B8,carga_horaria[],2,FALSE)/2)))+HLOOKUP(HR_A_FAZER[[#Headers],[MAIO]],'DIAS FRACIONADOS'!$B$3:$Y$4,2,FALSE),(VLOOKUP($B8,carga_horaria[],2,FALSE)*(HLOOKUP(G$3,'DIA UTEIS'!$B$4:$M$6,3,FALSE)))+HLOOKUP(HR_A_FAZER[[#Headers],[MAIO]],'DIAS FRACIONADOS'!$B$3:$Y$4,2,FALSE))) -> 7.3333333 | H8: =IF(VLOOKUP($B8,quadro_de_func[#All],3,FALSE)="MENOR APRENDIZ",VLOOKUP($B8,carga_horaria[],2,FALSE)*(HLOOKUP(H$3,'DIA UTEIS'!$B$4:$M$6,3,FALSE)+COUNTA('DIAS FRACIONADOS'!$B$6:$B$12)),IF(VLOOKUP($B8,quadro_de_func[#All],3,FALSE)="ESTAGIÁRIO",((VLOOKUP($B8,carga_horaria[],2,FALSE)*HLOOKUP(H$3,'DIA UTEIS'!$B$4:$M$6,3,FALSE))-(HLOOKUP($B8,'EST. PROVAS'!$B$3:$Z$4,2,FALSE)*(VLOOKUP($B8,carga_horaria[],2,FALSE)/2)))+HLOOKUP(HR_A_FAZER[[#Headers],[JUNHO]],'DIAS FRACIONADOS'!$B$3:$Y$4,2,FALSE),(VLOOKUP($B8,carga_horaria[],2,FALSE)*(HLOOKUP(H$3,'DIA UTEIS'!$B$4:$M$6,3,FALSE)))+HLOOKUP(HR_A_FAZER[[#Headers],[JUNHO]],'DIAS FRACIONADOS'!$B$3:$Y$4,2,FALSE))) -> 6.3333333 | I8: =IF(VLOOKUP($B8,quadro_de_func[#All],3,FALSE)="MENOR APRENDIZ",VLOOKUP($B8,carga_horaria[],2,FALSE)*(HLOOKUP(I$3,'DIA UTEIS'!$B$4:$M$6,3,FALSE)+COUNTA('DIAS FRACIONADOS'!$B$6:$B$12)),IF(VLOOKUP($B8,quadro_de_func[#All],3,FALSE)="ESTAGIÁRIO",((VLOOKUP($B8,carga_horaria[],2,FALSE)*HLOOKUP(I$3,'DIA UTEIS'!$B$4:$M$6,3,FALSE))-(HLOOKUP($B8,'EST. PROVAS'!$B$3:$Z$4,2,FALSE)*(VLOOKUP($B8,carga_horaria[],2,FALSE)/2)))+HLOOKUP(HR_A_FAZER[[#Headers],[JULHO]],'DIAS FRACIONADOS'!$B$3:$Y$4,2,FALSE),(VLOOKUP($B8,carga_horaria[],2,FALSE)*(HLOOKUP(I$3,'DIA UTEIS'!$B$4:$M$6,3,FALSE)))+HLOOKUP(HR_A_FAZER[[#Headers],[JULHO]],'DIAS FRACIONADOS'!$B$3:$Y$4,2,FALSE))) -> 7.3333333 | J8: =IF(VLOOKUP($B8,quadro_de_func[#All],3,FALSE)="MENOR APRENDIZ",VLOOKUP($B8,carga_horaria[],2,FALSE)*(HLOOKUP(J$3,'DIA UTEIS'!$B$4:$M$6,3,FALSE)+COUNTA('DIAS FRACIONADOS'!$B$6:$B$12)),IF(VLOOKUP($B8,quadro_de_func[#All],3,FALSE)="ESTAGIÁRIO",((VLOOKUP($B8,carga_horaria[],2,FALSE)*HLOOKUP(J$3,'DIA UTEIS'!$B$4:$M$6,3,FALSE))-(HLOOKUP($B8,'EST. PROVAS'!$B$3:$Z$4,2,FALSE)*(VLOOKUP($B8,carga_horaria[],2,FALSE)/2)))+HLOOKUP(HR_A_FAZER[[#Headers],[AGOSTO]],'DIAS FRACIONADOS'!$B$3:$Y$4,2,FALSE),(VLOOKUP($B8,carga_horaria[],2,FALSE)*(HLOOKUP(J$3,'DIA UTEIS'!$B$4:$M$6,3,FALSE)))+HLOOKUP(HR_A_FAZER[[#Headers],[AGOSTO]],'DIAS FRACIONADOS'!$B$3:$Y$4,2,FALSE))) -> 7.3333333 | K8: =IF(VLOOKUP($B8,quadro_de_func[#All],3,FALSE)="MENOR APRENDIZ",VLOOKUP($B8,carga_horaria[],2,FALSE)*(HLOOKUP(K$3,'DIA UTEIS'!$B$4:$M$6,3,FALSE)+COUNTA('DIAS FRACIONADOS'!$B$6:$B$12)),IF(VLOOKUP($B8,quadro_de_func[#All],3,FALSE)="ESTAGIÁRIO",((VLOOKUP($B8,carga_horaria[],2,FALSE)*HLOOKUP(K$3,'DIA UTEIS'!$B$4:$M$6,3,FALSE))-(HLOOKUP($B8,'EST. PROVAS'!$B$3:$Z$4,2,FALSE)*(VLOOKUP($B8,carga_horaria[],2,FALSE)/2)))+HLOOKUP(HR_A_FAZER[[#Headers],[SETEMBRO]],'DIAS FRACIONADOS'!$B$3:$Y$4,2,FALSE),(VLOOKUP($B8,carga_horaria[],2,FALSE)*(HLOOKUP(K$3,'DIA UTEIS'!$B$4:$M$6,3,FALSE)))+HLOOKUP(HR_A_FAZER[[#Headers],[SETEMBRO]],'DIAS FRACIONADOS'!$B$3:$Y$4,2,FALSE))) -> 6.6666667 | L8: =IF(VLOOKUP($B8,quadro_de_func[#All],3,FALSE)="MENOR APRENDIZ",VLOOKUP($B8,carga_horaria[],2,FALSE)*(HLOOKUP(L$3,'DIA UTEIS'!$B$4:$M$6,3,FALSE)+COUNTA('DIAS FRACIONADOS'!$B$6:$B$12)),IF(VLOOKUP($B8,quadro_de_func[#All],3,FALSE)="ESTAGIÁRIO",((VLOOKUP($B8,carga_horaria[],2,FALSE)*HLOOKUP(L$3,'DIA UTEIS'!$B$4:$M$6,3,FALSE))-(HLOOKUP($B8,'EST. PROVAS'!$B$3:$Z$4,2,FALSE)*(VLOOKUP($B8,carga_horaria[],2,FALSE)/2)))+HLOOKUP(HR_A_FAZER[[#Headers],[OUTUBRO]],'DIAS FRACIONADOS'!$B$3:$Y$4,2,FALSE),(VLOOKUP($B8,carga_horaria[],2,FALSE)*(HLOOKUP(L$3,'DIA UTEIS'!$B$4:$M$6,3,FALSE)))+HLOOKUP(HR_A_FAZER[[#Headers],[OUTUBRO]],'DIAS FRACIONADOS'!$B$3:$Y$4,2,FALSE))) -> 7.6666667 | M8: =IF(VLOOKUP($B8,quadro_de_func[#All],3,FALSE)="MENOR APRENDIZ",VLOOKUP($B8,carga_horaria[],2,FALSE)*(HLOOKUP(M$3,'DIA UTEIS'!$B$4:$M$6,3,FALSE)+COUNTA('DIAS FRACIONADOS'!$B$6:$B$12)),IF(VLOOKUP($B8,quadro_de_func[#All],3,FALSE)="ESTAGIÁRIO",((VLOOKUP($B8,carga_horaria[],2,FALSE)*HLOOKUP(M$3,'DIA UTEIS'!$B$4:$M$6,3,FALSE))-(HLOOKUP($B8,'EST. PROVAS'!$B$3:$Z$4,2,FALSE)*(VLOOKUP($B8,carga_horaria[],2,FALSE)/2)))+HLOOKUP(HR_A_FAZER[[#Headers],[NOVEMBRO]],'DIAS FRACIONADOS'!$B$3:$Y$4,2,FALSE),(VLOOKUP($B8,carga_horaria[],2,FALSE)*(HLOOKUP(M$3,'DIA UTEIS'!$B$4:$M$6,3,FALSE)))+HLOOKUP(HR_A_FAZER[[#Headers],[NOVEMBRO]],'DIAS FRACIONADOS'!$B$3:$Y$4,2,FALSE))) -> 6.6666667 | N8: =IF(VLOOKUP($B8,quadro_de_func[#All],3,FALSE)="MENOR APRENDIZ",VLOOKUP($B8,carga_horaria[],2,FALSE)*(HLOOKUP(N$3,'DIA UTEIS'!$B$4:$M$6,3,FALSE)+COUNTA('DIAS FRACIONADOS'!$B$6:$B$12)),IF(VLOOKUP($B8,quadro_de_func[#All],3,FALSE)="ESTAGIÁRIO",((VLOOKUP($B8,carga_horaria[],2,FALSE)*HLOOKUP(N$3,'DIA UTEIS'!$B$4:$M$6,3,FALSE))-(HLOOKUP($B8,'EST. PROVAS'!$B$3:$Z$4,2,FALSE)*(VLOOKUP($B8,carga_horaria[],2,FALSE)/2)))+HLOOKUP(HR_A_FAZER[[#Headers],[DEZEMBRO]],'DIAS FRACIONADOS'!$B$3:$Y$4,2,FALSE),(VLOOKUP($B8,carga_horaria[],2,FALSE)*(HLOOKUP(N$3,'DIA UTEIS'!$B$4:$M$6,3,FALSE)))+HLOOKUP(HR_A_FAZER[[#Headers],[DEZEMBRO]],'DIAS FRACIONADOS'!$B$3:$Y$4,2,FALSE))) -> 7
B9: =quadro_de_func[[#This Row],[NOME]] -> func 6 | C9: =IF(VLOOKUP($B9,quadro_de_func[#All],3,FALSE)="MENOR APRENDIZ",VLOOKUP($B9,carga_horaria[],2,FALSE)*(HLOOKUP(C$3,'DIA UTEIS'!$B$4:$M$6,3,FALSE)+COUNTA('DIAS FRACIONADOS'!$B$6:$B$12)),IF(VLOOKUP($B9,quadro_de_func[#All],3,FALSE)="ESTAGIÁRIO",((VLOOKUP($B9,carga_horaria[],2,FALSE)*HLOOKUP(C$3,'DIA UTEIS'!$B$4:$M$6,3,FALSE))-(HLOOKUP($B9,'EST. PROVAS'!$B$3:$Z$4,2,FALSE)*(VLOOKUP($B9,carga_horaria[],2,FALSE)/2)))+HLOOKUP(HR_A_FAZER[[#Headers],[JANEIRO]],'DIAS FRACIONADOS'!$B$3:$Y$4,2,FALSE),(VLOOKUP($B9,carga_horaria[],2,FALSE)*(HLOOKUP(C$3,'DIA UTEIS'!$B$4:$M$6,3,FALSE)))+HLOOKUP(HR_A_FAZER[[#Headers],[JANEIRO]],'DIAS FRACIONADOS'!$B$3:$Y$4,2,FALSE))) -> 5.4583333 | D9: =IF(VLOOKUP($B9,quadro_de_func[#All],3,FALSE)="MENOR APRENDIZ",VLOOKUP($B9,carga_horaria[],2,FALSE)*(HLOOKUP(D$3,'DIA UTEIS'!$B$4:$M$6,3,FALSE)+COUNTA('DIAS FRACIONADOS'!$B$6:$B$12)),IF(VLOOKUP($B9,quadro_de_func[#All],3,FALSE)="ESTAGIÁRIO",((VLOOKUP($B9,carga_horaria[],2,FALSE)*HLOOKUP(D$3,'DIA UTEIS'!$B$4:$M$6,3,FALSE))-(HLOOKUP($B9,'EST. PROVAS'!$B$3:$Z$4,2,FALSE)*(VLOOKUP($B9,carga_horaria[],2,FALSE)/2)))+HLOOKUP(HR_A_FAZER[[#Headers],[FEVEREIRO]],'DIAS FRACIONADOS'!$B$3:$Y$4,2,FALSE),(VLOOKUP($B9,carga_horaria[],2,FALSE)*(HLOOKUP(D$3,'DIA UTEIS'!$B$4:$M$6,3,FALSE)))+HLOOKUP(HR_A_FAZER[[#Headers],[FEVEREIRO]],'DIAS FRACIONADOS'!$B$3:$Y$4,2,FALSE))) -> 5 | E9: =IF(VLOOKUP($B9,quadro_de_func[#All],3,FALSE)="MENOR APRENDIZ",VLOOKUP($B9,carga_horaria[],2,FALSE)*(HLOOKUP(E$3,'DIA UTEIS'!$B$4:$M$6,3,FALSE)+COUNTA('DIAS FRACIONADOS'!$B$6:$B$12)),IF(VLOOKUP($B9,quadro_de_func[#All],3,FALSE)="ESTAGIÁRIO",((VLOOKUP($B9,carga_horaria[],2,FALSE)*HLOOKUP(E$3,'DIA UTEIS'!$B$4:$M$6,3,FALSE))-(HLOOKUP($B9,'EST. PROVAS'!$B$3:$Z$4,2,FALSE)*(VLOOKUP($B9,carga_horaria[],2,FALSE)/2)))+HLOOKUP(HR_A_FAZER[[#Headers],[MARÇO]],'DIAS FRACIONADOS'!$B$3:$Y$4,2,FALSE),(VLOOKUP($B9,carga_horaria[],2,FALSE)*(HLOOKUP(E$3,'DIA UTEIS'!$B$4:$M$6,3,FALSE)))+HLOOKUP(HR_A_FAZER[[#Headers],[MARÇO]],'DIAS FRACIONADOS'!$B$3:$Y$4,2,FALSE))) -> 4.75 | F9: =IF(VLOOKUP($B9,quadro_de_func[#All],3,FALSE)="MENOR APRENDIZ",VLOOKUP($B9,carga_horaria[],2,FALSE)*(HLOOKUP(F$3,'DIA UTEIS'!$B$4:$M$6,3,FALSE)+COUNTA('DIAS FRACIONADOS'!$B$6:$B$12)),IF(VLOOKUP($B9,quadro_de_func[#All],3,FALSE)="ESTAGIÁRIO",((VLOOKUP($B9,carga_horaria[],2,FALSE)*HLOOKUP(F$3,'DIA UTEIS'!$B$4:$M$6,3,FALSE))-(HLOOKUP($B9,'EST. PROVAS'!$B$3:$Z$4,2,FALSE)*(VLOOKUP($B9,carga_horaria[],2,FALSE)/2)))+HLOOKUP(HR_A_FAZER[[#Headers],[ABRIL]],'DIAS FRACIONADOS'!$B$3:$Y$4,2,FALSE),(VLOOKUP($B9,carga_horaria[],2,FALSE)*(HLOOKUP(F$3,'DIA UTEIS'!$B$4:$M$6,3,FALSE)))+HLOOKUP(HR_A_FAZER[[#Headers],[ABRIL]],'DIAS FRACIONADOS'!$B$3:$Y$4,2,FALSE))) -> 5.25 | G9: =IF(VLOOKUP($B9,quadro_de_func[#All],3,FALSE)="MENOR APRENDIZ",VLOOKUP($B9,carga_horaria[],2,FALSE)*(HLOOKUP(G$3,'DIA UTEIS'!$B$4:$M$6,3,FALSE)+COUNTA('DIAS FRACIONADOS'!$B$6:$B$12)),IF(VLOOKUP($B9,quadro_de_func[#All],3,FALSE)="ESTAGIÁRIO",((VLOOKUP($B9,carga_horaria[],2,FALSE)*HLOOKUP(G$3,'DIA UTEIS'!$B$4:$M$6,3,FALSE))-(HLOOKUP($B9,'EST. PROVAS'!$B$3:$Z$4,2,FALSE)*(VLOOKUP($B9,carga_horaria[],2,FALSE)/2)))+HLOOKUP(HR_A_FAZER[[#Headers],[MAIO]],'DIAS FRACIONADOS'!$B$3:$Y$4,2,FALSE),(VLOOKUP($B9,carga_horaria[],2,FALSE)*(HLOOKUP(G$3,'DIA UTEIS'!$B$4:$M$6,3,FALSE)))+HLOOKUP(HR_A_FAZER[[#Headers],[MAIO]],'DIAS FRACIONADOS'!$B$3:$Y$4,2,FALSE))) -> 5.5 | H9: =IF(VLOOKUP($B9,quadro_de_func[#All],3,FALSE)="MENOR APRENDIZ",VLOOKUP($B9,carga_horaria[],2,FALSE)*(HLOOKUP(H$3,'DIA UTEIS'!$B$4:$M$6,3,FALSE)+COUNTA('DIAS FRACIONADOS'!$B$6:$B$12)),IF(VLOOKUP($B9,quadro_de_func[#All],3,FALSE)="ESTAGIÁRIO",((VLOOKUP($B9,carga_horaria[],2,FALSE)*HLOOKUP(H$3,'DIA UTEIS'!$B$4:$M$6,3,FALSE))-(HLOOKUP($B9,'EST. PROVAS'!$B$3:$Z$4,2,FALSE)*(VLOOKUP($B9,carga_horaria[],2,FALSE)/2)))+HLOOKUP(HR_A_FAZER[[#Headers],[JUNHO]],'DIAS FRACIONADOS'!$B$3:$Y$4,2,FALSE),(VLOOKUP($B9,carga_horaria[],2,FALSE)*(HLOOKUP(H$3,'DIA UTEIS'!$B$4:$M$6,3,FALSE)))+HLOOKUP(HR_A_FAZER[[#Headers],[JUNHO]],'DIAS FRACIONADOS'!$B$3:$Y$4,2,FALSE))) -> 4.75 | I9: =IF(VLOOKUP($B9,quadro_de_func[#All],3,FALSE)="MENOR APRENDIZ",VLOOKUP($B9,carga_horaria[],2,FALSE)*(HLOOKUP(I$3,'DIA UTEIS'!$B$4:$M$6,3,FALSE)+COUNTA('DIAS FRACIONADOS'!$B$6:$B$12)),IF(VLOOKUP($B9,quadro_de_func[#All],3,FALSE)="ESTAGIÁRIO",((VLOOKUP($B9,carga_horaria[],2,FALSE)*HLOOKUP(I$3,'DIA UTEIS'!$B$4:$M$6,3,FALSE))-(HLOOKUP($B9,'EST. PROVAS'!$B$3:$Z$4,2,FALSE)*(VLOOKUP($B9,carga_horaria[],2,FALSE)/2)))+HLOOKUP(HR_A_FAZER[[#Headers],[JULHO]],'DIAS FRACIONADOS'!$B$3:$Y$4,2,FALSE),(VLOOKUP($B9,carga_horaria[],2,FALSE)*(HLOOKUP(I$3,'DIA UTEIS'!$B$4:$M$6,3,FALSE)))+HLOOKUP(HR_A_FAZER[[#Headers],[JULHO]],'DIAS FRACIONADOS'!$B$3:$Y$4,2,FALSE))) -> 5.5 | J9: =IF(VLOOKUP($B9,quadro_de_func[#All],3,FALSE)="MENOR APRENDIZ",VLOOKUP($B9,carga_horaria[],2,FALSE)*(HLOOKUP(J$3,'DIA UTEIS'!$B$4:$M$6,3,FALSE)+COUNTA('DIAS FRACIONADOS'!$B$6:$B$12)),IF(VLOOKUP($B9,quadro_de_func[#All],3,FALSE)="ESTAGIÁRIO",((VLOOKUP($B9,carga_horaria[],2,FALSE)*HLOOKUP(J$3,'DIA UTEIS'!$B$4:$M$6,3,FALSE))-(HLOOKUP($B9,'EST. PROVAS'!$B$3:$Z$4,2,FALSE)*(VLOOKUP($B9,carga_horaria[],2,FALSE)/2)))+HLOOKUP(HR_A_FAZER[[#Headers],[AGOSTO]],'DIAS FRACIONADOS'!$B$3:$Y$4,2,FALSE),(VLOOKUP($B9,carga_horaria[],2,FALSE)*(HLOOKUP(J$3,'DIA UTEIS'!$B$4:$M$6,3,FALSE)))+HLOOKUP(HR_A_FAZER[[#Headers],[AGOSTO]],'DIAS FRACIONADOS'!$B$3:$Y$4,2,FALSE))) -> 5.5 | K9: =IF(VLOOKUP($B9,quadro_de_func[#All],3,FALSE)="MENOR APRENDIZ",VLOOKUP($B9,carga_horaria[],2,FALSE)*(HLOOKUP(K$3,'DIA UTEIS'!$B$4:$M$6,3,FALSE)+COUNTA('DIAS FRACIONADOS'!$B$6:$B$12)),IF(VLOOKUP($B9,quadro_de_func[#All],3,FALSE)="ESTAGIÁRIO",((VLOOKUP($B9,carga_horaria[],2,FALSE)*HLOOKUP(K$3,'DIA UTEIS'!$B$4:$M$6,3,FALSE))-(HLOOKUP($B9,'EST. PROVAS'!$B$3:$Z$4,2,FALSE)*(VLOOKUP($B9,carga_horaria[],2,FALSE)/2)))+HLOOKUP(HR_A_FAZER[[#Headers],[SETEMBRO]],'DIAS FRACIONADOS'!$B$3:$Y$4,2,FALSE),(VLOOKUP($B9,carga_horaria[],2,FALSE)*(HLOOKUP(K$3,'DIA UTEIS'!$B$4:$M$6,3,FALSE)))+HLOOKUP(HR_A_FAZER[[#Headers],[SETEMBRO]],'DIAS FRACIONADOS'!$B$3:$Y$4,2,FALSE))) -> 5 | L9: =IF(VLOOKUP($B9,quadro_de_func[#All],3,FALSE)="MENOR APRENDIZ",VLOOKUP($B9,carga_horaria[],2,FALSE)*(HLOOKUP(L$3,'DIA UTEIS'!$B$4:$M$6,3,FALSE)+COUNTA('DIAS FRACIONADOS'!$B$6:$B$12)),IF(VLOOKUP($B9,quadro_de_func[#All],3,FALSE)="ESTAGIÁRIO",((VLOOKUP($B9,carga_horaria[],2,FALSE)*HLOOKUP(L$3,'DIA UTEIS'!$B$4:$M$6,3,FALSE))-(HLOOKUP($B9,'EST. PROVAS'!$B$3:$Z$4,2,FALSE)*(VLOOKUP($B9,carga_horaria[],2,FALSE)/2)))+HLOOKUP(HR_A_FAZER[[#Headers],[OUTUBRO]],'DIAS FRACIONADOS'!$B$3:$Y$4,2,FALSE),(VLOOKUP($B9,carga_horaria[],2,FALSE)*(HLOOKUP(L$3,'DIA UTEIS'!$B$4:$M$6,3,FALSE)))+HLOOKUP(HR_A_FAZER[[#Headers],[OUTUBRO]],'DIAS FRACIONADOS'!$B$3:$Y$4,2,FALSE))) -> 5.75 | M9: =IF(VLOOKUP($B9,quadro_de_func[#All],3,FALSE)="MENOR APRENDIZ",VLOOKUP($B9,carga_horaria[],2,FALSE)*(HLOOKUP(M$3,'DIA UTEIS'!$B$4:$M$6,3,FALSE)+COUNTA('DIAS FRACIONADOS'!$B$6:$B$12)),IF(VLOOKUP($B9,quadro_de_func[#All],3,FALSE)="ESTAGIÁRIO",((VLOOKUP($B9,carga_horaria[],2,FALSE)*HLOOKUP(M$3,'DIA UTEIS'!$B$4:$M$6,3,FALSE))-(HLOOKUP($B9,'EST. PROVAS'!$B$3:$Z$4,2,FALSE)*(VLOOKUP($B9,carga_horaria[],2,FALSE)/2)))+HLOOKUP(HR_A_FAZER[[#Headers],[NOVEMBRO]],'DIAS FRACIONADOS'!$B$3:$Y$4,2,FALSE),(VLOOKUP($B9,carga_horaria[],2,FALSE)*(HLOOKUP(M$3,'DIA UTEIS'!$B$4:$M$6,3,FALSE)))+HLOOKUP(HR_A_FAZER[[#Headers],[NOVEMBRO]],'DIAS FRACIONADOS'!$B$3:$Y$4,2,FALSE))) -> 5 | N9: =IF(VLOOKUP($B9,quadro_de_func[#All],3,FALSE)="MENOR APRENDIZ",VLOOKUP($B9,carga_horaria[],2,FALSE)*(HLOOKUP(N$3,'DIA UTEIS'!$B$4:$M$6,3,FALSE)+COUNTA('DIAS FRACIONADOS'!$B$6:$B$12)),IF(VLOOKUP($B9,quadro_de_func[#All],3,FALSE)="ESTAGIÁRIO",((VLOOKUP($B9,carga_horaria[],2,FALSE)*HLOOKUP(N$3,'DIA UTEIS'!$B$4:$M$6,3,FALSE))-(HLOOKUP($B9,'EST. PROVAS'!$B$3:$Z$4,2,FALSE)*(VLOOKUP($B9,carga_horaria[],2,FALSE)/2)))+HLOOKUP(HR_A_FAZER[[#Headers],[DEZEMBRO]],'DIAS FRACIONADOS'!$B$3:$Y$4,2,FALSE),(VLOOKUP($B9,carga_horaria[],2,FALSE)*(HLOOKUP(N$3,'DIA UTEIS'!$B$4:$M$6,3,FALSE)))+HLOOKUP(HR_A_FAZER[[#Headers],[DEZEMBRO]],'DIAS FRACIONADOS'!$B$3:$Y$4,2,FALSE))) -> 5.25
