Workbook

Sheet Fórmula
B1: Fernando S. Ribeiro | C1: Dados de Contato | D1: Tel. 11 947796708 | E1: fsrfernando1985@gmail.com
B3: Base INSS | D3: ='Relatório da Folha'!E31 -> 1652.9697 | E3: *** Neste campo informar o base de INSS da folha.
B4: Tipo | C4: Calculo | D4: Valor descontado
B5: Faixa 1 - R$ 1.100,00 | C5: =IF(D3>=1100,"R$ 1100,00",IF(D3<=1100,D3,)) -> R$ 1100,00 | D5: =SUM(C5*7.5%) -> 82.5
B6: Faixa 2 - R$ 2.203,48 | C6: =IF(D3<=1100,"0",IF(D3<=2203.48,D3-1100,IF(D3>2203.48,2203.48-C5))) -> 552.9697 | D6: =SUM(C6*9%) -> 49.767273
B7: Faixa 3 - R$ 3.305,22 | C7: =IF(D3<=2203.48,"0",IF(D3<=3305.22,D3-C5-C6,IF(D3>3305.22,3305.22-C6-C5))) -> 0 | D7: =SUM(C7*12%) -> 0
B8: Faixa 4 - R$ 6.433,57 | C8: =IF(D3<=3305.22,"0",IF(D3<6433.57,D3-C7-C6-C5,IF(D3>6433.57,6433.57-C7-C6-C5))) -> 0 | D8: =SUM(C8*14%) -> 0
B9: Total | C9: =SUM(C5:C8) -> 552.9697 | D9: =SUM(D5:D8) -> 132.26727
B11: Salário Família | C11: =IF(D3<=1503.27,"R$ 51,27",IF(D3>1503.27,D2,)) -> 0 | D11: =IF(C14=0,"R$ 0",IF(C14>0,C11,)) -> R$ 0
B13: Base de Cálculo de IR
B14: Dependentes | C14: ='Relatório da Folha'!E7 -> 0 | D14: *** Neste campo informar a quantidade de Dependentes
B15: Valor de INSS Base de Cálculo | C15: =$D$3-$D$9 -> 1520.7024
B17: Faixas | E17: Base de Cálculo | G17: Dependentes | I17: Alíquota DARF | J17: Valor de IR
C18: =IF($C$15<B19,0,IF(,$C$15>=B19,$C$15)) -> 0 | G18: =IF(F19=0,0,IF(,F19<0,C14*189.59)) -> 0 | H18: 100 | I18: 7.5 | J18: 142.8
B19: 1903.99 | C19: =IF(,$C$18<=B21,$C$18) -> 0 | D19: =IF($C$19>B22,0,IF(,$C$19<=B21,$C$19)) -> 0 | E19: =D19 -> 0 | F19: =E19 -> 0 | G19: =F19-G18 -> 0 | H19: =G19/H18 -> 0 | I19: =H19*I18 -> 0 | J19: =IF(I19=0,0,IF(,I19>0,I19-J18)) -> 0
B21: 2826.65 | C21: =IF($C$15<B22,0,IF(,$C$15>=B22,$C$15)) -> 0 | G21: =IF(F22=0,0,IF(,F22<0,C14*189.59)) -> 0 | H21: 100 | I21: 15 | J21: 354.8
B22: 2826.66 | C22: =IF(,$C$21>=B22,$C$21) -> 0 | D22: =IF($C$22>B25,0,IF(,$C$22<=B24,$C$22)) -> 0 | E22: =D22 -> 0 | F22: =E22 -> 0 | G22: =F22-G21 -> 0 | H22: =G22/H21 -> 0 | I22: =H22*I21 -> 0 | J22: =IF(I22=0,0,IF(,I22>0,I22-J21)) -> 0
B24: 3751.05 | C24: =IF($C$15<B25,0,IF(,$C$15>=B25,$C$15)) -> 0 | G24: =IF(F25=0,0,IF(,F25<0,C14*189.59)) -> 0 | H24: 100 | I24: 22.5 | J24: 636.13
B25: 3751.06 | C25: =IF(,$C$24>=B25,$C$24) -> 0 | D25: =IF($C$25>B28,0,IF(,$C$25<=B27,$C$25)) -> 0 | E25: =D25 -> 0 | F25: =E25 -> 0 | G25: =F25-G24 -> 0 | H25: =G25/H24 -> 0 | I25: =H25*I24 -> 0 | J25: =IF(I25=0,0,IF(,I25>0,I25-J24)) -> 0
B27: 4664.68 | C27: =IF($C$15<B28,0,IF(,$C$15>=B28,$C$15)) -> 0 | G27: =IF(F28=0,0,IF(,F28<0,C14*189.59)) -> 0 | H27: 100 | I27: 27.5 | J27: 869.36
B28: 4664.69 | C28: =IF(,$C$27>=B28,$C$27) -> 0 | D28: =IF($C$28<B30,$C$28,IF(,$C$28>=B31,0)) -> 0 | E28: =D28 -> 0 | F28: =E28 -> 0 | G28: =F28-G27 -> 0 | H28: =G28/H27 -> 0 | I28: =H28*I27 -> 0 | J28: =IF(I28=0,0,IF(,I28>0,I28-J27)) -> 0
I29: Valor de IR | J29: =SUM(J19+J22+J25+J28) -> 0
B30: 9999999999
B31: 9999999999

Sheet Relatório da Folha
B1: Fernando S. Ribeiro | C1: Dados de Contato | D1: Tel. 11 947796708 | E1: fsrfernando1985@gmail.com
B3: Somente os Campos em Amarelo estão liberados para Edição
B5: Teto Máximo de Contribuição R$ 6.433,57 = INSS de R$ 751,99
B6: Empregado 01
B7: Dependentes Menores de Idade e Conjuge | E7: 0
B9: Proventos | E9: Campos digitáveis
B10: Salário Bruto: | E10: 1300
B11: Valor de Comissão | E11: 0
C12: Dias Úteis | D12: Domingos e Feriados
B13: DSR Sobre Comissão | C13: 22 | D13: 8 | E13: =(E11/C13)*D13 -> 0
B14: Bonus e Gratificações | E14: 0
C15: Percentual | D15: Quantidade de Horas
C16: 60 | D16: 0
B17: Horas Extras | C17: =((((E10+E11+E13)/220)/100)*C16)+((E10+E11+E13)/220) -> 9.4545455 | D17: =C17*D16 -> 0 | E17: =D17 -> 0
C18: Dias Úteis | D18: Domingos e Feriados
B19: DSR Sobre Horas Extras | C19: 22 | D19: 8 | E19: =(E17/C19)*D19 -> 0
C20: Percentual | D20: Quantidade de Horas
C21: 100 | D21: 25.6
B22: Horas Extras | C22: =((((E10+E11+E13)/220)/100)*C21)+((E10+E11+E13)/220) -> 11.818182 | D22: =C22*D21 -> 302.54545 | E22: =D22 -> 302.54545
C23: Dias Úteis | D23: Domingos e Feriados
B24: DSR Sobre Horas Extras | C24: 24 | D24: 4 | E24: =(E22/C24)*D24 -> 50.424242
C25: Percentual | D25: Quantidade de Horas
C26: 30 | D26: 0
B27: Adicional Noturno | C27: =((((E10+E11)/220)/100)*C26) -> 1.7727273 | D27: =C27*D26 -> 0 | E27: =D27 -> 0
C28: Dias Úteis | D28: Domingos e Feriados
B29: DSR Sobre Horas Extras | C29: 22 | D29: 8 | E29: =(E27/C29)*D29 -> 0
B30: Salário Família | C30: 51.27 | D30: =Fórmula!D11 -> R$ 0
D31: Valor Bruto Total | E31: =SUM(E10:E30) -> 1652.9697
D32: Valor Líquido Total | E32: =E31+D30 -> 1652.9697
B34: Descontos
B35: Valor de INSS | E35: =Fórmula!D9 -> 132.26727
B36: Valor de FGTS (Não é descontado do Empregado Em Folha) | E36: =(E31/100)*8 -> 132.23758
B37: Valor de IR Faixa 01 (Valores > R$ 10,00 não são considerados) | E37: =Fórmula!J19 -> 0
B38: Valor de IR Faixa 02 | E38: =Fórmula!J22 -> 0
B39: Valor de IR Faixa 03 | E39: =Fórmula!J25 -> 0
B40: Valor de IR Faixa 04 | E40: =Fórmula!J28 -> 0
B41: Desconto de Adiantamento de 40% | C41: 0 | E41: =(E10/100)*C41 -> 0
B42: Demais Descontos Sem Incidência nos Tributos | C42: 0 | E42: =C42 -> 0
B43: Desconto de Vale Transporte Até 06% Vide Observação* | C43: 3700 | D43: 0 | E43: =(C43/100)*D43 -> 0
D44: Valor Total | E44: =SUM(E37:E43)+E35 -> 132.26727
...

Sheet Custo ao Empregador
B1: Fernando S. Ribeiro | C1: Dados de Contato | D1: Tel. 11 947796708 | E1: fsrfernando1985@gmail.com
B4: Empresa Optante Pelo Simples
B5: Guia de INSS Empresa Simples Código 2003 | C5: ='Relatório da Folha'!C49 -> 132.26727
B6: Guia de FGTS de 08% Sobre Rendimentos | C6: ='Relatório da Folha'!C50 -> 132.23758
B7: Guia de IRRF Sobre Folha de Pag Empregado | C7: ='Relatório da Folha'!C51 -> 0
B8: Desconto de INSS Sobre Salário Família | C8: ='Relatório da Folha'!C52 -> R$ 0
B9: Valor Total das Guias Trabalhistas | C9: =SUM(C5:C8)-C8 -> 264.50485
B12: Empresa Não Optante Pelo Simples
B13: Guia de FGTS de 08% Sobre Rendimentos | C13: ='Relatório da Folha'!D58 -> 132.23758
B14: Guia de IRRF Sobre Folha de Pag Empregado | C14: ='Relatório da Folha'!D59 -> 0
B15: Desconto de INSS Sobre Salário Família | C15: ='Relatório da Folha'!D60 -> R$ 0
B16: Guia de INSS Empresa Segurados | C16: ='Relatório da Folha'!D61 -> 132.26727
B17: Guia de INSS Empresa Empresa | C17: ='Relatório da Folha'!D62 -> 347.12364
B18: Guia de INSS Empresa Terceiros | C18: ='Relatório da Folha'!D63 -> 95.872242
B20: Valor Total da Guia GPS Código 2100 | C20: =SUM(C16:C18)-C15 -> 575.26315
B22: Valor Total das Guias Trabalhistas | C22: =SUM(C13:C18)-C14 -> 707.50073
B24: Valor Líquido do Salário do Empregado | C24: ='Relatório da Folha'!E46 -> 1520.7024
B27: *Observação Importante! A Guia de IR Sobre a Folha e o INSS Descontado do Empregado não são considerados como Custo ao Empregador, uma vez que é descontado do Empregado e repassado ao governo
