Workbook
Name NativeTimeline_DATA: #N/A

Sheet Apresentação
D9: Planilha Grátis Excel - Orçamento familiar / Despesas pessoais
D11: Planilha produzida para o site ExcelSolução.com.br - ©Diretos Reservados
E16: Conheça a versão completa desta planilha:

Sheet Orçamento
D2: Planilha de orçamento pessoal com gráficos - Excel Solução
D3: Personalizamos para sua necessidade.
D4: Entre em contato: contato@excelsolucao.com.br
C6: Janeiro | D6: Fevereiro | E6: Março | F6: Abril | G6: Maio | H6: Junho | I6: Julho | J6: Agosto | K6: Setembro | L6: Outubro | M6: Novembro | N6: Dezembro | O6: Soma-Ano
B9: Receitas
B10: Salário | C10: 4000 | O10: =SUM(C10:N10) -> 4000
B11: Outras Receitas | C11: 1000 | O11: =SUM(C11:N11) -> 1000
B12: Total | C12: =SUM(C10:C11) -> 5000 | D12: =SUM(D10:D11) -> 0 | E12: =SUM(E10:E11) -> 0 | F12: =SUM(F10:F11) -> 0 | G12: =SUM(G10:G11) -> 0 | H12: =SUM(H10:H11) -> 0 | I12: =SUM(I10:I11) -> 0 | J12: =SUM(J10:J11) -> 0 | ... N12: =SUM(N10:N11) -> 0 | O12: =SUM(C12:N12) -> 5000
B15: Despesas - Moradia
B16: Aluguel | C16: 1200 | O16: =SUM(C16:N16) -> 1200
B17: Condomínio | C17: - | O17: =SUM(C17:N17) -> 0 | P17: 0
B18: Água | C18: 60 | O18: =SUM(C18:N18) -> 60
B19: Energia Elétrica | C19: 70 | O19: =SUM(C19:N19) -> 70
B20: Gás | C20: 20 | O20: =SUM(C20:N20) -> 20
B21: Telefone | C21: 90 | O21: =SUM(C21:N21) -> 90
B22: Internet | C22: 120 | O22: =SUM(C22:N22) -> 120
B23: Tv a Cabo | C23: 40 | O23: =SUM(C23:N23) -> 40
B24: IPTU | C24: 30 | O24: =SUM(C24:N24) -> 30
B25: Manutenção | C25: 40 | O25: =SUM(C25:N25) -> 40
B26: Outras - Moradia | C26: 10 | O26: =SUM(C26:N26) -> 10
B27: Total | C27: =SUM(C16:C26) -> 1680 | D27: =SUM(D16:D26) -> 0 | E27: =SUM(E16:E26) -> 0 | F27: =SUM(F16:F26) -> 0 | G27: =SUM(G16:G26) -> 0 | H27: =SUM(H16:H26) -> 0 | I27: =SUM(I16:I26) -> 0 | J27: =SUM(J16:J26) -> 0 | ... N27: =SUM(N16:N26) -> 0 | O27: =SUM(C27:N27) -> 1680
B29: Despesas - Transporte
B30: Transporte Público | C30: 50 | O30: =SUM(C30:N30) -> 50
B31: Prestação do Carro | C31: 500 | O31: =SUM(C31:N31) -> 500
B32: Seguro do Carro | C32: 100 | O32: =SUM(C32:N32) -> 100
B33: Combustível | C33: 250 | O33: =SUM(C33:N33) -> 250
B34: Estacionamento | C34: 100 | O34: =SUM(C34:N34) -> 100
B35: IPVA | C35: 50 | O35: =SUM(C35:N35) -> 50
B36: Outras - Transporte | C36: 15 | O36: =SUM(C36:N36) -> 15
B37: Total | C37: =SUM(C30:C36) -> 1065 | D37: =SUM(D30:D36) -> 0 | E37: =SUM(E30:E36) -> 0 | F37: =SUM(F30:F36) -> 0 | G37: =SUM(G30:G36) -> 0 | H37: =SUM(H30:H36) -> 0 | I37: =SUM(I30:I36) -> 0 | J37: =SUM(J30:J36) -> 0 | ... N37: =SUM(N30:N36) -> 0 | O37: =SUM(C37:N37) -> 1065
B39: Despesas com Serviços
B40: Escola | C40: 450 | O40: =SUM(C40:N40) -> 450
B41: Cursos | C41: - | O41: =SUM(C41:N41) -> 0
B42: Saúde | C42: 100 | O42: =SUM(C42:N42) -> 100
B43: Lazer | C43: 140 | O43: =SUM(C43:N43) -> 140
B44: Assinaturas | C44: 60 | O44: =SUM(C44:N44) -> 60
B45: Outros Serviços | C45: 30 | O45: =SUM(C45:N45) -> 30
B46: Total | C46: =SUM(C40:C45) -> 780 | D46: =SUM(D40:D45) -> 0 | E46: =SUM(E40:E45) -> 0 | F46: =SUM(F40:F45) -> 0 | G46: =SUM(G40:G45) -> 0 | H46: =SUM(H40:H45) -> 0 | I46: =SUM(I40:I45) -> 0 | J46: =SUM(J40:J45) -> 0 | ... N46: =SUM(N40:N45) -> 0 | O46: =SUM(C46:N46) -> 780
B48: Despesas Pessoais
B49: Vestuário | C49: 70 | O49: =SUM(C49:N49) -> 70
...

Sheet Resumo
D2: Planilha de orçamento pessoal com gráficos - Excel Solução
D3: Personalizamos para sua necessidade.
D4: Entre em contato: contato@excelsolucao.com.br
B6: Mês | C6: Janeiro | D6: Fevereiro | E6: Março | F6: Abril | G6: Maio | H6: Junho | I6: Julho | J6: Agosto | K6: Setembro | L6: Outubro | M6: Novembro | N6: Dezembro | O6: Soma-Ano
B7: Soma Receitas | C7: =Orçamento!C12 -> 5000 | D7: =Orçamento!D12 -> 0 | E7: =Orçamento!E12 -> 0 | F7: =Orçamento!F12 -> 0 | G7: =Orçamento!G12 -> 0 | H7: =Orçamento!H12 -> 0 | I7: =Orçamento!I12 -> 0 | J7: =Orçamento!J12 -> 0 | ... N7: =Orçamento!N12 -> 0 | O7: =SUM(C7:N7) -> 5000
B9: Despesas - Moradia | C9: =Orçamento!C27 -> 1680 | D9: =Orçamento!D27 -> 0 | E9: =Orçamento!E27 -> 0 | F9: =Orçamento!F27 -> 0 | G9: =Orçamento!G27 -> 0 | H9: =Orçamento!H27 -> 0 | I9: =Orçamento!I27 -> 0 | J9: =Orçamento!J27 -> 0 | ... N9: =Orçamento!N27 -> 0 | O9: =SUM(C9:N9) -> 1680
B10: Despesas - Transporte | C10: =Orçamento!C37 -> 1065 | D10: =Orçamento!D37 -> 0 | E10: =Orçamento!E37 -> 0 | F10: =Orçamento!F37 -> 0 | G10: =Orçamento!G37 -> 0 | H10: =Orçamento!H37 -> 0 | I10: =Orçamento!I37 -> 0 | J10: =Orçamento!J37 -> 0 | ... N10: =Orçamento!N37 -> 0 | O10: =SUM(C10:N10) -> 1065
B11: Despesas com Serviços | C11: =Orçamento!C46 -> 780 | D11: =Orçamento!D46 -> 0 | E11: =Orçamento!E46 -> 0 | F11: =Orçamento!F46 -> 0 | G11: =Orçamento!G46 -> 0 | H11: =Orçamento!H46 -> 0 | I11: =Orçamento!I46 -> 0 | J11: =Orçamento!J46 -> 0 | ... N11: =Orçamento!N46 -> 0 | O11: =SUM(C11:N11) -> 780
B12: Despesas Pessoais | C12: =Orçamento!C56 -> 1045 | D12: =Orçamento!D56 -> 0 | E12: =Orçamento!E56 -> 0 | F12: =Orçamento!F56 -> 0 | G12: =Orçamento!G56 -> 0 | H12: =Orçamento!H56 -> 0 | I12: =Orçamento!I56 -> 0 | J12: =Orçamento!J56 -> 0 | ... N12: =Orçamento!N56 -> 0 | O12: =SUM(C12:N12) -> 1045
B13: Soma Despesas | C13: =SUM(C9:C12) -> 4570 | D13: =SUM(D9:D12) -> 0 | E13: =SUM(E9:E12) -> 0 | F13: =SUM(F9:F12) -> 0 | G13: =SUM(G9:G12) -> 0 | H13: =SUM(H9:H12) -> 0 | I13: =SUM(I9:I12) -> 0 | J13: =SUM(J9:J12) -> 0 | ... N13: =SUM(N9:N12) -> 0 | O13: =SUM(C13:N13) -> 4570
B15: Investimentos | C15: =Orçamento!C62 -> 300 | D15: =Orçamento!D62 -> 0 | E15: =Orçamento!E62 -> 0 | F15: =Orçamento!F62 -> 0 | G15: =Orçamento!G62 -> 0 | H15: =Orçamento!H62 -> 0 | I15: =Orçamento!I62 -> 0 | J15: =Orçamento!J62 -> 0 | ... N15: =Orçamento!N62 -> 0 | O15: =SUM(C15:N15) -> 300
B17: Saldo Mês | C17: =C7-C13+C15 -> 730 | D17: =D7-D13+D15 -> 0 | E17: =E7-E13+E15 -> 0 | F17: =F7-F13+F15 -> 0 | G17: =G7-G13+G15 -> 0 | H17: =H7-H13+H15 -> 0 | I17: =I7-I13+I15 -> 0 | J17: =J7-J13+J15 -> 0 | ... N17: =N7-N13+N15 -> 0 | O17: =SUM(C17:N17) -> 730
B19: Saldo Acumulado | C19: =C17 -> 730 | D19: =C19+D17 -> 730 | E19: =D19+E17 -> 730 | F19: =E19+F17 -> 730 | G19: =F19+G17 -> 730 | H19: =G19+H17 -> 730 | I19: =H19+I17 -> 730 | J19: =I19+J17 -> 730 | K19: =J19+K17 -> 730 | ... N19: =M19+N17 -> 730 | O19: =N19 -> 730

Sheet Gráficos

Sheet Desbloquear Planilha
D10: Desbloquear esta planilha para edição:
D26: Clique aqui e contribua para receber a versão desbloqueada para editar esta planilha.
D31: Clique aqui e conheça a versão mais atualizada e avançada desta planilha.
