Workbook
Name area_impressao_ap: #REF!,#REF!
Name area_impressao_ap: #REF!,#REF!
Name area_impressao_ap: 'Listagem de Pagamentos Efet'!$A$1:$G$3,'Listagem de Pagamentos Efet'!#REF!
Name Bu: [1]INPUT!$B$10
Name DC: [1]INPUT!$B$8
Name EXHIBIT_01: #REF!
Name EXHIBIT_01: #REF!
Name EXHIBIT_01: #REF!
Name EXHIBIT_01: #REF!
Name EXHIBIT_01: #REF!
Name EXHIBIT_02: #REF!
Name EXHIBIT_02: #REF!
Name EXHIBIT_02: #REF!
Name EXHIBIT_02: #REF!
Name EXHIBIT_02: #REF!
Name EXHIBIT_05: #REF!
Name EXHIBIT_05: #REF!
Name EXHIBIT_05: #REF!
Name EXHIBIT_05: #REF!
Name EXHIBIT_05: #REF!
Name EXHIBIT_06: #REF!
Name EXHIBIT_06: #REF!
Name EXHIBIT_06: #REF!
Name EXHIBIT_06: #REF!
Name EXHIBIT_06: #REF!
Name EXHIBIT_07: #REF!
Name EXHIBIT_07: #REF!
Name EXHIBIT_07: #REF!
Name EXHIBIT_07: #REF!
Name EXHIBIT_07: #REF!
Name EXHIBIT_08: #REF!
Name EXHIBIT_08: #REF!
Name EXHIBIT_08: #REF!
Name EXHIBIT_08: #REF!
Name EXHIBIT_08: #REF!
Name new_proj: '[2]Novos Projectos'!$A$3:$A$57
Name Pm: [1]INPUT!$B$6
Name Rd: [1]INPUT!$B$4
Name t: [1]INPUT!$B$7
Name TD: [1]INPUT!$B$9
Name VARa: [1]INPUT!$B$12

Sheet Pressupostos 
D1: Empresa:
A4: Pressupostos Gerais
A7: Unidade monetária | B7: Moeda: Real BRL | C7: Saldo Inicial: | D7: =SUM(E13:E21) -> 1008.12
A9: Ano de Balisamento / Data para o Início dos trabalhos diários | B9: 2018 | C9: 43586 | D9: Atenção a mudança as fórmulas no dia a dia dos meses
A12: Contas Bancárias | B12: Agência | C12: Conta | D12: Tx. De Contrato | E12: Saldo Inicial
A13: BANCO DO BRASIL | E13: 730.01
A14: DAYCOVAL - | E14: -42.91
A15: DAYCOVAL - 01 | E15: -455.47
A16: HSBC - 01 | E16: 0
A17: BRADESCO - | E17: -158.86
A18: BRADESCO - 01 | E18: 1501
A19: HSBC - 01 | E19: 86.56
A20: BRADESCO - | E20: 0
A21: DAYCOVAL 02 | E21: -652.21
E22: =SUM(E13:E21) -> 1008.12

Sheet AUTORIZAÇÃO PAGAMENTO
F1: Empresa: | G1: =+'Pressupostos '!E1 -> 0
A3: AUTORIZAÇÃO DE PAGAMENTO
G5: x
A7: DT EMISSÃO | B7: DT. VENCIMENTO | C7: RUBRICA | D7: ORIGEM DA DESPESA | E7: FAVORECIDO | F7: NºDOC | G7: CPF/CNPJ | H7: CHEQUE nº | I7: DOC/TED | J7: VALOR | K7: ORÇAMENTO DISPONÍVEL
L8: =+IFERROR(VLOOKUP(#REF!,[3]DRE!B:N,12,FALSE),"")
A12: DT EMISSÃO | B12: DT. VENCIMENTO | C12: RUBRICA | D12: ORIGEM DA DESPESA | E12: FAVORECIDO | F12: NºDOC | G12: CPF/CNPJ | H12: CHEQUE nº | I12: DOC/TED | J12: VALOR | K12: ORÇAMENTO DISPONÍVEL
L13: =+IFERROR(VLOOKUP(#REF!,[3]DRE!B:N,12,FALSE),"")
L14: =+IFERROR(VLOOKUP(#REF!,DRE!B:N,12,FALSE),"")
K15: =+IFERROR(VLOOKUP(C15,DRE!B:N,12,FALSE),"") | L15: =+IFERROR(VLOOKUP(#REF!,DRE!B:N,12,FALSE),"")
K16: =+IFERROR(VLOOKUP(C16,DRE!B:N,12,FALSE),"")
K17: =+IFERROR(VLOOKUP(C17,DRE!B:N,12,FALSE),"")
K18: =+IFERROR(VLOOKUP(C18,DRE!B:N,12,FALSE),"")
K19: =+IFERROR(VLOOKUP(C19,DRE!B:N,12,FALSE),"")
K20: =+IFERROR(VLOOKUP(C20,DRE!B:N,12,FALSE),"")
K21: =+IFERROR(VLOOKUP(C21,DRE!B:N,12,FALSE),"")
K22: =+IFERROR(VLOOKUP(C22,DRE!B:N,12,FALSE),"")
K23: =+IFERROR(VLOOKUP(C23,DRE!B:N,12,FALSE),"")
K24: =+IFERROR(VLOOKUP(C24,DRE!B:N,12,FALSE),"")
K25: =+IFERROR(VLOOKUP(C25,DRE!B:N,12,FALSE),"")
K26: =+IFERROR(VLOOKUP(C26,DRE!B:N,12,FALSE),"")
K27: =+IFERROR(VLOOKUP(C27,DRE!B:N,12,FALSE),"")
... K55: =+IFERROR(VLOOKUP(C55,DRE!B:N,12,FALSE),"")
A57: SALDO BANCÁRIO | B57: =(FECHAMENTO!AH17+J57)*0+62425.73 -> 62425.73 | D57: SALDO APÓS AP | E57: =B57-J57 -> 62425.73 | I57: TOTAL DA AP | J57: =SUM(J15:J56) -> 0
C61: -60387
AA62: ----------------------------------------------------------------------------------
Z63: ALFA MIX | AA63: DINHEIRO (D+1)
Z64: CSN DISTRIBUIDORA | AA64: CHEQUE (D+1)
Z65: TAMOYO | AA65: DÉBITO (D+1)
Z66: FORTALEZA | AA66: CRÉDITO (D+1)
Z67: NATAL | AA67: BOLETO (D+1)
Z68: JOÃO PESSOA | AA68: OUTROS RECEBIMENTOS (D+1)
Z69: RECIFE | AA69: -------------------------------------------------------------------------------
Z70: CSN REPRESENTAÇÕES | AA70: --------------------------------------------------------------------------------
AA71: PIS
AA72: COFINS
AA73: ISS
AA74: ICMS (AJUSTADO)
AA75: --------------------------------------------------------------------------------
AA76: CARTÃO DÉBITO
AA77: CARTÃO CRÉDITO
...

Sheet Listagem de Pagamentos Efet
F1: EMPRESA:
A4: DT EMISSÃO | B4: VENCIMENTO | C4: RUBRICA | D4: ORIGEM DA DESPESA | E4: FAVORECIDO | F4: NºDOC | G4: CPF/CNPJ | J4: VALOR
A5: 43525 | B5: 43525 | C5: GÁS | E5: CIA DE GAS DO CEARA - CEGAS | F5: NF 189303 | J5: 10000 | K5: BANCOS
A6: 43525 | B6: 43525 | C6: CUSTO DE REPOSIÇÃO/PRESTAÇÃO DE SERVIÇOS | E6: POSTO ALTO ALEGRE LTDA | F6: NF 19433--19439 | J6: 30000 | K6: BANCOS
A7: 43525 | B7: 43525 | C7: VALE ALIMENTAÇÃO | E7: CV DISTRIBUIDORA DE ALIMENTOS EIRELE ME (CAMPO VERDE) | F7: NF 78519 | J7: 4000 | K7: BANCOS
A8: 43525 | B8: 43525 | C8: ICMS (AJUSTADO) | E8: DARE | J8: 100 | K8: BANCOS
J353: =SUM(J5:J352) -> 44100
J360: =2168.97+2205.49 -> 4374.46

Sheet FLUXO DE CAIXA
D3: =+WEEKDAY(D4,1) -> 3 | E3: =+WEEKDAY(E4,1) -> 4 | F3: =+WEEKDAY(F4,1) -> 5 | G3: =+WEEKDAY(G4,1) -> 6 | H3: =+WEEKDAY(H4,1) -> 7 | I3: =+WEEKDAY(I4,1) -> 1 | J3: =+WEEKDAY(J4,1) -> 2 | K3: =+WEEKDAY(K4,1) -> 3 | ... AE3: =+WEEKDAY(AE4,1) -> 2 | AI3: =+WEEKDAY(AI4,1) -> 5 | AJ3: =+WEEKDAY(AJ4,1) -> 6 | AK3: =+WEEKDAY(AK4,1) -> 7 | AL3: =+WEEKDAY(AL4,1) -> 1 | AM3: =+WEEKDAY(AM4,1) -> 2 | AN3: =+WEEKDAY(AN4,1) -> 3 | AO3: =+WEEKDAY(AO4,1) -> 4 | AP3: =+WEEKDAY(AP4,1) -> 5 | ... BM3: =+WEEKDAY(BM4,1) -> 7 | BO3: =+WEEKDAY(BO4,1) -> 1 | BP3: =+WEEKDAY(BP4,1) -> 2 | BQ3: =+WEEKDAY(BQ4,1) -> 3 | BR3: =+WEEKDAY(BR4,1) -> 4 | BS3: =+WEEKDAY(BS4,1) -> 5 | BT3: =+WEEKDAY(BT4,1) -> 6 | BU3: =+WEEKDAY(BU4,1) -> 7 | BV3: =+WEEKDAY(BV4,1) -> 1 | ... CR3: =+WEEKDAY(CR4,1) -> 2 | CT3: =+WEEKDAY(CT4,1) -> 3 | CU3: =+WEEKDAY(CU4,1) -> 4 | CV3: =+WEEKDAY(CV4,1) -> 5 | CW3: =+WEEKDAY(CW4,1) -> 6 | CX3: =+WEEKDAY(CX4,1) -> 7 | CY3: =+WEEKDAY(CY4,1) -> 1 | CZ3: =+WEEKDAY(CZ4,1) -> 2 | DA3: =+WEEKDAY(DA4,1) -> 3 | ... DX3: =+WEEKDAY(DX4,1) -> 5 | DZ3: =+WEEKDAY(DZ4,1) -> 6 | EA3: =+WEEKDAY(EA4,1) -> 7 | EB3: =+WEEKDAY(EB4,1) -> 1 | EC3: =+WEEKDAY(EC4,1) -> 2 | ED3: =+WEEKDAY(ED4,1) -> 3 | EE3: =+WEEKDAY(EE4,1) -> 4 | EF3: =+WEEKDAY(EF4,1) -> 5 | EG3: =+WEEKDAY(EG4,1) -> 6 | ... FC3: =+WEEKDAY(FC4,1) -> 7 | FE3: =+WEEKDAY(FE4,1) -> 1 | FF3: =+WEEKDAY(FF4,1) -> 2 | FG3: =+WEEKDAY(FG4,1) -> 3 | FH3: =+WEEKDAY(FH4,1) -> 4 | FI3: =+WEEKDAY(FI4,1) -> 5 | FJ3: =+WEEKDAY(FJ4,1) -> 6 | FK3: =+WEEKDAY(FK4,1) -> 7 | FL3: =+WEEKDAY(FL4,1) -> 1 | ... GI3: =+WEEKDAY(GI4,1) -> 3 | GK3: =+WEEKDAY(GK4,1) -> 4 | GL3: =+WEEKDAY(GL4,1) -> 5 | GM3: =+WEEKDAY(GM4,1) -> 6 | GN3: =+WEEKDAY(GN4,1) -> 7 | GO3: =+WEEKDAY(GO4,1) -> 1 | GP3: =+WEEKDAY(GP4,1) -> 2 | GQ3: =+WEEKDAY(GQ4,1) -> 3 | GR3: =+WEEKDAY(GR4,1) -> 4 | ... HO3: =+WEEKDAY(HO4,1) -> 6 | HQ3: =+WEEKDAY(HQ4,1) -> 7 | HR3: =+WEEKDAY(HR4,1) -> 1 | HS3: =+WEEKDAY(HS4,1) -> 2 | HT3: =+WEEKDAY(HT4,1) -> 3 | HU3: =+WEEKDAY(HU4,1) -> 4 | HV3: =+WEEKDAY(HV4,1) -> 5 | HW3: =+WEEKDAY(HW4,1) -> 6 | HX3: =+WEEKDAY(HX4,1) -> 7 | ... IT3: =+WEEKDAY(IT4,1) -> 1 | IV3: =+WEEKDAY(IV4,1) -> 2 | IW3: =+WEEKDAY(IW4,1) -> 3 | IX3: =+WEEKDAY(IX4,1) -> 4 | IY3: =+WEEKDAY(IY4,1) -> 5 | IZ3: =+WEEKDAY(IZ4,1) -> 6 | JA3: =+WEEKDAY(JA4,1) -> 7 | JB3: =+WEEKDAY(JB4,1) -> 1 | JC3: =+WEEKDAY(JC4,1) -> 2 | ... JZ3: =+WEEKDAY(JZ4,1) -> 4 | KB3: =+WEEKDAY(KB4,1) -> 5 | KC3: =+WEEKDAY(KC4,1) -> 6 | KD3: =+WEEKDAY(KD4,1) -> 7 | KE3: =+WEEKDAY(KE4,1) -> 1 | KF3: =+WEEKDAY(KF4,1) -> 2 | KG3: =+WEEKDAY(KG4,1) -> 3 | KH3: =+WEEKDAY(KH4,1) -> 4 | KI3: =+WEEKDAY(KI4,1) -> 5 | ... LE3: =+WEEKDAY(LE4,1) -> 6 | LG3: =+WEEKDAY(LG4,1) -> 7 | LH3: =+WEEKDAY(LH4,1) -> 1 | LI3: =+WEEKDAY(LI4,1) -> 2 | LJ3: =+WEEKDAY(LJ4,1) -> 3 | LK3: =+WEEKDAY(LK4,1) -> 4 | LL3: =+WEEKDAY(LL4,1) -> 5 | LM3: =+WEEKDAY(LM4,1) -> 6 | LN3: =+WEEKDAY(LN4,1) -> 7 | ... MK3: =+WEEKDAY(MK4,1) -> 2 | MM3: =+WEEKDAY(MM4,1) -> 3 | MN3: =+WEEKDAY(MN4,1) -> 4 | MO3: =+WEEKDAY(MO4,1) -> 5 | MP3: =+WEEKDAY(MP4,1) -> 6 | MQ3: =+WEEKDAY(MQ4,1) -> 7 | MR3: =+WEEKDAY(MR4,1) -> 1 | MS3: =+WEEKDAY(MS4,1) -> 2 | MT3: =+WEEKDAY(MT4,1) -> 3 | ... NQ3: =+WEEKDAY(NQ4,1) -> 5 | NS3: =+WEEKDAY(NS4,1) -> 6 | NT3: =+WEEKDAY(NT4,1) -> 7 | NU3: =+WEEKDAY(NU4,1) -> 1 | NV3: =+WEEKDAY(NV4,1) -> 2 | NW3: =+WEEKDAY(NW4,1) -> 3 | NX3: =+WEEKDAY(NX4,1) -> 4 | NY3: =+WEEKDAY(NY4,1) -> 5 | NZ3: =+WEEKDAY(NZ4,1) -> 6 | ... OT3: =+WEEKDAY(OT4,1) -> 5 | OV3: =+WEEKDAY(OV4,1) -> 6 | OW3: =+WEEKDAY(OW4,1) -> 7 | OX3: =+WEEKDAY(OX4,1) -> 1 | OY3: =+WEEKDAY(OY4,1) -> 2 | OZ3: =+WEEKDAY(OZ4,1) -> 3 | PA3: =+WEEKDAY(PA4,1) -> 4 | PB3: =+WEEKDAY(PB4,1) -> 5 | PC3: =+WEEKDAY(PC4,1) -> 6 | ... PZ3: =+WEEKDAY(PZ4,1) -> 1 | QB3: =+WEEKDAY(QB4,1) -> 2 | QC3: =+WEEKDAY(QC4,1) -> 3 | QD3: =+WEEKDAY(QD4,1) -> 4 | QE3: =+WEEKDAY(QE4,1) -> 5 | QF3: =+WEEKDAY(QF4,1) -> 6 | QG3: =+WEEKDAY(QG4,1) -> 7 | QH3: =+WEEKDAY(QH4,1) -> 1 | QI3: =+WEEKDAY(QI4,1) -> 2 | ... RE3: =+WEEKDAY(RE4,1) -> 3 | RG3: =+WEEKDAY(RG4,1) -> 4 | RH3: =+WEEKDAY(RH4,1) -> 5 | RI3: =+WEEKDAY(RI4,1) -> 6 | RJ3: =+WEEKDAY(RJ4,1) -> 7 | RK3: =+WEEKDAY(RK4,1) -> 1 | RL3: =+WEEKDAY(RL4,1) -> 2 | RM3: =+WEEKDAY(RM4,1) -> 3 | RN3: =+WEEKDAY(RN4,1) -> 4 | ... SK3: =+WEEKDAY(SK4,1) -> 6 | SM3: =+WEEKDAY(SM4,1) -> 7 | SN3: =+WEEKDAY(SN4,1) -> 1 | SO3: =+WEEKDAY(SO4,1) -> 2 | SP3: =+WEEKDAY(SP4,1) -> 3 | SQ3: =+WEEKDAY(SQ4,1) -> 4 | SR3: =+WEEKDAY(SR4,1) -> 5 | SS3: =+WEEKDAY(SS4,1) -> 6 | ST3: =+WEEKDAY(ST4,1) -> 7 | ... TP3: =+WEEKDAY(TP4,1) -> 1 | TR3: =+WEEKDAY(TR4,1) -> 2 | TS3: =+WEEKDAY(TS4,1) -> 3 | TT3: =+WEEKDAY(TT4,1) -> 4 | TU3: =+WEEKDAY(TU4,1) -> 5 | TV3: =+WEEKDAY(TV4,1) -> 6 | TW3: =+WEEKDAY(TW4,1) -> 7 | TX3: =+WEEKDAY(TX4,1) -> 1 | TY3: =+WEEKDAY(TY4,1) -> 2 | ... UV3: =+WEEKDAY(UV4,1) -> 4 | UX3: =+WEEKDAY(UX4,1) -> 5 | UY3: =+WEEKDAY(UY4,1) -> 6 | UZ3: =+WEEKDAY(UZ4,1) -> 7 | VA3: =+WEEKDAY(VA4,1) -> 1 | VB3: =+WEEKDAY(VB4,1) -> 2 | VC3: =+WEEKDAY(VC4,1) -> 3 | VD3: =+WEEKDAY(VD4,1) -> 4 | VE3: =+WEEKDAY(VE4,1) -> 5 | ... WB3: =+WEEKDAY(WB4,1) -> 7
B4: FLUXO DE CAIXA | C4: 42947 | D4: =+C4+1 -> 42948 | E4: =+D4+1 -> 42949 | F4: =+E4+1 -> 42950 | G4: =+F4+1 -> 42951 | H4: =+G4+1 -> 42952 | I4: =+H4+1 -> 42953 | J4: =+I4+1 -> 42954 | K4: =+J4+1 -> 42955 | ... AG4: =+AF4+1 -> 42977 | AH4: ABRIL | AI4: =+AG4+1 -> 42978 | AJ4: =+AI4+1 -> 42979 | AK4: =+AJ4+1 -> 42980 | AL4: =+AK4+1 -> 42981 | AM4: =+AL4+1 -> 42982 | AN4: =+AM4+1 -> 42983 | AO4: =+AN4+1 -> 42984 | AP4: =+AO4+1 -> 42985 | AQ4: =+AP4+1 -> 42986 | ... BM4: =+BL4+1 -> 43008 | BN4: MARÇO | BO4: =+BM4+1 -> 43009 | BP4: =+BO4+1 -> 43010 | BQ4: =+BP4+1 -> 43011 | BR4: =+BQ4+1 -> 43012 | BS4: =+BR4+1 -> 43013 | BT4: =+BS4+1 -> 43014 | BU4: =+BT4+1 -> 43015 | BV4: =+BU4+1 -> 43016 | BW4: =+BV4+1 -> 43017 | ... CR4: =+CQ4+1 -> 43038 | CS4: ABRIL | CT4: =+CR4+1 -> 43039 | CU4: =+CT4+1 -> 43040 | CV4: =+CU4+1 -> 43041 | CW4: =+CV4+1 -> 43042 | CX4: =+CW4+1 -> 43043 | CY4: =+CX4+1 -> 43044 | CZ4: =+CY4+1 -> 43045 | DA4: =+CZ4+1 -> 43046 | DB4: =+DA4+1 -> 43047 | ... DX4: =+DW4+1 -> 43069 | DY4: MAIO | DZ4: =+DX4+1 -> 43070 | EA4: =+DZ4+1 -> 43071 | EB4: =+EA4+1 -> 43072 | EC4: =+EB4+1 -> 43073 | ED4: =+EC4+1 -> 43074 | EE4: =+ED4+1 -> 43075 | EF4: =+EE4+1 -> 43076 | EG4: =+EF4+1 -> 43077 | EH4: =+EG4+1 -> 43078 | ... FC4: =+FB4+1 -> 43099 | FD4: JUNHO | FE4: =+FC4+1 -> 43100 | FF4: =+FE4+1 -> 43101 | FG4: =+FF4+1 -> 43102 | FH4: =+FG4+1 -> 43103 | FI4: =+FH4+1 -> 43104 | FJ4: =+FI4+1 -> 43105 | FK4: =+FJ4+1 -> 43106 | FL4: =+FK4+1 -> 43107 | FM4: =+FL4+1 -> 43108 | ... GI4: =+GH4+1 -> 43130 | GJ4: JULHO | GK4: =+GI4+1 -> 43131 | GL4: =+GK4+1 -> 43132 | GM4: =+GL4+1 -> 43133 | GN4: =+GM4+1 -> 43134 | GO4: =+GN4+1 -> 43135 | GP4: =+GO4+1 -> 43136 | GQ4: =+GP4+1 -> 43137 | GR4: =+GQ4+1 -> 43138 | GS4: =+GR4+1 -> 43139 | ... HO4: =+HN4+1 -> 43161 | HP4: AGOSTO | HQ4: =+HO4+1 -> 43162 | HR4: =+HQ4+1 -> 43163 | HS4: =+HR4+1 -> 43164 | HT4: =+HS4+1 -> 43165 | HU4: =+HT4+1 -> 43166 | HV4: =+HU4+1 -> 43167 | HW4: =+HV4+1 -> 43168 | HX4: =+HW4+1 -> 43169 | HY4: =+HX4+1 -> 43170 | ... IT4: =+IS4+1 -> 43191 | IU4: SETEMBRO | IV4: =+IT4+1 -> 43192 | IW4: =+IV4+1 -> 43193 | IX4: =+IW4+1 -> 43194 | IY4: =+IX4+1 -> 43195 | IZ4: =+IY4+1 -> 43196 | JA4: =+IZ4+1 -> 43197 | JB4: =+JA4+1 -> 43198 | JC4: =+JB4+1 -> 43199 | JD4: =+JC4+1 -> 43200 | ... JZ4: =+JY4+1 -> 43222 | KA4: OUTUBRO | KB4: =+JZ4+1 -> 43223 | KC4: =+KB4+1 -> 43224 | KD4: =+KC4+1 -> 43225 | KE4: =+KD4+1 -> 43226 | KF4: =+KE4+1 -> 43227 | KG4: =+KF4+1 -> 43228 | KH4: =+KG4+1 -> 43229 | KI4: =+KH4+1 -> 43230 | KJ4: =+KI4+1 -> 43231 | ... LE4: =+LD4+1 -> 43252 | LF4: NOVEMBRO | LG4: =+LE4+1 -> 43253 | LH4: =+LG4+1 -> 43254 | LI4: =+LH4+1 -> 43255 | LJ4: =+LI4+1 -> 43256 | LK4: =+LJ4+1 -> 43257 | LL4: =+LK4+1 -> 43258 | LM4: =+LL4+1 -> 43259 | LN4: =+LM4+1 -> 43260 | LO4: =+LN4+1 -> 43261 | ... MK4: =+MJ4+1 -> 43283 | ML4: DEZEMBRO | MM4: =+MK4+1 -> 43284 | MN4: =+MM4+1 -> 43285 | MO4: =+MN4+1 -> 43286 | MP4: =+MO4+1 -> 43287 | MQ4: =+MP4+1 -> 43288 | MR4: =+MQ4+1 -> 43289 | MS4: =+MR4+1 -> 43290 | MT4: =+MS4+1 -> 43291 | MU4: =+MT4+1 -> 43292 | ... NQ4: =+NP4+1 -> 43314 | NR4: JANEIRO | NS4: =+NQ4+1 -> 43315 | NT4: =+NS4+1 -> 43316 | NU4: =+NT4+1 -> 43317 | NV4: =+NU4+1 -> 43318 | NW4: =+NV4+1 -> 43319 | NX4: =+NW4+1 -> 43320 | NY4: =+NX4+1 -> 43321 | NZ4: =+NY4+1 -> 43322 | OA4: =+NZ4+1 -> 43323 | ... OT4: =+OS4+1 -> 43342 | OU4: FEVEREIRO | OV4: =+OT4+1 -> 43343 | OW4: =+OV4+1 -> 43344 | OX4: =+OW4+1 -> 43345 | OY4: =+OX4+1 -> 43346 | OZ4: =+OY4+1 -> 43347 | PA4: =+OZ4+1 -> 43348 | PB4: =+PA4+1 -> 43349 | PC4: =+PB4+1 -> 43350 | PD4: =+PC4+1 -> 43351 | ... PZ4: =+PY4+1 -> 43373 | QA4: MARÇO | QB4: =+PZ4+1 -> 43374 | QC4: =+QB4+1 -> 43375 | QD4: =+QC4+1 -> 43376 | QE4: =+QD4+1 -> 43377 | QF4: =+QE4+1 -> 43378 | QG4: =+QF4+1 -> 43379 | QH4: =+QG4+1 -> 43380 | QI4: =+QH4+1 -> 43381 | QJ4: =+QI4+1 -> 43382 | ... RE4: =+RD4+1 -> 43403 | RF4: ABRIL | RG4: =+RE4+1 -> 43404 | RH4: =+RG4+1 -> 43405 | RI4: =+RH4+1 -> 43406 | RJ4: =+RI4+1 -> 43407 | RK4: =+RJ4+1 -> 43408 | RL4: =+RK4+1 -> 43409 | RM4: =+RL4+1 -> 43410 | RN4: =+RM4+1 -> 43411 | RO4: =+RN4+1 -> 43412 | ... SK4: =+SJ4+1 -> 43434 | SL4: JUNHO | SM4: =+SK4+1 -> 43435 | SN4: =+SM4+1 -> 43436 | SO4: =+SN4+1 -> 43437 | SP4: =+SO4+1 -> 43438 | SQ4: =+SP4+1 -> 43439 | SR4: =+SQ4+1 -> 43440 | SS4: =+SR4+1 -> 43441 | ST4: =+SS4+1 -> 43442 | SU4: =+ST4+1 -> 43443 | ... TP4: =+TO4+1 -> 43464 | TQ4: JUNHO | TR4: =+TP4+1 -> 43465 | TS4: =+TR4+1 -> 43466 | TT4: =+TS4+1 -> 43467 | TU4: =+TT4+1 -> 43468 | TV4: =+TU4+1 -> 43469 | TW4: =+TV4+1 -> 43470 | TX4: =+TW4+1 -> 43471 | TY4: =+TX4+1 -> 43472 | TZ4: =+TY4+1 -> 43473 | ... UV4: =+UU4+1 -> 43495 | UW4: JULHO | UX4: =+UV4+1 -> 43496 | UY4: =+UX4+1 -> 43497 | UZ4: =+UY4+1 -> 43498 | VA4: =+UZ4+1 -> 43499 | VB4: =+VA4+1 -> 43500 | VC4: =+VB4+1 -> 43501 | VD4: =+VC4+1 -> 43502 | VE4: =+VD4+1 -> 43503 | VF4: =+VE4+1 -> 43504 | ... WB4: =+WA4+1 -> 43526 | WC4: AGOSTO
B5: PROJEÇÃO DO LVD (COMERCIAL) | D5: 93636.4 | E5: 0 | F5: 48940.172 | G5: 48940.172 | H5: 48940.172 | I5: 80606.825 | J5: 80606.825 | K5: 3636.4 | L5: 0 | M5: 48940.172 | N5: 48940.172 | O5: 48940.172 | P5: 80606.825 | Q5: 0 | R5: 0 | S5: 0 | T5: 48940.172 | U5: 48940.172 | V5: 48940.172 | W5: 80606.825 | X5: 0 | Y5: 3636.4 | Z5: 33637.105 | AA5: 48940.172 | AB5: 48940.172 | AC5: 48940.172 | AD5: 80606.825 | AE5: 80606.825 | AH5: =+SUM(D5:AE5) -> 1205469.3 | AI5: 0 | AJ5: 0 | AK5: =+F5 -> 48940.172 | AL5: =+G5 -> 48940.172 | AM5: =+H5 -> 48940.172 | AN5: =+I5 -> 80606.825 | AO5: =+J5 -> 80606.825 | AP5: =+K5 -> 3636.4 | AQ5: =+L5 -> 0 | AR5: =+M5 -> 48940.172 | ... BI5: =+AD5 -> 80606.825 | BJ5: =+J5 -> 80606.825 | BK5: =+K5 -> 3636.4 | BL5: =+L5 -> 0 | BM5: =+M5 -> 48940.172 | BN5: =+SUM(AI5:BM5) -> 1164409.5 | BO5: =+AL5 -> 48940.172 | BP5: =+AM5 -> 48940.172 | BQ5: =+AN5 -> 80606.825 | BR5: =+AO5 -> 80606.825 | BS5: =+AP5 -> 3636.4 | BT5: =+AQ5 -> 0 | BU5: =+AR5 -> 48940.172 | BV5: =+AS5 -> 48940.172 | ... CP5: =+BM5 -> 48940.172 | CQ5: =+CJ5 -> 48940.172 | CR5: =+CK5 -> 48940.172 | CS5: =SUM(BO5:CR5) -> 1213349.7 | CT5: =+BQ5 -> 80606.825 | CU5: =+BR5 -> 80606.825 | CV5: =+BS5 -> 3636.4 | CW5: =+BT5 -> 0 | CX5: =+BU5 -> 48940.172 | CY5: =+BV5 -> 48940.172 | CZ5: =+BW5 -> 48940.172 | DA5: =+BX5 -> 80606.825 | ... DT5: =+CQ5 -> 48940.172 | DU5: =+BW5 -> 48940.172 | DV5: =+BX5 -> 80606.825 | DW5: =+BY5 -> 0 | DX5: =+BZ5 -> 0 | DY5: =+SUM(CT5:DX5) -> 1196076.1 | DZ5: =+CW5 -> 0 | EA5: =+CX5 -> 48940.172 | EB5: =+CY5 -> 48940.172 | EC5: =+CZ5 -> 48940.172 | ED5: =+DA5 -> 80606.825 | EE5: =+DB5 -> 0 | EF5: =+DC5 -> 0 | EG5: =+DD5 -> 0 | ... EZ5: =+DW5 -> 0 | FA5: =+DC5 -> 0 | FB5: =+DD5 -> 0 | FC5: =+DE5 -> 48940.172 | FD5: =+SUM(DZ5:FC5) -> 1080166.3 | FE5: =+EC5 -> 48940.172 | FF5: =+ED5 -> 80606.825 | FG5: =+EE5 -> 0 | FH5: =+EF5 -> 0 | FI5: =+EG5 -> 0 | FJ5: =+EH5 -> 48940.172 | FK5: =+EI5 -> 48940.172 | FL5: =+EJ5 -> 48940.172 | ... GE5: =+FC5 -> 48940.172 | GF5: =+EI5 -> 48940.172 | GG5: =+EJ5 -> 48940.172 | GH5: =+EK5 -> 80606.825 | GI5: =+EL5 -> 0 | GJ5: =+SUM(FE5:GI5) -> 1160773.1 | GK5: =+FH5 -> 0 | GL5: =+FI5 -> 0 | GM5: =+FJ5 -> 48940.172 | GN5: =+FK5 -> 48940.172 | GO5: =+FL5 -> 48940.172 | GP5: =+FM5 -> 80606.825 | GQ5: =+FN5 -> 0 | GR5: =+FO5 -> 3636.4 | ... HK5: =+GH5 -> 80606.825 | HL5: =+FN5 -> 0 | HM5: =+FO5 -> 3636.4 | HN5: =+FP5 -> 33637.105 | HO5: =+FQ5 -> 48940.172 | HP5: =+SUM(GK5:HO5) -> 1117439.8 | HQ5: =+GN5 -> 48940.172 | HR5: =+GO5 -> 48940.172 | HS5: =+GP5 -> 80606.825 | HT5: =+GQ5 -> 0 | HU5: =+GR5 -> 3636.4 | HV5: =+GS5 -> 33637.105 | HW5: =+GT5 -> 48940.172 | HX5: =+GU5 -> 48940.172 | ... IQ5: =+HN5 -> 33637.105 | IR5: =+GT5 -> 48940.172 | IS5: =+GU5 -> 48940.172 | IT5: =+GV5 -> 48940.172 | IU5: =+SUM(HQ5:IT5) -> 1166379.9 | IV5: =+HT5 -> 0 | IW5: =+HU5 -> 3636.4 | IX5: =+HV5 -> 33637.105 | IY5: =+HW5 -> 48940.172 | IZ5: =+HX5 -> 48940.172 | JA5: =+HY5 -> 48940.172 | JB5: =+HZ5 -> 80606.825 | JC5: =+IA5 -> 80606.825 | ... JV5: =+IT5 -> 48940.172 | JW5: =+HZ5 -> 80606.825 | JX5: =+IA5 -> 80606.825 | JY5: =+IB5 -> 3636.4 | JZ5: =+IC5 -> 0 | KA5: =+SUM(IV5:JZ5) -> 1152742.8 | KB5: =+IY5 -> 48940.172 | KC5: =+IZ5 -> 48940.172 | KD5: =+JA5 -> 48940.172 | KE5: =+JB5 -> 80606.825 | KF5: =+JC5 -> 80606.825 | KG5: =+JD5 -> 3636.4 | KH5: =+JE5 -> 0 | KI5: =+JF5 -> 48940.172 | ... LB5: =+JY5 -> 3636.4 | LC5: =+JE5 -> 0 | LD5: =+JF5 -> 48940.172 | LE5: =+JG5 -> 48940.172 | LF5: =+SUM(KB5:LE5) -> 1213349.7 | LG5: =+KE5 -> 80606.825 | LH5: =+KF5 -> 80606.825 | LI5: =+KG5 -> 3636.4 | LJ5: =+KH5 -> 0 | LK5: =+KI5 -> 48940.172 | LL5: =+KJ5 -> 48940.172 | LM5: =+KK5 -> 48940.172 | LN5: =+KL5 -> 80606.825 | ... MG5: =+LE5 -> 48940.172 | MH5: =+KK5 -> 48940.172 | MI5: =+KL5 -> 80606.825 | MJ5: =+KM5 -> 0 | MK5: =+KN5 -> 0 | ML5: =+SUM(LG5:MK5) -> 1196076.1 | MM5: =+LJ5 -> 0 | MN5: =+LK5 -> 48940.172 | MO5: =+LL5 -> 48940.172 | MP5: =+LM5 -> 48940.172 | MQ5: =+LN5 -> 80606.825 | MR5: =+LO5 -> 0 | MS5: =+LP5 -> 0 | MT5: =+LQ5 -> 0 | ... NM5: =+MJ5 -> 0 | NN5: =+LP5 -> 0 | NO5: =+LQ5 -> 0 | NP5: =+LR5 -> 48940.172 | NQ5: =+LS5 -> 48940.172 | NR5: =+SUM(MM5:NQ5) -> 1129106.4 | NS5: =+MP5 -> 48940.172 | NT5: =+MQ5 -> 80606.825 | NU5: =+MR5 -> 0 | NV5: =+MS5 -> 0 | NW5: =+MT5 -> 0 | NX5: =+MU5 -> 48940.172 | NY5: =+MV5 -> 48940.172 | NZ5: =+MW5 -> 48940.172 | ... OS5: =+NP5 -> 48940.172 | OT5: =+MV5 -> 48940.172 | OU5: =+SUM(NS5:OT5) -> 1031226.1 | OV5: =+NV5 -> 0 | OW5: =+NW5 -> 0 | OX5: =+NX5 -> 48940.172 | OY5: =+NY5 -> 48940.172 | OZ5: =+NZ5 -> 48940.172 | PA5: =+OA5 -> 80606.825 | PB5: =+OB5 -> 0 | PC5: =+OC5 -> 3636.4 | ... PV5: =+OV5 -> 0 | PW5: =+OB5 -> 0 | PX5: =+OC5 -> 3636.4 | PY5: =+OD5 -> 33637.105 | PZ5: =+OE5 -> 48940.172 | QA5: =+SUM(OV5:PZ5) -> 2019118.9 | QB5: =+OY5 -> 48940.172 | QC5: =+OZ5 -> 48940.172 | QD5: =+PA5 -> 80606.825 | QE5: =+PB5 -> 0 | QF5: =+PC5 -> 3636.4 | QG5: =+PD5 -> 33637.105 | QH5: =+PE5 -> 48940.172 | QI5: =+PF5 -> 48940.172 | ... RB5: =+PY5 -> 33637.105 | RC5: =+PE5 -> 48940.172 | RD5: =+PF5 -> 48940.172 | RE5: =+PG5 -> 48940.172 | RF5: =+SUM(QB5:RE5) -> 2068059 | RG5: =+QE5 -> 0 | RH5: =+QF5 -> 3636.4 | RI5: =+QG5 -> 33637.105 | RJ5: =+QH5 -> 48940.172 | RK5: =+QI5 -> 48940.172 | RL5: =+QJ5 -> 48940.172 | RM5: =+QK5 -> 80606.825 | RN5: =+QL5 -> 80606.825 | ... SG5: =+RE5 -> 48940.172 | SH5: =+QK5 -> 80606.825 | SI5: =+QL5 -> 80606.825 | SJ5: =+QM5 -> 3636.4 | SK5: =+QN5 -> 0 | SL5: =+SUM(RG5:SK5) -> 2054421.9 | SM5: =+RJ5 -> 48940.172 | SN5: =+RK5 -> 48940.172 | SO5: =+RL5 -> 48940.172 | SP5: =+RM5 -> 80606.825 | SQ5: =+RN5 -> 80606.825 | SR5: =+RO5 -> 3636.4 | SS5: =+RP5 -> 0 | ST5: =+RQ5 -> 48940.172 | ... TM5: =+SJ5 -> 3636.4 | TN5: =+RP5 -> 0 | TO5: =+RQ5 -> 48940.172 | TP5: =+RR5 -> 48940.172 | TQ5: =+SUM(SM5:TP5) -> 2115028.8 | TR5: =+SP5 -> 80606.825 | TS5: =+SQ5 -> 80606.825 | TT5: =+SR5 -> 3636.4 | TU5: =+SS5 -> 0 | TV5: =+ST5 -> 48940.172 | TW5: =+SU5 -> 48940.172 | TX5: =+SV5 -> 48940.172 | TY5: =+SW5 -> 80606.825 | ... UR5: =+TP5 -> 48940.172 | US5: =+SV5 -> 48940.172 | UT5: =+SW5 -> 80606.825 | UU5: =+SX5 -> 0 | UV5: =+SY5 -> 0 | UW5: =+SUM(TR5:UV5) -> 2097755.2 | UX5: =+TU5 -> 0 | UY5: =+TV5 -> 48940.172 | UZ5: =+TW5 -> 48940.172 | VA5: =+TX5 -> 48940.172 | VB5: =+TY5 -> 80606.825 | VC5: =+TZ5 -> 0 | VD5: =+UA5 -> 0 | VE5: =+UB5 -> 0 | ... VX5: =+UU5 -> 0 | VY5: =+UA5 -> 0 | VZ5: =+UB5 -> 0 | WA5: =+UC5 -> 48940.172 | WB5: =+UD5 -> 48940.172 | WC5: =+SUM(UX5:WB5) -> 2030785.5
B6: RECEITA BRUTA PROJETADA | D6: 0 | E6: 0 | F6: =F5 -> 48940.172 | G6: =G5 -> 48940.172 | H6: =H5 -> 48940.172 | I6: =I5 -> 80606.825 | J6: =J5 -> 80606.825 | K6: =K5 -> 3636.4 | L6: =L5 -> 0 | M6: =M5 -> 48940.172 | ... AE6: =AE5 -> 80606.825 | AH6: =+SUM(D6:AE6) -> 1111832.9 | AI6: =AI5 -> 0 | AJ6: =AJ5 -> 0 | AK6: =AK5 -> 48940.172 | AL6: =AL5 -> 48940.172 | AM6: =AM5 -> 48940.172 | AN6: =AN5 -> 80606.825 | AO6: =AO5 -> 80606.825 | AP6: =AP5 -> 3636.4 | ... BM6: =BM5 -> 48940.172 | BN6: =+SUM(AI6:BM6) -> 1164409.5 | BO6: =BO5 -> 48940.172 | BP6: =BP5 -> 48940.172 | BQ6: =BQ5 -> 80606.825 | BR6: =BR5 -> 80606.825 | BS6: =BS5 -> 3636.4 | BT6: =BT5 -> 0 | BU6: =BU5 -> 48940.172 | BV6: =BV5 -> 48940.172 | ... CR6: =CR5 -> 48940.172 | CS6: =SUM(BO6:CR6) -> 1213349.7 | CT6: =CT5 -> 80606.825 | CU6: =CU5 -> 80606.825 | CV6: =CV5 -> 3636.4 | CW6: =CW5 -> 0 | CX6: =CX5 -> 48940.172 | CY6: =CY5 -> 48940.172 | CZ6: =CZ5 -> 48940.172 | DA6: =DA5 -> 80606.825 | ... DX6: =DX5 -> 0 | DY6: =+SUM(CT6:DX6) -> 1196076.1 | DZ6: =DZ5 -> 0 | EA6: =EA5 -> 48940.172 | EB6: =EB5 -> 48940.172 | EC6: =EC5 -> 48940.172 | ED6: =ED5 -> 80606.825 | EE6: =EE5 -> 0 | EF6: =EF5 -> 0 | EG6: =EG5 -> 0 | ... FC6: =FC5 -> 48940.172 | FD6: =+SUM(DZ6:FC6) -> 1080166.3 | FE6: =FE5 -> 48940.172 | FF6: =FF5 -> 80606.825 | FG6: =FG5 -> 0 | FH6: =FH5 -> 0 | FI6: =FI5 -> 0 | FJ6: =FJ5 -> 48940.172 | FK6: =FK5 -> 48940.172 | FL6: =FL5 -> 48940.172 | ... GI6: =GI5 -> 0 | GJ6: =+SUM(FE6:GI6) -> 1160773.1 | GK6: =GK5 -> 0 | GL6: =GL5 -> 0 | GM6: =GM5 -> 48940.172 | GN6: =GN5 -> 48940.172 | GO6: =GO5 -> 48940.172 | GP6: =GP5 -> 80606.825 | GQ6: =GQ5 -> 0 | GR6: =GR5 -> 3636.4 | ... HO6: =HO5 -> 48940.172 | HP6: =+SUM(GK6:HO6) -> 1117439.8 | HQ6: =HQ5 -> 48940.172 | HR6: =HR5 -> 48940.172 | HS6: =HS5 -> 80606.825 | HT6: =HT5 -> 0 | HU6: =HU5 -> 3636.4 | HV6: =HV5 -> 33637.105 | HW6: =HW5 -> 48940.172 | HX6: =HX5 -> 48940.172 | ... IT6: =IT5 -> 48940.172 | IU6: =+SUM(HQ6:IT6) -> 1166379.9 | IV6: =IV5 -> 0 | IW6: =IW5 -> 3636.4 | IX6: =IX5 -> 33637.105 | IY6: =IY5 -> 48940.172 | IZ6: =IZ5 -> 48940.172 | JA6: =JA5 -> 48940.172 | JB6: =JB5 -> 80606.825 | JC6: =JC5 -> 80606.825 | ... JZ6: =JZ5 -> 0 | KA6: =+SUM(IV6:JZ6) -> 1152742.8 | KB6: =KB5 -> 48940.172 | KC6: =KC5 -> 48940.172 | KD6: =KD5 -> 48940.172 | KE6: =KE5 -> 80606.825 | KF6: =KF5 -> 80606.825 | KG6: =KG5 -> 3636.4 | KH6: =KH5 -> 0 | KI6: =KI5 -> 48940.172 | ... LE6: =LE5 -> 48940.172 | LF6: =+SUM(KB6:LE6) -> 1213349.7 | LG6: =LG5 -> 80606.825 | LH6: =LH5 -> 80606.825 | LI6: =LI5 -> 3636.4 | LJ6: =LJ5 -> 0 | LK6: =LK5 -> 48940.172 | LL6: =LL5 -> 48940.172 | LM6: =LM5 -> 48940.172 | LN6: =LN5 -> 80606.825 | ... MK6: =MK5 -> 0 | ML6: =+SUM(LG6:MK6) -> 1196076.1 | MM6: =MM5 -> 0 | MN6: =MN5 -> 48940.172 | MO6: =MO5 -> 48940.172 | MP6: =MP5 -> 48940.172 | MQ6: =MQ5 -> 80606.825 | MR6: =MR5 -> 0 | MS6: =MS5 -> 0 | MT6: =MT5 -> 0 | ... NQ6: =NQ5 -> 48940.172 | NR6: =+SUM(MM6:NQ6) -> 1129106.4 | NS6: =NS5 -> 48940.172 | NT6: =NT5 -> 80606.825 | NU6: =NU5 -> 0 | NV6: =NV5 -> 0 | NW6: =NW5 -> 0 | NX6: =NX5 -> 48940.172 | NY6: =NY5 -> 48940.172 | NZ6: =NZ5 -> 48940.172 | ... OT6: =OT5 -> 48940.172 | OU6: =+SUM(NS6:OT6) -> 1031226.1 | OV6: =OV5 -> 0 | OW6: =OW5 -> 0 | OX6: =OX5 -> 48940.172 | OY6: =OY5 -> 48940.172 | OZ6: =OZ5 -> 48940.172 | PA6: =PA5 -> 80606.825 | PB6: =PB5 -> 0 | PC6: =PC5 -> 3636.4 | ... PZ6: =PZ5 -> 48940.172 | QA6: =+SUM(OV6:PZ6) -> 2019118.9 | QB6: =QB5 -> 48940.172 | QC6: =QC5 -> 48940.172 | QD6: =QD5 -> 80606.825 | QE6: =QE5 -> 0 | QF6: =QF5 -> 3636.4 | QG6: =QG5 -> 33637.105 | QH6: =QH5 -> 48940.172 | QI6: =QI5 -> 48940.172 | ... RE6: =RE5 -> 48940.172 | RF6: =+SUM(QB6:RE6) -> 2068059 | RG6: =RG5 -> 0 | RH6: =RH5 -> 3636.4 | RI6: =RI5 -> 33637.105 | RJ6: =RJ5 -> 48940.172 | RK6: =RK5 -> 48940.172 | RL6: =RL5 -> 48940.172 | RM6: =RM5 -> 80606.825 | RN6: =RN5 -> 80606.825 | ... SK6: =SK5 -> 0 | SL6: =+SUM(RG6:SK6) -> 2054421.9 | SM6: =SM5 -> 48940.172 | SN6: =SN5 -> 48940.172 | SO6: =SO5 -> 48940.172 | SP6: =SP5 -> 80606.825 | SQ6: =SQ5 -> 80606.825 | SR6: =SR5 -> 3636.4 | SS6: =SS5 -> 0 | ST6: =ST5 -> 48940.172 | ... TP6: =TP5 -> 48940.172 | TQ6: =+SUM(SM6:TP6) -> 2115028.8 | TR6: =TR5 -> 80606.825 | TS6: =TS5 -> 80606.825 | TT6: =TT5 -> 3636.4 | TU6: =TU5 -> 0 | TV6: =TV5 -> 48940.172 | TW6: =TW5 -> 48940.172 | TX6: =TX5 -> 48940.172 | TY6: =TY5 -> 80606.825 | ... UV6: =UV5 -> 0 | UW6: =+SUM(TR6:UV6) -> 2097755.2 | UX6: =UX5 -> 0 | UY6: =UY5 -> 48940.172 | UZ6: =UZ5 -> 48940.172 | VA6: =VA5 -> 48940.172 | VB6: =VB5 -> 80606.825 | VC6: =VC5 -> 0 | VD6: =VD5 -> 0 | VE6: =VE5 -> 0 | ... WB6: =WB5 -> 48940.172 | WC6: =+SUM(UX6:WB6) -> 2030785.5
B7: DINHEIRO (D+1) | C7: =+[4]DRE!AC8 -> 0.38580871 | D7: =+D$6*$C7 -> 0 | E7: =+E$6*$C7 -> 0 | F7: =+F$6*$C7 -> 18881.544 | G7: =+G$6*$C7 -> 18881.544 | H7: =+H$6*$C7 -> 18881.544 | I7: =+I$6*$C7 -> 31098.815 | J7: =+J$6*$C7 -> 31098.815 | K7: =+K$6*$C7 -> 1402.9548 | ... AE7: =+AE$6*$C7 -> 31098.815 | AH7: =+SUM(D7:AE7) -> 428954.82 | AI7: =+AI$6*$C7 -> 0 | AJ7: =+AJ$6*$C7 -> 0 | AK7: =+AK$6*$C7 -> 18881.544 | AL7: =+AL$6*$C7 -> 18881.544 | AM7: =+AM$6*$C7 -> 18881.544 | AN7: =+AN$6*$C7 -> 31098.815 | AO7: =+AO$6*$C7 -> 31098.815 | AP7: =+AP$6*$C7 -> 1402.9548 | ... AS7: =+AS$6*$C7 -> 18881.544 | AT7: 0 | AU7: =+AU$6*$C7 -> 31098.815 | AV7: =+AV$6*$C7 -> 0 | AW7: =+AW$6*$C7 -> 0 | AX7: =+AX$6*$C7 -> 0 | AY7: =+AY$6*$C7 -> 18881.544 | AZ7: =+AZ$6*$C7 -> 18881.544 | BA7: 0 | BB7: =+BB$6*$C7 -> 31098.815 | BC7: =+BC$6*$C7 -> 0 | BD7: =+BD$6*$C7 -> 1402.9548 | BE7: =+BE$6*$C7 -> 12977.488 | BF7: =+BF$6*$C7 -> 18881.544 | BG7: =+BG$6*$C7 -> 18881.544 | BH7: 0 | BI7: =+BI$6*$C7 -> 31098.815 | BJ7: =+BJ$6*$C7 -> 31098.815 | BK7: =+BK$6*$C7 -> 1402.9548 | BL7: =+BL$6*$C7 -> 0 | BM7: =+BM$6*$C7 -> 18881.544 | BN7: =+SUM(AI7:BM7) -> 392594.69 | BO7: =+BO$6*$C7 -> 18881.544 | BP7: 0 | BQ7: =+BQ$6*$C7 -> 31098.815 | BR7: =+BR$6*$C7 -> 31098.815 | BS7: =+BS$6*$C7 -> 1402.9548 | BT7: =+BT$6*$C7 -> 0 | BU7: =+BU$6*$C7 -> 18881.544 | BV7: =+BV$6*$C7 -> 18881.544 | BW7: 0 | BX7: =+BX$6*$C7 -> 31098.815 | BY7: =+BY$6*$C7 -> 0 | BZ7: =+BZ$6*$C7 -> 0 | CA7: =+CA$6*$C7 -> 0 | CB7: =+CB$6*$C7 -> 18881.544 | CC7: =+CC$6*$C7 -> 18881.544 | CD7: 0 | CE7: =+CE$6*$C7 -> 31098.815 | CF7: =+CF$6*$C7 -> 0 | CG7: =+CG$6*$C7 -> 1402.9548 | CH7: =+CH$6*$C7 -> 12977.488 | CI7: =+CI$6*$C7 -> 18881.544 | CJ7: =+CJ$6*$C7 -> 18881.544 | CK7: 0 | CL7: =+CL$6*$C7 -> 31098.815 | CM7: =+CM$6*$C7 -> 31098.815 | CN7: =+CN$6*$C7 -> 1402.9548 | CO7: =+CO$6*$C7 -> 0 | CP7: =+CP$6*$C7 -> 18881.544 | CQ7: =+CQ$6*$C7 -> 18881.544 | CR7: 0 | CS7: =SUM(BO7:CR7) -> 373713.14 | CT7: =+CT$6*$C7 -> 31098.815 | CU7: =+CU$6*$C7 -> 31098.815 | CV7: =+CV$6*$C7 -> 1402.9548 | CW7: =+CW$6*$C7 -> 0 | CX7: =+CX$6*$C7 -> 18881.544 | CY7: =+CY$6*$C7 -> 18881.544 | CZ7: =+CZ$6*$C7 -> 18881.544 | DA7: =+DA$6*$C7 -> 31098.815 | ... DD7: =+DD$6*$C7 -> 0 | DE7: 0 | DF7: =+DF$6*$C7 -> 18881.544 | DG7: =+DG$6*$C7 -> 18881.544 | DH7: =+DH$6*$C7 -> 31098.815 | DI7: =+DI$6*$C7 -> 0 | DJ7: =+DJ$6*$C7 -> 1402.9548 | DK7: =+DK$6*$C7 -> 12977.488 | DL7: 0 | DM7: =+DM$6*$C7 -> 18881.544 | DN7: =+DN$6*$C7 -> 18881.544 | DO7: =+DO$6*$C7 -> 31098.815 | DP7: =+DP$6*$C7 -> 31098.815 | DQ7: =+DQ$6*$C7 -> 1402.9548 | DR7: =+DR$6*$C7 -> 0 | DS7: 0 | DT7: =+DT$6*$C7 -> 18881.544 | DU7: =+DU$6*$C7 -> 18881.544 | DV7: =+DV$6*$C7 -> 31098.815 | DW7: =+DW$6*$C7 -> 0 | DX7: =+DX$6*$C7 -> 0 | DY7: =+SUM(CT7:DX7) -> 404811.96 | DZ7: =+DZ$6*$C7 -> 0 | EA7: =+EA$6*$C7 -> 18881.544 | EB7: =+EB$6*$C7 -> 18881.544 | EC7: =+EC$6*$C7 -> 18881.544 | ED7: =+ED$6*$C7 -> 31098.815 | EE7: =+EE$6*$C7 -> 0 | EF7: =+EF$6*$C7 -> 0 | EG7: =+EG$6*$C7 -> 0 | ... EJ7: =+EJ$6*$C7 -> 18881.544 | EK7: 0 | EL7: =+EL$6*$C7 -> 0 | EM7: =+EM$6*$C7 -> 1402.9548 | EN7: =+EN$6*$C7 -> 12977.488 | EO7: =+EO$6*$C7 -> 18881.544 | EP7: =+EP$6*$C7 -> 18881.544 | EQ7: =+EQ$6*$C7 -> 18881.544 | ER7: 0 | ES7: =+ES$6*$C7 -> 31098.815 | ET7: =+ET$6*$C7 -> 1402.9548 | EU7: =+EU$6*$C7 -> 0 | EV7: =+EV$6*$C7 -> 18881.544 | EW7: =+EW$6*$C7 -> 18881.544 | EX7: =+EX$6*$C7 -> 18881.544 | EY7: 0 | EZ7: =+EZ$6*$C7 -> 0 | FA7: =+FA$6*$C7 -> 0 | FB7: =+FB$6*$C7 -> 0 | FC7: =+FC$6*$C7 -> 18881.544 | FD7: =+SUM(DZ7:FC7) -> 323441.11 | FE7: =+FE$6*$C7 -> 18881.544 | FF7: =+FF$6*$C7 -> 31098.815 | FG7: =+FG$6*$C7 -> 0 | FH7: =+FH$6*$C7 -> 0 | FI7: =+FI$6*$C7 -> 0 | FJ7: =+FJ$6*$C7 -> 18881.544 | FK7: =+FK$6*$C7 -> 18881.544 | FL7: =+FL$6*$C7 -> 18881.544 | ... FO7: =+FO$6*$C7 -> 1402.9548 | FP7: 0 | FQ7: =+FQ$6*$C7 -> 18881.544 | FR7: =+FR$6*$C7 -> 18881.544 | FS7: =+FS$6*$C7 -> 18881.544 | FT7: =+FT$6*$C7 -> 31098.815 | FU7: =+FU$6*$C7 -> 31098.815 | FV7: =+FV$6*$C7 -> 1402.9548 | FW7: 0 | FX7: =+FX$6*$C7 -> 18881.544 | FY7: =+FY$6*$C7 -> 18881.544 | FZ7: =+FZ$6*$C7 -> 18881.544 | GA7: =+GA$6*$C7 -> 31098.815 | GB7: =+GB$6*$C7 -> 0 | GC7: =+GC$6*$C7 -> 0 | GD7: 0 | GE7: =+GE$6*$C7 -> 18881.544 | GF7: =+GF$6*$C7 -> 18881.544 | GG7: =+GG$6*$C7 -> 18881.544 | GH7: =+GH$6*$C7 -> 31098.815 | GI7: =+GI$6*$C7 -> 0 | GJ7: =+SUM(FE7:GI7) -> 434858.88 | GK7: =+GK$6*$C7 -> 0 | GL7: =+GL$6*$C7 -> 0 | GM7: =+GM$6*$C7 -> 18881.544 | GN7: =+GN$6*$C7 -> 18881.544 | GO7: =+GO$6*$C7 -> 18881.544 | GP7: =+GP$6*$C7 -> 31098.815 | GQ7: =+GQ$6*$C7 -> 0 | GR7: =+GR$6*$C7 -> 1402.9548 | ... GU7: =+GU$6*$C7 -> 18881.544 | GV7: 0 | GW7: =+GW$6*$C7 -> 31098.815 | GX7: =+GX$6*$C7 -> 31098.815 | GY7: =+GY$6*$C7 -> 1402.9548 | GZ7: =+GZ$6*$C7 -> 0 | HA7: =+HA$6*$C7 -> 18881.544 | HB7: =+HB$6*$C7 -> 18881.544 | HC7: 0 | HD7: =+HD$6*$C7 -> 31098.815 | HE7: =+HE$6*$C7 -> 0 | HF7: =+HF$6*$C7 -> 0 | HG7: =+HG$6*$C7 -> 0 | HH7: =+HH$6*$C7 -> 18881.544 | HI7: =+HI$6*$C7 -> 18881.544 | HJ7: 0 | HK7: =+HK$6*$C7 -> 31098.815 | HL7: =+HL$6*$C7 -> 0 | HM7: =+HM$6*$C7 -> 1402.9548 | HN7: =+HN$6*$C7 -> 12977.488 | HO7: =+HO$6*$C7 -> 18881.544 | HP7: =+SUM(GK7:HO7) -> 374473.36 | HQ7: =+HQ$6*$C7 -> 18881.544 | HR7: =+HR$6*$C7 -> 18881.544 | HS7: =+HS$6*$C7 -> 31098.815 | HT7: =+HT$6*$C7 -> 0 | HU7: =+HU$6*$C7 -> 1402.9548 | HV7: =+HV$6*$C7 -> 12977.488 | HW7: =+HW$6*$C7 -> 18881.544 | HX7: =+HX$6*$C7 -> 18881.544 | ... IA7: =+IA$6*$C7 -> 31098.815 | IB7: 0 | IC7: =+IC$6*$C7 -> 0 | ID7: =+ID$6*$C7 -> 18881.544 | IE7: =+IE$6*$C7 -> 18881.544 | IF7: =+IF$6*$C7 -> 18881.544 | IG7: =+IG$6*$C7 -> 31098.815 | IH7: =+IH$6*$C7 -> 0 | II7: 0 | IJ7: =+IJ$6*$C7 -> 0 | IK7: =+IK$6*$C7 -> 18881.544 | IL7: =+IL$6*$C7 -> 18881.544 | IM7: =+IM$6*$C7 -> 18881.544 | IN7: =+IN$6*$C7 -> 31098.815 | IO7: =+IO$6*$C7 -> 0 | IP7: 0 | IQ7: =+IQ$6*$C7 -> 12977.488 | IR7: =+IR$6*$C7 -> 18881.544 | IS7: =+IS$6*$C7 -> 18881.544 | IT7: =+IT$6*$C7 -> 18881.544 | IU7: =+SUM(HQ7:IT7) -> 447193.63 | IV7: =+IV$6*$C7 -> 0 | IW7: =+IW$6*$C7 -> 1402.9548 | IX7: =+IX$6*$C7 -> 12977.488 | IY7: =+IY$6*$C7 -> 18881.544 | IZ7: =+IZ$6*$C7 -> 18881.544 | JA7: =+JA$6*$C7 -> 18881.544 | JB7: =+JB$6*$C7 -> 31098.815 | JC7: =+JC$6*$C7 -> 31098.815 | ... JF7: =+JF$6*$C7 -> 18881.544 | JG7: 0 | JH7: =+JH$6*$C7 -> 18881.544 | JI7: =+JI$6*$C7 -> 31098.815 | JJ7: =+JJ$6*$C7 -> 0 | JK7: =+JK$6*$C7 -> 0 | JL7: =+JL$6*$C7 -> 0 | JM7: =+JM$6*$C7 -> 18881.544 | JN7: 0 | JO7: =+JO$6*$C7 -> 18881.544 | JP7: =+JP$6*$C7 -> 31098.815 | JQ7: =+JQ$6*$C7 -> 0 | JR7: =+JR$6*$C7 -> 1402.9548 | JS7: =+JS$6*$C7 -> 12977.488 | JT7: =+JT$6*$C7 -> 18881.544 | JU7: 0 | JV7: =+JV$6*$C7 -> 18881.544 | JW7: =+JW$6*$C7 -> 31098.815 | JX7: =+JX$6*$C7 -> 31098.815 | JY7: =+JY$6*$C7 -> 1402.9548 | JZ7: =+JZ$6*$C7 -> 0 | KA7: =+SUM(IV7:JZ7) -> 388093.59 | KB7: =+KB$6*$C7 -> 18881.544 | KC7: =+KC$6*$C7 -> 18881.544 | KD7: =+KD$6*$C7 -> 18881.544 | KE7: =+KE$6*$C7 -> 31098.815 | KF7: =+KF$6*$C7 -> 31098.815 | KG7: =+KG$6*$C7 -> 1402.9548 | KH7: =+KH$6*$C7 -> 0 | KI7: =+KI$6*$C7 -> 18881.544 | ... KL7: =+KL$6*$C7 -> 31098.815 | KM7: 0 | KN7: =+KN$6*$C7 -> 0 | KO7: =+KO$6*$C7 -> 0 | KP7: =+KP$6*$C7 -> 18881.544 | KQ7: =+KQ$6*$C7 -> 18881.544 | KR7: =+KR$6*$C7 -> 18881.544 | KS7: =+KS$6*$C7 -> 31098.815 | KT7: 0 | KU7: =+KU$6*$C7 -> 1402.9548 | KV7: =+KV$6*$C7 -> 12977.488 | KW7: =+KW$6*$C7 -> 18881.544 | KX7: =+KX$6*$C7 -> 18881.544 | KY7: =+KY$6*$C7 -> 18881.544 | KZ7: =+KZ$6*$C7 -> 31098.815 | LA7: 0 | LB7: =+LB$6*$C7 -> 1402.9548 | LC7: =+LC$6*$C7 -> 0 | LD7: =+LD$6*$C7 -> 18881.544 | LE7: =+LE$6*$C7 -> 18881.544 | LF7: =+SUM(KB7:LE7) -> 437022.05 | LG7: =+LG$6*$C7 -> 31098.815 | LH7: =+LH$6*$C7 -> 31098.815 | LI7: =+LI$6*$C7 -> 1402.9548 | LJ7: =+LJ$6*$C7 -> 0 | LK7: =+LK$6*$C7 -> 18881.544 | LL7: =+LL$6*$C7 -> 18881.544 | LM7: =+LM$6*$C7 -> 18881.544 | LN7: =+LN$6*$C7 -> 31098.815 | ... LQ7: =+LQ$6*$C7 -> 0 | LR7: 0 | LS7: =+LS$6*$C7 -> 18881.544 | LT7: =+LT$6*$C7 -> 18881.544 | LU7: =+LU$6*$C7 -> 31098.815 | LV7: =+LV$6*$C7 -> 0 | LW7: =+LW$6*$C7 -> 1402.9548 | LX7: =+LX$6*$C7 -> 12977.488 | LY7: 0 | LZ7: =+LZ$6*$C7 -> 18881.544 | MA7: =+MA$6*$C7 -> 18881.544 | MB7: =+MB$6*$C7 -> 31098.815 | MC7: =+MC$6*$C7 -> 31098.815 | MD7: =+MD$6*$C7 -> 1402.9548 | ME7: =+ME$6*$C7 -> 0 | MF7: 0 | MG7: =+MG$6*$C7 -> 18881.544 | MH7: =+MH$6*$C7 -> 18881.544 | MI7: =+MI$6*$C7 -> 31098.815 | MJ7: =+MJ$6*$C7 -> 0 | MK7: =+MK$6*$C7 -> 0 | ML7: =+SUM(LG7:MK7) -> 404811.96 | MM7: =+MM$6*$C7 -> 0 | MN7: =+MN$6*$C7 -> 18881.544 | MO7: =+MO$6*$C7 -> 18881.544 | MP7: =+MP$6*$C7 -> 18881.544 | MQ7: =+MQ$6*$C7 -> 31098.815 | MR7: =+MR$6*$C7 -> 0 | MS7: =+MS$6*$C7 -> 0 | MT7: =+MT$6*$C7 -> 0 | ... MW7: =+MW$6*$C7 -> 18881.544 | MX7: 0 | MY7: =+MY$6*$C7 -> 0 | MZ7: =+MZ$6*$C7 -> 1402.9548 | NA7: =+NA$6*$C7 -> 12977.488 | NB7: =+NB$6*$C7 -> 18881.544 | NC7: =+NC$6*$C7 -> 18881.544 | ND7: =+ND$6*$C7 -> 18881.544 | NE7: 0 | NF7: =+NF$6*$C7 -> 31098.815 | NG7: =+NG$6*$C7 -> 1402.9548 | NH7: =+NH$6*$C7 -> 0 | NI7: =+NI$6*$C7 -> 18881.544 | NJ7: =+NJ$6*$C7 -> 18881.544 | NK7: =+NK$6*$C7 -> 18881.544 | NL7: 0 | NM7: =+NM$6*$C7 -> 0 | NN7: =+NN$6*$C7 -> 0 | NO7: =+NO$6*$C7 -> 0 | NP7: =+NP$6*$C7 -> 18881.544 | NQ7: =+NQ$6*$C7 -> 18881.544 | NR7: =+SUM(MM7:NQ7) -> 342322.65 | NS7: =+NS$6*$C7 -> 18881.544 | NT7: =+NT$6*$C7 -> 31098.815 | NU7: =+NU$6*$C7 -> 0 | NV7: =+NV$6*$C7 -> 0 | NW7: =+NW$6*$C7 -> 0 | NX7: =+NX$6*$C7 -> 18881.544 | NY7: =+NY$6*$C7 -> 18881.544 | NZ7: =+NZ$6*$C7 -> 18881.544 | ... OC7: =+OC$6*$C7 -> 1402.9548 | OD7: 0 | OE7: =+OE$6*$C7 -> 18881.544 | OF7: =+OF$6*$C7 -> 18881.544 | OG7: =+OG$6*$C7 -> 18881.544 | OH7: =+OH$6*$C7 -> 31098.815 | OI7: =+OI$6*$C7 -> 31098.815 | OJ7: =+OJ$6*$C7 -> 1402.9548 | OK7: 0 | OL7: =+OL$6*$C7 -> 18881.544 | OM7: =+OM$6*$C7 -> 18881.544 | ON7: =+ON$6*$C7 -> 18881.544 | OO7: =+OO$6*$C7 -> 31098.815 | OP7: =+OP$6*$C7 -> 0 | OQ7: =+OQ$6*$C7 -> 0 | OR7: 0 | OS7: =+OS$6*$C7 -> 18881.544 | OT7: =+OT$6*$C7 -> 18881.544 | OU7: =+SUM(NS7:OT7) -> 384878.52 | OV7: =+OV$6*$C7 -> 0 | OW7: =+OW$6*$C7 -> 0 | OX7: =+OX$6*$C7 -> 18881.544 | OY7: =+OY$6*$C7 -> 18881.544 | OZ7: =+OZ$6*$C7 -> 18881.544 | PA7: =+PA$6*$C7 -> 31098.815 | PB7: =+PB$6*$C7 -> 0 | PC7: =+PC$6*$C7 -> 1402.9548 | ... PF7: =+PF$6*$C7 -> 18881.544 | PG7: 0 | PH7: =+PH$6*$C7 -> 31098.815 | PI7: =+PI$6*$C7 -> 31098.815 | PJ7: =+PJ$6*$C7 -> 1402.9548 | PK7: =+PK$6*$C7 -> 0 | PL7: =+PL$6*$C7 -> 18881.544 | PM7: =+PM$6*$C7 -> 18881.544 | PN7: 0 | PO7: =+PO$6*$C7 -> 31098.815 | PP7: =+PP$6*$C7 -> 0 | PQ7: =+PQ$6*$C7 -> 0 | PR7: =+PR$6*$C7 -> 0 | PS7: =+PS$6*$C7 -> 18881.544 | PT7: =+PT$6*$C7 -> 18881.544 | PU7: 0 | PV7: =+PV$6*$C7 -> 0 | PW7: =+PW$6*$C7 -> 0 | PX7: =+PX$6*$C7 -> 1402.9548 | PY7: =+PY$6*$C7 -> 12977.488 | PZ7: =+PZ$6*$C7 -> 18881.544 | QA7: =+SUM(OV7:PZ7) -> 343374.55 | QB7: =+QB$6*$C7 -> 18881.544 | QC7: =+QC$6*$C7 -> 18881.544 | QD7: =+QD$6*$C7 -> 31098.815 | QE7: =+QE$6*$C7 -> 0 | QF7: =+QF$6*$C7 -> 1402.9548 | QG7: =+QG$6*$C7 -> 12977.488 | QH7: =+QH$6*$C7 -> 18881.544 | QI7: =+QI$6*$C7 -> 18881.544 | ... QL7: =+QL$6*$C7 -> 31098.815 | QM7: 0 | QN7: =+QN$6*$C7 -> 0 | QO7: =+QO$6*$C7 -> 18881.544 | QP7: =+QP$6*$C7 -> 18881.544 | QQ7: =+QQ$6*$C7 -> 18881.544 | QR7: =+QR$6*$C7 -> 31098.815 | QS7: =+QS$6*$C7 -> 0 | QT7: 0 | QU7: =+QU$6*$C7 -> 0 | QV7: =+QV$6*$C7 -> 18881.544 | QW7: =+QW$6*$C7 -> 18881.544 | QX7: =+QX$6*$C7 -> 397856.01 | QY7: =+QY$6*$C7 -> 0 | QZ7: =+QZ$6*$C7 -> 0 | RA7: 0 | RB7: =+RB$6*$C7 -> 12977.488 | RC7: =+RC$6*$C7 -> 18881.544 | RD7: =+RD$6*$C7 -> 18881.544 | RE7: =+RE$6*$C7 -> 18881.544 | RF7: =+SUM(QB7:RE7) -> 795069.28 | RG7: =+RG$6*$C7 -> 0 | RH7: =+RH$6*$C7 -> 1402.9548 | RI7: =+RI$6*$C7 -> 12977.488 | RJ7: =+RJ$6*$C7 -> 18881.544 | RK7: =+RK$6*$C7 -> 18881.544 | RL7: =+RL$6*$C7 -> 18881.544 | RM7: =+RM$6*$C7 -> 31098.815 | RN7: =+RN$6*$C7 -> 31098.815 | ... RQ7: =+RQ$6*$C7 -> 18881.544 | RR7: 0 | RS7: =+RS$6*$C7 -> 18881.544 | RT7: =+RT$6*$C7 -> 31098.815 | RU7: =+RU$6*$C7 -> 0 | RV7: =+RV$6*$C7 -> 0 | RW7: =+RW$6*$C7 -> 0 | RX7: =+RX$6*$C7 -> 18881.544 | RY7: 0 | RZ7: =+RZ$6*$C7 -> 397856.01 | SA7: =+SA$6*$C7 -> 0 | SB7: =+SB$6*$C7 -> 0 | SC7: =+SC$6*$C7 -> 1402.9548 | SD7: =+SD$6*$C7 -> 12977.488 | SE7: =+SE$6*$C7 -> 18881.544 | SF7: 0 | SG7: =+SG$6*$C7 -> 18881.544 | SH7: =+SH$6*$C7 -> 31098.815 | SI7: =+SI$6*$C7 -> 31098.815 | SJ7: =+SJ$6*$C7 -> 1402.9548 | SK7: =+SK$6*$C7 -> 0 | SL7: =+SUM(RG7:SK7) -> 735969.23 | SM7: =+SM$6*$C7 -> 18881.544 | SN7: =+SN$6*$C7 -> 18881.544 | SO7: =+SO$6*$C7 -> 18881.544 | SP7: =+SP$6*$C7 -> 31098.815 | SQ7: =+SQ$6*$C7 -> 31098.815 | SR7: =+SR$6*$C7 -> 1402.9548 | SS7: =+SS$6*$C7 -> 0 | ST7: =+ST$6*$C7 -> 18881.544 | ... SW7: =+SW$6*$C7 -> 31098.815 | SX7: 0 | SY7: =+SY$6*$C7 -> 0 | SZ7: =+SZ$6*$C7 -> 0 | TA7: =+TA$6*$C7 -> 18881.544 | TB7: =+TB$6*$C7 -> 18881.544 | TC7: =+TC$6*$C7 -> 397856.01 | TD7: =+TD$6*$C7 -> 0 | TE7: 0 | TF7: =+TF$6*$C7 -> 1402.9548 | TG7: =+TG$6*$C7 -> 12977.488 | TH7: =+TH$6*$C7 -> 18881.544 | TI7: =+TI$6*$C7 -> 18881.544 | TJ7: =+TJ$6*$C7 -> 18881.544 | TK7: =+TK$6*$C7 -> 31098.815 | TL7: 0 | TM7: =+TM$6*$C7 -> 1402.9548 | TN7: =+TN$6*$C7 -> 0 | TO7: =+TO$6*$C7 -> 18881.544 | TP7: =+TP$6*$C7 -> 18881.544 | TQ7: =+SUM(SM7:TP7) -> 784897.7 | TR7: =+TR$6*$C7 -> 31098.815 | TS7: =+TS$6*$C7 -> 31098.815 | TT7: =+TT$6*$C7 -> 1402.9548 | TU7: =+TU$6*$C7 -> 0 | TV7: =+TV$6*$C7 -> 18881.544 | TW7: =+TW$6*$C7 -> 18881.544 | TX7: =+TX$6*$C7 -> 18881.544 | TY7: =+TY$6*$C7 -> 31098.815 | ... UB7: =+UB$6*$C7 -> 0 | UC7: 0 | UD7: =+UD$6*$C7 -> 18881.544 | UE7: =+UE$6*$C7 -> 397856.01 | UF7: =+UF$6*$C7 -> 0 | UG7: =+UG$6*$C7 -> 0 | UH7: =+UH$6*$C7 -> 1402.9548 | UI7: =+UI$6*$C7 -> 12977.488 | UJ7: 0 | UK7: =+UK$6*$C7 -> 18881.544 | UL7: =+UL$6*$C7 -> 18881.544 | UM7: =+UM$6*$C7 -> 31098.815 | UN7: =+UN$6*$C7 -> 31098.815 | UO7: =+UO$6*$C7 -> 1402.9548 | UP7: =+UP$6*$C7 -> 0 | UQ7: 0 | UR7: =+UR$6*$C7 -> 18881.544 | US7: =+US$6*$C7 -> 18881.544 | UT7: =+UT$6*$C7 -> 31098.815 | UU7: =+UU$6*$C7 -> 0 | UV7: =+UV$6*$C7 -> 0 | UW7: =+SUM(TR7:UV7) -> 752687.61 | UX7: =+UX$6*$C7 -> 0 | UY7: =+UY$6*$C7 -> 18881.544 | UZ7: =+UZ$6*$C7 -> 18881.544 | VA7: =+VA$6*$C7 -> 18881.544 | VB7: =+VB$6*$C7 -> 31098.815 | VC7: =+VC$6*$C7 -> 0 | VD7: =+VD$6*$C7 -> 0 | VE7: =+VE$6*$C7 -> 0 | ... VH7: =+VH$6*$C7 -> 397856.01 | VI7: 0 | VJ7: =+VJ$6*$C7 -> 0 | VK7: =+VK$6*$C7 -> 1402.9548 | VL7: =+VL$6*$C7 -> 12977.488 | VM7: =+VM$6*$C7 -> 18881.544 | VN7: =+VN$6*$C7 -> 18881.544 | VO7: =+VO$6*$C7 -> 18881.544 | VP7: 0 | VQ7: =+VQ$6*$C7 -> 31098.815 | VR7: =+VR$6*$C7 -> 1402.9548 | VS7: =+VS$6*$C7 -> 0 | VT7: =+VT$6*$C7 -> 18881.544 | VU7: =+VU$6*$C7 -> 18881.544 | VV7: =+VV$6*$C7 -> 18881.544 | VW7: 0 | VX7: =+VX$6*$C7 -> 0 | VY7: =+VY$6*$C7 -> 0 | VZ7: =+VZ$6*$C7 -> 0 | WA7: =+WA$6*$C7 -> 18881.544 | WB7: =+WB$6*$C7 -> 18881.544 | WC7: =+SUM(UX7:WB7) -> 721297.11
B8: CHEQUE (D+1) | C8: =+[4]DRE!AC9 -> 0.055007171 | D8: =+D$6*$C8 -> 0 | E8: =+E$6*$C8 -> 0 | F8: =+F$6*$C8 -> 2692.0604 | G8: =+G$6*$C8 -> 2692.0604 | H8: =+H$6*$C8 -> 2692.0604 | I8: =+I$6*$C8 -> 4433.9534 | J8: =+J$6*$C8 -> 4433.9534 | K8: =+K$6*$C8 -> 200.02808 | ... AE8: =+AE$6*$C8 -> 4433.9534 | AH8: =+SUM(D8:AE8) -> 61158.783 | AI8: =+AI$6*$C8 -> 0 | AJ8: =+AJ$6*$C8 -> 0 | AK8: =+AK$6*$C8 -> 2692.0604 | AL8: =+AL$6*$C8 -> 2692.0604 | AM8: =+AM$6*$C8 -> 2692.0604 | AN8: =+AN$6*$C8 -> 4433.9534 | AO8: =+AO$6*$C8 -> 4433.9534 | AP8: =+AP$6*$C8 -> 200.02808 | ... AS8: =+AS$6*$C8 -> 2692.0604 | AT8: 0 | AU8: =+AU$6*$C8 -> 4433.9534 | AV8: =+AV$6*$C8 -> 0 | AW8: =+AW$6*$C8 -> 0 | AX8: =+AX$6*$C8 -> 0 | AY8: =+AY$6*$C8 -> 2692.0604 | AZ8: =+AZ$6*$C8 -> 2692.0604 | BA8: 0 | BB8: =+BB$6*$C8 -> 4433.9534 | BC8: =+BC$6*$C8 -> 0 | BD8: =+BD$6*$C8 -> 200.02808 | BE8: =+BE$6*$C8 -> 1850.282 | BF8: =+BF$6*$C8 -> 2692.0604 | BG8: =+BG$6*$C8 -> 2692.0604 | BH8: 0 | BI8: =+BI$6*$C8 -> 4433.9534 | BJ8: =+BJ$6*$C8 -> 4433.9534 | BK8: =+BK$6*$C8 -> 200.02808 | BL8: =+BL$6*$C8 -> 0 | BM8: =+BM$6*$C8 -> 2692.0604 | BN8: =+SUM(AI8:BM8) -> 55974.69 | BO8: =+BO$6*$C8 -> 2692.0604 | BP8: 0 | BQ8: =+BQ$6*$C8 -> 4433.9534 | BR8: =+BR$6*$C8 -> 4433.9534 | BS8: =+BS$6*$C8 -> 200.02808 | BT8: =+BT$6*$C8 -> 0 | BU8: =+BU$6*$C8 -> 2692.0604 | BV8: =+BV$6*$C8 -> 2692.0604 | BW8: 0 | BX8: =+BX$6*$C8 -> 4433.9534 | BY8: =+BY$6*$C8 -> 0 | BZ8: =+BZ$6*$C8 -> 0 | CA8: =+CA$6*$C8 -> 0 | CB8: =+CB$6*$C8 -> 2692.0604 | CC8: =+CC$6*$C8 -> 2692.0604 | CD8: 0 | CE8: =+CE$6*$C8 -> 4433.9534 | CF8: =+CF$6*$C8 -> 0 | CG8: =+CG$6*$C8 -> 200.02808 | CH8: =+CH$6*$C8 -> 1850.282 | CI8: =+CI$6*$C8 -> 2692.0604 | CJ8: =+CJ$6*$C8 -> 2692.0604 | CK8: 0 | CL8: =+CL$6*$C8 -> 4433.9534 | CM8: =+CM$6*$C8 -> 4433.9534 | CN8: =+CN$6*$C8 -> 200.02808 | CO8: =+CO$6*$C8 -> 0 | CP8: =+CP$6*$C8 -> 2692.0604 | CQ8: =+CQ$6*$C8 -> 2692.0604 | CR8: 0 | CS8: =SUM(BO8:CR8) -> 53282.63 | CT8: =+CT$6*$C8 -> 4433.9534 | CU8: =+CU$6*$C8 -> 4433.9534 | CV8: =+CV$6*$C8 -> 200.02808 | CW8: =+CW$6*$C8 -> 0 | CX8: =+CX$6*$C8 -> 2692.0604 | CY8: =+CY$6*$C8 -> 2692.0604 | CZ8: =+CZ$6*$C8 -> 2692.0604 | DA8: =+DA$6*$C8 -> 4433.9534 | ... DD8: =+DD$6*$C8 -> 0 | DE8: 0 | DF8: =+DF$6*$C8 -> 2692.0604 | DG8: =+DG$6*$C8 -> 2692.0604 | DH8: =+DH$6*$C8 -> 4433.9534 | DI8: =+DI$6*$C8 -> 0 | DJ8: =+DJ$6*$C8 -> 200.02808 | DK8: =+DK$6*$C8 -> 1850.282 | DL8: 0 | DM8: =+DM$6*$C8 -> 2692.0604 | DN8: =+DN$6*$C8 -> 2692.0604 | DO8: =+DO$6*$C8 -> 4433.9534 | DP8: =+DP$6*$C8 -> 4433.9534 | DQ8: =+DQ$6*$C8 -> 200.02808 | DR8: =+DR$6*$C8 -> 0 | DS8: 0 | DT8: =+DT$6*$C8 -> 2692.0604 | DU8: =+DU$6*$C8 -> 2692.0604 | DV8: =+DV$6*$C8 -> 4433.9534 | DW8: =+DW$6*$C8 -> 0 | DX8: =+DX$6*$C8 -> 0 | DY8: =+SUM(CT8:DX8) -> 57716.583 | DZ8: =+DZ$6*$C8 -> 0 | EA8: =+EA$6*$C8 -> 2692.0604 | EB8: =+EB$6*$C8 -> 2692.0604 | EC8: =+EC$6*$C8 -> 2692.0604 | ED8: =+ED$6*$C8 -> 4433.9534 | EE8: =+EE$6*$C8 -> 0 | EF8: =+EF$6*$C8 -> 0 | EG8: =+EG$6*$C8 -> 0 | ... EJ8: =+EJ$6*$C8 -> 2692.0604 | EK8: 0 | EL8: =+EL$6*$C8 -> 0 | EM8: =+EM$6*$C8 -> 200.02808 | EN8: =+EN$6*$C8 -> 1850.282 | EO8: =+EO$6*$C8 -> 2692.0604 | EP8: =+EP$6*$C8 -> 2692.0604 | EQ8: =+EQ$6*$C8 -> 2692.0604 | ER8: 0 | ES8: =+ES$6*$C8 -> 4433.9534 | ET8: =+ET$6*$C8 -> 200.02808 | EU8: =+EU$6*$C8 -> 0 | EV8: =+EV$6*$C8 -> 2692.0604 | EW8: =+EW$6*$C8 -> 2692.0604 | EX8: =+EX$6*$C8 -> 2692.0604 | EY8: 0 | EZ8: =+EZ$6*$C8 -> 0 | FA8: =+FA$6*$C8 -> 0 | FB8: =+FB$6*$C8 -> 0 | FC8: =+FC$6*$C8 -> 2692.0604 | FD8: =+SUM(DZ8:FC8) -> 46115.03 | FE8: =+FE$6*$C8 -> 2692.0604 | FF8: =+FF$6*$C8 -> 4433.9534 | FG8: =+FG$6*$C8 -> 0 | FH8: =+FH$6*$C8 -> 0 | FI8: =+FI$6*$C8 -> 0 | FJ8: =+FJ$6*$C8 -> 2692.0604 | FK8: =+FK$6*$C8 -> 2692.0604 | FL8: =+FL$6*$C8 -> 2692.0604 | ... FO8: =+FO$6*$C8 -> 200.02808 | FP8: 0 | FQ8: =+FQ$6*$C8 -> 2692.0604 | FR8: =+FR$6*$C8 -> 2692.0604 | FS8: =+FS$6*$C8 -> 2692.0604 | FT8: =+FT$6*$C8 -> 4433.9534 | FU8: =+FU$6*$C8 -> 4433.9534 | FV8: =+FV$6*$C8 -> 200.02808 | FW8: 0 | FX8: =+FX$6*$C8 -> 2692.0604 | FY8: =+FY$6*$C8 -> 2692.0604 | FZ8: =+FZ$6*$C8 -> 2692.0604 | GA8: =+GA$6*$C8 -> 4433.9534 | GB8: =+GB$6*$C8 -> 0 | GC8: =+GC$6*$C8 -> 0 | GD8: 0 | GE8: =+GE$6*$C8 -> 2692.0604 | GF8: =+GF$6*$C8 -> 2692.0604 | GG8: =+GG$6*$C8 -> 2692.0604 | GH8: =+GH$6*$C8 -> 4433.9534 | GI8: =+GI$6*$C8 -> 0 | GJ8: =+SUM(FE8:GI8) -> 62000.561 | GK8: =+GK$6*$C8 -> 0 | GL8: =+GL$6*$C8 -> 0 | GM8: =+GM$6*$C8 -> 2692.0604 | GN8: =+GN$6*$C8 -> 2692.0604 | GO8: =+GO$6*$C8 -> 2692.0604 | GP8: =+GP$6*$C8 -> 4433.9534 | GQ8: =+GQ$6*$C8 -> 0 | GR8: =+GR$6*$C8 -> 200.02808 | ... GU8: =+GU$6*$C8 -> 2692.0604 | GV8: 0 | GW8: =+GW$6*$C8 -> 4433.9534 | GX8: =+GX$6*$C8 -> 4433.9534 | GY8: =+GY$6*$C8 -> 200.02808 | GZ8: =+GZ$6*$C8 -> 0 | HA8: =+HA$6*$C8 -> 2692.0604 | HB8: =+HB$6*$C8 -> 2692.0604 | HC8: 0 | HD8: =+HD$6*$C8 -> 4433.9534 | HE8: =+HE$6*$C8 -> 0 | HF8: =+HF$6*$C8 -> 0 | HG8: =+HG$6*$C8 -> 0 | HH8: =+HH$6*$C8 -> 2692.0604 | HI8: =+HI$6*$C8 -> 2692.0604 | HJ8: 0 | HK8: =+HK$6*$C8 -> 4433.9534 | HL8: =+HL$6*$C8 -> 0 | HM8: =+HM$6*$C8 -> 200.02808 | HN8: =+HN$6*$C8 -> 1850.282 | HO8: =+HO$6*$C8 -> 2692.0604 | HP8: =+SUM(GK8:HO8) -> 53391.019 | HQ8: =+HQ$6*$C8 -> 2692.0604 | HR8: =+HR$6*$C8 -> 2692.0604 | HS8: =+HS$6*$C8 -> 4433.9534 | HT8: =+HT$6*$C8 -> 0 | HU8: =+HU$6*$C8 -> 200.02808 | HV8: =+HV$6*$C8 -> 1850.282 | HW8: =+HW$6*$C8 -> 2692.0604 | HX8: =+HX$6*$C8 -> 2692.0604 | ... IA8: =+IA$6*$C8 -> 4433.9534 | IB8: 0 | IC8: =+IC$6*$C8 -> 0 | ID8: =+ID$6*$C8 -> 2692.0604 | IE8: =+IE$6*$C8 -> 2692.0604 | IF8: =+IF$6*$C8 -> 2692.0604 | IG8: =+IG$6*$C8 -> 4433.9534 | IH8: =+IH$6*$C8 -> 0 | II8: 0 | IJ8: =+IJ$6*$C8 -> 0 | IK8: =+IK$6*$C8 -> 2692.0604 | IL8: =+IL$6*$C8 -> 2692.0604 | IM8: =+IM$6*$C8 -> 2692.0604 | IN8: =+IN$6*$C8 -> 4433.9534 | IO8: =+IO$6*$C8 -> 0 | IP8: 0 | IQ8: =+IQ$6*$C8 -> 1850.282 | IR8: =+IR$6*$C8 -> 2692.0604 | IS8: =+IS$6*$C8 -> 2692.0604 | IT8: =+IT$6*$C8 -> 2692.0604 | IU8: =+SUM(HQ8:IT8) -> 63759.204 | IV8: =+IV$6*$C8 -> 0 | IW8: =+IW$6*$C8 -> 200.02808 | IX8: =+IX$6*$C8 -> 1850.282 | IY8: =+IY$6*$C8 -> 2692.0604 | IZ8: =+IZ$6*$C8 -> 2692.0604 | JA8: =+JA$6*$C8 -> 2692.0604 | JB8: =+JB$6*$C8 -> 4433.9534 | JC8: =+JC$6*$C8 -> 4433.9534 | ... JF8: =+JF$6*$C8 -> 2692.0604 | JG8: 0 | JH8: =+JH$6*$C8 -> 2692.0604 | JI8: =+JI$6*$C8 -> 4433.9534 | JJ8: =+JJ$6*$C8 -> 0 | JK8: =+JK$6*$C8 -> 0 | JL8: =+JL$6*$C8 -> 0 | JM8: =+JM$6*$C8 -> 2692.0604 | JN8: 0 | JO8: =+JO$6*$C8 -> 2692.0604 | JP8: =+JP$6*$C8 -> 4433.9534 | JQ8: =+JQ$6*$C8 -> 0 | JR8: =+JR$6*$C8 -> 200.02808 | JS8: =+JS$6*$C8 -> 1850.282 | JT8: =+JT$6*$C8 -> 2692.0604 | JU8: 0 | JV8: =+JV$6*$C8 -> 2692.0604 | JW8: =+JW$6*$C8 -> 4433.9534 | JX8: =+JX$6*$C8 -> 4433.9534 | JY8: =+JY$6*$C8 -> 200.02808 | JZ8: =+JZ$6*$C8 -> 0 | KA8: =+SUM(IV8:JZ8) -> 55332.94 | KB8: =+KB$6*$C8 -> 2692.0604 | KC8: =+KC$6*$C8 -> 2692.0604 | KD8: =+KD$6*$C8 -> 2692.0604 | KE8: =+KE$6*$C8 -> 4433.9534 | KF8: =+KF$6*$C8 -> 4433.9534 | KG8: =+KG$6*$C8 -> 200.02808 | KH8: =+KH$6*$C8 -> 0 | KI8: =+KI$6*$C8 -> 2692.0604 | ... KL8: =+KL$6*$C8 -> 4433.9534 | KM8: 0 | KN8: =+KN$6*$C8 -> 0 | KO8: =+KO$6*$C8 -> 0 | KP8: =+KP$6*$C8 -> 2692.0604 | KQ8: =+KQ$6*$C8 -> 2692.0604 | KR8: =+KR$6*$C8 -> 2692.0604 | KS8: =+KS$6*$C8 -> 4433.9534 | KT8: 0 | KU8: =+KU$6*$C8 -> 200.02808 | KV8: =+KV$6*$C8 -> 1850.282 | KW8: =+KW$6*$C8 -> 2692.0604 | KX8: =+KX$6*$C8 -> 2692.0604 | KY8: =+KY$6*$C8 -> 2692.0604 | KZ8: =+KZ$6*$C8 -> 4433.9534 | LA8: 0 | LB8: =+LB$6*$C8 -> 200.02808 | LC8: =+LC$6*$C8 -> 0 | LD8: =+LD$6*$C8 -> 2692.0604 | LE8: =+LE$6*$C8 -> 2692.0604 | LF8: =+SUM(KB8:LE8) -> 62308.979 | LG8: =+LG$6*$C8 -> 4433.9534 | LH8: =+LH$6*$C8 -> 4433.9534 | LI8: =+LI$6*$C8 -> 200.02808 | LJ8: =+LJ$6*$C8 -> 0 | LK8: =+LK$6*$C8 -> 2692.0604 | LL8: =+LL$6*$C8 -> 2692.0604 | LM8: =+LM$6*$C8 -> 2692.0604 | LN8: =+LN$6*$C8 -> 4433.9534 | ... LQ8: =+LQ$6*$C8 -> 0 | LR8: 0 | LS8: =+LS$6*$C8 -> 2692.0604 | LT8: =+LT$6*$C8 -> 2692.0604 | LU8: =+LU$6*$C8 -> 4433.9534 | LV8: =+LV$6*$C8 -> 0 | LW8: =+LW$6*$C8 -> 200.02808 | LX8: =+LX$6*$C8 -> 1850.282 | LY8: 0 | LZ8: =+LZ$6*$C8 -> 2692.0604 | MA8: =+MA$6*$C8 -> 2692.0604 | MB8: =+MB$6*$C8 -> 4433.9534 | MC8: =+MC$6*$C8 -> 4433.9534 | MD8: =+MD$6*$C8 -> 200.02808 | ME8: =+ME$6*$C8 -> 0 | MF8: 0 | MG8: =+MG$6*$C8 -> 2692.0604 | MH8: =+MH$6*$C8 -> 2692.0604 | MI8: =+MI$6*$C8 -> 4433.9534 | MJ8: =+MJ$6*$C8 -> 0 | MK8: =+MK$6*$C8 -> 0 | ML8: =+SUM(LG8:MK8) -> 57716.583 | MM8: =+MM$6*$C8 -> 0 | MN8: =+MN$6*$C8 -> 2692.0604 | MO8: =+MO$6*$C8 -> 2692.0604 | MP8: =+MP$6*$C8 -> 2692.0604 | MQ8: =+MQ$6*$C8 -> 4433.9534 | MR8: =+MR$6*$C8 -> 0 | MS8: =+MS$6*$C8 -> 0 | MT8: =+MT$6*$C8 -> 0 | ... MW8: =+MW$6*$C8 -> 2692.0604 | MX8: 0 | MY8: =+MY$6*$C8 -> 0 | MZ8: =+MZ$6*$C8 -> 200.02808 | NA8: =+NA$6*$C8 -> 1850.282 | NB8: =+NB$6*$C8 -> 2692.0604 | NC8: =+NC$6*$C8 -> 2692.0604 | ND8: =+ND$6*$C8 -> 2692.0604 | NE8: 0 | NF8: =+NF$6*$C8 -> 4433.9534 | NG8: =+NG$6*$C8 -> 200.02808 | NH8: =+NH$6*$C8 -> 0 | NI8: =+NI$6*$C8 -> 2692.0604 | NJ8: =+NJ$6*$C8 -> 2692.0604 | NK8: =+NK$6*$C8 -> 2692.0604 | NL8: 0 | NM8: =+NM$6*$C8 -> 0 | NN8: =+NN$6*$C8 -> 0 | NO8: =+NO$6*$C8 -> 0 | NP8: =+NP$6*$C8 -> 2692.0604 | NQ8: =+NQ$6*$C8 -> 2692.0604 | NR8: =+SUM(MM8:NQ8) -> 48807.09 | NS8: =+NS$6*$C8 -> 2692.0604 | NT8: =+NT$6*$C8 -> 4433.9534 | NU8: =+NU$6*$C8 -> 0 | NV8: =+NV$6*$C8 -> 0 | NW8: =+NW$6*$C8 -> 0 | NX8: =+NX$6*$C8 -> 2692.0604 | NY8: =+NY$6*$C8 -> 2692.0604 | NZ8: =+NZ$6*$C8 -> 2692.0604 | ... OC8: =+OC$6*$C8 -> 200.02808 | OD8: 0 | OE8: =+OE$6*$C8 -> 2692.0604 | OF8: =+OF$6*$C8 -> 2692.0604 | OG8: =+OG$6*$C8 -> 2692.0604 | OH8: =+OH$6*$C8 -> 4433.9534 | OI8: =+OI$6*$C8 -> 4433.9534 | OJ8: =+OJ$6*$C8 -> 200.02808 | OK8: 0 | OL8: =+OL$6*$C8 -> 2692.0604 | OM8: =+OM$6*$C8 -> 2692.0604 | ON8: =+ON$6*$C8 -> 2692.0604 | OO8: =+OO$6*$C8 -> 4433.9534 | OP8: =+OP$6*$C8 -> 0 | OQ8: =+OQ$6*$C8 -> 0 | OR8: 0 | OS8: =+OS$6*$C8 -> 2692.0604 | OT8: =+OT$6*$C8 -> 2692.0604 | OU8: =+SUM(NS8:OT8) -> 54874.548 | OV8: =+OV$6*$C8 -> 0 | OW8: =+OW$6*$C8 -> 0 | OX8: =+OX$6*$C8 -> 2692.0604 | OY8: =+OY$6*$C8 -> 2692.0604 | OZ8: =+OZ$6*$C8 -> 2692.0604 | PA8: =+PA$6*$C8 -> 4433.9534 | PB8: =+PB$6*$C8 -> 0 | PC8: =+PC$6*$C8 -> 200.02808 | ... PF8: =+PF$6*$C8 -> 2692.0604 | PG8: 0 | PH8: =+PH$6*$C8 -> 4433.9534 | PI8: =+PI$6*$C8 -> 4433.9534 | PJ8: =+PJ$6*$C8 -> 200.02808 | PK8: =+PK$6*$C8 -> 0 | PL8: =+PL$6*$C8 -> 2692.0604 | PM8: =+PM$6*$C8 -> 2692.0604 | PN8: 0 | PO8: =+PO$6*$C8 -> 4433.9534 | PP8: =+PP$6*$C8 -> 0 | PQ8: =+PQ$6*$C8 -> 0 | PR8: =+PR$6*$C8 -> 0 | PS8: =+PS$6*$C8 -> 2692.0604 | PT8: =+PT$6*$C8 -> 2692.0604 | PU8: 0 | PV8: =+PV$6*$C8 -> 0 | PW8: =+PW$6*$C8 -> 0 | PX8: =+PX$6*$C8 -> 200.02808 | PY8: =+PY$6*$C8 -> 1850.282 | PZ8: =+PZ$6*$C8 -> 2692.0604 | QA8: =+SUM(OV8:PZ8) -> 48957.066 | QB8: =+QB$6*$C8 -> 2692.0604 | QC8: =+QC$6*$C8 -> 2692.0604 | QD8: =+QD$6*$C8 -> 4433.9534 | QE8: =+QE$6*$C8 -> 0 | QF8: =+QF$6*$C8 -> 200.02808 | QG8: =+QG$6*$C8 -> 1850.282 | QH8: =+QH$6*$C8 -> 2692.0604 | QI8: =+QI$6*$C8 -> 2692.0604 | ... QL8: =+QL$6*$C8 -> 4433.9534 | QM8: 0 | QN8: =+QN$6*$C8 -> 0 | QO8: =+QO$6*$C8 -> 2692.0604 | QP8: =+QP$6*$C8 -> 2692.0604 | QQ8: =+QQ$6*$C8 -> 2692.0604 | QR8: =+QR$6*$C8 -> 4433.9534 | QS8: =+QS$6*$C8 -> 0 | QT8: 0 | QU8: =+QU$6*$C8 -> 0 | QV8: =+QV$6*$C8 -> 2692.0604 | QW8: =+QW$6*$C8 -> 2692.0604 | QX8: =+QX$6*$C8 -> 56724.83 | QY8: =+QY$6*$C8 -> 0 | QZ8: =+QZ$6*$C8 -> 0 | RA8: 0 | RB8: =+RB$6*$C8 -> 1850.282 | RC8: =+RC$6*$C8 -> 2692.0604 | RD8: =+RD$6*$C8 -> 2692.0604 | RE8: =+RE$6*$C8 -> 2692.0604 | RF8: =+SUM(QB8:RE8) -> 113358.02 | RG8: =+RG$6*$C8 -> 0 | RH8: =+RH$6*$C8 -> 200.02808 | RI8: =+RI$6*$C8 -> 1850.282 | RJ8: =+RJ$6*$C8 -> 2692.0604 | RK8: =+RK$6*$C8 -> 2692.0604 | RL8: =+RL$6*$C8 -> 2692.0604 | RM8: =+RM$6*$C8 -> 4433.9534 | RN8: =+RN$6*$C8 -> 4433.9534 | ... RQ8: =+RQ$6*$C8 -> 2692.0604 | RR8: 0 | RS8: =+RS$6*$C8 -> 2692.0604 | RT8: =+RT$6*$C8 -> 4433.9534 | RU8: =+RU$6*$C8 -> 0 | RV8: =+RV$6*$C8 -> 0 | RW8: =+RW$6*$C8 -> 0 | RX8: =+RX$6*$C8 -> 2692.0604 | RY8: 0 | RZ8: =+RZ$6*$C8 -> 56724.83 | SA8: =+SA$6*$C8 -> 0 | SB8: =+SB$6*$C8 -> 0 | SC8: =+SC$6*$C8 -> 200.02808 | SD8: =+SD$6*$C8 -> 1850.282 | SE8: =+SE$6*$C8 -> 2692.0604 | SF8: 0 | SG8: =+SG$6*$C8 -> 2692.0604 | SH8: =+SH$6*$C8 -> 4433.9534 | SI8: =+SI$6*$C8 -> 4433.9534 | SJ8: =+SJ$6*$C8 -> 200.02808 | SK8: =+SK$6*$C8 -> 0 | SL8: =+SUM(RG8:SK8) -> 104931.76 | SM8: =+SM$6*$C8 -> 2692.0604 | SN8: =+SN$6*$C8 -> 2692.0604 | SO8: =+SO$6*$C8 -> 2692.0604 | SP8: =+SP$6*$C8 -> 4433.9534 | SQ8: =+SQ$6*$C8 -> 4433.9534 | SR8: =+SR$6*$C8 -> 200.02808 | SS8: =+SS$6*$C8 -> 0 | ST8: =+ST$6*$C8 -> 2692.0604 | ... SW8: =+SW$6*$C8 -> 4433.9534 | SX8: 0 | SY8: =+SY$6*$C8 -> 0 | SZ8: =+SZ$6*$C8 -> 0 | TA8: =+TA$6*$C8 -> 2692.0604 | TB8: =+TB$6*$C8 -> 2692.0604 | TC8: =+TC$6*$C8 -> 56724.83 | TD8: =+TD$6*$C8 -> 0 | TE8: 0 | TF8: =+TF$6*$C8 -> 200.02808 | TG8: =+TG$6*$C8 -> 1850.282 | TH8: =+TH$6*$C8 -> 2692.0604 | TI8: =+TI$6*$C8 -> 2692.0604 | TJ8: =+TJ$6*$C8 -> 2692.0604 | TK8: =+TK$6*$C8 -> 4433.9534 | TL8: 0 | TM8: =+TM$6*$C8 -> 200.02808 | TN8: =+TN$6*$C8 -> 0 | TO8: =+TO$6*$C8 -> 2692.0604 | TP8: =+TP$6*$C8 -> 2692.0604 | TQ8: =+SUM(SM8:TP8) -> 111907.79 | TR8: =+TR$6*$C8 -> 4433.9534 | TS8: =+TS$6*$C8 -> 4433.9534 | TT8: =+TT$6*$C8 -> 200.02808 | TU8: =+TU$6*$C8 -> 0 | TV8: =+TV$6*$C8 -> 2692.0604 | TW8: =+TW$6*$C8 -> 2692.0604 | TX8: =+TX$6*$C8 -> 2692.0604 | TY8: =+TY$6*$C8 -> 4433.9534 | ... UB8: =+UB$6*$C8 -> 0 | UC8: 0 | UD8: =+UD$6*$C8 -> 2692.0604 | UE8: =+UE$6*$C8 -> 56724.83 | UF8: =+UF$6*$C8 -> 0 | UG8: =+UG$6*$C8 -> 0 | UH8: =+UH$6*$C8 -> 200.02808 | UI8: =+UI$6*$C8 -> 1850.282 | UJ8: 0 | UK8: =+UK$6*$C8 -> 2692.0604 | UL8: =+UL$6*$C8 -> 2692.0604 | UM8: =+UM$6*$C8 -> 4433.9534 | UN8: =+UN$6*$C8 -> 4433.9534 | UO8: =+UO$6*$C8 -> 200.02808 | UP8: =+UP$6*$C8 -> 0 | UQ8: 0 | UR8: =+UR$6*$C8 -> 2692.0604 | US8: =+US$6*$C8 -> 2692.0604 | UT8: =+UT$6*$C8 -> 4433.9534 | UU8: =+UU$6*$C8 -> 0 | UV8: =+UV$6*$C8 -> 0 | UW8: =+SUM(TR8:UV8) -> 107315.4 | UX8: =+UX$6*$C8 -> 0 | UY8: =+UY$6*$C8 -> 2692.0604 | UZ8: =+UZ$6*$C8 -> 2692.0604 | VA8: =+VA$6*$C8 -> 2692.0604 | VB8: =+VB$6*$C8 -> 4433.9534 | VC8: =+VC$6*$C8 -> 0 | VD8: =+VD$6*$C8 -> 0 | VE8: =+VE$6*$C8 -> 0 | ... VH8: =+VH$6*$C8 -> 56724.83 | VI8: 0 | VJ8: =+VJ$6*$C8 -> 0 | VK8: =+VK$6*$C8 -> 200.02808 | VL8: =+VL$6*$C8 -> 1850.282 | VM8: =+VM$6*$C8 -> 2692.0604 | VN8: =+VN$6*$C8 -> 2692.0604 | VO8: =+VO$6*$C8 -> 2692.0604 | VP8: 0 | VQ8: =+VQ$6*$C8 -> 4433.9534 | VR8: =+VR$6*$C8 -> 200.02808 | VS8: =+VS$6*$C8 -> 0 | VT8: =+VT$6*$C8 -> 2692.0604 | VU8: =+VU$6*$C8 -> 2692.0604 | VV8: =+VV$6*$C8 -> 2692.0604 | VW8: 0 | VX8: =+VX$6*$C8 -> 0 | VY8: =+VY$6*$C8 -> 0 | VZ8: =+VZ$6*$C8 -> 0 | WA8: =+WA$6*$C8 -> 2692.0604 | WB8: =+WB$6*$C8 -> 2692.0604 | WC8: =+SUM(UX8:WB8) -> 102839.86
