Workbook
Name Loans: Dashboard!$L$18:$Q$18
Name test1: OFFSET(Calcs!$I$1,COUNTA(Calcs!XFA:XFA)-1,0,-18)
Name Tstuuuu: OFFSET(Calcs!$I$1,COUNTA(Calcs!$I:$I)-(12+1),0,12,1)
Name xVals: OFFSET(Calcs!$I$1,COUNTA(Calcs!$I:$I)-1,0,MIN(12,COUNTA(Calcs!$I:$I)-1),1)

Sheet Lists
B1: List of Areas | C1: Actual | D1: Jan | E1: Report | F1: Menu
B2: Group | C2: Budget | D2: Feb | E2: EBIT
B3: England | C3: Forecast 1 | D3: Mar | E3: Revenue | F3: EBIT
B4: Scotland | C4: Forecast 2 | D4: Apr | E4: Expenses | F4: Revenue
B5: Wales | C5: Forecast 3 | D5: May | F5: Expenses
B6: Northern Ireland | D6: Jun | F6: FTEs
D7: Jul | F7: Leave Balances
D8: Aug | F8: Other Measure
D9: Sep
D10: Oct
D11: Nov
D12: Dec

Sheet Projects
A1: Region | B1: Index | C1: Project | D1: Mthly Spend
A2: England | B2: 2 | C2: Project 1 | D2: 1362.45
A3: England | B3: 2 | C3: Project 3 | D3: 1116
A4: England | B4: 2 | C4: Project 4 | D4: 1038.5
A5: England | B5: 2 | C5: Project 5 | D5: 988
A6: England | B6: 2 | C6: Project 2 | D6: 809.1
A7: Scotland | B7: 3 | C7: Project 4 | D7: 247.8105
A8: Scotland | B8: 3 | C8: Project 2 | D8: 239.6835
A9: Scotland | B9: 3 | C9: Project 3 | D9: 213.7905
A10: Scotland | B10: 3 | C10: Project 5 | D10: 213
A11: Scotland | B11: 3 | C11: Project 1 | D11: 189.2205
A12: Wales | B12: 4 | C12: Project 2 | D12: 175.959
A13: Wales | B13: 4 | C13: Project 3 | D13: 151.6599
... A21: Northern Ireland | B21: 5 | C21: Project 4 | D21: 99.6975
A22: Group | B22: 1 | C22: Project 1 | D22: =SUMIF($C$2:$C$21,C22,$D$2:$D$21) -> 1851.897
A23: Group | B23: 1 | C23: Project 2 | D23: =SUMIF($C$2:$C$21,C23,$D$2:$D$21) -> 1338.7725
A24: Group | B24: 1 | C24: Project 3 | D24: =SUMIF($C$2:$C$21,C24,$D$2:$D$21) -> 1586.9754
A25: Group | B25: 1 | C25: Project 4 | D25: =SUMIF($C$2:$C$21,C25,$D$2:$D$21) -> 1526.3563
A26: Group | B26: 1 | C26: Project 5 | D26: =SUMIF($C$2:$C$21,C26,$D$2:$D$21) -> 1456

Sheet HR
A1: Region | B1: Index | C1: City | D1: FTEs | E1: Overtime Hrs | F1: Avg Svs Length | G1: Avg Salary
A2: England | B2: 2 | C2: London | D2: 108 | E2: 976 | F2: 3.5 | G2: 100000 | H2: =G2*D2 -> 10800000
A3: England | B3: 2 | C3: Manchester | D3: 55 | E3: 433
A4: England | B4: 2 | C4: Liverpool | D4: 33 | E4: 200
A5: England | B5: 2 | C5: Bristol | D5: 43 | E5: 187
A6: Scotland | B6: 3 | C6: Edinburgh | D6: 33 | E6: 198
A7: Scotland | B7: 3 | C7: Glasgow | D7: 23 | E7: 133
A8: Scotland | B8: 3 | C8: Aberdeen | D8: 13 | E8: 87
A9: Scotland | B9: 3 | C9: Dundee | D9: 12 | E9: 90
A10: Wales | B10: 4 | C10: Cardiff | D10: 58 | E10: 236
A11: Wales | B11: 4 | C11: Swansea | D11: 35 | E11: 177
A12: Wales | B12: 4 | C12: Newport | D12: 16 | E12: 88
A13: Wales | B13: 4 | C13: Llanelli | D13: 9 | E13: 34
A14: Northern Ireland | B14: 5 | C14: Belfast | D14: 44 | E14: 184
... A17: Northern Ireland | B17: 5 | C17: Bangor | D17: 7 | E17: 54
A18: Group | B18: 1 | C18: =INDEX($C$2:$C$17,MATCH(D18,$D$2:$D$17,0),1) -> London | D18: =LARGE($D$2:$D$17,ROW(A1)) -> 108 | E18: =VLOOKUP(C18,$C$2:$E$17,3,0) -> 976
A19: Group | B19: 1 | C19: =INDEX($C$2:$C$17,MATCH(D19,$D$2:$D$17,0),1) -> Cardiff | D19: =LARGE($D$2:$D$17,ROW(A2)) -> 58 | E19: =VLOOKUP(C19,$C$2:$E$17,3,0) -> 236
A20: Group | B20: 1 | C20: =INDEX($C$2:$C$17,MATCH(D20,$D$2:$D$17,0),1) -> Manchester | D20: =LARGE($D$2:$D$17,ROW(A3)) -> 55 | E20: =VLOOKUP(C20,$C$2:$E$17,3,0) -> 433
A21: Group | B21: 1 | C21: =INDEX($C$2:$C$17,MATCH(D21,$D$2:$D$17,0),1) -> Belfast | D21: =LARGE($D$2:$D$17,ROW(A4)) -> 44 | E21: =VLOOKUP(C21,$C$2:$E$17,3,0) -> 184
A24: Region | B24: Staff | C24: Leave Bal
A25: England | B25: Employee 1 | C25: 520
A26: England | B26: Employee 2 | C26: 461.5
A27: England | B27: Employee 3 | C27: 422.5
A28: England | B28: Employee 4 | C28: 405.6
A29: England | B29: Employee 5 | C29: 390
A30: Scotland | B30: Employee 1 | C30: 499
A31: Scotland | B31: Employee 2 | C31: 490
A32: Scotland | B32: Employee 3 | C32: 478
A33: Scotland | B33: Employee 4 | C33: 457
A34: Scotland | B34: Employee 5 | C34: 387
A35: Wales | B35: Employee 1 | C35: 412
A36: Wales | B36: Employee 2 | C36: 405
... A44: Northern Ireland | B44: Employee 5 | C44: 421
A45: Group | B45: Employee 1 | C45: =LARGE($C$25:$C$44,1) -> 520
A46: Group | B46: Employee 2 | C46: =LARGE($C$25:$C$44,2) -> 499
A47: Group | B47: Employee 3 | C47: =LARGE($C$25:$C$44,3) -> 490
A48: Group | B48: Employee 4 | C48: =LARGE($C$25:$C$44,4) -> 478
A49: Group | B49: Employee 5 | C49: =LARGE($C$25:$C$44,5) -> 477
A52: Region | B52: Group | C52: CY F % | D52: Issues PY | E52: Issues CY
A53: England | B53: IT | C53: 0.35 | D53: 22 | E53: 20
...

Sheet Exp
A1: State | B1: Category | C1: Exp | D1: 2015 | E1: 2016
A2: England | B2: Operations | C2: Exp | D2: 1264337.6 | E2: 1408528
A3: England | B3: Strategy | C3: Exp | D3: 1784947.2 | E3: 1549380.8
A4: England | B4: Finance | C4: Exp | D4: 1859320 | E4: 1478954.4
A5: England | B5: Commercial | C5: Exp | D5: 1859320 | E5: 1056396
A6: England | B6: HR | C6: Exp | D6: 669355.2 | E6: 1549380.8
A7: Scotland | B7: Operations | C7: Exp | D7: 922134.4 | E7: 1481154.4
A8: Scotland | B8: Strategy | C8: Exp | D8: 1193350.4 | E8: 1211853.6
A9: Scotland | B9: Finance | C9: Exp | D9: 1084864 | E9: 1077203.2
A10: Scotland | B10: Commercial | C10: Exp | D10: 922134.4 | E10: 1481154.4
A11: Scotland | B11: HR | C11: Exp | D11: 1301836.8 | E11: 1481154.4
A12: Wales | B12: Operations | C12: Exp | D12: 776291.4 | E12: 1038099.5
... A21: Northern Ireland | B21: HR | C21: Exp | D21: 2051468 | E21: 1496411.3
A22: Group | B22: Operations | C22: Exp | D22: =SUMIFS(D$2:D$21,$B$2:$B$21,$B22) -> 4177918.6 | E22: =SUMIFS(E$2:E$21,$B$2:$B$21,$B22) -> 5736630.7
A23: Group | B23: Strategy | C23: Exp | D23: =SUMIFS(D$2:D$21,$B$2:$B$21,$B23) -> 5555463.8 | E23: =SUMIFS(E$2:E$21,$B$2:$B$21,$B23) -> 5090555.7
A24: Group | B24: Finance | C24: Exp | D24: =SUMIFS(D$2:D$21,$B$2:$B$21,$B24) -> 5072623.2 | E24: =SUMIFS(E$2:E$21,$B$2:$B$21,$B24) -> 5119987.8
A25: Group | B25: Commercial | C25: Exp | D25: =SUMIFS(D$2:D$21,$B$2:$B$21,$B25) -> 4651385.5 | E25: =SUMIFS(E$2:E$21,$B$2:$B$21,$B25) -> 5203613.8
A26: Group | B26: HR | C26: Exp | D26: =SUMIFS(D$2:D$21,$B$2:$B$21,$B26) -> 5118600.8 | E26: =SUMIFS(E$2:E$21,$B$2:$B$21,$B26) -> 5565046

Sheet Data
A1: Region | B1: Code | C1: Month | D1: P&L Actual | E1: P&L Budget | F1: Rev Actual | G1: Rev Budget | H1: Exp Actual | I1: Exp Budget
A2: England | B2: 2 | C2: 40909 | D2: 8679 | E2: 7164.4429 | F2: 12229.5 | G2: 11006.55 | H2: 3550.5 | I2: 3842.1071
A3: England | B3: 2 | C3: 40940 | D3: 9240 | E3: 7427.8302 | F3: 13020 | G3: 11718 | H3: 3780 | I3: 4290.1698
A4: England | B4: 2 | C4: 40969 | D4: 7964 | E4: 7381.6185 | F4: 11222 | G4: 10099.8 | H4: 3258 | I4: 2718.1815
A5: England | B5: 2 | C5: 41000 | D5: 7370 | E5: 6610.8486 | F5: 10385 | G5: 9346.5 | H5: 3015 | I5: 2735.6514
A6: England | B6: 2 | C6: 41030 | D6: 6963 | E6: 5804.6647 | F6: 9811.5 | G6: 8830.35 | H6: 2848.5 | I6: 3025.6853
A7: England | B7: 2 | C7: 41061 | D7: 9988 | E7: 9164.4928 | F7: 14074 | G7: 12666.6 | H7: 4086 | I7: 3502.1072
A8: England | B8: 2 | C8: 41091 | D8: 7865 | E8: 6910.1509 | F8: 11082.5 | G8: 9974.25 | H8: 3217.5 | I8: 3064.0991
A9: England | B9: 2 | C9: 41122 | D9: 9724 | E9: 8746.7749 | F9: 13702 | G9: 12331.8 | H9: 3978 | I9: 3585.0251
A10: England | B10: 2 | C10: 41153 | D10: 9757 | E10: 7873.65 | F10: 13748.5 | G10: 12373.65 | H10: 3991.5 | I10: 4500
A11: England | B11: 2 | C11: 41183 | D11: 6336 | E11: 5616.2378 | F11: 8928 | G11: 8035.2 | H11: 2592 | I11: 2418.9622
A12: England | B12: 2 | C12: 41214 | D12: 8107 | E12: 6120.8639 | F12: 11423.5 | G12: 10281.15 | H12: 3316.5 | I12: 4160.2861
A13: England | B13: 2 | C13: 41244 | D13: 9669 | E13: 8263.8184 | F13: 13624.5 | G13: 12262.05 | H13: 3955.5 | I13: 3998.2316
... A77: Northern Ireland | B77: 5 | C77: 41000 | D77: 921.25 | E77: 826.35607 | F77: 1298.125 | G77: 1168.3125 | H77: 376.875 | I77: 341.95643
A78: Northern Ireland | B78: 5 | C78: 41030 | D78: 1643.9375 | E78: 1821.7893 | F78: 2000 | G78: 2200 | H78: 356.0625 | I78: 378.21067 | M78: =L78*2 -> 0
A79: Northern Ireland | B79: 5 | C79: 41061 | D79: 812.25 | E79: 1106.2366 | F79: 1323 | G79: 1544 | H79: 510.75 | I79: 437.76341 | M79: =L79*2 -> 0
A80: Northern Ireland | B80: 5 | C80: 41091 | D80: 2597.8125 | E80: 2416.9876 | F80: 3000 | G80: 2800 | H80: 402.1875 | I80: 383.01239 | M80: =L80*2 -> 0
A81: Northern Ireland | B81: 5 | C81: 41122 | D81: 2262.75 | E81: 1891.8719 | F81: 2760 | G81: 2340 | H81: 497.25 | I81: 448.12814 | M81: =L81*2 -> 0
A82: Northern Ireland | B82: 5 | C82: 41153 | D82: 1518.825 | E82: 1253.7775 | F82: 2140.1625 | G82: 1926.1462 | H82: 621.3375 | I82: 672.36874
A83: Northern Ireland | B83: 5 | C83: 41183 | D83: 1617 | E83: 1299.8703 | F83: 2278.5 | G83: 2050.65 | H83: 661.5 | I83: 750.77972
A84: Northern Ireland | B84: 5 | C84: 41214 | D84: 1393.7 | E84: 1291.7832 | F84: 1963.85 | G84: 1767.465 | H84: 570.15 | I84: 475.68177
A85: Northern Ireland | B85: 5 | C85: 41244 | D85: 1289.75 | E85: 1156.8985 | F85: 1817.375 | G85: 1635.6375 | H85: 527.625 | I85: 478.739
A86: Northern Ireland | B86: 5 | C86: 41275 | D86: 1290.5125 | E86: 1337.5051 | F86: 1789 | G86: 1867 | H86: 498.4875 | I86: 529.49493
A87: Northern Ireland | B87: 5 | C87: 41306 | D87: 718.1275 | E87: 5121.7723 | F87: 1588 | G87: 6063.0885 | H87: 869.8725 | I87: 941.31624
A88: Northern Ireland | B88: 5 | C88: 41334 | D88: 1317.9 | E88: 1814.9084 | F88: 2244 | G88: 2866 | H88: 926.1 | I88: 1051.0916
A89: Northern Ireland | B89: 5 | C89: 41365 | D89: 1335.79 | E89: 1467.0455 | F89: 2134 | G89: 2133 | H89: 798.21 | I89: 665.95447
A90: Northern Ireland | B90: 5 | C90: 41395 | D90: 1138.325 | E90: 1528.7654 | F90: 1877 | G90: 2199 | H90: 738.675 | I90: 670.23459
A91: Northern Ireland | B91: 5 | C91: 41426 | D91: 1318.345 | E91: 975.31185 | F91: 2016.2275 | G91: 1716.6047 | H91: 697.8825 | I91: 741.2929
A92: Northern Ireland | B92: 5 | C92: 41456 | D92: 1969.506 | E92: 1578.3796 | F92: 2775.213 | G92: 2497.6917 | H92: 805.707 | I92: 919.31209
A93: Northern Ireland | B93: 5 | C93: 41487 | D93: 1084.875 | E93: 895.55536 | F93: 1528.6875 | G93: 1375.8187 | H93: 443.8125 | I93: 480.26339
... A97: Northern Ireland | B97: 5 | C97: 41609 | D97: 1643.9375 | E97: 1821.7893 | F97: 2000 | G97: 2200 | H97: 356.0625 | I97: 378.21067
A98: Group | B98: 1 | C98: 40909 | D98: =SUMIF($C$2:$C$97,$C98,D$2:D$97) -> 16273.125 | E98: =SUMIF($C$2:$C$97,$C98,E$2:E$97) -> 13433.33 | F98: =SUMIF($C$2:$C$97,$C98,F$2:F$97) -> 22930.312 | G98: =SUMIF($C$2:$C$97,$C98,G$2:G$97) -> 20637.281 | H98: =SUMIF($C$2:$C$97,$C98,H$2:H$97) -> 6657.1875 | I98: =SUMIF($C$2:$C$97,$C98,I$2:I$97) -> 7203.9508
A99: Group | B99: 1 | C99: 40940 | D99: =SUMIF($C$2:$C$97,$C99,D$2:D$97) -> 17325 | E99: =SUMIF($C$2:$C$97,$C99,E$2:E$97) -> 13927.182 | F99: =SUMIF($C$2:$C$97,$C99,F$2:F$97) -> 24412.5 | G99: =SUMIF($C$2:$C$97,$C99,G$2:G$97) -> 21971.25 | H99: =SUMIF($C$2:$C$97,$C99,H$2:H$97) -> 7087.5 | I99: =SUMIF($C$2:$C$97,$C99,I$2:I$97) -> 8044.0685
A100: Group | B100: 1 | C100: 40969 | D100: =SUMIF($C$2:$C$97,$C100,D$2:D$97) -> 14932.5 | E100: =SUMIF($C$2:$C$97,$C100,E$2:E$97) -> 13840.535 | F100: =SUMIF($C$2:$C$97,$C100,F$2:F$97) -> 21041.25 | G100: =SUMIF($C$2:$C$97,$C100,G$2:G$97) -> 18937.125 | H100: =SUMIF($C$2:$C$97,$C100,H$2:H$97) -> 6108.75 | I100: =SUMIF($C$2:$C$97,$C100,I$2:I$97) -> 5096.5904
A101: Group | B101: 1 | C101: 41000 | D101: =SUMIF($C$2:$C$97,$C101,D$2:D$97) -> 13818.75 | E101: =SUMIF($C$2:$C$97,$C101,E$2:E$97) -> 12395.341 | F101: =SUMIF($C$2:$C$97,$C101,F$2:F$97) -> 19471.875 | G101: =SUMIF($C$2:$C$97,$C101,G$2:G$97) -> 17524.688 | H101: =SUMIF($C$2:$C$97,$C101,H$2:H$97) -> 5653.125 | I101: =SUMIF($C$2:$C$97,$C101,I$2:I$97) -> 5129.3464
A102: Group | B102: 1 | C102: 41030 | D102: =SUMIF($C$2:$C$97,$C102,D$2:D$97) -> 11642.688 | E102: =SUMIF($C$2:$C$97,$C102,E$2:E$97) -> 10060.465 | F102: =SUMIF($C$2:$C$97,$C102,F$2:F$97) -> 16983.625 | G102: =SUMIF($C$2:$C$97,$C102,G$2:G$97) -> 15733.625 | H102: =SUMIF($C$2:$C$97,$C102,H$2:H$97) -> 5340.9375 | I102: =SUMIF($C$2:$C$97,$C102,I$2:I$97) -> 5673.16
A103: Group | B103: 1 | C103: 41061 | D103: =SUMIF($C$2:$C$97,$C103,D$2:D$97) -> 13500.75 | E103: =SUMIF($C$2:$C$97,$C103,E$2:E$97) -> 12432.649 | F103: =SUMIF($C$2:$C$97,$C103,F$2:F$97) -> 21162 | G103: =SUMIF($C$2:$C$97,$C103,G$2:G$97) -> 18999.1 | H103: =SUMIF($C$2:$C$97,$C103,H$2:H$97) -> 7661.25 | I103: =SUMIF($C$2:$C$97,$C103,I$2:I$97) -> 6566.4511
A104: Group | B104: 1 | C104: 41091 | D104: =SUMIF($C$2:$C$97,$C104,D$2:D$97) -> 14660.688 | E104: =SUMIF($C$2:$C$97,$C104,E$2:E$97) -> 12878.964 | F104: =SUMIF($C$2:$C$97,$C104,F$2:F$97) -> 20693.5 | G104: =SUMIF($C$2:$C$97,$C104,G$2:G$97) -> 18624.15 | H104: =SUMIF($C$2:$C$97,$C104,H$2:H$97) -> 6032.8125 | I104: =SUMIF($C$2:$C$97,$C104,I$2:I$97) -> 5745.1859
A105: Group | B105: 1 | C105: 41122 | D105: =SUMIF($C$2:$C$97,$C105,D$2:D$97) -> 14955.75 | E105: =SUMIF($C$2:$C$97,$C105,E$2:E$97) -> 12963.128 | F105: =SUMIF($C$2:$C$97,$C105,F$2:F$97) -> 22414.5 | G105: =SUMIF($C$2:$C$97,$C105,G$2:G$97) -> 19685.05 | H105: =SUMIF($C$2:$C$97,$C105,H$2:H$97) -> 7458.75 | I105: =SUMIF($C$2:$C$97,$C105,I$2:I$97) -> 6721.9221
A106: Group | B106: 1 | C106: 41153 | D106: =SUMIF($C$2:$C$97,$C106,D$2:D$97) -> 18332.875 | E106: =SUMIF($C$2:$C$97,$C106,E$2:E$97) -> 14856.165 | F106: =SUMIF($C$2:$C$97,$C106,F$2:F$97) -> 25832.688 | G106: =SUMIF($C$2:$C$97,$C106,G$2:G$97) -> 23249.419 | H106: =SUMIF($C$2:$C$97,$C106,H$2:H$97) -> 7499.8125 | I106: =SUMIF($C$2:$C$97,$C106,I$2:I$97) -> 8393.2534
...

Sheet Sales
A1: Region | B1: Date | C1: CY | D1: PY
A2: England | B2: 36892 | C2: 46 | D2: 28
A3: England | B3: 36893 | C3: 55 | D3: 21
A4: England | B4: 36894 | C4: 50 | D4: 28
A5: England | B5: 36895 | C5: 50 | D5: 31
A6: England | B6: 36896 | C6: 52 | D6: 26
A7: England | B7: 36897 | C7: 41 | D7: 27
A8: England | B8: 36898 | C8: 47 | D8: 34
A9: England | B9: 36899 | C9: 51 | D9: 34
A10: England | B10: 36900 | C10: 50 | D10: 28
A11: England | B11: 36901 | C11: 48 | D11: 20
A12: England | B12: 36902 | C12: 60 | D12: 35
A13: England | B13: 36903 | C13: 51 | D13: 34
... A1361: Northern Ireland | B1361: 37231 | C1361: 39 | D1361: 10
A1362: Group | B1362: 36892 | C1362: =SUMIFS(C$342:C$1361,$B$342:$B$1361,$B1362) -> 128 | D1362: =SUMIFS(D$342:D$1361,$B$342:$B$1361,$B1362) -> 75
A1363: Group | B1363: 36893 | C1363: =SUMIFS(C$342:C$1361,$B$342:$B$1361,$B1363) -> 126 | D1363: =SUMIFS(D$342:D$1361,$B$342:$B$1361,$B1363) -> 78
A1364: Group | B1364: 36894 | C1364: =SUMIFS(C$342:C$1361,$B$342:$B$1361,$B1364) -> 142 | D1364: =SUMIFS(D$342:D$1361,$B$342:$B$1361,$B1364) -> 83
A1365: Group | B1365: 36895 | C1365: =SUMIFS(C$342:C$1361,$B$342:$B$1361,$B1365) -> 125 | D1365: =SUMIFS(D$342:D$1361,$B$342:$B$1361,$B1365) -> 63
A1366: Group | B1366: 36896 | C1366: =SUMIFS(C$342:C$1361,$B$342:$B$1361,$B1366) -> 142 | D1366: =SUMIFS(D$342:D$1361,$B$342:$B$1361,$B1366) -> 71
A1367: Group | B1367: 36897 | C1367: =SUMIFS(C$342:C$1361,$B$342:$B$1361,$B1367) -> 123 | D1367: =SUMIFS(D$342:D$1361,$B$342:$B$1361,$B1367) -> 72
A1368: Group | B1368: 36898 | C1368: =SUMIFS(C$342:C$1361,$B$342:$B$1361,$B1368) -> 129 | D1368: =SUMIFS(D$342:D$1361,$B$342:$B$1361,$B1368) -> 67
A1369: Group | B1369: 36899 | C1369: =SUMIFS(C$342:C$1361,$B$342:$B$1361,$B1369) -> 140 | D1369: =SUMIFS(D$342:D$1361,$B$342:$B$1361,$B1369) -> 79
A1370: Group | B1370: 36900 | C1370: =SUMIFS(C$342:C$1361,$B$342:$B$1361,$B1370) -> 137 | D1370: =SUMIFS(D$342:D$1361,$B$342:$B$1361,$B1370) -> 87
A1371: Group | B1371: 36901 | C1371: =SUMIFS(C$342:C$1361,$B$342:$B$1361,$B1371) -> 135 | D1371: =SUMIFS(D$342:D$1361,$B$342:$B$1361,$B1371) -> 78
A1372: Group | B1372: 36902 | C1372: =SUMIFS(C$342:C$1361,$B$342:$B$1361,$B1372) -> 144 | D1372: =SUMIFS(D$342:D$1361,$B$342:$B$1361,$B1372) -> 64
A1373: Group | B1373: 36903 | C1373: =SUMIFS(C$342:C$1361,$B$342:$B$1361,$B1373) -> 113 | D1373: =SUMIFS(D$342:D$1361,$B$342:$B$1361,$B1373) -> 64
... A1701: Group | B1701: 37231 | C1701: =SUMIFS(C$342:C$1361,$B$342:$B$1361,$B1701) -> 138 | D1701: =SUMIFS(D$342:D$1361,$B$342:$B$1361,$B1701) -> 64

Sheet Profit
A1: Region | B1: Product | C1: Sales Growth | D1: Profit % | E1: Volume
A2: England | B2: Household | C2: 0.06 | D2: 0.22 | E2: 30000
A3: England | B3: Furniture | C3: 0 | D3: 0.31 | E3: 25000
A4: England | B4: Hardware | C4: -0.03 | D4: 0.095 | E4: 10000
A5: England | B5: Clothing | C5: 0.15 | D5: 0.16 | E5: 15000
A6: England | B6: IT | C6: -0.06 | D6: 0.21 | E6: 8000
A7: Scotland | B7: Household | C7: 0.09 | D7: 0.08 | E7: 21000
A8: Scotland | B8: Furniture | C8: 0 | D8: 0.27 | E8: 25000
A9: Scotland | B9: Hardware | C9: -0.03 | D9: 0.15 | E9: 13000
A10: Scotland | B10: Clothing | C10: 0.15 | D10: 0.22 | E10: 16000
A11: Scotland | B11: IT | C11: -0.06 | D11: 0.21 | E11: 10000
A12: Wales | B12: Household | C12: 0.06 | D12: 0.14 | E12: 12000
A13: Wales | B13: Furniture | C13: 0 | D13: 0.21 | E13: 14000
... A21: Northern Ireland | B21: IT | C21: -0.06 | D21: 0.19 | E21: 10000
A22: Group | B22: Household | C22: 0.06 | D22: 0.22 | E22: =SUMIFS(E$2:E$21,$B$2:$B$21,B22) -> 88000
A23: Group | B23: Furniture | C23: 0 | D23: 0.31 | E23: =SUMIFS(E$2:E$21,$B$2:$B$21,B23) -> 83000
A24: Group | B24: Hardware | C24: -0.03 | D24: 0.095 | E24: =SUMIFS(E$2:E$21,$B$2:$B$21,B24) -> 48000
A25: Group | B25: Clothing | C25: 0.15 | D25: 0.16 | E25: =SUMIFS(E$2:E$21,$B$2:$B$21,B25) -> 65000
A26: Group | B26: IT | C26: -0.06 | D26: 0.21 | E26: =SUMIFS(E$2:E$21,$B$2:$B$21,B26) -> 34000
A28: Region | B28: Reserve | C28: Value
A29: England | B29: Cash | C29: 2307067
A30: Scotland | B30: Cash | C30: 5608786
A31: Wales | B31: Cash | C31: 3456765
A32: Northern Ireland | B32: Cash | C32: 2056784
A33: Group | B33: Cash | C33: =SUM(C29:C32) -> 13429402
C35: Prior
A36: Group | B36: Stock P | C36: 16.92 | D36: 17.43

Sheet Calcs
A1: =INDEX(Lists!$B$2:$B$6,Dashboard!B17,1) -> Group | B1: P&L Actual | C1: P&L Budget | D1: Rev Actual | E1: Rev Budget | F1: Exp Actual | G1: Exp Budget | H1: =INDEX(Lists!$E$2:$E$4,Dashboard!$D17,1) -> Expenses | I1: =OFFSET(A1,0,CHOOSE(Dashboard!$D$17,1,3,5),1,1) -> Exp Actual | J1: =OFFSET(B1,0,CHOOSE(Dashboard!$D$17,1,3,5),1,1) -> Exp Budget | N1: =Dashboard!S8 -> 12 | O1: Month | P1: =H1&" Actual" -> Expenses Actual | Q1: =H1&" Budget" -> Expenses Budget | R1: Chart label
A2: 40909 | B2: =SUMPRODUCT((Data!$C$2:$C$121=$A2)*(Data!$B$2:$B$121=Dashboard!$B$17)*(Data!D$2:D$121)) -> 16273.125 | C2: =SUMPRODUCT((Data!$C$2:$C$121=$A2)*(Data!$B$2:$B$121=Dashboard!$B$17)*(Data!E$2:E$121)) -> 13433.33 | D2: =SUMPRODUCT((Data!$C$2:$C$121=$A2)*(Data!$B$2:$B$121=Dashboard!$B$17)*(Data!F$2:F$121)) -> 22930.312 | E2: =SUMPRODUCT((Data!$C$2:$C$121=$A2)*(Data!$B$2:$B$121=Dashboard!$B$17)*(Data!G$2:G$121)) -> 20637.281 | F2: =SUMPRODUCT((Data!$C$2:$C$121=$A2)*(Data!$B$2:$B$121=Dashboard!$B$17)*(Data!H$2:H$121)) -> 6657.1875 | G2: =SUMPRODUCT((Data!$C$2:$C$121=$A2)*(Data!$B$2:$B$121=Dashboard!$B$17)*(Data!I$2:I$121)) -> 7203.9508 | I2: =OFFSET(A2,0,CHOOSE(Dashboard!$D$17,1,3,5),1,1) -> 6657.1875 | J2: =OFFSET(B2,0,CHOOSE(Dashboard!$D$17,1,3,5),1,1) -> 7203.9508 | O2: =IF(ISERROR(P2),NA(),A2) -> 40909 | P2: =OFFSET($I$1,IF(ROW()-1>$N$1,NA(),ROW()-1),0,1,1) -> 6657.1875 | Q2: =OFFSET($J$1,IF(ROW()-1>$N$1,NA(),ROW()-1),0,1,1) -> 7203.9508 | R2: =IF(ISERROR(P2),"",P2/1000) -> 6.6571875
A3: 40940 | B3: =SUMPRODUCT((Data!$C$2:$C$121=$A3)*(Data!$B$2:$B$121=Dashboard!$B$17)*(Data!D$2:D$121)) -> 17325 | C3: =SUMPRODUCT((Data!$C$2:$C$121=$A3)*(Data!$B$2:$B$121=Dashboard!$B$17)*(Data!E$2:E$121)) -> 13927.182 | D3: =SUMPRODUCT((Data!$C$2:$C$121=$A3)*(Data!$B$2:$B$121=Dashboard!$B$17)*(Data!F$2:F$121)) -> 24412.5 | E3: =SUMPRODUCT((Data!$C$2:$C$121=$A3)*(Data!$B$2:$B$121=Dashboard!$B$17)*(Data!G$2:G$121)) -> 21971.25 | F3: =SUMPRODUCT((Data!$C$2:$C$121=$A3)*(Data!$B$2:$B$121=Dashboard!$B$17)*(Data!H$2:H$121)) -> 7087.5 | G3: =SUMPRODUCT((Data!$C$2:$C$121=$A3)*(Data!$B$2:$B$121=Dashboard!$B$17)*(Data!I$2:I$121)) -> 8044.0685 | I3: =OFFSET(A3,0,CHOOSE(Dashboard!$D$17,1,3,5),1,1) -> 7087.5 | J3: =OFFSET(B3,0,CHOOSE(Dashboard!$D$17,1,3,5),1,1) -> 8044.0685 | O3: =IF(ISERROR(P3),NA(),A3) -> 40940 | P3: =OFFSET($I$1,IF(ROW()-1>$N$1,NA(),ROW()-1),0,1,1) -> 7087.5 | Q3: =OFFSET($J$1,IF(ROW()-1>$N$1,NA(),ROW()-1),0,1,1) -> 8044.0685 | R3: =IF(ISERROR(P3),"",P3/1000) -> 7.0875
A4: 40969 | B4: =SUMPRODUCT((Data!$C$2:$C$121=$A4)*(Data!$B$2:$B$121=Dashboard!$B$17)*(Data!D$2:D$121)) -> 14932.5 | C4: =SUMPRODUCT((Data!$C$2:$C$121=$A4)*(Data!$B$2:$B$121=Dashboard!$B$17)*(Data!E$2:E$121)) -> 13840.535 | D4: =SUMPRODUCT((Data!$C$2:$C$121=$A4)*(Data!$B$2:$B$121=Dashboard!$B$17)*(Data!F$2:F$121)) -> 21041.25 | E4: =SUMPRODUCT((Data!$C$2:$C$121=$A4)*(Data!$B$2:$B$121=Dashboard!$B$17)*(Data!G$2:G$121)) -> 18937.125 | F4: =SUMPRODUCT((Data!$C$2:$C$121=$A4)*(Data!$B$2:$B$121=Dashboard!$B$17)*(Data!H$2:H$121)) -> 6108.75 | G4: =SUMPRODUCT((Data!$C$2:$C$121=$A4)*(Data!$B$2:$B$121=Dashboard!$B$17)*(Data!I$2:I$121)) -> 5096.5904 | I4: =OFFSET(A4,0,CHOOSE(Dashboard!$D$17,1,3,5),1,1) -> 6108.75 | J4: =OFFSET(B4,0,CHOOSE(Dashboard!$D$17,1,3,5),1,1) -> 5096.5904 | O4: =IF(ISERROR(P4),NA(),A4) -> 40969 | P4: =OFFSET($I$1,IF(ROW()-1>$N$1,NA(),ROW()-1),0,1,1) -> 6108.75 | Q4: =OFFSET($J$1,IF(ROW()-1>$N$1,NA(),ROW()-1),0,1,1) -> 5096.5904 | R4: =IF(ISERROR(P4),"",P4/1000) -> 6.10875
A5: 41000 | B5: =SUMPRODUCT((Data!$C$2:$C$121=$A5)*(Data!$B$2:$B$121=Dashboard!$B$17)*(Data!D$2:D$121)) -> 13818.75 | C5: =SUMPRODUCT((Data!$C$2:$C$121=$A5)*(Data!$B$2:$B$121=Dashboard!$B$17)*(Data!E$2:E$121)) -> 12395.341 | D5: =SUMPRODUCT((Data!$C$2:$C$121=$A5)*(Data!$B$2:$B$121=Dashboard!$B$17)*(Data!F$2:F$121)) -> 19471.875 | E5: =SUMPRODUCT((Data!$C$2:$C$121=$A5)*(Data!$B$2:$B$121=Dashboard!$B$17)*(Data!G$2:G$121)) -> 17524.688 | F5: =SUMPRODUCT((Data!$C$2:$C$121=$A5)*(Data!$B$2:$B$121=Dashboard!$B$17)*(Data!H$2:H$121)) -> 5653.125 | G5: =SUMPRODUCT((Data!$C$2:$C$121=$A5)*(Data!$B$2:$B$121=Dashboard!$B$17)*(Data!I$2:I$121)) -> 5129.3464 | I5: =OFFSET(A5,0,CHOOSE(Dashboard!$D$17,1,3,5),1,1) -> 5653.125 | J5: =OFFSET(B5,0,CHOOSE(Dashboard!$D$17,1,3,5),1,1) -> 5129.3464 | O5: =IF(ISERROR(P5),NA(),A5) -> 41000 | P5: =OFFSET($I$1,IF(ROW()-1>$N$1,NA(),ROW()-1),0,1,1) -> 5653.125 | Q5: =OFFSET($J$1,IF(ROW()-1>$N$1,NA(),ROW()-1),0,1,1) -> 5129.3464 | R5: =IF(ISERROR(P5),"",P5/1000) -> 5.653125
A6: 41030 | B6: =SUMPRODUCT((Data!$C$2:$C$121=$A6)*(Data!$B$2:$B$121=Dashboard!$B$17)*(Data!D$2:D$121)) -> 11642.688 | C6: =SUMPRODUCT((Data!$C$2:$C$121=$A6)*(Data!$B$2:$B$121=Dashboard!$B$17)*(Data!E$2:E$121)) -> 10060.465 | D6: =SUMPRODUCT((Data!$C$2:$C$121=$A6)*(Data!$B$2:$B$121=Dashboard!$B$17)*(Data!F$2:F$121)) -> 16983.625 | E6: =SUMPRODUCT((Data!$C$2:$C$121=$A6)*(Data!$B$2:$B$121=Dashboard!$B$17)*(Data!G$2:G$121)) -> 15733.625 | F6: =SUMPRODUCT((Data!$C$2:$C$121=$A6)*(Data!$B$2:$B$121=Dashboard!$B$17)*(Data!H$2:H$121)) -> 5340.9375 | G6: =SUMPRODUCT((Data!$C$2:$C$121=$A6)*(Data!$B$2:$B$121=Dashboard!$B$17)*(Data!I$2:I$121)) -> 5673.16 | I6: =OFFSET(A6,0,CHOOSE(Dashboard!$D$17,1,3,5),1,1) -> 5340.9375 | J6: =OFFSET(B6,0,CHOOSE(Dashboard!$D$17,1,3,5),1,1) -> 5673.16 | O6: =IF(ISERROR(P6),NA(),A6) -> 41030 | P6: =OFFSET($I$1,IF(ROW()-1>$N$1,NA(),ROW()-1),0,1,1) -> 5340.9375 | Q6: =OFFSET($J$1,IF(ROW()-1>$N$1,NA(),ROW()-1),0,1,1) -> 5673.16 | R6: =IF(ISERROR(P6),"",P6/1000) -> 5.3409375
A7: 41061 | B7: =SUMPRODUCT((Data!$C$2:$C$121=$A7)*(Data!$B$2:$B$121=Dashboard!$B$17)*(Data!D$2:D$121)) -> 13500.75 | C7: =SUMPRODUCT((Data!$C$2:$C$121=$A7)*(Data!$B$2:$B$121=Dashboard!$B$17)*(Data!E$2:E$121)) -> 12432.649 | D7: =SUMPRODUCT((Data!$C$2:$C$121=$A7)*(Data!$B$2:$B$121=Dashboard!$B$17)*(Data!F$2:F$121)) -> 21162 | E7: =SUMPRODUCT((Data!$C$2:$C$121=$A7)*(Data!$B$2:$B$121=Dashboard!$B$17)*(Data!G$2:G$121)) -> 18999.1 | F7: =SUMPRODUCT((Data!$C$2:$C$121=$A7)*(Data!$B$2:$B$121=Dashboard!$B$17)*(Data!H$2:H$121)) -> 7661.25 | G7: =SUMPRODUCT((Data!$C$2:$C$121=$A7)*(Data!$B$2:$B$121=Dashboard!$B$17)*(Data!I$2:I$121)) -> 6566.4511 | I7: =OFFSET(A7,0,CHOOSE(Dashboard!$D$17,1,3,5),1,1) -> 7661.25 | J7: =OFFSET(B7,0,CHOOSE(Dashboard!$D$17,1,3,5),1,1) -> 6566.4511 | O7: =IF(ISERROR(P7),NA(),A7) -> 41061 | P7: =OFFSET($I$1,IF(ROW()-1>$N$1,NA(),ROW()-1),0,1,1) -> 7661.25 | Q7: =OFFSET($J$1,IF(ROW()-1>$N$1,NA(),ROW()-1),0,1,1) -> 6566.4511 | R7: =IF(ISERROR(P7),"",P7/1000) -> 7.66125
A8: 41091 | B8: =SUMPRODUCT((Data!$C$2:$C$121=$A8)*(Data!$B$2:$B$121=Dashboard!$B$17)*(Data!D$2:D$121)) -> 14660.688 | C8: =SUMPRODUCT((Data!$C$2:$C$121=$A8)*(Data!$B$2:$B$121=Dashboard!$B$17)*(Data!E$2:E$121)) -> 12878.964 | D8: =SUMPRODUCT((Data!$C$2:$C$121=$A8)*(Data!$B$2:$B$121=Dashboard!$B$17)*(Data!F$2:F$121)) -> 20693.5 | E8: =SUMPRODUCT((Data!$C$2:$C$121=$A8)*(Data!$B$2:$B$121=Dashboard!$B$17)*(Data!G$2:G$121)) -> 18624.15 | F8: =SUMPRODUCT((Data!$C$2:$C$121=$A8)*(Data!$B$2:$B$121=Dashboard!$B$17)*(Data!H$2:H$121)) -> 6032.8125 | G8: =SUMPRODUCT((Data!$C$2:$C$121=$A8)*(Data!$B$2:$B$121=Dashboard!$B$17)*(Data!I$2:I$121)) -> 5745.1859 | I8: =OFFSET(A8,0,CHOOSE(Dashboard!$D$17,1,3,5),1,1) -> 6032.8125 | J8: =OFFSET(B8,0,CHOOSE(Dashboard!$D$17,1,3,5),1,1) -> 5745.1859 | O8: =IF(ISERROR(P8),NA(),A8) -> 41091 | P8: =OFFSET($I$1,IF(ROW()-1>$N$1,NA(),ROW()-1),0,1,1) -> 6032.8125 | Q8: =OFFSET($J$1,IF(ROW()-1>$N$1,NA(),ROW()-1),0,1,1) -> 5745.1859 | R8: =IF(ISERROR(P8),"",P8/1000) -> 6.0328125
A9: 41122 | B9: =SUMPRODUCT((Data!$C$2:$C$121=$A9)*(Data!$B$2:$B$121=Dashboard!$B$17)*(Data!D$2:D$121)) -> 14955.75 | C9: =SUMPRODUCT((Data!$C$2:$C$121=$A9)*(Data!$B$2:$B$121=Dashboard!$B$17)*(Data!E$2:E$121)) -> 12963.128 | D9: =SUMPRODUCT((Data!$C$2:$C$121=$A9)*(Data!$B$2:$B$121=Dashboard!$B$17)*(Data!F$2:F$121)) -> 22414.5 | E9: =SUMPRODUCT((Data!$C$2:$C$121=$A9)*(Data!$B$2:$B$121=Dashboard!$B$17)*(Data!G$2:G$121)) -> 19685.05 | F9: =SUMPRODUCT((Data!$C$2:$C$121=$A9)*(Data!$B$2:$B$121=Dashboard!$B$17)*(Data!H$2:H$121)) -> 7458.75 | G9: =SUMPRODUCT((Data!$C$2:$C$121=$A9)*(Data!$B$2:$B$121=Dashboard!$B$17)*(Data!I$2:I$121)) -> 6721.9221 | I9: =OFFSET(A9,0,CHOOSE(Dashboard!$D$17,1,3,5),1,1) -> 7458.75 | J9: =OFFSET(B9,0,CHOOSE(Dashboard!$D$17,1,3,5),1,1) -> 6721.9221 | O9: =IF(ISERROR(P9),NA(),A9) -> 41122 | P9: =OFFSET($I$1,IF(ROW()-1>$N$1,NA(),ROW()-1),0,1,1) -> 7458.75 | Q9: =OFFSET($J$1,IF(ROW()-1>$N$1,NA(),ROW()-1),0,1,1) -> 6721.9221 | R9: =IF(ISERROR(P9),"",P9/1000) -> 7.45875
A10: 41153 | B10: =SUMPRODUCT((Data!$C$2:$C$121=$A10)*(Data!$B$2:$B$121=Dashboard!$B$17)*(Data!D$2:D$121)) -> 18332.875 | C10: =SUMPRODUCT((Data!$C$2:$C$121=$A10)*(Data!$B$2:$B$121=Dashboard!$B$17)*(Data!E$2:E$121)) -> 14856.165 | D10: =SUMPRODUCT((Data!$C$2:$C$121=$A10)*(Data!$B$2:$B$121=Dashboard!$B$17)*(Data!F$2:F$121)) -> 25832.688 | E10: =SUMPRODUCT((Data!$C$2:$C$121=$A10)*(Data!$B$2:$B$121=Dashboard!$B$17)*(Data!G$2:G$121)) -> 23249.419 | F10: =SUMPRODUCT((Data!$C$2:$C$121=$A10)*(Data!$B$2:$B$121=Dashboard!$B$17)*(Data!H$2:H$121)) -> 7499.8125 | G10: =SUMPRODUCT((Data!$C$2:$C$121=$A10)*(Data!$B$2:$B$121=Dashboard!$B$17)*(Data!I$2:I$121)) -> 8393.2534 | I10: =OFFSET(A10,0,CHOOSE(Dashboard!$D$17,1,3,5),1,1) -> 7499.8125 | J10: =OFFSET(B10,0,CHOOSE(Dashboard!$D$17,1,3,5),1,1) -> 8393.2534 | O10: =IF(ISERROR(P10),NA(),A10) -> 41153 | P10: =OFFSET($I$1,IF(ROW()-1>$N$1,NA(),ROW()-1),0,1,1) -> 7499.8125 | Q10: =OFFSET($J$1,IF(ROW()-1>$N$1,NA(),ROW()-1),0,1,1) -> 8393.2534 | R10: =IF(ISERROR(P10),"",P10/1000) -> 7.4998125
A11: 41183 | B11: =SUMPRODUCT((Data!$C$2:$C$121=$A11)*(Data!$B$2:$B$121=Dashboard!$B$17)*(Data!D$2:D$121)) -> 15812.39 | C11: =SUMPRODUCT((Data!$C$2:$C$121=$A11)*(Data!$B$2:$B$121=Dashboard!$B$17)*(Data!E$2:E$121)) -> 13400.964 | D11: =SUMPRODUCT((Data!$C$2:$C$121=$A11)*(Data!$B$2:$B$121=Dashboard!$B$17)*(Data!F$2:F$121)) -> 22281.095 | E11: =SUMPRODUCT((Data!$C$2:$C$121=$A11)*(Data!$B$2:$B$121=Dashboard!$B$17)*(Data!G$2:G$121)) -> 20052.986 | F11: =SUMPRODUCT((Data!$C$2:$C$121=$A11)*(Data!$B$2:$B$121=Dashboard!$B$17)*(Data!H$2:H$121)) -> 6468.705 | G11: =SUMPRODUCT((Data!$C$2:$C$121=$A11)*(Data!$B$2:$B$121=Dashboard!$B$17)*(Data!I$2:I$121)) -> 6652.0214 | I11: =OFFSET(A11,0,CHOOSE(Dashboard!$D$17,1,3,5),1,1) -> 6468.705 | J11: =OFFSET(B11,0,CHOOSE(Dashboard!$D$17,1,3,5),1,1) -> 6652.0214 | O11: =IF(ISERROR(P11),NA(),A11) -> 41183 | P11: =OFFSET($I$1,IF(ROW()-1>$N$1,NA(),ROW()-1),0,1,1) -> 6468.705 | Q11: =OFFSET($J$1,IF(ROW()-1>$N$1,NA(),ROW()-1),0,1,1) -> 6652.0214 | R11: =IF(ISERROR(P11),"",P11/1000) -> 6.468705
A12: 41214 | B12: =SUMPRODUCT((Data!$C$2:$C$121=$A12)*(Data!$B$2:$B$121=Dashboard!$B$17)*(Data!D$2:D$121)) -> 18147.03 | C12: =SUMPRODUCT((Data!$C$2:$C$121=$A12)*(Data!$B$2:$B$121=Dashboard!$B$17)*(Data!E$2:E$121)) -> 15112.727 | D12: =SUMPRODUCT((Data!$C$2:$C$121=$A12)*(Data!$B$2:$B$121=Dashboard!$B$17)*(Data!F$2:F$121)) -> 25570.815 | E12: =SUMPRODUCT((Data!$C$2:$C$121=$A12)*(Data!$B$2:$B$121=Dashboard!$B$17)*(Data!G$2:G$121)) -> 23013.733 | F12: =SUMPRODUCT((Data!$C$2:$C$121=$A12)*(Data!$B$2:$B$121=Dashboard!$B$17)*(Data!H$2:H$121)) -> 7423.785 | G12: =SUMPRODUCT((Data!$C$2:$C$121=$A12)*(Data!$B$2:$B$121=Dashboard!$B$17)*(Data!I$2:I$121)) -> 7901.0064 | I12: =OFFSET(A12,0,CHOOSE(Dashboard!$D$17,1,3,5),1,1) -> 7423.785 | J12: =OFFSET(B12,0,CHOOSE(Dashboard!$D$17,1,3,5),1,1) -> 7901.0064 | O12: =IF(ISERROR(P12),NA(),A12) -> 41214 | P12: =OFFSET($I$1,IF(ROW()-1>$N$1,NA(),ROW()-1),0,1,1) -> 7423.785 | Q12: =OFFSET($J$1,IF(ROW()-1>$N$1,NA(),ROW()-1),0,1,1) -> 7901.0064 | R12: =IF(ISERROR(P12),"",P12/1000) -> 7.423785
A13: 41244 | B13: =SUMPRODUCT((Data!$C$2:$C$121=$A13)*(Data!$B$2:$B$121=Dashboard!$B$17)*(Data!D$2:D$121)) -> 18764.24 | C13: =SUMPRODUCT((Data!$C$2:$C$121=$A13)*(Data!$B$2:$B$121=Dashboard!$B$17)*(Data!E$2:E$121)) -> 16118.274 | D13: =SUMPRODUCT((Data!$C$2:$C$121=$A13)*(Data!$B$2:$B$121=Dashboard!$B$17)*(Data!F$2:F$121)) -> 26440.52 | E13: =SUMPRODUCT((Data!$C$2:$C$121=$A13)*(Data!$B$2:$B$121=Dashboard!$B$17)*(Data!G$2:G$121)) -> 23796.468 | F13: =SUMPRODUCT((Data!$C$2:$C$121=$A13)*(Data!$B$2:$B$121=Dashboard!$B$17)*(Data!H$2:H$121)) -> 7676.28 | G13: =SUMPRODUCT((Data!$C$2:$C$121=$A13)*(Data!$B$2:$B$121=Dashboard!$B$17)*(Data!I$2:I$121)) -> 7678.1936 | I13: =OFFSET(A13,0,CHOOSE(Dashboard!$D$17,1,3,5),1,1) -> 7676.28 | J13: =OFFSET(B13,0,CHOOSE(Dashboard!$D$17,1,3,5),1,1) -> 7678.1936 | O13: =IF(ISERROR(P13),NA(),A13) -> 41244 | P13: =OFFSET($I$1,IF(ROW()-1>$N$1,NA(),ROW()-1),0,1,1) -> 7676.28 | Q13: =OFFSET($J$1,IF(ROW()-1>$N$1,NA(),ROW()-1),0,1,1) -> 7678.1936 | R13: =IF(ISERROR(P13),"",P13/1000) -> 7.67628
... A25: 41609 | B25: =SUMPRODUCT((Data!$C$2:$C$121=$A25)*(Data!$B$2:$B$121=Dashboard!$B$17)*(Data!D$2:D$121)) -> 13333.388 | C25: =SUMPRODUCT((Data!$C$2:$C$121=$A25)*(Data!$B$2:$B$121=Dashboard!$B$17)*(Data!E$2:E$121)) -> 11786.415 | D25: =SUMPRODUCT((Data!$C$2:$C$121=$A25)*(Data!$B$2:$B$121=Dashboard!$B$17)*(Data!F$2:F$121)) -> 19365.975 | E25: =SUMPRODUCT((Data!$C$2:$C$121=$A25)*(Data!$B$2:$B$121=Dashboard!$B$17)*(Data!G$2:G$121)) -> 17877.74 | F25: =SUMPRODUCT((Data!$C$2:$C$121=$A25)*(Data!$B$2:$B$121=Dashboard!$B$17)*(Data!H$2:H$121)) -> 6032.5875 | G25: =SUMPRODUCT((Data!$C$2:$C$121=$A25)*(Data!$B$2:$B$121=Dashboard!$B$17)*(Data!I$2:I$121)) -> 6091.3247 | I25: =OFFSET(A25,0,CHOOSE(Dashboard!$D$17,1,3,5),1,1) -> 6032.5875 | J25: =OFFSET(B25,0,CHOOSE(Dashboard!$D$17,1,3,5),1,1) -> 6091.3247 | O25: =IF(ISERROR(P25),NA(),A25) -> #N/A | P25: =OFFSET($I$1,IF(ROW()-1>$N$1,NA(),ROW()-1),0,1,1) -> #N/A | Q25: =OFFSET($J$1,IF(ROW()-1>$N$1,NA(),ROW()-1),0,1,1) -> #N/A | R25: =IF(ISERROR(P25),"",P25/1000)
L26: 12
A27: Region | B27: City | C27: FTEs | D27: OT Hrs
A28: =$A$1 -> Group | B28: =OFFSET(HR!$C$1,MATCH(A28,HR!$A$2:$A$21,0),0,1,1) -> London | C28: =SUMIF(HR!$C$2:$C$21,B28,HR!$D$2:$D$21) -> 216 | D28: =SUMIF(HR!$C$2:$C$21,B28,HR!$E$2:$E$21) -> 1952
A29: =$A$1 -> Group | B29: =OFFSET(HR!$C$1,MATCH(A29,HR!$A$2:$A$21,0)+1,0,1,1) -> Cardiff | C29: =SUMIF(HR!$C$2:$C$21,B29,HR!$D$2:$D$21) -> 116 | D29: =SUMIF(HR!$C$2:$C$21,B29,HR!$E$2:$E$21) -> 472
A30: =$A$1 -> Group | B30: =OFFSET(HR!$C$1,MATCH(A30,HR!$A$2:$A$21,0)+2,0,1,1) -> Manchester | C30: =SUMIF(HR!$C$2:$C$21,B30,HR!$D$2:$D$21) -> 110 | D30: =SUMIF(HR!$C$2:$C$21,B30,HR!$E$2:$E$21) -> 866
A31: =$A$1 -> Group | B31: =OFFSET(HR!$C$1,MATCH(A31,HR!$A$2:$A$21,0)+3,0,1,1) -> Belfast | C31: =SUMIF(HR!$C$2:$C$21,B31,HR!$D$2:$D$21) -> 88 | D31: =SUMIF(HR!$C$2:$C$21,B31,HR!$E$2:$E$21) -> 368
H32: 0.12
H33: 0.12
A34: Region | B34: Projects | C34: Spend | H34: 0.12
A35: =$A$1 -> Group | B35: =INDEX(Projects!$C$2:$C$26,MATCH(C35,Projects!$D$2:$D$26,0),1) -> Project 1 | C35: {=LARGE(IF(Projects!$A$2:$A$26=A35,Projects!$D$2:$D$26),ROW(A1))} -> 1851.897 | H35: 0.12
A36: =$A$1 -> Group | B36: =INDEX(Projects!$C$2:$C$26,MATCH(C36,Projects!$D$2:$D$26,0),1) -> Project 3 | C36: {=LARGE(IF(Projects!$A$2:$A$26=A36,Projects!$D$2:$D$26),ROW(A2))} -> 1586.9754 | H36: 0.12
A37: =$A$1 -> Group | B37: =INDEX(Projects!$C$2:$C$26,MATCH(C37,Projects!$D$2:$D$26,0),1) -> Project 4 | C37: {=LARGE(IF(Projects!$A$2:$A$26=A37,Projects!$D$2:$D$26),ROW(A3))} -> 1526.3563 | H37: 0.12
A38: =$A$1 -> Group | B38: =INDEX(Projects!$C$2:$C$26,MATCH(C38,Projects!$D$2:$D$26,0),1) -> Project 5 | C38: {=LARGE(IF(Projects!$A$2:$A$26=A38,Projects!$D$2:$D$26),ROW(A4))} -> 1456 | H38: -0.05
A39: =$A$1 -> Group | B39: =INDEX(Projects!$C$2:$C$26,MATCH(C39,Projects!$D$2:$D$26,0),1) -> Project 2 | C39: {=LARGE(IF(Projects!$A$2:$A$26=A39,Projects!$D$2:$D$26),ROW(A5))} -> 1338.7725 | H39: 0.12
H40: 0.12
H41: 0.12
H42: 0.12
A43: =$A$1 -> Group | B43: Employee 1 | C43: =SUMIFS(HR!$C$25:$C$49,HR!$A$25:$A$49,$A43,HR!$B$25:$B$49,$B43) -> 520
A44: =$A$1 -> Group | B44: Employee 2 | C44: =SUMIFS(HR!$C$25:$C$49,HR!$A$25:$A$49,$A44,HR!$B$25:$B$49,$B44) -> 499
A45: =$A$1 -> Group | B45: Employee 3 | C45: =SUMIFS(HR!$C$25:$C$49,HR!$A$25:$A$49,$A45,HR!$B$25:$B$49,$B45) -> 490
A46: =$A$1 -> Group | B46: Employee 4 | C46: =SUMIFS(HR!$C$25:$C$49,HR!$A$25:$A$49,$A46,HR!$B$25:$B$49,$B46) -> 478
A47: =$A$1 -> Group | B47: Employee 5 | C47: =SUMIFS(HR!$C$25:$C$49,HR!$A$25:$A$49,$A47,HR!$B$25:$B$49,$B47) -> 477
A50: Region | B50: Group | C50: CY F % | D50: Male % | E50: Issues PY | F50: Issues CY
A51: =$A$1 -> Group | B51: IT | C51: =SUMIFS(HR!$C$53:$C$67,HR!$A$53:$A$67,$A51,HR!$B$53:$B$67,$B51) -> 0.3 | D51: =1-C51 -> 0.7 | E51: =SUMIFS(HR!D$53:D$67,HR!$A$53:$A$67,$A51,HR!$B$53:$B$67,$B51) -> 78 | F51: =SUMIFS(HR!E$53:E$67,HR!$A$53:$A$67,$A51,HR!$B$53:$B$67,$B51) -> 77
A52: =$A$1 -> Group | B52: HR | C52: =SUMIFS(HR!$C$53:$C$67,HR!$A$53:$A$67,$A52,HR!$B$53:$B$67,$B52) -> 0.6825 | D52: =1-C52 -> 0.3175 | E52: =SUMIFS(HR!D$53:D$67,HR!$A$53:$A$67,$A52,HR!$B$53:$B$67,$B52) -> 59 | F52: =SUMIFS(HR!E$53:E$67,HR!$A$53:$A$67,$A52,HR!$B$53:$B$67,$B52) -> 43
A53: =$A$1 -> Group | B53: Ops | C53: =SUMIFS(HR!$C$53:$C$67,HR!$A$53:$A$67,$A53,HR!$B$53:$B$67,$B53) -> 0.4325 | D53: =1-C53 -> 0.5675 | E53: =SUMIFS(HR!D$53:D$67,HR!$A$53:$A$67,$A53,HR!$B$53:$B$67,$B53) -> 82 | F53: =SUMIFS(HR!E$53:E$67,HR!$A$53:$A$67,$A53,HR!$B$53:$B$67,$B53) -> 85
...

Sheet Charts
A1: Region | B1: Product | C1: Sales Growth | D1: Profit % | E1: Sales Volume | F1: Growth | G1: y | H1: x | I1: x
A2: =Calcs!$A$1 -> Group | B2: Household | C2: =SUMIFS(Profit!C$2:C$26,Profit!$A$2:$A$26,$A2,Profit!$B$2:$B$26,$B2) -> 0.06 | D2: =SUMIFS(Profit!D$2:D$26,Profit!$A$2:$A$26,$A2,Profit!$B$2:$B$26,$B2) -> 0.22 | E2: =SUMIFS(Profit!E$2:E$26,Profit!$A$2:$A$26,$A2,Profit!$B$2:$B$26,$B2) -> 88000 | F2: =C2 -> 0.06 | G2: =F2+E2/$E$7 -> 0.33672956 | H2: =D2 -> 0.22 | I2: =H2 -> 0.22
A3: =Calcs!$A$1 -> Group | B3: Furniture | C3: =SUMIFS(Profit!C$2:C$26,Profit!$A$2:$A$26,$A3,Profit!$B$2:$B$26,$B3) -> 0 | D3: =SUMIFS(Profit!D$2:D$26,Profit!$A$2:$A$26,$A3,Profit!$B$2:$B$26,$B3) -> 0.31 | E3: =SUMIFS(Profit!E$2:E$26,Profit!$A$2:$A$26,$A3,Profit!$B$2:$B$26,$B3) -> 83000 | F3: =C3 -> 0 | G3: =F3+E3/$E$7 -> 0.26100629 | H3: =D3 -> 0.31 | I3: =H3 -> 0.31
A4: =Calcs!$A$1 -> Group | B4: Hardware | C4: =SUMIFS(Profit!C$2:C$26,Profit!$A$2:$A$26,$A4,Profit!$B$2:$B$26,$B4) -> -0.03 | D4: =SUMIFS(Profit!D$2:D$26,Profit!$A$2:$A$26,$A4,Profit!$B$2:$B$26,$B4) -> 0.095 | E4: =SUMIFS(Profit!E$2:E$26,Profit!$A$2:$A$26,$A4,Profit!$B$2:$B$26,$B4) -> 48000 | F4: =C4 -> -0.03 | G4: =F4+E4/$E$7 -> 0.1209434 | H4: =D4 -> 0.095 | I4: =H4 -> 0.095
A5: =Calcs!$A$1 -> Group | B5: Clothing | C5: =SUMIFS(Profit!C$2:C$26,Profit!$A$2:$A$26,$A5,Profit!$B$2:$B$26,$B5) -> 0.15 | D5: =SUMIFS(Profit!D$2:D$26,Profit!$A$2:$A$26,$A5,Profit!$B$2:$B$26,$B5) -> 0.16 | E5: =SUMIFS(Profit!E$2:E$26,Profit!$A$2:$A$26,$A5,Profit!$B$2:$B$26,$B5) -> 65000 | F5: =C5 -> 0.15 | G5: =F5+E5/$E$7 -> 0.35440252 | H5: =D5 -> 0.16 | I5: =H5 -> 0.16
A6: =Calcs!$A$1 -> Group | B6: IT | C6: =SUMIFS(Profit!C$2:C$26,Profit!$A$2:$A$26,$A6,Profit!$B$2:$B$26,$B6) -> -0.06 | D6: =SUMIFS(Profit!D$2:D$26,Profit!$A$2:$A$26,$A6,Profit!$B$2:$B$26,$B6) -> 0.21 | E6: =SUMIFS(Profit!E$2:E$26,Profit!$A$2:$A$26,$A6,Profit!$B$2:$B$26,$B6) -> 34000 | F6: =C6 -> -0.06 | G6: =F6+E6/$E$7 -> 0.046918239 | H6: =D6 -> 0.21 | I6: =H6 -> 0.21
B7: TOTAL | E7: =SUM(E2:E6) -> 318000
A10: England
A11: Scotland
A12: Wales
A13: Northern Ireland
A18: Region | B18: Date | C18: CY | D18: PY
A19: =Calcs!$A$28 -> Group | B19: 36892 | C19: =SUMIFS(Sales!C$2:C$1701,Sales!$A$2:$A$1701,$A19,Sales!$B$2:$B$1701,$B19) -> 128 | D19: =SUMIFS(Sales!D$2:D$1701,Sales!$A$2:$A$1701,$A19,Sales!$B$2:$B$1701,$B19) -> 75
A20: =Calcs!$A$28 -> Group | B20: 36893 | C20: =SUMIFS(Sales!C$2:C$1701,Sales!$A$2:$A$1701,$A20,Sales!$B$2:$B$1701,$B20) -> 126 | D20: =SUMIFS(Sales!D$2:D$1701,Sales!$A$2:$A$1701,$A20,Sales!$B$2:$B$1701,$B20) -> 78
A21: =Calcs!$A$28 -> Group | B21: 36894 | C21: =SUMIFS(Sales!C$2:C$1701,Sales!$A$2:$A$1701,$A21,Sales!$B$2:$B$1701,$B21) -> 142 | D21: =SUMIFS(Sales!D$2:D$1701,Sales!$A$2:$A$1701,$A21,Sales!$B$2:$B$1701,$B21) -> 83
A22: =Calcs!$A$28 -> Group | B22: 36895 | C22: =SUMIFS(Sales!C$2:C$1701,Sales!$A$2:$A$1701,$A22,Sales!$B$2:$B$1701,$B22) -> 125 | D22: =SUMIFS(Sales!D$2:D$1701,Sales!$A$2:$A$1701,$A22,Sales!$B$2:$B$1701,$B22) -> 63
A23: =Calcs!$A$28 -> Group | B23: 36896 | C23: =SUMIFS(Sales!C$2:C$1701,Sales!$A$2:$A$1701,$A23,Sales!$B$2:$B$1701,$B23) -> 142 | D23: =SUMIFS(Sales!D$2:D$1701,Sales!$A$2:$A$1701,$A23,Sales!$B$2:$B$1701,$B23) -> 71
A24: =Calcs!$A$28 -> Group | B24: 36897 | C24: =SUMIFS(Sales!C$2:C$1701,Sales!$A$2:$A$1701,$A24,Sales!$B$2:$B$1701,$B24) -> 123 | D24: =SUMIFS(Sales!D$2:D$1701,Sales!$A$2:$A$1701,$A24,Sales!$B$2:$B$1701,$B24) -> 72
A25: =Calcs!$A$28 -> Group | B25: 36898 | C25: =SUMIFS(Sales!C$2:C$1701,Sales!$A$2:$A$1701,$A25,Sales!$B$2:$B$1701,$B25) -> 129 | D25: =SUMIFS(Sales!D$2:D$1701,Sales!$A$2:$A$1701,$A25,Sales!$B$2:$B$1701,$B25) -> 67
A26: =Calcs!$A$28 -> Group | B26: 36899 | C26: =SUMIFS(Sales!C$2:C$1701,Sales!$A$2:$A$1701,$A26,Sales!$B$2:$B$1701,$B26) -> 140 | D26: =SUMIFS(Sales!D$2:D$1701,Sales!$A$2:$A$1701,$A26,Sales!$B$2:$B$1701,$B26) -> 79
A27: =Calcs!$A$28 -> Group | B27: 36900 | C27: =SUMIFS(Sales!C$2:C$1701,Sales!$A$2:$A$1701,$A27,Sales!$B$2:$B$1701,$B27) -> 137 | D27: =SUMIFS(Sales!D$2:D$1701,Sales!$A$2:$A$1701,$A27,Sales!$B$2:$B$1701,$B27) -> 87
A28: =Calcs!$A$28 -> Group | B28: 36901 | C28: =SUMIFS(Sales!C$2:C$1701,Sales!$A$2:$A$1701,$A28,Sales!$B$2:$B$1701,$B28) -> 135 | D28: =SUMIFS(Sales!D$2:D$1701,Sales!$A$2:$A$1701,$A28,Sales!$B$2:$B$1701,$B28) -> 78
A29: =Calcs!$A$28 -> Group | B29: 36902 | C29: =SUMIFS(Sales!C$2:C$1701,Sales!$A$2:$A$1701,$A29,Sales!$B$2:$B$1701,$B29) -> 144 | D29: =SUMIFS(Sales!D$2:D$1701,Sales!$A$2:$A$1701,$A29,Sales!$B$2:$B$1701,$B29) -> 64
A30: =Calcs!$A$28 -> Group | B30: 36903 | C30: =SUMIFS(Sales!C$2:C$1701,Sales!$A$2:$A$1701,$A30,Sales!$B$2:$B$1701,$B30) -> 113 | D30: =SUMIFS(Sales!D$2:D$1701,Sales!$A$2:$A$1701,$A30,Sales!$B$2:$B$1701,$B30) -> 64
... A358: =Calcs!$A$28 -> Group | B358: 37231 | C358: =SUMIFS(Sales!C$2:C$1701,Sales!$A$2:$A$1701,$A358,Sales!$B$2:$B$1701,$B358) -> 138 | D358: =SUMIFS(Sales!D$2:D$1701,Sales!$A$2:$A$1701,$A358,Sales!$B$2:$B$1701,$B358) -> 64

Sheet Dashboard
S8: 12
B17: 1 | D17: 3
B23: Expenditure by Department | P23: `
B24: Dept | C24: PY | D24: CY | G24: Headcount | I24: =HR!D1 -> FTEs | L24: Overtime | N24: Hrs | Q24: Capital Spend | S24: Top 5 $m | V24: Leave Bal | W24: Top 5
B25: Operations | C25: =Calcs!C74/1000 -> 4177.9186 | D25: =Calcs!D74/1000 -> 5736.6307 | G25: =Calcs!B28 -> London | I25: =Calcs!C28 -> 216 | L25: =Calcs!B28 -> London | N25: =Calcs!D28 -> 1952 | Q25: =Calcs!B35 -> Project 1 | S25: =Calcs!C35 -> 1851.897 | V25: Emp1 | W25: =Calcs!C43 -> 520
B26: Strategy | C26: =Calcs!C75/1000 -> 5555.4638 | D26: =Calcs!D75/1000 -> 5090.5557 | G26: =Calcs!B29 -> Cardiff | I26: =Calcs!C29 -> 116 | L26: =Calcs!B29 -> Cardiff | N26: =Calcs!D29 -> 472 | Q26: =Calcs!B36 -> Project 3 | S26: =Calcs!C36 -> 1586.9754 | V26: Emp2 | W26: =Calcs!C44 -> 499
B27: Finance | C27: =Calcs!C76/1000 -> 5072.6232 | D27: =Calcs!D76/1000 -> 5119.9878 | G27: =Calcs!B30 -> Manchester | I27: =Calcs!C30 -> 110 | L27: =Calcs!B30 -> Manchester | N27: =Calcs!D30 -> 866 | Q27: =Calcs!B37 -> Project 4 | S27: =Calcs!C37 -> 1526.3563 | V27: Emp3 | W27: =Calcs!C45 -> 490
B28: Commercial | C28: =Calcs!C77/1000 -> 4651.3855 | D28: =Calcs!D77/1000 -> 5203.6138 | G28: =Calcs!B31 -> Belfast | I28: =Calcs!C31 -> 88 | L28: =Calcs!B31 -> Belfast | N28: =Calcs!D31 -> 368 | Q28: =Calcs!B38 -> Project 5 | S28: =Calcs!C38 -> 1456 | V28: Emp4 | W28: =Calcs!C46 -> 478
B29: HR | C29: =Calcs!C78/1000 -> 5118.6008 | D29: =Calcs!D78/1000 -> 5565.046 | G29: Total FTEs | I29: =SUM(I25:I28) -> 530 | L29: Data Supplied by; | Q29: =Calcs!B39 -> Project 2 | S29: =Calcs!C39 -> 1338.7725 | V29: Emp5 | W29: =Calcs!C47 -> 477
