Workbook
Name Despesas_com_Alimentacao: 'Bancos e Cartões'!#REF!
Name Despesas_com_Alimentacao: 'Resumo (3)'!#REF!
Name Despesas_com_Alimentacao: 'PC Despesas'!$G$5:$G$103
Name Despesas_com_Lazer_e_Informacao: 'Bancos e Cartões'!#REF!
Name Despesas_com_Lazer_e_Informacao: 'Resumo (3)'!#REF!
Name Despesas_com_Lazer_e_Informacao: 'PC Despesas'!$P$5:$P$103
Name Despesas_com_Saude: 'Bancos e Cartões'!#REF!
Name Despesas_com_Saude: 'Resumo (3)'!#REF!
Name Despesas_com_Saude: 'PC Despesas'!$J$5:$J$103
Name Despesas_com_Transportes: 'Bancos e Cartões'!#REF!
Name Despesas_com_Transportes: 'Resumo (3)'!#REF!
Name Despesas_com_Transportes: 'PC Despesas'!$M$5:$M$103
Name Despesas_de_Moradia: 'Bancos e Cartões'!#REF!
Name Despesas_de_Moradia: 'Resumo (3)'!#REF!
Name Despesas_de_Moradia: 'PC Despesas'!$D$5:$D$103
Name Imposto_de_Renda: 'Bancos e Cartões'!#REF!
Name Imposto_de_Renda: 'Resumo (3)'!#REF!
Name Imposto_de_Renda: 'PC Despesas'!$V$5:$V$103
Name Investimentos_Bens: 'Bancos e Cartões'!#REF!
Name Investimentos_Bens: 'Resumo (3)'!#REF!
Name Investimentos_Bens: 'PC Despesas'!$Y$5:$Y$103
Name Outras_Despesas: 'Bancos e Cartões'!#REF!
Name Outras_Despesas: 'Resumo (3)'!#REF!
Name Outras_Despesas: 'PC Despesas'!$S$5:$S$103
Name Outras_Receitas: 'PC Receitas'!$J$5:$J$103
Name Receitas_com_Aplicacoes_Financeiras: 'PC Receitas'!$G$5:$G$103
Name Renda_Familiar: 'PC Receitas'!$D$5:$D$103

Sheet Início
A1: 3.0.2 | C1: PLANILHA DE ORÇAMENTO
C2: PESSOAL E FAMILIAR 3.0
C3: Seja bem-vindo(a). Com esta planilha você terá o controle das suas finanças pessoais e poderá tomar decisões importantes com base em números
C4: Instruções sobre como você deve começar
C6: 1 | E6: Cadastre seus grupos de Receitas e Despesas
E7: É o começo de tudo! Esta aba vai ajudá-lo a criar grupos diferentes para suas rendas e gastos mais comuns. Para isso, você deve criar nomes para os grupos de receitas e despesas.
C10: 2 | E10: Insira seus lançamentos (suas receitas e despesas)
E11: Os valores que entrarem (receita) e os valores que saírem (despesas) devem ser registrados aqui. Você irá relacionar isso a uma data e a uma categoria dos seus grupos de contas
C14: 3 | E14: Veja o resumo dos seus lançamentos cada mês
E15: Aqui você pode ver um resumo dos seus lançamentos por dia. Ou seja, total de receitas, total de despesas e o saldo final de cada dia do mês.
C18: 4 | E18: Faça uma análise dos seus resultados
E19: Tenha uma visão clara sobre todas as suas Contas a Receber, a Pagar, seu Resultado Financeiro e o Fluxo de Caixa propriamente dito.
C22: 5 | E22: Veja os resultados através de gráficos
E23: Aqui você verá os gráficos a partir de todos os dados que você cadastrou em “lançamentos”. É uma forma rápida e agradável para visualizar seus resultados de forma prática.
C26: 6 | E26: Saiba exatamente o que fazer através dos alertas e dicas
E27: Seus resultados vão indicar se o seu fluxo financeiro está indo bem ou mal. Através destes indicadores, esta planilha fornecerá dicas automatizadas para sua tomada de decisões.
C30: 7 | E30: Imprima um relatório completo
E31: Já separamos uma aba exclusiva com suas principais informações financeiras prontas para impressão. Basta entrar no relatório e imprimir!

Sheet PC Receitas
A1: 3.0.2 | C1: 1. GRUPOS DE CONTAS
C4: 4.1 | D4: RENDA FAMILIAR | F4: 4.2 | G4: RECEITAS COM APLICAÇÕES FINANCEIRAS | I4: 4.3 | J4: OUTRAS RECEITAS | N4: =D4 -> RENDA FAMILIAR | O4: Renda_Familiar
C5: 4.1.1 | D5: Comissões | F5: 4.2.1 | G5: Poupança | I5: 4.3.1 | J5: - | N5: =G4 -> RECEITAS COM APLICAÇÕES FINANCEIRAS | O5: Receitas_com_Aplicacoes_Financeiras
C6: 4.1.2 | D6: Lucro Projetos | F6: 4.2.2 | G6: Títulos | I6: 4.3.2 | J6: - | N6: =J4 -> OUTRAS RECEITAS | O6: Outras_Receitas
C7: 4.1.3 | D7: Pró-labore | F7: 4.2.3 | G7: Bolsa de Valores | I7: 4.3.3 | J7: - | N7: ='PC Despesas'!D4 -> DESPESA DE MORADIA | O7: Despesas_de_Moradia
C8: 4.1.4 | D8: Salário da esposa | F8: 4.2.4 | G8: Aluguel do terreno | I8: 4.3.4 | J8: - | N8: ='PC Despesas'!G4 -> DESPESAS COM ALIMENTAÇÃO | O8: Despesas_com_Alimentacao
C9: 4.1.5 | D9: - | F9: 4.2.5 | G9: - | I9: 4.3.5 | J9: - | N9: ='PC Despesas'!J4 -> DESPESAS COM SAÚDE | O9: Despesas_com_Saude
C10: 4.1.6 | D10: - | F10: 4.2.6 | G10: - | I10: 4.3.6 | J10: - | N10: ='PC Despesas'!M4 -> DESPESAS COM TRANSPORTES | O10: Despesas_com_Transportes
C11: 4.1.7 | D11: - | F11: 4.2.7 | G11: - | I11: 4.3.7 | J11: - | N11: ='PC Despesas'!P4 -> DESPESAS COM LAZER E INFORMAÇÃO | O11: Despesas_com_Lazer_e_Informacao
C12: 4.1.8 | D12: - | F12: 4.2.8 | G12: - | I12: 4.3.8 | J12: - | N12: ='PC Despesas'!S4 -> OUTRAS DESPESAS | O12: Outras_Despesas
C13: 4.1.9 | D13: - | F13: 4.2.9 | G13: - | I13: 4.3.9 | J13: - | N13: ='PC Despesas'!V4 -> IMPOSTO DE RENDA | O13: Imposto_de_Renda
C14: 4.1.10 | D14: - | F14: 4.2.10 | G14: - | I14: 4.3.10 | J14: - | N14: ='PC Despesas'!Y4 -> INVESTIMENTOS (BENS) | O14: Investimentos_Bens
C15: 4.1.11 | D15: - | F15: 4.2.11 | G15: - | I15: 4.3.11 | J15: -
C16: 4.1.12 | D16: - | F16: 4.2.12 | G16: - | I16: 4.3.12 | J16: -
C17: 4.1.13 | D17: - | F17: 4.2.13 | G17: - | I17: 4.3.13 | J17: -
C18: 4.1.14 | D18: - | F18: 4.2.14 | G18: - | I18: 4.3.14 | J18: -
C19: 4.1.15 | D19: - | F19: 4.2.15 | G19: - | I19: 4.3.15 | J19: -
C20: 4.1.16 | D20: - | F20: 4.2.16 | G20: - | I20: 4.3.16 | J20: -
C21: 4.1.17 | D21: - | F21: 4.2.17 | G21: - | I21: 4.3.17 | J21: -
C22: 4.1.18 | D22: - | F22: 4.2.18 | G22: - | I22: 4.3.18 | J22: -
C23: 4.1.19 | D23: - | F23: 4.2.19 | G23: - | I23: 4.3.19 | J23: -
C24: 4.1.20 | D24: - | F24: 4.2.20 | G24: - | I24: 4.3.20 | J24: -
C25: 4.1.21 | D25: - | F25: 4.2.21 | G25: - | I25: 4.3.21 | J25: -
C26: 4.1.22 | D26: - | F26: 4.2.22 | G26: - | I26: 4.3.22 | J26: -
... C103: 4.1.99 | D103: Outras Fontes de Renda | F103: 4.2.99 | G103: Outras Rendas com Aplicações | I103: 4.3.99 | J103: Outras Fontes de Outras Receitas

Sheet PC Despesas
A1: 3.0.1 | C1: 1. PLANO DE CONTAS
C4: 5.1 | D4: DESPESA DE MORADIA | F4: 5.2 | G4: DESPESAS COM ALIMENTAÇÃO | I4: 5.3 | J4: DESPESAS COM SAÚDE | L4: 5.4 | M4: DESPESAS COM TRANSPORTES | O4: 5.5 | P4: DESPESAS COM LAZER E INFORMAÇÃO | R4: 5.6 | S4: OUTRAS DESPESAS | U4: 5.7 | V4: IMPOSTO DE RENDA | X4: 5.8 | Y4: INVESTIMENTOS (BENS)
C5: 5.1.1 | D5: Manutenção | F5: 5.2.1 | G5: Supermercado | I5: 5.3.1 | J5: Farmácia | L5: 5.4.1 | M5: Combustível | O5: 5.5.1 | P5: - | R5: 5.6.1 | S5: Faculdade | U5: 5.7.1 | V5: - | X5: 5.8.1 | Y5: -
C6: 5.1.2 | D6: - | F6: 5.2.2 | G6: - | I6: 5.3.2 | J6: - | L6: 5.4.2 | M6: - | O6: 5.5.2 | P6: - | R6: 5.6.2 | S6: - | U6: 5.7.2 | V6: - | X6: 5.8.2 | Y6: -
C7: 5.1.3 | D7: - | F7: 5.2.3 | G7: - | I7: 5.3.3 | J7: - | L7: 5.4.3 | M7: - | O7: 5.5.3 | P7: - | R7: 5.6.3 | S7: - | U7: 5.7.3 | V7: - | X7: 5.8.3 | Y7: -
C8: 5.1.4 | D8: - | F8: 5.2.4 | G8: - | I8: 5.3.4 | J8: - | L8: 5.4.4 | M8: - | O8: 5.5.4 | P8: - | R8: 5.6.4 | S8: - | U8: 5.7.4 | V8: - | X8: 5.8.4 | Y8: -
C9: 5.1.5 | D9: - | F9: 5.2.5 | G9: - | I9: 5.3.5 | J9: - | L9: 5.4.5 | M9: - | O9: 5.5.5 | P9: - | R9: 5.6.5 | S9: - | U9: 5.7.5 | V9: - | X9: 5.8.5 | Y9: -
C10: 5.1.6 | D10: - | F10: 5.2.6 | G10: - | I10: 5.3.6 | J10: - | L10: 5.4.6 | M10: - | O10: 5.5.6 | P10: - | R10: 5.6.6 | S10: - | U10: 5.7.6 | V10: - | X10: 5.8.6 | Y10: -
C11: 5.1.7 | D11: - | F11: 5.2.7 | G11: - | I11: 5.3.7 | J11: - | L11: 5.4.7 | M11: - | O11: 5.5.7 | P11: - | R11: 5.6.7 | S11: - | U11: 5.7.7 | V11: - | X11: 5.8.7 | Y11: -
C12: 5.1.8 | D12: - | F12: 5.2.8 | G12: - | I12: 5.3.8 | J12: - | L12: 5.4.8 | M12: - | O12: 5.5.8 | P12: - | R12: 5.6.8 | S12: - | U12: 5.7.8 | V12: - | X12: 5.8.8 | Y12: -
C13: 5.1.9 | D13: - | F13: 5.2.9 | G13: - | I13: 5.3.9 | J13: - | L13: 5.4.9 | M13: - | O13: 5.5.9 | P13: - | R13: 5.6.9 | S13: - | U13: 5.7.9 | V13: - | X13: 5.8.9 | Y13: -
C14: 5.1.10 | D14: - | F14: 5.2.10 | G14: - | I14: 5.3.10 | J14: - | L14: 5.4.10 | M14: - | O14: 5.5.10 | P14: - | R14: 5.6.10 | S14: - | U14: 5.7.10 | V14: - | X14: 5.8.10 | Y14: -
C15: 5.1.11 | D15: - | F15: 5.2.11 | G15: - | I15: 5.3.11 | J15: - | L15: 5.4.11 | M15: - | O15: 5.5.11 | P15: - | R15: 5.6.11 | S15: - | U15: 5.7.11 | V15: - | X15: 5.8.11 | Y15: -
... C102: 5.1.98 | D102: - | F102: 5.2.98 | G102: - | I102: 5.3.98 | J102: - | L102: 5.4.98 | M102: - | O102: 5.5.98 | P102: - | R102: 5.6.98 | S102: - | U102: 5.7.98 | V102: - | X102: 5.8.98 | Y102: -
C103: 5.1.99 | D103: ="OUTRAS "&D4 -> OUTRAS DESPESA DE MORADIA | F103: 5.2.99 | G103: ="OUTRAS "&G4 -> OUTRAS DESPESAS COM ALIMENTAÇÃO | I103: 5.3.99 | J103: ="OUTRAS "&J4 -> OUTRAS DESPESAS COM SAÚDE | L103: 5.4.99 | M103: ="OUTRAS "&M4 -> OUTRAS DESPESAS COM TRANSPORTES | O103: 5.5.99 | P103: ="OUTRAS "&P4 -> OUTRAS DESPESAS COM LAZER E INFORMAÇÃO | R103: 5.6.99 | S103: =S4 -> OUTRAS DESPESAS | U103: 5.7.99 | V103: Outros Impostos | X103: 5.8.99 | Y103: ="OUTROS "&Y4 -> OUTROS INVESTIMENTOS (BENS)
C106: =D5 -> Manutenção
C107: =D84 -> -
C108: =D85 -> -
C109: =D98 -> -
C110: =D99 -> -
C111: =D100 -> -
C112: =D101 -> -
C113: =D102 -> -
C114: =D103 -> OUTRAS DESPESA DE MORADIA
C115: -------------------------------------------
C116: =G5 -> Supermercado
C117: =G84 -> -
C118: =G85 -> -
C119: =G98 -> -
C120: =G99 -> -
C121: =G100 -> -
C122: =G101 -> -
C123: =G102 -> -
C124: =G103 -> OUTRAS DESPESAS COM ALIMENTAÇÃO
C126: -------------------------------------------
C127: =J5 -> Farmácia
C128: =J84 -> -
C129: =J85 -> -
C130: =J98 -> -
C131: =J99 -> -
...

Sheet Bancos e Cartões
A1: 3.0.1 | C1: 1. PLANO DE CONTAS
C5: 6.1 | D5: Bancos | E5: Saldos Iniciais | F5: Pagamentos parcelados no Cartão de Crédito do ano anterior já programados para os meses do ano corrente
F6: Janeiro | G6: Fevereiro | H6: Março | I6: Abril | J6: Maio | K6: Junho | L6: Julho | M6: Agosto | N6: Setembro | O6: Outubro | P6: Novembro | Q6: Dezembro
C7: 6.1.1 | D7: Mastercard | F7: 400 | G7: 100 | H7: 100
C8: 6.1.2 | D8: Itaú | E8: 1000
C9: 6.1.3 | D9: Caixinha | E9: 50
C10: 6.1.4 | D10: -
C11: 6.1.5 | D11: -
C12: 6.1.6 | D12: -
C13: 6.1.7 | D13: -
C14: 6.1.8 | D14: -
C15: 6.1.9 | D15: -
C16: 6.1.10 | D16: -
C17: 6.1.11 | D17: -
C18: 6.1.12 | D18: -
C19: 6.1.13 | D19: -
C20: 6.1.14 | D20: -

Sheet Jan
A1: 3.0.1 | C1: 2. LANÇAMENTOS: JAN
C4: Dia | D4: Classificação | E4: Item | F4: Grupo de Contas | G4: Forma de Pgt | H4: Banco | I4: Valor | J4: Status | K4: Saldo | M4: Resumo Geral
D5: Faturas de Cartão | E5: - | F5: =D5 -> Faturas de Cartão | G5: À Vista | H5: =W5 -> Mastercard | I5: ='Resumo (3)'!E7 -> 400 | K5: =N5-IF(J5="pago",I5,0) -> 1050 | M5: Saldo do Ano Anterior | N5: =SUM('Bancos e Cartões'!E7:E20) -> 1050 | P5: =IF(T5="Despesas_com_Transportes","Despesa",IF(T5="Despesas_com_Lazer_e_Informacao","Despesa",IF(T5="Outras_Despesas","Despesa",IF(T5="Imposto_de_Renda","Despesa",IF(T5="Investimentos_Bens","Despesa",""))))) | Q5: =IF(T5="Despesas_de_Moradia","Despesa",IF(T5="Despesas_com_Alimentacao","Despesa",IF(T5="Despesas_com_Saude","Despesa",""))) | R5: =IF(T5="Renda_Familiar","Receita",IF(T5="Receitas_com_Aplicacoes_Financeiras","Receita",IF(T5="Outras_Receitas","Receita",""))) | S5: Despesa | V5: ='PC Receitas'!D4 -> RENDA FAMILIAR | W5: ='Bancos e Cartões'!D7 -> Mastercard | X5: À Vista
D6: Faturas de Cartão | E6: - | F6: =D6 -> Faturas de Cartão | G6: À Vista | H6: =W6 -> Itaú | I6: ='Resumo (3)'!E8 -> 0 | K6: =K5-IF(J6="pago",I6,0) -> 1050 | P6: =IF(T6="Despesas_com_Transportes","Despesa",IF(T6="Despesas_com_Lazer_e_Informacao","Despesa",IF(T6="Outras_Despesas","Despesa",IF(T6="Imposto_de_Renda","Despesa",IF(T6="Investimentos_Bens","Despesa",""))))) | Q6: =IF(T6="Despesas_de_Moradia","Despesa",IF(T6="Despesas_com_Alimentacao","Despesa",IF(T6="Despesas_com_Saude","Despesa",""))) | R6: =IF(T6="Renda_Familiar","Receita",IF(T6="Receitas_com_Aplicacoes_Financeiras","Receita",IF(T6="Outras_Receitas","Receita",""))) | S6: Despesa | V6: ='PC Receitas'!G4 -> RECEITAS COM APLICAÇÕES FINANCEIRAS | W6: ='Bancos e Cartões'!D8 -> Itaú | X6: Crédito
D7: Faturas de Cartão | E7: - | F7: =D7 -> Faturas de Cartão | G7: À Vista | H7: =W7 -> Caixinha | I7: ='Resumo (3)'!E9 -> 0 | K7: =K6-IF(J7="pago",I7,0) -> 1050 | M7: Total de Receitas | N7: =SUMIFS($I$5:$I$619,$S$5:$S$619,"Receita",$J$5:$J$619,"Pago",$G$5:$G$619,"À Vista") -> 39000 | P7: =IF(T7="Despesas_com_Transportes","Despesa",IF(T7="Despesas_com_Lazer_e_Informacao","Despesa",IF(T7="Outras_Despesas","Despesa",IF(T7="Imposto_de_Renda","Despesa",IF(T7="Investimentos_Bens","Despesa",""))))) | Q7: =IF(T7="Despesas_de_Moradia","Despesa",IF(T7="Despesas_com_Alimentacao","Despesa",IF(T7="Despesas_com_Saude","Despesa",""))) | R7: =IF(T7="Renda_Familiar","Receita",IF(T7="Receitas_com_Aplicacoes_Financeiras","Receita",IF(T7="Outras_Receitas","Receita",""))) | S7: Despesa | V7: ='PC Receitas'!J4 -> OUTRAS RECEITAS | W7: ='Bancos e Cartões'!D9 -> Caixinha | X7: 2x
D8: Faturas de Cartão | E8: - | F8: =D8 -> Faturas de Cartão | G8: À Vista | H8: =W8 -> - | I8: ='Resumo (3)'!E10 -> 0 | K8: =K7-IF(J8="pago",I8,0) -> 1050 | P8: =IF(T8="Despesas_com_Transportes","Despesa",IF(T8="Despesas_com_Lazer_e_Informacao","Despesa",IF(T8="Outras_Despesas","Despesa",IF(T8="Imposto_de_Renda","Despesa",IF(T8="Investimentos_Bens","Despesa",""))))) | Q8: =IF(T8="Despesas_de_Moradia","Despesa",IF(T8="Despesas_com_Alimentacao","Despesa",IF(T8="Despesas_com_Saude","Despesa",""))) | R8: =IF(T8="Renda_Familiar","Receita",IF(T8="Receitas_com_Aplicacoes_Financeiras","Receita",IF(T8="Outras_Receitas","Receita",""))) | S8: Despesa | V8: ='PC Despesas'!D4 -> DESPESA DE MORADIA | W8: ='Bancos e Cartões'!D10 -> - | X8: 3x
D9: Faturas de Cartão | E9: - | F9: =D9 -> Faturas de Cartão | G9: À Vista | H9: =W9 -> - | I9: ='Resumo (3)'!E11 -> 0 | K9: =K8-IF(J9="pago",I9,0) -> 1050 | M9: Total de Despesas | N9: =SUMIFS($I$5:$I$619,$S$5:$S$619,"Despesa",$J$5:$J$619,"Pago",$G$5:$G$619,"À Vista") -> 1350 | P9: =IF(T9="Despesas_com_Transportes","Despesa",IF(T9="Despesas_com_Lazer_e_Informacao","Despesa",IF(T9="Outras_Despesas","Despesa",IF(T9="Imposto_de_Renda","Despesa",IF(T9="Investimentos_Bens","Despesa",""))))) | Q9: =IF(T9="Despesas_de_Moradia","Despesa",IF(T9="Despesas_com_Alimentacao","Despesa",IF(T9="Despesas_com_Saude","Despesa",""))) | R9: =IF(T9="Renda_Familiar","Receita",IF(T9="Receitas_com_Aplicacoes_Financeiras","Receita",IF(T9="Outras_Receitas","Receita",""))) | S9: Despesa | V9: ='PC Despesas'!G4 -> DESPESAS COM ALIMENTAÇÃO | W9: ='Bancos e Cartões'!D11 -> - | X9: 4x
D10: Faturas de Cartão | E10: - | F10: =D10 -> Faturas de Cartão | G10: À Vista | H10: =W10 -> - | I10: ='Resumo (3)'!E12 -> 0 | K10: =K9-IF(J10="pago",I10,0) -> 1050 | P10: =IF(T10="Despesas_com_Transportes","Despesa",IF(T10="Despesas_com_Lazer_e_Informacao","Despesa",IF(T10="Outras_Despesas","Despesa",IF(T10="Imposto_de_Renda","Despesa",IF(T10="Investimentos_Bens","Despesa",""))))) | Q10: =IF(T10="Despesas_de_Moradia","Despesa",IF(T10="Despesas_com_Alimentacao","Despesa",IF(T10="Despesas_com_Saude","Despesa",""))) | R10: =IF(T10="Renda_Familiar","Receita",IF(T10="Receitas_com_Aplicacoes_Financeiras","Receita",IF(T10="Outras_Receitas","Receita",""))) | S10: Despesa | V10: ='PC Despesas'!J4 -> DESPESAS COM SAÚDE | W10: ='Bancos e Cartões'!D12 -> - | X10: 5x
D11: Faturas de Cartão | E11: - | F11: =D11 -> Faturas de Cartão | G11: À Vista | H11: =W11 -> - | I11: ='Resumo (3)'!E13 -> 0 | K11: =K10-IF(J11="pago",I11,0) -> 1050 | M11: Resultado do Mês | N11: =N7-N9 -> 37650 | P11: =IF(T11="Despesas_com_Transportes","Despesa",IF(T11="Despesas_com_Lazer_e_Informacao","Despesa",IF(T11="Outras_Despesas","Despesa",IF(T11="Imposto_de_Renda","Despesa",IF(T11="Investimentos_Bens","Despesa",""))))) | Q11: =IF(T11="Despesas_de_Moradia","Despesa",IF(T11="Despesas_com_Alimentacao","Despesa",IF(T11="Despesas_com_Saude","Despesa",""))) | R11: =IF(T11="Renda_Familiar","Receita",IF(T11="Receitas_com_Aplicacoes_Financeiras","Receita",IF(T11="Outras_Receitas","Receita",""))) | S11: Despesa | V11: ='PC Despesas'!M4 -> DESPESAS COM TRANSPORTES | W11: ='Bancos e Cartões'!D13 -> - | X11: 6x
D12: Faturas de Cartão | E12: - | F12: =D12 -> Faturas de Cartão | G12: À Vista | H12: =W12 -> - | I12: ='Resumo (3)'!E14 -> 0 | K12: =K11-IF(J12="pago",I12,0) -> 1050 | P12: =IF(T12="Despesas_com_Transportes","Despesa",IF(T12="Despesas_com_Lazer_e_Informacao","Despesa",IF(T12="Outras_Despesas","Despesa",IF(T12="Imposto_de_Renda","Despesa",IF(T12="Investimentos_Bens","Despesa",""))))) | Q12: =IF(T12="Despesas_de_Moradia","Despesa",IF(T12="Despesas_com_Alimentacao","Despesa",IF(T12="Despesas_com_Saude","Despesa",""))) | R12: =IF(T12="Renda_Familiar","Receita",IF(T12="Receitas_com_Aplicacoes_Financeiras","Receita",IF(T12="Outras_Receitas","Receita",""))) | S12: Despesa | V12: ='PC Despesas'!P4 -> DESPESAS COM LAZER E INFORMAÇÃO | W12: ='Bancos e Cartões'!D14 -> - | X12: 7x
D13: Faturas de Cartão | E13: - | F13: =D13 -> Faturas de Cartão | G13: À Vista | H13: =W13 -> - | I13: ='Resumo (3)'!E15 -> 0 | K13: =K12-IF(J13="pago",I13,0) -> 1050 | M13: Acumulado | N13: =K619 -> 38700 | P13: =IF(T13="Despesas_com_Transportes","Despesa",IF(T13="Despesas_com_Lazer_e_Informacao","Despesa",IF(T13="Outras_Despesas","Despesa",IF(T13="Imposto_de_Renda","Despesa",IF(T13="Investimentos_Bens","Despesa",""))))) | Q13: =IF(T13="Despesas_de_Moradia","Despesa",IF(T13="Despesas_com_Alimentacao","Despesa",IF(T13="Despesas_com_Saude","Despesa",""))) | R13: =IF(T13="Renda_Familiar","Receita",IF(T13="Receitas_com_Aplicacoes_Financeiras","Receita",IF(T13="Outras_Receitas","Receita",""))) | S13: Despesa | V13: ='PC Despesas'!S4 -> OUTRAS DESPESAS | W13: ='Bancos e Cartões'!D15 -> - | X13: 8x
D14: Faturas de Cartão | E14: - | F14: =D14 -> Faturas de Cartão | G14: À Vista | H14: =W14 -> - | I14: ='Resumo (3)'!E16 -> 0 | K14: =K13-IF(J14="pago",I14,0) -> 1050 | P14: =IF(T14="Despesas_com_Transportes","Despesa",IF(T14="Despesas_com_Lazer_e_Informacao","Despesa",IF(T14="Outras_Despesas","Despesa",IF(T14="Imposto_de_Renda","Despesa",IF(T14="Investimentos_Bens","Despesa",""))))) | Q14: =IF(T14="Despesas_de_Moradia","Despesa",IF(T14="Despesas_com_Alimentacao","Despesa",IF(T14="Despesas_com_Saude","Despesa",""))) | R14: =IF(T14="Renda_Familiar","Receita",IF(T14="Receitas_com_Aplicacoes_Financeiras","Receita",IF(T14="Outras_Receitas","Receita",""))) | S14: Despesa | V14: ='PC Despesas'!V4 -> IMPOSTO DE RENDA | W14: ='Bancos e Cartões'!D16 -> - | X14: 9x
D15: Faturas de Cartão | E15: - | F15: =D15 -> Faturas de Cartão | G15: À Vista | H15: =W15 -> - | I15: ='Resumo (3)'!E17 -> 0 | K15: =K14-IF(J15="pago",I15,0) -> 1050 | P15: =IF(T15="Despesas_com_Transportes","Despesa",IF(T15="Despesas_com_Lazer_e_Informacao","Despesa",IF(T15="Outras_Despesas","Despesa",IF(T15="Imposto_de_Renda","Despesa",IF(T15="Investimentos_Bens","Despesa",""))))) | Q15: =IF(T15="Despesas_de_Moradia","Despesa",IF(T15="Despesas_com_Alimentacao","Despesa",IF(T15="Despesas_com_Saude","Despesa",""))) | R15: =IF(T15="Renda_Familiar","Receita",IF(T15="Receitas_com_Aplicacoes_Financeiras","Receita",IF(T15="Outras_Receitas","Receita",""))) | S15: Despesa | V15: ='PC Despesas'!Y4 -> INVESTIMENTOS (BENS) | W15: ='Bancos e Cartões'!D17 -> - | X15: 10x
D16: Faturas de Cartão | E16: - | F16: =D16 -> Faturas de Cartão | G16: À Vista | H16: =W16 -> - | I16: ='Resumo (3)'!E18 -> 0 | K16: =K15-IF(J16="pago",I16,0) -> 1050 | P16: =IF(T16="Despesas_com_Transportes","Despesa",IF(T16="Despesas_com_Lazer_e_Informacao","Despesa",IF(T16="Outras_Despesas","Despesa",IF(T16="Imposto_de_Renda","Despesa",IF(T16="Investimentos_Bens","Despesa",""))))) | Q16: =IF(T16="Despesas_de_Moradia","Despesa",IF(T16="Despesas_com_Alimentacao","Despesa",IF(T16="Despesas_com_Saude","Despesa",""))) | R16: =IF(T16="Renda_Familiar","Receita",IF(T16="Receitas_com_Aplicacoes_Financeiras","Receita",IF(T16="Outras_Receitas","Receita",""))) | S16: Despesa | W16: ='Bancos e Cartões'!D18 -> - | X16: 11x
D17: Faturas de Cartão | E17: - | F17: =D17 -> Faturas de Cartão | G17: À Vista | H17: =W17 -> - | I17: ='Resumo (3)'!E19 -> 0 | K17: =K16-IF(J17="pago",I17,0) -> 1050 | P17: =IF(T17="Despesas_com_Transportes","Despesa",IF(T17="Despesas_com_Lazer_e_Informacao","Despesa",IF(T17="Outras_Despesas","Despesa",IF(T17="Imposto_de_Renda","Despesa",IF(T17="Investimentos_Bens","Despesa",""))))) | Q17: =IF(T17="Despesas_de_Moradia","Despesa",IF(T17="Despesas_com_Alimentacao","Despesa",IF(T17="Despesas_com_Saude","Despesa",""))) | R17: =IF(T17="Renda_Familiar","Receita",IF(T17="Receitas_com_Aplicacoes_Financeiras","Receita",IF(T17="Outras_Receitas","Receita",""))) | S17: Despesa | W17: ='Bancos e Cartões'!D19 -> - | X17: 12x
D18: Faturas de Cartão | E18: - | F18: =D18 -> Faturas de Cartão | G18: À Vista | H18: =W18 -> - | I18: ='Resumo (3)'!E20 -> 0 | K18: =K17-IF(J18="pago",I18,0) -> 1050 | P18: =IF(T18="Despesas_com_Transportes","Despesa",IF(T18="Despesas_com_Lazer_e_Informacao","Despesa",IF(T18="Outras_Despesas","Despesa",IF(T18="Imposto_de_Renda","Despesa",IF(T18="Investimentos_Bens","Despesa",""))))) | Q18: =IF(T18="Despesas_de_Moradia","Despesa",IF(T18="Despesas_com_Alimentacao","Despesa",IF(T18="Despesas_com_Saude","Despesa",""))) | R18: =IF(T18="Renda_Familiar","Receita",IF(T18="Receitas_com_Aplicacoes_Financeiras","Receita",IF(T18="Outras_Receitas","Receita",""))) | S18: Despesa | W18: ='Bancos e Cartões'!D20 -> -
C19: 2 | D19: DESPESA DE MORADIA | E19: Luzes | F19: Manutenção | G19: À Vista | H19: Mastercard | I19: 100 | J19: Pago | K19: =K18+IF(AND(J19="Pago",OR(D19=$V$5,D19=$V$6,D19=$V$7)),I19,IF(AND(J19="Pago",OR(D19=$V$8,D19=$V$9,D19=$V$10,D19=$V$11,D19=$V$12,D19=$V$13,D19=$V$14,D19=$V$15)),-I19,IF(G19="À Vista",IF(J19="Pago",-I19,0),0))) -> 950 | P19: =IF(T19="Despesas_com_Transportes","Despesa",IF(T19="Despesas_com_Lazer_e_Informacao","Despesa",IF(T19="Outras_Despesas","Despesa",IF(T19="Imposto_de_Renda","Despesa",IF(T19="Investimentos_Bens","Despesa",""))))) | Q19: =IF(T19="Despesas_de_Moradia","Despesa",IF(T19="Despesas_com_Alimentacao","Despesa",IF(T19="Despesas_com_Saude","Despesa",""))) -> Despesa | R19: =IF(T19="Renda_Familiar","Receita",IF(T19="Receitas_com_Aplicacoes_Financeiras","Receita",IF(T19="Outras_Receitas","Receita",""))) | S19: =IF(P19<>"",P19,IF(Q19<>"",Q19,IF(R19<>"",R19,""))) -> Despesa | T19: =VLOOKUP(D19,'PC Receitas'!$N$4:$O$14,2,FALSE) -> Despesas_de_Moradia
C20: 3 | D20: DESPESA DE MORADIA | E20: Água | F20: Manutenção | G20: À Vista | H20: Mastercard | I20: 150 | J20: Pago | K20: =K19+IF(AND(J20="Pago",OR(D20=$V$5,D20=$V$6,D20=$V$7)),I20,IF(AND(J20="Pago",OR(D20=$V$8,D20=$V$9,D20=$V$10,D20=$V$11,D20=$V$12,D20=$V$13,D20=$V$14,D20=$V$15)),-I20,IF(G20="À Vista",IF(J20="Pago",-I20,0),0))) -> 800 | P20: =IF(T20="Despesas_com_Transportes","Despesa",IF(T20="Despesas_com_Lazer_e_Informacao","Despesa",IF(T20="Outras_Despesas","Despesa",IF(T20="Imposto_de_Renda","Despesa",IF(T20="Investimentos_Bens","Despesa",""))))) | Q20: =IF(T20="Despesas_de_Moradia","Despesa",IF(T20="Despesas_com_Alimentacao","Despesa",IF(T20="Despesas_com_Saude","Despesa",""))) -> Despesa | R20: =IF(T20="Renda_Familiar","Receita",IF(T20="Receitas_com_Aplicacoes_Financeiras","Receita",IF(T20="Outras_Receitas","Receita",""))) | S20: =IF(P20<>"",P20,IF(Q20<>"",Q20,IF(R20<>"",R20,""))) -> Despesa | T20: =VLOOKUP(D20,'PC Receitas'!$N$4:$O$14,2,FALSE) -> Despesas_de_Moradia
C21: 3 | D21: DESPESA DE MORADIA | E21: Net | F21: Manutenção | G21: À Vista | H21: Mastercard | I21: 200 | J21: Pago | K21: =K20+IF(AND(J21="Pago",OR(D21=$V$5,D21=$V$6,D21=$V$7)),I21,IF(AND(J21="Pago",OR(D21=$V$8,D21=$V$9,D21=$V$10,D21=$V$11,D21=$V$12,D21=$V$13,D21=$V$14,D21=$V$15)),-I21,IF(G21="À Vista",IF(J21="Pago",-I21,0),0))) -> 600 | P21: =IF(T21="Despesas_com_Transportes","Despesa",IF(T21="Despesas_com_Lazer_e_Informacao","Despesa",IF(T21="Outras_Despesas","Despesa",IF(T21="Imposto_de_Renda","Despesa",IF(T21="Investimentos_Bens","Despesa",""))))) | Q21: =IF(T21="Despesas_de_Moradia","Despesa",IF(T21="Despesas_com_Alimentacao","Despesa",IF(T21="Despesas_com_Saude","Despesa",""))) -> Despesa | R21: =IF(T21="Renda_Familiar","Receita",IF(T21="Receitas_com_Aplicacoes_Financeiras","Receita",IF(T21="Outras_Receitas","Receita",""))) | S21: =IF(P21<>"",P21,IF(Q21<>"",Q21,IF(R21<>"",R21,""))) -> Despesa | T21: =VLOOKUP(D21,'PC Receitas'!$N$4:$O$14,2,FALSE) -> Despesas_de_Moradia
C22: 3 | D22: DESPESA DE MORADIA | E22: Telefone | F22: Manutenção | G22: À Vista | I22: 100 | J22: Não Pago | K22: =K21+IF(AND(J22="Pago",OR(D22=$V$5,D22=$V$6,D22=$V$7)),I22,IF(AND(J22="Pago",OR(D22=$V$8,D22=$V$9,D22=$V$10,D22=$V$11,D22=$V$12,D22=$V$13,D22=$V$14,D22=$V$15)),-I22,IF(G22="À Vista",IF(J22="Pago",-I22,0),0))) -> 600 | P22: =IF(T22="Despesas_com_Transportes","Despesa",IF(T22="Despesas_com_Lazer_e_Informacao","Despesa",IF(T22="Outras_Despesas","Despesa",IF(T22="Imposto_de_Renda","Despesa",IF(T22="Investimentos_Bens","Despesa",""))))) | Q22: =IF(T22="Despesas_de_Moradia","Despesa",IF(T22="Despesas_com_Alimentacao","Despesa",IF(T22="Despesas_com_Saude","Despesa",""))) -> Despesa | R22: =IF(T22="Renda_Familiar","Receita",IF(T22="Receitas_com_Aplicacoes_Financeiras","Receita",IF(T22="Outras_Receitas","Receita",""))) | S22: =IF(P22<>"",P22,IF(Q22<>"",Q22,IF(R22<>"",R22,""))) -> Despesa | T22: =VLOOKUP(D22,'PC Receitas'!$N$4:$O$14,2,FALSE) -> Despesas_de_Moradia
C23: 5 | D23: DESPESAS COM LAZER E INFORMAÇÃO | E23: Presente | F23: - | G23: 3x | H23: Itaú | I23: 300 | J23: Não Pago | K23: =K22+IF(AND(J23="Pago",OR(D23=$V$5,D23=$V$6,D23=$V$7)),I23,IF(AND(J23="Pago",OR(D23=$V$8,D23=$V$9,D23=$V$10,D23=$V$11,D23=$V$12,D23=$V$13,D23=$V$14,D23=$V$15)),-I23,IF(G23="À Vista",IF(J23="Pago",-I23,0),0))) -> 600 | P23: =IF(T23="Despesas_com_Transportes","Despesa",IF(T23="Despesas_com_Lazer_e_Informacao","Despesa",IF(T23="Outras_Despesas","Despesa",IF(T23="Imposto_de_Renda","Despesa",IF(T23="Investimentos_Bens","Despesa",""))))) -> Despesa | Q23: =IF(T23="Despesas_de_Moradia","Despesa",IF(T23="Despesas_com_Alimentacao","Despesa",IF(T23="Despesas_com_Saude","Despesa",""))) | R23: =IF(T23="Renda_Familiar","Receita",IF(T23="Receitas_com_Aplicacoes_Financeiras","Receita",IF(T23="Outras_Receitas","Receita",""))) | S23: =IF(P23<>"",P23,IF(Q23<>"",Q23,IF(R23<>"",R23,""))) -> Despesa | T23: =VLOOKUP(D23,'PC Receitas'!$N$4:$O$14,2,FALSE) -> Despesas_com_Lazer_e_Informacao
D24: RENDA FAMILIAR | E24: Minha empresa | F24: Pró-labore | G24: À Vista | H24: Mastercard | I24: 7000 | J24: Pago | K24: =K23+IF(AND(J24="Pago",OR(D24=$V$5,D24=$V$6,D24=$V$7)),I24,IF(AND(J24="Pago",OR(D24=$V$8,D24=$V$9,D24=$V$10,D24=$V$11,D24=$V$12,D24=$V$13,D24=$V$14,D24=$V$15)),-I24,IF(G24="À Vista",IF(J24="Pago",-I24,0),0))) -> 7600 | P24: =IF(T24="Despesas_com_Transportes","Despesa",IF(T24="Despesas_com_Lazer_e_Informacao","Despesa",IF(T24="Outras_Despesas","Despesa",IF(T24="Imposto_de_Renda","Despesa",IF(T24="Investimentos_Bens","Despesa",""))))) | Q24: =IF(T24="Despesas_de_Moradia","Despesa",IF(T24="Despesas_com_Alimentacao","Despesa",IF(T24="Despesas_com_Saude","Despesa",""))) | R24: =IF(T24="Renda_Familiar","Receita",IF(T24="Receitas_com_Aplicacoes_Financeiras","Receita",IF(T24="Outras_Receitas","Receita",""))) -> Receita | S24: =IF(P24<>"",P24,IF(Q24<>"",Q24,IF(R24<>"",R24,""))) -> Receita | T24: =VLOOKUP(D24,'PC Receitas'!$N$4:$O$14,2,FALSE) -> Renda_Familiar
D25: RENDA FAMILIAR | E25: Salário | F25: Salário da esposa | G25: À Vista | I25: 6000 | J25: Pago | K25: =K24+IF(AND(J25="Pago",OR(D25=$V$5,D25=$V$6,D25=$V$7)),I25,IF(AND(J25="Pago",OR(D25=$V$8,D25=$V$9,D25=$V$10,D25=$V$11,D25=$V$12,D25=$V$13,D25=$V$14,D25=$V$15)),-I25,IF(G25="À Vista",IF(J25="Pago",-I25,0),0))) -> 13600 | P25: =IF(T25="Despesas_com_Transportes","Despesa",IF(T25="Despesas_com_Lazer_e_Informacao","Despesa",IF(T25="Outras_Despesas","Despesa",IF(T25="Imposto_de_Renda","Despesa",IF(T25="Investimentos_Bens","Despesa",""))))) | Q25: =IF(T25="Despesas_de_Moradia","Despesa",IF(T25="Despesas_com_Alimentacao","Despesa",IF(T25="Despesas_com_Saude","Despesa",""))) | R25: =IF(T25="Renda_Familiar","Receita",IF(T25="Receitas_com_Aplicacoes_Financeiras","Receita",IF(T25="Outras_Receitas","Receita",""))) -> Receita | S25: =IF(P25<>"",P25,IF(Q25<>"",Q25,IF(R25<>"",R25,""))) -> Receita | T25: =VLOOKUP(D25,'PC Receitas'!$N$4:$O$14,2,FALSE) -> Renda_Familiar
C26: 2 | D26: DESPESA DE MORADIA | E26: Luzes | F26: Manutenção | G26: À Vista | H26: Mastercard | I26: 100 | J26: Pago | K26: =K25+IF(AND(J26="Pago",OR(D26=$V$5,D26=$V$6,D26=$V$7)),I26,IF(AND(J26="Pago",OR(D26=$V$8,D26=$V$9,D26=$V$10,D26=$V$11,D26=$V$12,D26=$V$13,D26=$V$14,D26=$V$15)),-I26,IF(G26="À Vista",IF(J26="Pago",-I26,0),0))) -> 13500 | P26: =IF(T26="Despesas_com_Transportes","Despesa",IF(T26="Despesas_com_Lazer_e_Informacao","Despesa",IF(T26="Outras_Despesas","Despesa",IF(T26="Imposto_de_Renda","Despesa",IF(T26="Investimentos_Bens","Despesa",""))))) | Q26: =IF(T26="Despesas_de_Moradia","Despesa",IF(T26="Despesas_com_Alimentacao","Despesa",IF(T26="Despesas_com_Saude","Despesa",""))) -> Despesa | R26: =IF(T26="Renda_Familiar","Receita",IF(T26="Receitas_com_Aplicacoes_Financeiras","Receita",IF(T26="Outras_Receitas","Receita",""))) | S26: =IF(P26<>"",P26,IF(Q26<>"",Q26,IF(R26<>"",R26,""))) -> Despesa | T26: =VLOOKUP(D26,'PC Receitas'!$N$4:$O$14,2,FALSE) -> Despesas_de_Moradia
C27: 3 | D27: DESPESA DE MORADIA | E27: Água | F27: Manutenção | G27: À Vista | H27: Mastercard | I27: 150 | J27: Pago | K27: =K26+IF(AND(J27="Pago",OR(D27=$V$5,D27=$V$6,D27=$V$7)),I27,IF(AND(J27="Pago",OR(D27=$V$8,D27=$V$9,D27=$V$10,D27=$V$11,D27=$V$12,D27=$V$13,D27=$V$14,D27=$V$15)),-I27,IF(G27="À Vista",IF(J27="Pago",-I27,0),0))) -> 13350 | P27: =IF(T27="Despesas_com_Transportes","Despesa",IF(T27="Despesas_com_Lazer_e_Informacao","Despesa",IF(T27="Outras_Despesas","Despesa",IF(T27="Imposto_de_Renda","Despesa",IF(T27="Investimentos_Bens","Despesa",""))))) | Q27: =IF(T27="Despesas_de_Moradia","Despesa",IF(T27="Despesas_com_Alimentacao","Despesa",IF(T27="Despesas_com_Saude","Despesa",""))) -> Despesa | R27: =IF(T27="Renda_Familiar","Receita",IF(T27="Receitas_com_Aplicacoes_Financeiras","Receita",IF(T27="Outras_Receitas","Receita",""))) | S27: =IF(P27<>"",P27,IF(Q27<>"",Q27,IF(R27<>"",R27,""))) -> Despesa | T27: =VLOOKUP(D27,'PC Receitas'!$N$4:$O$14,2,FALSE) -> Despesas_de_Moradia
C28: 3 | D28: DESPESA DE MORADIA | E28: Net | F28: Manutenção | G28: À Vista | H28: Mastercard | I28: 200 | J28: Pago | K28: =K27+IF(AND(J28="Pago",OR(D28=$V$5,D28=$V$6,D28=$V$7)),I28,IF(AND(J28="Pago",OR(D28=$V$8,D28=$V$9,D28=$V$10,D28=$V$11,D28=$V$12,D28=$V$13,D28=$V$14,D28=$V$15)),-I28,IF(G28="À Vista",IF(J28="Pago",-I28,0),0))) -> 13150 | P28: =IF(T28="Despesas_com_Transportes","Despesa",IF(T28="Despesas_com_Lazer_e_Informacao","Despesa",IF(T28="Outras_Despesas","Despesa",IF(T28="Imposto_de_Renda","Despesa",IF(T28="Investimentos_Bens","Despesa",""))))) | Q28: =IF(T28="Despesas_de_Moradia","Despesa",IF(T28="Despesas_com_Alimentacao","Despesa",IF(T28="Despesas_com_Saude","Despesa",""))) -> Despesa | R28: =IF(T28="Renda_Familiar","Receita",IF(T28="Receitas_com_Aplicacoes_Financeiras","Receita",IF(T28="Outras_Receitas","Receita",""))) | S28: =IF(P28<>"",P28,IF(Q28<>"",Q28,IF(R28<>"",R28,""))) -> Despesa | T28: =VLOOKUP(D28,'PC Receitas'!$N$4:$O$14,2,FALSE) -> Despesas_de_Moradia
C29: 3 | D29: DESPESA DE MORADIA | E29: Telefone | F29: Manutenção | G29: À Vista | I29: 100 | J29: Não Pago | K29: =K28+IF(AND(J29="Pago",OR(D29=$V$5,D29=$V$6,D29=$V$7)),I29,IF(AND(J29="Pago",OR(D29=$V$8,D29=$V$9,D29=$V$10,D29=$V$11,D29=$V$12,D29=$V$13,D29=$V$14,D29=$V$15)),-I29,IF(G29="À Vista",IF(J29="Pago",-I29,0),0))) -> 13150 | P29: =IF(T29="Despesas_com_Transportes","Despesa",IF(T29="Despesas_com_Lazer_e_Informacao","Despesa",IF(T29="Outras_Despesas","Despesa",IF(T29="Imposto_de_Renda","Despesa",IF(T29="Investimentos_Bens","Despesa",""))))) | Q29: =IF(T29="Despesas_de_Moradia","Despesa",IF(T29="Despesas_com_Alimentacao","Despesa",IF(T29="Despesas_com_Saude","Despesa",""))) -> Despesa | R29: =IF(T29="Renda_Familiar","Receita",IF(T29="Receitas_com_Aplicacoes_Financeiras","Receita",IF(T29="Outras_Receitas","Receita",""))) | S29: =IF(P29<>"",P29,IF(Q29<>"",Q29,IF(R29<>"",R29,""))) -> Despesa | T29: =VLOOKUP(D29,'PC Receitas'!$N$4:$O$14,2,FALSE) -> Despesas_de_Moradia
C30: 5 | D30: DESPESAS COM LAZER E INFORMAÇÃO | E30: Presente | F30: - | G30: 3x | H30: Itaú | I30: 300 | J30: Não Pago | K30: =K29+IF(AND(J30="Pago",OR(D30=$V$5,D30=$V$6,D30=$V$7)),I30,IF(AND(J30="Pago",OR(D30=$V$8,D30=$V$9,D30=$V$10,D30=$V$11,D30=$V$12,D30=$V$13,D30=$V$14,D30=$V$15)),-I30,IF(G30="À Vista",IF(J30="Pago",-I30,0),0))) -> 13150 | P30: =IF(T30="Despesas_com_Transportes","Despesa",IF(T30="Despesas_com_Lazer_e_Informacao","Despesa",IF(T30="Outras_Despesas","Despesa",IF(T30="Imposto_de_Renda","Despesa",IF(T30="Investimentos_Bens","Despesa",""))))) -> Despesa | Q30: =IF(T30="Despesas_de_Moradia","Despesa",IF(T30="Despesas_com_Alimentacao","Despesa",IF(T30="Despesas_com_Saude","Despesa",""))) | R30: =IF(T30="Renda_Familiar","Receita",IF(T30="Receitas_com_Aplicacoes_Financeiras","Receita",IF(T30="Outras_Receitas","Receita",""))) | S30: =IF(P30<>"",P30,IF(Q30<>"",Q30,IF(R30<>"",R30,""))) -> Despesa | T30: =VLOOKUP(D30,'PC Receitas'!$N$4:$O$14,2,FALSE) -> Despesas_com_Lazer_e_Informacao
D31: RENDA FAMILIAR | E31: Minha empresa | F31: Pró-labore | G31: À Vista | H31: Mastercard | I31: 7000 | J31: Pago | K31: =K30+IF(AND(J31="Pago",OR(D31=$V$5,D31=$V$6,D31=$V$7)),I31,IF(AND(J31="Pago",OR(D31=$V$8,D31=$V$9,D31=$V$10,D31=$V$11,D31=$V$12,D31=$V$13,D31=$V$14,D31=$V$15)),-I31,IF(G31="À Vista",IF(J31="Pago",-I31,0),0))) -> 20150 | P31: =IF(T31="Despesas_com_Transportes","Despesa",IF(T31="Despesas_com_Lazer_e_Informacao","Despesa",IF(T31="Outras_Despesas","Despesa",IF(T31="Imposto_de_Renda","Despesa",IF(T31="Investimentos_Bens","Despesa",""))))) | Q31: =IF(T31="Despesas_de_Moradia","Despesa",IF(T31="Despesas_com_Alimentacao","Despesa",IF(T31="Despesas_com_Saude","Despesa",""))) | R31: =IF(T31="Renda_Familiar","Receita",IF(T31="Receitas_com_Aplicacoes_Financeiras","Receita",IF(T31="Outras_Receitas","Receita",""))) -> Receita | S31: =IF(P31<>"",P31,IF(Q31<>"",Q31,IF(R31<>"",R31,""))) -> Receita | T31: =VLOOKUP(D31,'PC Receitas'!$N$4:$O$14,2,FALSE) -> Renda_Familiar
D32: RENDA FAMILIAR | E32: Salário | F32: Salário da esposa | G32: À Vista | I32: 6000 | J32: Pago | K32: =K31+IF(AND(J32="Pago",OR(D32=$V$5,D32=$V$6,D32=$V$7)),I32,IF(AND(J32="Pago",OR(D32=$V$8,D32=$V$9,D32=$V$10,D32=$V$11,D32=$V$12,D32=$V$13,D32=$V$14,D32=$V$15)),-I32,IF(G32="À Vista",IF(J32="Pago",-I32,0),0))) -> 26150 | P32: =IF(T32="Despesas_com_Transportes","Despesa",IF(T32="Despesas_com_Lazer_e_Informacao","Despesa",IF(T32="Outras_Despesas","Despesa",IF(T32="Imposto_de_Renda","Despesa",IF(T32="Investimentos_Bens","Despesa",""))))) | Q32: =IF(T32="Despesas_de_Moradia","Despesa",IF(T32="Despesas_com_Alimentacao","Despesa",IF(T32="Despesas_com_Saude","Despesa",""))) | R32: =IF(T32="Renda_Familiar","Receita",IF(T32="Receitas_com_Aplicacoes_Financeiras","Receita",IF(T32="Outras_Receitas","Receita",""))) -> Receita | S32: =IF(P32<>"",P32,IF(Q32<>"",Q32,IF(R32<>"",R32,""))) -> Receita | T32: =VLOOKUP(D32,'PC Receitas'!$N$4:$O$14,2,FALSE) -> Renda_Familiar
C33: 2 | D33: DESPESA DE MORADIA | E33: Luzes | F33: Manutenção | G33: À Vista | H33: Mastercard | I33: 100 | J33: Pago | K33: =K32+IF(AND(J33="Pago",OR(D33=$V$5,D33=$V$6,D33=$V$7)),I33,IF(AND(J33="Pago",OR(D33=$V$8,D33=$V$9,D33=$V$10,D33=$V$11,D33=$V$12,D33=$V$13,D33=$V$14,D33=$V$15)),-I33,IF(G33="À Vista",IF(J33="Pago",-I33,0),0))) -> 26050 | P33: =IF(T33="Despesas_com_Transportes","Despesa",IF(T33="Despesas_com_Lazer_e_Informacao","Despesa",IF(T33="Outras_Despesas","Despesa",IF(T33="Imposto_de_Renda","Despesa",IF(T33="Investimentos_Bens","Despesa",""))))) | Q33: =IF(T33="Despesas_de_Moradia","Despesa",IF(T33="Despesas_com_Alimentacao","Despesa",IF(T33="Despesas_com_Saude","Despesa",""))) -> Despesa | R33: =IF(T33="Renda_Familiar","Receita",IF(T33="Receitas_com_Aplicacoes_Financeiras","Receita",IF(T33="Outras_Receitas","Receita",""))) | S33: =IF(P33<>"",P33,IF(Q33<>"",Q33,IF(R33<>"",R33,""))) -> Despesa | T33: =VLOOKUP(D33,'PC Receitas'!$N$4:$O$14,2,FALSE) -> Despesas_de_Moradia
C34: 3 | D34: DESPESA DE MORADIA | E34: Água | F34: Manutenção | G34: À Vista | H34: Mastercard | I34: 150 | J34: Pago | K34: =K33+IF(AND(J34="Pago",OR(D34=$V$5,D34=$V$6,D34=$V$7)),I34,IF(AND(J34="Pago",OR(D34=$V$8,D34=$V$9,D34=$V$10,D34=$V$11,D34=$V$12,D34=$V$13,D34=$V$14,D34=$V$15)),-I34,IF(G34="À Vista",IF(J34="Pago",-I34,0),0))) -> 25900 | P34: =IF(T34="Despesas_com_Transportes","Despesa",IF(T34="Despesas_com_Lazer_e_Informacao","Despesa",IF(T34="Outras_Despesas","Despesa",IF(T34="Imposto_de_Renda","Despesa",IF(T34="Investimentos_Bens","Despesa",""))))) | Q34: =IF(T34="Despesas_de_Moradia","Despesa",IF(T34="Despesas_com_Alimentacao","Despesa",IF(T34="Despesas_com_Saude","Despesa",""))) -> Despesa | R34: =IF(T34="Renda_Familiar","Receita",IF(T34="Receitas_com_Aplicacoes_Financeiras","Receita",IF(T34="Outras_Receitas","Receita",""))) | S34: =IF(P34<>"",P34,IF(Q34<>"",Q34,IF(R34<>"",R34,""))) -> Despesa | T34: =VLOOKUP(D34,'PC Receitas'!$N$4:$O$14,2,FALSE) -> Despesas_de_Moradia
C35: 3 | D35: DESPESA DE MORADIA | E35: Net | F35: Manutenção | G35: À Vista | H35: Mastercard | I35: 200 | J35: Pago | K35: =K34+IF(AND(J35="Pago",OR(D35=$V$5,D35=$V$6,D35=$V$7)),I35,IF(AND(J35="Pago",OR(D35=$V$8,D35=$V$9,D35=$V$10,D35=$V$11,D35=$V$12,D35=$V$13,D35=$V$14,D35=$V$15)),-I35,IF(G35="À Vista",IF(J35="Pago",-I35,0),0))) -> 25700 | P35: =IF(T35="Despesas_com_Transportes","Despesa",IF(T35="Despesas_com_Lazer_e_Informacao","Despesa",IF(T35="Outras_Despesas","Despesa",IF(T35="Imposto_de_Renda","Despesa",IF(T35="Investimentos_Bens","Despesa",""))))) | Q35: =IF(T35="Despesas_de_Moradia","Despesa",IF(T35="Despesas_com_Alimentacao","Despesa",IF(T35="Despesas_com_Saude","Despesa",""))) -> Despesa | R35: =IF(T35="Renda_Familiar","Receita",IF(T35="Receitas_com_Aplicacoes_Financeiras","Receita",IF(T35="Outras_Receitas","Receita",""))) | S35: =IF(P35<>"",P35,IF(Q35<>"",Q35,IF(R35<>"",R35,""))) -> Despesa | T35: =VLOOKUP(D35,'PC Receitas'!$N$4:$O$14,2,FALSE) -> Despesas_de_Moradia
C36: 3 | D36: DESPESA DE MORADIA | E36: Telefone | F36: Manutenção | G36: À Vista | I36: 100 | J36: Não Pago | K36: =K35+IF(AND(J36="Pago",OR(D36=$V$5,D36=$V$6,D36=$V$7)),I36,IF(AND(J36="Pago",OR(D36=$V$8,D36=$V$9,D36=$V$10,D36=$V$11,D36=$V$12,D36=$V$13,D36=$V$14,D36=$V$15)),-I36,IF(G36="À Vista",IF(J36="Pago",-I36,0),0))) -> 25700 | P36: =IF(T36="Despesas_com_Transportes","Despesa",IF(T36="Despesas_com_Lazer_e_Informacao","Despesa",IF(T36="Outras_Despesas","Despesa",IF(T36="Imposto_de_Renda","Despesa",IF(T36="Investimentos_Bens","Despesa",""))))) | Q36: =IF(T36="Despesas_de_Moradia","Despesa",IF(T36="Despesas_com_Alimentacao","Despesa",IF(T36="Despesas_com_Saude","Despesa",""))) -> Despesa | R36: =IF(T36="Renda_Familiar","Receita",IF(T36="Receitas_com_Aplicacoes_Financeiras","Receita",IF(T36="Outras_Receitas","Receita",""))) | S36: =IF(P36<>"",P36,IF(Q36<>"",Q36,IF(R36<>"",R36,""))) -> Despesa | T36: =VLOOKUP(D36,'PC Receitas'!$N$4:$O$14,2,FALSE) -> Despesas_de_Moradia
C37: 5 | D37: DESPESAS COM LAZER E INFORMAÇÃO | E37: Presente | F37: - | G37: 3x | H37: Itaú | I37: 300 | J37: Não Pago | K37: =K36+IF(AND(J37="Pago",OR(D37=$V$5,D37=$V$6,D37=$V$7)),I37,IF(AND(J37="Pago",OR(D37=$V$8,D37=$V$9,D37=$V$10,D37=$V$11,D37=$V$12,D37=$V$13,D37=$V$14,D37=$V$15)),-I37,IF(G37="À Vista",IF(J37="Pago",-I37,0),0))) -> 25700 | P37: =IF(T37="Despesas_com_Transportes","Despesa",IF(T37="Despesas_com_Lazer_e_Informacao","Despesa",IF(T37="Outras_Despesas","Despesa",IF(T37="Imposto_de_Renda","Despesa",IF(T37="Investimentos_Bens","Despesa",""))))) -> Despesa | Q37: =IF(T37="Despesas_de_Moradia","Despesa",IF(T37="Despesas_com_Alimentacao","Despesa",IF(T37="Despesas_com_Saude","Despesa",""))) | R37: =IF(T37="Renda_Familiar","Receita",IF(T37="Receitas_com_Aplicacoes_Financeiras","Receita",IF(T37="Outras_Receitas","Receita",""))) | S37: =IF(P37<>"",P37,IF(Q37<>"",Q37,IF(R37<>"",R37,""))) -> Despesa | T37: =VLOOKUP(D37,'PC Receitas'!$N$4:$O$14,2,FALSE) -> Despesas_com_Lazer_e_Informacao
D38: RENDA FAMILIAR | E38: Minha empresa | F38: Pró-labore | G38: À Vista | H38: Mastercard | I38: 7000 | J38: Pago | K38: =K37+IF(AND(J38="Pago",OR(D38=$V$5,D38=$V$6,D38=$V$7)),I38,IF(AND(J38="Pago",OR(D38=$V$8,D38=$V$9,D38=$V$10,D38=$V$11,D38=$V$12,D38=$V$13,D38=$V$14,D38=$V$15)),-I38,IF(G38="À Vista",IF(J38="Pago",-I38,0),0))) -> 32700 | P38: =IF(T38="Despesas_com_Transportes","Despesa",IF(T38="Despesas_com_Lazer_e_Informacao","Despesa",IF(T38="Outras_Despesas","Despesa",IF(T38="Imposto_de_Renda","Despesa",IF(T38="Investimentos_Bens","Despesa",""))))) | Q38: =IF(T38="Despesas_de_Moradia","Despesa",IF(T38="Despesas_com_Alimentacao","Despesa",IF(T38="Despesas_com_Saude","Despesa",""))) | R38: =IF(T38="Renda_Familiar","Receita",IF(T38="Receitas_com_Aplicacoes_Financeiras","Receita",IF(T38="Outras_Receitas","Receita",""))) -> Receita | S38: =IF(P38<>"",P38,IF(Q38<>"",Q38,IF(R38<>"",R38,""))) -> Receita | T38: =VLOOKUP(D38,'PC Receitas'!$N$4:$O$14,2,FALSE) -> Renda_Familiar
D39: RENDA FAMILIAR | E39: Salário | F39: Salário da esposa | G39: À Vista | I39: 6000 | J39: Pago | K39: =K38+IF(AND(J39="Pago",OR(D39=$V$5,D39=$V$6,D39=$V$7)),I39,IF(AND(J39="Pago",OR(D39=$V$8,D39=$V$9,D39=$V$10,D39=$V$11,D39=$V$12,D39=$V$13,D39=$V$14,D39=$V$15)),-I39,IF(G39="À Vista",IF(J39="Pago",-I39,0),0))) -> 38700 | P39: =IF(T39="Despesas_com_Transportes","Despesa",IF(T39="Despesas_com_Lazer_e_Informacao","Despesa",IF(T39="Outras_Despesas","Despesa",IF(T39="Imposto_de_Renda","Despesa",IF(T39="Investimentos_Bens","Despesa",""))))) | Q39: =IF(T39="Despesas_de_Moradia","Despesa",IF(T39="Despesas_com_Alimentacao","Despesa",IF(T39="Despesas_com_Saude","Despesa",""))) | R39: =IF(T39="Renda_Familiar","Receita",IF(T39="Receitas_com_Aplicacoes_Financeiras","Receita",IF(T39="Outras_Receitas","Receita",""))) -> Receita | S39: =IF(P39<>"",P39,IF(Q39<>"",Q39,IF(R39<>"",R39,""))) -> Receita | T39: =VLOOKUP(D39,'PC Receitas'!$N$4:$O$14,2,FALSE) -> Renda_Familiar
K40: =K39+IF(AND(J40="Pago",OR(D40=$V$5,D40=$V$6,D40=$V$7)),I40,IF(AND(J40="Pago",OR(D40=$V$8,D40=$V$9,D40=$V$10,D40=$V$11,D40=$V$12,D40=$V$13,D40=$V$14,D40=$V$15)),-I40,IF(G40="À Vista",IF(J40="Pago",-I40,0),0))) -> 38700 | P40: =IF(T40="Despesas_com_Transportes","Despesa",IF(T40="Despesas_com_Lazer_e_Informacao","Despesa",IF(T40="Outras_Despesas","Despesa",IF(T40="Imposto_de_Renda","Despesa",IF(T40="Investimentos_Bens","Despesa",""))))) -> #N/A | Q40: =IF(T40="Despesas_de_Moradia","Despesa",IF(T40="Despesas_com_Alimentacao","Despesa",IF(T40="Despesas_com_Saude","Despesa",""))) -> #N/A | R40: =IF(T40="Renda_Familiar","Receita",IF(T40="Receitas_com_Aplicacoes_Financeiras","Receita",IF(T40="Outras_Receitas","Receita",""))) -> #N/A | S40: =IF(P40<>"",P40,IF(Q40<>"",Q40,IF(R40<>"",R40,""))) -> #N/A | T40: =VLOOKUP(D40,'PC Receitas'!$N$4:$O$14,2,FALSE) -> #N/A
K41: =K40+IF(AND(J41="Pago",OR(D41=$V$5,D41=$V$6,D41=$V$7)),I41,IF(AND(J41="Pago",OR(D41=$V$8,D41=$V$9,D41=$V$10,D41=$V$11,D41=$V$12,D41=$V$13,D41=$V$14,D41=$V$15)),-I41,IF(G41="À Vista",IF(J41="Pago",-I41,0),0))) -> 38700 | P41: =IF(T41="Despesas_com_Transportes","Despesa",IF(T41="Despesas_com_Lazer_e_Informacao","Despesa",IF(T41="Outras_Despesas","Despesa",IF(T41="Imposto_de_Renda","Despesa",IF(T41="Investimentos_Bens","Despesa",""))))) -> #N/A | Q41: =IF(T41="Despesas_de_Moradia","Despesa",IF(T41="Despesas_com_Alimentacao","Despesa",IF(T41="Despesas_com_Saude","Despesa",""))) -> #N/A | R41: =IF(T41="Renda_Familiar","Receita",IF(T41="Receitas_com_Aplicacoes_Financeiras","Receita",IF(T41="Outras_Receitas","Receita",""))) -> #N/A | S41: =IF(P41<>"",P41,IF(Q41<>"",Q41,IF(R41<>"",R41,""))) -> #N/A | T41: =VLOOKUP(D41,'PC Receitas'!$N$4:$O$14,2,FALSE) -> #N/A
K42: =K41+IF(AND(J42="Pago",OR(D42=$V$5,D42=$V$6,D42=$V$7)),I42,IF(AND(J42="Pago",OR(D42=$V$8,D42=$V$9,D42=$V$10,D42=$V$11,D42=$V$12,D42=$V$13,D42=$V$14,D42=$V$15)),-I42,IF(G42="À Vista",IF(J42="Pago",-I42,0),0))) -> 38700 | P42: =IF(T42="Despesas_com_Transportes","Despesa",IF(T42="Despesas_com_Lazer_e_Informacao","Despesa",IF(T42="Outras_Despesas","Despesa",IF(T42="Imposto_de_Renda","Despesa",IF(T42="Investimentos_Bens","Despesa",""))))) -> #N/A | Q42: =IF(T42="Despesas_de_Moradia","Despesa",IF(T42="Despesas_com_Alimentacao","Despesa",IF(T42="Despesas_com_Saude","Despesa",""))) -> #N/A | R42: =IF(T42="Renda_Familiar","Receita",IF(T42="Receitas_com_Aplicacoes_Financeiras","Receita",IF(T42="Outras_Receitas","Receita",""))) -> #N/A | S42: =IF(P42<>"",P42,IF(Q42<>"",Q42,IF(R42<>"",R42,""))) -> #N/A | T42: =VLOOKUP(D42,'PC Receitas'!$N$4:$O$14,2,FALSE) -> #N/A
...

Sheet Fev
A1: 3.0.1 | C1: 2. LANÇAMENTOS: FEV
C4: Dia | D4: Classificação | E4: Item | F4: Grupo de Contas | G4: Forma de Pgt | H4: Banco | I4: Valor | J4: Status | K4: Saldo | M4: Resumo Geral
D5: Faturas de Cartão | E5: - | F5: =D5 -> Faturas de Cartão | G5: À Vista | H5: =W5 -> Mastercard | I5: ='Resumo (3)'!F7 -> 100 | K5: =N5-IF(J5="pago",I5,0) -> 38700 | M5: Saldo de Janeiro | N5: =Jan!N13 -> 38700 | P5: =IF(T5="Despesas_com_Transportes","Despesa",IF(T5="Despesas_com_Lazer_e_Informacao","Despesa",IF(T5="Outras_Despesas","Despesa",IF(T5="Imposto_de_Renda","Despesa",IF(T5="Investimentos_Bens","Despesa",""))))) | Q5: =IF(T5="Despesas_de_Moradia","Despesa",IF(T5="Despesas_com_Alimentacao","Despesa",IF(T5="Despesas_com_Saude","Despesa",""))) | R5: =IF(T5="Renda_Familiar","Receita",IF(T5="Receitas_com_Aplicacoes_Financeiras","Receita",IF(T5="Outras_Receitas","Receita",""))) | S5: Despesa | V5: ='PC Receitas'!D4 -> RENDA FAMILIAR | W5: ='Bancos e Cartões'!D7 -> Mastercard | X5: À Vista
C6: 1 | D6: Faturas de Cartão | E6: - | F6: =D6 -> Faturas de Cartão | G6: À Vista | H6: =W6 -> Itaú | I6: ='Resumo (3)'!F8 -> 300 | J6: Pago | K6: =K5-IF(J6="pago",I6,0) -> 38400 | P6: =IF(T6="Despesas_com_Transportes","Despesa",IF(T6="Despesas_com_Lazer_e_Informacao","Despesa",IF(T6="Outras_Despesas","Despesa",IF(T6="Imposto_de_Renda","Despesa",IF(T6="Investimentos_Bens","Despesa",""))))) | Q6: =IF(T6="Despesas_de_Moradia","Despesa",IF(T6="Despesas_com_Alimentacao","Despesa",IF(T6="Despesas_com_Saude","Despesa",""))) | R6: =IF(T6="Renda_Familiar","Receita",IF(T6="Receitas_com_Aplicacoes_Financeiras","Receita",IF(T6="Outras_Receitas","Receita",""))) | S6: Despesa | V6: ='PC Receitas'!G4 -> RECEITAS COM APLICAÇÕES FINANCEIRAS | W6: ='Bancos e Cartões'!D8 -> Itaú | X6: Crédito
D7: Faturas de Cartão | E7: - | F7: =D7 -> Faturas de Cartão | G7: À Vista | H7: =W7 -> Caixinha | I7: ='Resumo (3)'!F9 -> 0 | K7: =K6-IF(J7="pago",I7,0) -> 38400 | M7: Total de Receitas | N7: =SUMIFS($I$5:$I$619,$S$5:$S$619,"Receita",$J$5:$J$619,"Pago",$G$5:$G$619,"À Vista") -> 39000 | P7: =IF(T7="Despesas_com_Transportes","Despesa",IF(T7="Despesas_com_Lazer_e_Informacao","Despesa",IF(T7="Outras_Despesas","Despesa",IF(T7="Imposto_de_Renda","Despesa",IF(T7="Investimentos_Bens","Despesa",""))))) | Q7: =IF(T7="Despesas_de_Moradia","Despesa",IF(T7="Despesas_com_Alimentacao","Despesa",IF(T7="Despesas_com_Saude","Despesa",""))) | R7: =IF(T7="Renda_Familiar","Receita",IF(T7="Receitas_com_Aplicacoes_Financeiras","Receita",IF(T7="Outras_Receitas","Receita",""))) | S7: Despesa | V7: ='PC Receitas'!J4 -> OUTRAS RECEITAS | W7: ='Bancos e Cartões'!D9 -> Caixinha | X7: 2x
D8: Faturas de Cartão | E8: - | F8: =D8 -> Faturas de Cartão | G8: À Vista | H8: =W8 -> - | I8: ='Resumo (3)'!F10 -> 0 | K8: =K7-IF(J8="pago",I8,0) -> 38400 | P8: =IF(T8="Despesas_com_Transportes","Despesa",IF(T8="Despesas_com_Lazer_e_Informacao","Despesa",IF(T8="Outras_Despesas","Despesa",IF(T8="Imposto_de_Renda","Despesa",IF(T8="Investimentos_Bens","Despesa",""))))) | Q8: =IF(T8="Despesas_de_Moradia","Despesa",IF(T8="Despesas_com_Alimentacao","Despesa",IF(T8="Despesas_com_Saude","Despesa",""))) | R8: =IF(T8="Renda_Familiar","Receita",IF(T8="Receitas_com_Aplicacoes_Financeiras","Receita",IF(T8="Outras_Receitas","Receita",""))) | S8: Despesa | V8: ='PC Despesas'!D4 -> DESPESA DE MORADIA | W8: ='Bancos e Cartões'!D10 -> - | X8: 3x
D9: Faturas de Cartão | E9: - | F9: =D9 -> Faturas de Cartão | G9: À Vista | H9: =W9 -> - | I9: ='Resumo (3)'!F11 -> 0 | K9: =K8-IF(J9="pago",I9,0) -> 38400 | M9: Total de Despesas | N9: =SUMIFS($I$5:$I$619,$S$5:$S$619,"Despesa",$J$5:$J$619,"Pago",$G$5:$G$619,"À Vista") -> 2100 | P9: =IF(T9="Despesas_com_Transportes","Despesa",IF(T9="Despesas_com_Lazer_e_Informacao","Despesa",IF(T9="Outras_Despesas","Despesa",IF(T9="Imposto_de_Renda","Despesa",IF(T9="Investimentos_Bens","Despesa",""))))) | Q9: =IF(T9="Despesas_de_Moradia","Despesa",IF(T9="Despesas_com_Alimentacao","Despesa",IF(T9="Despesas_com_Saude","Despesa",""))) | R9: =IF(T9="Renda_Familiar","Receita",IF(T9="Receitas_com_Aplicacoes_Financeiras","Receita",IF(T9="Outras_Receitas","Receita",""))) | S9: Despesa | V9: ='PC Despesas'!G4 -> DESPESAS COM ALIMENTAÇÃO | W9: ='Bancos e Cartões'!D11 -> - | X9: 4x
D10: Faturas de Cartão | E10: - | F10: =D10 -> Faturas de Cartão | G10: À Vista | H10: =W10 -> - | I10: ='Resumo (3)'!F12 -> 0 | K10: =K9-IF(J10="pago",I10,0) -> 38400 | P10: =IF(T10="Despesas_com_Transportes","Despesa",IF(T10="Despesas_com_Lazer_e_Informacao","Despesa",IF(T10="Outras_Despesas","Despesa",IF(T10="Imposto_de_Renda","Despesa",IF(T10="Investimentos_Bens","Despesa",""))))) | Q10: =IF(T10="Despesas_de_Moradia","Despesa",IF(T10="Despesas_com_Alimentacao","Despesa",IF(T10="Despesas_com_Saude","Despesa",""))) | R10: =IF(T10="Renda_Familiar","Receita",IF(T10="Receitas_com_Aplicacoes_Financeiras","Receita",IF(T10="Outras_Receitas","Receita",""))) | S10: Despesa | V10: ='PC Despesas'!J4 -> DESPESAS COM SAÚDE | W10: ='Bancos e Cartões'!D12 -> - | X10: 5x
D11: Faturas de Cartão | E11: - | F11: =D11 -> Faturas de Cartão | G11: À Vista | H11: =W11 -> - | I11: ='Resumo (3)'!F13 -> 0 | K11: =K10-IF(J11="pago",I11,0) -> 38400 | M11: Resultado do Mês | N11: =N7-N9 -> 36900 | P11: =IF(T11="Despesas_com_Transportes","Despesa",IF(T11="Despesas_com_Lazer_e_Informacao","Despesa",IF(T11="Outras_Despesas","Despesa",IF(T11="Imposto_de_Renda","Despesa",IF(T11="Investimentos_Bens","Despesa",""))))) | Q11: =IF(T11="Despesas_de_Moradia","Despesa",IF(T11="Despesas_com_Alimentacao","Despesa",IF(T11="Despesas_com_Saude","Despesa",""))) | R11: =IF(T11="Renda_Familiar","Receita",IF(T11="Receitas_com_Aplicacoes_Financeiras","Receita",IF(T11="Outras_Receitas","Receita",""))) | S11: Despesa | V11: ='PC Despesas'!M4 -> DESPESAS COM TRANSPORTES | W11: ='Bancos e Cartões'!D13 -> - | X11: 6x
D12: Faturas de Cartão | E12: - | F12: =D12 -> Faturas de Cartão | G12: À Vista | H12: =W12 -> - | I12: ='Resumo (3)'!F14 -> 0 | K12: =K11-IF(J12="pago",I12,0) -> 38400 | P12: =IF(T12="Despesas_com_Transportes","Despesa",IF(T12="Despesas_com_Lazer_e_Informacao","Despesa",IF(T12="Outras_Despesas","Despesa",IF(T12="Imposto_de_Renda","Despesa",IF(T12="Investimentos_Bens","Despesa",""))))) | Q12: =IF(T12="Despesas_de_Moradia","Despesa",IF(T12="Despesas_com_Alimentacao","Despesa",IF(T12="Despesas_com_Saude","Despesa",""))) | R12: =IF(T12="Renda_Familiar","Receita",IF(T12="Receitas_com_Aplicacoes_Financeiras","Receita",IF(T12="Outras_Receitas","Receita",""))) | S12: Despesa | V12: ='PC Despesas'!P4 -> DESPESAS COM LAZER E INFORMAÇÃO | W12: ='Bancos e Cartões'!D14 -> - | X12: 7x
D13: Faturas de Cartão | E13: - | F13: =D13 -> Faturas de Cartão | G13: À Vista | H13: =W13 -> - | I13: ='Resumo (3)'!F15 -> 0 | K13: =K12-IF(J13="pago",I13,0) -> 38400 | M13: Acumulado | N13: =K619 -> 75600 | P13: =IF(T13="Despesas_com_Transportes","Despesa",IF(T13="Despesas_com_Lazer_e_Informacao","Despesa",IF(T13="Outras_Despesas","Despesa",IF(T13="Imposto_de_Renda","Despesa",IF(T13="Investimentos_Bens","Despesa",""))))) | Q13: =IF(T13="Despesas_de_Moradia","Despesa",IF(T13="Despesas_com_Alimentacao","Despesa",IF(T13="Despesas_com_Saude","Despesa",""))) | R13: =IF(T13="Renda_Familiar","Receita",IF(T13="Receitas_com_Aplicacoes_Financeiras","Receita",IF(T13="Outras_Receitas","Receita",""))) | S13: Despesa | V13: ='PC Despesas'!S4 -> OUTRAS DESPESAS | W13: ='Bancos e Cartões'!D15 -> - | X13: 8x
D14: Faturas de Cartão | E14: - | F14: =D14 -> Faturas de Cartão | G14: À Vista | H14: =W14 -> - | I14: ='Resumo (3)'!F16 -> 0 | K14: =K13-IF(J14="pago",I14,0) -> 38400 | P14: =IF(T14="Despesas_com_Transportes","Despesa",IF(T14="Despesas_com_Lazer_e_Informacao","Despesa",IF(T14="Outras_Despesas","Despesa",IF(T14="Imposto_de_Renda","Despesa",IF(T14="Investimentos_Bens","Despesa",""))))) | Q14: =IF(T14="Despesas_de_Moradia","Despesa",IF(T14="Despesas_com_Alimentacao","Despesa",IF(T14="Despesas_com_Saude","Despesa",""))) | R14: =IF(T14="Renda_Familiar","Receita",IF(T14="Receitas_com_Aplicacoes_Financeiras","Receita",IF(T14="Outras_Receitas","Receita",""))) | S14: Despesa | V14: ='PC Despesas'!V4 -> IMPOSTO DE RENDA | W14: ='Bancos e Cartões'!D16 -> - | X14: 9x
D15: Faturas de Cartão | E15: - | F15: =D15 -> Faturas de Cartão | G15: À Vista | H15: =W15 -> - | I15: ='Resumo (3)'!F17 -> 0 | K15: =K14-IF(J15="pago",I15,0) -> 38400 | P15: =IF(T15="Despesas_com_Transportes","Despesa",IF(T15="Despesas_com_Lazer_e_Informacao","Despesa",IF(T15="Outras_Despesas","Despesa",IF(T15="Imposto_de_Renda","Despesa",IF(T15="Investimentos_Bens","Despesa",""))))) | Q15: =IF(T15="Despesas_de_Moradia","Despesa",IF(T15="Despesas_com_Alimentacao","Despesa",IF(T15="Despesas_com_Saude","Despesa",""))) | R15: =IF(T15="Renda_Familiar","Receita",IF(T15="Receitas_com_Aplicacoes_Financeiras","Receita",IF(T15="Outras_Receitas","Receita",""))) | S15: Despesa | V15: ='PC Despesas'!Y4 -> INVESTIMENTOS (BENS) | W15: ='Bancos e Cartões'!D17 -> - | X15: 10x
D16: Faturas de Cartão | E16: - | F16: =D16 -> Faturas de Cartão | G16: À Vista | H16: =W16 -> - | I16: ='Resumo (3)'!F18 -> 0 | K16: =K15-IF(J16="pago",I16,0) -> 38400 | P16: =IF(T16="Despesas_com_Transportes","Despesa",IF(T16="Despesas_com_Lazer_e_Informacao","Despesa",IF(T16="Outras_Despesas","Despesa",IF(T16="Imposto_de_Renda","Despesa",IF(T16="Investimentos_Bens","Despesa",""))))) | Q16: =IF(T16="Despesas_de_Moradia","Despesa",IF(T16="Despesas_com_Alimentacao","Despesa",IF(T16="Despesas_com_Saude","Despesa",""))) | R16: =IF(T16="Renda_Familiar","Receita",IF(T16="Receitas_com_Aplicacoes_Financeiras","Receita",IF(T16="Outras_Receitas","Receita",""))) | S16: Despesa | W16: ='Bancos e Cartões'!D18 -> - | X16: 11x
D17: Faturas de Cartão | E17: - | F17: =D17 -> Faturas de Cartão | G17: À Vista | H17: =W17 -> - | I17: ='Resumo (3)'!F19 -> 0 | K17: =K16-IF(J17="pago",I17,0) -> 38400 | P17: =IF(T17="Despesas_com_Transportes","Despesa",IF(T17="Despesas_com_Lazer_e_Informacao","Despesa",IF(T17="Outras_Despesas","Despesa",IF(T17="Imposto_de_Renda","Despesa",IF(T17="Investimentos_Bens","Despesa",""))))) | Q17: =IF(T17="Despesas_de_Moradia","Despesa",IF(T17="Despesas_com_Alimentacao","Despesa",IF(T17="Despesas_com_Saude","Despesa",""))) | R17: =IF(T17="Renda_Familiar","Receita",IF(T17="Receitas_com_Aplicacoes_Financeiras","Receita",IF(T17="Outras_Receitas","Receita",""))) | S17: Despesa | W17: ='Bancos e Cartões'!D19 -> - | X17: 12x
D18: Faturas de Cartão | E18: - | F18: =D18 -> Faturas de Cartão | G18: À Vista | H18: =W18 -> - | I18: ='Resumo (3)'!F20 -> 0 | K18: =K17-IF(J18="pago",I18,0) -> 38400 | P18: =IF(T18="Despesas_com_Transportes","Despesa",IF(T18="Despesas_com_Lazer_e_Informacao","Despesa",IF(T18="Outras_Despesas","Despesa",IF(T18="Imposto_de_Renda","Despesa",IF(T18="Investimentos_Bens","Despesa",""))))) | Q18: =IF(T18="Despesas_de_Moradia","Despesa",IF(T18="Despesas_com_Alimentacao","Despesa",IF(T18="Despesas_com_Saude","Despesa",""))) | R18: =IF(T18="Renda_Familiar","Receita",IF(T18="Receitas_com_Aplicacoes_Financeiras","Receita",IF(T18="Outras_Receitas","Receita",""))) | S18: Despesa | W18: ='Bancos e Cartões'!D20 -> -
C19: 2 | D19: DESPESA DE MORADIA | E19: Luzes | F19: Manutenção | G19: À Vista | H19: Mastercard | I19: 100 | J19: Pago | K19: =K18+IF(AND(J19="Pago",OR(D19=$V$5,D19=$V$6,D19=$V$7)),I19,IF(AND(J19="Pago",OR(D19=$V$8,D19=$V$9,D19=$V$10,D19=$V$11,D19=$V$12,D19=$V$13,D19=$V$14,D19=$V$15)),-I19,IF(G19="À Vista",IF(J19="Pago",-I19,0),0))) -> 38300 | P19: =IF(T19="Despesas_com_Transportes","Despesa",IF(T19="Despesas_com_Lazer_e_Informacao","Despesa",IF(T19="Outras_Despesas","Despesa",IF(T19="Imposto_de_Renda","Despesa",IF(T19="Investimentos_Bens","Despesa",""))))) | Q19: =IF(T19="Despesas_de_Moradia","Despesa",IF(T19="Despesas_com_Alimentacao","Despesa",IF(T19="Despesas_com_Saude","Despesa",""))) -> Despesa | R19: =IF(T19="Renda_Familiar","Receita",IF(T19="Receitas_com_Aplicacoes_Financeiras","Receita",IF(T19="Outras_Receitas","Receita",""))) | S19: =IF(P19<>"",P19,IF(Q19<>"",Q19,IF(R19<>"",R19,""))) -> Despesa | T19: =VLOOKUP(D19,'PC Receitas'!$N$4:$O$14,2,FALSE) -> Despesas_de_Moradia
C20: 3 | D20: DESPESA DE MORADIA | E20: Água | F20: Manutenção | G20: À Vista | H20: Mastercard | I20: 150 | J20: Pago | K20: =K19+IF(AND(J20="Pago",OR(D20=$V$5,D20=$V$6,D20=$V$7)),I20,IF(AND(J20="Pago",OR(D20=$V$8,D20=$V$9,D20=$V$10,D20=$V$11,D20=$V$12,D20=$V$13,D20=$V$14,D20=$V$15)),-I20,IF(G20="À Vista",IF(J20="Pago",-I20,0),0))) -> 38150 | P20: =IF(T20="Despesas_com_Transportes","Despesa",IF(T20="Despesas_com_Lazer_e_Informacao","Despesa",IF(T20="Outras_Despesas","Despesa",IF(T20="Imposto_de_Renda","Despesa",IF(T20="Investimentos_Bens","Despesa",""))))) | Q20: =IF(T20="Despesas_de_Moradia","Despesa",IF(T20="Despesas_com_Alimentacao","Despesa",IF(T20="Despesas_com_Saude","Despesa",""))) -> Despesa | R20: =IF(T20="Renda_Familiar","Receita",IF(T20="Receitas_com_Aplicacoes_Financeiras","Receita",IF(T20="Outras_Receitas","Receita",""))) | S20: =IF(P20<>"",P20,IF(Q20<>"",Q20,IF(R20<>"",R20,""))) -> Despesa | T20: =VLOOKUP(D20,'PC Receitas'!$N$4:$O$14,2,FALSE) -> Despesas_de_Moradia
C21: 3 | D21: DESPESA DE MORADIA | E21: Net | F21: Manutenção | G21: À Vista | H21: Mastercard | I21: 200 | J21: Pago | K21: =K20+IF(AND(J21="Pago",OR(D21=$V$5,D21=$V$6,D21=$V$7)),I21,IF(AND(J21="Pago",OR(D21=$V$8,D21=$V$9,D21=$V$10,D21=$V$11,D21=$V$12,D21=$V$13,D21=$V$14,D21=$V$15)),-I21,IF(G21="À Vista",IF(J21="Pago",-I21,0),0))) -> 37950 | P21: =IF(T21="Despesas_com_Transportes","Despesa",IF(T21="Despesas_com_Lazer_e_Informacao","Despesa",IF(T21="Outras_Despesas","Despesa",IF(T21="Imposto_de_Renda","Despesa",IF(T21="Investimentos_Bens","Despesa",""))))) | Q21: =IF(T21="Despesas_de_Moradia","Despesa",IF(T21="Despesas_com_Alimentacao","Despesa",IF(T21="Despesas_com_Saude","Despesa",""))) -> Despesa | R21: =IF(T21="Renda_Familiar","Receita",IF(T21="Receitas_com_Aplicacoes_Financeiras","Receita",IF(T21="Outras_Receitas","Receita",""))) | S21: =IF(P21<>"",P21,IF(Q21<>"",Q21,IF(R21<>"",R21,""))) -> Despesa | T21: =VLOOKUP(D21,'PC Receitas'!$N$4:$O$14,2,FALSE) -> Despesas_de_Moradia
C22: 2 | D22: DESPESA DE MORADIA | E22: Luzes | F22: Manutenção | G22: À Vista | H22: Mastercard | I22: 100 | J22: Pago | K22: =K21+IF(AND(J22="Pago",OR(D22=$V$5,D22=$V$6,D22=$V$7)),I22,IF(AND(J22="Pago",OR(D22=$V$8,D22=$V$9,D22=$V$10,D22=$V$11,D22=$V$12,D22=$V$13,D22=$V$14,D22=$V$15)),-I22,IF(G22="À Vista",IF(J22="Pago",-I22,0),0))) -> 37850 | P22: =IF(T22="Despesas_com_Transportes","Despesa",IF(T22="Despesas_com_Lazer_e_Informacao","Despesa",IF(T22="Outras_Despesas","Despesa",IF(T22="Imposto_de_Renda","Despesa",IF(T22="Investimentos_Bens","Despesa",""))))) | Q22: =IF(T22="Despesas_de_Moradia","Despesa",IF(T22="Despesas_com_Alimentacao","Despesa",IF(T22="Despesas_com_Saude","Despesa",""))) -> Despesa | R22: =IF(T22="Renda_Familiar","Receita",IF(T22="Receitas_com_Aplicacoes_Financeiras","Receita",IF(T22="Outras_Receitas","Receita",""))) | S22: =IF(P22<>"",P22,IF(Q22<>"",Q22,IF(R22<>"",R22,""))) -> Despesa | T22: =VLOOKUP(D22,'PC Receitas'!$N$4:$O$14,2,FALSE) -> Despesas_de_Moradia
