Workbook

Sheet Calculadora do PIS-Anterior
B2: Contabes
F3: PLANILHA DE CÁLCULO DO PIS NÃO CUMULATIVO
F4: ALÍQUOTA DE 1,65% - PESSOAS JURÍDICAS TRIBUTADAS COM BASE NO LUCRO REAL
B7: Empresa: | G7: Mês / Ano:
E10: DISCRIMINAÇÕES
E12: FATURAMENTO / RECEITA BRUTA - ART. 1º DA LEI Nº 10.537/2002 | H12: VALORES EM R$
B14: RECEITAS | D14: 1 | E14: (+) | F14: Faturamento Mensal (Receita Bruta Total do Mês)
D15: 2 | E15: (+) | F15: Rendimentos de Aplicações Financeiras e de Renda Fixa
D16: 3 | E16: (+) | F16: Ganhos de Aplicações de Rend Variável
D17: 4 | E17: (+) | F17: Juros Ativos
D18: 5 | E18: (+) | F18: Receita de Aluguéis
D19: 6 | E19: (+) | F19: Outras Receitas Financeira
D20: 7 | E20: (+) | F20: Outras Receitas Operacionais
D21: 8 | E21: (+) | F21: Receitas Não Operacionais (Vendas de Bens do Ativo Permanente / Ganhos de Capitais)
D23: 9 | E23: (=) | F23: Total da Receita Bruta | H23: =SUM(H14:H21) -> 0
E25: EXCLUSÕES DA BASE DE CÁLCULO - ART. 1º DA LEI Nº 10.637/2002 | H25: VALORES EM R$
B27: EXCLUSÕES | D27: 10 | E27: (-) | F27: Receitas Sujeitas a Alíquota Zero
D28: 11 | E28: (-) | F28: Receitas Sujeitas a Substituição Tributária
D29: 12 | E29: (-) | F29: Receitas Sujeitas ao Regime Monofásico
D30: 13 | E30: (-) | F30: Vendas Canceladas
D31: 14 | E31: (-) | F31: Descontos Incondicionais Concedidos
D32: 15 | E32: (-) | F32: Reversão de Provisões
D33: 16 | E33: (-) | F33: Recuperação de Créditos Baixados Como Perdas
D34: 17 | E34: (-) | F34: Resultado Positivo de Equivalência Patrimonial
D35: 18 | E35: (-) | F35: Dividendos Receb. de Investimentos Avaliados pelo Custo de Aquisição do Ativo Imobilizado
D37: 19 | E37: (=) | F37: Total das Exclusões | H37: =SUM(H27:H35) -> 0
E39: ISENÇÕES | H39: VALORES EM R$
B41: ISENÇÕES | D41: 20 | E41: (-) | F41: Receitas de Exportação para o Exterior
D42: 21 | E42: (-) | F42: Receitas Prest. Serviços PF/PJ domiciliadas Exterior c/recebimento em Moeda Estrangeira
D43: 22 | E43: (-) | F43: Receitas de Vendas para Empresa Comercial Exportadora
D45: 23 | E45: (=) | F45: Total das Isenções | H45: =SUM(H41:H43) -> 0
D47: 24 | E47: (=) | F47: BASE DE CÁLCULO DO PIS/PASEP NÃO CUMULATIVO | H47: =H23-H37-H45 -> 0
D49: 25 | E49: (=) | F49: PIS/PASEP DEVIDO = BASE DE CÁLCULO X 1,65% | H49: =H47*1.65% -> 0
E51: CRÉDITOS DO PIS - ART. 3º DA LEI Nº 10.637/2002 | G51: VALORES EM R$ | H51: VALORES EM R$
B53: CRÉDITOS | D53: 26 | E53: (-) | F53: Mercadorias Adquiridas para Revenda | H53: =G53*1.65% -> 0
D54: 27 | E54: (-) | F54: Bens e Serviços Utilizados com Insumos na Fabricação | H54: =G54*1.65% -> 0
D55: 28 | E55: (-) | F55: Bens e Serviços Utilizados com Insumos na Fabricação | H55: =G55*1.65% -> 0
D56: 29 | E56: (-) | F56: Alugéis Pagos a PJ (prédios, máquinas e equipamentos) | H56: =G56*1.65% -> 0
D57: 30 | E57: (-) | F57: Despesas Financeiras de Empréstimos e Financiamentos de PJ | H57: =G57*1.65% -> 0
D58: 31 | E58: (-) | F58: Encargos de Depreciações do Ativo Imobilizado | H58: =G58*1.65% -> 0
...

Sheet Abertura
F3: Prezado Colega Contabilista:
F5: Bem vindo à Planilha de Cálculos do PIS e COFINS Não Cumulativos
F6: Lei Nº 10.833/2003
F7: Mensagem:
F8: Este trabalho foi executado com a finalidade de colaborar
F9: com a classe contabil, em uma parceria entre
F10: ASCOL - Associação dos Contabilistas de Linhares
F11: e CONTABES (João Batista - Contabilidade)
F13: Qualquer comentário, dúvidas ou sugestões
F14: poderão ser encaminhados para:
F15: joaobatista@joaobatista.com.br
F16: ou acessar
... F27: Insira os dados nos campos sombreados das tabelas

Sheet Calculadora da COFINS
B2: Contabes
F3: PLANILHA DE CÁLCULO DA COFINS NÃO CUMULATIVA
F4: ALÍQUOTA DE 7,6% - PESSOAS JURÍDICAS TRIBUTADAS COM BASE NO LUCRO REAL
B7: Ref. Empresa: | G7: Dia/Mês/Ano:
D8: CNPJ Nº :
E11: DISCRIMINAÇÕES
E13: FATURAMENTO / RECEITA BRUTA - ART. 1º DA LEI Nº 10.833/2003 | H13: VALORES EM R$
B15: RECEITAS | D15: 1 | E15: (+) | F15: Faturamento Mensal (Receita Bruta Total do Mês) | H15: 1305000
D16: 2 | E16: (+) | F16: Rendimentos de Aplicações Financeiras e de Renda Fixa
D17: 3 | E17: (+) | F17: Ganhos de Aplicações de Renda Variável
D18: 4 | E18: (+) | F18: Juros Ativos | H18: 5000
D19: 5 | E19: (+) | F19: Receita de Aluguéis
D20: 6 | E20: (+) | F20: Outras Receitas Financeiras | H20: 2300
D21: 7 | E21: (+) | F21: Outras Receitas Operacionais
D22: 8 | E22: (+) | F22: Receitas Não Operacionais (Vendas de Bens do Ativo Permanente / Ganhos de Capitais)
D24: 9 | E24: (=) | F24: Total da Receita Bruta | H24: =SUM(H15:H22) -> 1312300
E26: EXCLUSÕES DA BASE DE CÁLCULO - ART. 1º DA LEI Nº 10.833/2003 | H26: VALORES EM R$
B28: EXCLUSÕES | D28: 10 | E28: (-) | F28: Receitas Sujeitas a Alíquota Zero
D29: 11 | E29: (-) | F29: Receitas Sujeitas a Substituição Tributária
D30: 12 | E30: (-) | F30: Receitas Sujeitas ao Regime Monofásico
D31: 13 | E31: (-) | F31: Vendas Canceladas | H31: 1400
D32: 14 | E32: (-) | F32: Descontos Incondicionais Concedidos
D33: 15 | E33: (-) | F33: Reversão de Provisões
D34: 16 | E34: (-) | F34: Recuperação de Créditos Baixados Como Perdas
D35: 17 | E35: (-) | F35: Resultado Positivo de Equivalência Patrimonial
D36: 18 | E36: (-) | F36: Lucros e Dividendos Recebidos
D37: 19 | E37: (-) | F37: Receitas de Vendas do Ativo Permanente Avaliados pelo Custo de Aquisição | H37: 18500
D39: 20 | E39: (=) | F39: Total das Exclusões | H39: =SUM(H28:H37) -> 19900
E41: ISENÇÕES | H41: VALORES EM R$
B43: ISENÇÕES | D43: 21 | E43: (-) | F43: Receitas de Exportação para o Exterior
D44: 22 | E44: (-) | F44: Receitas Prest. Serviços PF/PJ domiciliadas Exterior c/recebimento em Moeda Estrangeira
D45: 23 | E45: (-) | F45: Receitas de Vendas para Empresa Comercial Exportadora | H45: 15000
D47: 24 | E47: (=) | F47: Total das Isenções | H47: =SUM(H43:H45) -> 15000
D49: 25 | E49: (=) | F49: BASE DE CÁLCULO DA COFINS NÃO CUMULATIVA | H49: =H24-H39-H47 -> 1277400
D51: 26 | E51: (=) | F51: COFINS DEVIDA = BASE DE CÁLCULO X 7,6% | H51: =H49*7.6% -> 97082.4
E53: CRÉDITOS DA COFINS - ART. 3º DA LEI Nº 10.833/2003 | G53: VALORES EM R$ | H53: VALORES EM R$
B55: CRÉDITOS | D55: 27 | E55: (-) | F55: Mercadorias Adquiridas para Revenda | G55: 100000 | H55: =G55*7.6% -> 7600
D56: 28 | E56: (-) | F56: Bens e Serviços Utilizados como Insumos na Produção / Fabricação | G56: 930000 | H56: =G56*7.6% -> 70680
D57: 29 | E57: (-) | F57: Bens e Serviços Utilizados como Insumos na Prestação de Serviços | G57: 10000 | H57: =G57*7.6% -> 760
D58: 30 | E58: (-) | F58: Energia Elétrica Consumida nos Estabelecimentos da Pessoa Jurídica | G58: 10000 | H58: =G58*7.6% -> 760
...

Sheet Calculadora do PIS
B2: Contabes
F3: PLANILHA DE CÁLCULO DO PIS NÃO CUMULATIVO
F4: ALÍQUOTA DE 1,65% - PESSOAS JURÍDICAS TRIBUTADAS COM BASE NO LUCRO REAL
B7: Ref. Empresa: | G7: Dia/Mês/Ano:
D8: CNPJ Nº : | G8: Telefone Nº:
E11: DISCRIMINAÇÕES
E13: FATURAMENTO / RECEITA BRUTA - ART. 1º DA LEI Nº 10.637/2002 | H13: VALORES EM R$
B15: RECEITAS | D15: 1 | E15: (+) | F15: Faturamento Mensal (Receita Bruta Total do Mês)
D16: 2 | E16: (+) | F16: Rendimentos de Aplicações Financeiras e de Renda Fixa
D17: 3 | E17: (+) | F17: Ganhos de Aplicações de Renda Variável
D18: 4 | E18: (+) | F18: Juros Ativos
D19: 5 | E19: (+) | F19: Receita de Aluguéis
D20: 6 | E20: (+) | F20: Outras Receitas Financeiras
D21: 7 | E21: (+) | F21: Outras Receitas Operacionais
D22: 8 | E22: (+) | F22: Receitas Não Operacionais (Vendas de Bens do Ativo Permanente / Ganhos de Capitais)
D24: 9 | E24: (=) | F24: Total da Receita Bruta | H24: =SUM(H15:H22) -> 0
E26: EXCLUSÕES DA BASE DE CÁLCULO - ART. 1º DA LEI Nº 10.637/2002 | H26: VALORES EM R$
B28: EXCLUSÕES | D28: 10 | E28: (-) | F28: Receitas Sujeitas a Alíquota Zero
D29: 11 | E29: (-) | F29: Receitas Sujeitas a Substituição Tributária
D30: 12 | E30: (-) | F30: Receitas Sujeitas ao Regime Monofásico
D31: 13 | E31: (-) | F31: Vendas Canceladas
D32: 14 | E32: (-) | F32: Descontos Incondicionais Concedidos
D33: 15 | E33: (-) | F33: Reversão de Provisões
D34: 16 | E34: (-) | F34: Recuperação de Créditos Baixados Como Perdas
D35: 17 | E35: (-) | F35: Resultado Positivo de Equivalência Patrimonial
D36: 18 | E36: (-) | F36: Lucros e Dividendos Recebidos
D37: 19 | E37: (-) | F37: Receitas de Vendas do Ativo Permanente Avaliados pelo Custo de Aquisição
D39: 20 | E39: (=) | F39: Total das Exclusões | H39: =SUM(H28:H37) -> 0
E41: ISENÇÕES | H41: VALORES EM R$
B43: ISENÇÕES | D43: 21 | E43: (-) | F43: Receitas de Exportação para o Exterior
D44: 22 | E44: (-) | F44: Receitas Prest. Serviços PF/PJ domiciliadas Exterior c/recebimento em Moeda Estrangeira
D45: 23 | E45: (-) | F45: Receitas de Vendas para Empresa Comercial Exportadora
D47: 24 | E47: (=) | F47: Total das Isenções | H47: =SUM(H43:H45) -> 0
D49: 25 | E49: (=) | F49: BASE DE CÁLCULO DO PIS NÃO CUMULATIVO | H49: =H24-H39-H47 -> 0
D51: 26 | E51: (=) | F51: PIS DEVIDO = BASE DE CÁLCULO X 1,65% | H51: =H49*1.65% -> 0
E53: CRÉDITOS DO PIS - ART. 3º DA LEI Nº 10.637/2002 | G53: VALORES EM R$ | H53: VALORES EM R$
B55: CRÉDITOS | D55: 27 | E55: (-) | F55: Mercadorias Adquiridas para Revenda | H55: =G55*1.65% -> 0
D56: 28 | E56: (-) | F56: Bens e Serviços Utilizados como Insumos na Produção / Fabricação | H56: =G56*1.65% -> 0
D57: 29 | E57: (-) | F57: Bens e Serviços Utilizados como Insumos na Prestação de Serviços | H57: =G57*1.65% -> 0
D58: 30 | E58: (-) | F58: Energia Elétrica Consumida nos Estabelecimentos da Pessoa Jurídica | H58: =G58*1.65% -> 0
...

Sheet DARF - COFINS
B2: DARF - COFINS Não Cumulativa - Código: 5856
D6: 02 | E6: PERÍODO DE APURAÇÃO | G6: ='Calculadora da COFINS'!H7 -> 0
C7: MINISTÉRIO DA FAZENDA | F7: 
C8: SECRETARIA DA RECEITA FEDERAL
C9: Documento de Arrecadação de Receitas Federais | D9: 03 | E9: NÚMERO DO CPF OU CNPJ | G9: ='Calculadora da COFINS'!F8 -> 0
F10: 
C11: DARF
D12: 04 | E12: CÓDIGO DA RECEITA | G12: 5856
F13: 
D15: 05 | E15: NÚMERO DE REFERÊNCIA
B16: 01 - NOME / TELEFONE | F16: 
B17: ='Calculadora da COFINS'!F7 -> 0
D18: 06 | E18: DATA DE VENCIMENTO
B19: Telefone: | C19: ='Calculadora da COFINS'!H8 -> 0 | F19: 
B21: Veja no verso | D21: 07 | E21: VALOR PRINCIPAL | G21: ='Calculadora da COFINS'!H79 -> 12697.4
F22: 
B24: Instruções para preenchimento | D24: 08 | E24: VALOR DA MULTA
F25: 
B27: ATENÇÃO | D27: 09 | E27: VALOR DOS JUROS E/OU
E28: ENCARGOS DL - 1025/69 | F28: 
B30: É vedado o recolhimento de tributos e contribuições administradas pela Secretaria da Receita Federal, cujo valor seja inferior a R$ 10,00. Ocorrendo tal situação, adicione esse valor ao tributo ou contribuição de mesmo código de períodos subsequentes, até que o total seja igual ou superior a R$ 10,00. | D30: 10 | E30: VALOR TOTAL | G30: =G21 -> 12697.4
F31: 
D33: 11 | E33: AUTENTICAÇÃO BANCÁRIA (Somente nas 1ª e 2ª vias)
B38: Aprovado pela IN?SRF Nº 81/96.
D43: 02 | E43: PERÍODO DE APURAÇÃO | G43: =G6 -> 0
C44: MINISTÉRIO DA FAZENDA | F44: 
C45: SECRETARIA DA RECEITA FEDERAL
C46: Documento de Arrecadação de Receitas Federais | D46: 03 | E46: NÚMERO DO CPF OU CNPJ | G46: =G9 -> 0
F47: 
C48: DARF
D49: 04 | E49: CÓDIGO DA RECEITA | G49: =G12 -> 5856
F50: 
D52: 05 | E52: NÚMERO DE REFERÊNCIA | G52: =G15 -> 0
B53: 01 - NOME / TELEFONE | F53: 
B54: =B17 -> 0
D55: 06 | E55: DATA DE VENCIMENTO | G55: =G18 -> 0
B56: Telefone: | C56: =C19 -> 0 | F56: 
B58: Veja no verso | D58: 07 | E58: VALOR PRINCIPAL | G58: =G21 -> 12697.4
F59: 
B61: Instruções para preenchimento | D61: 08 | E61: VALOR DA MULTA | G61: =G24 -> 0
...

Sheet DARF - PIS
B2: DARF - PIS Não Cumulativo - Código: 6912
D6: 02 | E6: PERÍODO DE APURAÇÃO | G6: ='Calculadora do PIS'!H7 -> 0
C7: MINISTÉRIO DA FAZENDA | F7: 
C8: SECRETARIA DA RECEITA FEDERAL
C9: Documento de Arrecadação de Receitas Federais | D9: 03 | E9: NÚMERO DO CPF OU CNPJ | G9: ='Calculadora do PIS'!F8 -> 0
F10: 
C11: DARF
D12: 04 | E12: CÓDIGO DA RECEITA | G12: 6912
F13: 
D15: 05 | E15: NÚMERO DE REFERÊNCIA
B16: 01 - NOME / TELEFONE | F16: 
B17: ='Calculadora do PIS'!F7 -> 0
D18: 06 | E18: DATA DE VENCIMENTO
B19: Telefone: | C19: ='Calculadora do PIS'!H8 -> 0 | F19: 
B21: Veja no verso | D21: 07 | E21: VALOR PRINCIPAL | G21: ='Calculadora do PIS'!H78 -> 0
F22: 
B24: Instruções para preenchimento | D24: 08 | E24: VALOR DA MULTA
F25: 
B27: ATENÇÃO | D27: 09 | E27: VALOR DOS JUROS E/OU
E28: ENCARGOS DL - 1025/69 | F28: 
B30: É vedado o recolhimento de tributos e contribuições administradas pela Secretaria da Receita Federal, cujo valor seja inferior a R$ 10,00. Ocorrendo tal situação, adicione esse valor ao tributo ou contribuição de mesmo código de períodos subsequentes, até que o total seja igual ou superior a R$ 10,00. | D30: 10 | E30: VALOR TOTAL | G30: =G21 -> 0
F31: 
D33: 11 | E33: AUTENTICAÇÃO BANCÁRIA (Somente nas 1ª e 2ª vias)
B38: Aprovado pela IN?SRF Nº 81/96.
D43: 02 | E43: PERÍODO DE APURAÇÃO | G43: ='Calculadora do PIS'!H7 -> 0
C44: MINISTÉRIO DA FAZENDA | F44: 
C45: SECRETARIA DA RECEITA FEDERAL
C46: Documento de Arrecadação de Receitas Federais | D46: 03 | E46: NÚMERO DO CPF OU CNPJ | G46: =G9 -> 0
F47: 
C48: DARF
D49: 04 | E49: CÓDIGO DA RECEITA | G49: =G12 -> 6912
F50: 
D52: 05 | E52: NÚMERO DE REFERÊNCIA | G52: =G15 -> 0
B53: 01 - NOME / TELEFONE | F53: 
B54: =B17 -> 0
D55: 06 | E55: DATA DE VENCIMENTO | G55: =G18 -> 0
B56: Telefone: | C56: =C19 -> 0 | F56: 
B58: Veja no verso | D58: 07 | E58: VALOR PRINCIPAL | G58: =G21 -> 0
F59: 
B61: Instruções para preenchimento | D61: 08 | E61: VALOR DA MULTA | G61: =G24 -> 0
...
