Workbook

Sheet EDUARDO
C2: - Preencher na coluna "C" a palavra "FERIADO", quando houver.
C3: - Na coluna "D" a "G", deve ser preenchido os horários de entrada e saída. Quando houver folga, deve ser escrito "FOLGA"
C4: - As colunas bloqueadas, são formulas de cálculo, no qual não deve ser alterado,
C5: - Na coluna "D" a "G", deve ser preenchido os horários de entrada e saída. Quando houver Falta, deve ser escrito "FALTA"
C6: - Na coluna "D" a "G", deve ser preenchido os horários de entrada e saída. Quando houver atestado, deve ser escrito "ATESTADO"
C7: - Para ter o registro de todos os pontos, sugerido deixar o histórico por nome de funcionário e mês | K7: =+K8-J8 -> 0.1875 | L7: =+I8-H8 -> 0.17916667
A8: 44378 | D8: EDUARDO LUIZ LIMA SANTOS | H8: =VLOOKUP($D$8,'CADASTRO FUNCIONARIO'!$B:$G,2,0) -> 0.3125 | I8: =VLOOKUP($D$8,'CADASTRO FUNCIONARIO'!$B:$G,3,0) -> 0.49166667 | J8: =VLOOKUP($D$8,'CADASTRO FUNCIONARIO'!$B:$G,4,0) -> 0.54166667 | K8: =VLOOKUP($D$8,'CADASTRO FUNCIONARIO'!$B:$G,5,0) -> 0.72916667 | L8: =IF(H8="FALTA",0,IF(H8="ATESTADO",0.30555555556,IF(H8="folga",0,(K8-J8)+(I8-H8)))) -> 0.36666667
A9: DIA | B9: DIA SEMANA | C9: Feriado | D9: Entrada | E9: Saída almoço | F9: Volta do almoço | G9: Saída | H9: Carga diária TRABALHADA | I9: Carga diária CONTRATO | J9: Extras 50% | K9: Extras 100% | L9: Faltas Integrais | M9: Faltas Parciais
A10: =A8 -> 44378 | B10: =TEXT(A10,"ddd") -> qui | H10: =IF(F10="FALTA","",IF(D10="ATESTADO",$K$7,IF(G10="ATESTADO",$L$7,IF(D10="FALTA",$K$7,IF(G10="FALTA",$L$7,IF(D10="","",IF(D10="FOLGA","",IF(D10="FALTA","",IF(D10="ATESTADO",$L$8,IF(D10="folga",0,(G10-F10)+(E10-D10))))))))))) | I10: =IF(D10="","",IF(D10="FOLGA","",$L$8)) | J10: =IF(H10="","",IF($B10="FERIADO","",IF(H10>I10,IF(H10-I10>0.006944,H10-I10,""),""))) | K10: =IF($C10="FERIADO",H10,"") | L10: =IF(H10="",I10,IF(D10="","",IF(H10=0,IF(D10="FOLGA","",I10),""))) | M10: =IF(H10=0,"",IF(H10<I10,IF(I10-H10>0.006944,I10-H10,""),""))
A11: =A10+1 -> 44379 | B11: =TEXT(A11,"ddd") -> sex | C11: FERIADO | H11: =IF(F11="FALTA","",IF(D11="ATESTADO",$K$7,IF(G11="ATESTADO",$L$7,IF(D11="FALTA",$K$7,IF(G11="FALTA",$L$7,IF(D11="","",IF(D11="FOLGA","",IF(D11="FALTA","",IF(D11="ATESTADO",$L$8,IF(D11="folga",0,(G11-F11)+(E11-D11))))))))))) | I11: =IF(D11="","",IF(D11="FOLGA","",$L$8)) | J11: =IF(H11="","",IF($B11="FERIADO","",IF(H11>I11,IF(H11-I11>0.006944,H11-I11,""),""))) | K11: =IF($C11="FERIADO",H11,"") | L11: =IF(H11="",I11,IF(D11="","",IF(H11=0,IF(D11="FOLGA","",I11),""))) | M11: =IF(H11=0,"",IF(H11<I11,IF(I11-H11>0.006944,I11-H11,""),""))
A12: =A11+1 -> 44380 | B12: =TEXT(A12,"ddd") -> sáb | H12: =IF(F12="FALTA","",IF(D12="ATESTADO",$K$7,IF(G12="ATESTADO",$L$7,IF(D12="FALTA",$K$7,IF(G12="FALTA",$L$7,IF(D12="","",IF(D12="FOLGA","",IF(D12="FALTA","",IF(D12="ATESTADO",$L$8,IF(D12="folga",0,(G12-F12)+(E12-D12))))))))))) | I12: =IF(D12="","",IF(D12="FOLGA","",$L$8)) | J12: =IF(H12="","",IF($B12="FERIADO","",IF(H12>I12,IF(H12-I12>0.006944,H12-I12,""),""))) | K12: =IF($C12="FERIADO",H12,"") | L12: =IF(H12="",I12,IF(D12="","",IF(H12=0,IF(D12="FOLGA","",I12),""))) | M12: =IF(H12=0,"",IF(H12<I12,IF(I12-H12>0.006944,I12-H12,""),""))
A13: =A12+1 -> 44381 | B13: =TEXT(A13,"ddd") -> dom | H13: =IF(F13="FALTA","",IF(D13="ATESTADO",$K$7,IF(G13="ATESTADO",$L$7,IF(D13="FALTA",$K$7,IF(G13="FALTA",$L$7,IF(D13="","",IF(D13="FOLGA","",IF(D13="FALTA","",IF(D13="ATESTADO",$L$8,IF(D13="folga",0,(G13-F13)+(E13-D13))))))))))) | I13: =IF(D13="","",IF(D13="FOLGA","",$L$8)) | J13: =IF(H13="","",IF($B13="FERIADO","",IF(H13>I13,IF(H13-I13>0.006944,H13-I13,""),""))) | K13: =IF($C13="FERIADO",H13,"") | L13: =IF(H13="",I13,IF(D13="","",IF(H13=0,IF(D13="FOLGA","",I13),""))) | M13: =IF(H13=0,"",IF(H13<I13,IF(I13-H13>0.006944,I13-H13,""),""))
A14: =A13+1 -> 44382 | B14: =TEXT(A14,"ddd") -> seg | H14: =IF(F14="FALTA","",IF(D14="ATESTADO",$K$7,IF(G14="ATESTADO",$L$7,IF(D14="FALTA",$K$7,IF(G14="FALTA",$L$7,IF(D14="","",IF(D14="FOLGA","",IF(D14="FALTA","",IF(D14="ATESTADO",$L$8,IF(D14="folga",0,(G14-F14)+(E14-D14))))))))))) | I14: =IF(D14="","",IF(D14="FOLGA","",$L$8)) | J14: =IF(H14="","",IF($B14="FERIADO","",IF(H14>I14,IF(H14-I14>0.006944,H14-I14,""),""))) | K14: =IF($C14="FERIADO",H14,"") | L14: =IF(H14="",I14,IF(D14="","",IF(H14=0,IF(D14="FOLGA","",I14),""))) | M14: =IF(H14=0,"",IF(H14<I14,IF(I14-H14>0.006944,I14-H14,""),""))
A15: =A14+1 -> 44383 | B15: =TEXT(A15,"ddd") -> ter | H15: =IF(F15="FALTA","",IF(D15="ATESTADO",$K$7,IF(G15="ATESTADO",$L$7,IF(D15="FALTA",$K$7,IF(G15="FALTA",$L$7,IF(D15="","",IF(D15="FOLGA","",IF(D15="FALTA","",IF(D15="ATESTADO",$L$8,IF(D15="folga",0,(G15-F15)+(E15-D15))))))))))) | I15: =IF(D15="","",IF(D15="FOLGA","",$L$8)) | J15: =IF(H15="","",IF($B15="FERIADO","",IF(H15>I15,IF(H15-I15>0.006944,H15-I15,""),""))) | K15: =IF($C15="FERIADO",H15,"") | L15: =IF(H15="",I15,IF(D15="","",IF(H15=0,IF(D15="FOLGA","",I15),""))) | M15: =IF(H15=0,"",IF(H15<I15,IF(I15-H15>0.006944,I15-H15,""),""))
A16: =A15+1 -> 44384 | B16: =TEXT(A16,"ddd") -> qua | D16: ATESTADO | H16: =IF(F16="FALTA","",IF(D16="ATESTADO",$K$7,IF(G16="ATESTADO",$L$7,IF(D16="FALTA",$K$7,IF(G16="FALTA",$L$7,IF(D16="","",IF(D16="FOLGA","",IF(D16="FALTA","",IF(D16="ATESTADO",$L$8,IF(D16="folga",0,(G16-F16)+(E16-D16))))))))))) -> 0.1875 | I16: =IF(D16="","",IF(D16="FOLGA","",$L$8)) -> 0.36666667 | J16: =IF(H16="","",IF($B16="FERIADO","",IF(H16>I16,IF(H16-I16>0.006944,H16-I16,""),""))) | K16: =IF($C16="FERIADO",H16,"") | L16: =IF(H16="",I16,IF(D16="","",IF(H16=0,IF(D16="FOLGA","",I16),""))) | M16: =IF(H16=0,"",IF(H16<I16,IF(I16-H16>0.006944,I16-H16,""),"")) -> 0.17916667
A17: =A16+1 -> 44385 | B17: =TEXT(A17,"ddd") -> qui | D17: 0.3125 | E17: 0.49166667 | G17: ATESTADO | H17: =IF(F17="FALTA","",IF(D17="ATESTADO",$K$7,IF(G17="ATESTADO",$L$7,IF(D17="FALTA",$K$7,IF(G17="FALTA",$L$7,IF(D17="","",IF(D17="FOLGA","",IF(D17="FALTA","",IF(D17="ATESTADO",$L$8,IF(D17="folga",0,(G17-F17)+(E17-D17))))))))))) -> 0.17916667 | I17: =IF(D17="","",IF(D17="FOLGA","",$L$8)) -> 0.36666667 | J17: =IF(H17="","",IF($B17="FERIADO","",IF(H17>I17,IF(H17-I17>0.006944,H17-I17,""),""))) | K17: =IF($C17="FERIADO",H17,"") | L17: =IF(H17="",I17,IF(D17="","",IF(H17=0,IF(D17="FOLGA","",I17),""))) | M17: =IF(H17=0,"",IF(H17<I17,IF(I17-H17>0.006944,I17-H17,""),"")) -> 0.1875
A18: =A17+1 -> 44386 | B18: =TEXT(A18,"ddd") -> sex | H18: =IF(F18="FALTA","",IF(D18="ATESTADO",$K$7,IF(G18="ATESTADO",$L$7,IF(D18="FALTA",$K$7,IF(G18="FALTA",$L$7,IF(D18="","",IF(D18="FOLGA","",IF(D18="FALTA","",IF(D18="ATESTADO",$L$8,IF(D18="folga",0,(G18-F18)+(E18-D18))))))))))) | I18: =IF(D18="","",IF(D18="FOLGA","",$L$8)) | J18: =IF(H18="","",IF($B18="FERIADO","",IF(H18>I18,IF(H18-I18>0.006944,H18-I18,""),""))) | K18: =IF($C18="FERIADO",H18,"") | L18: =IF(H18="",I18,IF(D18="","",IF(H18=0,IF(D18="FOLGA","",I18),""))) | M18: =IF(H18=0,"",IF(H18<I18,IF(I18-H18>0.006944,I18-H18,""),""))
A19: =A18+1 -> 44387 | B19: =TEXT(A19,"ddd") -> sáb | D19: FALTA | H19: =IF(F19="FALTA","",IF(D19="ATESTADO",$K$7,IF(G19="ATESTADO",$L$7,IF(D19="FALTA",$K$7,IF(G19="FALTA",$L$7,IF(D19="","",IF(D19="FOLGA","",IF(D19="FALTA","",IF(D19="ATESTADO",$L$8,IF(D19="folga",0,(G19-F19)+(E19-D19))))))))))) -> 0.1875 | I19: =IF(D19="","",IF(D19="FOLGA","",$L$8)) -> 0.36666667 | J19: =IF(H19="","",IF($B19="FERIADO","",IF(H19>I19,IF(H19-I19>0.006944,H19-I19,""),""))) | K19: =IF($C19="FERIADO",H19,"") | L19: =IF(H19="",I19,IF(D19="","",IF(H19=0,IF(D19="FOLGA","",I19),""))) | M19: =IF(H19=0,"",IF(H19<I19,IF(I19-H19>0.006944,I19-H19,""),"")) -> 0.17916667
A20: =A19+1 -> 44388 | B20: =TEXT(A20,"ddd") -> dom | D20: 0.3125 | E20: 0.49166667 | G20: FALTA | H20: =IF(F20="FALTA","",IF(D20="ATESTADO",$K$7,IF(G20="ATESTADO",$L$7,IF(D20="FALTA",$K$7,IF(G20="FALTA",$L$7,IF(D20="","",IF(D20="FOLGA","",IF(D20="FALTA","",IF(D20="ATESTADO",$L$8,IF(D20="folga",0,(G20-F20)+(E20-D20))))))))))) -> 0.17916667 | I20: =IF(D20="","",IF(D20="FOLGA","",$L$8)) -> 0.36666667 | J20: =IF(H20="","",IF($B20="FERIADO","",IF(H20>I20,IF(H20-I20>0.006944,H20-I20,""),""))) | K20: =IF($C20="FERIADO",H20,"") | L20: =IF(H20="",I20,IF(D20="","",IF(H20=0,IF(D20="FOLGA","",I20),""))) | M20: =IF(H20=0,"",IF(H20<I20,IF(I20-H20>0.006944,I20-H20,""),"")) -> 0.1875
A21: =A20+1 -> 44389 | B21: =TEXT(A21,"ddd") -> seg | H21: =IF(F21="FALTA","",IF(D21="ATESTADO",$K$7,IF(G21="ATESTADO",$L$7,IF(D21="FALTA",$K$7,IF(G21="FALTA",$L$7,IF(D21="","",IF(D21="FOLGA","",IF(D21="FALTA","",IF(D21="ATESTADO",$L$8,IF(D21="folga",0,(G21-F21)+(E21-D21))))))))))) | I21: =IF(D21="","",IF(D21="FOLGA","",$L$8)) | J21: =IF(H21="","",IF($B21="FERIADO","",IF(H21>I21,IF(H21-I21>0.006944,H21-I21,""),""))) | K21: =IF($C21="FERIADO",H21,"") | L21: =IF(H21="",I21,IF(D21="","",IF(H21=0,IF(D21="FOLGA","",I21),""))) | M21: =IF(H21=0,"",IF(H21<I21,IF(I21-H21>0.006944,I21-H21,""),""))
A22: =A21+1 -> 44390 | B22: =TEXT(A22,"ddd") -> ter | D22: ATESTADO | H22: =IF(F22="FALTA","",IF(D22="ATESTADO",$K$7,IF(G22="ATESTADO",$L$7,IF(D22="FALTA",$K$7,IF(G22="FALTA",$L$7,IF(D22="","",IF(D22="FOLGA","",IF(D22="FALTA","",IF(D22="ATESTADO",$L$8,IF(D22="folga",0,(G22-F22)+(E22-D22))))))))))) -> 0.1875 | I22: =IF(D22="","",IF(D22="FOLGA","",$L$8)) -> 0.36666667 | J22: =IF(H22="","",IF($B22="FERIADO","",IF(H22>I22,IF(H22-I22>0.006944,H22-I22,""),""))) | K22: =IF($C22="FERIADO",H22,"") | L22: =IF(H22="",I22,IF(D22="","",IF(H22=0,IF(D22="FOLGA","",I22),""))) | M22: =IF(H22=0,"",IF(H22<I22,IF(I22-H22>0.006944,I22-H22,""),"")) -> 0.17916667
A23: =A22+1 -> 44391 | B23: =TEXT(A23,"ddd") -> qua | H23: =IF(F23="FALTA","",IF(D23="ATESTADO",$K$7,IF(G23="ATESTADO",$L$7,IF(D23="FALTA",$K$7,IF(G23="FALTA",$L$7,IF(D23="","",IF(D23="FOLGA","",IF(D23="FALTA","",IF(D23="ATESTADO",$L$8,IF(D23="folga",0,(G23-F23)+(E23-D23))))))))))) | I23: =IF(D23="","",IF(D23="FOLGA","",$L$8)) | J23: =IF(H23="","",IF($B23="FERIADO","",IF(H23>I23,IF(H23-I23>0.006944,H23-I23,""),""))) | K23: =IF($C23="FERIADO",H23,"") | L23: =IF(H23="",I23,IF(D23="","",IF(H23=0,IF(D23="FOLGA","",I23),""))) | M23: =IF(H23=0,"",IF(H23<I23,IF(I23-H23>0.006944,I23-H23,""),""))
A24: =A23+1 -> 44392 | B24: =TEXT(A24,"ddd") -> qui | D24: 0.31319444 | E24: 0.49166667 | F24: 0.54166667 | G24: FALTA | H24: =IF(F24="FALTA","",IF(D24="ATESTADO",$K$7,IF(G24="ATESTADO",$L$7,IF(D24="FALTA",$K$7,IF(G24="FALTA",$L$7,IF(D24="","",IF(D24="FOLGA","",IF(D24="FALTA","",IF(D24="ATESTADO",$L$8,IF(D24="folga",0,(G24-F24)+(E24-D24))))))))))) -> 0.17916667 | I24: =IF(D24="","",IF(D24="FOLGA","",$L$8)) -> 0.36666667 | J24: =IF(H24="","",IF($B24="FERIADO","",IF(H24>I24,IF(H24-I24>0.006944,H24-I24,""),""))) | K24: =IF($C24="FERIADO",H24,"") | L24: =IF(H24="",I24,IF(D24="","",IF(H24=0,IF(D24="FOLGA","",I24),""))) | M24: =IF(H24=0,"",IF(H24<I24,IF(I24-H24>0.006944,I24-H24,""),"")) -> 0.1875
A25: =A24+1 -> 44393 | B25: =TEXT(A25,"ddd") -> sex | D25: ATESTADO | E25: ATESTADO | F25: ATESTADO | G25: ATESTADO | H25: =IF(F25="FALTA","",IF(D25="ATESTADO",$K$7,IF(G25="ATESTADO",$L$7,IF(D25="FALTA",$K$7,IF(G25="FALTA",$L$7,IF(D25="","",IF(D25="FOLGA","",IF(D25="FALTA","",IF(D25="ATESTADO",$L$8,IF(D25="folga",0,(G25-F25)+(E25-D25))))))))))) -> 0.1875 | I25: =IF(D25="","",IF(D25="FOLGA","",$L$8)) -> 0.36666667 | J25: =IF(H25="","",IF($B25="FERIADO","",IF(H25>I25,IF(H25-I25>0.006944,H25-I25,""),""))) | K25: =IF($C25="FERIADO",H25,"") | L25: =IF(H25="",I25,IF(D25="","",IF(H25=0,IF(D25="FOLGA","",I25),""))) | M25: =IF(H25=0,"",IF(H25<I25,IF(I25-H25>0.006944,I25-H25,""),"")) -> 0.17916667
A26: =A25+1 -> 44394 | B26: =TEXT(A26,"ddd") -> sáb | D26: FOLGA | E26: FOLGA | F26: FOLGA | G26: FOLGA | H26: =IF(F26="FALTA","",IF(D26="ATESTADO",$K$7,IF(G26="ATESTADO",$L$7,IF(D26="FALTA",$K$7,IF(G26="FALTA",$L$7,IF(D26="","",IF(D26="FOLGA","",IF(D26="FALTA","",IF(D26="ATESTADO",$L$8,IF(D26="folga",0,(G26-F26)+(E26-D26))))))))))) | I26: =IF(D26="","",IF(D26="FOLGA","",$L$8)) | J26: =IF(H26="","",IF($B26="FERIADO","",IF(H26>I26,IF(H26-I26>0.006944,H26-I26,""),""))) | K26: =IF($C26="FERIADO",H26,"") | L26: =IF(H26="",I26,IF(D26="","",IF(H26=0,IF(D26="FOLGA","",I26),""))) | M26: =IF(H26=0,"",IF(H26<I26,IF(I26-H26>0.006944,I26-H26,""),""))
A27: =A26+1 -> 44395 | B27: =TEXT(A27,"ddd") -> dom | D27: FOLGA | E27: FOLGA | F27: FOLGA | G27: FOLGA | H27: =IF(F27="FALTA","",IF(D27="ATESTADO",$K$7,IF(G27="ATESTADO",$L$7,IF(D27="FALTA",$K$7,IF(G27="FALTA",$L$7,IF(D27="","",IF(D27="FOLGA","",IF(D27="FALTA","",IF(D27="ATESTADO",$L$8,IF(D27="folga",0,(G27-F27)+(E27-D27))))))))))) | I27: =IF(D27="","",IF(D27="FOLGA","",$L$8)) | J27: =IF(H27="","",IF($B27="FERIADO","",IF(H27>I27,IF(H27-I27>0.006944,H27-I27,""),""))) | K27: =IF($C27="FERIADO",H27,"") | L27: =IF(H27="",I27,IF(D27="","",IF(H27=0,IF(D27="FOLGA","",I27),""))) | M27: =IF(H27=0,"",IF(H27<I27,IF(I27-H27>0.006944,I27-H27,""),""))
A28: =A27+1 -> 44396 | B28: =TEXT(A28,"ddd") -> seg | C28: FERIADO | D28: 0.31319444 | E28: 0.49305556 | F28: 0.54444444 | G28: 0.72916667 | H28: =IF(F28="FALTA","",IF(D28="ATESTADO",$K$7,IF(G28="ATESTADO",$L$7,IF(D28="FALTA",$K$7,IF(G28="FALTA",$L$7,IF(D28="","",IF(D28="FOLGA","",IF(D28="FALTA","",IF(D28="ATESTADO",$L$8,IF(D28="folga",0,(G28-F28)+(E28-D28))))))))))) -> 0.36458333 | I28: =IF(D28="","",IF(D28="FOLGA","",$L$8)) -> 0.36666667 | J28: =IF(H28="","",IF($B28="FERIADO","",IF(H28>I28,IF(H28-I28>0.006944,H28-I28,""),""))) | K28: =IF($C28="FERIADO",H28,"") -> 0.36458333 | L28: =IF(H28="",I28,IF(D28="","",IF(H28=0,IF(D28="FOLGA","",I28),""))) | M28: =IF(H28=0,"",IF(H28<I28,IF(I28-H28>0.006944,I28-H28,""),""))
A29: =A28+1 -> 44397 | B29: =TEXT(A29,"ddd") -> ter | D29: FALTA | E29: 0.49097222 | F29: 0.54166667 | G29: 0.72986111 | H29: =IF(F29="FALTA","",IF(D29="ATESTADO",$K$7,IF(G29="ATESTADO",$L$7,IF(D29="FALTA",$K$7,IF(G29="FALTA",$L$7,IF(D29="","",IF(D29="FOLGA","",IF(D29="FALTA","",IF(D29="ATESTADO",$L$8,IF(D29="folga",0,(G29-F29)+(E29-D29))))))))))) -> 0.1875 | I29: =IF(D29="","",IF(D29="FOLGA","",$L$8)) -> 0.36666667 | J29: =IF(H29="","",IF($B29="FERIADO","",IF(H29>I29,IF(H29-I29>0.006944,H29-I29,""),""))) | K29: =IF($C29="FERIADO",H29,"") | L29: =IF(H29="",I29,IF(D29="","",IF(H29=0,IF(D29="FOLGA","",I29),""))) | M29: =IF(H29=0,"",IF(H29<I29,IF(I29-H29>0.006944,I29-H29,""),"")) -> 0.17916667
A30: =A29+1 -> 44398 | B30: =TEXT(A30,"ddd") -> qua | D30: FALTA | E30: FALTA | F30: FALTA | G30: FALTA | H30: =IF(F30="FALTA","",IF(D30="ATESTADO",$K$7,IF(G30="ATESTADO",$L$7,IF(D30="FALTA",$K$7,IF(G30="FALTA",$L$7,IF(D30="","",IF(D30="FOLGA","",IF(D30="FALTA","",IF(D30="ATESTADO",$L$8,IF(D30="folga",0,(G30-F30)+(E30-D30))))))))))) | I30: =IF(D30="","",IF(D30="FOLGA","",$L$8)) -> 0.36666667 | J30: =IF(H30="","",IF($B30="FERIADO","",IF(H30>I30,IF(H30-I30>0.006944,H30-I30,""),""))) | K30: =IF($C30="FERIADO",H30,"") | L30: =IF(H30="",I30,IF(D30="","",IF(H30=0,IF(D30="FOLGA","",I30),""))) -> 0.36666667 | M30: =IF(H30=0,"",IF(H30<I30,IF(I30-H30>0.006944,I30-H30,""),""))
A31: =A30+1 -> 44399 | B31: =TEXT(A31,"ddd") -> qui | D31: FALTA | E31: FALTA | F31: FALTA | G31: FALTA | H31: =IF(F31="FALTA","",IF(D31="ATESTADO",$K$7,IF(G31="ATESTADO",$L$7,IF(D31="FALTA",$K$7,IF(G31="FALTA",$L$7,IF(D31="","",IF(D31="FOLGA","",IF(D31="FALTA","",IF(D31="ATESTADO",$L$8,IF(D31="folga",0,(G31-F31)+(E31-D31))))))))))) | I31: =IF(D31="","",IF(D31="FOLGA","",$L$8)) -> 0.36666667 | J31: =IF(H31="","",IF($B31="FERIADO","",IF(H31>I31,IF(H31-I31>0.006944,H31-I31,""),""))) | K31: =IF($C31="FERIADO",H31,"") | L31: =IF(H31="",I31,IF(D31="","",IF(H31=0,IF(D31="FOLGA","",I31),""))) -> 0.36666667 | M31: =IF(H31=0,"",IF(H31<I31,IF(I31-H31>0.006944,I31-H31,""),""))
A32: =A31+1 -> 44400 | B32: =TEXT(A32,"ddd") -> sex | D32: 0.31319444 | E32: 0.49166667 | F32: 0.54166667 | G32: 0.68541667 | H32: =IF(F32="FALTA","",IF(D32="ATESTADO",$K$7,IF(G32="ATESTADO",$L$7,IF(D32="FALTA",$K$7,IF(G32="FALTA",$L$7,IF(D32="","",IF(D32="FOLGA","",IF(D32="FALTA","",IF(D32="ATESTADO",$L$8,IF(D32="folga",0,(G32-F32)+(E32-D32))))))))))) -> 0.32222222 | I32: =IF(D32="","",IF(D32="FOLGA","",$L$8)) -> 0.36666667 | J32: =IF(H32="","",IF($B32="FERIADO","",IF(H32>I32,IF(H32-I32>0.006944,H32-I32,""),""))) | K32: =IF($C32="FERIADO",H32,"") | L32: =IF(H32="",I32,IF(D32="","",IF(H32=0,IF(D32="FOLGA","",I32),""))) | M32: =IF(H32=0,"",IF(H32<I32,IF(I32-H32>0.006944,I32-H32,""),"")) -> 0.044444444
A33: =A32+1 -> 44401 | B33: =TEXT(A33,"ddd") -> sáb | D33: FOLGA | E33: FOLGA | F33: FOLGA | G33: FOLGA | H33: =IF(F33="FALTA","",IF(D33="ATESTADO",$K$7,IF(G33="ATESTADO",$L$7,IF(D33="FALTA",$K$7,IF(G33="FALTA",$L$7,IF(D33="","",IF(D33="FOLGA","",IF(D33="FALTA","",IF(D33="ATESTADO",$L$8,IF(D33="folga",0,(G33-F33)+(E33-D33))))))))))) | I33: =IF(D33="","",IF(D33="FOLGA","",$L$8)) | J33: =IF(H33="","",IF($B33="FERIADO","",IF(H33>I33,IF(H33-I33>0.006944,H33-I33,""),""))) | K33: =IF($C33="FERIADO",H33,"") | L33: =IF(H33="",I33,IF(D33="","",IF(H33=0,IF(D33="FOLGA","",I33),""))) | M33: =IF(H33=0,"",IF(H33<I33,IF(I33-H33>0.006944,I33-H33,""),""))
A34: =A33+1 -> 44402 | B34: =TEXT(A34,"ddd") -> dom | D34: FOLGA | E34: FOLGA | F34: FOLGA | G34: FOLGA | H34: =IF(F34="FALTA","",IF(D34="ATESTADO",$K$7,IF(G34="ATESTADO",$L$7,IF(D34="FALTA",$K$7,IF(G34="FALTA",$L$7,IF(D34="","",IF(D34="FOLGA","",IF(D34="FALTA","",IF(D34="ATESTADO",$L$8,IF(D34="folga",0,(G34-F34)+(E34-D34))))))))))) | I34: =IF(D34="","",IF(D34="FOLGA","",$L$8)) | J34: =IF(H34="","",IF($B34="FERIADO","",IF(H34>I34,IF(H34-I34>0.006944,H34-I34,""),""))) | K34: =IF($C34="FERIADO",H34,"") | L34: =IF(H34="",I34,IF(D34="","",IF(H34=0,IF(D34="FOLGA","",I34),""))) | M34: =IF(H34=0,"",IF(H34<I34,IF(I34-H34>0.006944,I34-H34,""),""))
A35: =A34+1 -> 44403 | B35: =TEXT(A35,"ddd") -> seg | D35: FALTA | E35: FALTA | F35: FALTA | G35: FALTA | H35: =IF(F35="FALTA","",IF(D35="ATESTADO",$K$7,IF(G35="ATESTADO",$L$7,IF(D35="FALTA",$K$7,IF(G35="FALTA",$L$7,IF(D35="","",IF(D35="FOLGA","",IF(D35="FALTA","",IF(D35="ATESTADO",$L$8,IF(D35="folga",0,(G35-F35)+(E35-D35))))))))))) | I35: =IF(D35="","",IF(D35="FOLGA","",$L$8)) -> 0.36666667 | J35: =IF(H35="","",IF($B35="FERIADO","",IF(H35>I35,IF(H35-I35>0.006944,H35-I35,""),""))) | K35: =IF($C35="FERIADO",H35,"") | L35: =IF(H35="",I35,IF(D35="","",IF(H35=0,IF(D35="FOLGA","",I35),""))) -> 0.36666667 | M35: =IF(H35=0,"",IF(H35<I35,IF(I35-H35>0.006944,I35-H35,""),""))
A36: =A35+1 -> 44404 | B36: =TEXT(A36,"ddd") -> ter | D36: FALTA | E36: FALTA | F36: FALTA | G36: FALTA | H36: =IF(F36="FALTA","",IF(D36="ATESTADO",$K$7,IF(G36="ATESTADO",$L$7,IF(D36="FALTA",$K$7,IF(G36="FALTA",$L$7,IF(D36="","",IF(D36="FOLGA","",IF(D36="FALTA","",IF(D36="ATESTADO",$L$8,IF(D36="folga",0,(G36-F36)+(E36-D36))))))))))) | I36: =IF(D36="","",IF(D36="FOLGA","",$L$8)) -> 0.36666667 | J36: =IF(H36="","",IF($B36="FERIADO","",IF(H36>I36,IF(H36-I36>0.006944,H36-I36,""),""))) | K36: =IF($C36="FERIADO",H36,"") | L36: =IF(H36="",I36,IF(D36="","",IF(H36=0,IF(D36="FOLGA","",I36),""))) -> 0.36666667 | M36: =IF(H36=0,"",IF(H36<I36,IF(I36-H36>0.006944,I36-H36,""),""))
A37: =A36+1 -> 44405 | B37: =TEXT(A37,"ddd") -> qua | D37: FALTA | E37: FALTA | F37: FALTA | G37: FALTA | H37: =IF(F37="FALTA","",IF(D37="ATESTADO",$K$7,IF(G37="ATESTADO",$L$7,IF(D37="FALTA",$K$7,IF(G37="FALTA",$L$7,IF(D37="","",IF(D37="FOLGA","",IF(D37="FALTA","",IF(D37="ATESTADO",$L$8,IF(D37="folga",0,(G37-F37)+(E37-D37))))))))))) | I37: =IF(D37="","",IF(D37="FOLGA","",$L$8)) -> 0.36666667 | J37: =IF(H37="","",IF($B37="FERIADO","",IF(H37>I37,IF(H37-I37>0.006944,H37-I37,""),""))) | K37: =IF($C37="FERIADO",H37,"") | L37: =IF(H37="",I37,IF(D37="","",IF(H37=0,IF(D37="FOLGA","",I37),""))) -> 0.36666667 | M37: =IF(H37=0,"",IF(H37<I37,IF(I37-H37>0.006944,I37-H37,""),""))
A38: =A37+1 -> 44406 | B38: =TEXT(A38,"ddd") -> qui | D38: 0.31319444 | E38: 0.48819444 | F38: 0.54236111 | G38: 0.72708333 | H38: =IF(F38="FALTA","",IF(D38="ATESTADO",$K$7,IF(G38="ATESTADO",$L$7,IF(D38="FALTA",$K$7,IF(G38="FALTA",$L$7,IF(D38="","",IF(D38="FOLGA","",IF(D38="FALTA","",IF(D38="ATESTADO",$L$8,IF(D38="folga",0,(G38-F38)+(E38-D38))))))))))) -> 0.35972222 | I38: =IF(D38="","",IF(D38="FOLGA","",$L$8)) -> 0.36666667 | J38: =IF(H38="","",IF($B38="FERIADO","",IF(H38>I38,IF(H38-I38>0.006944,H38-I38,""),""))) | K38: =IF($C38="FERIADO",H38,"") | L38: =IF(H38="",I38,IF(D38="","",IF(H38=0,IF(D38="FOLGA","",I38),""))) | M38: =IF(H38=0,"",IF(H38<I38,IF(I38-H38>0.006944,I38-H38,""),"")) -> 0.0069444444
A39: =A38+1 -> 44407 | B39: =TEXT(A39,"ddd") -> sex | D39: FALTA | E39: FALTA | F39: FALTA | G39: FALTA | H39: =IF(F39="FALTA","",IF(D39="ATESTADO",$K$7,IF(G39="ATESTADO",$L$7,IF(D39="FALTA",$K$7,IF(G39="FALTA",$L$7,IF(D39="","",IF(D39="FOLGA","",IF(D39="FALTA","",IF(D39="ATESTADO",$L$8,IF(D39="folga",0,(G39-F39)+(E39-D39))))))))))) | I39: =IF(D39="","",IF(D39="FOLGA","",$L$8)) -> 0.36666667 | J39: =IF(H39="","",IF($B39="FERIADO","",IF(H39>I39,IF(H39-I39>0.006944,H39-I39,""),""))) | K39: =IF($C39="FERIADO",H39,"") | L39: =IF(H39="",I39,IF(D39="","",IF(H39=0,IF(D39="FOLGA","",I39),""))) -> 0.36666667 | M39: =IF(H39=0,"",IF(H39<I39,IF(I39-H39>0.006944,I39-H39,""),""))
A40: =A39+1 -> 44408 | B40: =TEXT(A40,"ddd") -> sáb | D40: FOLGA | E40: FOLGA | F40: FOLGA | G40: FOLGA | H40: =IF(F40="FALTA","",IF(D40="ATESTADO",$K$7,IF(G40="ATESTADO",$L$7,IF(D40="FALTA",$K$7,IF(G40="FALTA",$L$7,IF(D40="","",IF(D40="FOLGA","",IF(D40="FALTA","",IF(D40="ATESTADO",$L$8,IF(D40="folga",0,(G40-F40)+(E40-D40))))))))))) | I40: =IF(D40="","",IF(D40="FOLGA","",$L$8)) | J40: =IF(H40="","",IF($B40="FERIADO","",IF(H40>I40,IF(H40-I40>0.006944,H40-I40,""),""))) | K40: =IF($C40="FERIADO",H40,"") | L40: =IF(H40="",I40,IF(D40="","",IF(H40=0,IF(D40="FOLGA","",I40),""))) | M40: =IF(H40=0,"",IF(H40<I40,IF(I40-H40>0.006944,I40-H40,""),""))
A42: TOTAL | H42: =SUM(H10:H41) -> 2.5215278 | I42: =SUM(I10:I41) -> 6.2333333 | J42: =SUM(J10:J41) -> 0 | K42: =SUM(K10:K41) -> 0.36458333 | L42: =SUM(L10:L41) -> 2.2 | M42: =SUM(M10:M41) -> 1.5097222
...

Sheet MODELO
D3: CONTROLE PONTO
A7: 44409 | C7: Nome: | D7: Entrada | E7: Saída almoço | F7: Volta do almoço | G7: Saída
A8: DENILSON LORENÇO RIBEIRO | D8: =VLOOKUP($A$8,'CADASTRO FUNCIONARIO'!$B:$G,2,0) -> 0.3125 | E8: =VLOOKUP($A$8,'CADASTRO FUNCIONARIO'!$B:$G,3,0) -> 0.49166667 | F8: =VLOOKUP($A$8,'CADASTRO FUNCIONARIO'!$B:$G,4,0) -> 0.54166667 | G8: =VLOOKUP($A$8,'CADASTRO FUNCIONARIO'!$B:$G,5,0) -> 0.72916667
A9: DIA | B9: DIA SEMANA | C9: Feriado | D9: Entrada | E9: Saída almoço | F9: Volta do almoço | G9: Saída
A10: =A7 -> 44409 | B10: =TEXT(A10,"ddd") -> dom
A11: =A10+1 -> 44410 | B11: =TEXT(A11,"ddd") -> seg
A12: =A11+1 -> 44411 | B12: =TEXT(A12,"ddd") -> ter
A13: =A12+1 -> 44412 | B13: =TEXT(A13,"ddd") -> qua
A14: =A13+1 -> 44413 | B14: =TEXT(A14,"ddd") -> qui
A15: =A14+1 -> 44414 | B15: =TEXT(A15,"ddd") -> sex
A16: =A15+1 -> 44415 | B16: =TEXT(A16,"ddd") -> sáb
A17: =A16+1 -> 44416 | B17: =TEXT(A17,"ddd") -> dom
A18: =A17+1 -> 44417 | B18: =TEXT(A18,"ddd") -> seg
A19: =A18+1 -> 44418 | B19: =TEXT(A19,"ddd") -> ter
A20: =A19+1 -> 44419 | B20: =TEXT(A20,"ddd") -> qua
A21: =A20+1 -> 44420 | B21: =TEXT(A21,"ddd") -> qui
A22: =A21+1 -> 44421 | B22: =TEXT(A22,"ddd") -> sex
... A40: =A39+1 -> 44439 | B40: =TEXT(A40,"ddd") -> ter

Sheet CADASTRO FUNCIONARIO
B9: FUNCIONÁRIO | C9: CARGA HORÁRIA
C10: Entrada | D10: Saída almoço | E10: Volta do almoço | F10: Saída | G10: TOTAL
B11: MODELO | C11: 0.3125 | D11: 0.49166667 | E11: 0.54166667 | F11: 0.72916667 | G11: =IF(C11="FALTA",0,IF(C11="ATESTADO",0.30555555556,IF(C11="folga",0,(F11-E11)+(D11-C11)))) -> 0.36666667
B12: EDUARDO LUIZ LIMA SANTOS | C12: 0.3125 | D12: 0.49166667 | E12: 0.54166667 | F12: 0.72916667 | G12: =IF(C12="FALTA",0,IF(C12="ATESTADO",0.30555555556,IF(C12="folga",0,(F12-E12)+(D12-C12)))) -> 0.36666667
B13: THIAGO DE PAULA | C13: 0.3125 | D13: 0.49166667 | E13: 0.54166667 | F13: 0.72916667 | G13: =IF(C13="FALTA",0,IF(C13="ATESTADO",0.30555555556,IF(C13="folga",0,(F13-E13)+(D13-C13)))) -> 0.36666667
B14: DENILSON LORENÇO RIBEIRO | C14: 0.3125 | D14: 0.49166667 | E14: 0.54166667 | F14: 0.72916667 | G14: =IF(C14="FALTA",0,IF(C14="ATESTADO",0.30555555556,IF(C14="folga",0,(F14-E14)+(D14-C14)))) -> 0.36666667
G15: =IF(C15="FALTA",0,IF(C15="ATESTADO",0.30555555556,IF(C15="folga",0,(F15-E15)+(D15-C15)))) -> 0
G16: =IF(C16="FALTA",0,IF(C16="ATESTADO",0.30555555556,IF(C16="folga",0,(F16-E16)+(D16-C16)))) -> 0
G17: =IF(C17="FALTA",0,IF(C17="ATESTADO",0.30555555556,IF(C17="folga",0,(F17-E17)+(D17-C17)))) -> 0
G18: =IF(C18="FALTA",0,IF(C18="ATESTADO",0.30555555556,IF(C18="folga",0,(F18-E18)+(D18-C18)))) -> 0
G19: =IF(C19="FALTA",0,IF(C19="ATESTADO",0.30555555556,IF(C19="folga",0,(F19-E19)+(D19-C19)))) -> 0
G20: =IF(C20="FALTA",0,IF(C20="ATESTADO",0.30555555556,IF(C20="folga",0,(F20-E20)+(D20-C20)))) -> 0
G21: =IF(C21="FALTA",0,IF(C21="ATESTADO",0.30555555556,IF(C21="folga",0,(F21-E21)+(D21-C21)))) -> 0
G22: =IF(C22="FALTA",0,IF(C22="ATESTADO",0.30555555556,IF(C22="folga",0,(F22-E22)+(D22-C22)))) -> 0
G23: =IF(C23="FALTA",0,IF(C23="ATESTADO",0.30555555556,IF(C23="folga",0,(F23-E23)+(D23-C23)))) -> 0
G24: =IF(C24="FALTA",0,IF(C24="ATESTADO",0.30555555556,IF(C24="folga",0,(F24-E24)+(D24-C24)))) -> 0
G25: =IF(C25="FALTA",0,IF(C25="ATESTADO",0.30555555556,IF(C25="folga",0,(F25-E25)+(D25-C25)))) -> 0
G26: =IF(C26="FALTA",0,IF(C26="ATESTADO",0.30555555556,IF(C26="folga",0,(F26-E26)+(D26-C26)))) -> 0
... G76: =IF(C76="FALTA",0,IF(C76="ATESTADO",0.30555555556,IF(C76="folga",0,(F76-E76)+(D76-C76)))) -> 0

Sheet ESCALA DE TRABALHO
E3: CONTROLE ESCALA DE TRABALHO
C8: 44409 | E8: =C8 -> 44409 | F8: =E8+1 -> 44410 | G8: =F8+1 -> 44411 | H8: =G8+1 -> 44412 | I8: =H8+1 -> 44413 | J8: =I8+1 -> 44414 | K8: =J8+1 -> 44415 | L8: =K8+1 -> 44416 | M8: =L8+1 -> 44417 | ... S8: =R8+1 -> 44423
E9: =TEXT(E8,"ddd") -> dom | F9: =TEXT(F8,"ddd") -> seg | G9: =TEXT(G8,"ddd") -> ter | H9: =TEXT(H8,"ddd") -> qua | I9: =TEXT(I8,"ddd") -> qui | J9: =TEXT(J8,"ddd") -> sex | K9: =TEXT(K8,"ddd") -> sáb | L9: =TEXT(L8,"ddd") -> dom | ... S9: =TEXT(S8,"ddd") -> dom
C10: DENILSON LORENÇO RIBEIRO | J10: =VLOOKUP($C$10,'CADASTRO FUNCIONARIO'!$B:$G,2,0) -> 0.3125 | K10: =VLOOKUP($C$10,'CADASTRO FUNCIONARIO'!$B:$G,3,0) -> 0.49166667 | L10: =VLOOKUP($C$10,'CADASTRO FUNCIONARIO'!$B:$G,4,0) -> 0.54166667 | M10: =VLOOKUP($C$10,'CADASTRO FUNCIONARIO'!$B:$G,5,0) -> 0.72916667
C18: =+C8 -> 44409 | E18: =S8+1 -> 44424 | F18: =E18+1 -> 44425 | G18: =F18+1 -> 44426 | H18: =G18+1 -> 44427 | I18: =H18+1 -> 44428 | J18: =I18+1 -> 44429 | K18: =J18+1 -> 44430 | L18: =K18+1 -> 44431 | M18: =L18+1 -> 44432 | ... T18: =S18+1 -> 44439
E19: =TEXT(E18,"ddd") -> seg | F19: =TEXT(F18,"ddd") -> ter | G19: =TEXT(G18,"ddd") -> qua | H19: =TEXT(H18,"ddd") -> qui | I19: =TEXT(I18,"ddd") -> sex | J19: =TEXT(J18,"ddd") -> sáb | K19: =TEXT(K18,"ddd") -> dom | L19: =TEXT(L18,"ddd") -> seg | ... T19: =TEXT(T18,"ddd") -> ter
C20: =+C10 -> DENILSON LORENÇO RIBEIRO | J20: =+J10 -> 0.3125 | K20: =+K10 -> 0.49166667 | L20: =+L10 -> 0.54166667 | M20: =+M10 -> 0.72916667
