Workbook

Sheet CAD_PROD
C5: Produto | D5: Preço de Venda | E5: Projeções de vendas mensais | F5: Receita bruta mensal | G5: % de Participação
B6: =IFERROR(F6+H6,0) -> 500 | C6: Produto 1 | D6: 50 | E6: 10 | F6: =IF(C6="","",D6*E6) -> 500 | G6: =IF(C6="","",F6/SUM($F$6:$F$505)) -> 0.020242915 | H6: 1e-06
B7: =IFERROR(F7+H7,0) -> 5400 | C7: Produto 2 | D7: 60 | E7: 90 | F7: =IF(C7="","",D7*E7) -> 5400 | G7: =IF(C7="","",F7/SUM($F$6:$F$505)) -> 0.21862348 | H7: 2e-06
B8: =IFERROR(F8+H8,0) -> 2100 | C8: Produto 3 | D8: 70 | E8: 30 | F8: =IF(C8="","",D8*E8) -> 2100 | G8: =IF(C8="","",F8/SUM($F$6:$F$505)) -> 0.085020243 | H8: 3e-06
B9: =IFERROR(F9+H9,0) -> 3200 | C9: Produto 4 | D9: 80 | E9: 40 | F9: =IF(C9="","",D9*E9) -> 3200 | G9: =IF(C9="","",F9/SUM($F$6:$F$505)) -> 0.12955466 | H9: 4e-06
B10: =IFERROR(F10+H10,0) -> 13500 | C10: Produto 5 | D10: 90 | E10: 150 | F10: =IF(C10="","",D10*E10) -> 13500 | G10: =IF(C10="","",F10/SUM($F$6:$F$505)) -> 0.5465587 | H10: 5e-06
B11: =IFERROR(F11+H11,0) -> 0 | F11: =IF(C11="","",D11*E11) | G11: =IF(C11="","",F11/SUM($F$6:$F$505)) | H11: 6e-06
B12: =IFERROR(F12+H12,0) -> 0 | F12: =IF(C12="","",D12*E12) | G12: =IF(C12="","",F12/SUM($F$6:$F$505)) | H12: 7e-06
B13: =IFERROR(F13+H13,0) -> 0 | F13: =IF(C13="","",D13*E13) | G13: =IF(C13="","",F13/SUM($F$6:$F$505)) | H13: 8e-06
B14: =IFERROR(F14+H14,0) -> 0 | F14: =IF(C14="","",D14*E14) | G14: =IF(C14="","",F14/SUM($F$6:$F$505)) | H14: 9e-06
B15: =IFERROR(F15+H15,0) -> 0 | F15: =IF(C15="","",D15*E15) | G15: =IF(C15="","",F15/SUM($F$6:$F$505)) | H15: 1e-05
B16: =IFERROR(F16+H16,0) -> 0 | F16: =IF(C16="","",D16*E16) | G16: =IF(C16="","",F16/SUM($F$6:$F$505)) | H16: 1.1e-05
B17: =IFERROR(F17+H17,0) -> 0 | F17: =IF(C17="","",D17*E17) | G17: =IF(C17="","",F17/SUM($F$6:$F$505)) | H17: 1.2e-05
B18: =IFERROR(F18+H18,0) -> 0 | F18: =IF(C18="","",D18*E18) | G18: =IF(C18="","",F18/SUM($F$6:$F$505)) | H18: 1.3e-05
B19: =IFERROR(F19+H19,0) -> 0 | F19: =IF(C19="","",D19*E19) | G19: =IF(C19="","",F19/SUM($F$6:$F$505)) | H19: 1.4e-05
B20: =IFERROR(F20+H20,0) -> 0 | F20: =IF(C20="","",D20*E20) | G20: =IF(C20="","",F20/SUM($F$6:$F$505)) | H20: 1.5e-05
B21: =IFERROR(F21+H21,0) -> 0 | F21: =IF(C21="","",D21*E21) | G21: =IF(C21="","",F21/SUM($F$6:$F$505)) | H21: 1.6e-05
B22: =IFERROR(F22+H22,0) -> 0 | F22: =IF(C22="","",D22*E22) | G22: =IF(C22="","",F22/SUM($F$6:$F$505)) | H22: 1.7e-05
... B505: =IFERROR(F505+H505,0) -> 0 | F505: =IF(C505="","",D505*E505) | G505: =IF(C505="","",F505/SUM($F$6:$F$505)) | H505: 0.0005

Sheet CAD_CUST
C5: Produto | D5: Matéria - Prima | E5: Comissões (%) | F5: Impostos (%) | G5: Outros gastos | H5: Total custo por produto | J5: Comissões | K5: Impostos | L5: Margem de contribuição unitária | M5: IMC (%) | N5: Receita no ponto de equilíbrio | O5: Cutos Fixos Proporcionais | P5: Quantidade a ser vendida | Q5: Outros Gastos | R5: Matéria Prima | S5: Atingiu?
A6: =IFERROR(L6+I6,0) -> 30.500001 | B6: =IFERROR(H6+I6,0) -> 19.500001 | C6: =IF(CAD_PROD!C6="","",CAD_PROD!C6) -> Produto 1 | D6: 9 | E6: 0.1 | F6: 0.01 | G6: 5 | H6: =IF(C6="","",D6+CAD_PROD!D6*(E6+F6)+G6) -> 19.5 | I6: 1e-06 | J6: =IF(ISERROR( CAD_PROD!F6*E6),"",CAD_PROD!F6*E6) -> 50 | K6: =IF(ISERROR( CAD_PROD!F6*F6),"",CAD_PROD!F6*F6) -> 5 | L6: =IF(ISERROR( CAD_PROD!D6-H6),"",CAD_PROD!D6-H6) -> 30.5 | M6: =IF(ISERROR( L6/CAD_PROD!D6),"",L6/CAD_PROD!D6) -> 0.61 | N6: =IF(ISERROR((P6*CAD_PROD!D6)),"",(P6*CAD_PROD!D6)) -> 450 | O6: =IF(ISERROR(PE_GERAL!$J$7*CAD_PROD!G6),"",PE_GERAL!$J$7*CAD_PROD!G6) -> 263.15789 | P6: =IF(ISERROR(ROUNDUP(O6/L6,0)),"",ROUNDUP(O6/L6,0)) -> 9 | Q6: =IF(C6="","",IF(ISERROR( CAD_PROD!E6*G6),"",CAD_PROD!E6*G6)) -> 50 | R6: =IF(C6="","",IF(ISERROR( CAD_PROD!E6*D6),"",CAD_PROD!E6*D6)) -> 90 | S6: =IF(C6="","",IF(CAD_PROD!E6>=P6,"Sim","Não")) -> Sim
A7: =IFERROR(L7+I7,0) -> 32.200001 | B7: =IFERROR(H7+I7,0) -> 27.800001 | C7: =IF(CAD_PROD!C7="","",CAD_PROD!C7) -> Produto 2 | D7: 10 | E7: 0.11 | F7: 0.02 | G7: 10 | H7: =IF(C7="","",D7+CAD_PROD!D7*(E7+F7)+G7) -> 27.8 | I7: 1e-06 | J7: =IF(ISERROR( CAD_PROD!F7*E7),"",CAD_PROD!F7*E7) -> 594 | K7: =IF(ISERROR( CAD_PROD!F7*F7),"",CAD_PROD!F7*F7) -> 108 | L7: =IF(ISERROR( CAD_PROD!D7-H7),"",CAD_PROD!D7-H7) -> 32.2 | M7: =IF(ISERROR( L7/CAD_PROD!D7),"",L7/CAD_PROD!D7) -> 0.53666667 | N7: =IF(ISERROR( (P7*CAD_PROD!D7)),"",(P7*CAD_PROD!D7)) -> 5340 | O7: =IF(ISERROR(PE_GERAL!$J$7*CAD_PROD!G7),"",PE_GERAL!$J$7*CAD_PROD!G7) -> 2842.1053 | P7: =IF(ISERROR(ROUNDUP(O7/L7,0)),"",ROUNDUP(O7/L7,0)) -> 89 | Q7: =IF(C7="","",IF(ISERROR( CAD_PROD!E7*G7),"",CAD_PROD!E7*G7)) -> 900 | R7: =IF(C7="","",IF(ISERROR( CAD_PROD!E7*D7),"",CAD_PROD!E7*D7)) -> 900 | S7: =IF(C7="","",IF(CAD_PROD!E7>=P7,"Sim","Não")) -> Sim
A8: =IFERROR(L8+I8,0) -> 33.500001 | B8: =IFERROR(H8+I8,0) -> 36.500001 | C8: =IF(CAD_PROD!C8="","",CAD_PROD!C8) -> Produto 3 | D8: 11 | E8: 0.12 | F8: 0.03 | G8: 15 | H8: =IF(C8="","",D8+CAD_PROD!D8*(E8+F8)+G8) -> 36.5 | I8: 1e-06 | J8: =IF(ISERROR( CAD_PROD!F8*E8),"",CAD_PROD!F8*E8) -> 252 | K8: =IF(ISERROR( CAD_PROD!F8*F8),"",CAD_PROD!F8*F8) -> 63 | L8: =IF(ISERROR( CAD_PROD!D8-H8),"",CAD_PROD!D8-H8) -> 33.5 | M8: =IF(ISERROR( L8/CAD_PROD!D8),"",L8/CAD_PROD!D8) -> 0.47857143 | N8: =IF(ISERROR( (P8*CAD_PROD!D8)),"",(P8*CAD_PROD!D8)) -> 2310 | O8: =IF(ISERROR(PE_GERAL!$J$7*CAD_PROD!G8),"",PE_GERAL!$J$7*CAD_PROD!G8) -> 1105.2632 | P8: =IF(ISERROR(ROUNDUP(O8/L8,0)),"",ROUNDUP(O8/L8,0)) -> 33 | Q8: =IF(C8="","",IF(ISERROR( CAD_PROD!E8*G8),"",CAD_PROD!E8*G8)) -> 450 | R8: =IF(C8="","",IF(ISERROR( CAD_PROD!E8*D8),"",CAD_PROD!E8*D8)) -> 330 | S8: =IF(C8="","",IF(CAD_PROD!E8>=P8,"Sim","Não")) -> Não
A9: =IFERROR(L9+I9,0) -> 34.400001 | B9: =IFERROR(H9+I9,0) -> 45.600001 | C9: =IF(CAD_PROD!C9="","",CAD_PROD!C9) -> Produto 4 | D9: 12 | E9: 0.13 | F9: 0.04 | G9: 20 | H9: =IF(C9="","",D9+CAD_PROD!D9*(E9+F9)+G9) -> 45.6 | I9: 1e-06 | J9: =IF(ISERROR( CAD_PROD!F9*E9),"",CAD_PROD!F9*E9) -> 416 | K9: =IF(ISERROR( CAD_PROD!F9*F9),"",CAD_PROD!F9*F9) -> 128 | L9: =IF(ISERROR( CAD_PROD!D9-H9),"",CAD_PROD!D9-H9) -> 34.4 | M9: =IF(ISERROR( L9/CAD_PROD!D9),"",L9/CAD_PROD!D9) -> 0.43 | N9: =IF(ISERROR( (P9*CAD_PROD!D9)),"",(P9*CAD_PROD!D9)) -> 3920 | O9: =IF(ISERROR(PE_GERAL!$J$7*CAD_PROD!G9),"",PE_GERAL!$J$7*CAD_PROD!G9) -> 1684.2105 | P9: =IF(ISERROR(ROUNDUP(O9/L9,0)),"",ROUNDUP(O9/L9,0)) -> 49 | Q9: =IF(C9="","",IF(ISERROR( CAD_PROD!E9*G9),"",CAD_PROD!E9*G9)) -> 800 | R9: =IF(C9="","",IF(ISERROR( CAD_PROD!E9*D9),"",CAD_PROD!E9*D9)) -> 480 | S9: =IF(C9="","",IF(CAD_PROD!E9>=P9,"Sim","Não")) -> Não
A10: =IFERROR(L10+I10,0) -> 34.900001 | B10: =IFERROR(H10+I10,0) -> 55.100001 | C10: =IF(CAD_PROD!C10="","",CAD_PROD!C10) -> Produto 5 | D10: 13 | E10: 0.14 | F10: 0.05 | G10: 25 | H10: =IF(C10="","",D10+CAD_PROD!D10*(E10+F10)+G10) -> 55.1 | I10: 1e-06 | J10: =IF(ISERROR( CAD_PROD!F10*E10),"",CAD_PROD!F10*E10) -> 1890 | K10: =IF(ISERROR( CAD_PROD!F10*F10),"",CAD_PROD!F10*F10) -> 675 | L10: =IF(ISERROR( CAD_PROD!D10-H10),"",CAD_PROD!D10-H10) -> 34.9 | M10: =IF(ISERROR( L10/CAD_PROD!D10),"",L10/CAD_PROD!D10) -> 0.38777778 | N10: =IF(ISERROR( (P10*CAD_PROD!D10)),"",(P10*CAD_PROD!D10)) -> 18360 | O10: =IF(ISERROR(PE_GERAL!$J$7*CAD_PROD!G10),"",PE_GERAL!$J$7*CAD_PROD!G10) -> 7105.2632 | P10: =IF(ISERROR(ROUNDUP(O10/L10,0)),"",ROUNDUP(O10/L10,0)) -> 204 | Q10: =IF(C10="","",IF(ISERROR( CAD_PROD!E10*G10),"",CAD_PROD!E10*G10)) -> 3750 | R10: =IF(C10="","",IF(ISERROR( CAD_PROD!E10*D10),"",CAD_PROD!E10*D10)) -> 1950 | S10: =IF(C10="","",IF(CAD_PROD!E10>=P10,"Sim","Não")) -> Não
A11: =IFERROR(L11+I11,0) -> 0 | B11: =IFERROR(H11+I11,0) -> 0 | C11: =IF(CAD_PROD!C11="","",CAD_PROD!C11) | H11: =IF(C11="","",D11+CAD_PROD!D11*(E11+F11)+G11) | I11: 1e-06 | J11: =IF(ISERROR( CAD_PROD!F11*E11),"",CAD_PROD!F11*E11) | K11: =IF(ISERROR( CAD_PROD!F11*F11),"",CAD_PROD!F11*F11) | L11: =IF(ISERROR( CAD_PROD!D11-H11),"",CAD_PROD!D11-H11) | M11: =IF(ISERROR( L11/CAD_PROD!D11),"",L11/CAD_PROD!D11) | N11: =IF(ISERROR( (P11*CAD_PROD!D11)),"",(P11*CAD_PROD!D11)) | O11: =IF(ISERROR(PE_GERAL!$J$7*CAD_PROD!G11),"",PE_GERAL!$J$7*CAD_PROD!G11) | P11: =IF(ISERROR(ROUNDUP(O11/L11,0)),"",ROUNDUP(O11/L11,0)) | Q11: =IF(C11="","",IF(ISERROR( CAD_PROD!E11*G11),"",CAD_PROD!E11*G11)) | R11: =IF(C11="","",IF(ISERROR( CAD_PROD!E11*D11),"",CAD_PROD!E11*D11)) | S11: =IF(C11="","",IF(CAD_PROD!E11>=P11,"Sim","Não"))
A12: =IFERROR(L12+I12,0) -> 0 | B12: =IFERROR(H12+I12,0) -> 0 | C12: =IF(CAD_PROD!C12="","",CAD_PROD!C12) | H12: =IF(C12="","",D12+CAD_PROD!D12*(E12+F12)+G12) | I12: 1e-06 | J12: =IF(ISERROR( CAD_PROD!F12*E12),"",CAD_PROD!F12*E12) | K12: =IF(ISERROR( CAD_PROD!F12*F12),"",CAD_PROD!F12*F12) | L12: =IF(ISERROR( CAD_PROD!D12-H12),"",CAD_PROD!D12-H12) | M12: =IF(ISERROR( L12/CAD_PROD!D12),"",L12/CAD_PROD!D12) | N12: =IF(ISERROR( (P12*CAD_PROD!D12)),"",(P12*CAD_PROD!D12)) | O12: =IF(ISERROR(PE_GERAL!$J$7*CAD_PROD!G12),"",PE_GERAL!$J$7*CAD_PROD!G12) | P12: =IF(ISERROR(ROUNDUP(O12/L12,0)),"",ROUNDUP(O12/L12,0)) | Q12: =IF(C12="","",IF(ISERROR( CAD_PROD!E12*G12),"",CAD_PROD!E12*G12)) | R12: =IF(C12="","",IF(ISERROR( CAD_PROD!E12*D12),"",CAD_PROD!E12*D12)) | S12: =IF(C12="","",IF(CAD_PROD!E12>=P12,"Sim","Não"))
A13: =IFERROR(L13+I13,0) -> 0 | B13: =IFERROR(H13+I13,0) -> 0 | C13: =IF(CAD_PROD!C13="","",CAD_PROD!C13) | H13: =IF(C13="","",D13+CAD_PROD!D13*(E13+F13)+G13) | I13: 1e-06 | J13: =IF(ISERROR( CAD_PROD!F13*E13),"",CAD_PROD!F13*E13) | K13: =IF(ISERROR( CAD_PROD!F13*F13),"",CAD_PROD!F13*F13) | L13: =IF(ISERROR( CAD_PROD!D13-H13),"",CAD_PROD!D13-H13) | M13: =IF(ISERROR( L13/CAD_PROD!D13),"",L13/CAD_PROD!D13) | N13: =IF(ISERROR( (P13*CAD_PROD!D13)),"",(P13*CAD_PROD!D13)) | O13: =IF(ISERROR(PE_GERAL!$J$7*CAD_PROD!G13),"",PE_GERAL!$J$7*CAD_PROD!G13) | P13: =IF(ISERROR(ROUNDUP(O13/L13,0)),"",ROUNDUP(O13/L13,0)) | Q13: =IF(C13="","",IF(ISERROR( CAD_PROD!E13*G13),"",CAD_PROD!E13*G13)) | R13: =IF(C13="","",IF(ISERROR( CAD_PROD!E13*D13),"",CAD_PROD!E13*D13)) | S13: =IF(C13="","",IF(CAD_PROD!E13>=P13,"Sim","Não"))
A14: =IFERROR(L14+I14,0) -> 0 | B14: =IFERROR(H14+I14,0) -> 0 | C14: =IF(CAD_PROD!C14="","",CAD_PROD!C14) | H14: =IF(C14="","",D14+CAD_PROD!D14*(E14+F14)+G14) | I14: 1e-06 | J14: =IF(ISERROR( CAD_PROD!F14*E14),"",CAD_PROD!F14*E14) | K14: =IF(ISERROR( CAD_PROD!F14*F14),"",CAD_PROD!F14*F14) | L14: =IF(ISERROR( CAD_PROD!D14-H14),"",CAD_PROD!D14-H14) | M14: =IF(ISERROR( L14/CAD_PROD!D14),"",L14/CAD_PROD!D14) | N14: =IF(ISERROR( (P14*CAD_PROD!D14)),"",(P14*CAD_PROD!D14)) | O14: =IF(ISERROR(PE_GERAL!$J$7*CAD_PROD!G14),"",PE_GERAL!$J$7*CAD_PROD!G14) | P14: =IF(ISERROR(ROUNDUP(O14/L14,0)),"",ROUNDUP(O14/L14,0)) | Q14: =IF(C14="","",IF(ISERROR( CAD_PROD!E14*G14),"",CAD_PROD!E14*G14)) | R14: =IF(C14="","",IF(ISERROR( CAD_PROD!E14*D14),"",CAD_PROD!E14*D14)) | S14: =IF(C14="","",IF(CAD_PROD!E14>=P14,"Sim","Não"))
A15: =IFERROR(L15+I15,0) -> 0 | B15: =IFERROR(H15+I15,0) -> 0 | C15: =IF(CAD_PROD!C15="","",CAD_PROD!C15) | H15: =IF(C15="","",D15+CAD_PROD!D15*(E15+F15)+G15) | I15: 1e-06 | J15: =IF(ISERROR( CAD_PROD!F15*E15),"",CAD_PROD!F15*E15) | K15: =IF(ISERROR( CAD_PROD!F15*F15),"",CAD_PROD!F15*F15) | L15: =IF(ISERROR( CAD_PROD!D15-H15),"",CAD_PROD!D15-H15) | M15: =IF(ISERROR( L15/CAD_PROD!D15),"",L15/CAD_PROD!D15) | N15: =IF(ISERROR( (P15*CAD_PROD!D15)),"",(P15*CAD_PROD!D15)) | O15: =IF(ISERROR(PE_GERAL!$J$7*CAD_PROD!G15),"",PE_GERAL!$J$7*CAD_PROD!G15) | P15: =IF(ISERROR(ROUNDUP(O15/L15,0)),"",ROUNDUP(O15/L15,0)) | Q15: =IF(C15="","",IF(ISERROR( CAD_PROD!E15*G15),"",CAD_PROD!E15*G15)) | R15: =IF(C15="","",IF(ISERROR( CAD_PROD!E15*D15),"",CAD_PROD!E15*D15)) | S15: =IF(C15="","",IF(CAD_PROD!E15>=P15,"Sim","Não"))
A16: =IFERROR(L16+I16,0) -> 0 | B16: =IFERROR(H16+I16,0) -> 0 | C16: =IF(CAD_PROD!C16="","",CAD_PROD!C16) | H16: =IF(C16="","",D16+CAD_PROD!D16*(E16+F16)+G16) | I16: 1e-06 | J16: =IF(ISERROR( CAD_PROD!F16*E16),"",CAD_PROD!F16*E16) | K16: =IF(ISERROR( CAD_PROD!F16*F16),"",CAD_PROD!F16*F16) | L16: =IF(ISERROR( CAD_PROD!D16-H16),"",CAD_PROD!D16-H16) | M16: =IF(ISERROR( L16/CAD_PROD!D16),"",L16/CAD_PROD!D16) | N16: =IF(ISERROR( (P16*CAD_PROD!D16)),"",(P16*CAD_PROD!D16)) | O16: =IF(ISERROR(PE_GERAL!$J$7*CAD_PROD!G16),"",PE_GERAL!$J$7*CAD_PROD!G16) | P16: =IF(ISERROR(ROUNDUP(O16/L16,0)),"",ROUNDUP(O16/L16,0)) | Q16: =IF(C16="","",IF(ISERROR( CAD_PROD!E16*G16),"",CAD_PROD!E16*G16)) | R16: =IF(C16="","",IF(ISERROR( CAD_PROD!E16*D16),"",CAD_PROD!E16*D16)) | S16: =IF(C16="","",IF(CAD_PROD!E16>=P16,"Sim","Não"))
A17: =IFERROR(L17+I17,0) -> 0 | B17: =IFERROR(H17+I17,0) -> 0 | C17: =IF(CAD_PROD!C17="","",CAD_PROD!C17) | H17: =IF(C17="","",D17+CAD_PROD!D17*(E17+F17)+G17) | I17: 1e-06 | J17: =IF(ISERROR( CAD_PROD!F17*E17),"",CAD_PROD!F17*E17) | K17: =IF(ISERROR( CAD_PROD!F17*F17),"",CAD_PROD!F17*F17) | L17: =IF(ISERROR( CAD_PROD!D17-H17),"",CAD_PROD!D17-H17) | M17: =IF(ISERROR( L17/CAD_PROD!D17),"",L17/CAD_PROD!D17) | N17: =IF(ISERROR( (P17*CAD_PROD!D17)),"",(P17*CAD_PROD!D17)) | O17: =IF(ISERROR(PE_GERAL!$J$7*CAD_PROD!G17),"",PE_GERAL!$J$7*CAD_PROD!G17) | P17: =IF(ISERROR(ROUNDUP(O17/L17,0)),"",ROUNDUP(O17/L17,0)) | Q17: =IF(C17="","",IF(ISERROR( CAD_PROD!E17*G17),"",CAD_PROD!E17*G17)) | R17: =IF(C17="","",IF(ISERROR( CAD_PROD!E17*D17),"",CAD_PROD!E17*D17)) | S17: =IF(C17="","",IF(CAD_PROD!E17>=P17,"Sim","Não"))
A18: =IFERROR(L18+I18,0) -> 0 | B18: =IFERROR(H18+I18,0) -> 0 | C18: =IF(CAD_PROD!C18="","",CAD_PROD!C18) | H18: =IF(C18="","",D18+CAD_PROD!D18*(E18+F18)+G18) | I18: 1e-06 | J18: =IF(ISERROR( CAD_PROD!F18*E18),"",CAD_PROD!F18*E18) | K18: =IF(ISERROR( CAD_PROD!F18*F18),"",CAD_PROD!F18*F18) | L18: =IF(ISERROR( CAD_PROD!D18-H18),"",CAD_PROD!D18-H18) | M18: =IF(ISERROR( L18/CAD_PROD!D18),"",L18/CAD_PROD!D18) | N18: =IF(ISERROR( (P18*CAD_PROD!D18)),"",(P18*CAD_PROD!D18)) | O18: =IF(ISERROR(PE_GERAL!$J$7*CAD_PROD!G18),"",PE_GERAL!$J$7*CAD_PROD!G18) | P18: =IF(ISERROR(ROUNDUP(O18/L18,0)),"",ROUNDUP(O18/L18,0)) | Q18: =IF(C18="","",IF(ISERROR( CAD_PROD!E18*G18),"",CAD_PROD!E18*G18)) | R18: =IF(C18="","",IF(ISERROR( CAD_PROD!E18*D18),"",CAD_PROD!E18*D18)) | S18: =IF(C18="","",IF(CAD_PROD!E18>=P18,"Sim","Não"))
A19: =IFERROR(L19+I19,0) -> 0 | B19: =IFERROR(H19+I19,0) -> 0 | C19: =IF(CAD_PROD!C19="","",CAD_PROD!C19) | H19: =IF(C19="","",D19+CAD_PROD!D19*(E19+F19)+G19) | I19: 1e-06 | J19: =IF(ISERROR( CAD_PROD!F19*E19),"",CAD_PROD!F19*E19) | K19: =IF(ISERROR( CAD_PROD!F19*F19),"",CAD_PROD!F19*F19) | L19: =IF(ISERROR( CAD_PROD!D19-H19),"",CAD_PROD!D19-H19) | M19: =IF(ISERROR( L19/CAD_PROD!D19),"",L19/CAD_PROD!D19) | N19: =IF(ISERROR( (P19*CAD_PROD!D19)),"",(P19*CAD_PROD!D19)) | O19: =IF(ISERROR(PE_GERAL!$J$7*CAD_PROD!G19),"",PE_GERAL!$J$7*CAD_PROD!G19) | P19: =IF(ISERROR(ROUNDUP(O19/L19,0)),"",ROUNDUP(O19/L19,0)) | Q19: =IF(C19="","",IF(ISERROR( CAD_PROD!E19*G19),"",CAD_PROD!E19*G19)) | R19: =IF(C19="","",IF(ISERROR( CAD_PROD!E19*D19),"",CAD_PROD!E19*D19)) | S19: =IF(C19="","",IF(CAD_PROD!E19>=P19,"Sim","Não"))
A20: =IFERROR(L20+I20,0) -> 0 | B20: =IFERROR(H20+I20,0) -> 0 | C20: =IF(CAD_PROD!C20="","",CAD_PROD!C20) | H20: =IF(C20="","",D20+CAD_PROD!D20*(E20+F20)+G20) | I20: 1e-06 | J20: =IF(ISERROR( CAD_PROD!F20*E20),"",CAD_PROD!F20*E20) | K20: =IF(ISERROR( CAD_PROD!F20*F20),"",CAD_PROD!F20*F20) | L20: =IF(ISERROR( CAD_PROD!D20-H20),"",CAD_PROD!D20-H20) | M20: =IF(ISERROR( L20/CAD_PROD!D20),"",L20/CAD_PROD!D20) | N20: =IF(ISERROR( (P20*CAD_PROD!D20)),"",(P20*CAD_PROD!D20)) | O20: =IF(ISERROR(PE_GERAL!$J$7*CAD_PROD!G20),"",PE_GERAL!$J$7*CAD_PROD!G20) | P20: =IF(ISERROR(ROUNDUP(O20/L20,0)),"",ROUNDUP(O20/L20,0)) | Q20: =IF(C20="","",IF(ISERROR( CAD_PROD!E20*G20),"",CAD_PROD!E20*G20)) | R20: =IF(C20="","",IF(ISERROR( CAD_PROD!E20*D20),"",CAD_PROD!E20*D20)) | S20: =IF(C20="","",IF(CAD_PROD!E20>=P20,"Sim","Não"))
A21: =IFERROR(L21+I21,0) -> 0 | B21: =IFERROR(H21+I21,0) -> 0 | C21: =IF(CAD_PROD!C21="","",CAD_PROD!C21) | H21: =IF(C21="","",D21+CAD_PROD!D21*(E21+F21)+G21) | I21: 1e-06 | J21: =IF(ISERROR( CAD_PROD!F21*E21),"",CAD_PROD!F21*E21) | K21: =IF(ISERROR( CAD_PROD!F21*F21),"",CAD_PROD!F21*F21) | L21: =IF(ISERROR( CAD_PROD!D21-H21),"",CAD_PROD!D21-H21) | M21: =IF(ISERROR( L21/CAD_PROD!D21),"",L21/CAD_PROD!D21) | N21: =IF(ISERROR( (P21*CAD_PROD!D21)),"",(P21*CAD_PROD!D21)) | O21: =IF(ISERROR(PE_GERAL!$J$7*CAD_PROD!G21),"",PE_GERAL!$J$7*CAD_PROD!G21) | P21: =IF(ISERROR(ROUNDUP(O21/L21,0)),"",ROUNDUP(O21/L21,0)) | Q21: =IF(C21="","",IF(ISERROR( CAD_PROD!E21*G21),"",CAD_PROD!E21*G21)) | R21: =IF(C21="","",IF(ISERROR( CAD_PROD!E21*D21),"",CAD_PROD!E21*D21)) | S21: =IF(C21="","",IF(CAD_PROD!E21>=P21,"Sim","Não"))
A22: =IFERROR(L22+I22,0) -> 0 | B22: =IFERROR(H22+I22,0) -> 0 | C22: =IF(CAD_PROD!C22="","",CAD_PROD!C22) | H22: =IF(C22="","",D22+CAD_PROD!D22*(E22+F22)+G22) | I22: 1e-06 | J22: =IF(ISERROR( CAD_PROD!F22*E22),"",CAD_PROD!F22*E22) | K22: =IF(ISERROR( CAD_PROD!F22*F22),"",CAD_PROD!F22*F22) | L22: =IF(ISERROR( CAD_PROD!D22-H22),"",CAD_PROD!D22-H22) | M22: =IF(ISERROR( L22/CAD_PROD!D22),"",L22/CAD_PROD!D22) | N22: =IF(ISERROR( (P22*CAD_PROD!D22)),"",(P22*CAD_PROD!D22)) | O22: =IF(ISERROR(PE_GERAL!$J$7*CAD_PROD!G22),"",PE_GERAL!$J$7*CAD_PROD!G22) | P22: =IF(ISERROR(ROUNDUP(O22/L22,0)),"",ROUNDUP(O22/L22,0)) | Q22: =IF(C22="","",IF(ISERROR( CAD_PROD!E22*G22),"",CAD_PROD!E22*G22)) | R22: =IF(C22="","",IF(ISERROR( CAD_PROD!E22*D22),"",CAD_PROD!E22*D22)) | S22: =IF(C22="","",IF(CAD_PROD!E22>=P22,"Sim","Não"))
... A505: =IFERROR(L505+I505,0) -> 0 | B505: =IFERROR(H505+I505,0) -> 0 | C505: =IF(CAD_PROD!C505="","",CAD_PROD!C505) | H505: =IF(C505="","",D505+CAD_PROD!D505*(E505+F505)+G505) | I505: 1e-06 | J505: =IF(ISERROR( CAD_PROD!F505*E505),"",CAD_PROD!F505*E505) | K505: =IF(ISERROR( CAD_PROD!F505*F505),"",CAD_PROD!F505*F505) | L505: =IF(ISERROR( CAD_PROD!D505-H505),"",CAD_PROD!D505-H505) | M505: =IF(ISERROR( L505/CAD_PROD!D505),"",L505/CAD_PROD!D505) | N505: =IF(ISERROR( (P505*CAD_PROD!D505)),"",(P505*CAD_PROD!D505)) | O505: =IF(ISERROR(PE_GERAL!$J$7*CAD_PROD!G505),"",PE_GERAL!$J$7*CAD_PROD!G505) | P505: =IF(ISERROR(ROUNDUP(O505/L505,0)),"",ROUNDUP(O505/L505,0)) | Q505: =IF(C505="","",IF(ISERROR( CAD_PROD!E505*G505),"",CAD_PROD!E505*G505)) | R505: =IF(C505="","",IF(ISERROR( CAD_PROD!E505*D505),"",CAD_PROD!E505*D505)) | S505: =IF(C505="","",IF(CAD_PROD!E505>=P505,"Sim","Não"))

Sheet PE_GERAL
C5: Custo Fixo | D5: Valor Mensal | F5: Margem de contribuição | I5: Ponto de Equilíbrio (Break Even Point)
B6: =IF(C6="",0,D6+E6) -> 10000 | C6: Custo 1 | D6: 10000 | E6: 1e-06 | F6: Descrição | G6: Valor (R$) | I6: Descrição | J6: Valor (R$)
B7: =IF(C7="",0,D7+E7) -> 600 | C7: Custo 2 | D7: 600 | E7: 2e-06 | F7: Preço de venda médio dos seus produtos | G7: =IF(ISERROR(SUMPRODUCT(CAD_PROD!D6:D506,CAD_PROD!E6:E506)/SUM(CAD_PROD!E6:E506)),"",SUMPRODUCT(CAD_PROD!D6:D506,CAD_PROD!E6:E506)/SUM(CAD_PROD!E6:E506)) -> 77.1875 | I7: Qual o valor total dos seus custos fixos mensal? | J7: =SUM(D6:D50) -> 13000
B8: =IF(C8="",0,D8+E8) -> 700 | C8: Custo 3 | D8: 700 | E8: 3e-06
B9: =IF(C9="",0,D9+E9) -> 800 | C9: Custo 4 | D9: 800 | E9: 4e-06
B10: =IF(C10="",0,D10+E10) -> 900 | C10: Custo 5 | D10: 900 | E10: 5e-06 | F10: Margem de contribuição média dos seus produtos | G10: =IF(ISERROR(SUMPRODUCT(CAD_CUST!L6:L505,CAD_PROD!E6:E505)/SUM(CAD_PROD!E6:E505)),"",SUMPRODUCT(CAD_CUST!L6:L505,CAD_PROD!E6:E505)/SUM(CAD_PROD!E6:E505)) -> 33.809375 | I10: Qual deve ser o faturamento mensal para não ter prejuízo? | J10: =IF(ISERROR(J7/(G10/G7)),"",J7/(G10/G7)) -> 29679.268
B11: =IF(C11="",0,D11+E11) -> 0 | E11: 6e-06
B12: =IF(C12="",0,D12+E12) -> 0 | E12: 7e-06
B13: =IF(C13="",0,D13+E13) -> 0 | E13: 8e-06 | F13: Custos diretos totais na projeção de vendas | G13: =IF(ISERROR(SUMPRODUCT(CAD_CUST!$H$6:$H$505,CAD_PROD!E6:E505)),"",SUMPRODUCT(CAD_CUST!$H$6:$H$505,CAD_PROD!E6:E505)) -> 13881 | I13: Quantos produtos em média você precisa vender para não ter prejuízo? | J13: =IF(ISERROR(J10/G7),"",J10/G7) -> 384.50873
B14: =IF(C14="",0,D14+E14) -> 0 | E14: 9e-06 | F14: Custos diretos médio por produto | G14: =G13/SUM(CAD_PROD!C6:E505) -> 20.71791
B15: =IF(C15="",0,D15+E15) -> 0 | E15: 1e-05
B16: =IF(C16="",0,D16+E16) -> 0 | E16: 1.1e-05
B17: =IF(C17="",0,D17+E17) -> 0 | E17: 1.2e-05
B18: =IF(C18="",0,D18+E18) -> 0 | E18: 1.3e-05
B19: =IF(C19="",0,D19+E19) -> 0 | E19: 1.4e-05
B20: =IF(C20="",0,D20+E20) -> 0 | E20: 1.5e-05
B21: =IF(C21="",0,D21+E21) -> 0 | E21: 1.6e-05
B22: =IF(C22="",0,D22+E22) -> 0 | E22: 1.7e-05
B23: =IF(C23="",0,D23+E23) -> 0 | E23: 1.8e-05
B24: =IF(C24="",0,D24+E24) -> 0 | E24: 1.9e-05
B25: =IF(C25="",0,D25+E25) -> 0 | E25: 2e-05
B26: =IF(C26="",0,D26+E26) -> 0 | E26: 2.1e-05
... B505: =IF(C505="",0,D505+E505) -> 0 | E505: 0.0005

Sheet PE_PROD
C5: Selecione o seu produto | D5: Produto 1
C7: Preço de Venda | D7: =IFERROR(VLOOKUP(D5,CAD_PROD!$C$6:$O$505,2,FALSE),"") -> 50 | F7: Unidades vendidas no Ponto de Equilíbrio | G7: =IFERROR(D10/D9,"") -> 8.6281277
C8: Despesas Diretas | D8: =IFERROR(VLOOKUP(D5,CAD_CUST!$C$6:$P$505,6,FALSE),"") -> 19.5 | F8: Receita no Ponto de Equilíbrio | G8: =IFERROR(G7*D7,"") -> 431.40638
C9: Margem de Contribuição Unitária | D9: =IF(ISERROR( VLOOKUP(D5,CAD_CUST!$C$6:$L$505,10,0)),"",VLOOKUP(D5,CAD_CUST!$C$6:$L$505,10,0)) -> 30.5 | F9: Vendas Projetadas | G9: =IFERROR(VLOOKUP(D5,CAD_PROD!$C$6:$O$505,3,FALSE),"") -> 10
C10: Total de custos fixos proporcionais à projeção de vendas | D10: =IFERROR(VLOOKUP(D5,CAD_CUST!$C$6:$P$505,13,FALSE),"") -> 263.15789 | F10: Atingirá o Ponto de Equilíbrio se alcançar as vendas projetadas? | G10: =IFERROR(VLOOKUP(D5,CAD_CUST!$C$6:$S$505,17,FALSE),"") -> Sim

Sheet ANA_CONC
B5: 0 | C5: Empresa | D5: Diferencial | E5: Produto | F5: Preço Concorrente | G5: Seu Preço | H5: Orientação
B6: =IF(E6=TOP_CONC!$D$5,B5+1,B5) -> 0 | C6: Concorrente 1 | D6: Qualidade | E6: Produto 1 | F6: 60 | G6: =IF(ISERROR( IF(C6="","",IFERROR(VLOOKUP(E6,CAD_PROD!$C$6:$D$506,2,0),""))),"",IF(C6="","",IFERROR(VLOOKUP(E6,CAD_PROD!$C$6:$D$506,2,0),""))) -> 50 | H6: =IF(ISERROR( IF(C6="","", IF(F6<G6,"Seu preço está acima do seu concorrente. Você precisa encontrar meios como qualidade, localização, etc, para justificar esta diferença.",IF(F6>G6,"Seu preço está abaixo do seu concorrente. Mas ele se posiciona pelo(a) "&D6&". Fique atento sobre este detalhe, pois preço baixo não é garantia de sucesso.","Seu preço está igual ao do seu concorrente. Ele se posiciona pela "&D6&". Se você conseguir se posicionar melhor que ele nesse atributo, poderá estar em vantagem.")))),"", IF(C6="","", IF(F6<G6,"Seu preço está acima do seu concorrente. Você precisa encontrar meios como qualidade, localização, etc, para justificar esta diferença.",IF(F6>G6,"Seu preço está abaixo do seu concorrente. Mas ele se posiciona pelo(a) "&D6&". Fique atento sobre este detalhe, pois preço baixo não é garantia de sucesso.","Seu preço está igual ao do seu concorrente. Ele se posiciona pela "&D6&". Se você conseguir se posicionar melhor que ele nesse atributo, poderá estar em vantagem.")))) -> Seu preço está abaixo do seu concorrente. Mas ele se posiciona pelo(a) Qualidade. Fique atento sobre este detalhe, pois preço baixo não é garantia de sucesso.
B7: =IF(E7=TOP_CONC!$D$5,B6+1,B6) -> 1 | C7: Concorrente 2 | D7: Qualidade | E7: Produto 2 | F7: 70 | G7: =IF(ISERROR( IF(C7="","",IFERROR(VLOOKUP(E7,CAD_PROD!$C$6:$D$506,2,0),""))),"",IF(C7="","",IFERROR(VLOOKUP(E7,CAD_PROD!$C$6:$D$506,2,0),""))) -> 60 | H7: =IF(ISERROR( IF(C7="","", IF(F7<G7,"Seu preço está acima do seu concorrente. Você precisa encontrar meios como qualidade, localização, etc, para justificar esta diferença.",IF(F7>G7,"Seu preço está abaixo do seu concorrente. Mas ele se posiciona pelo(a) "&D7&". Fique atento sobre este detalhe, pois preço baixo não é garantia de sucesso.","Seu preço está igual ao do seu concorrente. Ele se posiciona pela "&D7&". Se você conseguir se posicionar melhor que ele nesse atributo, poderá estar em vantagem.")))),"", IF(C7="","", IF(F7<G7,"Seu preço está acima do seu concorrente. Você precisa encontrar meios como qualidade, localização, etc, para justificar esta diferença.",IF(F7>G7,"Seu preço está abaixo do seu concorrente. Mas ele se posiciona pelo(a) "&D7&". Fique atento sobre este detalhe, pois preço baixo não é garantia de sucesso.","Seu preço está igual ao do seu concorrente. Ele se posiciona pela "&D7&". Se você conseguir se posicionar melhor que ele nesse atributo, poderá estar em vantagem.")))) -> Seu preço está abaixo do seu concorrente. Mas ele se posiciona pelo(a) Qualidade. Fique atento sobre este detalhe, pois preço baixo não é garantia de sucesso.
B8: =IF(E8=TOP_CONC!$D$5,B7+1,B7) -> 1 | C8: Concorrente 3 | D8: Qualidade | E8: Produto 3 | F8: 60 | G8: =IF(ISERROR( IF(C8="","",IFERROR(VLOOKUP(E8,CAD_PROD!$C$6:$D$506,2,0),""))),"",IF(C8="","",IFERROR(VLOOKUP(E8,CAD_PROD!$C$6:$D$506,2,0),""))) -> 70 | H8: =IF(ISERROR( IF(C8="","", IF(F8<G8,"Seu preço está acima do seu concorrente. Você precisa encontrar meios como qualidade, localização, etc, para justificar esta diferença.",IF(F8>G8,"Seu preço está abaixo do seu concorrente. Mas ele se posiciona pelo(a) "&D8&". Fique atento sobre este detalhe, pois preço baixo não é garantia de sucesso.","Seu preço está igual ao do seu concorrente. Ele se posiciona pela "&D8&". Se você conseguir se posicionar melhor que ele nesse atributo, poderá estar em vantagem.")))),"", IF(C8="","", IF(F8<G8,"Seu preço está acima do seu concorrente. Você precisa encontrar meios como qualidade, localização, etc, para justificar esta diferença.",IF(F8>G8,"Seu preço está abaixo do seu concorrente. Mas ele se posiciona pelo(a) "&D8&". Fique atento sobre este detalhe, pois preço baixo não é garantia de sucesso.","Seu preço está igual ao do seu concorrente. Ele se posiciona pela "&D8&". Se você conseguir se posicionar melhor que ele nesse atributo, poderá estar em vantagem.")))) -> Seu preço está acima do seu concorrente. Você precisa encontrar meios como qualidade, localização, etc, para justificar esta diferença.
B9: =IF(E9=TOP_CONC!$D$5,B8+1,B8) -> 1 | C9: Concorrente 4 | D9: Qualidade | E9: Produto 4 | F9: 80 | G9: =IF(ISERROR( IF(C9="","",IFERROR(VLOOKUP(E9,CAD_PROD!$C$6:$D$506,2,0),""))),"",IF(C9="","",IFERROR(VLOOKUP(E9,CAD_PROD!$C$6:$D$506,2,0),""))) -> 80 | H9: =IF(ISERROR( IF(C9="","", IF(F9<G9,"Seu preço está acima do seu concorrente. Você precisa encontrar meios como qualidade, localização, etc, para justificar esta diferença.",IF(F9>G9,"Seu preço está abaixo do seu concorrente. Mas ele se posiciona pelo(a) "&D9&". Fique atento sobre este detalhe, pois preço baixo não é garantia de sucesso.","Seu preço está igual ao do seu concorrente. Ele se posiciona pela "&D9&". Se você conseguir se posicionar melhor que ele nesse atributo, poderá estar em vantagem.")))),"", IF(C9="","", IF(F9<G9,"Seu preço está acima do seu concorrente. Você precisa encontrar meios como qualidade, localização, etc, para justificar esta diferença.",IF(F9>G9,"Seu preço está abaixo do seu concorrente. Mas ele se posiciona pelo(a) "&D9&". Fique atento sobre este detalhe, pois preço baixo não é garantia de sucesso.","Seu preço está igual ao do seu concorrente. Ele se posiciona pela "&D9&". Se você conseguir se posicionar melhor que ele nesse atributo, poderá estar em vantagem.")))) -> Seu preço está igual ao do seu concorrente. Ele se posiciona pela Qualidade. Se você conseguir se posicionar melhor que ele nesse atributo, poderá estar em vantagem.
B10: =IF(E10=TOP_CONC!$D$5,B9+1,B9) -> 1 | C10: Concorrente 5 | D10: Qualidade | E10: Produto 5 | F10: 20 | G10: =IF(ISERROR( IF(C10="","",IFERROR(VLOOKUP(E10,CAD_PROD!$C$6:$D$506,2,0),""))),"",IF(C10="","",IFERROR(VLOOKUP(E10,CAD_PROD!$C$6:$D$506,2,0),""))) -> 90 | H10: =IF(ISERROR( IF(C10="","", IF(F10<G10,"Seu preço está acima do seu concorrente. Você precisa encontrar meios como qualidade, localização, etc, para justificar esta diferença.",IF(F10>G10,"Seu preço está abaixo do seu concorrente. Mas ele se posiciona pelo(a) "&D10&". Fique atento sobre este detalhe, pois preço baixo não é garantia de sucesso.","Seu preço está igual ao do seu concorrente. Ele se posiciona pela "&D10&". Se você conseguir se posicionar melhor que ele nesse atributo, poderá estar em vantagem.")))),"", IF(C10="","", IF(F10<G10,"Seu preço está acima do seu concorrente. Você precisa encontrar meios como qualidade, localização, etc, para justificar esta diferença.",IF(F10>G10,"Seu preço está abaixo do seu concorrente. Mas ele se posiciona pelo(a) "&D10&". Fique atento sobre este detalhe, pois preço baixo não é garantia de sucesso.","Seu preço está igual ao do seu concorrente. Ele se posiciona pela "&D10&". Se você conseguir se posicionar melhor que ele nesse atributo, poderá estar em vantagem.")))) -> Seu preço está acima do seu concorrente. Você precisa encontrar meios como qualidade, localização, etc, para justificar esta diferença.
B11: =IF(E11=TOP_CONC!$D$5,B10+1,B10) -> 2 | C11: Concorrente 6 | D11: Preço | E11: Produto 2 | F11: 40 | G11: =IF(ISERROR( IF(C11="","",IFERROR(VLOOKUP(E11,CAD_PROD!$C$6:$D$506,2,0),""))),"",IF(C11="","",IFERROR(VLOOKUP(E11,CAD_PROD!$C$6:$D$506,2,0),""))) -> 60 | H11: =IF(ISERROR( IF(C11="","", IF(F11<G11,"Seu preço está acima do seu concorrente. Você precisa encontrar meios como qualidade, localização, etc, para justificar esta diferença.",IF(F11>G11,"Seu preço está abaixo do seu concorrente. Mas ele se posiciona pelo(a) "&D11&". Fique atento sobre este detalhe, pois preço baixo não é garantia de sucesso.","Seu preço está igual ao do seu concorrente. Ele se posiciona pela "&D11&". Se você conseguir se posicionar melhor que ele nesse atributo, poderá estar em vantagem.")))),"", IF(C11="","", IF(F11<G11,"Seu preço está acima do seu concorrente. Você precisa encontrar meios como qualidade, localização, etc, para justificar esta diferença.",IF(F11>G11,"Seu preço está abaixo do seu concorrente. Mas ele se posiciona pelo(a) "&D11&". Fique atento sobre este detalhe, pois preço baixo não é garantia de sucesso.","Seu preço está igual ao do seu concorrente. Ele se posiciona pela "&D11&". Se você conseguir se posicionar melhor que ele nesse atributo, poderá estar em vantagem.")))) -> Seu preço está acima do seu concorrente. Você precisa encontrar meios como qualidade, localização, etc, para justificar esta diferença.
B12: =IF(E12=TOP_CONC!$D$5,B11+1,B11) -> 2 | G12: =IF(ISERROR( IF(C12="","",IFERROR(VLOOKUP(E12,CAD_PROD!$C$6:$D$506,2,0),""))),"",IF(C12="","",IFERROR(VLOOKUP(E12,CAD_PROD!$C$6:$D$506,2,0),""))) | H12: =IF(ISERROR( IF(C12="","", IF(F12<G12,"Seu preço está acima do seu concorrente. Você precisa encontrar meios como qualidade, localização, etc, para justificar esta diferença.",IF(F12>G12,"Seu preço está abaixo do seu concorrente. Mas ele se posiciona pelo(a) "&D12&". Fique atento sobre este detalhe, pois preço baixo não é garantia de sucesso.","Seu preço está igual ao do seu concorrente. Ele se posiciona pela "&D12&". Se você conseguir se posicionar melhor que ele nesse atributo, poderá estar em vantagem.")))),"", IF(C12="","", IF(F12<G12,"Seu preço está acima do seu concorrente. Você precisa encontrar meios como qualidade, localização, etc, para justificar esta diferença.",IF(F12>G12,"Seu preço está abaixo do seu concorrente. Mas ele se posiciona pelo(a) "&D12&". Fique atento sobre este detalhe, pois preço baixo não é garantia de sucesso.","Seu preço está igual ao do seu concorrente. Ele se posiciona pela "&D12&". Se você conseguir se posicionar melhor que ele nesse atributo, poderá estar em vantagem."))))
B13: =IF(E13=TOP_CONC!$D$5,B12+1,B12) -> 2 | G13: =IF(ISERROR( IF(C13="","",IFERROR(VLOOKUP(E13,CAD_PROD!$C$6:$D$506,2,0),""))),"",IF(C13="","",IFERROR(VLOOKUP(E13,CAD_PROD!$C$6:$D$506,2,0),""))) | H13: =IF(ISERROR( IF(C13="","", IF(F13<G13,"Seu preço está acima do seu concorrente. Você precisa encontrar meios como qualidade, localização, etc, para justificar esta diferença.",IF(F13>G13,"Seu preço está abaixo do seu concorrente. Mas ele se posiciona pelo(a) "&D13&". Fique atento sobre este detalhe, pois preço baixo não é garantia de sucesso.","Seu preço está igual ao do seu concorrente. Ele se posiciona pela "&D13&". Se você conseguir se posicionar melhor que ele nesse atributo, poderá estar em vantagem.")))),"", IF(C13="","", IF(F13<G13,"Seu preço está acima do seu concorrente. Você precisa encontrar meios como qualidade, localização, etc, para justificar esta diferença.",IF(F13>G13,"Seu preço está abaixo do seu concorrente. Mas ele se posiciona pelo(a) "&D13&". Fique atento sobre este detalhe, pois preço baixo não é garantia de sucesso.","Seu preço está igual ao do seu concorrente. Ele se posiciona pela "&D13&". Se você conseguir se posicionar melhor que ele nesse atributo, poderá estar em vantagem."))))
B14: =IF(E14=TOP_CONC!$D$5,B13+1,B13) -> 2 | G14: =IF(ISERROR( IF(C14="","",IFERROR(VLOOKUP(E14,CAD_PROD!$C$6:$D$506,2,0),""))),"",IF(C14="","",IFERROR(VLOOKUP(E14,CAD_PROD!$C$6:$D$506,2,0),""))) | H14: =IF(ISERROR( IF(C14="","", IF(F14<G14,"Seu preço está acima do seu concorrente. Você precisa encontrar meios como qualidade, localização, etc, para justificar esta diferença.",IF(F14>G14,"Seu preço está abaixo do seu concorrente. Mas ele se posiciona pelo(a) "&D14&". Fique atento sobre este detalhe, pois preço baixo não é garantia de sucesso.","Seu preço está igual ao do seu concorrente. Ele se posiciona pela "&D14&". Se você conseguir se posicionar melhor que ele nesse atributo, poderá estar em vantagem.")))),"", IF(C14="","", IF(F14<G14,"Seu preço está acima do seu concorrente. Você precisa encontrar meios como qualidade, localização, etc, para justificar esta diferença.",IF(F14>G14,"Seu preço está abaixo do seu concorrente. Mas ele se posiciona pelo(a) "&D14&". Fique atento sobre este detalhe, pois preço baixo não é garantia de sucesso.","Seu preço está igual ao do seu concorrente. Ele se posiciona pela "&D14&". Se você conseguir se posicionar melhor que ele nesse atributo, poderá estar em vantagem."))))
B15: =IF(E15=TOP_CONC!$D$5,B14+1,B14) -> 2 | G15: =IF(ISERROR( IF(C15="","",IFERROR(VLOOKUP(E15,CAD_PROD!$C$6:$D$506,2,0),""))),"",IF(C15="","",IFERROR(VLOOKUP(E15,CAD_PROD!$C$6:$D$506,2,0),""))) | H15: =IF(ISERROR( IF(C15="","", IF(F15<G15,"Seu preço está acima do seu concorrente. Você precisa encontrar meios como qualidade, localização, etc, para justificar esta diferença.",IF(F15>G15,"Seu preço está abaixo do seu concorrente. Mas ele se posiciona pelo(a) "&D15&". Fique atento sobre este detalhe, pois preço baixo não é garantia de sucesso.","Seu preço está igual ao do seu concorrente. Ele se posiciona pela "&D15&". Se você conseguir se posicionar melhor que ele nesse atributo, poderá estar em vantagem.")))),"", IF(C15="","", IF(F15<G15,"Seu preço está acima do seu concorrente. Você precisa encontrar meios como qualidade, localização, etc, para justificar esta diferença.",IF(F15>G15,"Seu preço está abaixo do seu concorrente. Mas ele se posiciona pelo(a) "&D15&". Fique atento sobre este detalhe, pois preço baixo não é garantia de sucesso.","Seu preço está igual ao do seu concorrente. Ele se posiciona pela "&D15&". Se você conseguir se posicionar melhor que ele nesse atributo, poderá estar em vantagem."))))
B16: =IF(E16=TOP_CONC!$D$5,B15+1,B15) -> 2 | G16: =IF(ISERROR( IF(C16="","",IFERROR(VLOOKUP(E16,CAD_PROD!$C$6:$D$506,2,0),""))),"",IF(C16="","",IFERROR(VLOOKUP(E16,CAD_PROD!$C$6:$D$506,2,0),""))) | H16: =IF(ISERROR( IF(C16="","", IF(F16<G16,"Seu preço está acima do seu concorrente. Você precisa encontrar meios como qualidade, localização, etc, para justificar esta diferença.",IF(F16>G16,"Seu preço está abaixo do seu concorrente. Mas ele se posiciona pelo(a) "&D16&". Fique atento sobre este detalhe, pois preço baixo não é garantia de sucesso.","Seu preço está igual ao do seu concorrente. Ele se posiciona pela "&D16&". Se você conseguir se posicionar melhor que ele nesse atributo, poderá estar em vantagem.")))),"", IF(C16="","", IF(F16<G16,"Seu preço está acima do seu concorrente. Você precisa encontrar meios como qualidade, localização, etc, para justificar esta diferença.",IF(F16>G16,"Seu preço está abaixo do seu concorrente. Mas ele se posiciona pelo(a) "&D16&". Fique atento sobre este detalhe, pois preço baixo não é garantia de sucesso.","Seu preço está igual ao do seu concorrente. Ele se posiciona pela "&D16&". Se você conseguir se posicionar melhor que ele nesse atributo, poderá estar em vantagem."))))
B17: =IF(E17=TOP_CONC!$D$5,B16+1,B16) -> 2 | G17: =IF(ISERROR( IF(C17="","",IFERROR(VLOOKUP(E17,CAD_PROD!$C$6:$D$506,2,0),""))),"",IF(C17="","",IFERROR(VLOOKUP(E17,CAD_PROD!$C$6:$D$506,2,0),""))) | H17: =IF(ISERROR( IF(C17="","", IF(F17<G17,"Seu preço está acima do seu concorrente. Você precisa encontrar meios como qualidade, localização, etc, para justificar esta diferença.",IF(F17>G17,"Seu preço está abaixo do seu concorrente. Mas ele se posiciona pelo(a) "&D17&". Fique atento sobre este detalhe, pois preço baixo não é garantia de sucesso.","Seu preço está igual ao do seu concorrente. Ele se posiciona pela "&D17&". Se você conseguir se posicionar melhor que ele nesse atributo, poderá estar em vantagem.")))),"", IF(C17="","", IF(F17<G17,"Seu preço está acima do seu concorrente. Você precisa encontrar meios como qualidade, localização, etc, para justificar esta diferença.",IF(F17>G17,"Seu preço está abaixo do seu concorrente. Mas ele se posiciona pelo(a) "&D17&". Fique atento sobre este detalhe, pois preço baixo não é garantia de sucesso.","Seu preço está igual ao do seu concorrente. Ele se posiciona pela "&D17&". Se você conseguir se posicionar melhor que ele nesse atributo, poderá estar em vantagem."))))
B18: =IF(E18=TOP_CONC!$D$5,B17+1,B17) -> 2 | G18: =IF(ISERROR( IF(C18="","",IFERROR(VLOOKUP(E18,CAD_PROD!$C$6:$D$506,2,0),""))),"",IF(C18="","",IFERROR(VLOOKUP(E18,CAD_PROD!$C$6:$D$506,2,0),""))) | H18: =IF(ISERROR( IF(C18="","", IF(F18<G18,"Seu preço está acima do seu concorrente. Você precisa encontrar meios como qualidade, localização, etc, para justificar esta diferença.",IF(F18>G18,"Seu preço está abaixo do seu concorrente. Mas ele se posiciona pelo(a) "&D18&". Fique atento sobre este detalhe, pois preço baixo não é garantia de sucesso.","Seu preço está igual ao do seu concorrente. Ele se posiciona pela "&D18&". Se você conseguir se posicionar melhor que ele nesse atributo, poderá estar em vantagem.")))),"", IF(C18="","", IF(F18<G18,"Seu preço está acima do seu concorrente. Você precisa encontrar meios como qualidade, localização, etc, para justificar esta diferença.",IF(F18>G18,"Seu preço está abaixo do seu concorrente. Mas ele se posiciona pelo(a) "&D18&". Fique atento sobre este detalhe, pois preço baixo não é garantia de sucesso.","Seu preço está igual ao do seu concorrente. Ele se posiciona pela "&D18&". Se você conseguir se posicionar melhor que ele nesse atributo, poderá estar em vantagem."))))
B19: =IF(E19=TOP_CONC!$D$5,B18+1,B18) -> 2 | G19: =IF(ISERROR( IF(C19="","",IFERROR(VLOOKUP(E19,CAD_PROD!$C$6:$D$506,2,0),""))),"",IF(C19="","",IFERROR(VLOOKUP(E19,CAD_PROD!$C$6:$D$506,2,0),""))) | H19: =IF(ISERROR( IF(C19="","", IF(F19<G19,"Seu preço está acima do seu concorrente. Você precisa encontrar meios como qualidade, localização, etc, para justificar esta diferença.",IF(F19>G19,"Seu preço está abaixo do seu concorrente. Mas ele se posiciona pelo(a) "&D19&". Fique atento sobre este detalhe, pois preço baixo não é garantia de sucesso.","Seu preço está igual ao do seu concorrente. Ele se posiciona pela "&D19&". Se você conseguir se posicionar melhor que ele nesse atributo, poderá estar em vantagem.")))),"", IF(C19="","", IF(F19<G19,"Seu preço está acima do seu concorrente. Você precisa encontrar meios como qualidade, localização, etc, para justificar esta diferença.",IF(F19>G19,"Seu preço está abaixo do seu concorrente. Mas ele se posiciona pelo(a) "&D19&". Fique atento sobre este detalhe, pois preço baixo não é garantia de sucesso.","Seu preço está igual ao do seu concorrente. Ele se posiciona pela "&D19&". Se você conseguir se posicionar melhor que ele nesse atributo, poderá estar em vantagem."))))
B20: =IF(E20=TOP_CONC!$D$5,B19+1,B19) -> 2 | G20: =IF(ISERROR( IF(C20="","",IFERROR(VLOOKUP(E20,CAD_PROD!$C$6:$D$506,2,0),""))),"",IF(C20="","",IFERROR(VLOOKUP(E20,CAD_PROD!$C$6:$D$506,2,0),""))) | H20: =IF(ISERROR( IF(C20="","", IF(F20<G20,"Seu preço está acima do seu concorrente. Você precisa encontrar meios como qualidade, localização, etc, para justificar esta diferença.",IF(F20>G20,"Seu preço está abaixo do seu concorrente. Mas ele se posiciona pelo(a) "&D20&". Fique atento sobre este detalhe, pois preço baixo não é garantia de sucesso.","Seu preço está igual ao do seu concorrente. Ele se posiciona pela "&D20&". Se você conseguir se posicionar melhor que ele nesse atributo, poderá estar em vantagem.")))),"", IF(C20="","", IF(F20<G20,"Seu preço está acima do seu concorrente. Você precisa encontrar meios como qualidade, localização, etc, para justificar esta diferença.",IF(F20>G20,"Seu preço está abaixo do seu concorrente. Mas ele se posiciona pelo(a) "&D20&". Fique atento sobre este detalhe, pois preço baixo não é garantia de sucesso.","Seu preço está igual ao do seu concorrente. Ele se posiciona pela "&D20&". Se você conseguir se posicionar melhor que ele nesse atributo, poderá estar em vantagem."))))
B21: =IF(E21=TOP_CONC!$D$5,B20+1,B20) -> 2 | G21: =IF(ISERROR( IF(C21="","",IFERROR(VLOOKUP(E21,CAD_PROD!$C$6:$D$506,2,0),""))),"",IF(C21="","",IFERROR(VLOOKUP(E21,CAD_PROD!$C$6:$D$506,2,0),""))) | H21: =IF(ISERROR( IF(C21="","", IF(F21<G21,"Seu preço está acima do seu concorrente. Você precisa encontrar meios como qualidade, localização, etc, para justificar esta diferença.",IF(F21>G21,"Seu preço está abaixo do seu concorrente. Mas ele se posiciona pelo(a) "&D21&". Fique atento sobre este detalhe, pois preço baixo não é garantia de sucesso.","Seu preço está igual ao do seu concorrente. Ele se posiciona pela "&D21&". Se você conseguir se posicionar melhor que ele nesse atributo, poderá estar em vantagem.")))),"", IF(C21="","", IF(F21<G21,"Seu preço está acima do seu concorrente. Você precisa encontrar meios como qualidade, localização, etc, para justificar esta diferença.",IF(F21>G21,"Seu preço está abaixo do seu concorrente. Mas ele se posiciona pelo(a) "&D21&". Fique atento sobre este detalhe, pois preço baixo não é garantia de sucesso.","Seu preço está igual ao do seu concorrente. Ele se posiciona pela "&D21&". Se você conseguir se posicionar melhor que ele nesse atributo, poderá estar em vantagem."))))
B22: =IF(E22=TOP_CONC!$D$5,B21+1,B21) -> 2 | G22: =IF(ISERROR( IF(C22="","",IFERROR(VLOOKUP(E22,CAD_PROD!$C$6:$D$506,2,0),""))),"",IF(C22="","",IFERROR(VLOOKUP(E22,CAD_PROD!$C$6:$D$506,2,0),""))) | H22: =IF(ISERROR( IF(C22="","", IF(F22<G22,"Seu preço está acima do seu concorrente. Você precisa encontrar meios como qualidade, localização, etc, para justificar esta diferença.",IF(F22>G22,"Seu preço está abaixo do seu concorrente. Mas ele se posiciona pelo(a) "&D22&". Fique atento sobre este detalhe, pois preço baixo não é garantia de sucesso.","Seu preço está igual ao do seu concorrente. Ele se posiciona pela "&D22&". Se você conseguir se posicionar melhor que ele nesse atributo, poderá estar em vantagem.")))),"", IF(C22="","", IF(F22<G22,"Seu preço está acima do seu concorrente. Você precisa encontrar meios como qualidade, localização, etc, para justificar esta diferença.",IF(F22>G22,"Seu preço está abaixo do seu concorrente. Mas ele se posiciona pelo(a) "&D22&". Fique atento sobre este detalhe, pois preço baixo não é garantia de sucesso.","Seu preço está igual ao do seu concorrente. Ele se posiciona pela "&D22&". Se você conseguir se posicionar melhor que ele nesse atributo, poderá estar em vantagem."))))
B23: =IF(E23=TOP_CONC!$D$5,B22+1,B22) -> 2 | G23: =IF(ISERROR( IF(C23="","",IFERROR(VLOOKUP(E23,CAD_PROD!$C$6:$D$506,2,0),""))),"",IF(C23="","",IFERROR(VLOOKUP(E23,CAD_PROD!$C$6:$D$506,2,0),""))) | H23: =IF(ISERROR( IF(C23="","", IF(F23<G23,"Seu preço está acima do seu concorrente. Você precisa encontrar meios como qualidade, localização, etc, para justificar esta diferença.",IF(F23>G23,"Seu preço está abaixo do seu concorrente. Mas ele se posiciona pelo(a) "&D23&". Fique atento sobre este detalhe, pois preço baixo não é garantia de sucesso.","Seu preço está igual ao do seu concorrente. Ele se posiciona pela "&D23&". Se você conseguir se posicionar melhor que ele nesse atributo, poderá estar em vantagem.")))),"", IF(C23="","", IF(F23<G23,"Seu preço está acima do seu concorrente. Você precisa encontrar meios como qualidade, localização, etc, para justificar esta diferença.",IF(F23>G23,"Seu preço está abaixo do seu concorrente. Mas ele se posiciona pelo(a) "&D23&". Fique atento sobre este detalhe, pois preço baixo não é garantia de sucesso.","Seu preço está igual ao do seu concorrente. Ele se posiciona pela "&D23&". Se você conseguir se posicionar melhor que ele nesse atributo, poderá estar em vantagem."))))
... B505: =IF(E505=TOP_CONC!$D$5,B504+1,B504) -> 2 | G505: =IF(ISERROR( IF(C505="","",IFERROR(VLOOKUP(E505,CAD_PROD!$C$6:$D$506,2,0),""))),"",IF(C505="","",IFERROR(VLOOKUP(E505,CAD_PROD!$C$6:$D$506,2,0),""))) | H505: =IF(ISERROR( IF(C505="","", IF(F505<G505,"Seu preço está acima do seu concorrente. Você precisa encontrar meios como qualidade, localização, etc, para justificar esta diferença.",IF(F505>G505,"Seu preço está abaixo do seu concorrente. Mas ele se posiciona pelo(a) "&D505&". Fique atento sobre este detalhe, pois preço baixo não é garantia de sucesso.","Seu preço está igual ao do seu concorrente. Ele se posiciona pela "&D505&". Se você conseguir se posicionar melhor que ele nesse atributo, poderá estar em vantagem.")))),"", IF(C505="","", IF(F505<G505,"Seu preço está acima do seu concorrente. Você precisa encontrar meios como qualidade, localização, etc, para justificar esta diferença.",IF(F505>G505,"Seu preço está abaixo do seu concorrente. Mas ele se posiciona pelo(a) "&D505&". Fique atento sobre este detalhe, pois preço baixo não é garantia de sucesso.","Seu preço está igual ao do seu concorrente. Ele se posiciona pela "&D505&". Se você conseguir se posicionar melhor que ele nesse atributo, poderá estar em vantagem."))))

Sheet TOP_PROD
C5: Produto | D5: Quantidade vendida para o ponto de equilíbrio | E5: Vendas projetadas | F5: Diferença | G5: Receita gerada no ponto de equilíbrio | H5: Receita projetada | I5: Diferença
B6: =LARGE(CAD_PROD!$B$6:$B$505,1) -> 13500 | C6: =IF(B6=0,"",VLOOKUP(B6,CAD_PROD!$B:$C,2,0)) -> Produto 5 | D6: =IF(C6="","",VLOOKUP(C6,CAD_CUST!$C:$R,14,0)) -> 204 | E6: =IF(C6="","",VLOOKUP(C6,CAD_PROD!C:G,3,0)) -> 150 | F6: =IF(C6="","",E6-D6) -> -54 | G6: =IF(C6="","",VLOOKUP(C6,CAD_CUST!$C:$R,12,0)) -> 18360 | H6: =IF(C6="","",VLOOKUP(C6,CAD_PROD!C:G,4,0)) -> 13500 | I6: =IF(C6="","",H6-G6) -> -4860
B7: =LARGE(CAD_PROD!B6:B505,2) -> 5400 | C7: =IF(B7=0,"",VLOOKUP(B7,CAD_PROD!B:C,2,0)) -> Produto 2 | D7: =IF(C7="","",VLOOKUP(C7,CAD_CUST!$C:$R,14,0)) -> 89 | E7: =IF(C7="","",VLOOKUP(C7,CAD_PROD!C:G,3,0)) -> 90 | F7: =IF(C7="","",E7-D7) -> 1 | G7: =IF(C7="","",VLOOKUP(C7,CAD_CUST!$C:$R,12,0)) -> 5340 | H7: =IF(C7="","",VLOOKUP(C7,CAD_PROD!C:G,4,0)) -> 5400 | I7: =IF(C7="","",H7-G7) -> 60
B8: =LARGE(CAD_PROD!B6:B505,3) -> 3200 | C8: =IF(B8=0,"",VLOOKUP(B8,CAD_PROD!B:C,2,0)) -> Produto 4 | D8: =IF(C8="","",VLOOKUP(C8,CAD_CUST!$C:$R,14,0)) -> 49 | E8: =IF(C8="","",VLOOKUP(C8,CAD_PROD!C:G,3,0)) -> 40 | F8: =IF(C8="","",E8-D8) -> -9 | G8: =IF(C8="","",VLOOKUP(C8,CAD_CUST!$C:$R,12,0)) -> 3920 | H8: =IF(C8="","",VLOOKUP(C8,CAD_PROD!C:G,4,0)) -> 3200 | I8: =IF(C8="","",H8-G8) -> -720
B9: =LARGE(CAD_PROD!B6:B505,4) -> 2100 | C9: =IF(B9=0,"",VLOOKUP(B9,CAD_PROD!B:C,2,0)) -> Produto 3 | D9: =IF(C9="","",VLOOKUP(C9,CAD_CUST!$C:$R,14,0)) -> 33 | E9: =IF(C9="","",VLOOKUP(C9,CAD_PROD!C:G,3,0)) -> 30 | F9: =IF(C9="","",E9-D9) -> -3 | G9: =IF(C9="","",VLOOKUP(C9,CAD_CUST!$C:$R,12,0)) -> 2310 | H9: =IF(C9="","",VLOOKUP(C9,CAD_PROD!C:G,4,0)) -> 2100 | I9: =IF(C9="","",H9-G9) -> -210
B10: =LARGE(CAD_PROD!B6:B505,5) -> 500 | C10: =IF(B10=0,"",VLOOKUP(B10,CAD_PROD!B:C,2,0)) -> Produto 1 | D10: =IF(C10="","",VLOOKUP(C10,CAD_CUST!$C:$R,14,0)) -> 9 | E10: =IF(C10="","",VLOOKUP(C10,CAD_PROD!C:G,3,0)) -> 10 | F10: =IF(C10="","",E10-D10) -> 1 | G10: =IF(C10="","",VLOOKUP(C10,CAD_CUST!$C:$R,12,0)) -> 450 | H10: =IF(C10="","",VLOOKUP(C10,CAD_PROD!C:G,4,0)) -> 500 | I10: =IF(C10="","",H10-G10) -> 50
B11: =LARGE(CAD_PROD!B6:B505,6) -> 0 | C11: =IF(B11=0,"",VLOOKUP(B11,CAD_PROD!B:C,2,0)) | D11: =IF(C11="","",VLOOKUP(C11,CAD_CUST!$C:$R,14,0)) | E11: =IF(C11="","",VLOOKUP(C11,CAD_PROD!C:G,3,0)) | F11: =IF(C11="","",E11-D11) | G11: =IF(C11="","",VLOOKUP(C11,CAD_CUST!$C:$R,12,0)) | H11: =IF(C11="","",VLOOKUP(C11,CAD_PROD!C:G,4,0)) | I11: =IF(C11="","",H11-G11)
B12: =LARGE(CAD_PROD!B6:B505,7) -> 0 | C12: =IF(B12=0,"",VLOOKUP(B12,CAD_PROD!B:C,2,0)) | D12: =IF(C12="","",VLOOKUP(C12,CAD_CUST!$C:$R,14,0)) | E12: =IF(C12="","",VLOOKUP(C12,CAD_PROD!C:G,3,0)) | F12: =IF(C12="","",E12-D12) | G12: =IF(C12="","",VLOOKUP(C12,CAD_CUST!$C:$R,12,0)) | H12: =IF(C12="","",VLOOKUP(C12,CAD_PROD!C:G,4,0)) | I12: =IF(C12="","",H12-G12)
B13: =LARGE(CAD_PROD!B6:B505,8) -> 0 | C13: =IF(B13=0,"",VLOOKUP(B13,CAD_PROD!B:C,2,0)) | D13: =IF(C13="","",VLOOKUP(C13,CAD_CUST!$C:$R,14,0)) | E13: =IF(C13="","",VLOOKUP(C13,CAD_PROD!C:G,3,0)) | F13: =IF(C13="","",E13-D13) | G13: =IF(C13="","",VLOOKUP(C13,CAD_CUST!$C:$R,12,0)) | H13: =IF(C13="","",VLOOKUP(C13,CAD_PROD!C:G,4,0)) | I13: =IF(C13="","",H13-G13)
B14: =LARGE(CAD_PROD!B6:B505,9) -> 0 | C14: =IF(B14=0,"",VLOOKUP(B14,CAD_PROD!B:C,2,0)) | D14: =IF(C14="","",VLOOKUP(C14,CAD_CUST!$C:$R,14,0)) | E14: =IF(C14="","",VLOOKUP(C14,CAD_PROD!C:G,3,0)) | F14: =IF(C14="","",E14-D14) | G14: =IF(C14="","",VLOOKUP(C14,CAD_CUST!$C:$R,12,0)) | H14: =IF(C14="","",VLOOKUP(C14,CAD_PROD!C:G,4,0)) | I14: =IF(C14="","",H14-G14)
B15: =LARGE(CAD_PROD!B6:B505,10) -> 0 | C15: =IF(B15=0,"",VLOOKUP(B15,CAD_PROD!B:C,2,0)) | D15: =IF(C15="","",VLOOKUP(C15,CAD_CUST!$C:$R,14,0)) | E15: =IF(C15="","",VLOOKUP(C15,CAD_PROD!C:G,3,0)) | F15: =IF(C15="","",E15-D15) | G15: =IF(C15="","",VLOOKUP(C15,CAD_CUST!$C:$R,12,0)) | H15: =IF(C15="","",VLOOKUP(C15,CAD_PROD!C:G,4,0)) | I15: =IF(C15="","",H15-G15)

Sheet TOP_CUST
C5: Produtos | D5: Custos Diretos | F5: Custos Fixos | G5: Valores
B6: =LARGE(CAD_CUST!$B$6:$B$505,1) -> 55.100001 | C6: =IF(B6=0,"",VLOOKUP(B6,CAD_CUST!B:H,2,0)) -> Produto 5 | D6: =IF(B6=0,"",VLOOKUP(B6,CAD_CUST!B:H,7,0)) -> 55.1 | E6: =LARGE(PE_GERAL!$B$6:$B$505,1) -> 10000 | F6: =IF(E6=0,"",VLOOKUP(E6,PE_GERAL!B:D,2,0)) -> Custo 1 | G6: =IF(E6=0,"",VLOOKUP(E6,PE_GERAL!B:D,3,0)) -> 10000
B7: =LARGE(CAD_CUST!$B$6:$B$505,2) -> 45.600001 | C7: =IF(B7=0,"",VLOOKUP(B7,CAD_CUST!B:H,2,0)) -> Produto 4 | D7: =IF(B7=0,"",VLOOKUP(B7,CAD_CUST!B:H,7,0)) -> 45.6 | E7: =LARGE(PE_GERAL!$B$6:$B$505,2) -> 900 | F7: =IF(E7=0,"",VLOOKUP(E7,PE_GERAL!B:D,2,0)) -> Custo 5 | G7: =IF(E7=0,"",VLOOKUP(E7,PE_GERAL!B:D,3,0)) -> 900
B8: =LARGE(CAD_CUST!$B$6:$B$505,3) -> 36.500001 | C8: =IF(B8=0,"",VLOOKUP(B8,CAD_CUST!B:H,2,0)) -> Produto 3 | D8: =IF(B8=0,"",VLOOKUP(B8,CAD_CUST!B:H,7,0)) -> 36.5 | E8: =LARGE(PE_GERAL!$B$6:$B$505,3) -> 800 | F8: =IF(E8=0,"",VLOOKUP(E8,PE_GERAL!B:D,2,0)) -> Custo 4 | G8: =IF(E8=0,"",VLOOKUP(E8,PE_GERAL!B:D,3,0)) -> 800
B9: =LARGE(CAD_CUST!$B$6:$B$505,4) -> 27.800001 | C9: =IF(B9=0,"",VLOOKUP(B9,CAD_CUST!B:H,2,0)) -> Produto 2 | D9: =IF(B9=0,"",VLOOKUP(B9,CAD_CUST!B:H,7,0)) -> 27.8 | E9: =LARGE(PE_GERAL!$B$6:$B$505,4) -> 700 | F9: =IF(E9=0,"",VLOOKUP(E9,PE_GERAL!B:D,2,0)) -> Custo 3 | G9: =IF(E9=0,"",VLOOKUP(E9,PE_GERAL!B:D,3,0)) -> 700
B10: =LARGE(CAD_CUST!$B$6:$B$505,5) -> 19.500001 | C10: =IF(B10=0,"",VLOOKUP(B10,CAD_CUST!B:H,2,0)) -> Produto 1 | D10: =IF(B10=0,"",VLOOKUP(B10,CAD_CUST!B:H,7,0)) -> 19.5 | E10: =LARGE(PE_GERAL!$B$6:$B$505,5) -> 600 | F10: =IF(E10=0,"",VLOOKUP(E10,PE_GERAL!B:D,2,0)) -> Custo 2 | G10: =IF(E10=0,"",VLOOKUP(E10,PE_GERAL!B:D,3,0)) -> 600
B11: =LARGE(CAD_CUST!$B$6:$B$505,6) -> 0 | C11: =IF(B11=0,"",VLOOKUP(B11,CAD_CUST!B:H,2,0)) | D11: =IF(B11=0,"",VLOOKUP(B11,CAD_CUST!B:H,7,0)) | E11: =LARGE(PE_GERAL!$B$6:$B$505,6) -> 0 | F11: =IF(E11=0,"",VLOOKUP(E11,PE_GERAL!B:D,2,0)) | G11: =IF(E11=0,"",VLOOKUP(E11,PE_GERAL!B:D,3,0))
B12: =LARGE(CAD_CUST!$B$6:$B$505,7) -> 0 | C12: =IF(B12=0,"",VLOOKUP(B12,CAD_CUST!B:H,2,0)) | D12: =IF(B12=0,"",VLOOKUP(B12,CAD_CUST!B:H,7,0)) | E12: =LARGE(PE_GERAL!$B$6:$B$505,7) -> 0 | F12: =IF(E12=0,"",VLOOKUP(E12,PE_GERAL!B:D,2,0)) | G12: =IF(E12=0,"",VLOOKUP(E12,PE_GERAL!B:D,3,0))
B13: =LARGE(CAD_CUST!$B$6:$B$505,8) -> 0 | C13: =IF(B13=0,"",VLOOKUP(B13,CAD_CUST!B:H,2,0)) | D13: =IF(B13=0,"",VLOOKUP(B13,CAD_CUST!B:H,7,0)) | E13: =LARGE(PE_GERAL!$B$6:$B$505,8) -> 0 | F13: =IF(E13=0,"",VLOOKUP(E13,PE_GERAL!B:D,2,0)) | G13: =IF(E13=0,"",VLOOKUP(E13,PE_GERAL!B:D,3,0))
B14: =LARGE(CAD_CUST!$B$6:$B$505,9) -> 0 | C14: =IF(B14=0,"",VLOOKUP(B14,CAD_CUST!B:H,2,0)) | D14: =IF(B14=0,"",VLOOKUP(B14,CAD_CUST!B:H,7,0)) | E14: =LARGE(PE_GERAL!$B$6:$B$505,9) -> 0 | F14: =IF(E14=0,"",VLOOKUP(E14,PE_GERAL!B:D,2,0)) | G14: =IF(E14=0,"",VLOOKUP(E14,PE_GERAL!B:D,3,0))
B15: =LARGE(CAD_CUST!$B$6:$B$505,10) -> 0 | C15: =IF(B15=0,"",VLOOKUP(B15,CAD_CUST!B:H,2,0)) | D15: =IF(B15=0,"",VLOOKUP(B15,CAD_CUST!B:H,7,0)) | E15: =LARGE(PE_GERAL!$B$6:$B$505,10) -> 0 | F15: =IF(E15=0,"",VLOOKUP(E15,PE_GERAL!B:D,2,0)) | G15: =IF(E15=0,"",VLOOKUP(E15,PE_GERAL!B:D,3,0))

Sheet TOP_CONC
C5: Produto | D5: Produto 2
C7: Empresa | D7: Diferencial | E7: Preço Concorrente | F7: Seu Preço | G7: Orientação
C8: =IFERROR(VLOOKUP(ROW()-6,ANA_CONC!B:G,2,0),"") -> Concorrente 6 | D8: =IFERROR(VLOOKUP(ROW()-6,ANA_CONC!B:G,3,0),"") -> Preço | E8: =IFERROR(VLOOKUP(ROW()-6,ANA_CONC!B:G,5,0),"") -> 40 | F8: =IFERROR(VLOOKUP(ROW()-6,ANA_CONC!B:G,6,0),"") -> 60 | G8: =IF(ISERROR( IF(C8="","", IF(E8<F8,"Seu preço está acima de um dos seus concorrentes. Você precisa encontrar meios como qualidade, localização, etc, para justificar esta diferença.",IF(E8>F8,"Seu preço está abaixo de um dos seus concorrentes. Mas ele se posiciona pelo(a) "&D8&". Fique atento sobre este detalhe, pois preço baixo não é garantia de sucesso.","Seu preço está igual a de um dos seus concorrentes. Mas ele se posiciona pela "&D8&". Se você conseguir este mesmo benefício, poderá estar em vantagem.")))),"", IF(C8="","", IF(E8<F8,"Seu preço está acima de um dos seus concorrentes. Você precisa encontrar meios como qualidade, localização, etc, para justificar esta diferença.",IF(E8>F8,"Seu preço está abaixo de um dos seus concorrentes. Mas ele se posiciona pelo(a) "&D8&". Fique atento sobre este detalhe, pois preço baixo não é garantia de sucesso.","Seu preço está igual a de um dos seus concorrentes. Mas ele se posiciona pela "&D8&". Se você conseguir este mesmo benefício, poderá estar em vantagem.")))) -> Seu preço está acima de um dos seus concorrentes. Você precisa encontrar meios como qualidade, localização, etc, para justificar esta diferença.
C9: =IFERROR(VLOOKUP(ROW()-6,ANA_CONC!B:G,2,0),"") | D9: =IFERROR(VLOOKUP(ROW()-6,ANA_CONC!B:G,3,0),"") | E9: =IFERROR(VLOOKUP(ROW()-6,ANA_CONC!B:G,5,0),"") | F9: =IFERROR(VLOOKUP(ROW()-6,ANA_CONC!B:G,6,0),"") | G9: =IF(ISERROR( IF(C9="","", IF(E9<F9,"Seu preço está acima de um dos seus concorrentes. Você precisa encontrar meios como qualidade, localização, etc, para justificar esta diferença.",IF(E9>F9,"Seu preço está abaixo de um dos seus concorrentes. Mas ele se posiciona pelo(a) "&D9&". Fique atento sobre este detalhe, pois preço baixo não é garantia de sucesso.","Seu preço está igual a de um dos seus concorrentes. Mas ele se posiciona pela "&D9&". Se você conseguir este mesmo benefício, poderá estar em vantagem.")))),"", IF(C9="","", IF(E9<F9,"Seu preço está acima de um dos seus concorrentes. Você precisa encontrar meios como qualidade, localização, etc, para justificar esta diferença.",IF(E9>F9,"Seu preço está abaixo de um dos seus concorrentes. Mas ele se posiciona pelo(a) "&D9&". Fique atento sobre este detalhe, pois preço baixo não é garantia de sucesso.","Seu preço está igual a de um dos seus concorrentes. Mas ele se posiciona pela "&D9&". Se você conseguir este mesmo benefício, poderá estar em vantagem."))))
C10: =IFERROR(VLOOKUP(ROW()-6,ANA_CONC!B:G,2,0),"") | D10: =IFERROR(VLOOKUP(ROW()-6,ANA_CONC!B:G,3,0),"") | E10: =IFERROR(VLOOKUP(ROW()-6,ANA_CONC!B:G,5,0),"") | F10: =IFERROR(VLOOKUP(ROW()-6,ANA_CONC!B:G,6,0),"") | G10: =IF(ISERROR( IF(C10="","", IF(E10<F10,"Seu preço está acima de um dos seus concorrentes. Você precisa encontrar meios como qualidade, localização, etc, para justificar esta diferença.",IF(E10>F10,"Seu preço está abaixo de um dos seus concorrentes. Mas ele se posiciona pelo(a) "&D10&". Fique atento sobre este detalhe, pois preço baixo não é garantia de sucesso.","Seu preço está igual a de um dos seus concorrentes. Mas ele se posiciona pela "&D10&". Se você conseguir este mesmo benefício, poderá estar em vantagem.")))),"", IF(C10="","", IF(E10<F10,"Seu preço está acima de um dos seus concorrentes. Você precisa encontrar meios como qualidade, localização, etc, para justificar esta diferença.",IF(E10>F10,"Seu preço está abaixo de um dos seus concorrentes. Mas ele se posiciona pelo(a) "&D10&". Fique atento sobre este detalhe, pois preço baixo não é garantia de sucesso.","Seu preço está igual a de um dos seus concorrentes. Mas ele se posiciona pela "&D10&". Se você conseguir este mesmo benefício, poderá estar em vantagem."))))
C11: =IFERROR(VLOOKUP(ROW()-6,ANA_CONC!B:G,2,0),"") | D11: =IFERROR(VLOOKUP(ROW()-6,ANA_CONC!B:G,3,0),"") | E11: =IFERROR(VLOOKUP(ROW()-6,ANA_CONC!B:G,5,0),"") | F11: =IFERROR(VLOOKUP(ROW()-6,ANA_CONC!B:G,6,0),"") | G11: =IF(ISERROR( IF(C11="","", IF(E11<F11,"Seu preço está acima de um dos seus concorrentes. Você precisa encontrar meios como qualidade, localização, etc, para justificar esta diferença.",IF(E11>F11,"Seu preço está abaixo de um dos seus concorrentes. Mas ele se posiciona pelo(a) "&D11&". Fique atento sobre este detalhe, pois preço baixo não é garantia de sucesso.","Seu preço está igual a de um dos seus concorrentes. Mas ele se posiciona pela "&D11&". Se você conseguir este mesmo benefício, poderá estar em vantagem.")))),"", IF(C11="","", IF(E11<F11,"Seu preço está acima de um dos seus concorrentes. Você precisa encontrar meios como qualidade, localização, etc, para justificar esta diferença.",IF(E11>F11,"Seu preço está abaixo de um dos seus concorrentes. Mas ele se posiciona pelo(a) "&D11&". Fique atento sobre este detalhe, pois preço baixo não é garantia de sucesso.","Seu preço está igual a de um dos seus concorrentes. Mas ele se posiciona pela "&D11&". Se você conseguir este mesmo benefício, poderá estar em vantagem."))))
C12: =IFERROR(VLOOKUP(ROW()-6,ANA_CONC!B:G,2,0),"") | D12: =IFERROR(VLOOKUP(ROW()-6,ANA_CONC!B:G,3,0),"") | E12: =IFERROR(VLOOKUP(ROW()-6,ANA_CONC!B:G,5,0),"") | F12: =IFERROR(VLOOKUP(ROW()-6,ANA_CONC!B:G,6,0),"") | G12: =IF(ISERROR( IF(C12="","", IF(E12<F12,"Seu preço está acima de um dos seus concorrentes. Você precisa encontrar meios como qualidade, localização, etc, para justificar esta diferença.",IF(E12>F12,"Seu preço está abaixo de um dos seus concorrentes. Mas ele se posiciona pelo(a) "&D12&". Fique atento sobre este detalhe, pois preço baixo não é garantia de sucesso.","Seu preço está igual a de um dos seus concorrentes. Mas ele se posiciona pela "&D12&". Se você conseguir este mesmo benefício, poderá estar em vantagem.")))),"", IF(C12="","", IF(E12<F12,"Seu preço está acima de um dos seus concorrentes. Você precisa encontrar meios como qualidade, localização, etc, para justificar esta diferença.",IF(E12>F12,"Seu preço está abaixo de um dos seus concorrentes. Mas ele se posiciona pelo(a) "&D12&". Fique atento sobre este detalhe, pois preço baixo não é garantia de sucesso.","Seu preço está igual a de um dos seus concorrentes. Mas ele se posiciona pela "&D12&". Se você conseguir este mesmo benefício, poderá estar em vantagem."))))
