Workbook

Sheet CLIENTES
A1: ="LISTA DE CLIENTES ("&COUNTA(B7:B156)&"/"&COUNTA(A7:A156)&")" -> LISTA DE CLIENTES (1/150) | C1: =HYPERLINK("#orçamento!A4","VOLTAR PARA O ORÇAMENTO") -> VOLTAR PARA O ORÇAMENTO
A4: COD | B4: DESCRIÇÃO | C4: DOCUMENTO (CNPJ / CPF) | D4: ENDEREÇO | E4: NOME DO CONTATO | F4: TELEFONE | G4: E-MAIL
A7: CLI001 | B7: [digite aqui a descrição] | C7: 00.000.000/0000-00 | D7: [endereço do cliente] | E7: [nome do contato] | F7: (00) 0000-0000 | G7: cliente@email.com
A8: CLI002
A9: CLI003
A10: CLI004
A11: CLI005
A12: CLI006
A13: CLI007
A14: CLI008
A15: CLI009
A16: CLI010
A17: CLI011
A18: CLI012
A19: CLI013
... A156: CLI150

Sheet PRODUTOS
A1: ="LISTA DE PRODUTOS ("&COUNTA(B6:B205)&"/"&COUNTA(A6:A205)&")" -> LISTA DE PRODUTOS (1/200) | C1: =HYPERLINK("#orçamento!A4","VOLTAR PARA O ORÇAMENTO") -> VOLTAR PARA O ORÇAMENTO
A4: COD | B4: DESCRIÇÃO | C4: UNIDADE | D4: VALOR UNITÁRIO
A6: PRD001 | B6: [digite a descrição do produto] | C6: KG | D6: 5 | F6: =IF(TRIM(B6)<>"",1,0) -> 1
A7: PRD002 | F7: =IF(TRIM(B7)<>"",1,0) -> 0
A8: PRD003 | F8: =IF(TRIM(B8)<>"",1,0) -> 0
A9: PRD004 | F9: =IF(TRIM(B9)<>"",1,0) -> 0
A10: PRD005 | F10: =IF(TRIM(B10)<>"",1,0) -> 0
A11: PRD006 | F11: =IF(TRIM(B11)<>"",1,0) -> 0
A12: PRD007 | F12: =IF(TRIM(B12)<>"",1,0) -> 0
A13: PRD008 | F13: =IF(TRIM(B13)<>"",1,0) -> 0
A14: PRD009 | F14: =IF(TRIM(B14)<>"",1,0) -> 0
A15: PRD010 | F15: =IF(TRIM(B15)<>"",1,0) -> 0
A16: PRD011 | F16: =IF(TRIM(B16)<>"",1,0) -> 0
A17: PRD012 | F17: =IF(TRIM(B17)<>"",1,0) -> 0
A18: PRD013 | F18: =IF(TRIM(B18)<>"",1,0) -> 0
... A205: PRD200 | F205: =IF(TRIM(B205)<>"",1,0) -> 0

Sheet ORÇAMENTO
A3: DADOS PERSONALIZADOS PARA PREENCHIMENTO DO FORMULÁRIO
A4: >> | B4: CÓDIGO DO CLIENTE | C4: CLI001 | D4: =HYPERLINK("#CLIENTES!A1","CLIQUE PARA LISTAR TODOS OS CLIENTES") -> CLIQUE PARA LISTAR TODOS OS CLIENTES
A5: >> | B5: ASSINATURA VENDEDOR – LOCALIDADE | C5: Recife
A6: >> | B6: ASSINATURA VENDEDOR – DATA DA EMISSÃO | C6: =NOW() -> 41935.579
A7: >> | B7: ASSINATURA VENDEDOR – LINHA #1 | C7: [nome do vendedor]
A8: >> | B8: ASSINATURA VENDEDOR – LINHA #2 | C8: [digite aqui todas as formas de contato: telefones, email]
A10: UTILIZE OS CAMPOS ACIMA PARA PERSONALIZAR SEU ORÇAMENTO.
A11: PARA EDITAR OS DADOS E A LOGOMARCA DE SUA EMPRESA, UTILIZE O MENU FORMATAR >> PÁGINA >> CABEÇALHO.
A15: DADOS DO CLIENTE | E15: ORÇAMENTO Nº.
A16: =UPPER(TRIM(LOOKUP($C$4,CLIENTES!$A$7:$A$156,CLIENTES!$E$7:$E$156)&" - "&LOOKUP($C$4,CLIENTES!$A$7:$A$156,CLIENTES!$F$7:$F$156)&" - "&LOOKUP($C$4,CLIENTES!$A$7:$A$156,CLIENTES!$G$7:$G$156))) -> [NOME DO CONTATO] - (00) 0000-0000 - CLIENTE@EMAIL.COM | E16: =TEXT(NOW(),"AAAAMMDDHHMMSS") -> 20141023135339
A17: =UPPER(TRIM(LOOKUP($C$4,CLIENTES!$A$7:$A$156,CLIENTES!$B$7:$B$156)&" ("&LOOKUP($C$4,CLIENTES!$A$7:$A$156,CLIENTES!$C$7:$C$156)&")")) -> [DIGITE AQUI A DESCRIÇÃO] (00.000.000/0000-00)
A18: =UPPER(TRIM(LOOKUP($C$4,CLIENTES!$A$7:$A$156,CLIENTES!$D$7:$D$156))) -> [ENDEREÇO DO CLIENTE]
J19: UTILIZE OS CAMPOS ABAIXO PARA DEFINIR O FRETE TOTAL
A20: DETALHAMENTO DO PEDIDO
A21: COD | B21: DESCRIÇÃO DO PRODUTO | C21: QTD | D21: UND | E21: VL. UNIT. | F21: VL. TOTAL | J21: UND | K21: DESCRIÇÃO | L21: FRETE UNIT. | M21: QTD | N21: FRETE TOTAL
A23: PRD001 | B23: =IF(H23,LOOKUP($A23,PRODUTOS!A$6:A$205,PRODUTOS!B$6:B$205),"") -> [digite a descrição do produto] | C23: 1 | D23: =IF(H23,LOOKUP($A23,PRODUTOS!A$6:A$205,PRODUTOS!C$6:C$205),"") -> KG | E23: =IF(H23,LOOKUP($A23,PRODUTOS!A$6:A$205,PRODUTOS!D$6:D$205),"") -> 5 | F23: =IF(H23,C23*E23,"") -> 5 | G23: =HYPERLINK("#PRODUTOS!A1","LISTAR MAIS") -> LISTAR MAIS | H23: =IF(TRIM(A23)<>"",1,0) -> 1 | J23: L | K23: LITRO | L23: 0.5 | M23: =IF(J23<>"",SUMIF(D$23:D$47,$J23,C$23:C$47),"") -> 0 | N23: =IF(J23<>"",M23*L23,"") -> 0
B24: =IF(H24,LOOKUP($A24,PRODUTOS!A$6:A$205,PRODUTOS!B$6:B$205),"") | D24: =IF(H24,LOOKUP($A24,PRODUTOS!A$6:A$205,PRODUTOS!C$6:C$205),"") | E24: =IF(H24,LOOKUP($A24,PRODUTOS!A$6:A$205,PRODUTOS!D$6:D$205),"") | F24: =IF(H24,C24*E24,"") | G24: =HYPERLINK("#PRODUTOS!A1","LISTAR MAIS") -> LISTAR MAIS | H24: =IF(TRIM(A24)<>"",1,0) -> 0 | J24: KG | K24: KILO | L24: 2 | M24: =IF(J24<>"",SUMIF(D$23:D$47,$J24,C$23:C$47),"") -> 1 | N24: =IF(J24<>"",M24*L24,"") -> 2
B25: =IF(H25,LOOKUP($A25,PRODUTOS!A$6:A$205,PRODUTOS!B$6:B$205),"") | D25: =IF(H25,LOOKUP($A25,PRODUTOS!A$6:A$205,PRODUTOS!C$6:C$205),"") | E25: =IF(H25,LOOKUP($A25,PRODUTOS!A$6:A$205,PRODUTOS!D$6:D$205),"") | F25: =IF(H25,C25*E25,"") | G25: =HYPERLINK("#PRODUTOS!A1","LISTAR MAIS") -> LISTAR MAIS | H25: =IF(TRIM(A25)<>"",1,0) -> 0 | M25: =IF(J25<>"",SUMIF(D$23:D$47,$J25,C$23:C$47),"") | N25: =IF(J25<>"",M25*L25,"")
B26: =IF(H26,LOOKUP($A26,PRODUTOS!A$6:A$205,PRODUTOS!B$6:B$205),"") | D26: =IF(H26,LOOKUP($A26,PRODUTOS!A$6:A$205,PRODUTOS!C$6:C$205),"") | E26: =IF(H26,LOOKUP($A26,PRODUTOS!A$6:A$205,PRODUTOS!D$6:D$205),"") | F26: =IF(H26,C26*E26,"") | G26: =HYPERLINK("#PRODUTOS!A1","LISTAR MAIS") -> LISTAR MAIS | H26: =IF(TRIM(A26)<>"",1,0) -> 0 | M26: =IF(J26<>"",SUMIF(D$23:D$47,$J26,C$23:C$47),"") | N26: =IF(J26<>"",M26*L26,"")
B27: =IF(H27,LOOKUP($A27,PRODUTOS!A$6:A$205,PRODUTOS!B$6:B$205),"") | D27: =IF(H27,LOOKUP($A27,PRODUTOS!A$6:A$205,PRODUTOS!C$6:C$205),"") | E27: =IF(H27,LOOKUP($A27,PRODUTOS!A$6:A$205,PRODUTOS!D$6:D$205),"") | F27: =IF(H27,C27*E27,"") | G27: =HYPERLINK("#PRODUTOS!A1","LISTAR MAIS") -> LISTAR MAIS | H27: =IF(TRIM(A27)<>"",1,0) -> 0 | M27: =IF(J27<>"",SUMIF(D$23:D$47,$J27,C$23:C$47),"") | N27: =IF(J27<>"",M27*L27,"")
B28: =IF(H28,LOOKUP($A28,PRODUTOS!A$6:A$205,PRODUTOS!B$6:B$205),"") | D28: =IF(H28,LOOKUP($A28,PRODUTOS!A$6:A$205,PRODUTOS!C$6:C$205),"") | E28: =IF(H28,LOOKUP($A28,PRODUTOS!A$6:A$205,PRODUTOS!D$6:D$205),"") | F28: =IF(H28,C28*E28,"") | G28: =HYPERLINK("#PRODUTOS!A1","LISTAR MAIS") -> LISTAR MAIS | H28: =IF(TRIM(A28)<>"",1,0) -> 0 | M28: =IF(J28<>"",SUMIF(D$23:D$47,$J28,C$23:C$47),"") | N28: =IF(J28<>"",M28*L28,"")
B29: =IF(H29,LOOKUP($A29,PRODUTOS!A$6:A$205,PRODUTOS!B$6:B$205),"") | D29: =IF(H29,LOOKUP($A29,PRODUTOS!A$6:A$205,PRODUTOS!C$6:C$205),"") | E29: =IF(H29,LOOKUP($A29,PRODUTOS!A$6:A$205,PRODUTOS!D$6:D$205),"") | F29: =IF(H29,C29*E29,"") | G29: =HYPERLINK("#PRODUTOS!A1","LISTAR MAIS") -> LISTAR MAIS | H29: =IF(TRIM(A29)<>"",1,0) -> 0 | M29: =IF(J29<>"",SUMIF(D$23:D$47,$J29,C$23:C$47),"") | N29: =IF(J29<>"",M29*L29,"")
B30: =IF(H30,LOOKUP($A30,PRODUTOS!A$6:A$205,PRODUTOS!B$6:B$205),"") | D30: =IF(H30,LOOKUP($A30,PRODUTOS!A$6:A$205,PRODUTOS!C$6:C$205),"") | E30: =IF(H30,LOOKUP($A30,PRODUTOS!A$6:A$205,PRODUTOS!D$6:D$205),"") | F30: =IF(H30,C30*E30,"") | G30: =HYPERLINK("#PRODUTOS!A1","LISTAR MAIS") -> LISTAR MAIS | H30: =IF(TRIM(A30)<>"",1,0) -> 0 | M30: =IF(J30<>"",SUMIF(D$23:D$47,$J30,C$23:C$47),"") | N30: =IF(J30<>"",M30*L30,"")
B31: =IF(H31,LOOKUP($A31,PRODUTOS!A$6:A$205,PRODUTOS!B$6:B$205),"") | D31: =IF(H31,LOOKUP($A31,PRODUTOS!A$6:A$205,PRODUTOS!C$6:C$205),"") | E31: =IF(H31,LOOKUP($A31,PRODUTOS!A$6:A$205,PRODUTOS!D$6:D$205),"") | F31: =IF(H31,C31*E31,"") | G31: =HYPERLINK("#PRODUTOS!A1","LISTAR MAIS") -> LISTAR MAIS | H31: =IF(TRIM(A31)<>"",1,0) -> 0 | M31: =IF(J31<>"",SUMIF(D$23:D$47,$J31,C$23:C$47),"") | N31: =IF(J31<>"",M31*L31,"")
B32: =IF(H32,LOOKUP($A32,PRODUTOS!A$6:A$205,PRODUTOS!B$6:B$205),"") | D32: =IF(H32,LOOKUP($A32,PRODUTOS!A$6:A$205,PRODUTOS!C$6:C$205),"") | E32: =IF(H32,LOOKUP($A32,PRODUTOS!A$6:A$205,PRODUTOS!D$6:D$205),"") | F32: =IF(H32,C32*E32,"") | G32: =HYPERLINK("#PRODUTOS!A1","LISTAR MAIS") -> LISTAR MAIS | H32: =IF(TRIM(A32)<>"",1,0) -> 0 | M32: =IF(J32<>"",SUMIF(D$23:D$47,$J32,C$23:C$47),"") | N32: =IF(J32<>"",M32*L32,"")
B33: =IF(H33,LOOKUP($A33,PRODUTOS!A$6:A$205,PRODUTOS!B$6:B$205),"") | D33: =IF(H33,LOOKUP($A33,PRODUTOS!A$6:A$205,PRODUTOS!C$6:C$205),"") | E33: =IF(H33,LOOKUP($A33,PRODUTOS!A$6:A$205,PRODUTOS!D$6:D$205),"") | F33: =IF(H33,C33*E33,"") | G33: =HYPERLINK("#PRODUTOS!A1","LISTAR MAIS") -> LISTAR MAIS | H33: =IF(TRIM(A33)<>"",1,0) -> 0 | M33: =IF(J33<>"",SUMIF(D$23:D$47,$J33,C$23:C$47),"") | N33: =IF(J33<>"",M33*L33,"")
B34: =IF(H34,LOOKUP($A34,PRODUTOS!A$6:A$205,PRODUTOS!B$6:B$205),"") | D34: =IF(H34,LOOKUP($A34,PRODUTOS!A$6:A$205,PRODUTOS!C$6:C$205),"") | E34: =IF(H34,LOOKUP($A34,PRODUTOS!A$6:A$205,PRODUTOS!D$6:D$205),"") | F34: =IF(H34,C34*E34,"") | G34: =HYPERLINK("#PRODUTOS!A1","LISTAR MAIS") -> LISTAR MAIS | H34: =IF(TRIM(A34)<>"",1,0) -> 0 | M34: =IF(J34<>"",SUMIF(D$23:D$47,$J34,C$23:C$47),"") | N34: =IF(J34<>"",M34*L34,"")
B35: =IF(H35,LOOKUP($A35,PRODUTOS!A$6:A$205,PRODUTOS!B$6:B$205),"") | D35: =IF(H35,LOOKUP($A35,PRODUTOS!A$6:A$205,PRODUTOS!C$6:C$205),"") | E35: =IF(H35,LOOKUP($A35,PRODUTOS!A$6:A$205,PRODUTOS!D$6:D$205),"") | F35: =IF(H35,C35*E35,"") | G35: =HYPERLINK("#PRODUTOS!A1","LISTAR MAIS") -> LISTAR MAIS | H35: =IF(TRIM(A35)<>"",1,0) -> 0 | M35: =IF(J35<>"",SUMIF(D$23:D$47,$J35,C$23:C$47),"") | N35: =IF(J35<>"",M35*L35,"")
B36: =IF(H36,LOOKUP($A36,PRODUTOS!A$6:A$205,PRODUTOS!B$6:B$205),"") | D36: =IF(H36,LOOKUP($A36,PRODUTOS!A$6:A$205,PRODUTOS!C$6:C$205),"") | E36: =IF(H36,LOOKUP($A36,PRODUTOS!A$6:A$205,PRODUTOS!D$6:D$205),"") | F36: =IF(H36,C36*E36,"") | G36: =HYPERLINK("#PRODUTOS!A1","LISTAR MAIS") -> LISTAR MAIS | H36: =IF(TRIM(A36)<>"",1,0) -> 0 | M36: =IF(J36<>"",SUMIF(D$23:D$47,$J36,C$23:C$47),"") | N36: =IF(J36<>"",M36*L36,"")
B37: =IF(H37,LOOKUP($A37,PRODUTOS!A$6:A$205,PRODUTOS!B$6:B$205),"") | D37: =IF(H37,LOOKUP($A37,PRODUTOS!A$6:A$205,PRODUTOS!C$6:C$205),"") | E37: =IF(H37,LOOKUP($A37,PRODUTOS!A$6:A$205,PRODUTOS!D$6:D$205),"") | F37: =IF(H37,C37*E37,"") | G37: =HYPERLINK("#PRODUTOS!A1","LISTAR MAIS") -> LISTAR MAIS | H37: =IF(TRIM(A37)<>"",1,0) -> 0 | J37: TOTAL DO FRETE PARA UNIDADES DISCRIMINADAS ACIMA | N37: =SUM(N23:N36) -> 2
B38: =IF(H38,LOOKUP($A38,PRODUTOS!A$6:A$205,PRODUTOS!B$6:B$205),"") | D38: =IF(H38,LOOKUP($A38,PRODUTOS!A$6:A$205,PRODUTOS!C$6:C$205),"") | E38: =IF(H38,LOOKUP($A38,PRODUTOS!A$6:A$205,PRODUTOS!D$6:D$205),"") | F38: =IF(H38,C38*E38,"") | G38: =HYPERLINK("#PRODUTOS!A1","LISTAR MAIS") -> LISTAR MAIS | H38: =IF(TRIM(A38)<>"",1,0) -> 0 | J38: FRETE PARA ITENS DE UNIDADES NÃO RELACIONADAS ACIMA | N38: 20
B39: =IF(H39,LOOKUP($A39,PRODUTOS!A$6:A$205,PRODUTOS!B$6:B$205),"") | D39: =IF(H39,LOOKUP($A39,PRODUTOS!A$6:A$205,PRODUTOS!C$6:C$205),"") | E39: =IF(H39,LOOKUP($A39,PRODUTOS!A$6:A$205,PRODUTOS!D$6:D$205),"") | F39: =IF(H39,C39*E39,"") | G39: =HYPERLINK("#PRODUTOS!A1","LISTAR MAIS") -> LISTAR MAIS | H39: =IF(TRIM(A39)<>"",1,0) -> 0 | J39: FRETE TOTAL | N39: =N38+N37 -> 22
B40: =IF(H40,LOOKUP($A40,PRODUTOS!A$6:A$205,PRODUTOS!B$6:B$205),"") | D40: =IF(H40,LOOKUP($A40,PRODUTOS!A$6:A$205,PRODUTOS!C$6:C$205),"") | E40: =IF(H40,LOOKUP($A40,PRODUTOS!A$6:A$205,PRODUTOS!D$6:D$205),"") | F40: =IF(H40,C40*E40,"") | G40: =HYPERLINK("#PRODUTOS!A1","LISTAR MAIS") -> LISTAR MAIS | H40: =IF(TRIM(A40)<>"",1,0) -> 0
B41: =IF(H41,LOOKUP($A41,PRODUTOS!A$6:A$205,PRODUTOS!B$6:B$205),"") | D41: =IF(H41,LOOKUP($A41,PRODUTOS!A$6:A$205,PRODUTOS!C$6:C$205),"") | E41: =IF(H41,LOOKUP($A41,PRODUTOS!A$6:A$205,PRODUTOS!D$6:D$205),"") | F41: =IF(H41,C41*E41,"") | G41: =HYPERLINK("#PRODUTOS!A1","LISTAR MAIS") -> LISTAR MAIS | H41: =IF(TRIM(A41)<>"",1,0) -> 0
B42: =IF(H42,LOOKUP($A42,PRODUTOS!A$6:A$205,PRODUTOS!B$6:B$205),"") | D42: =IF(H42,LOOKUP($A42,PRODUTOS!A$6:A$205,PRODUTOS!C$6:C$205),"") | E42: =IF(H42,LOOKUP($A42,PRODUTOS!A$6:A$205,PRODUTOS!D$6:D$205),"") | F42: =IF(H42,C42*E42,"") | G42: =HYPERLINK("#PRODUTOS!A1","LISTAR MAIS") -> LISTAR MAIS | H42: =IF(TRIM(A42)<>"",1,0) -> 0
B43: =IF(H43,LOOKUP($A43,PRODUTOS!A$6:A$205,PRODUTOS!B$6:B$205),"") | D43: =IF(H43,LOOKUP($A43,PRODUTOS!A$6:A$205,PRODUTOS!C$6:C$205),"") | E43: =IF(H43,LOOKUP($A43,PRODUTOS!A$6:A$205,PRODUTOS!D$6:D$205),"") | F43: =IF(H43,C43*E43,"") | G43: =HYPERLINK("#PRODUTOS!A1","LISTAR MAIS") -> LISTAR MAIS | H43: =IF(TRIM(A43)<>"",1,0) -> 0 | J43: UTILIZE O SIMULADOR DE DESCONTO ABAIXO PARA DEFINIR
B44: =IF(H44,LOOKUP($A44,PRODUTOS!A$6:A$205,PRODUTOS!B$6:B$205),"") | D44: =IF(H44,LOOKUP($A44,PRODUTOS!A$6:A$205,PRODUTOS!C$6:C$205),"") | E44: =IF(H44,LOOKUP($A44,PRODUTOS!A$6:A$205,PRODUTOS!D$6:D$205),"") | F44: =IF(H44,C44*E44,"") | G44: =HYPERLINK("#PRODUTOS!A1","LISTAR MAIS") -> LISTAR MAIS | H44: =IF(TRIM(A44)<>"",1,0) -> 0 | J44: O DESCONTO POR PORCENTAGEM OU DIGITE O VALOR
B45: =IF(H45,LOOKUP($A45,PRODUTOS!A$6:A$205,PRODUTOS!B$6:B$205),"") | D45: =IF(H45,LOOKUP($A45,PRODUTOS!A$6:A$205,PRODUTOS!C$6:C$205),"") | E45: =IF(H45,LOOKUP($A45,PRODUTOS!A$6:A$205,PRODUTOS!D$6:D$205),"") | F45: =IF(H45,C45*E45,"") | G45: =HYPERLINK("#PRODUTOS!A1","LISTAR MAIS") -> LISTAR MAIS | H45: =IF(TRIM(A45)<>"",1,0) -> 0 | J45: DO DESCONTO DIRETAMENTE NA CÉLULA F48, AO LADO.
B46: =IF(H46,LOOKUP($A46,PRODUTOS!A$6:A$205,PRODUTOS!B$6:B$205),"") | D46: =IF(H46,LOOKUP($A46,PRODUTOS!A$6:A$205,PRODUTOS!C$6:C$205),"") | E46: =IF(H46,LOOKUP($A46,PRODUTOS!A$6:A$205,PRODUTOS!D$6:D$205),"") | F46: =IF(H46,C46*E46,"") | G46: =HYPERLINK("#PRODUTOS!A1","LISTAR MAIS") -> LISTAR MAIS | H46: =IF(TRIM(A46)<>"",1,0) -> 0
B47: =IF(H47,LOOKUP($A47,PRODUTOS!A$6:A$205,PRODUTOS!B$6:B$205),"") | D47: =IF(H47,LOOKUP($A47,PRODUTOS!A$6:A$205,PRODUTOS!C$6:C$205),"") | E47: =IF(H47,LOOKUP($A47,PRODUTOS!A$6:A$205,PRODUTOS!D$6:D$205),"") | F47: =IF(H47,C47*E47,"") | G47: =HYPERLINK("#PRODUTOS!A1","LISTAR MAIS") -> LISTAR MAIS | H47: =IF(TRIM(A47)<>"",1,0) -> 0 | J47: SIMULADOR DE DESCONTO
...
