Workbook
Name _1_2: #REF!
Name _1_2: #REF!
Name _2: #REF!
Name _2: #REF!
Name _GoBack: Configurações!#REF!
Name CotacoesTodosAtivos_3: #REF!
Name CotacoesTodosAtivos_3: #REF!
Name default_2: #REF!
Name default_2: #REF!

Sheet Operações Normais
B2: Período de Apuração | G2: Operação Normal: Operação com compra e venda em dias diferentes
B3: Mês: | C3: 6 | D3: Ano: | E3: 2020
B5: Operações Normais Ações e Opções | X5: ISS | AB5: Taxas compra | AI5: Taxas Venda
B6: Tipo | C6: Data Compra | D6: Código Ativo | E6: Quantidade | F6: Preço Compra | G6: PM Compra com custos inclusos? | H6: Movimento Compra | I6: Data Venda | J6: Preço Venda | K6: PM Venda com custos inclusos? | L6: Movimento Total | M6: Movimento Venda | N6: Taxa Negociação | O6: Taxa Liquidação | P6: Taxa Registro | Q6: Corretagem Compra | R6: Corretagem Venda | S6: Outras despesas | T6: Resultado | U6: IRRF s/ Operações | V6: % | W6: Dias | X6: (AJUSTAR) | AB6: Taxa Negociação | AC6: Taxa Liquidação | AD6: Taxa Registro | AE6: Corretagem | AF6: ISS | AG6: Total | AI6: Taxa Negociação | AJ6: Taxa Liquidação | AK6: Taxa Registro | AL6: Corretagem | AM6: ISS | AN6: Total
X7: 0.1068
B8: ACAO | G8: NÃO | H8: =E8*F8 -> 0 | K8: NÃO | L8: =SUM(H8,M8) -> 0 | M8: =E8*J8 -> 0 | N8: =ROUNDDOWN(IF(OR(B8="ACAO",B8="DIR",B8="ETF",B8="EXERCICIO"),L8*Configurações!$B$9,IF(B8="EXERC. LC",H8*Configurações!$B$9+M8*Configurações!$B$37,IF(B8="OPCAO",L8*Configurações!$B$23))),2) -> 0 | O8: =ROUNDDOWN(IF(OR(B8="ACAO",B8="DIR",B8="ETF",B8="EXERCICIO"),L8*Configurações!$C$9,IF(B8="EXERC. LC",H8*Configurações!$C$9+M8*Configurações!$C$37,IF(B8="OPCAO",L8*Configurações!$C$23))),2) -> 0 | P8: =ROUNDDOWN(IF(OR(B8="ACAO",B8="DIR",B8="ETF",B8="EXERCICIO"),L8*Configurações!$D$9,IF(B8="EXERC. LC",H8*Configurações!$D$9+M8*Configurações!$D$37,IF(B8="OPCAO",L8*Configurações!$D$23))),2) -> 0 | T8: =IF(AND(G8="SIM",K8="NÃO"),-H8+M8-P8-Q8-R8-X8-S8-O8-N8+AG8,IF(AND(K8="SIM",G8="NÃO"),-H8+M8-P8-Q8-R8-X8-S8-O8-N8+AN8,IF(AND(K8="SIM",G8="SIM"),-H8+M8-P8-Q8-R8-X8-S8-O8-N8+AN8+AG8,IF(AND(K8="NÃO",G8="NÃO"),-H8+M8-P8-Q8-R8-X8-S8-O8-N8,0)))) -> 0 | V8: =IF(D8="","-",T8/H8) -> - | W8: =DAYS360(C8,I8) -> 0 | X8: =(Q8+R8)*$X$7 -> 0 | AB8: =ROUNDDOWN(IF(OR(B8="ACAO",B8="DIR",B8="ETF",B8="EXERCICIO"),H8*Configurações!$B$9,IF(B8="EXERC. LC",H8*Configurações!$B$9,IF(B8="OPCAO",H8*Configurações!$B$23))),2) -> 0 | AC8: =ROUNDDOWN(IF(OR(B8="ACAO",B8="DIR",B8="ETF",B8="EXERCICIO"),H8*Configurações!$C$9,IF(B8="EXERC. LC",H8*Configurações!$C$9,IF(B8="OPCAO",H8*Configurações!$C$23))),2) -> 0 | AD8: =ROUNDDOWN(IF(OR(B8="ACAO",B8="DIR",B8="ETF",B8="EXERCICIO"),H8*Configurações!$D$9,IF(B8="EXERC. LC",H8*Configurações!$D$9,IF(B8="OPCAO",H8*Configurações!$D$23))),2) -> 0 | AE8: =Q8 -> 0 | AF8: =AE8*$X$7 -> 0 | AG8: =SUM(AB8:AF8) -> 0 | AI8: =ROUNDDOWN(IF(OR(B8="ACAO",B8="DIR",B8="ETF",B8="EXERCICIO"),M8*Configurações!$B$9,IF(B8="EXERC. LC",M8*Configurações!$B$37,IF(B8="OPCAO",M8*Configurações!$B$23))),2) -> 0 | AJ8: =ROUNDDOWN(IF(OR(B8="ACAO",B8="DIR",B8="ETF",B8="EXERCICIO"),M8*Configurações!$C$9,IF(B8="EXERC. LC",M8*Configurações!$C$37,IF(B8="OPCAO",M8*Configurações!$C$23))),2) -> 0 | AK8: =ROUNDDOWN(IF(OR(B8="ACAO",B8="DIR",B8="ETF",B8="EXERCICIO"),M8*Configurações!$D$9,IF(B8="EXERC. LC",M8*Configurações!$D$37,IF(B8="OPCAO",M8*Configurações!$D$23))),2) -> 0 | AL8: =R8 -> 0 | AM8: =AL8*$X$7 -> 0 | AN8: =SUM(AI8:AM8) -> 0
B9: ACAO | G9: NÃO | H9: =E9*F9 -> 0 | K9: NÃO | L9: =SUM(H9,M9) -> 0 | M9: =E9*J9 -> 0 | N9: =ROUNDDOWN(IF(OR(B9="ACAO",B9="DIR",B9="ETF",B9="EXERCICIO"),L9*Configurações!$B$9,IF(B9="EXERC. LC",H9*Configurações!$B$9+M9*Configurações!$B$37,IF(B9="OPCAO",L9*Configurações!$B$23))),2) -> 0 | O9: =ROUNDDOWN(IF(OR(B9="ACAO",B9="DIR",B9="ETF",B9="EXERCICIO"),L9*Configurações!$C$9,IF(B9="EXERC. LC",H9*Configurações!$C$9+M9*Configurações!$C$37,IF(B9="OPCAO",L9*Configurações!$C$23))),2) -> 0 | P9: =ROUNDDOWN(IF(OR(B9="ACAO",B9="DIR",B9="ETF",B9="EXERCICIO"),L9*Configurações!$D$9,IF(B9="EXERC. LC",H9*Configurações!$D$9+M9*Configurações!$D$37,IF(B9="OPCAO",L9*Configurações!$D$23))),2) -> 0 | T9: =IF(AND(G9="SIM",K9="NÃO"),-H9+M9-P9-Q9-R9-X9-S9-O9-N9+AG9,IF(AND(K9="SIM",G9="NÃO"),-H9+M9-P9-Q9-R9-X9-S9-O9-N9+AN9,IF(AND(K9="SIM",G9="SIM"),-H9+M9-P9-Q9-R9-X9-S9-O9-N9+AN9+AG9,IF(AND(K9="NÃO",G9="NÃO"),-H9+M9-P9-Q9-R9-X9-S9-O9-N9,0)))) -> 0 | V9: =IF(D9="","-",T9/H9) -> - | W9: =DAYS360(C9,I9) -> 0 | X9: =(Q9+R9)*$X$7 -> 0 | AB9: =ROUNDDOWN(IF(OR(B9="ACAO",B9="DIR",B9="ETF",B9="EXERCICIO"),H9*Configurações!$B$9,IF(B9="EXERC. LC",H9*Configurações!$B$9,IF(B9="OPCAO",H9*Configurações!$B$23))),2) -> 0 | AC9: =ROUNDDOWN(IF(OR(B9="ACAO",B9="DIR",B9="ETF",B9="EXERCICIO"),H9*Configurações!$C$9,IF(B9="EXERC. LC",H9*Configurações!$C$9,IF(B9="OPCAO",H9*Configurações!$C$23))),2) -> 0 | AD9: =ROUNDDOWN(IF(OR(B9="ACAO",B9="DIR",B9="ETF",B9="EXERCICIO"),H9*Configurações!$D$9,IF(B9="EXERC. LC",H9*Configurações!$D$9,IF(B9="OPCAO",H9*Configurações!$D$23))),2) -> 0 | AE9: =Q9 -> 0 | AF9: =AE9*$X$7 -> 0 | AG9: =SUM(AB9:AF9) -> 0 | AI9: =ROUNDDOWN(IF(OR(B9="ACAO",B9="DIR",B9="ETF",B9="EXERCICIO"),M9*Configurações!$B$9,IF(B9="EXERC. LC",M9*Configurações!$B$37,IF(B9="OPCAO",M9*Configurações!$B$23))),2) -> 0 | AJ9: =ROUNDDOWN(IF(OR(B9="ACAO",B9="DIR",B9="ETF",B9="EXERCICIO"),M9*Configurações!$C$9,IF(B9="EXERC. LC",M9*Configurações!$C$37,IF(B9="OPCAO",M9*Configurações!$C$23))),2) -> 0 | AK9: =ROUNDDOWN(IF(OR(B9="ACAO",B9="DIR",B9="ETF",B9="EXERCICIO"),M9*Configurações!$D$9,IF(B9="EXERC. LC",M9*Configurações!$D$37,IF(B9="OPCAO",M9*Configurações!$D$23))),2) -> 0 | AL9: =R9 -> 0 | AM9: =AL9*$X$7 -> 0 | AN9: =SUM(AI9:AM9) -> 0
B10: ACAO | G10: NÃO | H10: =E10*F10 -> 0 | K10: NÃO | L10: =SUM(H10,M10) -> 0 | M10: =E10*J10 -> 0 | N10: =ROUNDDOWN(IF(OR(B10="ACAO",B10="DIR",B10="ETF",B10="EXERCICIO"),L10*Configurações!$B$9,IF(B10="EXERC. LC",H10*Configurações!$B$9+M10*Configurações!$B$37,IF(B10="OPCAO",L10*Configurações!$B$23))),2) -> 0 | O10: =ROUNDDOWN(IF(OR(B10="ACAO",B10="DIR",B10="ETF",B10="EXERCICIO"),L10*Configurações!$C$9,IF(B10="EXERC. LC",H10*Configurações!$C$9+M10*Configurações!$C$37,IF(B10="OPCAO",L10*Configurações!$C$23))),2) -> 0 | P10: =ROUNDDOWN(IF(OR(B10="ACAO",B10="DIR",B10="ETF",B10="EXERCICIO"),L10*Configurações!$D$9,IF(B10="EXERC. LC",H10*Configurações!$D$9+M10*Configurações!$D$37,IF(B10="OPCAO",L10*Configurações!$D$23))),2) -> 0 | T10: =IF(AND(G10="SIM",K10="NÃO"),-H10+M10-P10-Q10-R10-X10-S10-O10-N10+AG10,IF(AND(K10="SIM",G10="NÃO"),-H10+M10-P10-Q10-R10-X10-S10-O10-N10+AN10,IF(AND(K10="SIM",G10="SIM"),-H10+M10-P10-Q10-R10-X10-S10-O10-N10+AN10+AG10,IF(AND(K10="NÃO",G10="NÃO"),-H10+M10-P10-Q10-R10-X10-S10-O10-N10,0)))) -> 0 | V10: =IF(D10="","-",T10/H10) -> - | W10: =DAYS360(C10,I10) -> 0 | X10: =(Q10+R10)*$X$7 -> 0 | AB10: =ROUNDDOWN(IF(OR(B10="ACAO",B10="DIR",B10="ETF",B10="EXERCICIO"),H10*Configurações!$B$9,IF(B10="EXERC. LC",H10*Configurações!$B$9,IF(B10="OPCAO",H10*Configurações!$B$23))),2) -> 0 | AC10: =ROUNDDOWN(IF(OR(B10="ACAO",B10="DIR",B10="ETF",B10="EXERCICIO"),H10*Configurações!$C$9,IF(B10="EXERC. LC",H10*Configurações!$C$9,IF(B10="OPCAO",H10*Configurações!$C$23))),2) -> 0 | AD10: =ROUNDDOWN(IF(OR(B10="ACAO",B10="DIR",B10="ETF",B10="EXERCICIO"),H10*Configurações!$D$9,IF(B10="EXERC. LC",H10*Configurações!$D$9,IF(B10="OPCAO",H10*Configurações!$D$23))),2) -> 0 | AE10: =Q10 -> 0 | AF10: =AE10*$X$7 -> 0 | AG10: =SUM(AB10:AF10) -> 0 | AI10: =ROUNDDOWN(IF(OR(B10="ACAO",B10="DIR",B10="ETF",B10="EXERCICIO"),M10*Configurações!$B$9,IF(B10="EXERC. LC",M10*Configurações!$B$37,IF(B10="OPCAO",M10*Configurações!$B$23))),2) -> 0 | AJ10: =ROUNDDOWN(IF(OR(B10="ACAO",B10="DIR",B10="ETF",B10="EXERCICIO"),M10*Configurações!$C$9,IF(B10="EXERC. LC",M10*Configurações!$C$37,IF(B10="OPCAO",M10*Configurações!$C$23))),2) -> 0 | AK10: =ROUNDDOWN(IF(OR(B10="ACAO",B10="DIR",B10="ETF",B10="EXERCICIO"),M10*Configurações!$D$9,IF(B10="EXERC. LC",M10*Configurações!$D$37,IF(B10="OPCAO",M10*Configurações!$D$23))),2) -> 0 | AL10: =R10 -> 0 | AM10: =AL10*$X$7 -> 0 | AN10: =SUM(AI10:AM10) -> 0 | AP10: SIM
B11: ACAO | G11: NÃO | H11: =E11*F11 -> 0 | K11: NÃO | L11: =SUM(H11,M11) -> 0 | M11: =E11*J11 -> 0 | N11: =ROUNDDOWN(IF(OR(B11="ACAO",B11="DIR",B11="ETF",B11="EXERCICIO"),L11*Configurações!$B$9,IF(B11="EXERC. LC",H11*Configurações!$B$9+M11*Configurações!$B$37,IF(B11="OPCAO",L11*Configurações!$B$23))),2) -> 0 | O11: =ROUNDDOWN(IF(OR(B11="ACAO",B11="DIR",B11="ETF",B11="EXERCICIO"),L11*Configurações!$C$9,IF(B11="EXERC. LC",H11*Configurações!$C$9+M11*Configurações!$C$37,IF(B11="OPCAO",L11*Configurações!$C$23))),2) -> 0 | P11: =ROUNDDOWN(IF(OR(B11="ACAO",B11="DIR",B11="ETF",B11="EXERCICIO"),L11*Configurações!$D$9,IF(B11="EXERC. LC",H11*Configurações!$D$9+M11*Configurações!$D$37,IF(B11="OPCAO",L11*Configurações!$D$23))),2) -> 0 | T11: =IF(AND(G11="SIM",K11="NÃO"),-H11+M11-P11-Q11-R11-X11-S11-O11-N11+AG11,IF(AND(K11="SIM",G11="NÃO"),-H11+M11-P11-Q11-R11-X11-S11-O11-N11+AN11,IF(AND(K11="SIM",G11="SIM"),-H11+M11-P11-Q11-R11-X11-S11-O11-N11+AN11+AG11,IF(AND(K11="NÃO",G11="NÃO"),-H11+M11-P11-Q11-R11-X11-S11-O11-N11,0)))) -> 0 | V11: =IF(D11="","-",T11/H11) -> - | W11: =DAYS360(C11,I11) -> 0 | X11: =(Q11+R11)*$X$7 -> 0 | AB11: =ROUNDDOWN(IF(OR(B11="ACAO",B11="DIR",B11="ETF",B11="EXERCICIO"),H11*Configurações!$B$9,IF(B11="EXERC. LC",H11*Configurações!$B$9,IF(B11="OPCAO",H11*Configurações!$B$23))),2) -> 0 | AC11: =ROUNDDOWN(IF(OR(B11="ACAO",B11="DIR",B11="ETF",B11="EXERCICIO"),H11*Configurações!$C$9,IF(B11="EXERC. LC",H11*Configurações!$C$9,IF(B11="OPCAO",H11*Configurações!$C$23))),2) -> 0 | AD11: =ROUNDDOWN(IF(OR(B11="ACAO",B11="DIR",B11="ETF",B11="EXERCICIO"),H11*Configurações!$D$9,IF(B11="EXERC. LC",H11*Configurações!$D$9,IF(B11="OPCAO",H11*Configurações!$D$23))),2) -> 0 | AE11: =Q11 -> 0 | AF11: =AE11*$X$7 -> 0 | AG11: =SUM(AB11:AF11) -> 0 | AI11: =ROUNDDOWN(IF(OR(B11="ACAO",B11="DIR",B11="ETF",B11="EXERCICIO"),M11*Configurações!$B$9,IF(B11="EXERC. LC",M11*Configurações!$B$37,IF(B11="OPCAO",M11*Configurações!$B$23))),2) -> 0 | AJ11: =ROUNDDOWN(IF(OR(B11="ACAO",B11="DIR",B11="ETF",B11="EXERCICIO"),M11*Configurações!$C$9,IF(B11="EXERC. LC",M11*Configurações!$C$37,IF(B11="OPCAO",M11*Configurações!$C$23))),2) -> 0 | AK11: =ROUNDDOWN(IF(OR(B11="ACAO",B11="DIR",B11="ETF",B11="EXERCICIO"),M11*Configurações!$D$9,IF(B11="EXERC. LC",M11*Configurações!$D$37,IF(B11="OPCAO",M11*Configurações!$D$23))),2) -> 0 | AL11: =R11 -> 0 | AM11: =AL11*$X$7 -> 0 | AN11: =SUM(AI11:AM11) -> 0 | AP11: NÃO
B12: ACAO | G12: NÃO | H12: =E12*F12 -> 0 | K12: NÃO | L12: =SUM(H12,M12) -> 0 | M12: =E12*J12 -> 0 | N12: =ROUNDDOWN(IF(OR(B12="ACAO",B12="DIR",B12="ETF",B12="EXERCICIO"),L12*Configurações!$B$9,IF(B12="EXERC. LC",H12*Configurações!$B$9+M12*Configurações!$B$37,IF(B12="OPCAO",L12*Configurações!$B$23))),2) -> 0 | O12: =ROUNDDOWN(IF(OR(B12="ACAO",B12="DIR",B12="ETF",B12="EXERCICIO"),L12*Configurações!$C$9,IF(B12="EXERC. LC",H12*Configurações!$C$9+M12*Configurações!$C$37,IF(B12="OPCAO",L12*Configurações!$C$23))),2) -> 0 | P12: =ROUNDDOWN(IF(OR(B12="ACAO",B12="DIR",B12="ETF",B12="EXERCICIO"),L12*Configurações!$D$9,IF(B12="EXERC. LC",H12*Configurações!$D$9+M12*Configurações!$D$37,IF(B12="OPCAO",L12*Configurações!$D$23))),2) -> 0 | T12: =IF(AND(G12="SIM",K12="NÃO"),-H12+M12-P12-Q12-R12-X12-S12-O12-N12+AG12,IF(AND(K12="SIM",G12="NÃO"),-H12+M12-P12-Q12-R12-X12-S12-O12-N12+AN12,IF(AND(K12="SIM",G12="SIM"),-H12+M12-P12-Q12-R12-X12-S12-O12-N12+AN12+AG12,IF(AND(K12="NÃO",G12="NÃO"),-H12+M12-P12-Q12-R12-X12-S12-O12-N12,0)))) -> 0 | V12: =IF(D12="","-",T12/H12) -> - | W12: =DAYS360(C12,I12) -> 0 | X12: =(Q12+R12)*$X$7 -> 0 | AB12: =ROUNDDOWN(IF(OR(B12="ACAO",B12="DIR",B12="ETF",B12="EXERCICIO"),H12*Configurações!$B$9,IF(B12="EXERC. LC",H12*Configurações!$B$9,IF(B12="OPCAO",H12*Configurações!$B$23))),2) -> 0 | AC12: =ROUNDDOWN(IF(OR(B12="ACAO",B12="DIR",B12="ETF",B12="EXERCICIO"),H12*Configurações!$C$9,IF(B12="EXERC. LC",H12*Configurações!$C$9,IF(B12="OPCAO",H12*Configurações!$C$23))),2) -> 0 | AD12: =ROUNDDOWN(IF(OR(B12="ACAO",B12="DIR",B12="ETF",B12="EXERCICIO"),H12*Configurações!$D$9,IF(B12="EXERC. LC",H12*Configurações!$D$9,IF(B12="OPCAO",H12*Configurações!$D$23))),2) -> 0 | AE12: =Q12 -> 0 | AF12: =AE12*$X$7 -> 0 | AG12: =SUM(AB12:AF12) -> 0 | AI12: =ROUNDDOWN(IF(OR(B12="ACAO",B12="DIR",B12="ETF",B12="EXERCICIO"),M12*Configurações!$B$9,IF(B12="EXERC. LC",M12*Configurações!$B$37,IF(B12="OPCAO",M12*Configurações!$B$23))),2) -> 0 | AJ12: =ROUNDDOWN(IF(OR(B12="ACAO",B12="DIR",B12="ETF",B12="EXERCICIO"),M12*Configurações!$C$9,IF(B12="EXERC. LC",M12*Configurações!$C$37,IF(B12="OPCAO",M12*Configurações!$C$23))),2) -> 0 | AK12: =ROUNDDOWN(IF(OR(B12="ACAO",B12="DIR",B12="ETF",B12="EXERCICIO"),M12*Configurações!$D$9,IF(B12="EXERC. LC",M12*Configurações!$D$37,IF(B12="OPCAO",M12*Configurações!$D$23))),2) -> 0 | AL12: =R12 -> 0 | AM12: =AL12*$X$7 -> 0 | AN12: =SUM(AI12:AM12) -> 0
B13: ACAO | G13: NÃO | H13: =E13*F13 -> 0 | K13: NÃO | L13: =SUM(H13,M13) -> 0 | M13: =E13*J13 -> 0 | N13: =ROUNDDOWN(IF(OR(B13="ACAO",B13="DIR",B13="ETF",B13="EXERCICIO"),L13*Configurações!$B$9,IF(B13="EXERC. LC",H13*Configurações!$B$9+M13*Configurações!$B$37,IF(B13="OPCAO",L13*Configurações!$B$23))),2) -> 0 | O13: =ROUNDDOWN(IF(OR(B13="ACAO",B13="DIR",B13="ETF",B13="EXERCICIO"),L13*Configurações!$C$9,IF(B13="EXERC. LC",H13*Configurações!$C$9+M13*Configurações!$C$37,IF(B13="OPCAO",L13*Configurações!$C$23))),2) -> 0 | P13: =ROUNDDOWN(IF(OR(B13="ACAO",B13="DIR",B13="ETF",B13="EXERCICIO"),L13*Configurações!$D$9,IF(B13="EXERC. LC",H13*Configurações!$D$9+M13*Configurações!$D$37,IF(B13="OPCAO",L13*Configurações!$D$23))),2) -> 0 | T13: =IF(AND(G13="SIM",K13="NÃO"),-H13+M13-P13-Q13-R13-X13-S13-O13-N13+AG13,IF(AND(K13="SIM",G13="NÃO"),-H13+M13-P13-Q13-R13-X13-S13-O13-N13+AN13,IF(AND(K13="SIM",G13="SIM"),-H13+M13-P13-Q13-R13-X13-S13-O13-N13+AN13+AG13,IF(AND(K13="NÃO",G13="NÃO"),-H13+M13-P13-Q13-R13-X13-S13-O13-N13,0)))) -> 0 | V13: =IF(D13="","-",T13/H13) -> - | W13: =DAYS360(C13,I13) -> 0 | X13: =(Q13+R13)*$X$7 -> 0 | AB13: =ROUNDDOWN(IF(OR(B13="ACAO",B13="DIR",B13="ETF",B13="EXERCICIO"),H13*Configurações!$B$9,IF(B13="EXERC. LC",H13*Configurações!$B$9,IF(B13="OPCAO",H13*Configurações!$B$23))),2) -> 0 | AC13: =ROUNDDOWN(IF(OR(B13="ACAO",B13="DIR",B13="ETF",B13="EXERCICIO"),H13*Configurações!$C$9,IF(B13="EXERC. LC",H13*Configurações!$C$9,IF(B13="OPCAO",H13*Configurações!$C$23))),2) -> 0 | AD13: =ROUNDDOWN(IF(OR(B13="ACAO",B13="DIR",B13="ETF",B13="EXERCICIO"),H13*Configurações!$D$9,IF(B13="EXERC. LC",H13*Configurações!$D$9,IF(B13="OPCAO",H13*Configurações!$D$23))),2) -> 0 | AE13: =Q13 -> 0 | AF13: =AE13*$X$7 -> 0 | AG13: =SUM(AB13:AF13) -> 0 | AI13: =ROUNDDOWN(IF(OR(B13="ACAO",B13="DIR",B13="ETF",B13="EXERCICIO"),M13*Configurações!$B$9,IF(B13="EXERC. LC",M13*Configurações!$B$37,IF(B13="OPCAO",M13*Configurações!$B$23))),2) -> 0 | AJ13: =ROUNDDOWN(IF(OR(B13="ACAO",B13="DIR",B13="ETF",B13="EXERCICIO"),M13*Configurações!$C$9,IF(B13="EXERC. LC",M13*Configurações!$C$37,IF(B13="OPCAO",M13*Configurações!$C$23))),2) -> 0 | AK13: =ROUNDDOWN(IF(OR(B13="ACAO",B13="DIR",B13="ETF",B13="EXERCICIO"),M13*Configurações!$D$9,IF(B13="EXERC. LC",M13*Configurações!$D$37,IF(B13="OPCAO",M13*Configurações!$D$23))),2) -> 0 | AL13: =R13 -> 0 | AM13: =AL13*$X$7 -> 0 | AN13: =SUM(AI13:AM13) -> 0
B14: ACAO | G14: NÃO | H14: =E14*F14 -> 0 | K14: NÃO | L14: =SUM(H14,M14) -> 0 | M14: =E14*J14 -> 0 | N14: =ROUNDDOWN(IF(OR(B14="ACAO",B14="DIR",B14="ETF",B14="EXERCICIO"),L14*Configurações!$B$9,IF(B14="EXERC. LC",H14*Configurações!$B$9+M14*Configurações!$B$37,IF(B14="OPCAO",L14*Configurações!$B$23))),2) -> 0 | O14: =ROUNDDOWN(IF(OR(B14="ACAO",B14="DIR",B14="ETF",B14="EXERCICIO"),L14*Configurações!$C$9,IF(B14="EXERC. LC",H14*Configurações!$C$9+M14*Configurações!$C$37,IF(B14="OPCAO",L14*Configurações!$C$23))),2) -> 0 | P14: =ROUNDDOWN(IF(OR(B14="ACAO",B14="DIR",B14="ETF",B14="EXERCICIO"),L14*Configurações!$D$9,IF(B14="EXERC. LC",H14*Configurações!$D$9+M14*Configurações!$D$37,IF(B14="OPCAO",L14*Configurações!$D$23))),2) -> 0 | T14: =IF(AND(G14="SIM",K14="NÃO"),-H14+M14-P14-Q14-R14-X14-S14-O14-N14+AG14,IF(AND(K14="SIM",G14="NÃO"),-H14+M14-P14-Q14-R14-X14-S14-O14-N14+AN14,IF(AND(K14="SIM",G14="SIM"),-H14+M14-P14-Q14-R14-X14-S14-O14-N14+AN14+AG14,IF(AND(K14="NÃO",G14="NÃO"),-H14+M14-P14-Q14-R14-X14-S14-O14-N14,0)))) -> 0 | V14: =IF(D14="","-",T14/H14) -> - | W14: =DAYS360(C14,I14) -> 0 | X14: =(Q14+R14)*$X$7 -> 0 | AB14: =ROUNDDOWN(IF(OR(B14="ACAO",B14="DIR",B14="ETF",B14="EXERCICIO"),H14*Configurações!$B$9,IF(B14="EXERC. LC",H14*Configurações!$B$9,IF(B14="OPCAO",H14*Configurações!$B$23))),2) -> 0 | AC14: =ROUNDDOWN(IF(OR(B14="ACAO",B14="DIR",B14="ETF",B14="EXERCICIO"),H14*Configurações!$C$9,IF(B14="EXERC. LC",H14*Configurações!$C$9,IF(B14="OPCAO",H14*Configurações!$C$23))),2) -> 0 | AD14: =ROUNDDOWN(IF(OR(B14="ACAO",B14="DIR",B14="ETF",B14="EXERCICIO"),H14*Configurações!$D$9,IF(B14="EXERC. LC",H14*Configurações!$D$9,IF(B14="OPCAO",H14*Configurações!$D$23))),2) -> 0 | AE14: =Q14 -> 0 | AF14: =AE14*$X$7 -> 0 | AG14: =SUM(AB14:AF14) -> 0 | AI14: =ROUNDDOWN(IF(OR(B14="ACAO",B14="DIR",B14="ETF",B14="EXERCICIO"),M14*Configurações!$B$9,IF(B14="EXERC. LC",M14*Configurações!$B$37,IF(B14="OPCAO",M14*Configurações!$B$23))),2) -> 0 | AJ14: =ROUNDDOWN(IF(OR(B14="ACAO",B14="DIR",B14="ETF",B14="EXERCICIO"),M14*Configurações!$C$9,IF(B14="EXERC. LC",M14*Configurações!$C$37,IF(B14="OPCAO",M14*Configurações!$C$23))),2) -> 0 | AK14: =ROUNDDOWN(IF(OR(B14="ACAO",B14="DIR",B14="ETF",B14="EXERCICIO"),M14*Configurações!$D$9,IF(B14="EXERC. LC",M14*Configurações!$D$37,IF(B14="OPCAO",M14*Configurações!$D$23))),2) -> 0 | AL14: =R14 -> 0 | AM14: =AL14*$X$7 -> 0 | AN14: =SUM(AI14:AM14) -> 0
B15: ACAO | G15: NÃO | H15: =E15*F15 -> 0 | K15: NÃO | L15: =SUM(H15,M15) -> 0 | M15: =E15*J15 -> 0 | N15: =ROUNDDOWN(IF(OR(B15="ACAO",B15="DIR",B15="ETF",B15="EXERCICIO"),L15*Configurações!$B$9,IF(B15="EXERC. LC",H15*Configurações!$B$9+M15*Configurações!$B$37,IF(B15="OPCAO",L15*Configurações!$B$23))),2) -> 0 | O15: =ROUNDDOWN(IF(OR(B15="ACAO",B15="DIR",B15="ETF",B15="EXERCICIO"),L15*Configurações!$C$9,IF(B15="EXERC. LC",H15*Configurações!$C$9+M15*Configurações!$C$37,IF(B15="OPCAO",L15*Configurações!$C$23))),2) -> 0 | P15: =ROUNDDOWN(IF(OR(B15="ACAO",B15="DIR",B15="ETF",B15="EXERCICIO"),L15*Configurações!$D$9,IF(B15="EXERC. LC",H15*Configurações!$D$9+M15*Configurações!$D$37,IF(B15="OPCAO",L15*Configurações!$D$23))),2) -> 0 | T15: =IF(AND(G15="SIM",K15="NÃO"),-H15+M15-P15-Q15-R15-X15-S15-O15-N15+AG15,IF(AND(K15="SIM",G15="NÃO"),-H15+M15-P15-Q15-R15-X15-S15-O15-N15+AN15,IF(AND(K15="SIM",G15="SIM"),-H15+M15-P15-Q15-R15-X15-S15-O15-N15+AN15+AG15,IF(AND(K15="NÃO",G15="NÃO"),-H15+M15-P15-Q15-R15-X15-S15-O15-N15,0)))) -> 0 | V15: =IF(D15="","-",T15/H15) -> - | W15: =DAYS360(C15,I15) -> 0 | X15: =(Q15+R15)*$X$7 -> 0 | AB15: =ROUNDDOWN(IF(OR(B15="ACAO",B15="DIR",B15="ETF",B15="EXERCICIO"),H15*Configurações!$B$9,IF(B15="EXERC. LC",H15*Configurações!$B$9,IF(B15="OPCAO",H15*Configurações!$B$23))),2) -> 0 | AC15: =ROUNDDOWN(IF(OR(B15="ACAO",B15="DIR",B15="ETF",B15="EXERCICIO"),H15*Configurações!$C$9,IF(B15="EXERC. LC",H15*Configurações!$C$9,IF(B15="OPCAO",H15*Configurações!$C$23))),2) -> 0 | AD15: =ROUNDDOWN(IF(OR(B15="ACAO",B15="DIR",B15="ETF",B15="EXERCICIO"),H15*Configurações!$D$9,IF(B15="EXERC. LC",H15*Configurações!$D$9,IF(B15="OPCAO",H15*Configurações!$D$23))),2) -> 0 | AE15: =Q15 -> 0 | AF15: =AE15*$X$7 -> 0 | AG15: =SUM(AB15:AF15) -> 0 | AI15: =ROUNDDOWN(IF(OR(B15="ACAO",B15="DIR",B15="ETF",B15="EXERCICIO"),M15*Configurações!$B$9,IF(B15="EXERC. LC",M15*Configurações!$B$37,IF(B15="OPCAO",M15*Configurações!$B$23))),2) -> 0 | AJ15: =ROUNDDOWN(IF(OR(B15="ACAO",B15="DIR",B15="ETF",B15="EXERCICIO"),M15*Configurações!$C$9,IF(B15="EXERC. LC",M15*Configurações!$C$37,IF(B15="OPCAO",M15*Configurações!$C$23))),2) -> 0 | AK15: =ROUNDDOWN(IF(OR(B15="ACAO",B15="DIR",B15="ETF",B15="EXERCICIO"),M15*Configurações!$D$9,IF(B15="EXERC. LC",M15*Configurações!$D$37,IF(B15="OPCAO",M15*Configurações!$D$23))),2) -> 0 | AL15: =R15 -> 0 | AM15: =AL15*$X$7 -> 0 | AN15: =SUM(AI15:AM15) -> 0
B16: ACAO | G16: NÃO | H16: =E16*F16 -> 0 | K16: NÃO | L16: =SUM(H16,M16) -> 0 | M16: =E16*J16 -> 0 | N16: =ROUNDDOWN(IF(OR(B16="ACAO",B16="DIR",B16="ETF",B16="EXERCICIO"),L16*Configurações!$B$9,IF(B16="EXERC. LC",H16*Configurações!$B$9+M16*Configurações!$B$37,IF(B16="OPCAO",L16*Configurações!$B$23))),2) -> 0 | O16: =ROUNDDOWN(IF(OR(B16="ACAO",B16="DIR",B16="ETF",B16="EXERCICIO"),L16*Configurações!$C$9,IF(B16="EXERC. LC",H16*Configurações!$C$9+M16*Configurações!$C$37,IF(B16="OPCAO",L16*Configurações!$C$23))),2) -> 0 | P16: =ROUNDDOWN(IF(OR(B16="ACAO",B16="DIR",B16="ETF",B16="EXERCICIO"),L16*Configurações!$D$9,IF(B16="EXERC. LC",H16*Configurações!$D$9+M16*Configurações!$D$37,IF(B16="OPCAO",L16*Configurações!$D$23))),2) -> 0 | T16: =IF(AND(G16="SIM",K16="NÃO"),-H16+M16-P16-Q16-R16-X16-S16-O16-N16+AG16,IF(AND(K16="SIM",G16="NÃO"),-H16+M16-P16-Q16-R16-X16-S16-O16-N16+AN16,IF(AND(K16="SIM",G16="SIM"),-H16+M16-P16-Q16-R16-X16-S16-O16-N16+AN16+AG16,IF(AND(K16="NÃO",G16="NÃO"),-H16+M16-P16-Q16-R16-X16-S16-O16-N16,0)))) -> 0 | V16: =IF(D16="","-",T16/H16) -> - | W16: =DAYS360(C16,I16) -> 0 | X16: =(Q16+R16)*$X$7 -> 0 | AB16: =ROUNDDOWN(IF(OR(B16="ACAO",B16="DIR",B16="ETF",B16="EXERCICIO"),H16*Configurações!$B$9,IF(B16="EXERC. LC",H16*Configurações!$B$9,IF(B16="OPCAO",H16*Configurações!$B$23))),2) -> 0 | AC16: =ROUNDDOWN(IF(OR(B16="ACAO",B16="DIR",B16="ETF",B16="EXERCICIO"),H16*Configurações!$C$9,IF(B16="EXERC. LC",H16*Configurações!$C$9,IF(B16="OPCAO",H16*Configurações!$C$23))),2) -> 0 | AD16: =ROUNDDOWN(IF(OR(B16="ACAO",B16="DIR",B16="ETF",B16="EXERCICIO"),H16*Configurações!$D$9,IF(B16="EXERC. LC",H16*Configurações!$D$9,IF(B16="OPCAO",H16*Configurações!$D$23))),2) -> 0 | AE16: =Q16 -> 0 | AF16: =AE16*$X$7 -> 0 | AG16: =SUM(AB16:AF16) -> 0 | AI16: =ROUNDDOWN(IF(OR(B16="ACAO",B16="DIR",B16="ETF",B16="EXERCICIO"),M16*Configurações!$B$9,IF(B16="EXERC. LC",M16*Configurações!$B$37,IF(B16="OPCAO",M16*Configurações!$B$23))),2) -> 0 | AJ16: =ROUNDDOWN(IF(OR(B16="ACAO",B16="DIR",B16="ETF",B16="EXERCICIO"),M16*Configurações!$C$9,IF(B16="EXERC. LC",M16*Configurações!$C$37,IF(B16="OPCAO",M16*Configurações!$C$23))),2) -> 0 | AK16: =ROUNDDOWN(IF(OR(B16="ACAO",B16="DIR",B16="ETF",B16="EXERCICIO"),M16*Configurações!$D$9,IF(B16="EXERC. LC",M16*Configurações!$D$37,IF(B16="OPCAO",M16*Configurações!$D$23))),2) -> 0 | AL16: =R16 -> 0 | AM16: =AL16*$X$7 -> 0 | AN16: =SUM(AI16:AM16) -> 0
B17: ACAO | G17: NÃO | H17: =E17*F17 -> 0 | K17: NÃO | L17: =SUM(H17,M17) -> 0 | M17: =E17*J17 -> 0 | N17: =ROUNDDOWN(IF(OR(B17="ACAO",B17="DIR",B17="ETF",B17="EXERCICIO"),L17*Configurações!$B$9,IF(B17="EXERC. LC",H17*Configurações!$B$9+M17*Configurações!$B$37,IF(B17="OPCAO",L17*Configurações!$B$23))),2) -> 0 | O17: =ROUNDDOWN(IF(OR(B17="ACAO",B17="DIR",B17="ETF",B17="EXERCICIO"),L17*Configurações!$C$9,IF(B17="EXERC. LC",H17*Configurações!$C$9+M17*Configurações!$C$37,IF(B17="OPCAO",L17*Configurações!$C$23))),2) -> 0 | P17: =ROUNDDOWN(IF(OR(B17="ACAO",B17="DIR",B17="ETF",B17="EXERCICIO"),L17*Configurações!$D$9,IF(B17="EXERC. LC",H17*Configurações!$D$9+M17*Configurações!$D$37,IF(B17="OPCAO",L17*Configurações!$D$23))),2) -> 0 | T17: =IF(AND(G17="SIM",K17="NÃO"),-H17+M17-P17-Q17-R17-X17-S17-O17-N17+AG17,IF(AND(K17="SIM",G17="NÃO"),-H17+M17-P17-Q17-R17-X17-S17-O17-N17+AN17,IF(AND(K17="SIM",G17="SIM"),-H17+M17-P17-Q17-R17-X17-S17-O17-N17+AN17+AG17,IF(AND(K17="NÃO",G17="NÃO"),-H17+M17-P17-Q17-R17-X17-S17-O17-N17,0)))) -> 0 | V17: =IF(D17="","-",T17/H17) -> - | W17: =DAYS360(C17,I17) -> 0 | X17: =(Q17+R17)*$X$7 -> 0 | AB17: =ROUNDDOWN(IF(OR(B17="ACAO",B17="DIR",B17="ETF",B17="EXERCICIO"),H17*Configurações!$B$9,IF(B17="EXERC. LC",H17*Configurações!$B$9,IF(B17="OPCAO",H17*Configurações!$B$23))),2) -> 0 | AC17: =ROUNDDOWN(IF(OR(B17="ACAO",B17="DIR",B17="ETF",B17="EXERCICIO"),H17*Configurações!$C$9,IF(B17="EXERC. LC",H17*Configurações!$C$9,IF(B17="OPCAO",H17*Configurações!$C$23))),2) -> 0 | AD17: =ROUNDDOWN(IF(OR(B17="ACAO",B17="DIR",B17="ETF",B17="EXERCICIO"),H17*Configurações!$D$9,IF(B17="EXERC. LC",H17*Configurações!$D$9,IF(B17="OPCAO",H17*Configurações!$D$23))),2) -> 0 | AE17: =Q17 -> 0 | AF17: =AE17*$X$7 -> 0 | AG17: =SUM(AB17:AF17) -> 0 | AI17: =ROUNDDOWN(IF(OR(B17="ACAO",B17="DIR",B17="ETF",B17="EXERCICIO"),M17*Configurações!$B$9,IF(B17="EXERC. LC",M17*Configurações!$B$37,IF(B17="OPCAO",M17*Configurações!$B$23))),2) -> 0 | AJ17: =ROUNDDOWN(IF(OR(B17="ACAO",B17="DIR",B17="ETF",B17="EXERCICIO"),M17*Configurações!$C$9,IF(B17="EXERC. LC",M17*Configurações!$C$37,IF(B17="OPCAO",M17*Configurações!$C$23))),2) -> 0 | AK17: =ROUNDDOWN(IF(OR(B17="ACAO",B17="DIR",B17="ETF",B17="EXERCICIO"),M17*Configurações!$D$9,IF(B17="EXERC. LC",M17*Configurações!$D$37,IF(B17="OPCAO",M17*Configurações!$D$23))),2) -> 0 | AL17: =R17 -> 0 | AM17: =AL17*$X$7 -> 0 | AN17: =SUM(AI17:AM17) -> 0
B18: ACAO | G18: NÃO | H18: =E18*F18 -> 0 | K18: NÃO | L18: =SUM(H18,M18) -> 0 | M18: =E18*J18 -> 0 | N18: =ROUNDDOWN(IF(OR(B18="ACAO",B18="DIR",B18="ETF",B18="EXERCICIO"),L18*Configurações!$B$9,IF(B18="EXERC. LC",H18*Configurações!$B$9+M18*Configurações!$B$37,IF(B18="OPCAO",L18*Configurações!$B$23))),2) -> 0 | O18: =ROUNDDOWN(IF(OR(B18="ACAO",B18="DIR",B18="ETF",B18="EXERCICIO"),L18*Configurações!$C$9,IF(B18="EXERC. LC",H18*Configurações!$C$9+M18*Configurações!$C$37,IF(B18="OPCAO",L18*Configurações!$C$23))),2) -> 0 | P18: =ROUNDDOWN(IF(OR(B18="ACAO",B18="DIR",B18="ETF",B18="EXERCICIO"),L18*Configurações!$D$9,IF(B18="EXERC. LC",H18*Configurações!$D$9+M18*Configurações!$D$37,IF(B18="OPCAO",L18*Configurações!$D$23))),2) -> 0 | T18: =IF(AND(G18="SIM",K18="NÃO"),-H18+M18-P18-Q18-R18-X18-S18-O18-N18+AG18,IF(AND(K18="SIM",G18="NÃO"),-H18+M18-P18-Q18-R18-X18-S18-O18-N18+AN18,IF(AND(K18="SIM",G18="SIM"),-H18+M18-P18-Q18-R18-X18-S18-O18-N18+AN18+AG18,IF(AND(K18="NÃO",G18="NÃO"),-H18+M18-P18-Q18-R18-X18-S18-O18-N18,0)))) -> 0 | V18: =IF(D18="","-",T18/H18) -> - | W18: =DAYS360(C18,I18) -> 0 | X18: =(Q18+R18)*$X$7 -> 0 | AB18: =ROUNDDOWN(IF(OR(B18="ACAO",B18="DIR",B18="ETF",B18="EXERCICIO"),H18*Configurações!$B$9,IF(B18="EXERC. LC",H18*Configurações!$B$9,IF(B18="OPCAO",H18*Configurações!$B$23))),2) -> 0 | AC18: =ROUNDDOWN(IF(OR(B18="ACAO",B18="DIR",B18="ETF",B18="EXERCICIO"),H18*Configurações!$C$9,IF(B18="EXERC. LC",H18*Configurações!$C$9,IF(B18="OPCAO",H18*Configurações!$C$23))),2) -> 0 | AD18: =ROUNDDOWN(IF(OR(B18="ACAO",B18="DIR",B18="ETF",B18="EXERCICIO"),H18*Configurações!$D$9,IF(B18="EXERC. LC",H18*Configurações!$D$9,IF(B18="OPCAO",H18*Configurações!$D$23))),2) -> 0 | AE18: =Q18 -> 0 | AF18: =AE18*$X$7 -> 0 | AG18: =SUM(AB18:AF18) -> 0 | AI18: =ROUNDDOWN(IF(OR(B18="ACAO",B18="DIR",B18="ETF",B18="EXERCICIO"),M18*Configurações!$B$9,IF(B18="EXERC. LC",M18*Configurações!$B$37,IF(B18="OPCAO",M18*Configurações!$B$23))),2) -> 0 | AJ18: =ROUNDDOWN(IF(OR(B18="ACAO",B18="DIR",B18="ETF",B18="EXERCICIO"),M18*Configurações!$C$9,IF(B18="EXERC. LC",M18*Configurações!$C$37,IF(B18="OPCAO",M18*Configurações!$C$23))),2) -> 0 | AK18: =ROUNDDOWN(IF(OR(B18="ACAO",B18="DIR",B18="ETF",B18="EXERCICIO"),M18*Configurações!$D$9,IF(B18="EXERC. LC",M18*Configurações!$D$37,IF(B18="OPCAO",M18*Configurações!$D$23))),2) -> 0 | AL18: =R18 -> 0 | AM18: =AL18*$X$7 -> 0 | AN18: =SUM(AI18:AM18) -> 0
B19: ACAO | G19: NÃO | H19: =E19*F19 -> 0 | K19: NÃO | L19: =SUM(H19,M19) -> 0 | M19: =E19*J19 -> 0 | N19: =ROUNDDOWN(IF(OR(B19="ACAO",B19="DIR",B19="ETF",B19="EXERCICIO"),L19*Configurações!$B$9,IF(B19="EXERC. LC",H19*Configurações!$B$9+M19*Configurações!$B$37,IF(B19="OPCAO",L19*Configurações!$B$23))),2) -> 0 | O19: =ROUNDDOWN(IF(OR(B19="ACAO",B19="DIR",B19="ETF",B19="EXERCICIO"),L19*Configurações!$C$9,IF(B19="EXERC. LC",H19*Configurações!$C$9+M19*Configurações!$C$37,IF(B19="OPCAO",L19*Configurações!$C$23))),2) -> 0 | P19: =ROUNDDOWN(IF(OR(B19="ACAO",B19="DIR",B19="ETF",B19="EXERCICIO"),L19*Configurações!$D$9,IF(B19="EXERC. LC",H19*Configurações!$D$9+M19*Configurações!$D$37,IF(B19="OPCAO",L19*Configurações!$D$23))),2) -> 0 | T19: =IF(AND(G19="SIM",K19="NÃO"),-H19+M19-P19-Q19-R19-X19-S19-O19-N19+AG19,IF(AND(K19="SIM",G19="NÃO"),-H19+M19-P19-Q19-R19-X19-S19-O19-N19+AN19,IF(AND(K19="SIM",G19="SIM"),-H19+M19-P19-Q19-R19-X19-S19-O19-N19+AN19+AG19,IF(AND(K19="NÃO",G19="NÃO"),-H19+M19-P19-Q19-R19-X19-S19-O19-N19,0)))) -> 0 | V19: =IF(D19="","-",T19/H19) -> - | W19: =DAYS360(C19,I19) -> 0 | X19: =(Q19+R19)*$X$7 -> 0 | AB19: =ROUNDDOWN(IF(OR(B19="ACAO",B19="DIR",B19="ETF",B19="EXERCICIO"),H19*Configurações!$B$9,IF(B19="EXERC. LC",H19*Configurações!$B$9,IF(B19="OPCAO",H19*Configurações!$B$23))),2) -> 0 | AC19: =ROUNDDOWN(IF(OR(B19="ACAO",B19="DIR",B19="ETF",B19="EXERCICIO"),H19*Configurações!$C$9,IF(B19="EXERC. LC",H19*Configurações!$C$9,IF(B19="OPCAO",H19*Configurações!$C$23))),2) -> 0 | AD19: =ROUNDDOWN(IF(OR(B19="ACAO",B19="DIR",B19="ETF",B19="EXERCICIO"),H19*Configurações!$D$9,IF(B19="EXERC. LC",H19*Configurações!$D$9,IF(B19="OPCAO",H19*Configurações!$D$23))),2) -> 0 | AE19: =Q19 -> 0 | AF19: =AE19*$X$7 -> 0 | AG19: =SUM(AB19:AF19) -> 0 | AI19: =ROUNDDOWN(IF(OR(B19="ACAO",B19="DIR",B19="ETF",B19="EXERCICIO"),M19*Configurações!$B$9,IF(B19="EXERC. LC",M19*Configurações!$B$37,IF(B19="OPCAO",M19*Configurações!$B$23))),2) -> 0 | AJ19: =ROUNDDOWN(IF(OR(B19="ACAO",B19="DIR",B19="ETF",B19="EXERCICIO"),M19*Configurações!$C$9,IF(B19="EXERC. LC",M19*Configurações!$C$37,IF(B19="OPCAO",M19*Configurações!$C$23))),2) -> 0 | AK19: =ROUNDDOWN(IF(OR(B19="ACAO",B19="DIR",B19="ETF",B19="EXERCICIO"),M19*Configurações!$D$9,IF(B19="EXERC. LC",M19*Configurações!$D$37,IF(B19="OPCAO",M19*Configurações!$D$23))),2) -> 0 | AL19: =R19 -> 0 | AM19: =AL19*$X$7 -> 0 | AN19: =SUM(AI19:AM19) -> 0
B20: ACAO | G20: NÃO | H20: =E20*F20 -> 0 | K20: NÃO | L20: =SUM(H20,M20) -> 0 | M20: =E20*J20 -> 0 | N20: =ROUNDDOWN(IF(OR(B20="ACAO",B20="DIR",B20="ETF",B20="EXERCICIO"),L20*Configurações!$B$9,IF(B20="EXERC. LC",H20*Configurações!$B$9+M20*Configurações!$B$37,IF(B20="OPCAO",L20*Configurações!$B$23))),2) -> 0 | O20: =ROUNDDOWN(IF(OR(B20="ACAO",B20="DIR",B20="ETF",B20="EXERCICIO"),L20*Configurações!$C$9,IF(B20="EXERC. LC",H20*Configurações!$C$9+M20*Configurações!$C$37,IF(B20="OPCAO",L20*Configurações!$C$23))),2) -> 0 | P20: =ROUNDDOWN(IF(OR(B20="ACAO",B20="DIR",B20="ETF",B20="EXERCICIO"),L20*Configurações!$D$9,IF(B20="EXERC. LC",H20*Configurações!$D$9+M20*Configurações!$D$37,IF(B20="OPCAO",L20*Configurações!$D$23))),2) -> 0 | T20: =IF(AND(G20="SIM",K20="NÃO"),-H20+M20-P20-Q20-R20-X20-S20-O20-N20+AG20,IF(AND(K20="SIM",G20="NÃO"),-H20+M20-P20-Q20-R20-X20-S20-O20-N20+AN20,IF(AND(K20="SIM",G20="SIM"),-H20+M20-P20-Q20-R20-X20-S20-O20-N20+AN20+AG20,IF(AND(K20="NÃO",G20="NÃO"),-H20+M20-P20-Q20-R20-X20-S20-O20-N20,0)))) -> 0 | V20: =IF(D20="","-",T20/H20) -> - | W20: =DAYS360(C20,I20) -> 0 | X20: =(Q20+R20)*$X$7 -> 0 | AB20: =ROUNDDOWN(IF(OR(B20="ACAO",B20="DIR",B20="ETF",B20="EXERCICIO"),H20*Configurações!$B$9,IF(B20="EXERC. LC",H20*Configurações!$B$9,IF(B20="OPCAO",H20*Configurações!$B$23))),2) -> 0 | AC20: =ROUNDDOWN(IF(OR(B20="ACAO",B20="DIR",B20="ETF",B20="EXERCICIO"),H20*Configurações!$C$9,IF(B20="EXERC. LC",H20*Configurações!$C$9,IF(B20="OPCAO",H20*Configurações!$C$23))),2) -> 0 | AD20: =ROUNDDOWN(IF(OR(B20="ACAO",B20="DIR",B20="ETF",B20="EXERCICIO"),H20*Configurações!$D$9,IF(B20="EXERC. LC",H20*Configurações!$D$9,IF(B20="OPCAO",H20*Configurações!$D$23))),2) -> 0 | AE20: =Q20 -> 0 | AF20: =AE20*$X$7 -> 0 | AG20: =SUM(AB20:AF20) -> 0 | AI20: =ROUNDDOWN(IF(OR(B20="ACAO",B20="DIR",B20="ETF",B20="EXERCICIO"),M20*Configurações!$B$9,IF(B20="EXERC. LC",M20*Configurações!$B$37,IF(B20="OPCAO",M20*Configurações!$B$23))),2) -> 0 | AJ20: =ROUNDDOWN(IF(OR(B20="ACAO",B20="DIR",B20="ETF",B20="EXERCICIO"),M20*Configurações!$C$9,IF(B20="EXERC. LC",M20*Configurações!$C$37,IF(B20="OPCAO",M20*Configurações!$C$23))),2) -> 0 | AK20: =ROUNDDOWN(IF(OR(B20="ACAO",B20="DIR",B20="ETF",B20="EXERCICIO"),M20*Configurações!$D$9,IF(B20="EXERC. LC",M20*Configurações!$D$37,IF(B20="OPCAO",M20*Configurações!$D$23))),2) -> 0 | AL20: =R20 -> 0 | AM20: =AL20*$X$7 -> 0 | AN20: =SUM(AI20:AM20) -> 0
B21: ACAO | G21: NÃO | H21: =E21*F21 -> 0 | K21: NÃO | L21: =SUM(H21,M21) -> 0 | M21: =E21*J21 -> 0 | N21: =ROUNDDOWN(IF(OR(B21="ACAO",B21="DIR",B21="ETF",B21="EXERCICIO"),L21*Configurações!$B$9,IF(B21="EXERC. LC",H21*Configurações!$B$9+M21*Configurações!$B$37,IF(B21="OPCAO",L21*Configurações!$B$23))),2) -> 0 | O21: =ROUNDDOWN(IF(OR(B21="ACAO",B21="DIR",B21="ETF",B21="EXERCICIO"),L21*Configurações!$C$9,IF(B21="EXERC. LC",H21*Configurações!$C$9+M21*Configurações!$C$37,IF(B21="OPCAO",L21*Configurações!$C$23))),2) -> 0 | P21: =ROUNDDOWN(IF(OR(B21="ACAO",B21="DIR",B21="ETF",B21="EXERCICIO"),L21*Configurações!$D$9,IF(B21="EXERC. LC",H21*Configurações!$D$9+M21*Configurações!$D$37,IF(B21="OPCAO",L21*Configurações!$D$23))),2) -> 0 | T21: =IF(AND(G21="SIM",K21="NÃO"),-H21+M21-P21-Q21-R21-X21-S21-O21-N21+AG21,IF(AND(K21="SIM",G21="NÃO"),-H21+M21-P21-Q21-R21-X21-S21-O21-N21+AN21,IF(AND(K21="SIM",G21="SIM"),-H21+M21-P21-Q21-R21-X21-S21-O21-N21+AN21+AG21,IF(AND(K21="NÃO",G21="NÃO"),-H21+M21-P21-Q21-R21-X21-S21-O21-N21,0)))) -> 0 | V21: =IF(D21="","-",T21/H21) -> - | W21: =DAYS360(C21,I21) -> 0 | X21: =(Q21+R21)*$X$7 -> 0 | AB21: =ROUNDDOWN(IF(OR(B21="ACAO",B21="DIR",B21="ETF",B21="EXERCICIO"),H21*Configurações!$B$9,IF(B21="EXERC. LC",H21*Configurações!$B$9,IF(B21="OPCAO",H21*Configurações!$B$23))),2) -> 0 | AC21: =ROUNDDOWN(IF(OR(B21="ACAO",B21="DIR",B21="ETF",B21="EXERCICIO"),H21*Configurações!$C$9,IF(B21="EXERC. LC",H21*Configurações!$C$9,IF(B21="OPCAO",H21*Configurações!$C$23))),2) -> 0 | AD21: =ROUNDDOWN(IF(OR(B21="ACAO",B21="DIR",B21="ETF",B21="EXERCICIO"),H21*Configurações!$D$9,IF(B21="EXERC. LC",H21*Configurações!$D$9,IF(B21="OPCAO",H21*Configurações!$D$23))),2) -> 0 | AE21: =Q21 -> 0 | AF21: =AE21*$X$7 -> 0 | AG21: =SUM(AB21:AF21) -> 0 | AI21: =ROUNDDOWN(IF(OR(B21="ACAO",B21="DIR",B21="ETF",B21="EXERCICIO"),M21*Configurações!$B$9,IF(B21="EXERC. LC",M21*Configurações!$B$37,IF(B21="OPCAO",M21*Configurações!$B$23))),2) -> 0 | AJ21: =ROUNDDOWN(IF(OR(B21="ACAO",B21="DIR",B21="ETF",B21="EXERCICIO"),M21*Configurações!$C$9,IF(B21="EXERC. LC",M21*Configurações!$C$37,IF(B21="OPCAO",M21*Configurações!$C$23))),2) -> 0 | AK21: =ROUNDDOWN(IF(OR(B21="ACAO",B21="DIR",B21="ETF",B21="EXERCICIO"),M21*Configurações!$D$9,IF(B21="EXERC. LC",M21*Configurações!$D$37,IF(B21="OPCAO",M21*Configurações!$D$23))),2) -> 0 | AL21: =R21 -> 0 | AM21: =AL21*$X$7 -> 0 | AN21: =SUM(AI21:AM21) -> 0
B22: ACAO | G22: NÃO | H22: =E22*F22 -> 0 | K22: NÃO | L22: =SUM(H22,M22) -> 0 | M22: =E22*J22 -> 0 | N22: =ROUNDDOWN(IF(OR(B22="ACAO",B22="DIR",B22="ETF",B22="EXERCICIO"),L22*Configurações!$B$9,IF(B22="EXERC. LC",H22*Configurações!$B$9+M22*Configurações!$B$37,IF(B22="OPCAO",L22*Configurações!$B$23))),2) -> 0 | O22: =ROUNDDOWN(IF(OR(B22="ACAO",B22="DIR",B22="ETF",B22="EXERCICIO"),L22*Configurações!$C$9,IF(B22="EXERC. LC",H22*Configurações!$C$9+M22*Configurações!$C$37,IF(B22="OPCAO",L22*Configurações!$C$23))),2) -> 0 | P22: =ROUNDDOWN(IF(OR(B22="ACAO",B22="DIR",B22="ETF",B22="EXERCICIO"),L22*Configurações!$D$9,IF(B22="EXERC. LC",H22*Configurações!$D$9+M22*Configurações!$D$37,IF(B22="OPCAO",L22*Configurações!$D$23))),2) -> 0 | T22: =IF(AND(G22="SIM",K22="NÃO"),-H22+M22-P22-Q22-R22-X22-S22-O22-N22+AG22,IF(AND(K22="SIM",G22="NÃO"),-H22+M22-P22-Q22-R22-X22-S22-O22-N22+AN22,IF(AND(K22="SIM",G22="SIM"),-H22+M22-P22-Q22-R22-X22-S22-O22-N22+AN22+AG22,IF(AND(K22="NÃO",G22="NÃO"),-H22+M22-P22-Q22-R22-X22-S22-O22-N22,0)))) -> 0 | V22: =IF(D22="","-",T22/H22) -> - | W22: =DAYS360(C22,I22) -> 0 | X22: =(Q22+R22)*$X$7 -> 0 | AB22: =ROUNDDOWN(IF(OR(B22="ACAO",B22="DIR",B22="ETF",B22="EXERCICIO"),H22*Configurações!$B$9,IF(B22="EXERC. LC",H22*Configurações!$B$9,IF(B22="OPCAO",H22*Configurações!$B$23))),2) -> 0 | AC22: =ROUNDDOWN(IF(OR(B22="ACAO",B22="DIR",B22="ETF",B22="EXERCICIO"),H22*Configurações!$C$9,IF(B22="EXERC. LC",H22*Configurações!$C$9,IF(B22="OPCAO",H22*Configurações!$C$23))),2) -> 0 | AD22: =ROUNDDOWN(IF(OR(B22="ACAO",B22="DIR",B22="ETF",B22="EXERCICIO"),H22*Configurações!$D$9,IF(B22="EXERC. LC",H22*Configurações!$D$9,IF(B22="OPCAO",H22*Configurações!$D$23))),2) -> 0 | AE22: =Q22 -> 0 | AF22: =AE22*$X$7 -> 0 | AG22: =SUM(AB22:AF22) -> 0 | AI22: =ROUNDDOWN(IF(OR(B22="ACAO",B22="DIR",B22="ETF",B22="EXERCICIO"),M22*Configurações!$B$9,IF(B22="EXERC. LC",M22*Configurações!$B$37,IF(B22="OPCAO",M22*Configurações!$B$23))),2) -> 0 | AJ22: =ROUNDDOWN(IF(OR(B22="ACAO",B22="DIR",B22="ETF",B22="EXERCICIO"),M22*Configurações!$C$9,IF(B22="EXERC. LC",M22*Configurações!$C$37,IF(B22="OPCAO",M22*Configurações!$C$23))),2) -> 0 | AK22: =ROUNDDOWN(IF(OR(B22="ACAO",B22="DIR",B22="ETF",B22="EXERCICIO"),M22*Configurações!$D$9,IF(B22="EXERC. LC",M22*Configurações!$D$37,IF(B22="OPCAO",M22*Configurações!$D$23))),2) -> 0 | AL22: =R22 -> 0 | AM22: =AL22*$X$7 -> 0 | AN22: =SUM(AI22:AM22) -> 0
B23: ACAO | G23: NÃO | H23: =E23*F23 -> 0 | K23: NÃO | L23: =SUM(H23,M23) -> 0 | M23: =E23*J23 -> 0 | N23: =ROUNDDOWN(IF(OR(B23="ACAO",B23="DIR",B23="ETF",B23="EXERCICIO"),L23*Configurações!$B$9,IF(B23="EXERC. LC",H23*Configurações!$B$9+M23*Configurações!$B$37,IF(B23="OPCAO",L23*Configurações!$B$23))),2) -> 0 | O23: =ROUNDDOWN(IF(OR(B23="ACAO",B23="DIR",B23="ETF",B23="EXERCICIO"),L23*Configurações!$C$9,IF(B23="EXERC. LC",H23*Configurações!$C$9+M23*Configurações!$C$37,IF(B23="OPCAO",L23*Configurações!$C$23))),2) -> 0 | P23: =ROUNDDOWN(IF(OR(B23="ACAO",B23="DIR",B23="ETF",B23="EXERCICIO"),L23*Configurações!$D$9,IF(B23="EXERC. LC",H23*Configurações!$D$9+M23*Configurações!$D$37,IF(B23="OPCAO",L23*Configurações!$D$23))),2) -> 0 | T23: =IF(AND(G23="SIM",K23="NÃO"),-H23+M23-P23-Q23-R23-X23-S23-O23-N23+AG23,IF(AND(K23="SIM",G23="NÃO"),-H23+M23-P23-Q23-R23-X23-S23-O23-N23+AN23,IF(AND(K23="SIM",G23="SIM"),-H23+M23-P23-Q23-R23-X23-S23-O23-N23+AN23+AG23,IF(AND(K23="NÃO",G23="NÃO"),-H23+M23-P23-Q23-R23-X23-S23-O23-N23,0)))) -> 0 | V23: =IF(D23="","-",T23/H23) -> - | W23: =DAYS360(C23,I23) -> 0 | X23: =(Q23+R23)*$X$7 -> 0 | AB23: =ROUNDDOWN(IF(OR(B23="ACAO",B23="DIR",B23="ETF",B23="EXERCICIO"),H23*Configurações!$B$9,IF(B23="EXERC. LC",H23*Configurações!$B$9,IF(B23="OPCAO",H23*Configurações!$B$23))),2) -> 0 | AC23: =ROUNDDOWN(IF(OR(B23="ACAO",B23="DIR",B23="ETF",B23="EXERCICIO"),H23*Configurações!$C$9,IF(B23="EXERC. LC",H23*Configurações!$C$9,IF(B23="OPCAO",H23*Configurações!$C$23))),2) -> 0 | AD23: =ROUNDDOWN(IF(OR(B23="ACAO",B23="DIR",B23="ETF",B23="EXERCICIO"),H23*Configurações!$D$9,IF(B23="EXERC. LC",H23*Configurações!$D$9,IF(B23="OPCAO",H23*Configurações!$D$23))),2) -> 0 | AE23: =Q23 -> 0 | AF23: =AE23*$X$7 -> 0 | AG23: =SUM(AB23:AF23) -> 0 | AI23: =ROUNDDOWN(IF(OR(B23="ACAO",B23="DIR",B23="ETF",B23="EXERCICIO"),M23*Configurações!$B$9,IF(B23="EXERC. LC",M23*Configurações!$B$37,IF(B23="OPCAO",M23*Configurações!$B$23))),2) -> 0 | AJ23: =ROUNDDOWN(IF(OR(B23="ACAO",B23="DIR",B23="ETF",B23="EXERCICIO"),M23*Configurações!$C$9,IF(B23="EXERC. LC",M23*Configurações!$C$37,IF(B23="OPCAO",M23*Configurações!$C$23))),2) -> 0 | AK23: =ROUNDDOWN(IF(OR(B23="ACAO",B23="DIR",B23="ETF",B23="EXERCICIO"),M23*Configurações!$D$9,IF(B23="EXERC. LC",M23*Configurações!$D$37,IF(B23="OPCAO",M23*Configurações!$D$23))),2) -> 0 | AL23: =R23 -> 0 | AM23: =AL23*$X$7 -> 0 | AN23: =SUM(AI23:AM23) -> 0
... B48: ACAO | G48: NÃO | H48: =E48*F48 -> 0 | K48: NÃO | L48: =SUM(H48,M48) -> 0 | M48: =E48*J48 -> 0 | N48: =ROUNDDOWN(IF(OR(B48="ACAO",B48="DIR",B48="ETF",B48="EXERCICIO"),L48*Configurações!$B$9,IF(B48="EXERC. LC",H48*Configurações!$B$9+M48*Configurações!$B$37,IF(B48="OPCAO",L48*Configurações!$B$23))),2) -> 0 | O48: =ROUNDDOWN(IF(OR(B48="ACAO",B48="DIR",B48="ETF",B48="EXERCICIO"),L48*Configurações!$C$9,IF(B48="EXERC. LC",H48*Configurações!$C$9+M48*Configurações!$C$37,IF(B48="OPCAO",L48*Configurações!$C$23))),2) -> 0 | P48: =ROUNDDOWN(IF(OR(B48="ACAO",B48="DIR",B48="ETF",B48="EXERCICIO"),L48*Configurações!$D$9,IF(B48="EXERC. LC",H48*Configurações!$D$9+M48*Configurações!$D$37,IF(B48="OPCAO",L48*Configurações!$D$23))),2) -> 0 | T48: =IF(AND(G48="SIM",K48="NÃO"),-H48+M48-P48-Q48-R48-X48-S48-O48-N48+AG48,IF(AND(K48="SIM",G48="NÃO"),-H48+M48-P48-Q48-R48-X48-S48-O48-N48+AN48,IF(AND(K48="SIM",G48="SIM"),-H48+M48-P48-Q48-R48-X48-S48-O48-N48+AN48+AG48,IF(AND(K48="NÃO",G48="NÃO"),-H48+M48-P48-Q48-R48-X48-S48-O48-N48,0)))) -> 0 | V48: =IF(D48="","-",T48/H48) -> - | W48: =DAYS360(C48,I48) -> 0 | X48: =(Q48+R48)*$X$7 -> 0 | AB48: =ROUNDDOWN(IF(OR(B48="ACAO",B48="DIR",B48="ETF",B48="EXERCICIO"),H48*Configurações!$B$9,IF(B48="EXERC. LC",H48*Configurações!$B$9,IF(B48="OPCAO",H48*Configurações!$B$23))),2) -> 0 | AC48: =ROUNDDOWN(IF(OR(B48="ACAO",B48="DIR",B48="ETF",B48="EXERCICIO"),H48*Configurações!$C$9,IF(B48="EXERC. LC",H48*Configurações!$C$9,IF(B48="OPCAO",H48*Configurações!$C$23))),2) -> 0 | AD48: =ROUNDDOWN(IF(OR(B48="ACAO",B48="DIR",B48="ETF",B48="EXERCICIO"),H48*Configurações!$D$9,IF(B48="EXERC. LC",H48*Configurações!$D$9,IF(B48="OPCAO",H48*Configurações!$D$23))),2) -> 0 | AE48: =Q48 -> 0 | AF48: =AE48*$X$7 -> 0 | AG48: =SUM(AB48:AF48) -> 0 | AI48: =ROUNDDOWN(IF(OR(B48="ACAO",B48="DIR",B48="ETF",B48="EXERCICIO"),M48*Configurações!$B$9,IF(B48="EXERC. LC",M48*Configurações!$B$37,IF(B48="OPCAO",M48*Configurações!$B$23))),2) -> 0 | AJ48: =ROUNDDOWN(IF(OR(B48="ACAO",B48="DIR",B48="ETF",B48="EXERCICIO"),M48*Configurações!$C$9,IF(B48="EXERC. LC",M48*Configurações!$C$37,IF(B48="OPCAO",M48*Configurações!$C$23))),2) -> 0 | AK48: =ROUNDDOWN(IF(OR(B48="ACAO",B48="DIR",B48="ETF",B48="EXERCICIO"),M48*Configurações!$D$9,IF(B48="EXERC. LC",M48*Configurações!$D$37,IF(B48="OPCAO",M48*Configurações!$D$23))),2) -> 0 | AL48: =R48 -> 0 | AM48: =AL48*$X$7 -> 0 | AN48: =SUM(AI48:AM48) -> 0
M49: =SUM(M8:M48) -> 0 | U49: =IF(SUM(U8:U48)>1,SUM(U8:U48),0) -> 0
E52: OPERAÇÕES NORMAIS
E54: Ações | I54: ETFs | M54: Direitos de Subscrição | Q54: Opções
C57: Resultado | E57: =SUMIF(B8:B48,"ACAO",T8:T48) -> 0 | I57: =SUMIF(B8:B48,"ETF",T8:T48) -> 0 | M57: =SUMIF(B8:B48,"DIR",T8:T48) -> 0 | Q57: =SUMIF(B8:B48,"OPCAO",T8:T48)+SUMIF(B8:B48,"EXERCICIO",T8:T48)+SUMIF(B8:B48,"EXERC. LC",T8:T48) -> 0
C60: Volume Vendas | E60: =SUMIF(B8:B48,"ACAO",M8:M48) -> 0
C63: Emolumentos/Taxas | E63: =SUMIF(B8:B48,"ACAO",N8:N48)+SUMIF(B8:B48,"ACAO",O8:O48)+SUMIF(B8:B48,"ACAO",P8:P48) -> 0 | I63: =SUMIF(B8:B48,"ETF",N8:N48)+SUMIF(B8:B48,"ETF",O8:O48)+SUMIF(B8:B48,"ETF",P8:P48) -> 0 | M63: =SUMIF(B8:B48,"DIR",N8:N48)+SUMIF(B8:B48,"DIR",O8:O48)+SUMIF(B8:B48,"DIR",P8:P48) -> 0 | Q63: =SUMIF(B8:B48,"OPCAO",N8:N48)+SUMIF(B8:B48,"OPCAO",O8:O48)+SUMIF(B8:B48,"OPCAO",P8:P48)+SUMIF(B8:B48,"EXERCICIO",N8:N48)+SUMIF(B8:B48,"EXERCICIO",O8:O48)+SUMIF(B8:B48,"EXERCICIO",P8:P48)+SUMIF(B8:B48,"EXERC. LC",N8:N48)+SUMIF(B8:B48,"EXERC. LC",O8:O48)+SUMIF(B8:B48,"EXERC. LC",P8:P48) -> 0
C66: Corretagens | E66: =SUMIF(B8:B48,"ACAO",Q8:Q48)+SUMIF(B8:B48,"ACAO",R8:R48) -> 0 | I66: =SUMIF(B8:B48,"ETF",Q8:Q48)+SUMIF(B8:B48,"ETF",R8:R48) -> 0 | M66: =SUMIF(B8:B48,"DIR",Q8:Q48)+SUMIF(B8:B48,"DIR",R8:R48) -> 0 | Q66: =SUMIF(B8:B48,"OPCAO",Q8:Q48)+SUMIF(B8:B48,"OPCAO",R8:R48)+SUMIF(B8:B48,"EXERCICIO",Q8:Q48)+SUMIF(B8:B48,"EXERCICIO",R8:R48)+SUMIF(B8:B48,"EXERC. LC",Q8:Q48)+SUMIF(B8:B48,"EXERC. LC",R8:R48) -> 0
E70: Resultado Ações | H70: + | I70: Resultado ETFs, DIR, Opções | L70: = | M70: Resultado Geral
E73: =E57 -> 0 | I73: =I57+M57+Q57 -> 0 | M73: =I73+E73 -> 0
B83: ACAO
B84: OPCAO
B85: ETF
B86: DIR
B87: EXERCICIO
B88: EXERC. LC

Sheet Operações Day Trade
B2: Período de Apuração | G2: Operação Day Trade: Operação com Compra e Venda no mesmo dia
B3: Mês: | C3: ='Operações Normais'!C3 -> 6 | D3: Ano: | E3: ='Operações Normais'!E3 -> 2020
B5: Operações Day Trade Ações e Opções | V5: ISS
B6: Tipo | C6: Data Compra | D6: Código Ativo | E6: Quantidade | F6: Preço Compra | G6: Movimento Compra | H6: Data Venda | I6: Preço Venda | J6: Movimento Total | K6: Movimento Venda | L6: Taxa Negociação | M6: Taxa Liquidação | N6: Taxa Registro | O6: Corretagem Compra | P6: Corretagem Venda | Q6: Outras despesas | R6: Resultado | S6: IRRF Day-Trade | T6: % | U6: Dias | V6: ='Operações Normais'!X7 -> 0.1068
B8: ACAO | G8: =E8*F8 -> 0 | H8: =C8 -> 0 | J8: =SUM(G8,K8) -> 0 | K8: =E8*I8 -> 0 | L8: =ROUNDDOWN(IF(OR(B8="ACAO",B8="DIR",B8="ETF"),J8*Configurações!$B$16,IF(B8="OPCAO",J8*Configurações!$B$30)),2) -> 0 | M8: =ROUNDDOWN(IF(OR(B8="ACAO",B8="DIR",B8="ETF"),J8*Configurações!$C$16,IF(B8="OPCAO",J8*Configurações!$C$30)),2) -> 0 | N8: =ROUNDDOWN(IF(OR(B8="ACAO",B8="DIR",B8="ETF"),J8*Configurações!$D$16,IF(B8="OPCAO",J8*Configurações!$D$30)),2) -> 0 | O8: 0 | P8: 0 | R8: =-G8+K8-N8-O8-P8-V8-Q8-M8-L8 -> 0 | T8: =IF(D8="","-",R8/G8) -> - | U8: =DAYS360(C8,H8) -> 0 | V8: =(O8+P8)*$V$6 -> 0
B9: ACAO | G9: =E9*F9 -> 0 | H9: =C9 -> 0 | J9: =SUM(G9,K9) -> 0 | K9: =E9*I9 -> 0 | L9: =ROUNDDOWN(IF(OR(B9="ACAO",B9="DIR",B9="ETF"),J9*Configurações!$B$16,IF(B9="OPCAO",J9*Configurações!$B$30)),2) -> 0 | M9: =ROUNDDOWN(IF(OR(B9="ACAO",B9="DIR",B9="ETF"),J9*Configurações!$C$16,IF(B9="OPCAO",J9*Configurações!$C$30)),2) -> 0 | N9: =ROUNDDOWN(IF(OR(B9="ACAO",B9="DIR",B9="ETF"),J9*Configurações!$D$16,IF(B9="OPCAO",J9*Configurações!$D$30)),2) -> 0 | O9: 0 | P9: 0 | R9: =-G9+K9-N9-O9-P9-V9-Q9-M9-L9 -> 0 | T9: =IF(D9="","-",R9/G9) -> - | U9: =DAYS360(C9,H9) -> 0 | V9: =(O9+P9)*$V$6 -> 0
B10: ACAO | G10: =E10*F10 -> 0 | H10: =C10 -> 0 | J10: =SUM(G10,K10) -> 0 | K10: =E10*I10 -> 0 | L10: =ROUNDDOWN(IF(OR(B10="ACAO",B10="DIR",B10="ETF"),J10*Configurações!$B$16,IF(B10="OPCAO",J10*Configurações!$B$30)),2) -> 0 | M10: =ROUNDDOWN(IF(OR(B10="ACAO",B10="DIR",B10="ETF"),J10*Configurações!$C$16,IF(B10="OPCAO",J10*Configurações!$C$30)),2) -> 0 | N10: =ROUNDDOWN(IF(OR(B10="ACAO",B10="DIR",B10="ETF"),J10*Configurações!$D$16,IF(B10="OPCAO",J10*Configurações!$D$30)),2) -> 0 | O10: 0 | P10: 0 | R10: =-G10+K10-N10-O10-P10-V10-Q10-M10-L10 -> 0 | T10: =IF(D10="","-",R10/G10) -> - | U10: =DAYS360(C10,H10) -> 0 | V10: =(O10+P10)*$V$6 -> 0
B11: ACAO | G11: =E11*F11 -> 0 | H11: =C11 -> 0 | J11: =SUM(G11,K11) -> 0 | K11: =E11*I11 -> 0 | L11: =ROUNDDOWN(IF(OR(B11="ACAO",B11="DIR",B11="ETF"),J11*Configurações!$B$16,IF(B11="OPCAO",J11*Configurações!$B$30)),2) -> 0 | M11: =ROUNDDOWN(IF(OR(B11="ACAO",B11="DIR",B11="ETF"),J11*Configurações!$C$16,IF(B11="OPCAO",J11*Configurações!$C$30)),2) -> 0 | N11: =ROUNDDOWN(IF(OR(B11="ACAO",B11="DIR",B11="ETF"),J11*Configurações!$D$16,IF(B11="OPCAO",J11*Configurações!$D$30)),2) -> 0 | R11: =-G11+K11-N11-O11-P11-V11-Q11-M11-L11 -> 0 | T11: =IF(D11="","-",R11/G11) -> - | U11: =DAYS360(C11,H11) -> 0 | V11: =(O11+P11)*$V$6 -> 0
B12: ACAO | G12: =E12*F12 -> 0 | H12: =C12 -> 0 | J12: =SUM(G12,K12) -> 0 | K12: =E12*I12 -> 0 | L12: =ROUNDDOWN(IF(OR(B12="ACAO",B12="DIR",B12="ETF"),J12*Configurações!$B$16,IF(B12="OPCAO",J12*Configurações!$B$30)),2) -> 0 | M12: =ROUNDDOWN(IF(OR(B12="ACAO",B12="DIR",B12="ETF"),J12*Configurações!$C$16,IF(B12="OPCAO",J12*Configurações!$C$30)),2) -> 0 | N12: =ROUNDDOWN(IF(OR(B12="ACAO",B12="DIR",B12="ETF"),J12*Configurações!$D$16,IF(B12="OPCAO",J12*Configurações!$D$30)),2) -> 0 | R12: =-G12+K12-N12-O12-P12-V12-Q12-M12-L12 -> 0 | T12: =IF(D12="","-",R12/G12) -> - | U12: =DAYS360(C12,H12) -> 0 | V12: =(O12+P12)*$V$6 -> 0
B13: ACAO | G13: =E13*F13 -> 0 | H13: =C13 -> 0 | J13: =SUM(G13,K13) -> 0 | K13: =E13*I13 -> 0 | L13: =ROUNDDOWN(IF(OR(B13="ACAO",B13="DIR",B13="ETF"),J13*Configurações!$B$16,IF(B13="OPCAO",J13*Configurações!$B$30)),2) -> 0 | M13: =ROUNDDOWN(IF(OR(B13="ACAO",B13="DIR",B13="ETF"),J13*Configurações!$C$16,IF(B13="OPCAO",J13*Configurações!$C$30)),2) -> 0 | N13: =ROUNDDOWN(IF(OR(B13="ACAO",B13="DIR",B13="ETF"),J13*Configurações!$D$16,IF(B13="OPCAO",J13*Configurações!$D$30)),2) -> 0 | R13: =-G13+K13-N13-O13-P13-V13-Q13-M13-L13 -> 0 | T13: =IF(D13="","-",R13/G13) -> - | U13: =DAYS360(C13,H13) -> 0 | V13: =(O13+P13)*$V$6 -> 0
B14: ACAO | G14: =E14*F14 -> 0 | H14: =C14 -> 0 | J14: =SUM(G14,K14) -> 0 | K14: =E14*I14 -> 0 | L14: =ROUNDDOWN(IF(OR(B14="ACAO",B14="DIR",B14="ETF"),J14*Configurações!$B$16,IF(B14="OPCAO",J14*Configurações!$B$30)),2) -> 0 | M14: =ROUNDDOWN(IF(OR(B14="ACAO",B14="DIR",B14="ETF"),J14*Configurações!$C$16,IF(B14="OPCAO",J14*Configurações!$C$30)),2) -> 0 | N14: =ROUNDDOWN(IF(OR(B14="ACAO",B14="DIR",B14="ETF"),J14*Configurações!$D$16,IF(B14="OPCAO",J14*Configurações!$D$30)),2) -> 0 | R14: =-G14+K14-N14-O14-P14-V14-Q14-M14-L14 -> 0 | T14: =IF(D14="","-",R14/G14) -> - | U14: =DAYS360(C14,H14) -> 0 | V14: =(O14+P14)*$V$6 -> 0
B15: ACAO | G15: =E15*F15 -> 0 | H15: =C15 -> 0 | J15: =SUM(G15,K15) -> 0 | K15: =E15*I15 -> 0 | L15: =ROUNDDOWN(IF(OR(B15="ACAO",B15="DIR",B15="ETF"),J15*Configurações!$B$16,IF(B15="OPCAO",J15*Configurações!$B$30)),2) -> 0 | M15: =ROUNDDOWN(IF(OR(B15="ACAO",B15="DIR",B15="ETF"),J15*Configurações!$C$16,IF(B15="OPCAO",J15*Configurações!$C$30)),2) -> 0 | N15: =ROUNDDOWN(IF(OR(B15="ACAO",B15="DIR",B15="ETF"),J15*Configurações!$D$16,IF(B15="OPCAO",J15*Configurações!$D$30)),2) -> 0 | R15: =-G15+K15-N15-O15-P15-V15-Q15-M15-L15 -> 0 | T15: =IF(D15="","-",R15/G15) -> - | U15: =DAYS360(C15,H15) -> 0 | V15: =(O15+P15)*$V$6 -> 0
B16: ACAO | G16: =E16*F16 -> 0 | H16: =C16 -> 0 | J16: =SUM(G16,K16) -> 0 | K16: =E16*I16 -> 0 | L16: =ROUNDDOWN(IF(OR(B16="ACAO",B16="DIR",B16="ETF"),J16*Configurações!$B$16,IF(B16="OPCAO",J16*Configurações!$B$30)),2) -> 0 | M16: =ROUNDDOWN(IF(OR(B16="ACAO",B16="DIR",B16="ETF"),J16*Configurações!$C$16,IF(B16="OPCAO",J16*Configurações!$C$30)),2) -> 0 | N16: =ROUNDDOWN(IF(OR(B16="ACAO",B16="DIR",B16="ETF"),J16*Configurações!$D$16,IF(B16="OPCAO",J16*Configurações!$D$30)),2) -> 0 | R16: =-G16+K16-N16-O16-P16-V16-Q16-M16-L16 -> 0 | T16: =IF(D16="","-",R16/G16) -> - | U16: =DAYS360(C16,H16) -> 0 | V16: =(O16+P16)*$V$6 -> 0
B17: ACAO | G17: =E17*F17 -> 0 | H17: =C17 -> 0 | J17: =SUM(G17,K17) -> 0 | K17: =E17*I17 -> 0 | L17: =ROUNDDOWN(IF(OR(B17="ACAO",B17="DIR",B17="ETF"),J17*Configurações!$B$16,IF(B17="OPCAO",J17*Configurações!$B$30)),2) -> 0 | M17: =ROUNDDOWN(IF(OR(B17="ACAO",B17="DIR",B17="ETF"),J17*Configurações!$C$16,IF(B17="OPCAO",J17*Configurações!$C$30)),2) -> 0 | N17: =ROUNDDOWN(IF(OR(B17="ACAO",B17="DIR",B17="ETF"),J17*Configurações!$D$16,IF(B17="OPCAO",J17*Configurações!$D$30)),2) -> 0 | R17: =-G17+K17-N17-O17-P17-V17-Q17-M17-L17 -> 0 | T17: =IF(D17="","-",R17/G17) -> - | U17: =DAYS360(C17,H17) -> 0 | V17: =(O17+P17)*$V$6 -> 0
B18: ACAO | G18: =E18*F18 -> 0 | H18: =C18 -> 0 | J18: =SUM(G18,K18) -> 0 | K18: =E18*I18 -> 0 | L18: =ROUNDDOWN(IF(OR(B18="ACAO",B18="DIR",B18="ETF"),J18*Configurações!$B$16,IF(B18="OPCAO",J18*Configurações!$B$30)),2) -> 0 | M18: =ROUNDDOWN(IF(OR(B18="ACAO",B18="DIR",B18="ETF"),J18*Configurações!$C$16,IF(B18="OPCAO",J18*Configurações!$C$30)),2) -> 0 | N18: =ROUNDDOWN(IF(OR(B18="ACAO",B18="DIR",B18="ETF"),J18*Configurações!$D$16,IF(B18="OPCAO",J18*Configurações!$D$30)),2) -> 0 | R18: =-G18+K18-N18-O18-P18-V18-Q18-M18-L18 -> 0 | T18: =IF(D18="","-",R18/G18) -> - | U18: =DAYS360(C18,H18) -> 0 | V18: =(O18+P18)*$V$6 -> 0
B19: ACAO | G19: =E19*F19 -> 0 | H19: =C19 -> 0 | J19: =SUM(G19,K19) -> 0 | K19: =E19*I19 -> 0 | L19: =ROUNDDOWN(IF(OR(B19="ACAO",B19="DIR",B19="ETF"),J19*Configurações!$B$16,IF(B19="OPCAO",J19*Configurações!$B$30)),2) -> 0 | M19: =ROUNDDOWN(IF(OR(B19="ACAO",B19="DIR",B19="ETF"),J19*Configurações!$C$16,IF(B19="OPCAO",J19*Configurações!$C$30)),2) -> 0 | N19: =ROUNDDOWN(IF(OR(B19="ACAO",B19="DIR",B19="ETF"),J19*Configurações!$D$16,IF(B19="OPCAO",J19*Configurações!$D$30)),2) -> 0 | R19: =-G19+K19-N19-O19-P19-V19-Q19-M19-L19 -> 0 | T19: =IF(D19="","-",R19/G19) -> - | U19: =DAYS360(C19,H19) -> 0 | V19: =(O19+P19)*$V$6 -> 0
B20: ACAO | G20: =E20*F20 -> 0 | H20: =C20 -> 0 | J20: =SUM(G20,K20) -> 0 | K20: =E20*I20 -> 0 | L20: =ROUNDDOWN(IF(OR(B20="ACAO",B20="DIR",B20="ETF"),J20*Configurações!$B$16,IF(B20="OPCAO",J20*Configurações!$B$30)),2) -> 0 | M20: =ROUNDDOWN(IF(OR(B20="ACAO",B20="DIR",B20="ETF"),J20*Configurações!$C$16,IF(B20="OPCAO",J20*Configurações!$C$30)),2) -> 0 | N20: =ROUNDDOWN(IF(OR(B20="ACAO",B20="DIR",B20="ETF"),J20*Configurações!$D$16,IF(B20="OPCAO",J20*Configurações!$D$30)),2) -> 0 | R20: =-G20+K20-N20-O20-P20-V20-Q20-M20-L20 -> 0 | T20: =IF(D20="","-",R20/G20) -> - | U20: =DAYS360(C20,H20) -> 0 | V20: =(O20+P20)*$V$6 -> 0
B21: ACAO | G21: =E21*F21 -> 0 | H21: =C21 -> 0 | J21: =SUM(G21,K21) -> 0 | K21: =E21*I21 -> 0 | L21: =ROUNDDOWN(IF(OR(B21="ACAO",B21="DIR",B21="ETF"),J21*Configurações!$B$16,IF(B21="OPCAO",J21*Configurações!$B$30)),2) -> 0 | M21: =ROUNDDOWN(IF(OR(B21="ACAO",B21="DIR",B21="ETF"),J21*Configurações!$C$16,IF(B21="OPCAO",J21*Configurações!$C$30)),2) -> 0 | N21: =ROUNDDOWN(IF(OR(B21="ACAO",B21="DIR",B21="ETF"),J21*Configurações!$D$16,IF(B21="OPCAO",J21*Configurações!$D$30)),2) -> 0 | R21: =-G21+K21-N21-O21-P21-V21-Q21-M21-L21 -> 0 | T21: =IF(D21="","-",R21/G21) -> - | U21: =DAYS360(C21,H21) -> 0 | V21: =(O21+P21)*$V$6 -> 0
B22: ACAO | G22: =E22*F22 -> 0 | H22: =C22 -> 0 | J22: =SUM(G22,K22) -> 0 | K22: =E22*I22 -> 0 | L22: =ROUNDDOWN(IF(OR(B22="ACAO",B22="DIR",B22="ETF"),J22*Configurações!$B$16,IF(B22="OPCAO",J22*Configurações!$B$30)),2) -> 0 | M22: =ROUNDDOWN(IF(OR(B22="ACAO",B22="DIR",B22="ETF"),J22*Configurações!$C$16,IF(B22="OPCAO",J22*Configurações!$C$30)),2) -> 0 | N22: =ROUNDDOWN(IF(OR(B22="ACAO",B22="DIR",B22="ETF"),J22*Configurações!$D$16,IF(B22="OPCAO",J22*Configurações!$D$30)),2) -> 0 | R22: =-G22+K22-N22-O22-P22-V22-Q22-M22-L22 -> 0 | T22: =IF(D22="","-",R22/G22) -> - | U22: =DAYS360(C22,H22) -> 0 | V22: =(O22+P22)*$V$6 -> 0
... B48: ACAO | G48: =E48*F48 -> 0 | H48: =C48 -> 0 | J48: =SUM(G48,K48) -> 0 | K48: =E48*I48 -> 0 | L48: =ROUNDDOWN(IF(OR(B48="ACAO",B48="DIR",B48="ETF"),J48*Configurações!$B$16,IF(B48="OPCAO",J48*Configurações!$B$30)),2) -> 0 | M48: =ROUNDDOWN(IF(OR(B48="ACAO",B48="DIR",B48="ETF"),J48*Configurações!$C$16,IF(B48="OPCAO",J48*Configurações!$C$30)),2) -> 0 | N48: =ROUNDDOWN(IF(OR(B48="ACAO",B48="DIR",B48="ETF"),J48*Configurações!$D$16,IF(B48="OPCAO",J48*Configurações!$D$30)),2) -> 0 | R48: =-G48+K48-N48-O48-P48-V48-Q48-M48-L48 -> 0 | T48: =IF(D48="","-",R48/G48) -> - | U48: =DAYS360(C48,H48) -> 0 | V48: =(O48+P48)*$V$6 -> 0
K49: =SUM(K8:K48) -> 0 | S49: =SUM(S8:S48) -> 0
E52: OPERAÇÕES DAY TRADE
E54: Ações | I54: ETFs | M54: Direitos de Subscrição | Q54: Opções
C57: Resultado | E57: =SUMIF(B8:B48,"ACAO",R8:R48) -> 0 | I57: =SUMIF(B8:B48,"ETF",R8:R48) -> 0 | M57: =SUMIF(B8:B48,"DIR",R8:R48) -> 0 | Q57: =SUMIF(B8:B48,"OPCAO",R8:R48) -> 0
C60: Volume Vendas | E60: =SUMIF(B8:B48,"ACAO",K8:K48) -> 0
C63: Emolumentos/Taxas | E63: =SUMIF(B8:B48,"ACAO",L8:L48)+SUMIF(B8:B48,"ACAO",M8:M48)+SUMIF(B8:B48,"ACAO",N8:N48) -> 0 | I63: =SUMIF(B8:B48,"ETF",L8:L48)+SUMIF(B8:B48,"ETF",M8:M48)+SUMIF(B8:B48,"ETF",N8:N48) -> 0 | M63: =SUMIF(B8:B48,"DIR",L8:L48)+SUMIF(B8:B48,"DIR",M8:M48)+SUMIF(B8:B48,"DIR",N8:N48) -> 0 | Q63: =SUMIF(B8:B48,"OPCAO",L8:L48)+SUMIF(B8:B48,"OPCAO",M8:M48)+SUMIF(B8:B48,"OPCAO",N8:N48) -> 0
C66: Corretagens | E66: =SUMIF(B8:B48,"ACAO",O8:O48)+SUMIF(B8:B48,"ACAO",P8:P48) -> 0 | I66: =SUMIF(B8:B48,"ETF",O8:O48)+SUMIF(B8:B48,"ETF",P8:P48) -> 0 | M66: =SUMIF(B8:B48,"DIR",O8:O48)+SUMIF(B8:B48,"DIR",P8:P48) -> 0 | Q66: =SUMIF(B8:B48,"OPCAO",O8:O48)+SUMIF(B8:B48,"OPCAO",P8:P48) -> 0
E70: Resultado Ações | H70: + | I70: Resultado ETFs, DIR, Opções | L70: = | M70: Resultado Geral
E73: =E57 -> 0 | I73: =I57+M57+Q57 -> 0 | M73: =E73+I73+A73 -> 0
B85: ACAO
B86: OPCAO
B87: ETF
B88: DIR

Sheet Normais Índice e Dólar
B3: CONTROLE DE IR OPERAÇÕES NORMAIS COM CONTRATOS FUTUROS DE ÍNDICE E DÓLAR
B7: Período de Apuração
B8: Mês: | C8: ='Operações Normais'!C3 -> 6 | D8: Ano: | E8: ='Operações Normais'!E3 -> 2020
B10: Como Preencher?
B12: 1) Selecionar um Tipo Contrato, WDO para Míni Dólar, DOL para Dólar Cheio, WIN para Mini Índice ou IND para Índice Cheio
B13: 2) Na coluna "Negócio foi encerrado?" Selecione SIM caso esteja encerrado, caso contrário selecione NÃO. Esta coluna servirá para a planilha considerar
B14: apenas os negócios encerrados no mês na base de cálculo de IR.
B15: 3) Negócio não encerrado deve ser copiado para a tabela do mês seguinte.
B16: 4) Lance o preço de compra e preço de venda, em pontos (índice) ou em milhares de reais (dólar).
B17: 5) Verifique exemplo de preenchimento no PDF de instruções da planilha.
D19: Dados da Compra | F19: Dados da Venda | H19: Taxas Operacionais (Verificar Nota de Corretagem) | N19: IRRF | O19: Resultado Bruto | P19: Resultado Descontadas as Taxas Operacionais | Q19: Negócio foi encerrado?
B22: Tipo Contrato | C22: Quantidade | D22: Data Compra | E22: Preço Compra | F22: Data Venda | G22: Preço Venda | H22: Corretagens | I22: ISS | J22: Taxas BM&F | K22: Taxa de Permanência | L22: Taxa Registro BM&F | M22: Outras Despesas
I24: ='Operações Normais'!X7 -> 0.1068
B25: WDO | I25: =H25*$I$24 -> 0 | O25: =IF(B25="WDO",(G25-E25)*C25*10,IF(B25="WIN",(G25-E25)*C25*0.2,IF(B25="IND",(G25-E25)*C25,IF(B25="DOL",(G25-E25)*C25*50,0)))) -> 0 | P25: =O25-H25-I25-J25-M25-K25-L25 -> 0 | Q25: SIM
I26: =H26*$I$24 -> 0 | O26: =IF(B26="WDO",(G26-E26)*C26*10,IF(B26="WIN",(G26-E26)*C26*0.2,IF(B26="IND",(G26-E26)*C26,IF(B26="DOL",(G26-E26)*C26*50,0)))) -> 0 | P26: =O26-H26-I26-J26-M26-K26-L26 -> 0 | Q26: SIM
I27: =H27*$I$24 -> 0 | O27: =IF(B27="WDO",(G27-E27)*C27*10,IF(B27="WIN",(G27-E27)*C27*0.2,IF(B27="IND",(G27-E27)*C27,IF(B27="DOL",(G27-E27)*C27*50,0)))) -> 0 | P27: =O27-H27-I27-J27-M27-K27-L27 -> 0
I28: =H28*$I$24 -> 0 | O28: =IF(B28="WDO",(G28-E28)*C28*10,IF(B28="WIN",(G28-E28)*C28*0.2,IF(B28="IND",(G28-E28)*C28,IF(B28="DOL",(G28-E28)*C28*50,0)))) -> 0 | P28: =O28-H28-I28-J28-M28-K28-L28 -> 0
I29: =H29*$I$24 -> 0 | O29: =IF(B29="WDO",(G29-E29)*C29*10,IF(B29="WIN",(G29-E29)*C29*0.2,IF(B29="IND",(G29-E29)*C29,IF(B29="DOL",(G29-E29)*C29*50,0)))) -> 0 | P29: =O29-H29-I29-J29-M29-K29-L29 -> 0
I30: =H30*$I$24 -> 0 | O30: =IF(B30="WDO",(G30-E30)*C30*10,IF(B30="WIN",(G30-E30)*C30*0.2,IF(B30="IND",(G30-E30)*C30,IF(B30="DOL",(G30-E30)*C30*50,0)))) -> 0 | P30: =O30-H30-I30-J30-M30-K30-L30 -> 0
I31: =H31*$I$24 -> 0 | O31: =IF(B31="WDO",(G31-E31)*C31*10,IF(B31="WIN",(G31-E31)*C31*0.2,IF(B31="IND",(G31-E31)*C31,IF(B31="DOL",(G31-E31)*C31*50,0)))) -> 0 | P31: =O31-H31-I31-J31-M31-K31-L31 -> 0
I32: =H32*$I$24 -> 0 | O32: =IF(B32="WDO",(G32-E32)*C32*10,IF(B32="WIN",(G32-E32)*C32*0.2,IF(B32="IND",(G32-E32)*C32,IF(B32="DOL",(G32-E32)*C32*50,0)))) -> 0 | P32: =O32-H32-I32-J32-M32-K32-L32 -> 0
I33: =H33*$I$24 -> 0 | O33: =IF(B33="WDO",(G33-E33)*C33*10,IF(B33="WIN",(G33-E33)*C33*0.2,IF(B33="IND",(G33-E33)*C33,IF(B33="DOL",(G33-E33)*C33*50,0)))) -> 0 | P33: =O33-H33-I33-J33-M33-K33-L33 -> 0
I34: =H34*$I$24 -> 0 | O34: =IF(B34="WDO",(G34-E34)*C34*10,IF(B34="WIN",(G34-E34)*C34*0.2,IF(B34="IND",(G34-E34)*C34,IF(B34="DOL",(G34-E34)*C34*50,0)))) -> 0 | P34: =O34-H34-I34-J34-M34-K34-L34 -> 0
I35: =H35*$I$24 -> 0 | O35: =IF(B35="WDO",(G35-E35)*C35*10,IF(B35="WIN",(G35-E35)*C35*0.2,IF(B35="IND",(G35-E35)*C35,IF(B35="DOL",(G35-E35)*C35*50,0)))) -> 0 | P35: =O35-H35-I35-J35-M35-K35-L35 -> 0
I36: =H36*$I$24 -> 0 | O36: =IF(B36="WDO",(G36-E36)*C36*10,IF(B36="WIN",(G36-E36)*C36*0.2,IF(B36="IND",(G36-E36)*C36,IF(B36="DOL",(G36-E36)*C36*50,0)))) -> 0 | P36: =O36-H36-I36-J36-M36-K36-L36 -> 0
I37: =H37*$I$24 -> 0 | O37: =IF(B37="WDO",(G37-E37)*C37*10,IF(B37="WIN",(G37-E37)*C37*0.2,IF(B37="IND",(G37-E37)*C37,IF(B37="DOL",(G37-E37)*C37*50,0)))) -> 0 | P37: =O37-H37-I37-J37-M37-K37-L37 -> 0
I38: =H38*$I$24 -> 0 | O38: =IF(B38="WDO",(G38-E38)*C38*10,IF(B38="WIN",(G38-E38)*C38*0.2,IF(B38="IND",(G38-E38)*C38,IF(B38="DOL",(G38-E38)*C38*50,0)))) -> 0 | P38: =O38-H38-I38-J38-M38-K38-L38 -> 0
... I51: =H51*$I$24 -> 0 | O51: =IF(B51="WDO",(G51-E51)*C51*10,IF(B51="WIN",(G51-E51)*C51*0.2,IF(B51="IND",(G51-E51)*C51,IF(B51="DOL",(G51-E51)*C51*50,0)))) -> 0 | P51: =O51-H51-I51-J51-M51-K51-L51 -> 0
B53: RESUMO
B55: Lucro / Prejuízo Mês | E55: =SUMIF(Q25:Q51,"SIM",P25:P51) -> 0
B57: Total Taxas Pagas | E57: =SUMIF(Q25:Q51,"SIM",H25:M51) -> 0
B59: Total Imposto Retido | E59: =SUM(N25:N51) -> 0 | H59: (ESTE NÃO É O IR A PAGAR. VERIFIQUE A ABA RESUMO IMPOSTO)
