Workbook

Sheet CONTROLE CONCILIAÇÃO 
A1: Planilha de Controle de Responsabilidades e Conciliação Contábil | K1: Balancetes Mensais
A4: Cod Conta | B4: Desc Moeda 1 | C4: Classe Conta | D4: Cond Normal | E4: Natureza Contábil | F4: Backup Responsável | G4: Responsável | H4: OK | I4: Data Limite da Conciliação | J4: DESCRIÇÃO | K4: JAN/2017 | L4: Concilição | M4: FEV/2017 | N4: Concilição | O4: MAR/2017 | P4: Concilição | Q4: ABR/2017 | R4: Concilição | S4: MAI/2017 | T4: Concilição | U4: JUN/2017 | V4: Concilição | W4: JUL/2017 | X4: Concilição | Y4: AGO/2017 | Z4: Concilição | AA4: SET/2017 | AB4: Concilição | AC4: OUT/2017 | AD4: Concilição | AE4: NOV/2017 | AF4: Concilição | AG4: DEZ/2017 | AH4: Concilição
A5: 1 | B5: ATIVO | C5: Sintetica | D5: Devedora | J5: ATIVO
A6: 10 | B6: CIRCULANTE | C6: Sintetica | D6: Devedora | J6: CIRCULANTE
A7: 100 | B7: DISPONIVEL | C7: Sintetica | D7: Devedora | J7: DISPONIVEL
A8: 1000 | B8: CAIXA | C8: Sintetica | D8: Devedora | J8: CAIXA
A9: 100001 | B9: CAIXA | C9: Analitica | D9: Devedora | J9: CAIXA
A10: 100002 | B10: VALORES EM TRANSITO | C10: Analitica | D10: Devedora | J10: VALORES EM TRANSITO
A11: 1001 | B11: BANCOS CONTA CORRENTE | C11: Sintetica | D11: Devedora | J11: BANCOS CONTA CORRENTE
A12: 100101 | B12: BANCO ITAU S.A. | C12: Analitica | D12: Devedora | J12: BANCO ITAU S.A. | L12: OK | N12: OK
A13: 100102 | B13: BANCO BRADESCO S.A. | C13: Analitica | D13: Devedora | J13: BANCO BRADESCO S.A. | L13: OK | N13: OK
A14: 100103 | B14: BANCO SANTANDER S.A. | C14: Analitica | D14: Devedora | J14: BANCO SANTANDER S.A. | L14: OK | N14: OK
A15: 100105 | B15: CAIXA ECONOMICA FEDERAL | C15: Analitica | D15: Devedora | J15: CAIXA ECONOMICA FEDERAL | L15: OK | N15: OK
A16: 100106 | B16: BANCO DO BRASIL S.A. | C16: Analitica | D16: Devedora | J16: BANCO DO BRASIL S.A. | L16: OK | N16: OK
A17: 100107 | B17: BANRISUL | C17: Analitica | D17: Devedora | J17: BANRISUL | L17: OK | N17: OK
A18: 1002 | B18: APLICACOES FINANCEIRAS | C18: Sintetica | D18: Devedora | J18: APLICACOES FINANCEIRAS | N18: OK
A19: 100201 | B19: BANCO ITAU S.A. | C19: Analitica | D19: Devedora | J19: BANCO ITAU S.A. | L19: OK | N19: OK
A20: 100202 | B20: BANCO BRADESCO S.A. | C20: Analitica | D20: Devedora | J20: BANCO BRADESCO S.A. | L20: OK | N20: OK
A21: 100203 | B21: BANCO SANTANDER S.A. | C21: Analitica | D21: Devedora | J21: BANCO SANTANDER S.A. | L21: OK | N21: OK
A22: 1003 | B22: BANCOS CONTA VINCULADA | C22: Sintetica | D22: Devedora | J22: BANCOS CONTA VINCULADA
A23: 100301 | B23: BANCO ITAU | C23: Analitica | D23: Devedora | J23: BANCO ITAU | L23: OK | N23: OK
A24: 103 | B24: CONTAS A RECEBER-CLIENTES | C24: Sintetica | D24: Devedora | J24: CONTAS A RECEBER-CLIENTES
A25: 1030 | B25: CONTAS A RECEBER-CLIENTES | C25: Sintetica | D25: Devedora | J25: CONTAS A RECEBER-CLIENTES
A26: 103003 | B26: CHEQUES A RECEBER | C26: Analitica | D26: Devedora | J26: CHEQUES A RECEBER
A27: 103005 | B27: CONTAS RECEBER | C27: Analitica | D27: Devedora | J27: CONTAS RECEBER
A28: 103006 | B28: PROVISAO DEVEDORES DUVIDOSO | C28: Analitica | D28: Credora | J28: PROVISAO DEVEDORES DUVIDOSO
A29: 104 | B29: VALORES A RECEBER | C29: Sintetica | D29: Devedora | J29: VALORES A RECEBER
A30: 1040 | B30: VALORES A RECEBER | C30: Sintetica | D30: Devedora | J30: VALORES A RECEBER
A31: 104001 | B31: ADIANTAMENTO DE SALARIO | C31: Analitica | D31: Devedora | J31: ADIANTAMENTO DE SALARIO
A32: 104002 | B32: ADIANTAMENTO 13* SALARIO | C32: Analitica | D32: Devedora | J32: ADIANTAMENTO 13* SALARIO
A33: 104003 | B33: ADIANTAMENTO FERIAS | C33: Analitica | D33: Devedora | J33: ADIANTAMENTO FERIAS
A34: 104004 | B34: INDENIZACOES A RECEBER | C34: Analitica | D34: Devedora | J34: INDENIZACOES A RECEBER
A35: 104005 | B35: VALORES A RECEBER | C35: Analitica | D35: Devedora | J35: VALORES A RECEBER
... A91: 1310 | B91: BENS DO ATIVO IMOBILIZADO | C91: Sintetica | D91: Devedora | J91: BENS DO ATIVO IMOBILIZADO
A92: 131001 | B92: VEICULOS | C92: Analitica | D92: Devedora | J92: VEICULOS | L92: OK | N92: OK
A93: 131002 | B93: EQUIPAMENTOS DE INFORMATICA | C93: Analitica | D93: Devedora | J93: EQUIPAMENTOS DE INFORMATICA | L93: OK | N93: OK
A94: 131003 | B94: MOVEIS E UTENSILIOS | C94: Analitica | D94: Devedora | J94: MOVEIS E UTENSILIOS | L94: OK | N94: OK
A95: 131004 | B95: EQUIPAMENTOS E INSTALACOES OPERACIONAIS | C95: Analitica | D95: Devedora | J95: EQUIPAMENTOS E INSTALACOES OPERACIONAIS | L95: OK | N95: OK
A96: 131005 | B96: INSTALACOES | C96: Analitica | D96: Devedora | J96: INSTALACOES | L96: OK | N96: OK
A97: 131006 | B97: DIREITO DE USO DE SOFTWARE | C97: Analitica | D97: Devedora | J97: DIREITO DE USO DE SOFTWARE | L97: OK | N97: OK
...

Sheet STATUS CONCILIAÇÃO_012020
B2: CONCILIAÇÕES MENSAIS POR CONTA x RESPONSÁVEL 2020 | K2: % de Evolução | M2: =COUNTIF(L14:L33,"Concluída")/COUNTA(L14:L33) -> 0.5
F4: Analitico
F5: Concluída | G5: =COUNTIF($L$14:$L$175,F5)+G171 -> 44 | H5: =G5/$G$9 -> #REF!
F6: A iniciar | G6: =COUNTIF($L$14:$L$175,F6)+G177 -> 0 | H6: =G6/$G$9 -> #REF!
B7: Escopo: | D7: CONCILIAÇÃO CONTAS 2020 - EMPRESA XXXXXXXXX BASE JANEIRO | F7: Em andamento | G7: =COUNTIF($L$14:$L$175,F7)+G153 -> 0 | H7: =G7/$G$9 -> #REF!
F8: Atrasada | G8: =COUNTIF($L$14:$L$175,F8)+#REF! -> #REF! | H8: =G8/$G$9 -> #REF!
G9: =SUM(G5:G8) -> #REF!
B12: Atividades | F12: Quem | H12: Prazo Previsto | J12: Realizado | L12: Status | N12: RESULTADO DA AÇÃO | O12: PONTOS PROBLEMÁTICOS | P12: PROPOSIÇÕES FUTURAS
B13: NO. | C13: CONTA | D13: Prioridade | E13: DESCRIÇÃO | F13: Respons. | G13: Executor | H13: INÍCIO | I13: TÉRMINO | J13: INÍCIO | K13: TÉRMINO | L13: Status | M13: Farol
B14: 1 | C14: 100001 | D14: Alta | E14: =VLOOKUP(C14,'CONTROLE CONCILIAÇÃO '!A:C,2,FALSE) -> CAIXA | H14: 42767 | I14: 42793 | L14: =IF(H14="","",IF(K14<>"","Concluída",IF(TODAY()>I14,"Atrasada",IF(J14<>"","Em andamento",IF(AND(J14="",TODAY()>H14),"Atrasada","A iniciar"))))) -> Atrasada | M14: =IF(L14<>"","n","") -> n
B15: 2 | C15: 100002 | D15: Alta | E15: =VLOOKUP(C15,'CONTROLE CONCILIAÇÃO '!A:C,2,FALSE) -> VALORES EM TRANSITO | H15: 42767 | I15: 42793 | L15: =IF(H15="","",IF(K15<>"","Concluída",IF(TODAY()>I15,"Atrasada",IF(J15<>"","Em andamento",IF(AND(J15="",TODAY()>H15),"Atrasada","A iniciar"))))) -> Atrasada | M15: =IF(L15<>"","n","") -> n
B16: 3 | C16: 100101 | D16: Alta | E16: =VLOOKUP(C16,'CONTROLE CONCILIAÇÃO '!A:C,2,FALSE) -> BANCO ITAU S.A. | H16: 42767 | I16: 42793 | J16: 42767 | K16: 42767 | L16: =IF(H16="","",IF(K16<>"","Concluída",IF(TODAY()>I16,"Atrasada",IF(J16<>"","Em andamento",IF(AND(J16="",TODAY()>H16),"Atrasada","A iniciar"))))) -> Concluída | M16: =IF(L16<>"","n","") -> n
B17: 4 | C17: 100102 | D17: Alta | E17: =VLOOKUP(C17,'CONTROLE CONCILIAÇÃO '!A:C,2,FALSE) -> BANCO BRADESCO S.A. | H17: 42767 | I17: 42793 | J17: 42767 | K17: 42767 | L17: =IF(H17="","",IF(K17<>"","Concluída",IF(TODAY()>I17,"Atrasada",IF(J17<>"","Em andamento",IF(AND(J17="",TODAY()>H17),"Atrasada","A iniciar"))))) -> Concluída | M17: =IF(L17<>"","n","") -> n
B18: 5 | C18: 100103 | D18: Alta | E18: =VLOOKUP(C18,'CONTROLE CONCILIAÇÃO '!A:C,2,FALSE) -> BANCO SANTANDER S.A. | H18: 42767 | I18: 42793 | J18: 42767 | K18: 42767 | L18: =IF(H18="","",IF(K18<>"","Concluída",IF(TODAY()>I18,"Atrasada",IF(J18<>"","Em andamento",IF(AND(J18="",TODAY()>H18),"Atrasada","A iniciar"))))) -> Concluída | M18: =IF(L18<>"","n","") -> n
B19: 6 | C19: 100105 | D19: Alta | E19: =VLOOKUP(C19,'CONTROLE CONCILIAÇÃO '!A:C,2,FALSE) -> CAIXA ECONOMICA FEDERAL | H19: 42767 | I19: 42793 | J19: 42767 | K19: 42767 | L19: =IF(H19="","",IF(K19<>"","Concluída",IF(TODAY()>I19,"Atrasada",IF(J19<>"","Em andamento",IF(AND(J19="",TODAY()>H19),"Atrasada","A iniciar"))))) -> Concluída | M19: =IF(L19<>"","n","") -> n
B20: 7 | C20: 100106 | D20: Alta | E20: =VLOOKUP(C20,'CONTROLE CONCILIAÇÃO '!A:C,2,FALSE) -> BANCO DO BRASIL S.A. | H20: 42767 | I20: 42793 | J20: 42767 | K20: 42767 | L20: =IF(H20="","",IF(K20<>"","Concluída",IF(TODAY()>I20,"Atrasada",IF(J20<>"","Em andamento",IF(AND(J20="",TODAY()>H20),"Atrasada","A iniciar"))))) -> Concluída | M20: =IF(L20<>"","n","") -> n
B21: 8 | C21: 100107 | D21: Alta | E21: =VLOOKUP(C21,'CONTROLE CONCILIAÇÃO '!A:C,2,FALSE) -> BANRISUL | H21: 42767 | I21: 42793 | J21: 42767 | K21: 42767 | L21: =IF(H21="","",IF(K21<>"","Concluída",IF(TODAY()>I21,"Atrasada",IF(J21<>"","Em andamento",IF(AND(J21="",TODAY()>H21),"Atrasada","A iniciar"))))) -> Concluída | M21: =IF(L21<>"","n","") -> n
B22: 9 | C22: 100201 | D22: Alta | E22: =VLOOKUP(C22,'CONTROLE CONCILIAÇÃO '!A:C,2,FALSE) -> BANCO ITAU S.A. | H22: 42767 | I22: 42793 | J22: 42767 | K22: 42767 | L22: =IF(H22="","",IF(K22<>"","Concluída",IF(TODAY()>I22,"Atrasada",IF(J22<>"","Em andamento",IF(AND(J22="",TODAY()>H22),"Atrasada","A iniciar"))))) -> Concluída | M22: =IF(L22<>"","n","") -> n
B23: 10 | C23: 100202 | D23: Alta | E23: =VLOOKUP(C23,'CONTROLE CONCILIAÇÃO '!A:C,2,FALSE) -> BANCO BRADESCO S.A. | H23: 42767 | I23: 42793 | J23: 42767 | K23: 42767 | L23: =IF(H23="","",IF(K23<>"","Concluída",IF(TODAY()>I23,"Atrasada",IF(J23<>"","Em andamento",IF(AND(J23="",TODAY()>H23),"Atrasada","A iniciar"))))) -> Concluída | M23: =IF(L23<>"","n","") -> n
B24: 11 | C24: 100203 | D24: Alta | E24: =VLOOKUP(C24,'CONTROLE CONCILIAÇÃO '!A:C,2,FALSE) -> BANCO SANTANDER S.A. | H24: 42767 | I24: 42793 | J24: 42767 | K24: 42767 | L24: =IF(H24="","",IF(K24<>"","Concluída",IF(TODAY()>I24,"Atrasada",IF(J24<>"","Em andamento",IF(AND(J24="",TODAY()>H24),"Atrasada","A iniciar"))))) -> Concluída | M24: =IF(L24<>"","n","") -> n
B25: 12 | C25: 100301 | D25: Alta | E25: =VLOOKUP(C25,'CONTROLE CONCILIAÇÃO '!A:C,2,FALSE) -> BANCO ITAU | H25: 42767 | I25: 42793 | J25: 42767 | K25: 42767 | L25: =IF(H25="","",IF(K25<>"","Concluída",IF(TODAY()>I25,"Atrasada",IF(J25<>"","Em andamento",IF(AND(J25="",TODAY()>H25),"Atrasada","A iniciar"))))) -> Concluída | M25: =IF(L25<>"","n","") -> n
B26: 13 | C26: 103003 | D26: Alta | E26: =VLOOKUP(C26,'CONTROLE CONCILIAÇÃO '!A:C,2,FALSE) -> CHEQUES A RECEBER | H26: 42767 | I26: 42793 | L26: =IF(H26="","",IF(K26<>"","Concluída",IF(TODAY()>I26,"Atrasada",IF(J26<>"","Em andamento",IF(AND(J26="",TODAY()>H26),"Atrasada","A iniciar"))))) -> Atrasada | M26: =IF(L26<>"","n","") -> n
B27: 14 | C27: 103005 | D27: Alta | E27: =VLOOKUP(C27,'CONTROLE CONCILIAÇÃO '!A:C,2,FALSE) -> CONTAS RECEBER | H27: 42767 | I27: 42793 | L27: =IF(H27="","",IF(K27<>"","Concluída",IF(TODAY()>I27,"Atrasada",IF(J27<>"","Em andamento",IF(AND(J27="",TODAY()>H27),"Atrasada","A iniciar"))))) -> Atrasada | M27: =IF(L27<>"","n","") -> n
B28: 15 | C28: 103006 | D28: Alta | E28: =VLOOKUP(C28,'CONTROLE CONCILIAÇÃO '!A:C,2,FALSE) -> PROVISAO DEVEDORES DUVIDOSO | H28: 42767 | I28: 42793 | L28: =IF(H28="","",IF(K28<>"","Concluída",IF(TODAY()>I28,"Atrasada",IF(J28<>"","Em andamento",IF(AND(J28="",TODAY()>H28),"Atrasada","A iniciar"))))) -> Atrasada | M28: =IF(L28<>"","n","") -> n
B29: 16 | C29: 104001 | D29: Alta | E29: =VLOOKUP(C29,'CONTROLE CONCILIAÇÃO '!A:C,2,FALSE) -> ADIANTAMENTO DE SALARIO | H29: 42767 | I29: 42793 | L29: =IF(H29="","",IF(K29<>"","Concluída",IF(TODAY()>I29,"Atrasada",IF(J29<>"","Em andamento",IF(AND(J29="",TODAY()>H29),"Atrasada","A iniciar"))))) -> Atrasada | M29: =IF(L29<>"","n","") -> n
B30: 17 | C30: 104002 | D30: Alta | E30: =VLOOKUP(C30,'CONTROLE CONCILIAÇÃO '!A:C,2,FALSE) -> ADIANTAMENTO 13* SALARIO | H30: 42767 | I30: 42793 | L30: =IF(H30="","",IF(K30<>"","Concluída",IF(TODAY()>I30,"Atrasada",IF(J30<>"","Em andamento",IF(AND(J30="",TODAY()>H30),"Atrasada","A iniciar"))))) -> Atrasada | M30: =IF(L30<>"","n","") -> n
B31: 18 | C31: 104003 | D31: Alta | E31: =VLOOKUP(C31,'CONTROLE CONCILIAÇÃO '!A:C,2,FALSE) -> ADIANTAMENTO FERIAS | H31: 42767 | I31: 42793 | L31: =IF(H31="","",IF(K31<>"","Concluída",IF(TODAY()>I31,"Atrasada",IF(J31<>"","Em andamento",IF(AND(J31="",TODAY()>H31),"Atrasada","A iniciar"))))) -> Atrasada | M31: =IF(L31<>"","n","") -> n
B32: 19 | C32: 104004 | D32: Alta | E32: =VLOOKUP(C32,'CONTROLE CONCILIAÇÃO '!A:C,2,FALSE) -> INDENIZACOES A RECEBER | H32: 42767 | I32: 42793 | L32: =IF(H32="","",IF(K32<>"","Concluída",IF(TODAY()>I32,"Atrasada",IF(J32<>"","Em andamento",IF(AND(J32="",TODAY()>H32),"Atrasada","A iniciar"))))) -> Atrasada | M32: =IF(L32<>"","n","") -> n
B33: 20 | C33: 104005 | D33: Alta | E33: =VLOOKUP(C33,'CONTROLE CONCILIAÇÃO '!A:C,2,FALSE) -> VALORES A RECEBER | H33: 42767 | I33: 42793 | L33: =IF(H33="","",IF(K33<>"","Concluída",IF(TODAY()>I33,"Atrasada",IF(J33<>"","Em andamento",IF(AND(J33="",TODAY()>H33),"Atrasada","A iniciar"))))) -> Atrasada | M33: =IF(L33<>"","n","") -> n
B34: 21 | C34: 104006 | D34: Alta | E34: =VLOOKUP(C34,'CONTROLE CONCILIAÇÃO '!A:C,2,FALSE) -> ABASTECIMENTOS A AGREGADOS | H34: 42767 | I34: 42793 | L34: =IF(H34="","",IF(K34<>"","Concluída",IF(TODAY()>I34,"Atrasada",IF(J34<>"","Em andamento",IF(AND(J34="",TODAY()>H34),"Atrasada","A iniciar"))))) -> Atrasada | M34: =IF(L34<>"","n","") -> n
B35: 22 | C35: 104007 | D35: Alta | E35: =VLOOKUP(C35,'CONTROLE CONCILIAÇÃO '!A:C,2,FALSE) -> ADIANTAMENTO A CARRETEIROS | H35: 42767 | I35: 42793 | L35: =IF(H35="","",IF(K35<>"","Concluída",IF(TODAY()>I35,"Atrasada",IF(J35<>"","Em andamento",IF(AND(J35="",TODAY()>H35),"Atrasada","A iniciar"))))) -> Atrasada | M35: =IF(L35<>"","n","") -> n
B36: 23 | C36: 104008 | D36: Alta | E36: =VLOOKUP(C36,'CONTROLE CONCILIAÇÃO '!A:C,2,FALSE) -> ADIANTAMENTO CAV | H36: 42767 | I36: 42793 | L36: =IF(H36="","",IF(K36<>"","Concluída",IF(TODAY()>I36,"Atrasada",IF(J36<>"","Em andamento",IF(AND(J36="",TODAY()>H36),"Atrasada","A iniciar"))))) -> Atrasada | M36: =IF(L36<>"","n","") -> n
B37: 24 | C37: 105001 | D37: Alta | E37: =VLOOKUP(C37,'CONTROLE CONCILIAÇÃO '!A:C,2,FALSE) -> PREMIO DE SEGURO | H37: 42767 | I37: 42793 | L37: =IF(H37="","",IF(K37<>"","Concluída",IF(TODAY()>I37,"Atrasada",IF(J37<>"","Em andamento",IF(AND(J37="",TODAY()>H37),"Atrasada","A iniciar"))))) -> Atrasada | M37: =IF(L37<>"","n","") -> n
... B70: 60 | C70: 110601 | D70: Alta | E70: =VLOOKUP(C70,'CONTROLE CONCILIAÇÃO '!A:C,2,FALSE) -> JUROS A APROPRIAR - LONGO PRAZO | H70: 42767 | I70: 42793 | L70: =IF(H70="","",IF(K70<>"","Concluída",IF(TODAY()>I70,"Atrasada",IF(J70<>"","Em andamento",IF(AND(J70="",TODAY()>H70),"Atrasada","A iniciar"))))) -> Atrasada | M70: =IF(L70<>"","n","") -> n
B71: 61 | C71: 131001 | D71: Alta | E71: =VLOOKUP(C71,'CONTROLE CONCILIAÇÃO '!A:C,2,FALSE) -> VEICULOS | H71: 42767 | I71: 42793 | J71: 42766 | K71: 42766 | L71: =IF(H71="","",IF(K71<>"","Concluída",IF(TODAY()>I71,"Atrasada",IF(J71<>"","Em andamento",IF(AND(J71="",TODAY()>H71),"Atrasada","A iniciar"))))) -> Concluída | M71: =IF(L71<>"","n","") -> n
B72: 62 | C72: 131002 | D72: Alta | E72: =VLOOKUP(C72,'CONTROLE CONCILIAÇÃO '!A:C,2,FALSE) -> EQUIPAMENTOS DE INFORMATICA | H72: 42767 | I72: 42793 | J72: 42766 | K72: 42766 | L72: =IF(H72="","",IF(K72<>"","Concluída",IF(TODAY()>I72,"Atrasada",IF(J72<>"","Em andamento",IF(AND(J72="",TODAY()>H72),"Atrasada","A iniciar"))))) -> Concluída | M72: =IF(L72<>"","n","") -> n
B73: 63 | C73: 131003 | D73: Alta | E73: =VLOOKUP(C73,'CONTROLE CONCILIAÇÃO '!A:C,2,FALSE) -> MOVEIS E UTENSILIOS | H73: 42767 | I73: 42793 | J73: 42766 | K73: 42766 | L73: =IF(H73="","",IF(K73<>"","Concluída",IF(TODAY()>I73,"Atrasada",IF(J73<>"","Em andamento",IF(AND(J73="",TODAY()>H73),"Atrasada","A iniciar"))))) -> Concluída | M73: =IF(L73<>"","n","") -> n
B74: 64 | C74: 131004 | D74: Alta | E74: =VLOOKUP(C74,'CONTROLE CONCILIAÇÃO '!A:C,2,FALSE) -> EQUIPAMENTOS E INSTALACOES OPERACIONAIS | H74: 42767 | I74: 42793 | J74: 42766 | K74: 42766 | L74: =IF(H74="","",IF(K74<>"","Concluída",IF(TODAY()>I74,"Atrasada",IF(J74<>"","Em andamento",IF(AND(J74="",TODAY()>H74),"Atrasada","A iniciar"))))) -> Concluída | M74: =IF(L74<>"","n","") -> n
B75: 65 | C75: 131005 | D75: Alta | E75: =VLOOKUP(C75,'CONTROLE CONCILIAÇÃO '!A:C,2,FALSE) -> INSTALACOES | H75: 42767 | I75: 42793 | J75: 42766 | K75: 42766 | L75: =IF(H75="","",IF(K75<>"","Concluída",IF(TODAY()>I75,"Atrasada",IF(J75<>"","Em andamento",IF(AND(J75="",TODAY()>H75),"Atrasada","A iniciar"))))) -> Concluída | M75: =IF(L75<>"","n","") -> n
B76: 66 | C76: 131006 | D76: Alta | E76: =VLOOKUP(C76,'CONTROLE CONCILIAÇÃO '!A:C,2,FALSE) -> DIREITO DE USO DE SOFTWARE | H76: 42767 | I76: 42793 | J76: 42766 | K76: 42766 | L76: =IF(H76="","",IF(K76<>"","Concluída",IF(TODAY()>I76,"Atrasada",IF(J76<>"","Em andamento",IF(AND(J76="",TODAY()>H76),"Atrasada","A iniciar"))))) -> Concluída | M76: =IF(L76<>"","n","") -> n
...
