Workbook

Sheet CAPA

Sheet Instruções
C1: INTRUÇÕES
B3: Abaixo, você encontra a explicação para todas as abas da planilha.
B6: ABAS: CADASTRO/ ENTRADAS/ SAÍDAS | C6: As cores das fontes dos valores nas tabelas dessas abas indicam que: (1) Células com fontes na cor PRETA devem ser preenchidas manualmente. (2) Células com fontes na cor AZUL são calculadas automaticamente por fórmulas, portanto NÃO devem ser editadas.
B8: CADASTRO PRODUTOS | C8: #========= OBSERVAÇÃO 1 =========# Esta aba faz parte do conjunto de 3 abas para cadastro de informações. Aqui, você pode cadastrar os dados referentes aos seus PRODUTOS. Esta tabela possui uma Validação de Dados que impede o cadastro de produtos duplicados. #========= OBSERVAÇÃO 2 =========# Para cadastrar um novo PRODUTO, basta preencher a primeira linha vazia logo abaixo da tabela. Ela está configurada de modo que toda a formatação da linha e fórmulas usadas sejam arrastadas automaticamente para a nova linha.
B10: CADASTRO FORNECEDORES | C10: #========= OBSERVAÇÃO 1 =========# Esta aba faz parte do conjunto de 3 abas para cadastro de informações. Aqui, você pode cadastrar os dados referentes aos seus FORNECEDORES Esta tabela possui uma Validação de Dados que impede o cadastro de fornecedores duplicados. #========= OBSERVAÇÃO 2 =========# Para cadastrar um novo FORNECEDOR, basta preencher a primeira linha vazia logo abaixo da tabela. Ela está configurada de modo que toda a formatação da linha e fórmulas usadas sejam arrastadas automaticamente para a nova linha.
B12: CADASTRO LOJAS | C12: #========= OBSERVAÇÃO 1 =========# Esta aba faz parte do conjunto de 3 abas para cadastro de informações. Aqui, você pode cadastrar os dados referentes às suas LOJAS. Esta tabela possui uma Validação de Dados que impede o cadastro de produtos duplicados. #========= OBSERVAÇÃO 2 =========# Para cadastrar uma nova LOJA, basta preencher a primeira linha vazia logo abaixo da tabela. Ela está configurada de modo que toda a formatação da linha e fórmulas usadas sejam arrastadas automaticamente para a nova linha.
B14: ENTRADAS | C14: #========= OBSERVAÇÃO 1 =========# Nesta aba você irá registrar todas as ENTRADAS, ou seja, compras para recomposição de estoque. Para cadastrar uma nova ENTRADA de um produto, basta utilizar a Validação de Dados (lista de opções) que se encontra nas células da coluna de PRODUTO. Essa lista se atualiza automaticamente quando você cadastra um novo produto na aba de CADASTRO. #========= OBSERVAÇÃO 2 =========# Para registrar uma nova ENTRADA, basta preencher a primeira linha vazia logo abaixo da tabela. Ela está configurada de modo que toda a formatação da linha e fórmulas usadas sejam arrastadas automaticamente para a nova linha.
B16: SAÍDAS | C16: #========= OBSERVAÇÃO 1 =========# Nesta aba você irá registrar todas as SAÍDAS, ou seja, vendas de produtos. A coluna QUANTIDADE possui uma Validação de Dados que impede que seja registrada uma venda caso não tenha estoque no momento da venda. Obs: Fique atento na coluna de ESTOQUE ACUMULADO, pois a sua venda depende do seu saldo em estoque. Você pode verificar o status de cada produto na aba de CONTROLE DE ESTOQUE, explicada mais abaixo. #========= OBSERVAÇÃO 2 =========# Para cadastrar uma nova SAÍDA de um produto, basta utilizar a Validação de Dados (lista de opções) que se encontra nas células da coluna de PRODUTO. Essa lista se atualiza automaticamente quando você cadastra um novo produto na aba de CADASTRO. #========= OBSERVAÇÃO 3 =========# As colunas de Quantidade Devolvida e Data da Devolução devem ser preenchidas SOMENTE se houver devolução da venda. #========= OBSERVAÇÃO 4 =========# Para registrar uma nova ENTRADA, basta preencher a primeira linha vazia logo abaixo da tabela. Ela está configurada de modo que toda a formatação da linha e fórmulas usadas sejam arrastadas automaticamente para a nova linha.
B18: CONT. ESTOQUE | C18: #========= OBSERVAÇÃO 1 =========# Na aba CONTROLE DE ESTOQUE, a única coluna a ser preenchida manualmente é a de PRODUTO, sempre que um novo produto for adicionado à sua aba de CADASTRO DE PRODUTOS. #========= OBSERVAÇÃO 2 =========# Toda vez que um novo produto for adicionado na aba de CADASTRO DE PRODUTO, a célula F4 da aba CONTROLE DE ESTOQUE apontará que a tabela está defasada. Para corrigir isso, basta adicionar este produto recém-cadastrado também na tabela de CONTROLE DE ESTOQUE. O processo para adicionar um novo produto é o mesmo feito para as outras tabelas: preencher a última linha vazia logo abaixo da tabela. Obs: Preencher somente a coluna de PRODUTO já é suficiente para que todas as fórmulas das demais colunas sejam calculadas! Outra forma de aumentar a tabela de modo geral, é clicar na quina azul na última linha da coluna J e arrastar uma linha para baixo. Feito isso, basta selecionar o produto que acabou de ser cadastrado dentre as opções da lista da coluna B na linha que você acabou de adicionar. Pronto! Seguindo esse passo a passo a mensagem na célula F4 vai mudar para "Sim!" e a tabela de Controle de Estoque estará 100% atualizada! #========= OBSERVAÇÃO 3 =========# Nesta tabela, você pode verificar a situação atual de estoque de cada um dos seus produtos. Os status possíveis são os seguintes: (a) Estoque Confortável: Você possui estoque suficiente para as vendas daquele produto. A linha daquele produto ficará verde. (b) Estoque Perigoso: Você ainda possui estoque, porém ele está abaixo do mínimo de segurança estabelecido. A linha daquele produto ficará pintada de amarelo. (c) Sem Estoque: Se o seu estoque zerar, esta mensagem aparece e a linha da tabela fica laranja.
B20: DASHBOARDS | C20: Nestas abas você encontrará gráficos e indicadores gerais do seu controle de estoque, podendo realizar análises por produtos específicos.

Sheet PROD
C1: CADASTRO DE PRODUTOS
B6: Item | C6: # Código Produto | D6: Unidade de Medida | E6: Estoque Mínimo | F6: Custo Unitário | G6: Preço Unitário
B7: Shampoo Recife
B8: Máscara Olinda
B9: Condicionador Calhetas
B10: Finalizador Petrolina
B11: Shampoo Salvador
B12: Biosfera Resistente | C12: 33059000 | D12: kg | E12: 20 | F12: 86.61 | G12: 240
B13: Booster Ilhéus
B14: Máscara Biosfera | C14: 33059000 | D14: kg | E14: 20 | F14: 46.44 | G14: 110
B15: Pré Escova Bainema
B16: Shampoo São Lius
B17: Cabelo Líquido
B18: Máscara Imperatriz
B19: Condicionador Balças
B20: Shampoo Matizador Curitiba
B21: Máscara Matizadora Londrina
B22: Shampoo Guaruja
B23: Ampola Power Santos
B24: Pré Escova Maresias
B25: Máscara Juquitiba
B26: Shampoo Manaus
... B36: Óleo reparador de pontas

Sheet FORN
C1: CADASTRO DE FORNECEDORES
B6: Empresa | C6: Telefone | D6: E-mail | E6: Endereço | F6: Total Comprado
B7: GL. COMERCIO | D7: PSS10@UOL.COM.BR | E7: R JOSE COSTA JUNIOR, 137, JARDIM SANTA ADELIA CEP 03.974-070 | F7: =IF(FORN!$B7<>"",SUMIF(ENTRADAS!$D$7:$D$57,FORN!$B7,ENTRADAS!$G$7:$G$57),"") -> R$ 66,525.00
F8: =IF(FORN!$B8<>"",SUMIF(ENTRADAS!$D$7:$D$57,FORN!$B8,ENTRADAS!$G$7:$G$57),"")
F9: =IF(FORN!$B9<>"",SUMIF(ENTRADAS!$D$7:$D$57,FORN!$B9,ENTRADAS!$G$7:$G$57),"")
F10: =IF(FORN!$B10<>"",SUMIF(ENTRADAS!$D$7:$D$57,FORN!$B10,ENTRADAS!$G$7:$G$57),"")
F11: =IF(FORN!$B11<>"",SUMIF(ENTRADAS!$D$7:$D$57,FORN!$B11,ENTRADAS!$G$7:$G$57),"")

Sheet LOJAS
C1: CADASTRO DE LOJAS
B6: Loja | C6: Responsável | D6: Telefone | E6: E-mail | F6: Endereço | G6: Total Vendido
B7: Rio de Janeiro | C7: Adriana | D7: (81) 99735-0727 | E7: adryanadyas39@gmail.com | F7: Rua: 60, Qr 264, Lote 15, S/N, Bairro: Jardim Atlatico, CEP: 24.934-440, Marica-RJ | G7: =IF(LOJAS!$B7<>"",SUMIF('SAÍDAS'!$D$7:$D$76,LOJAS!$B7,'SAÍDAS'!$K$7:$K$76),"") -> R$ 0.00
B8: Pernambuco | C8: Raquel | D8: (81) 95344-9193 | E8: raquelnathalia57@gmail.com | F8: Rua: Dois de Julho, 251, apto 1607 torre B, Santo Amaro, Recife -PE, CEP: 50.040-180 | G8: =IF(LOJAS!$B8<>"",SUMIF('SAÍDAS'!$D$7:$D$76,LOJAS!$B8,'SAÍDAS'!$K$7:$K$76),"") -> R$ 0.00
B9: Espanha | C9: Denilson | D9: 34 692 96 91 91 | E9: denilsoncarneirodurval@gmail.com | G9: =IF(LOJAS!$B9<>"",SUMIF('SAÍDAS'!$D$7:$D$76,LOJAS!$B9,'SAÍDAS'!$K$7:$K$76),"") -> R$ 0.00
B10: Distrito Federal/Góias | C10: Edson/Williams | D10: (81) 98193-5594 | E10: edson.ferre@globomail.com | F10: QRC 16, 15 - Condomínio Santos Drumont, Bairro: Santa Maria, CEP: 72.593-116, Brasilia - DF | G10: =IF(LOJAS!$B10<>"",SUMIF('SAÍDAS'!$D$7:$D$76,LOJAS!$B10,'SAÍDAS'!$K$7:$K$76),"") -> R$ 0.00
G11: =IF(LOJAS!$B11<>"",SUMIF('SAÍDAS'!$D$7:$D$76,LOJAS!$B11,'SAÍDAS'!$K$7:$K$76),"")

Sheet ENTRADAS
C1: CONTROLE DE ENTRADAS
B6: Data da Compra | C6: Produto | D6: Fornecedor | E6: Quantidade | F6: Custo Unitário | G6: Valor de Compra Total
B7: 44208 | C7: Biosfera Resistente | D7: GL. COMERCIO | E7: 300 | F7: =VLOOKUP(ENTRADAS!$C7,PROD!$B$7:$G$36,5,0) -> R$ 86.61 | G7: =F7*E7 -> R$ 25,983.00
B8: 44208 | C8: Máscara Biosfera | D8: GL. COMERCIO | E8: 300 | F8: =VLOOKUP(ENTRADAS!$C8,PROD!$B$7:$G$36,5,0) -> R$ 46.44 | G8: =F8*E8 -> R$ 13,932.00
B9: 44208 | C9: Biosfera Resistente | D9: GL. COMERCIO | E9: 100 | F9: =VLOOKUP(ENTRADAS!$C9,PROD!$B$7:$G$36,5,0) -> R$ 86.61 | G9: =F9*E9 -> R$ 8,661.00
B10: 44208 | C10: Máscara Biosfera | D10: GL. COMERCIO | E10: 100 | F10: =VLOOKUP(ENTRADAS!$C10,PROD!$B$7:$G$36,5,0) -> R$ 46.44 | G10: =F10*E10 -> R$ 4,644.00
B11: 44208 | C11: Biosfera Resistente | D11: GL. COMERCIO | E11: 100 | F11: =VLOOKUP(ENTRADAS!$C11,PROD!$B$7:$G$36,5,0) -> R$ 86.61 | G11: =F11*E11 -> R$ 8,661.00
B12: 44208 | C12: Máscara Biosfera | D12: GL. COMERCIO | E12: 100 | F12: =VLOOKUP(ENTRADAS!$C12,PROD!$B$7:$G$36,5,0) -> R$ 46.44 | G12: =F12*E12 -> R$ 4,644.00
F13: =VLOOKUP(ENTRADAS!$C13,PROD!$B$7:$G$36,5,0) -> #N/A | G13: =F13*E13 -> #N/A
F14: =VLOOKUP(ENTRADAS!$C14,PROD!$B$7:$G$36,5,0) -> #N/A | G14: =F14*E14 -> #N/A
F15: =VLOOKUP(ENTRADAS!$C15,PROD!$B$7:$G$36,5,0) -> #N/A | G15: =F15*E15 -> #N/A
F16: =VLOOKUP(ENTRADAS!$C16,PROD!$B$7:$G$36,5,0) -> #N/A | G16: =F16*E16 -> #N/A
F17: =VLOOKUP(ENTRADAS!$C17,PROD!$B$7:$G$36,5,0) -> #N/A | G17: =F17*E17 -> #N/A
F18: =VLOOKUP(ENTRADAS!$C18,PROD!$B$7:$G$36,5,0) -> #N/A | G18: =F18*E18 -> #N/A
F19: =VLOOKUP(ENTRADAS!$C19,PROD!$B$7:$G$36,5,0) -> #N/A | G19: =F19*E19 -> #N/A
F20: =VLOOKUP(ENTRADAS!$C20,PROD!$B$7:$G$36,5,0) -> #N/A | G20: =F20*E20 -> #N/A
F21: =VLOOKUP(ENTRADAS!$C21,PROD!$B$7:$G$36,5,0) -> #N/A | G21: =F21*E21 -> #N/A
F22: =VLOOKUP(ENTRADAS!$C22,PROD!$B$7:$G$36,5,0) -> #N/A | G22: =F22*E22 -> #N/A
F23: =VLOOKUP(ENTRADAS!$C23,PROD!$B$7:$G$36,5,0) -> #N/A | G23: =F23*E23 -> #N/A
F24: =VLOOKUP(ENTRADAS!$C24,PROD!$B$7:$G$36,5,0) -> #N/A | G24: =F24*E24 -> #N/A
... F57: =VLOOKUP(ENTRADAS!$C57,PROD!$B$7:$G$36,5,0) -> #N/A | G57: =F57*E57 -> #N/A

Sheet SAÍDAS
C1: CONTROLE DE SAÍDAS
B6: Data da Venda | C6: Produto | D6: Loja | E6: Quantidade | F6: Quantidade Devolvida | G6: Data da Devolução | H6: Quantidade Vendida | I6: Estoque Acumulado | J6: Preço Unitário | K6: Valor de Venda Total
H7: ='SAÍDAS'!$E7-'SAÍDAS'!$F7 -> 0 | I7: =SUMIFS(ENTRADAS!$E$7:$E$57,ENTRADAS!$B$7:$B$57,"<=" & 'SAÍDAS'!$B7,ENTRADAS!$C$7:$C$57,'SAÍDAS'!$C7)-SUMIFS('SAÍDAS'!$H$7:$H$76,'SAÍDAS'!$B$7:$B$76,"<=" & 'SAÍDAS'!$B7,'SAÍDAS'!$C$7:$C$76,'SAÍDAS'!$C7) -> 0 | J7: =VLOOKUP('SAÍDAS'!$C7,PROD!$B$7:$G$36,6,0) -> #N/A | K7: ='SAÍDAS'!$H7*'SAÍDAS'!$J7 -> #N/A
H8: ='SAÍDAS'!$E8-'SAÍDAS'!$F8 -> 0 | I8: =SUMIFS(ENTRADAS!$E$7:$E$57,ENTRADAS!$B$7:$B$57,"<=" & 'SAÍDAS'!$B8,ENTRADAS!$C$7:$C$57,'SAÍDAS'!$C8)-SUMIFS('SAÍDAS'!$H$7:$H$76,'SAÍDAS'!$B$7:$B$76,"<=" & 'SAÍDAS'!$B8,'SAÍDAS'!$C$7:$C$76,'SAÍDAS'!$C8) -> 0 | J8: =VLOOKUP('SAÍDAS'!$C8,PROD!$B$7:$G$36,6,0) -> #N/A | K8: ='SAÍDAS'!$H8*'SAÍDAS'!$J8 -> #N/A
H9: ='SAÍDAS'!$E9-'SAÍDAS'!$F9 -> 0 | I9: =SUMIFS(ENTRADAS!$E$7:$E$57,ENTRADAS!$B$7:$B$57,"<=" & 'SAÍDAS'!$B9,ENTRADAS!$C$7:$C$57,'SAÍDAS'!$C9)-SUMIFS('SAÍDAS'!$H$7:$H$76,'SAÍDAS'!$B$7:$B$76,"<=" & 'SAÍDAS'!$B9,'SAÍDAS'!$C$7:$C$76,'SAÍDAS'!$C9) -> 0 | J9: =VLOOKUP('SAÍDAS'!$C9,PROD!$B$7:$G$36,6,0) -> #N/A | K9: ='SAÍDAS'!$H9*'SAÍDAS'!$J9 -> #N/A
H10: ='SAÍDAS'!$E10-'SAÍDAS'!$F10 -> 0 | I10: =SUMIFS(ENTRADAS!$E$7:$E$57,ENTRADAS!$B$7:$B$57,"<=" & 'SAÍDAS'!$B10,ENTRADAS!$C$7:$C$57,'SAÍDAS'!$C10)-SUMIFS('SAÍDAS'!$H$7:$H$76,'SAÍDAS'!$B$7:$B$76,"<=" & 'SAÍDAS'!$B10,'SAÍDAS'!$C$7:$C$76,'SAÍDAS'!$C10) -> 0 | J10: =VLOOKUP('SAÍDAS'!$C10,PROD!$B$7:$G$36,6,0) -> #N/A | K10: ='SAÍDAS'!$H10*'SAÍDAS'!$J10 -> #N/A
H11: ='SAÍDAS'!$E11-'SAÍDAS'!$F11 -> 0 | I11: =SUMIFS(ENTRADAS!$E$7:$E$57,ENTRADAS!$B$7:$B$57,"<=" & 'SAÍDAS'!$B11,ENTRADAS!$C$7:$C$57,'SAÍDAS'!$C11)-SUMIFS('SAÍDAS'!$H$7:$H$76,'SAÍDAS'!$B$7:$B$76,"<=" & 'SAÍDAS'!$B11,'SAÍDAS'!$C$7:$C$76,'SAÍDAS'!$C11) -> 0 | J11: =VLOOKUP('SAÍDAS'!$C11,PROD!$B$7:$G$36,6,0) -> #N/A | K11: ='SAÍDAS'!$H11*'SAÍDAS'!$J11 -> #N/A
H12: ='SAÍDAS'!$E12-'SAÍDAS'!$F12 -> 0 | I12: =SUMIFS(ENTRADAS!$E$7:$E$57,ENTRADAS!$B$7:$B$57,"<=" & 'SAÍDAS'!$B12,ENTRADAS!$C$7:$C$57,'SAÍDAS'!$C12)-SUMIFS('SAÍDAS'!$H$7:$H$76,'SAÍDAS'!$B$7:$B$76,"<=" & 'SAÍDAS'!$B12,'SAÍDAS'!$C$7:$C$76,'SAÍDAS'!$C12) -> 0 | J12: =VLOOKUP('SAÍDAS'!$C12,PROD!$B$7:$G$36,6,0) -> #N/A | K12: ='SAÍDAS'!$H12*'SAÍDAS'!$J12 -> #N/A
H13: ='SAÍDAS'!$E13-'SAÍDAS'!$F13 -> 0 | I13: =SUMIFS(ENTRADAS!$E$7:$E$57,ENTRADAS!$B$7:$B$57,"<=" & 'SAÍDAS'!$B13,ENTRADAS!$C$7:$C$57,'SAÍDAS'!$C13)-SUMIFS('SAÍDAS'!$H$7:$H$76,'SAÍDAS'!$B$7:$B$76,"<=" & 'SAÍDAS'!$B13,'SAÍDAS'!$C$7:$C$76,'SAÍDAS'!$C13) -> 0 | J13: =VLOOKUP('SAÍDAS'!$C13,PROD!$B$7:$G$36,6,0) -> #N/A | K13: ='SAÍDAS'!$H13*'SAÍDAS'!$J13 -> #N/A
H14: ='SAÍDAS'!$E14-'SAÍDAS'!$F14 -> 0 | I14: =SUMIFS(ENTRADAS!$E$7:$E$57,ENTRADAS!$B$7:$B$57,"<=" & 'SAÍDAS'!$B14,ENTRADAS!$C$7:$C$57,'SAÍDAS'!$C14)-SUMIFS('SAÍDAS'!$H$7:$H$76,'SAÍDAS'!$B$7:$B$76,"<=" & 'SAÍDAS'!$B14,'SAÍDAS'!$C$7:$C$76,'SAÍDAS'!$C14) -> 0 | J14: =VLOOKUP('SAÍDAS'!$C14,PROD!$B$7:$G$36,6,0) -> #N/A | K14: ='SAÍDAS'!$H14*'SAÍDAS'!$J14 -> #N/A
H15: ='SAÍDAS'!$E15-'SAÍDAS'!$F15 -> 0 | I15: =SUMIFS(ENTRADAS!$E$7:$E$57,ENTRADAS!$B$7:$B$57,"<=" & 'SAÍDAS'!$B15,ENTRADAS!$C$7:$C$57,'SAÍDAS'!$C15)-SUMIFS('SAÍDAS'!$H$7:$H$76,'SAÍDAS'!$B$7:$B$76,"<=" & 'SAÍDAS'!$B15,'SAÍDAS'!$C$7:$C$76,'SAÍDAS'!$C15) -> 0 | J15: =VLOOKUP('SAÍDAS'!$C15,PROD!$B$7:$G$36,6,0) -> #N/A | K15: ='SAÍDAS'!$H15*'SAÍDAS'!$J15 -> #N/A
H16: ='SAÍDAS'!$E16-'SAÍDAS'!$F16 -> 0 | I16: =SUMIFS(ENTRADAS!$E$7:$E$57,ENTRADAS!$B$7:$B$57,"<=" & 'SAÍDAS'!$B16,ENTRADAS!$C$7:$C$57,'SAÍDAS'!$C16)-SUMIFS('SAÍDAS'!$H$7:$H$76,'SAÍDAS'!$B$7:$B$76,"<=" & 'SAÍDAS'!$B16,'SAÍDAS'!$C$7:$C$76,'SAÍDAS'!$C16) -> 0 | J16: =VLOOKUP('SAÍDAS'!$C16,PROD!$B$7:$G$36,6,0) -> #N/A | K16: ='SAÍDAS'!$H16*'SAÍDAS'!$J16 -> #N/A
H17: ='SAÍDAS'!$E17-'SAÍDAS'!$F17 -> 0 | I17: =SUMIFS(ENTRADAS!$E$7:$E$57,ENTRADAS!$B$7:$B$57,"<=" & 'SAÍDAS'!$B17,ENTRADAS!$C$7:$C$57,'SAÍDAS'!$C17)-SUMIFS('SAÍDAS'!$H$7:$H$76,'SAÍDAS'!$B$7:$B$76,"<=" & 'SAÍDAS'!$B17,'SAÍDAS'!$C$7:$C$76,'SAÍDAS'!$C17) -> 0 | J17: =VLOOKUP('SAÍDAS'!$C17,PROD!$B$7:$G$36,6,0) -> #N/A | K17: ='SAÍDAS'!$H17*'SAÍDAS'!$J17 -> #N/A
H18: ='SAÍDAS'!$E18-'SAÍDAS'!$F18 -> 0 | I18: =SUMIFS(ENTRADAS!$E$7:$E$57,ENTRADAS!$B$7:$B$57,"<=" & 'SAÍDAS'!$B18,ENTRADAS!$C$7:$C$57,'SAÍDAS'!$C18)-SUMIFS('SAÍDAS'!$H$7:$H$76,'SAÍDAS'!$B$7:$B$76,"<=" & 'SAÍDAS'!$B18,'SAÍDAS'!$C$7:$C$76,'SAÍDAS'!$C18) -> 0 | J18: =VLOOKUP('SAÍDAS'!$C18,PROD!$B$7:$G$36,6,0) -> #N/A | K18: ='SAÍDAS'!$H18*'SAÍDAS'!$J18 -> #N/A
... H76: ='SAÍDAS'!$E76-'SAÍDAS'!$F76 -> 0 | I76: =SUMIFS(ENTRADAS!$E$7:$E$57,ENTRADAS!$B$7:$B$57,"<=" & 'SAÍDAS'!$B76,ENTRADAS!$C$7:$C$57,'SAÍDAS'!$C76)-SUMIFS('SAÍDAS'!$H$7:$H$76,'SAÍDAS'!$B$7:$B$76,"<=" & 'SAÍDAS'!$B76,'SAÍDAS'!$C$7:$C$76,'SAÍDAS'!$C76) -> 0 | J76: =VLOOKUP('SAÍDAS'!$C76,PROD!$B$7:$G$36,6,0) -> #N/A | K76: ='SAÍDAS'!$H76*'SAÍDAS'!$J76 -> #N/A

Sheet CONT. ESTOQUE
C1: CONTROLE DE ESTOQUE
B4: Check automático: A tabela de Controle de Estoque está completa? | F4: =IF(COUNTA('CONT. ESTOQUE'!$B$7:$B$16)=COUNTA(PROD!$B$7:$B$36),"Sim!","Não! Tabela de Controle de Estoque defasada, acrescentar produto faltante.") -> Não! Tabela de Controle de Estoque defasada, acrescentar produto faltante.
B6: Produto | C6: Entradas | D6: Saídas | E6: Saldo | F6: Estoque Mínimo | G6: Status | H6: Receita Total | I6: Custo Total | J6: Lucro/Prejuízo Total
B7: Biosfera Resistente | C7: =IF('CONT. ESTOQUE'!$B7<>"",SUMIF(ENTRADAS!$C$7:$C$57,'CONT. ESTOQUE'!$B7,ENTRADAS!$E$7:$E$57),"") -> 500 | D7: =IF('CONT. ESTOQUE'!$B7<>"",SUMIF('SAÍDAS'!$C$7:$C$76,'CONT. ESTOQUE'!$B7,'SAÍDAS'!$H$7:$H$76),"") -> 0 | E7: =IFERROR('CONT. ESTOQUE'!$C7-'CONT. ESTOQUE'!$D7,"") -> 500 | F7: =IFERROR(VLOOKUP('CONT. ESTOQUE'!$B7,PROD!$B$6:$G$36,4,0),"") -> 20 | G7: =IF('CONT. ESTOQUE'!$B7<>"",IF('CONT. ESTOQUE'!$E7=0,"Sem Estoque",IF('CONT. ESTOQUE'!$E7<'CONT. ESTOQUE'!$F7,"Estoque Perigoso","Estoque Confortável")),"") -> Estoque Confortável | H7: =SUMIF('SAÍDAS'!$C$7:$C$76,'CONT. ESTOQUE'!$B7,'SAÍDAS'!$K$7:$K$76) -> R$ 0.00 | I7: =SUMIF(ENTRADAS!$C$7:$C$57,'CONT. ESTOQUE'!$B7,ENTRADAS!$G$7:$G$57) -> R$ 43,305.00 | J7: ='CONT. ESTOQUE'!$H7-'CONT. ESTOQUE'!$I7 -> -R$ 43,305.00
B8: Máscara Biosfera | C8: =IF('CONT. ESTOQUE'!$B8<>"",SUMIF(ENTRADAS!$C$7:$C$57,'CONT. ESTOQUE'!$B8,ENTRADAS!$E$7:$E$57),"") -> 500 | D8: =IF('CONT. ESTOQUE'!$B8<>"",SUMIF('SAÍDAS'!$C$7:$C$76,'CONT. ESTOQUE'!$B8,'SAÍDAS'!$H$7:$H$76),"") -> 0 | E8: =IFERROR('CONT. ESTOQUE'!$C8-'CONT. ESTOQUE'!$D8,"") -> 500 | F8: =IFERROR(VLOOKUP('CONT. ESTOQUE'!$B8,PROD!$B$6:$G$36,4,0),"") -> 20 | G8: =IF('CONT. ESTOQUE'!$B8<>"",IF('CONT. ESTOQUE'!$E8=0,"Sem Estoque",IF('CONT. ESTOQUE'!$E8<'CONT. ESTOQUE'!$F8,"Estoque Perigoso","Estoque Confortável")),"") -> Estoque Confortável | H8: =SUMIF('SAÍDAS'!$C$7:$C$76,'CONT. ESTOQUE'!$B8,'SAÍDAS'!$K$7:$K$76) -> R$ 0.00 | I8: =SUMIF(ENTRADAS!$C$7:$C$57,'CONT. ESTOQUE'!$B8,ENTRADAS!$G$7:$G$57) -> R$ 23,220.00 | J8: ='CONT. ESTOQUE'!$H8-'CONT. ESTOQUE'!$I8 -> -R$ 23,220.00
B9: Shampoo Recife | C9: =IF('CONT. ESTOQUE'!$B9<>"",SUMIF(ENTRADAS!$C$7:$C$57,'CONT. ESTOQUE'!$B9,ENTRADAS!$E$7:$E$57),"") -> 0 | D9: =IF('CONT. ESTOQUE'!$B9<>"",SUMIF('SAÍDAS'!$C$7:$C$76,'CONT. ESTOQUE'!$B9,'SAÍDAS'!$H$7:$H$76),"") -> 0 | E9: =IFERROR('CONT. ESTOQUE'!$C9-'CONT. ESTOQUE'!$D9,"") -> 0 | F9: =IFERROR(VLOOKUP('CONT. ESTOQUE'!$B9,PROD!$B$6:$G$36,4,0),"") | G9: =IF('CONT. ESTOQUE'!$B9<>"",IF('CONT. ESTOQUE'!$E9=0,"Sem Estoque",IF('CONT. ESTOQUE'!$E9<'CONT. ESTOQUE'!$F9,"Estoque Perigoso","Estoque Confortável")),"") -> Sem Estoque | H9: =SUMIF('SAÍDAS'!$C$7:$C$76,'CONT. ESTOQUE'!$B9,'SAÍDAS'!$K$7:$K$76) -> R$ 0.00 | I9: =SUMIF(ENTRADAS!$C$7:$C$57,'CONT. ESTOQUE'!$B9,ENTRADAS!$G$7:$G$57) -> R$ 0.00 | J9: ='CONT. ESTOQUE'!$H9-'CONT. ESTOQUE'!$I9 -> R$ 0.00
B10: Máscara Olinda | C10: =IF('CONT. ESTOQUE'!$B10<>"",SUMIF(ENTRADAS!$C$7:$C$57,'CONT. ESTOQUE'!$B10,ENTRADAS!$E$7:$E$57),"") -> 0 | D10: =IF('CONT. ESTOQUE'!$B10<>"",SUMIF('SAÍDAS'!$C$7:$C$76,'CONT. ESTOQUE'!$B10,'SAÍDAS'!$H$7:$H$76),"") -> 0 | E10: =IFERROR('CONT. ESTOQUE'!$C10-'CONT. ESTOQUE'!$D10,"") -> 0 | F10: =IFERROR(VLOOKUP('CONT. ESTOQUE'!$B10,PROD!$B$6:$G$36,4,0),"") | G10: =IF('CONT. ESTOQUE'!$B10<>"",IF('CONT. ESTOQUE'!$E10=0,"Sem Estoque",IF('CONT. ESTOQUE'!$E10<'CONT. ESTOQUE'!$F10,"Estoque Perigoso","Estoque Confortável")),"") -> Sem Estoque | H10: =SUMIF('SAÍDAS'!$C$7:$C$76,'CONT. ESTOQUE'!$B10,'SAÍDAS'!$K$7:$K$76) -> R$ 0.00 | I10: =SUMIF(ENTRADAS!$C$7:$C$57,'CONT. ESTOQUE'!$B10,ENTRADAS!$G$7:$G$57) -> R$ 0.00 | J10: ='CONT. ESTOQUE'!$H10-'CONT. ESTOQUE'!$I10 -> R$ 0.00
B11: Condicionador Calhetas | C11: =IF('CONT. ESTOQUE'!$B11<>"",SUMIF(ENTRADAS!$C$7:$C$57,'CONT. ESTOQUE'!$B11,ENTRADAS!$E$7:$E$57),"") -> 0 | D11: =IF('CONT. ESTOQUE'!$B11<>"",SUMIF('SAÍDAS'!$C$7:$C$76,'CONT. ESTOQUE'!$B11,'SAÍDAS'!$H$7:$H$76),"") -> 0 | E11: =IFERROR('CONT. ESTOQUE'!$C11-'CONT. ESTOQUE'!$D11,"") -> 0 | F11: =IFERROR(VLOOKUP('CONT. ESTOQUE'!$B11,PROD!$B$6:$G$36,4,0),"") | G11: =IF('CONT. ESTOQUE'!$B11<>"",IF('CONT. ESTOQUE'!$E11=0,"Sem Estoque",IF('CONT. ESTOQUE'!$E11<'CONT. ESTOQUE'!$F11,"Estoque Perigoso","Estoque Confortável")),"") -> Sem Estoque | H11: =SUMIF('SAÍDAS'!$C$7:$C$76,'CONT. ESTOQUE'!$B11,'SAÍDAS'!$K$7:$K$76) -> R$ 0.00 | I11: =SUMIF(ENTRADAS!$C$7:$C$57,'CONT. ESTOQUE'!$B11,ENTRADAS!$G$7:$G$57) -> R$ 0.00 | J11: ='CONT. ESTOQUE'!$H11-'CONT. ESTOQUE'!$I11 -> R$ 0.00
B12: Finalizador Petrolina | C12: =IF('CONT. ESTOQUE'!$B12<>"",SUMIF(ENTRADAS!$C$7:$C$57,'CONT. ESTOQUE'!$B12,ENTRADAS!$E$7:$E$57),"") -> 0 | D12: =IF('CONT. ESTOQUE'!$B12<>"",SUMIF('SAÍDAS'!$C$7:$C$76,'CONT. ESTOQUE'!$B12,'SAÍDAS'!$H$7:$H$76),"") -> 0 | E12: =IFERROR('CONT. ESTOQUE'!$C12-'CONT. ESTOQUE'!$D12,"") -> 0 | F12: =IFERROR(VLOOKUP('CONT. ESTOQUE'!$B12,PROD!$B$6:$G$36,4,0),"") | G12: =IF('CONT. ESTOQUE'!$B12<>"",IF('CONT. ESTOQUE'!$E12=0,"Sem Estoque",IF('CONT. ESTOQUE'!$E12<'CONT. ESTOQUE'!$F12,"Estoque Perigoso","Estoque Confortável")),"") -> Sem Estoque | H12: =SUMIF('SAÍDAS'!$C$7:$C$76,'CONT. ESTOQUE'!$B12,'SAÍDAS'!$K$7:$K$76) -> R$ 0.00 | I12: =SUMIF(ENTRADAS!$C$7:$C$57,'CONT. ESTOQUE'!$B12,ENTRADAS!$G$7:$G$57) -> R$ 0.00 | J12: ='CONT. ESTOQUE'!$H12-'CONT. ESTOQUE'!$I12 -> R$ 0.00
B13: Shampoo Salvador | C13: =IF('CONT. ESTOQUE'!$B13<>"",SUMIF(ENTRADAS!$C$7:$C$57,'CONT. ESTOQUE'!$B13,ENTRADAS!$E$7:$E$57),"") -> 0 | D13: =IF('CONT. ESTOQUE'!$B13<>"",SUMIF('SAÍDAS'!$C$7:$C$76,'CONT. ESTOQUE'!$B13,'SAÍDAS'!$H$7:$H$76),"") -> 0 | E13: =IFERROR('CONT. ESTOQUE'!$C13-'CONT. ESTOQUE'!$D13,"") -> 0 | F13: =IFERROR(VLOOKUP('CONT. ESTOQUE'!$B13,PROD!$B$6:$G$36,4,0),"") | G13: =IF('CONT. ESTOQUE'!$B13<>"",IF('CONT. ESTOQUE'!$E13=0,"Sem Estoque",IF('CONT. ESTOQUE'!$E13<'CONT. ESTOQUE'!$F13,"Estoque Perigoso","Estoque Confortável")),"") -> Sem Estoque | H13: =SUMIF('SAÍDAS'!$C$7:$C$76,'CONT. ESTOQUE'!$B13,'SAÍDAS'!$K$7:$K$76) -> R$ 0.00 | I13: =SUMIF(ENTRADAS!$C$7:$C$57,'CONT. ESTOQUE'!$B13,ENTRADAS!$G$7:$G$57) -> R$ 0.00 | J13: ='CONT. ESTOQUE'!$H13-'CONT. ESTOQUE'!$I13 -> R$ 0.00
B14: Cabelo Líquido | C14: =IF('CONT. ESTOQUE'!$B14<>"",SUMIF(ENTRADAS!$C$7:$C$57,'CONT. ESTOQUE'!$B14,ENTRADAS!$E$7:$E$57),"") -> 0 | D14: =IF('CONT. ESTOQUE'!$B14<>"",SUMIF('SAÍDAS'!$C$7:$C$76,'CONT. ESTOQUE'!$B14,'SAÍDAS'!$H$7:$H$76),"") -> 0 | E14: =IFERROR('CONT. ESTOQUE'!$C14-'CONT. ESTOQUE'!$D14,"") -> 0 | F14: =IFERROR(VLOOKUP('CONT. ESTOQUE'!$B14,PROD!$B$6:$G$36,4,0),"") | G14: =IF('CONT. ESTOQUE'!$B14<>"",IF('CONT. ESTOQUE'!$E14=0,"Sem Estoque",IF('CONT. ESTOQUE'!$E14<'CONT. ESTOQUE'!$F14,"Estoque Perigoso","Estoque Confortável")),"") -> Sem Estoque | H14: =SUMIF('SAÍDAS'!$C$7:$C$76,'CONT. ESTOQUE'!$B14,'SAÍDAS'!$K$7:$K$76) -> R$ 0.00 | I14: =SUMIF(ENTRADAS!$C$7:$C$57,'CONT. ESTOQUE'!$B14,ENTRADAS!$G$7:$G$57) -> R$ 0.00 | J14: ='CONT. ESTOQUE'!$H14-'CONT. ESTOQUE'!$I14 -> R$ 0.00
B15: Booster Ilhéus | C15: =IF('CONT. ESTOQUE'!$B15<>"",SUMIF(ENTRADAS!$C$7:$C$57,'CONT. ESTOQUE'!$B15,ENTRADAS!$E$7:$E$57),"") -> 0 | D15: =IF('CONT. ESTOQUE'!$B15<>"",SUMIF('SAÍDAS'!$C$7:$C$76,'CONT. ESTOQUE'!$B15,'SAÍDAS'!$H$7:$H$76),"") -> 0 | E15: =IFERROR('CONT. ESTOQUE'!$C15-'CONT. ESTOQUE'!$D15,"") -> 0 | F15: =IFERROR(VLOOKUP('CONT. ESTOQUE'!$B15,PROD!$B$6:$G$36,4,0),"") | G15: =IF('CONT. ESTOQUE'!$B15<>"",IF('CONT. ESTOQUE'!$E15=0,"Sem Estoque",IF('CONT. ESTOQUE'!$E15<'CONT. ESTOQUE'!$F15,"Estoque Perigoso","Estoque Confortável")),"") -> Sem Estoque | H15: =SUMIF('SAÍDAS'!$C$7:$C$76,'CONT. ESTOQUE'!$B15,'SAÍDAS'!$K$7:$K$76) -> R$ 0.00 | I15: =SUMIF(ENTRADAS!$C$7:$C$57,'CONT. ESTOQUE'!$B15,ENTRADAS!$G$7:$G$57) -> R$ 0.00 | J15: ='CONT. ESTOQUE'!$H15-'CONT. ESTOQUE'!$I15 -> R$ 0.00
B16: Shampoo Matizador Curitiba | C16: =IF('CONT. ESTOQUE'!$B16<>"",SUMIF(ENTRADAS!$C$7:$C$57,'CONT. ESTOQUE'!$B16,ENTRADAS!$E$7:$E$57),"") -> 0 | D16: =IF('CONT. ESTOQUE'!$B16<>"",SUMIF('SAÍDAS'!$C$7:$C$76,'CONT. ESTOQUE'!$B16,'SAÍDAS'!$H$7:$H$76),"") -> 0 | E16: =IFERROR('CONT. ESTOQUE'!$C16-'CONT. ESTOQUE'!$D16,"") -> 0 | F16: =IFERROR(VLOOKUP('CONT. ESTOQUE'!$B16,PROD!$B$6:$G$36,4,0),"") | G16: =IF('CONT. ESTOQUE'!$B16<>"",IF('CONT. ESTOQUE'!$E16=0,"Sem Estoque",IF('CONT. ESTOQUE'!$E16<'CONT. ESTOQUE'!$F16,"Estoque Perigoso","Estoque Confortável")),"") -> Sem Estoque | H16: =SUMIF('SAÍDAS'!$C$7:$C$76,'CONT. ESTOQUE'!$B16,'SAÍDAS'!$K$7:$K$76) -> R$ 0.00 | I16: =SUMIF(ENTRADAS!$C$7:$C$57,'CONT. ESTOQUE'!$B16,ENTRADAS!$G$7:$G$57) -> R$ 0.00 | J16: ='CONT. ESTOQUE'!$H16-'CONT. ESTOQUE'!$I16 -> R$ 0.00
B17: Joelho

Sheet DASH VG
C1: DASHBOARD

Sheet DASH ESTOQUE
C1: DASHBOARD
B7: Produto | C7: Biosfera Resistente
B9: Ano | C9: 2021

Sheet DASH RESULTADOS
C1: DASHBOARD
B7: Produto | C7: Biosfera Resistente
B9: Ano | C9: 2021

Sheet Auxiliar
B2: Produto | C2: ='DASH RESULTADOS'!C7 -> Biosfera Resistente
B4: Qtd Entrada x Saída | E4: Ano | F4: ='DASH RESULTADOS'!C9 -> 2021 | I4: ="Resultado de Compras X Vendas para o ano de " & F4 & CHAR(10) & "Quantidades" -> Resultado de Compras X Vendas para o ano de 2021 Quantidades
B6: Mês | C6: Compras | D6: Vendas
A7: 1 | B7: =DATE($F$4,A7,1) -> Jan-21 | C7: =SUMIFS(ENTRADAS!$E$7:$E$57,ENTRADAS!$B$7:$B$57,">=" & B7,ENTRADAS!$B$7:$B$57,"<" & EDATE($B$7,A7),ENTRADAS!$C$7:$C$57,$C$2) -> 500 | D7: =SUMIFS('SAÍDAS'!$H$7:$H$76,'SAÍDAS'!$B$7:$B$76,">=" & B7,'SAÍDAS'!$B$7:$B$76,"<" & EDATE($B$7,A7),'SAÍDAS'!$C$7:$C$76,$C$2) -> 0
A8: 2 | B8: =DATE($F$4,A8,1) -> Feb-21 | C8: =SUMIFS(ENTRADAS!$E$7:$E$57,ENTRADAS!$B$7:$B$57,">=" & B8,ENTRADAS!$B$7:$B$57,"<" & EDATE($B$7,A8),ENTRADAS!$C$7:$C$57,$C$2) -> 0 | D8: =SUMIFS('SAÍDAS'!$H$7:$H$76,'SAÍDAS'!$B$7:$B$76,">=" & B8,'SAÍDAS'!$B$7:$B$76,"<" & EDATE($B$7,A8),'SAÍDAS'!$C$7:$C$76,$C$2) -> 0
A9: 3 | B9: =DATE($F$4,A9,1) -> Mar-21 | C9: =SUMIFS(ENTRADAS!$E$7:$E$57,ENTRADAS!$B$7:$B$57,">=" & B9,ENTRADAS!$B$7:$B$57,"<" & EDATE($B$7,A9),ENTRADAS!$C$7:$C$57,$C$2) -> 0 | D9: =SUMIFS('SAÍDAS'!$H$7:$H$76,'SAÍDAS'!$B$7:$B$76,">=" & B9,'SAÍDAS'!$B$7:$B$76,"<" & EDATE($B$7,A9),'SAÍDAS'!$C$7:$C$76,$C$2) -> 0
A10: 4 | B10: =DATE($F$4,A10,1) -> Apr-21 | C10: =SUMIFS(ENTRADAS!$E$7:$E$57,ENTRADAS!$B$7:$B$57,">=" & B10,ENTRADAS!$B$7:$B$57,"<" & EDATE($B$7,A10),ENTRADAS!$C$7:$C$57,$C$2) -> 0 | D10: =SUMIFS('SAÍDAS'!$H$7:$H$76,'SAÍDAS'!$B$7:$B$76,">=" & B10,'SAÍDAS'!$B$7:$B$76,"<" & EDATE($B$7,A10),'SAÍDAS'!$C$7:$C$76,$C$2) -> 0
A11: 5 | B11: =DATE($F$4,A11,1) -> May-21 | C11: =SUMIFS(ENTRADAS!$E$7:$E$57,ENTRADAS!$B$7:$B$57,">=" & B11,ENTRADAS!$B$7:$B$57,"<" & EDATE($B$7,A11),ENTRADAS!$C$7:$C$57,$C$2) -> 0 | D11: =SUMIFS('SAÍDAS'!$H$7:$H$76,'SAÍDAS'!$B$7:$B$76,">=" & B11,'SAÍDAS'!$B$7:$B$76,"<" & EDATE($B$7,A11),'SAÍDAS'!$C$7:$C$76,$C$2) -> 0
A12: 6 | B12: =DATE($F$4,A12,1) -> Jun-21 | C12: =SUMIFS(ENTRADAS!$E$7:$E$57,ENTRADAS!$B$7:$B$57,">=" & B12,ENTRADAS!$B$7:$B$57,"<" & EDATE($B$7,A12),ENTRADAS!$C$7:$C$57,$C$2) -> 0 | D12: =SUMIFS('SAÍDAS'!$H$7:$H$76,'SAÍDAS'!$B$7:$B$76,">=" & B12,'SAÍDAS'!$B$7:$B$76,"<" & EDATE($B$7,A12),'SAÍDAS'!$C$7:$C$76,$C$2) -> 0
A13: 7 | B13: =DATE($F$4,A13,1) -> Jul-21 | C13: =SUMIFS(ENTRADAS!$E$7:$E$57,ENTRADAS!$B$7:$B$57,">=" & B13,ENTRADAS!$B$7:$B$57,"<" & EDATE($B$7,A13),ENTRADAS!$C$7:$C$57,$C$2) -> 0 | D13: =SUMIFS('SAÍDAS'!$H$7:$H$76,'SAÍDAS'!$B$7:$B$76,">=" & B13,'SAÍDAS'!$B$7:$B$76,"<" & EDATE($B$7,A13),'SAÍDAS'!$C$7:$C$76,$C$2) -> 0
A14: 8 | B14: =DATE($F$4,A14,1) -> Aug-21 | C14: =SUMIFS(ENTRADAS!$E$7:$E$57,ENTRADAS!$B$7:$B$57,">=" & B14,ENTRADAS!$B$7:$B$57,"<" & EDATE($B$7,A14),ENTRADAS!$C$7:$C$57,$C$2) -> 0 | D14: =SUMIFS('SAÍDAS'!$H$7:$H$76,'SAÍDAS'!$B$7:$B$76,">=" & B14,'SAÍDAS'!$B$7:$B$76,"<" & EDATE($B$7,A14),'SAÍDAS'!$C$7:$C$76,$C$2) -> 0
A15: 9 | B15: =DATE($F$4,A15,1) -> Sep-21 | C15: =SUMIFS(ENTRADAS!$E$7:$E$57,ENTRADAS!$B$7:$B$57,">=" & B15,ENTRADAS!$B$7:$B$57,"<" & EDATE($B$7,A15),ENTRADAS!$C$7:$C$57,$C$2) -> 0 | D15: =SUMIFS('SAÍDAS'!$H$7:$H$76,'SAÍDAS'!$B$7:$B$76,">=" & B15,'SAÍDAS'!$B$7:$B$76,"<" & EDATE($B$7,A15),'SAÍDAS'!$C$7:$C$76,$C$2) -> 0
A16: 10 | B16: =DATE($F$4,A16,1) -> Oct-21 | C16: =SUMIFS(ENTRADAS!$E$7:$E$57,ENTRADAS!$B$7:$B$57,">=" & B16,ENTRADAS!$B$7:$B$57,"<" & EDATE($B$7,A16),ENTRADAS!$C$7:$C$57,$C$2) -> 0 | D16: =SUMIFS('SAÍDAS'!$H$7:$H$76,'SAÍDAS'!$B$7:$B$76,">=" & B16,'SAÍDAS'!$B$7:$B$76,"<" & EDATE($B$7,A16),'SAÍDAS'!$C$7:$C$76,$C$2) -> 0
A17: 11 | B17: =DATE($F$4,A17,1) -> Nov-21 | C17: =SUMIFS(ENTRADAS!$E$7:$E$57,ENTRADAS!$B$7:$B$57,">=" & B17,ENTRADAS!$B$7:$B$57,"<" & EDATE($B$7,A17),ENTRADAS!$C$7:$C$57,$C$2) -> 0 | D17: =SUMIFS('SAÍDAS'!$H$7:$H$76,'SAÍDAS'!$B$7:$B$76,">=" & B17,'SAÍDAS'!$B$7:$B$76,"<" & EDATE($B$7,A17),'SAÍDAS'!$C$7:$C$76,$C$2) -> 0
A18: 12 | B18: =DATE($F$4,A18,1) -> Dec-21 | C18: =SUMIFS(ENTRADAS!$E$7:$E$57,ENTRADAS!$B$7:$B$57,">=" & B18,ENTRADAS!$B$7:$B$57,"<" & EDATE($B$7,A18),ENTRADAS!$C$7:$C$57,$C$2) -> 0 | D18: =SUMIFS('SAÍDAS'!$H$7:$H$76,'SAÍDAS'!$B$7:$B$76,">=" & B18,'SAÍDAS'!$B$7:$B$76,"<" & EDATE($B$7,A18),'SAÍDAS'!$C$7:$C$76,$C$2) -> 0
I20: ="Resultado de Compras X Vendas para o ano de " & F4 & CHAR(10) & "Valor em R$" -> Resultado de Compras X Vendas para o ano de 2021 Valor em R$
B21: R$ Entrada x Saída
B23: Mês | C23: Compras | D23: Vendas
A24: 1 | B24: =DATE($F$4,A24,1) -> Jan-21 | C24: =SUMIFS(ENTRADAS!$G$7:$G$57,ENTRADAS!$B$7:$B$57,">=" & B24,ENTRADAS!$B$7:$B$57,"<" & EDATE($B$7,A24),ENTRADAS!$C$7:$C$57,$C$2) -> R$ 43,305 | D24: =SUMIFS('SAÍDAS'!$K$7:$K$76,'SAÍDAS'!$B$7:$B$76,">=" & B24,'SAÍDAS'!$B$7:$B$76,"<" & EDATE($B$7,A24),'SAÍDAS'!$C$7:$C$76,$C$2) -> R$ -
A25: 2 | B25: =DATE($F$4,A25,1) -> Feb-21 | C25: =SUMIFS(ENTRADAS!$G$7:$G$57,ENTRADAS!$B$7:$B$57,">=" & B25,ENTRADAS!$B$7:$B$57,"<" & EDATE($B$7,A25),ENTRADAS!$C$7:$C$57,$C$2) -> R$ - | D25: =SUMIFS('SAÍDAS'!$K$7:$K$76,'SAÍDAS'!$B$7:$B$76,">=" & B25,'SAÍDAS'!$B$7:$B$76,"<" & EDATE($B$7,A25),'SAÍDAS'!$C$7:$C$76,$C$2) -> R$ -
A26: 3 | B26: =DATE($F$4,A26,1) -> Mar-21 | C26: =SUMIFS(ENTRADAS!$G$7:$G$57,ENTRADAS!$B$7:$B$57,">=" & B26,ENTRADAS!$B$7:$B$57,"<" & EDATE($B$7,A26),ENTRADAS!$C$7:$C$57,$C$2) -> R$ - | D26: =SUMIFS('SAÍDAS'!$K$7:$K$76,'SAÍDAS'!$B$7:$B$76,">=" & B26,'SAÍDAS'!$B$7:$B$76,"<" & EDATE($B$7,A26),'SAÍDAS'!$C$7:$C$76,$C$2) -> R$ -
A27: 4 | B27: =DATE($F$4,A27,1) -> Apr-21 | C27: =SUMIFS(ENTRADAS!$G$7:$G$57,ENTRADAS!$B$7:$B$57,">=" & B27,ENTRADAS!$B$7:$B$57,"<" & EDATE($B$7,A27),ENTRADAS!$C$7:$C$57,$C$2) -> R$ - | D27: =SUMIFS('SAÍDAS'!$K$7:$K$76,'SAÍDAS'!$B$7:$B$76,">=" & B27,'SAÍDAS'!$B$7:$B$76,"<" & EDATE($B$7,A27),'SAÍDAS'!$C$7:$C$76,$C$2) -> R$ -
A28: 5 | B28: =DATE($F$4,A28,1) -> May-21 | C28: =SUMIFS(ENTRADAS!$G$7:$G$57,ENTRADAS!$B$7:$B$57,">=" & B28,ENTRADAS!$B$7:$B$57,"<" & EDATE($B$7,A28),ENTRADAS!$C$7:$C$57,$C$2) -> R$ - | D28: =SUMIFS('SAÍDAS'!$K$7:$K$76,'SAÍDAS'!$B$7:$B$76,">=" & B28,'SAÍDAS'!$B$7:$B$76,"<" & EDATE($B$7,A28),'SAÍDAS'!$C$7:$C$76,$C$2) -> R$ -
A29: 6 | B29: =DATE($F$4,A29,1) -> Jun-21 | C29: =SUMIFS(ENTRADAS!$G$7:$G$57,ENTRADAS!$B$7:$B$57,">=" & B29,ENTRADAS!$B$7:$B$57,"<" & EDATE($B$7,A29),ENTRADAS!$C$7:$C$57,$C$2) -> R$ - | D29: =SUMIFS('SAÍDAS'!$K$7:$K$76,'SAÍDAS'!$B$7:$B$76,">=" & B29,'SAÍDAS'!$B$7:$B$76,"<" & EDATE($B$7,A29),'SAÍDAS'!$C$7:$C$76,$C$2) -> R$ -
A30: 7 | B30: =DATE($F$4,A30,1) -> Jul-21 | C30: =SUMIFS(ENTRADAS!$G$7:$G$57,ENTRADAS!$B$7:$B$57,">=" & B30,ENTRADAS!$B$7:$B$57,"<" & EDATE($B$7,A30),ENTRADAS!$C$7:$C$57,$C$2) -> R$ - | D30: =SUMIFS('SAÍDAS'!$K$7:$K$76,'SAÍDAS'!$B$7:$B$76,">=" & B30,'SAÍDAS'!$B$7:$B$76,"<" & EDATE($B$7,A30),'SAÍDAS'!$C$7:$C$76,$C$2) -> R$ -
A31: 8 | B31: =DATE($F$4,A31,1) -> Aug-21 | C31: =SUMIFS(ENTRADAS!$G$7:$G$57,ENTRADAS!$B$7:$B$57,">=" & B31,ENTRADAS!$B$7:$B$57,"<" & EDATE($B$7,A31),ENTRADAS!$C$7:$C$57,$C$2) -> R$ - | D31: =SUMIFS('SAÍDAS'!$K$7:$K$76,'SAÍDAS'!$B$7:$B$76,">=" & B31,'SAÍDAS'!$B$7:$B$76,"<" & EDATE($B$7,A31),'SAÍDAS'!$C$7:$C$76,$C$2) -> R$ -
A32: 9 | B32: =DATE($F$4,A32,1) -> Sep-21 | C32: =SUMIFS(ENTRADAS!$G$7:$G$57,ENTRADAS!$B$7:$B$57,">=" & B32,ENTRADAS!$B$7:$B$57,"<" & EDATE($B$7,A32),ENTRADAS!$C$7:$C$57,$C$2) -> R$ - | D32: =SUMIFS('SAÍDAS'!$K$7:$K$76,'SAÍDAS'!$B$7:$B$76,">=" & B32,'SAÍDAS'!$B$7:$B$76,"<" & EDATE($B$7,A32),'SAÍDAS'!$C$7:$C$76,$C$2) -> R$ -
A33: 10 | B33: =DATE($F$4,A33,1) -> Oct-21 | C33: =SUMIFS(ENTRADAS!$G$7:$G$57,ENTRADAS!$B$7:$B$57,">=" & B33,ENTRADAS!$B$7:$B$57,"<" & EDATE($B$7,A33),ENTRADAS!$C$7:$C$57,$C$2) -> R$ - | D33: =SUMIFS('SAÍDAS'!$K$7:$K$76,'SAÍDAS'!$B$7:$B$76,">=" & B33,'SAÍDAS'!$B$7:$B$76,"<" & EDATE($B$7,A33),'SAÍDAS'!$C$7:$C$76,$C$2) -> R$ -
A34: 11 | B34: =DATE($F$4,A34,1) -> Nov-21 | C34: =SUMIFS(ENTRADAS!$G$7:$G$57,ENTRADAS!$B$7:$B$57,">=" & B34,ENTRADAS!$B$7:$B$57,"<" & EDATE($B$7,A34),ENTRADAS!$C$7:$C$57,$C$2) -> R$ - | D34: =SUMIFS('SAÍDAS'!$K$7:$K$76,'SAÍDAS'!$B$7:$B$76,">=" & B34,'SAÍDAS'!$B$7:$B$76,"<" & EDATE($B$7,A34),'SAÍDAS'!$C$7:$C$76,$C$2) -> R$ -
A35: 12 | B35: =DATE($F$4,A35,1) -> Dec-21 | C35: =SUMIFS(ENTRADAS!$G$7:$G$57,ENTRADAS!$B$7:$B$57,">=" & B35,ENTRADAS!$B$7:$B$57,"<" & EDATE($B$7,A35),ENTRADAS!$C$7:$C$57,$C$2) -> R$ - | D35: =SUMIFS('SAÍDAS'!$K$7:$K$76,'SAÍDAS'!$B$7:$B$76,">=" & B35,'SAÍDAS'!$B$7:$B$76,"<" & EDATE($B$7,A35),'SAÍDAS'!$C$7:$C$76,$C$2) -> R$ -
B38: Produto | C38: ='DASH ESTOQUE'!C7 -> Biosfera Resistente
B40: Estoque no Tempo | E40: Ano | F40: ='DASH ESTOQUE'!C9 -> 2021 | I40: ="Saldo em Estoque para os meses do ano de " & F40 -> Saldo em Estoque para os meses do ano de 2021
B42: Mês | C42: Entrada Acumulada | D42: Saída Acumulada | E42: Saldo
A43: 1 | B43: =DATE($F$40,A43,1) -> Jan-21 | C43: =IF(AND(MONTH(B43)<=MONTH(MAX(ENTRADAS!$B$7:$B$57,'SAÍDAS'!$B$7:$B$76)),YEAR(B43)=YEAR(MAX(ENTRADAS!$B$7:$B$57,'SAÍDAS'!$B$7:$B$76))),SUMIFS(ENTRADAS!$E$7:$E$57,ENTRADAS!$B$7:$B$57,"<" & EDATE($B$43,A43),ENTRADAS!$C$7:$C$57,$C$38),0) -> 500 | D43: =IF(AND(MONTH(B43)<=MONTH(MAX(ENTRADAS!$B$7:$B$57,'SAÍDAS'!$B$7:$B$76)),YEAR(B43)=YEAR(MAX(ENTRADAS!$B$7:$B$57,'SAÍDAS'!$B$7:$B$76))),SUMIFS('SAÍDAS'!$H$7:$H$76,'SAÍDAS'!$B$7:$B$76,"<" & EDATE($B$43,A43),'SAÍDAS'!$C$7:$C$76,$C$38),0) -> 0 | E43: =IF(AND(C43=0,D43=0),-1E-30,C43-D43) -> 500
A44: 2 | B44: =DATE($F$40,A44,1) -> Feb-21 | C44: =IF(AND(MONTH(B44)<=MONTH(MAX(ENTRADAS!$B$7:$B$57,'SAÍDAS'!$B$7:$B$76)),YEAR(B44)=YEAR(MAX(ENTRADAS!$B$7:$B$57,'SAÍDAS'!$B$7:$B$76))),SUMIFS(ENTRADAS!$E$7:$E$57,ENTRADAS!$B$7:$B$57,"<" & EDATE($B$43,A44),ENTRADAS!$C$7:$C$57,$C$38),0) -> 0 | D44: =IF(AND(MONTH(B44)<=MONTH(MAX(ENTRADAS!$B$7:$B$57,'SAÍDAS'!$B$7:$B$76)),YEAR(B44)=YEAR(MAX(ENTRADAS!$B$7:$B$57,'SAÍDAS'!$B$7:$B$76))),SUMIFS('SAÍDAS'!$H$7:$H$76,'SAÍDAS'!$B$7:$B$76,"<" & EDATE($B$43,A44),'SAÍDAS'!$C$7:$C$76,$C$38),0) -> 0 | E44: =IF(AND(C44=0,D44=0),-1E-30,C44-D44) -> 0
A45: 3 | B45: =DATE($F$40,A45,1) -> Mar-21 | C45: =IF(AND(MONTH(B45)<=MONTH(MAX(ENTRADAS!$B$7:$B$57,'SAÍDAS'!$B$7:$B$76)),YEAR(B45)=YEAR(MAX(ENTRADAS!$B$7:$B$57,'SAÍDAS'!$B$7:$B$76))),SUMIFS(ENTRADAS!$E$7:$E$57,ENTRADAS!$B$7:$B$57,"<" & EDATE($B$43,A45),ENTRADAS!$C$7:$C$57,$C$38),0) -> 0 | D45: =IF(AND(MONTH(B45)<=MONTH(MAX(ENTRADAS!$B$7:$B$57,'SAÍDAS'!$B$7:$B$76)),YEAR(B45)=YEAR(MAX(ENTRADAS!$B$7:$B$57,'SAÍDAS'!$B$7:$B$76))),SUMIFS('SAÍDAS'!$H$7:$H$76,'SAÍDAS'!$B$7:$B$76,"<" & EDATE($B$43,A45),'SAÍDAS'!$C$7:$C$76,$C$38),0) -> 0 | E45: =IF(AND(C45=0,D45=0),-1E-30,C45-D45) -> 0
A46: 4 | B46: =DATE($F$40,A46,1) -> Apr-21 | C46: =IF(AND(MONTH(B46)<=MONTH(MAX(ENTRADAS!$B$7:$B$57,'SAÍDAS'!$B$7:$B$76)),YEAR(B46)=YEAR(MAX(ENTRADAS!$B$7:$B$57,'SAÍDAS'!$B$7:$B$76))),SUMIFS(ENTRADAS!$E$7:$E$57,ENTRADAS!$B$7:$B$57,"<" & EDATE($B$43,A46),ENTRADAS!$C$7:$C$57,$C$38),0) -> 0 | D46: =IF(AND(MONTH(B46)<=MONTH(MAX(ENTRADAS!$B$7:$B$57,'SAÍDAS'!$B$7:$B$76)),YEAR(B46)=YEAR(MAX(ENTRADAS!$B$7:$B$57,'SAÍDAS'!$B$7:$B$76))),SUMIFS('SAÍDAS'!$H$7:$H$76,'SAÍDAS'!$B$7:$B$76,"<" & EDATE($B$43,A46),'SAÍDAS'!$C$7:$C$76,$C$38),0) -> 0 | E46: =IF(AND(C46=0,D46=0),-1E-30,C46-D46) -> 0
A47: 5 | B47: =DATE($F$40,A47,1) -> May-21 | C47: =IF(AND(MONTH(B47)<=MONTH(MAX(ENTRADAS!$B$7:$B$57,'SAÍDAS'!$B$7:$B$76)),YEAR(B47)=YEAR(MAX(ENTRADAS!$B$7:$B$57,'SAÍDAS'!$B$7:$B$76))),SUMIFS(ENTRADAS!$E$7:$E$57,ENTRADAS!$B$7:$B$57,"<" & EDATE($B$43,A47),ENTRADAS!$C$7:$C$57,$C$38),0) -> 0 | D47: =IF(AND(MONTH(B47)<=MONTH(MAX(ENTRADAS!$B$7:$B$57,'SAÍDAS'!$B$7:$B$76)),YEAR(B47)=YEAR(MAX(ENTRADAS!$B$7:$B$57,'SAÍDAS'!$B$7:$B$76))),SUMIFS('SAÍDAS'!$H$7:$H$76,'SAÍDAS'!$B$7:$B$76,"<" & EDATE($B$43,A47),'SAÍDAS'!$C$7:$C$76,$C$38),0) -> 0 | E47: =IF(AND(C47=0,D47=0),-1E-30,C47-D47) -> 0
A48: 6 | B48: =DATE($F$40,A48,1) -> Jun-21 | C48: =IF(AND(MONTH(B48)<=MONTH(MAX(ENTRADAS!$B$7:$B$57,'SAÍDAS'!$B$7:$B$76)),YEAR(B48)=YEAR(MAX(ENTRADAS!$B$7:$B$57,'SAÍDAS'!$B$7:$B$76))),SUMIFS(ENTRADAS!$E$7:$E$57,ENTRADAS!$B$7:$B$57,"<" & EDATE($B$43,A48),ENTRADAS!$C$7:$C$57,$C$38),0) -> 0 | D48: =IF(AND(MONTH(B48)<=MONTH(MAX(ENTRADAS!$B$7:$B$57,'SAÍDAS'!$B$7:$B$76)),YEAR(B48)=YEAR(MAX(ENTRADAS!$B$7:$B$57,'SAÍDAS'!$B$7:$B$76))),SUMIFS('SAÍDAS'!$H$7:$H$76,'SAÍDAS'!$B$7:$B$76,"<" & EDATE($B$43,A48),'SAÍDAS'!$C$7:$C$76,$C$38),0) -> 0 | E48: =IF(AND(C48=0,D48=0),-1E-30,C48-D48) -> 0
A49: 7 | B49: =DATE($F$40,A49,1) -> Jul-21 | C49: =IF(AND(MONTH(B49)<=MONTH(MAX(ENTRADAS!$B$7:$B$57,'SAÍDAS'!$B$7:$B$76)),YEAR(B49)=YEAR(MAX(ENTRADAS!$B$7:$B$57,'SAÍDAS'!$B$7:$B$76))),SUMIFS(ENTRADAS!$E$7:$E$57,ENTRADAS!$B$7:$B$57,"<" & EDATE($B$43,A49),ENTRADAS!$C$7:$C$57,$C$38),0) -> 0 | D49: =IF(AND(MONTH(B49)<=MONTH(MAX(ENTRADAS!$B$7:$B$57,'SAÍDAS'!$B$7:$B$76)),YEAR(B49)=YEAR(MAX(ENTRADAS!$B$7:$B$57,'SAÍDAS'!$B$7:$B$76))),SUMIFS('SAÍDAS'!$H$7:$H$76,'SAÍDAS'!$B$7:$B$76,"<" & EDATE($B$43,A49),'SAÍDAS'!$C$7:$C$76,$C$38),0) -> 0 | E49: =IF(AND(C49=0,D49=0),-1E-30,C49-D49) -> 0
...
