Workbook

Sheet dadosgerais
A2: Custo Direto | B2: Custo Variável | F2: Custo Fixo
B4: Descrição | C4: Valor | F4: Descrição | G4: Valor
B5: Simples Nacional | C5: 4100 | F5: Folha de Pagamento | G5: 26000
B6: Materiais utilizados produção | C6: 1276.01 | F6: FGTS | G6: 2279.43
B7: Manutenções equipamentos | C7: 255 | F7: GPS | G7: 2183.72
B8: Energia Elétrica (proc. Fabricação) | C8: 2700 | F8: Previsão Férias | G8: 1930
F9: Previsão 13 Salário | G9: 1930
F10: Cesta Básica | G10: 1500
B25: Total Custos Variável Direto | C25: =SUM(C5:C24) -> 8331.01 | F25: Total Custo Fixo Direto | G25: =SUM(G5:G24) -> 35823.15
A28: Custo Indireto | B28: Energia Elétrica (administrativo) | C28: 200 | F28: IPTU | G28: 146.71
B29: Água | C29: 126.82 | F29: Aluguel | G29: 5500
B30: Telefonia | C30: 767.34 | F30: Seguros | G30: 505.82
B31: Convênios | C31: 3920.85 | F31: Pró – Labore | G31: 0
B32: Salários e despesas comerciais | C32: 0 | F32: Salários Administrativos | G32: 1500
B43: Total Custo Variável Indireto | C43: =SUM(C28:C42) -> 5015.01 | F43: Total Custo Fixo Indireto | G43: =SUM(G28:G42) -> 7652.53
B47: Total Geral | C47: =C25+C43+G25+G43 -> 56821.7

Sheet calculocusto
A1: Características do produto | E1: Resumo Custos / Despesas da Empresa
A2: Identificação do produto | B2: Valvulado
E3: Total Folha Pagamento (Produção) – Custo Dir. Fixo | J3: =(dadosgerais!G25)-J4 -> 34323.15
A4: Matéria-prima / peça | B4: =Dados!I14 -> 1.6 | E4: Total Folha Pagamento (Administrativo/apoio) | J4: =dadosgerais!G31+dadosgerais!G32 -> 1500
A5: Materiais auxiliares / peça | B5: =Dados!I15 -> 0.18 | E5: Depreciações | J5: 360
A6: Peças produzidas por hora /por funcionário | B6: 47 | E6: Salários e despesas comerciais | J6: =dadosgerais!C32 -> 0
A7: Qtde. Funcionários envolvidos | B7: 32 | E7: Custo Direto Variável | J7: =dadosgerais!C25 -> 8331.01
A8: Tempo produção (em minutos) por unidade | B8: =1/B16 -> 0.039893617 | E8: Custo Indireto Fixo | J8: =(dadosgerais!G43)-J4 -> 6152.53
A9: Tempo produção (em horas) por unidade | B9: =B8/60 -> 0.00066489362 | E9: Custo Indireto Variável | J9: =dadosgerais!C43 -> 5015.01
A10: Custo (MOD) /funcionário / hora | B10: =Dados!I12 -> 4.9
A11: Número total de funcionários | B11: =Dados!I9 -> 40 | E11: Produção e Tempo Real (Utilizado para Cálculo)
A12: Total de peças por hora | B12: =B7*B6 -> 1504 | E12: Total de peças produzidas por mês | J12: =Dados!I7 -> 710
A13: Total de peças produzidas por dia | B13: =B12*7 -> 10528 | E13: Total de funcionários envolvidos | J13: =Dados!I8 -> 1
A14: Total de peças produzidas por semana | B14: =B13*5 -> 52640 | E14: Total de peças produzidas por semana | J14: =J12/4.5 -> 157.77778
A15: Produção estimada mensal do produto | B15: =B14*4.5 -> 236880 | E15: Total de peças produzidas por dia | J15: =J14/5 -> 31.555556
A16: Peças produzidas por minuto | B16: =B12/60 -> 25.066667 | E16: Total de peças produzidas por hora | J16: =J15/7 -> 4.5079365
A17: Diferença entre cap. Produtiva e produção | B17: =B15-B22 -> 236170 | E17: Quantidade produzida por funcionário | J17: =J16/J13 -> 4.5079365
E18: Peças produzidas por minuto | J18: =J16/60 -> 0.075132275
A19: Dados Gerais sobre o produto | E19: Tempo produção (em minutos) por unidade | J19: =1/J18 -> 13.309859
A20: Comissão paga sobre venda | B20: =Dados!I10 -> 0.05 | E20: Tempo produção (em horas) por unidade | J20: =J19/60 -> 0.22183099
A21: Preço de venda | B21: =Dados!I11 -> 5 | E21: Tempo total de produção | J21: =(J20*B22)*J13 -> 157.5
A22: Quantidade produzida/mês/produto | B22: =J12 -> 710
A23: Quantidade total da produção mensal | B23: =Dados!I13 -> 150000
A24: Total de horas trabalho/mês | B24: =B11*220 -> 8800
A25: Total da receita mensal da empresa | B25: =Faturamento!C47 -> 77092.04
A28: Cálculos do Custo
A29: Horas diretas | B29: =J21 -> 157.5 | C29: (Quantidade de peças produzidas por mês * tempo para produção/peça)
A30: % da utilização da produção | B30: =B29/B24 -> 0.017897727 | C30: (Tempo total da linha de produção utilizado para produzir o produto)
A31: Salários e despesas de apoio (s) (C.Fixo) | B31: =J3*B30 -> 614.30638 | C31: (Total dos salários dos departamentos de apoio à produção empenhados no produto)
A32: Depreciações (d) | B32: =J5*B30 -> 6.4431818 | C32: (Total das depreciações pela % produzida do produto)
A33: Total (s + d) | B33: =B31+B32 -> 620.74956 | C33: (Total de salários + depreciações)
A34: Preço por unidade (Custo Direto Fabr.- Fixo) | B34: =B33/B22 -> 0.87429515 | C34: (Total do custo de produção / quantidade de peças produzidas)
A35: Custo Direto de Fabricação (Variável) (x) | B35: =J7*B30 -> 149.10614 | C35: (Custo direto de fabricação – CV* % utilização da produção)
A36: Custo Indireto de Fabricação (C. Fixo) (y) | B36: =J8*B30 -> 110.1163 | C36: (Custo indireto de fabricação – CF * % utilização da produção)
A37: Custo Indireto de Fabricação (C. Variável) (z) | B37: =J9*B30 -> 89.757281 | C37: (Custo indireto de fabricação – CV * % utilização da produção)
A38: Somatória | B38: =SUM(B35:B37) -> 348.97973 | C38: (Somatória X + Y + Z)
A39: Custo variável por unidade | B39: =B38/B22 -> 0.49152075
A40: Receita total do produto | B40: =B22*B21 -> 3550 | C40: (Quantidade produzida do produto * valor de venda)
A41: Repres. Sobre faturamento do produto (%) | B41: =B40/B25 -> 0.046048853 | C41: (Expressa a representatividade do produto em relação ao faturamento total da empresa)
A42: Despesas Administrativas do produto | B42: =J4*B41 -> 69.073279 | C42: (Representatividade total das desp.adm. sobre o faturamento do produto)
...

Sheet Faturamento
A2: Faturamento Mensal | B2: Faturamento Mensal
B4: Descrição | C4: Documento | D4: Valor
B5: Exemplo | C5: 1 | D5: 77092.04
B47: Total Faturamento | C47: =SUM(D5:D46) -> 77092.04

Sheet Dados
A2: Cálculo Custo Produtos
A4: Informe os dados abaixo para obter o custo
A7: Total de peças produzidas no mês | I7: 710
A8: Número de Funcionários envolvidos | I8: 1
A9: Número total de funcionários da empresa | I9: 40
A10: Comissão sobre venda | I10: 0.05
A11: Preço de venda | I11: 5
A12: Custo hora de cada funcionário | I12: 4.9
A13: Quantidade de todos os produtos fabricados pela empresa no mês | I13: 150000
A14: Valor da matéria-prima (estimado por peça) | I14: 1.6
A15: Valor materiais auxiliares (estimado por peça) | I15: 0.18
A16: Percentual estimado de perdas na produção | I16: 0.01
A18: Resultados Obtidos
A20: Despesas de Produção (DP) | E20: Cálculo Perdas
A21: Custo (Mão de obra direta)/ peça (a) | B21: =calculocusto!B47 -> 0.0032579787 | E21: Custo total produção | G21: =C33 -> 3.3181902
A22: Custo direto de Fabricação/peça (b) | B22: =calculocusto!B48 -> 0.87429515 | E22: % perda | G22: =calculocusto!G48 -> 0.01
A23: Custo matéria-prima/peça (c) | B23: =calculocusto!B49 -> 1.6 | E23: Peças produzidas | G23: =calculocusto!G49 -> 710
A24: Custo variável por unidade | B24: =calculocusto!B50 -> 0.49152075 | E24: Est. Peças perdidas | G24: =calculocusto!G50 -> 7.1
A25: Custo Total (a+b+c) | B25: =calculocusto!B51 -> 2.9690739 | E25: Total perdas | G25: =calculocusto!G51 -> 1.2993
E26: Repres. Por peça | G26: =calculocusto!G52 -> 0.00183
A27: Despesas Operacionais (DO)
A28: Comissões (d) | B28: =calculocusto!B54 -> 0.25
A29: Administração/Comercial (e) | B29: =calculocusto!B55 -> 0.097286309
A30: Perdas produtivas | B30: =calculocusto!B56 -> 0.00183
A31: Total (d + e) | B31: =calculocusto!B57 -> 0.34911631
A33: Custo total de produção (DP + DO) / item | C33: =calculocusto!C59 -> 3.3181902
A36: Cálculo da Margem de Lucro do Produto
B37: Valor | C37: %
A38: Preço de venda | B38: =calculocusto!B66 -> 5 | C38: =calculocusto!C66 -> 1 | D38: (Valor da Venda = 100%)
A39: Custo Unitário | B39: =calculocusto!B67 -> 2.9690739 | C39: =calculocusto!C67 -> 0.59381478 | D39: (Custo unitário / preço venda = % representatividade do custo)
A40: Despesas Operacionais | B40: =calculocusto!B68 -> 0.34911631 | C40: =calculocusto!C68 -> 0.069823262 | D40: (Desp. Operacionais / preço venda = % representatividade das desp. Operacionais)
A41: = margem de lucro | B41: =calculocusto!B69 -> 1.6818098 | C41: =calculocusto!C69 -> 0.33636196 | D41: (Total do custo unitário (100%) - Total Despesas Operacionais = Lucro Real)

Sheet Planilha4
