Workbook

Sheet ANUAL
L2: INFORME O ANO DO ORÇAMENTO | P2: 2010
A4: <--- ÁREA DE IMPRESSÃO INICIA NA PRÓXIMA LINHA --->
A5: >> | B5: =P$2 -> 2010
C9: SALDO MENSAL POR CONTA
C11: CONTA | D11: DESCRIÇÃO | E11: SALDO
E12: Janeiro | F12: Fevereiro | G12: Março | H12: Abril | I12: Maio | J12: Junho | K12: Julho | L12: Agosto | M12: Setembro | N12: Outubro | O12: Novembro | P12: Dezembro
A13: 1 | D13: CONTA CORRENTE BANCO 1 | E13: =INDIRECT("M"&COLUMN()-4&"!G"&ROW()-4) -> 0 | F13: =INDIRECT("M"&COLUMN()-4&"!G"&ROW()-4) -> 0 | G13: =INDIRECT("M"&COLUMN()-4&"!G"&ROW()-4) -> 0 | H13: =INDIRECT("M"&COLUMN()-4&"!G"&ROW()-4) -> 0 | I13: =INDIRECT("M"&COLUMN()-4&"!G"&ROW()-4) -> 0 | J13: =INDIRECT("M"&COLUMN()-4&"!G"&ROW()-4) -> 0 | K13: =INDIRECT("M"&COLUMN()-4&"!G"&ROW()-4) -> 0 | L13: =INDIRECT("M"&COLUMN()-4&"!G"&ROW()-4) -> 0 | ... P13: =INDIRECT("M"&COLUMN()-4&"!G"&ROW()-4) -> 0
A14: =A13+1 -> 2 | C14: INV1 | D14: POUPANÇA BANCO 1 | E14: =INDIRECT("M"&COLUMN()-4&"!G"&ROW()-4) -> 0 | F14: =INDIRECT("M"&COLUMN()-4&"!G"&ROW()-4) -> 0 | G14: =INDIRECT("M"&COLUMN()-4&"!G"&ROW()-4) -> 0 | H14: =INDIRECT("M"&COLUMN()-4&"!G"&ROW()-4) -> 0 | I14: =INDIRECT("M"&COLUMN()-4&"!G"&ROW()-4) -> 0 | J14: =INDIRECT("M"&COLUMN()-4&"!G"&ROW()-4) -> 0 | K14: =INDIRECT("M"&COLUMN()-4&"!G"&ROW()-4) -> 0 | L14: =INDIRECT("M"&COLUMN()-4&"!G"&ROW()-4) -> 0 | ... P14: =INDIRECT("M"&COLUMN()-4&"!G"&ROW()-4) -> 0
A15: =A14+1 -> 3 | C15: DINH1 | D15: EM ESPÉCIE | E15: =INDIRECT("M"&COLUMN()-4&"!G"&ROW()-4) -> 0 | F15: =INDIRECT("M"&COLUMN()-4&"!G"&ROW()-4) -> 0 | G15: =INDIRECT("M"&COLUMN()-4&"!G"&ROW()-4) -> 0 | H15: =INDIRECT("M"&COLUMN()-4&"!G"&ROW()-4) -> 0 | I15: =INDIRECT("M"&COLUMN()-4&"!G"&ROW()-4) -> 0 | J15: =INDIRECT("M"&COLUMN()-4&"!G"&ROW()-4) -> 0 | K15: =INDIRECT("M"&COLUMN()-4&"!G"&ROW()-4) -> 0 | L15: =INDIRECT("M"&COLUMN()-4&"!G"&ROW()-4) -> 0 | ... P15: =INDIRECT("M"&COLUMN()-4&"!G"&ROW()-4) -> 0
A16: =A15+1 -> 4 | C16: CRED1 | D16: CARTÃO DE CRÉDITO 1 | E16: =INDIRECT("M"&COLUMN()-4&"!G"&ROW()-4) -> 0 | F16: =INDIRECT("M"&COLUMN()-4&"!G"&ROW()-4) -> 0 | G16: =INDIRECT("M"&COLUMN()-4&"!G"&ROW()-4) -> 0 | H16: =INDIRECT("M"&COLUMN()-4&"!G"&ROW()-4) -> 0 | I16: =INDIRECT("M"&COLUMN()-4&"!G"&ROW()-4) -> 0 | J16: =INDIRECT("M"&COLUMN()-4&"!G"&ROW()-4) -> 0 | K16: =INDIRECT("M"&COLUMN()-4&"!G"&ROW()-4) -> 0 | L16: =INDIRECT("M"&COLUMN()-4&"!G"&ROW()-4) -> 0 | ... P16: =INDIRECT("M"&COLUMN()-4&"!G"&ROW()-4) -> 0
A17: =A16+1 -> 5 | C17: --- | E17: =INDIRECT("M"&COLUMN()-4&"!G"&ROW()-4) -> 0 | F17: =INDIRECT("M"&COLUMN()-4&"!G"&ROW()-4) -> 0 | G17: =INDIRECT("M"&COLUMN()-4&"!G"&ROW()-4) -> 0 | H17: =INDIRECT("M"&COLUMN()-4&"!G"&ROW()-4) -> 0 | I17: =INDIRECT("M"&COLUMN()-4&"!G"&ROW()-4) -> 0 | J17: =INDIRECT("M"&COLUMN()-4&"!G"&ROW()-4) -> 0 | K17: =INDIRECT("M"&COLUMN()-4&"!G"&ROW()-4) -> 0 | L17: =INDIRECT("M"&COLUMN()-4&"!G"&ROW()-4) -> 0 | ... P17: =INDIRECT("M"&COLUMN()-4&"!G"&ROW()-4) -> 0
A18: =A17+1 -> 6 | C18: --- | E18: =INDIRECT("M"&COLUMN()-4&"!G"&ROW()-4) -> 0 | F18: =INDIRECT("M"&COLUMN()-4&"!G"&ROW()-4) -> 0 | G18: =INDIRECT("M"&COLUMN()-4&"!G"&ROW()-4) -> 0 | H18: =INDIRECT("M"&COLUMN()-4&"!G"&ROW()-4) -> 0 | I18: =INDIRECT("M"&COLUMN()-4&"!G"&ROW()-4) -> 0 | J18: =INDIRECT("M"&COLUMN()-4&"!G"&ROW()-4) -> 0 | K18: =INDIRECT("M"&COLUMN()-4&"!G"&ROW()-4) -> 0 | L18: =INDIRECT("M"&COLUMN()-4&"!G"&ROW()-4) -> 0 | ... P18: =INDIRECT("M"&COLUMN()-4&"!G"&ROW()-4) -> 0
A19: =A18+1 -> 7 | C19: --- | E19: =INDIRECT("M"&COLUMN()-4&"!G"&ROW()-4) -> 0 | F19: =INDIRECT("M"&COLUMN()-4&"!G"&ROW()-4) -> 0 | G19: =INDIRECT("M"&COLUMN()-4&"!G"&ROW()-4) -> 0 | H19: =INDIRECT("M"&COLUMN()-4&"!G"&ROW()-4) -> 0 | I19: =INDIRECT("M"&COLUMN()-4&"!G"&ROW()-4) -> 0 | J19: =INDIRECT("M"&COLUMN()-4&"!G"&ROW()-4) -> 0 | K19: =INDIRECT("M"&COLUMN()-4&"!G"&ROW()-4) -> 0 | L19: =INDIRECT("M"&COLUMN()-4&"!G"&ROW()-4) -> 0 | ... P19: =INDIRECT("M"&COLUMN()-4&"!G"&ROW()-4) -> 0
A20: =A19+1 -> 8 | C20: --- | E20: =INDIRECT("M"&COLUMN()-4&"!G"&ROW()-4) -> 0 | F20: =INDIRECT("M"&COLUMN()-4&"!G"&ROW()-4) -> 0 | G20: =INDIRECT("M"&COLUMN()-4&"!G"&ROW()-4) -> 0 | H20: =INDIRECT("M"&COLUMN()-4&"!G"&ROW()-4) -> 0 | I20: =INDIRECT("M"&COLUMN()-4&"!G"&ROW()-4) -> 0 | J20: =INDIRECT("M"&COLUMN()-4&"!G"&ROW()-4) -> 0 | K20: =INDIRECT("M"&COLUMN()-4&"!G"&ROW()-4) -> 0 | L20: =INDIRECT("M"&COLUMN()-4&"!G"&ROW()-4) -> 0 | ... P20: =INDIRECT("M"&COLUMN()-4&"!G"&ROW()-4) -> 0
A21: =A20+1 -> 9 | C21: --- | E21: =INDIRECT("M"&COLUMN()-4&"!G"&ROW()-4) -> 0 | F21: =INDIRECT("M"&COLUMN()-4&"!G"&ROW()-4) -> 0 | G21: =INDIRECT("M"&COLUMN()-4&"!G"&ROW()-4) -> 0 | H21: =INDIRECT("M"&COLUMN()-4&"!G"&ROW()-4) -> 0 | I21: =INDIRECT("M"&COLUMN()-4&"!G"&ROW()-4) -> 0 | J21: =INDIRECT("M"&COLUMN()-4&"!G"&ROW()-4) -> 0 | K21: =INDIRECT("M"&COLUMN()-4&"!G"&ROW()-4) -> 0 | L21: =INDIRECT("M"&COLUMN()-4&"!G"&ROW()-4) -> 0 | ... P21: =INDIRECT("M"&COLUMN()-4&"!G"&ROW()-4) -> 0
A22: =A21+1 -> 10 | C22: --- | E22: =INDIRECT("M"&COLUMN()-4&"!G"&ROW()-4) -> 0 | F22: =INDIRECT("M"&COLUMN()-4&"!G"&ROW()-4) -> 0 | G22: =INDIRECT("M"&COLUMN()-4&"!G"&ROW()-4) -> 0 | H22: =INDIRECT("M"&COLUMN()-4&"!G"&ROW()-4) -> 0 | I22: =INDIRECT("M"&COLUMN()-4&"!G"&ROW()-4) -> 0 | J22: =INDIRECT("M"&COLUMN()-4&"!G"&ROW()-4) -> 0 | K22: =INDIRECT("M"&COLUMN()-4&"!G"&ROW()-4) -> 0 | L22: =INDIRECT("M"&COLUMN()-4&"!G"&ROW()-4) -> 0 | ... P22: =INDIRECT("M"&COLUMN()-4&"!G"&ROW()-4) -> 0
A23: =A22+1 -> 11 | C23: --- | E23: =INDIRECT("M"&COLUMN()-4&"!G"&ROW()-4) -> 0 | F23: =INDIRECT("M"&COLUMN()-4&"!G"&ROW()-4) -> 0 | G23: =INDIRECT("M"&COLUMN()-4&"!G"&ROW()-4) -> 0 | H23: =INDIRECT("M"&COLUMN()-4&"!G"&ROW()-4) -> 0 | I23: =INDIRECT("M"&COLUMN()-4&"!G"&ROW()-4) -> 0 | J23: =INDIRECT("M"&COLUMN()-4&"!G"&ROW()-4) -> 0 | K23: =INDIRECT("M"&COLUMN()-4&"!G"&ROW()-4) -> 0 | L23: =INDIRECT("M"&COLUMN()-4&"!G"&ROW()-4) -> 0 | ... P23: =INDIRECT("M"&COLUMN()-4&"!G"&ROW()-4) -> 0
A24: =A23+1 -> 12 | C24: --- | E24: =INDIRECT("M"&COLUMN()-4&"!G"&ROW()-4) -> 0 | F24: =INDIRECT("M"&COLUMN()-4&"!G"&ROW()-4) -> 0 | G24: =INDIRECT("M"&COLUMN()-4&"!G"&ROW()-4) -> 0 | H24: =INDIRECT("M"&COLUMN()-4&"!G"&ROW()-4) -> 0 | I24: =INDIRECT("M"&COLUMN()-4&"!G"&ROW()-4) -> 0 | J24: =INDIRECT("M"&COLUMN()-4&"!G"&ROW()-4) -> 0 | K24: =INDIRECT("M"&COLUMN()-4&"!G"&ROW()-4) -> 0 | L24: =INDIRECT("M"&COLUMN()-4&"!G"&ROW()-4) -> 0 | ... P24: =INDIRECT("M"&COLUMN()-4&"!G"&ROW()-4) -> 0
B26: =IF($D$13<>"",$D$13&" ("&$C$13&")",$C$13) -> CONTA CORRENTE BANCO 1 () | F26: =IF($D$14<>"",$D$14&" ("&$C$14&")",$C$14) -> POUPANÇA BANCO 1 (INV1) | L26: =IF($D$15<>"",$D$15&" ("&$C$15&")",$C$15) -> EM ESPÉCIE (DINH1)
B46: =IF($D$16<>"",$D$16&" ("&$C$16&")",$C$16) -> CARTÃO DE CRÉDITO 1 (CRED1) | F46: =IF($D$17<>"",$D$17&" ("&$C$17&")",$C$17) -> --- | L46: =IF($D$18<>"",$D$18&" ("&$C$18&")",$C$18) -> ---
B67: =IF($D$19<>"",$D$19&" ("&$C$19&")",$C$19) -> --- | F67: =IF($D$20<>"",$D$20&" ("&$C$20&")",$C$20) -> --- | L67: =IF($D$21<>"",$D$21&" ("&$C$21&")",$C$21) -> ---
B88: =IF($D$22<>"",$D$22&" ("&$C$22&")",$C$22) -> --- | F88: =IF($D$23<>"",$D$23&" ("&$C$23&")",$C$23) -> --- | L88: =IF($D$24<>"",$D$24&" ("&$C$24&")",$C$24) -> ---
C111: HISTÓRICO DE SALDOS POR GRUPO
C113: GRUPO | D113: DESCRIÇÃO | E113: SALDO
E114: Janeiro | F114: Fevereiro | G114: Março | H114: Abril | I114: Maio | J114: Junho | K114: Julho | L114: Agosto | M114: Setembro | N114: Outubro | O114: Novembro | P114: Dezembro
A115: 1 | C115: CC | D115: CONTA CORRENTE | E115: =INDIRECT("M"&COLUMN()-4&"!G"&47+$A115-1) -> 0 | F115: =INDIRECT("M"&COLUMN()-4&"!G"&47+$A115-1) -> 0 | G115: =INDIRECT("M"&COLUMN()-4&"!G"&47+$A115-1) -> 0 | H115: =INDIRECT("M"&COLUMN()-4&"!G"&47+$A115-1) -> 0 | I115: =INDIRECT("M"&COLUMN()-4&"!G"&47+$A115-1) -> 0 | J115: =INDIRECT("M"&COLUMN()-4&"!G"&47+$A115-1) -> 0 | K115: =INDIRECT("M"&COLUMN()-4&"!G"&47+$A115-1) -> 0 | L115: =INDIRECT("M"&COLUMN()-4&"!G"&47+$A115-1) -> 0 | ... P115: =INDIRECT("M"&COLUMN()-4&"!G"&47+$A115-1) -> 0
A116: =A115+1 -> 2 | C116: INV | D116: APLICAÇÕES DE INVESTIMENTO | E116: =INDIRECT("M"&COLUMN()-4&"!G"&47+$A116-1) -> 0 | F116: =INDIRECT("M"&COLUMN()-4&"!G"&47+$A116-1) -> 0 | G116: =INDIRECT("M"&COLUMN()-4&"!G"&47+$A116-1) -> 0 | H116: =INDIRECT("M"&COLUMN()-4&"!G"&47+$A116-1) -> 0 | I116: =INDIRECT("M"&COLUMN()-4&"!G"&47+$A116-1) -> 0 | J116: =INDIRECT("M"&COLUMN()-4&"!G"&47+$A116-1) -> 0 | K116: =INDIRECT("M"&COLUMN()-4&"!G"&47+$A116-1) -> 0 | L116: =INDIRECT("M"&COLUMN()-4&"!G"&47+$A116-1) -> 0 | ... P116: =INDIRECT("M"&COLUMN()-4&"!G"&47+$A116-1) -> 0
A117: =A116+1 -> 3 | C117: DINH | D117: EM ESPÉCIE | E117: =INDIRECT("M"&COLUMN()-4&"!G"&47+$A117-1) -> 0 | F117: =INDIRECT("M"&COLUMN()-4&"!G"&47+$A117-1) -> 0 | G117: =INDIRECT("M"&COLUMN()-4&"!G"&47+$A117-1) -> 0 | H117: =INDIRECT("M"&COLUMN()-4&"!G"&47+$A117-1) -> 0 | I117: =INDIRECT("M"&COLUMN()-4&"!G"&47+$A117-1) -> 0 | J117: =INDIRECT("M"&COLUMN()-4&"!G"&47+$A117-1) -> 0 | K117: =INDIRECT("M"&COLUMN()-4&"!G"&47+$A117-1) -> 0 | L117: =INDIRECT("M"&COLUMN()-4&"!G"&47+$A117-1) -> 0 | ... P117: =INDIRECT("M"&COLUMN()-4&"!G"&47+$A117-1) -> 0
B119: =IF($D$115<>"",$D$115&" ("&$C$115&")",$C$115) -> CONTA CORRENTE (CC) | F119: =IF($D$116<>"",$D$116&" ("&$C$116&")",$C$116) -> APLICAÇÕES DE INVESTIMENTO (INV) | L119: =IF($D$117<>"",$D$117&" ("&$C$117&")",$C$117) -> EM ESPÉCIE (DINH)
A133: >> | B133: =P$2 -> 2010
C137: ACOMPANHAMENTO DE DESPESAS
C139: CÓDIGO | D139: DESCRIÇÃO | E139: 1º TRIMESTRE | H139: 2º TRIMESTRE | K139: 3º TRIMESTRE | N139: 4º TRIMESTRE
E140: Janeiro | F140: Fevereiro | G140: Março | H140: Abril | I140: Maio | J140: Junho | K140: Julho | L140: Agosto | M140: Setembro | N140: Outubro | O140: Novembro | P140: Dezembro
A141: 1 | C141: M01 | D141: MORADIA – CONDOMÍNIO | E141: =INDIRECT("M"&COLUMN()-4&"!G"&ROW('M1'!$G57)) -> 0 | F141: =INDIRECT("M"&COLUMN()-4&"!G"&ROW('M1'!$G57)) -> 0 | G141: =INDIRECT("M"&COLUMN()-4&"!G"&ROW('M1'!$G57)) -> 0 | H141: =INDIRECT("M"&COLUMN()-4&"!G"&ROW('M1'!$G57)) -> 0 | I141: =INDIRECT("M"&COLUMN()-4&"!G"&ROW('M1'!$G57)) -> 0 | J141: =INDIRECT("M"&COLUMN()-4&"!G"&ROW('M1'!$G57)) -> 0 | K141: =INDIRECT("M"&COLUMN()-4&"!G"&ROW('M1'!$G57)) -> 0 | L141: =INDIRECT("M"&COLUMN()-4&"!G"&ROW('M1'!$G57)) -> 0 | ... P141: =INDIRECT("M"&COLUMN()-4&"!G"&ROW('M1'!$G57)) -> 0 | R141: =SUM(E141:P141) -> 0
A142: 2 | C142: M02 | D142: MORADIA – IPTU | E142: =INDIRECT("M"&COLUMN()-4&"!G"&ROW('M1'!$G58)) -> 0 | F142: =INDIRECT("M"&COLUMN()-4&"!G"&ROW('M1'!$G58)) -> 0 | G142: =INDIRECT("M"&COLUMN()-4&"!G"&ROW('M1'!$G58)) -> 0 | H142: =INDIRECT("M"&COLUMN()-4&"!G"&ROW('M1'!$G58)) -> 0 | I142: =INDIRECT("M"&COLUMN()-4&"!G"&ROW('M1'!$G58)) -> 0 | J142: =INDIRECT("M"&COLUMN()-4&"!G"&ROW('M1'!$G58)) -> 0 | K142: =INDIRECT("M"&COLUMN()-4&"!G"&ROW('M1'!$G58)) -> 0 | L142: =INDIRECT("M"&COLUMN()-4&"!G"&ROW('M1'!$G58)) -> 0 | ... P142: =INDIRECT("M"&COLUMN()-4&"!G"&ROW('M1'!$G58)) -> 0 | R142: =SUM(E142:P142) -> 0
A143: 3 | C143: M03 | D143: MORADIA – ALUGUEL | E143: =INDIRECT("M"&COLUMN()-4&"!G"&ROW('M1'!$G59)) -> 0 | F143: =INDIRECT("M"&COLUMN()-4&"!G"&ROW('M1'!$G59)) -> 0 | G143: =INDIRECT("M"&COLUMN()-4&"!G"&ROW('M1'!$G59)) -> 0 | H143: =INDIRECT("M"&COLUMN()-4&"!G"&ROW('M1'!$G59)) -> 0 | I143: =INDIRECT("M"&COLUMN()-4&"!G"&ROW('M1'!$G59)) -> 0 | J143: =INDIRECT("M"&COLUMN()-4&"!G"&ROW('M1'!$G59)) -> 0 | K143: =INDIRECT("M"&COLUMN()-4&"!G"&ROW('M1'!$G59)) -> 0 | L143: =INDIRECT("M"&COLUMN()-4&"!G"&ROW('M1'!$G59)) -> 0 | ... P143: =INDIRECT("M"&COLUMN()-4&"!G"&ROW('M1'!$G59)) -> 0 | R143: =SUM(E143:P143) -> 0
A144: 4 | C144: M04 | D144: MORADIA – REFORMA | E144: =INDIRECT("M"&COLUMN()-4&"!G"&ROW('M1'!$G60)) -> 0 | F144: =INDIRECT("M"&COLUMN()-4&"!G"&ROW('M1'!$G60)) -> 0 | G144: =INDIRECT("M"&COLUMN()-4&"!G"&ROW('M1'!$G60)) -> 0 | H144: =INDIRECT("M"&COLUMN()-4&"!G"&ROW('M1'!$G60)) -> 0 | I144: =INDIRECT("M"&COLUMN()-4&"!G"&ROW('M1'!$G60)) -> 0 | J144: =INDIRECT("M"&COLUMN()-4&"!G"&ROW('M1'!$G60)) -> 0 | K144: =INDIRECT("M"&COLUMN()-4&"!G"&ROW('M1'!$G60)) -> 0 | L144: =INDIRECT("M"&COLUMN()-4&"!G"&ROW('M1'!$G60)) -> 0 | ... P144: =INDIRECT("M"&COLUMN()-4&"!G"&ROW('M1'!$G60)) -> 0 | R144: =SUM(E144:P144) -> 0
A145: 5 | C145: U01 | D145: UTILITIES – ENERGIA ELÉTRICA | E145: =INDIRECT("M"&COLUMN()-4&"!G"&ROW('M1'!$G61)) -> 0 | F145: =INDIRECT("M"&COLUMN()-4&"!G"&ROW('M1'!$G61)) -> 0 | G145: =INDIRECT("M"&COLUMN()-4&"!G"&ROW('M1'!$G61)) -> 0 | H145: =INDIRECT("M"&COLUMN()-4&"!G"&ROW('M1'!$G61)) -> 0 | I145: =INDIRECT("M"&COLUMN()-4&"!G"&ROW('M1'!$G61)) -> 0 | J145: =INDIRECT("M"&COLUMN()-4&"!G"&ROW('M1'!$G61)) -> 0 | K145: =INDIRECT("M"&COLUMN()-4&"!G"&ROW('M1'!$G61)) -> 0 | L145: =INDIRECT("M"&COLUMN()-4&"!G"&ROW('M1'!$G61)) -> 0 | ... P145: =INDIRECT("M"&COLUMN()-4&"!G"&ROW('M1'!$G61)) -> 0 | R145: =SUM(E145:P145) -> 0
A146: 6 | C146: U02 | D146: UTILITIES – ÁGUA POTÁVEL | E146: =INDIRECT("M"&COLUMN()-4&"!G"&ROW('M1'!$G62)) -> 0 | F146: =INDIRECT("M"&COLUMN()-4&"!G"&ROW('M1'!$G62)) -> 0 | G146: =INDIRECT("M"&COLUMN()-4&"!G"&ROW('M1'!$G62)) -> 0 | H146: =INDIRECT("M"&COLUMN()-4&"!G"&ROW('M1'!$G62)) -> 0 | I146: =INDIRECT("M"&COLUMN()-4&"!G"&ROW('M1'!$G62)) -> 0 | J146: =INDIRECT("M"&COLUMN()-4&"!G"&ROW('M1'!$G62)) -> 0 | K146: =INDIRECT("M"&COLUMN()-4&"!G"&ROW('M1'!$G62)) -> 0 | L146: =INDIRECT("M"&COLUMN()-4&"!G"&ROW('M1'!$G62)) -> 0 | ... P146: =INDIRECT("M"&COLUMN()-4&"!G"&ROW('M1'!$G62)) -> 0 | R146: =SUM(E146:P146) -> 0
A147: 7 | C147: U03 | D147: UTILITIES – DIVERSOS (ÁGUA, GÁS, SERV. GERAIS) | E147: =INDIRECT("M"&COLUMN()-4&"!G"&ROW('M1'!$G63)) -> 0 | F147: =INDIRECT("M"&COLUMN()-4&"!G"&ROW('M1'!$G63)) -> 0 | G147: =INDIRECT("M"&COLUMN()-4&"!G"&ROW('M1'!$G63)) -> 0 | H147: =INDIRECT("M"&COLUMN()-4&"!G"&ROW('M1'!$G63)) -> 0 | I147: =INDIRECT("M"&COLUMN()-4&"!G"&ROW('M1'!$G63)) -> 0 | J147: =INDIRECT("M"&COLUMN()-4&"!G"&ROW('M1'!$G63)) -> 0 | K147: =INDIRECT("M"&COLUMN()-4&"!G"&ROW('M1'!$G63)) -> 0 | L147: =INDIRECT("M"&COLUMN()-4&"!G"&ROW('M1'!$G63)) -> 0 | ... P147: =INDIRECT("M"&COLUMN()-4&"!G"&ROW('M1'!$G63)) -> 0 | R147: =SUM(E147:P147) -> 0
...

Sheet M1
B1: =DATE(ANUAL!B5,B2,8) -> 40186 | I1: >> | M1: << | W1: >> | AL1: <<
B2: 1
C5: LISTA DE CONTAS | P5: MOVIMENTAÇÕES DO MÊS
C7: CONTA | D7: DESCRIÇÃO | E7: SALDO | P7: DATA | Q7: DESCRIÇÃO | R7: TRANFERÊNCIAS | T7: VALOR | U7: CODIGO
E8: ANTERIOR | F8: ATUAL | G8: PREVISTO | P8: DATA | Q8: DESCRIÇÃO | R8: SAÍDA | S8: ENTRADA | T8: VALOR | U8: TIPO | X8: ATUAL | Z8: =$C$9 | AA8: =$C$10 -> INV1 | AB8: =$C$11 -> DINH1 | AC8: =$C$12 -> CRED1 | AD8: =$C$13 -> --- | AE8: =$C$14 -> --- | AF8: =$C$15 -> --- | AG8: =$C$16 -> --- | AH8: =$C$17 -> --- | AI8: =$C$18 -> --- | AJ8: =$C$19 -> --- | AK8: =$C$20 -> ---
A9: 1 | C9: =TRIM(ANUAL!C13) | D9: =TRIM(ANUAL!D13) -> CONTA CORRENTE BANCO 1 | E9: 0 | F9: =E9+SUMIF(X$9:X$88,1,OFFSET($Z$9:$Z$88,0,A9-1)) -> 0 | G9: =E9+SUM(OFFSET($Z$9:$Z$88,0,A9-1)) -> 0 | J9: =NOT(ISERR(SEARCH(J$27,$C9))) -> FALSE | K9: =NOT(ISERR(SEARCH(K$27,$C9))) -> FALSE | L9: =NOT(ISERR(SEARCH(L$27,$C9))) -> FALSE | N9: 1 | X9: =IF(P9<NOW(),1,0) -> 1 | Z9: =IF(Z$8=$R9,-$T9,0)+IF(Z$8=$S9,$T9,0) -> 0 | AA9: =IF(AA$8=$R9,-$T9,0)+IF(AA$8=$S9,$T9,0) -> 0 | AB9: =IF(AB$8=$R9,-$T9,0)+IF(AB$8=$S9,$T9,0) -> 0 | AC9: =IF(AC$8=$R9,-$T9,0)+IF(AC$8=$S9,$T9,0) -> 0 | AD9: =IF(AD$8=$R9,-$T9,0)+IF(AD$8=$S9,$T9,0) -> 0 | AE9: =IF(AE$8=$R9,-$T9,0)+IF(AE$8=$S9,$T9,0) -> 0 | AF9: =IF(AF$8=$R9,-$T9,0)+IF(AF$8=$S9,$T9,0) -> 0 | AG9: =IF(AG$8=$R9,-$T9,0)+IF(AG$8=$S9,$T9,0) -> 0 | ... AK9: =IF(AK$8=$R9,-$T9,0)+IF(AK$8=$S9,$T9,0) -> 0
A10: 2 | C10: =TRIM(ANUAL!C14) -> INV1 | D10: =TRIM(ANUAL!D14) -> POUPANÇA BANCO 1 | E10: 0 | F10: =E10+SUMIF(X$9:X$88,1,OFFSET($Z$9:$Z$88,0,A10-1)) -> 0 | G10: =E10+SUM(OFFSET($Z$9:$Z$88,0,A10-1)) -> 0 | J10: =NOT(ISERR(SEARCH(J$27,$C10))) -> FALSE | K10: =NOT(ISERR(SEARCH(K$27,$C10))) -> TRUE | L10: =NOT(ISERR(SEARCH(L$27,$C10))) -> FALSE | N10: 2 | X10: =IF(P10<NOW(),1,0) -> 1 | Z10: =IF(Z$8=$R10,-$T10,0)+IF(Z$8=$S10,$T10,0) -> 0 | AA10: =IF(AA$8=$R10,-$T10,0)+IF(AA$8=$S10,$T10,0) -> 0 | AB10: =IF(AB$8=$R10,-$T10,0)+IF(AB$8=$S10,$T10,0) -> 0 | AC10: =IF(AC$8=$R10,-$T10,0)+IF(AC$8=$S10,$T10,0) -> 0 | AD10: =IF(AD$8=$R10,-$T10,0)+IF(AD$8=$S10,$T10,0) -> 0 | AE10: =IF(AE$8=$R10,-$T10,0)+IF(AE$8=$S10,$T10,0) -> 0 | AF10: =IF(AF$8=$R10,-$T10,0)+IF(AF$8=$S10,$T10,0) -> 0 | AG10: =IF(AG$8=$R10,-$T10,0)+IF(AG$8=$S10,$T10,0) -> 0 | ... AK10: =IF(AK$8=$R10,-$T10,0)+IF(AK$8=$S10,$T10,0) -> 0
A11: 3 | C11: =TRIM(ANUAL!C15) -> DINH1 | D11: =TRIM(ANUAL!D15) -> EM ESPÉCIE | E11: 0 | F11: =E11+SUMIF(X$9:X$88,1,OFFSET($Z$9:$Z$88,0,A11-1)) -> 0 | G11: =E11+SUM(OFFSET($Z$9:$Z$88,0,A11-1)) -> 0 | J11: =NOT(ISERR(SEARCH(J$27,$C11))) -> FALSE | K11: =NOT(ISERR(SEARCH(K$27,$C11))) -> FALSE | L11: =NOT(ISERR(SEARCH(L$27,$C11))) -> TRUE | N11: 3 | X11: =IF(P11<NOW(),1,0) -> 1 | Z11: =IF(Z$8=$R11,-$T11,0)+IF(Z$8=$S11,$T11,0) -> 0 | AA11: =IF(AA$8=$R11,-$T11,0)+IF(AA$8=$S11,$T11,0) -> 0 | AB11: =IF(AB$8=$R11,-$T11,0)+IF(AB$8=$S11,$T11,0) -> 0 | AC11: =IF(AC$8=$R11,-$T11,0)+IF(AC$8=$S11,$T11,0) -> 0 | AD11: =IF(AD$8=$R11,-$T11,0)+IF(AD$8=$S11,$T11,0) -> 0 | AE11: =IF(AE$8=$R11,-$T11,0)+IF(AE$8=$S11,$T11,0) -> 0 | AF11: =IF(AF$8=$R11,-$T11,0)+IF(AF$8=$S11,$T11,0) -> 0 | AG11: =IF(AG$8=$R11,-$T11,0)+IF(AG$8=$S11,$T11,0) -> 0 | ... AK11: =IF(AK$8=$R11,-$T11,0)+IF(AK$8=$S11,$T11,0) -> 0
A12: 4 | C12: =TRIM(ANUAL!C16) -> CRED1 | D12: =TRIM(ANUAL!D16) -> CARTÃO DE CRÉDITO 1 | E12: 0 | F12: =E12+SUMIF(X$9:X$88,1,OFFSET($Z$9:$Z$88,0,A12-1)) -> 0 | G12: =E12+SUM(OFFSET($Z$9:$Z$88,0,A12-1)) -> 0 | J12: =NOT(ISERR(SEARCH(J$27,$C12))) -> FALSE | K12: =NOT(ISERR(SEARCH(K$27,$C12))) -> FALSE | L12: =NOT(ISERR(SEARCH(L$27,$C12))) -> FALSE | N12: 4 | X12: =IF(P12<NOW(),1,0) -> 1 | Z12: =IF(Z$8=$R12,-$T12,0)+IF(Z$8=$S12,$T12,0) -> 0 | AA12: =IF(AA$8=$R12,-$T12,0)+IF(AA$8=$S12,$T12,0) -> 0 | AB12: =IF(AB$8=$R12,-$T12,0)+IF(AB$8=$S12,$T12,0) -> 0 | AC12: =IF(AC$8=$R12,-$T12,0)+IF(AC$8=$S12,$T12,0) -> 0 | AD12: =IF(AD$8=$R12,-$T12,0)+IF(AD$8=$S12,$T12,0) -> 0 | AE12: =IF(AE$8=$R12,-$T12,0)+IF(AE$8=$S12,$T12,0) -> 0 | AF12: =IF(AF$8=$R12,-$T12,0)+IF(AF$8=$S12,$T12,0) -> 0 | AG12: =IF(AG$8=$R12,-$T12,0)+IF(AG$8=$S12,$T12,0) -> 0 | ... AK12: =IF(AK$8=$R12,-$T12,0)+IF(AK$8=$S12,$T12,0) -> 0
A13: 5 | C13: =TRIM(ANUAL!C17) -> --- | D13: =TRIM(ANUAL!D17) | E13: 0 | F13: =E13+SUMIF(X$9:X$88,1,OFFSET($Z$9:$Z$88,0,A13-1)) -> 0 | G13: =E13+SUM(OFFSET($Z$9:$Z$88,0,A13-1)) -> 0 | J13: =NOT(ISERR(SEARCH(J$27,$C13))) -> FALSE | K13: =NOT(ISERR(SEARCH(K$27,$C13))) -> FALSE | L13: =NOT(ISERR(SEARCH(L$27,$C13))) -> FALSE | N13: 5 | X13: =IF(P13<NOW(),1,0) -> 1 | Z13: =IF(Z$8=$R13,-$T13,0)+IF(Z$8=$S13,$T13,0) -> 0 | AA13: =IF(AA$8=$R13,-$T13,0)+IF(AA$8=$S13,$T13,0) -> 0 | AB13: =IF(AB$8=$R13,-$T13,0)+IF(AB$8=$S13,$T13,0) -> 0 | AC13: =IF(AC$8=$R13,-$T13,0)+IF(AC$8=$S13,$T13,0) -> 0 | AD13: =IF(AD$8=$R13,-$T13,0)+IF(AD$8=$S13,$T13,0) -> 0 | AE13: =IF(AE$8=$R13,-$T13,0)+IF(AE$8=$S13,$T13,0) -> 0 | AF13: =IF(AF$8=$R13,-$T13,0)+IF(AF$8=$S13,$T13,0) -> 0 | AG13: =IF(AG$8=$R13,-$T13,0)+IF(AG$8=$S13,$T13,0) -> 0 | ... AK13: =IF(AK$8=$R13,-$T13,0)+IF(AK$8=$S13,$T13,0) -> 0
A14: 6 | C14: =TRIM(ANUAL!C18) -> --- | D14: =TRIM(ANUAL!D18) | E14: 0 | F14: =E14+SUMIF(X$9:X$88,1,OFFSET($Z$9:$Z$88,0,A14-1)) -> 0 | G14: =E14+SUM(OFFSET($Z$9:$Z$88,0,A14-1)) -> 0 | J14: =NOT(ISERR(SEARCH(J$27,$C14))) -> FALSE | K14: =NOT(ISERR(SEARCH(K$27,$C14))) -> FALSE | L14: =NOT(ISERR(SEARCH(L$27,$C14))) -> FALSE | N14: 6 | X14: =IF(P14<NOW(),1,0) -> 1 | Z14: =IF(Z$8=$R14,-$T14,0)+IF(Z$8=$S14,$T14,0) -> 0 | AA14: =IF(AA$8=$R14,-$T14,0)+IF(AA$8=$S14,$T14,0) -> 0 | AB14: =IF(AB$8=$R14,-$T14,0)+IF(AB$8=$S14,$T14,0) -> 0 | AC14: =IF(AC$8=$R14,-$T14,0)+IF(AC$8=$S14,$T14,0) -> 0 | AD14: =IF(AD$8=$R14,-$T14,0)+IF(AD$8=$S14,$T14,0) -> 0 | AE14: =IF(AE$8=$R14,-$T14,0)+IF(AE$8=$S14,$T14,0) -> 0 | AF14: =IF(AF$8=$R14,-$T14,0)+IF(AF$8=$S14,$T14,0) -> 0 | AG14: =IF(AG$8=$R14,-$T14,0)+IF(AG$8=$S14,$T14,0) -> 0 | ... AK14: =IF(AK$8=$R14,-$T14,0)+IF(AK$8=$S14,$T14,0) -> 0
A15: 7 | C15: =TRIM(ANUAL!C19) -> --- | D15: =TRIM(ANUAL!D19) | E15: 0 | F15: =E15+SUMIF(X$9:X$88,1,OFFSET($Z$9:$Z$88,0,A15-1)) -> 0 | G15: =E15+SUM(OFFSET($Z$9:$Z$88,0,A15-1)) -> 0 | J15: =NOT(ISERR(SEARCH(J$27,$C15))) -> FALSE | K15: =NOT(ISERR(SEARCH(K$27,$C15))) -> FALSE | L15: =NOT(ISERR(SEARCH(L$27,$C15))) -> FALSE | N15: 7 | X15: =IF(P15<NOW(),1,0) -> 1 | Z15: =IF(Z$8=$R15,-$T15,0)+IF(Z$8=$S15,$T15,0) -> 0 | AA15: =IF(AA$8=$R15,-$T15,0)+IF(AA$8=$S15,$T15,0) -> 0 | AB15: =IF(AB$8=$R15,-$T15,0)+IF(AB$8=$S15,$T15,0) -> 0 | AC15: =IF(AC$8=$R15,-$T15,0)+IF(AC$8=$S15,$T15,0) -> 0 | AD15: =IF(AD$8=$R15,-$T15,0)+IF(AD$8=$S15,$T15,0) -> 0 | AE15: =IF(AE$8=$R15,-$T15,0)+IF(AE$8=$S15,$T15,0) -> 0 | AF15: =IF(AF$8=$R15,-$T15,0)+IF(AF$8=$S15,$T15,0) -> 0 | AG15: =IF(AG$8=$R15,-$T15,0)+IF(AG$8=$S15,$T15,0) -> 0 | ... AK15: =IF(AK$8=$R15,-$T15,0)+IF(AK$8=$S15,$T15,0) -> 0
A16: 8 | C16: =TRIM(ANUAL!C20) -> --- | D16: =TRIM(ANUAL!D20) | E16: 0 | F16: =E16+SUMIF(X$9:X$88,1,OFFSET($Z$9:$Z$88,0,A16-1)) -> 0 | G16: =E16+SUM(OFFSET($Z$9:$Z$88,0,A16-1)) -> 0 | J16: =NOT(ISERR(SEARCH(J$27,$C16))) -> FALSE | K16: =NOT(ISERR(SEARCH(K$27,$C16))) -> FALSE | L16: =NOT(ISERR(SEARCH(L$27,$C16))) -> FALSE | N16: 8 | X16: =IF(P16<NOW(),1,0) -> 1 | Z16: =IF(Z$8=$R16,-$T16,0)+IF(Z$8=$S16,$T16,0) -> 0 | AA16: =IF(AA$8=$R16,-$T16,0)+IF(AA$8=$S16,$T16,0) -> 0 | AB16: =IF(AB$8=$R16,-$T16,0)+IF(AB$8=$S16,$T16,0) -> 0 | AC16: =IF(AC$8=$R16,-$T16,0)+IF(AC$8=$S16,$T16,0) -> 0 | AD16: =IF(AD$8=$R16,-$T16,0)+IF(AD$8=$S16,$T16,0) -> 0 | AE16: =IF(AE$8=$R16,-$T16,0)+IF(AE$8=$S16,$T16,0) -> 0 | AF16: =IF(AF$8=$R16,-$T16,0)+IF(AF$8=$S16,$T16,0) -> 0 | AG16: =IF(AG$8=$R16,-$T16,0)+IF(AG$8=$S16,$T16,0) -> 0 | ... AK16: =IF(AK$8=$R16,-$T16,0)+IF(AK$8=$S16,$T16,0) -> 0
A17: 9 | C17: =TRIM(ANUAL!C21) -> --- | D17: =TRIM(ANUAL!D21) | E17: 0 | F17: =E17+SUMIF(X$9:X$88,1,OFFSET($Z$9:$Z$88,0,A17-1)) -> 0 | G17: =E17+SUM(OFFSET($Z$9:$Z$88,0,A17-1)) -> 0 | J17: =NOT(ISERR(SEARCH(J$27,$C17))) -> FALSE | K17: =NOT(ISERR(SEARCH(K$27,$C17))) -> FALSE | L17: =NOT(ISERR(SEARCH(L$27,$C17))) -> FALSE | N17: 9 | X17: =IF(P17<NOW(),1,0) -> 1 | Z17: =IF(Z$8=$R17,-$T17,0)+IF(Z$8=$S17,$T17,0) -> 0 | AA17: =IF(AA$8=$R17,-$T17,0)+IF(AA$8=$S17,$T17,0) -> 0 | AB17: =IF(AB$8=$R17,-$T17,0)+IF(AB$8=$S17,$T17,0) -> 0 | AC17: =IF(AC$8=$R17,-$T17,0)+IF(AC$8=$S17,$T17,0) -> 0 | AD17: =IF(AD$8=$R17,-$T17,0)+IF(AD$8=$S17,$T17,0) -> 0 | AE17: =IF(AE$8=$R17,-$T17,0)+IF(AE$8=$S17,$T17,0) -> 0 | AF17: =IF(AF$8=$R17,-$T17,0)+IF(AF$8=$S17,$T17,0) -> 0 | AG17: =IF(AG$8=$R17,-$T17,0)+IF(AG$8=$S17,$T17,0) -> 0 | ... AK17: =IF(AK$8=$R17,-$T17,0)+IF(AK$8=$S17,$T17,0) -> 0
A18: 10 | C18: =TRIM(ANUAL!C22) -> --- | D18: =TRIM(ANUAL!D22) | E18: 0 | F18: =E18+SUMIF(X$9:X$88,1,OFFSET($Z$9:$Z$88,0,A18-1)) -> 0 | G18: =E18+SUM(OFFSET($Z$9:$Z$88,0,A18-1)) -> 0 | J18: =NOT(ISERR(SEARCH(J$27,$C18))) -> FALSE | K18: =NOT(ISERR(SEARCH(K$27,$C18))) -> FALSE | L18: =NOT(ISERR(SEARCH(L$27,$C18))) -> FALSE | N18: 10 | X18: =IF(P18<NOW(),1,0) -> 1 | Z18: =IF(Z$8=$R18,-$T18,0)+IF(Z$8=$S18,$T18,0) -> 0 | AA18: =IF(AA$8=$R18,-$T18,0)+IF(AA$8=$S18,$T18,0) -> 0 | AB18: =IF(AB$8=$R18,-$T18,0)+IF(AB$8=$S18,$T18,0) -> 0 | AC18: =IF(AC$8=$R18,-$T18,0)+IF(AC$8=$S18,$T18,0) -> 0 | AD18: =IF(AD$8=$R18,-$T18,0)+IF(AD$8=$S18,$T18,0) -> 0 | AE18: =IF(AE$8=$R18,-$T18,0)+IF(AE$8=$S18,$T18,0) -> 0 | AF18: =IF(AF$8=$R18,-$T18,0)+IF(AF$8=$S18,$T18,0) -> 0 | AG18: =IF(AG$8=$R18,-$T18,0)+IF(AG$8=$S18,$T18,0) -> 0 | ... AK18: =IF(AK$8=$R18,-$T18,0)+IF(AK$8=$S18,$T18,0) -> 0
A19: 11 | C19: =TRIM(ANUAL!C23) -> --- | D19: =TRIM(ANUAL!D23) | E19: 0 | F19: =E19+SUMIF(X$9:X$88,1,OFFSET($Z$9:$Z$88,0,A19-1)) -> 0 | G19: =E19+SUM(OFFSET($Z$9:$Z$88,0,A19-1)) -> 0 | J19: =NOT(ISERR(SEARCH(J$27,$C19))) -> FALSE | K19: =NOT(ISERR(SEARCH(K$27,$C19))) -> FALSE | L19: =NOT(ISERR(SEARCH(L$27,$C19))) -> FALSE | N19: 11 | X19: =IF(P19<NOW(),1,0) -> 1 | Z19: =IF(Z$8=$R19,-$T19,0)+IF(Z$8=$S19,$T19,0) -> 0 | AA19: =IF(AA$8=$R19,-$T19,0)+IF(AA$8=$S19,$T19,0) -> 0 | AB19: =IF(AB$8=$R19,-$T19,0)+IF(AB$8=$S19,$T19,0) -> 0 | AC19: =IF(AC$8=$R19,-$T19,0)+IF(AC$8=$S19,$T19,0) -> 0 | AD19: =IF(AD$8=$R19,-$T19,0)+IF(AD$8=$S19,$T19,0) -> 0 | AE19: =IF(AE$8=$R19,-$T19,0)+IF(AE$8=$S19,$T19,0) -> 0 | AF19: =IF(AF$8=$R19,-$T19,0)+IF(AF$8=$S19,$T19,0) -> 0 | AG19: =IF(AG$8=$R19,-$T19,0)+IF(AG$8=$S19,$T19,0) -> 0 | ... AK19: =IF(AK$8=$R19,-$T19,0)+IF(AK$8=$S19,$T19,0) -> 0
A20: 12 | C20: =TRIM(ANUAL!C24) -> --- | D20: =TRIM(ANUAL!D24) | E20: 0 | F20: =E20+SUMIF(X$9:X$88,1,OFFSET($Z$9:$Z$88,0,A20-1)) -> 0 | G20: =E20+SUM(OFFSET($Z$9:$Z$88,0,A20-1)) -> 0 | J20: =NOT(ISERR(SEARCH(J$27,$C20))) -> FALSE | K20: =NOT(ISERR(SEARCH(K$27,$C20))) -> FALSE | L20: =NOT(ISERR(SEARCH(L$27,$C20))) -> FALSE | N20: 12 | X20: =IF(P20<NOW(),1,0) -> 1 | Z20: =IF(Z$8=$R20,-$T20,0)+IF(Z$8=$S20,$T20,0) -> 0 | AA20: =IF(AA$8=$R20,-$T20,0)+IF(AA$8=$S20,$T20,0) -> 0 | AB20: =IF(AB$8=$R20,-$T20,0)+IF(AB$8=$S20,$T20,0) -> 0 | AC20: =IF(AC$8=$R20,-$T20,0)+IF(AC$8=$S20,$T20,0) -> 0 | AD20: =IF(AD$8=$R20,-$T20,0)+IF(AD$8=$S20,$T20,0) -> 0 | AE20: =IF(AE$8=$R20,-$T20,0)+IF(AE$8=$S20,$T20,0) -> 0 | AF20: =IF(AF$8=$R20,-$T20,0)+IF(AF$8=$S20,$T20,0) -> 0 | AG20: =IF(AG$8=$R20,-$T20,0)+IF(AG$8=$S20,$T20,0) -> 0 | ... AK20: =IF(AK$8=$R20,-$T20,0)+IF(AK$8=$S20,$T20,0) -> 0
N21: 13 | X21: =IF(P21<NOW(),1,0) -> 1 | Z21: =IF(Z$8=$R21,-$T21,0)+IF(Z$8=$S21,$T21,0) -> 0 | AA21: =IF(AA$8=$R21,-$T21,0)+IF(AA$8=$S21,$T21,0) -> 0 | AB21: =IF(AB$8=$R21,-$T21,0)+IF(AB$8=$S21,$T21,0) -> 0 | AC21: =IF(AC$8=$R21,-$T21,0)+IF(AC$8=$S21,$T21,0) -> 0 | AD21: =IF(AD$8=$R21,-$T21,0)+IF(AD$8=$S21,$T21,0) -> 0 | AE21: =IF(AE$8=$R21,-$T21,0)+IF(AE$8=$S21,$T21,0) -> 0 | AF21: =IF(AF$8=$R21,-$T21,0)+IF(AF$8=$S21,$T21,0) -> 0 | AG21: =IF(AG$8=$R21,-$T21,0)+IF(AG$8=$S21,$T21,0) -> 0 | ... AK21: =IF(AK$8=$R21,-$T21,0)+IF(AK$8=$S21,$T21,0) -> 0
N22: 14 | X22: =IF(P22<NOW(),1,0) -> 1 | Z22: =IF(Z$8=$R22,-$T22,0)+IF(Z$8=$S22,$T22,0) -> 0 | AA22: =IF(AA$8=$R22,-$T22,0)+IF(AA$8=$S22,$T22,0) -> 0 | AB22: =IF(AB$8=$R22,-$T22,0)+IF(AB$8=$S22,$T22,0) -> 0 | AC22: =IF(AC$8=$R22,-$T22,0)+IF(AC$8=$S22,$T22,0) -> 0 | AD22: =IF(AD$8=$R22,-$T22,0)+IF(AD$8=$S22,$T22,0) -> 0 | AE22: =IF(AE$8=$R22,-$T22,0)+IF(AE$8=$S22,$T22,0) -> 0 | AF22: =IF(AF$8=$R22,-$T22,0)+IF(AF$8=$S22,$T22,0) -> 0 | AG22: =IF(AG$8=$R22,-$T22,0)+IF(AG$8=$S22,$T22,0) -> 0 | ... AK22: =IF(AK$8=$R22,-$T22,0)+IF(AK$8=$S22,$T22,0) -> 0
N23: 15 | X23: =IF(P23<NOW(),1,0) -> 1 | Z23: =IF(Z$8=$R23,-$T23,0)+IF(Z$8=$S23,$T23,0) -> 0 | AA23: =IF(AA$8=$R23,-$T23,0)+IF(AA$8=$S23,$T23,0) -> 0 | AB23: =IF(AB$8=$R23,-$T23,0)+IF(AB$8=$S23,$T23,0) -> 0 | AC23: =IF(AC$8=$R23,-$T23,0)+IF(AC$8=$S23,$T23,0) -> 0 | AD23: =IF(AD$8=$R23,-$T23,0)+IF(AD$8=$S23,$T23,0) -> 0 | AE23: =IF(AE$8=$R23,-$T23,0)+IF(AE$8=$S23,$T23,0) -> 0 | AF23: =IF(AF$8=$R23,-$T23,0)+IF(AF$8=$S23,$T23,0) -> 0 | AG23: =IF(AG$8=$R23,-$T23,0)+IF(AG$8=$S23,$T23,0) -> 0 | ... AK23: =IF(AK$8=$R23,-$T23,0)+IF(AK$8=$S23,$T23,0) -> 0
C24: VARIAÇÃO MENSAL POR CONTA | N24: 16 | X24: =IF(P24<NOW(),1,0) -> 1 | Z24: =IF(Z$8=$R24,-$T24,0)+IF(Z$8=$S24,$T24,0) -> 0 | AA24: =IF(AA$8=$R24,-$T24,0)+IF(AA$8=$S24,$T24,0) -> 0 | AB24: =IF(AB$8=$R24,-$T24,0)+IF(AB$8=$S24,$T24,0) -> 0 | AC24: =IF(AC$8=$R24,-$T24,0)+IF(AC$8=$S24,$T24,0) -> 0 | AD24: =IF(AD$8=$R24,-$T24,0)+IF(AD$8=$S24,$T24,0) -> 0 | AE24: =IF(AE$8=$R24,-$T24,0)+IF(AE$8=$S24,$T24,0) -> 0 | AF24: =IF(AF$8=$R24,-$T24,0)+IF(AF$8=$S24,$T24,0) -> 0 | AG24: =IF(AG$8=$R24,-$T24,0)+IF(AG$8=$S24,$T24,0) -> 0 | ... AK24: =IF(AK$8=$R24,-$T24,0)+IF(AK$8=$S24,$T24,0) -> 0
N25: 17 | X25: =IF(P25<NOW(),1,0) -> 1 | Z25: =IF(Z$8=$R25,-$T25,0)+IF(Z$8=$S25,$T25,0) -> 0 | AA25: =IF(AA$8=$R25,-$T25,0)+IF(AA$8=$S25,$T25,0) -> 0 | AB25: =IF(AB$8=$R25,-$T25,0)+IF(AB$8=$S25,$T25,0) -> 0 | AC25: =IF(AC$8=$R25,-$T25,0)+IF(AC$8=$S25,$T25,0) -> 0 | AD25: =IF(AD$8=$R25,-$T25,0)+IF(AD$8=$S25,$T25,0) -> 0 | AE25: =IF(AE$8=$R25,-$T25,0)+IF(AE$8=$S25,$T25,0) -> 0 | AF25: =IF(AF$8=$R25,-$T25,0)+IF(AF$8=$S25,$T25,0) -> 0 | AG25: =IF(AG$8=$R25,-$T25,0)+IF(AG$8=$S25,$T25,0) -> 0 | ... AK25: =IF(AK$8=$R25,-$T25,0)+IF(AK$8=$S25,$T25,0) -> 0
C26: CONTA | D26: DESCRIÇÃO | E26: TRANSFERÊNCIAS | F26: SAÍDA | G26: SALDO | N26: 18 | X26: =IF(P26<NOW(),1,0) -> 1 | Z26: =IF(Z$8=$R26,-$T26,0)+IF(Z$8=$S26,$T26,0) -> 0 | AA26: =IF(AA$8=$R26,-$T26,0)+IF(AA$8=$S26,$T26,0) -> 0 | AB26: =IF(AB$8=$R26,-$T26,0)+IF(AB$8=$S26,$T26,0) -> 0 | AC26: =IF(AC$8=$R26,-$T26,0)+IF(AC$8=$S26,$T26,0) -> 0 | AD26: =IF(AD$8=$R26,-$T26,0)+IF(AD$8=$S26,$T26,0) -> 0 | AE26: =IF(AE$8=$R26,-$T26,0)+IF(AE$8=$S26,$T26,0) -> 0 | AF26: =IF(AF$8=$R26,-$T26,0)+IF(AF$8=$S26,$T26,0) -> 0 | AG26: =IF(AG$8=$R26,-$T26,0)+IF(AG$8=$S26,$T26,0) -> 0 | ... AK26: =IF(AK$8=$R26,-$T26,0)+IF(AK$8=$S26,$T26,0) -> 0
E27: ENTRADA | F27: SAÍDA | G27: VARIAÇÃO | J27: =ANUAL!C115 -> CC | K27: =ANUAL!C116 -> INV | L27: =ANUAL!C117 -> DINH | N27: 19 | X27: =IF(P27<NOW(),1,0) -> 1 | Z27: =IF(Z$8=$R27,-$T27,0)+IF(Z$8=$S27,$T27,0) -> 0 | AA27: =IF(AA$8=$R27,-$T27,0)+IF(AA$8=$S27,$T27,0) -> 0 | AB27: =IF(AB$8=$R27,-$T27,0)+IF(AB$8=$S27,$T27,0) -> 0 | AC27: =IF(AC$8=$R27,-$T27,0)+IF(AC$8=$S27,$T27,0) -> 0 | AD27: =IF(AD$8=$R27,-$T27,0)+IF(AD$8=$S27,$T27,0) -> 0 | AE27: =IF(AE$8=$R27,-$T27,0)+IF(AE$8=$S27,$T27,0) -> 0 | AF27: =IF(AF$8=$R27,-$T27,0)+IF(AF$8=$S27,$T27,0) -> 0 | AG27: =IF(AG$8=$R27,-$T27,0)+IF(AG$8=$S27,$T27,0) -> 0 | ... AK27: =IF(AK$8=$R27,-$T27,0)+IF(AK$8=$S27,$T27,0) -> 0
A28: 1 | C28: =C9 | D28: =D9 -> CONTA CORRENTE BANCO 1 | E28: =SUMIF(OFFSET($Z$9:$Z$88,0,A28-1),">0") -> 0 | F28: =SUMIF(OFFSET($Z$9:$Z$88,0,A28-1),"<0") -> 0 | G28: =SUM(E28:F28) -> 0 | J28: =NOT(ISERR(SEARCH(J$27,$C28))) -> FALSE | K28: =NOT(ISERR(SEARCH(K$27,$C28))) -> FALSE | L28: =NOT(ISERR(SEARCH(L$27,$C28))) -> FALSE | N28: 20 | X28: =IF(P28<NOW(),1,0) -> 1 | Z28: =IF(Z$8=$R28,-$T28,0)+IF(Z$8=$S28,$T28,0) -> 0 | AA28: =IF(AA$8=$R28,-$T28,0)+IF(AA$8=$S28,$T28,0) -> 0 | AB28: =IF(AB$8=$R28,-$T28,0)+IF(AB$8=$S28,$T28,0) -> 0 | AC28: =IF(AC$8=$R28,-$T28,0)+IF(AC$8=$S28,$T28,0) -> 0 | AD28: =IF(AD$8=$R28,-$T28,0)+IF(AD$8=$S28,$T28,0) -> 0 | AE28: =IF(AE$8=$R28,-$T28,0)+IF(AE$8=$S28,$T28,0) -> 0 | AF28: =IF(AF$8=$R28,-$T28,0)+IF(AF$8=$S28,$T28,0) -> 0 | AG28: =IF(AG$8=$R28,-$T28,0)+IF(AG$8=$S28,$T28,0) -> 0 | ... AK28: =IF(AK$8=$R28,-$T28,0)+IF(AK$8=$S28,$T28,0) -> 0
A29: 2 | C29: =C10 -> INV1 | D29: =D10 -> POUPANÇA BANCO 1 | E29: =SUMIF(OFFSET($Z$9:$Z$88,0,A29-1),">0") -> 0 | F29: =SUMIF(OFFSET($Z$9:$Z$88,0,A29-1),"<0") -> 0 | G29: =SUM(E29:F29) -> 0 | J29: =NOT(ISERR(SEARCH(J$27,$C29))) -> FALSE | K29: =NOT(ISERR(SEARCH(K$27,$C29))) -> TRUE | L29: =NOT(ISERR(SEARCH(L$27,$C29))) -> FALSE | N29: 21 | X29: =IF(P29<NOW(),1,0) -> 1 | Z29: =IF(Z$8=$R29,-$T29,0)+IF(Z$8=$S29,$T29,0) -> 0 | AA29: =IF(AA$8=$R29,-$T29,0)+IF(AA$8=$S29,$T29,0) -> 0 | AB29: =IF(AB$8=$R29,-$T29,0)+IF(AB$8=$S29,$T29,0) -> 0 | AC29: =IF(AC$8=$R29,-$T29,0)+IF(AC$8=$S29,$T29,0) -> 0 | AD29: =IF(AD$8=$R29,-$T29,0)+IF(AD$8=$S29,$T29,0) -> 0 | AE29: =IF(AE$8=$R29,-$T29,0)+IF(AE$8=$S29,$T29,0) -> 0 | AF29: =IF(AF$8=$R29,-$T29,0)+IF(AF$8=$S29,$T29,0) -> 0 | AG29: =IF(AG$8=$R29,-$T29,0)+IF(AG$8=$S29,$T29,0) -> 0 | ... AK29: =IF(AK$8=$R29,-$T29,0)+IF(AK$8=$S29,$T29,0) -> 0
A30: 3 | C30: =C11 -> DINH1 | D30: =D11 -> EM ESPÉCIE | E30: =SUMIF(OFFSET($Z$9:$Z$88,0,A30-1),">0") -> 0 | F30: =SUMIF(OFFSET($Z$9:$Z$88,0,A30-1),"<0") -> 0 | G30: =SUM(E30:F30) -> 0 | J30: =NOT(ISERR(SEARCH(J$27,$C30))) -> FALSE | K30: =NOT(ISERR(SEARCH(K$27,$C30))) -> FALSE | L30: =NOT(ISERR(SEARCH(L$27,$C30))) -> TRUE | N30: 22 | X30: =IF(P30<NOW(),1,0) -> 1 | Z30: =IF(Z$8=$R30,-$T30,0)+IF(Z$8=$S30,$T30,0) -> 0 | AA30: =IF(AA$8=$R30,-$T30,0)+IF(AA$8=$S30,$T30,0) -> 0 | AB30: =IF(AB$8=$R30,-$T30,0)+IF(AB$8=$S30,$T30,0) -> 0 | AC30: =IF(AC$8=$R30,-$T30,0)+IF(AC$8=$S30,$T30,0) -> 0 | AD30: =IF(AD$8=$R30,-$T30,0)+IF(AD$8=$S30,$T30,0) -> 0 | AE30: =IF(AE$8=$R30,-$T30,0)+IF(AE$8=$S30,$T30,0) -> 0 | AF30: =IF(AF$8=$R30,-$T30,0)+IF(AF$8=$S30,$T30,0) -> 0 | AG30: =IF(AG$8=$R30,-$T30,0)+IF(AG$8=$S30,$T30,0) -> 0 | ... AK30: =IF(AK$8=$R30,-$T30,0)+IF(AK$8=$S30,$T30,0) -> 0
A31: 4 | C31: =C12 -> CRED1 | D31: =D12 -> CARTÃO DE CRÉDITO 1 | E31: =SUMIF(OFFSET($Z$9:$Z$88,0,A31-1),">0") -> 0 | F31: =SUMIF(OFFSET($Z$9:$Z$88,0,A31-1),"<0") -> 0 | G31: =SUM(E31:F31) -> 0 | J31: =NOT(ISERR(SEARCH(J$27,$C31))) -> FALSE | K31: =NOT(ISERR(SEARCH(K$27,$C31))) -> FALSE | L31: =NOT(ISERR(SEARCH(L$27,$C31))) -> FALSE | N31: 23 | X31: =IF(P31<NOW(),1,0) -> 1 | Z31: =IF(Z$8=$R31,-$T31,0)+IF(Z$8=$S31,$T31,0) -> 0 | AA31: =IF(AA$8=$R31,-$T31,0)+IF(AA$8=$S31,$T31,0) -> 0 | AB31: =IF(AB$8=$R31,-$T31,0)+IF(AB$8=$S31,$T31,0) -> 0 | AC31: =IF(AC$8=$R31,-$T31,0)+IF(AC$8=$S31,$T31,0) -> 0 | AD31: =IF(AD$8=$R31,-$T31,0)+IF(AD$8=$S31,$T31,0) -> 0 | AE31: =IF(AE$8=$R31,-$T31,0)+IF(AE$8=$S31,$T31,0) -> 0 | AF31: =IF(AF$8=$R31,-$T31,0)+IF(AF$8=$S31,$T31,0) -> 0 | AG31: =IF(AG$8=$R31,-$T31,0)+IF(AG$8=$S31,$T31,0) -> 0 | ... AK31: =IF(AK$8=$R31,-$T31,0)+IF(AK$8=$S31,$T31,0) -> 0
A32: 5 | C32: =C13 -> --- | D32: =D13 | E32: =SUMIF(OFFSET($Z$9:$Z$88,0,A32-1),">0") -> 0 | F32: =SUMIF(OFFSET($Z$9:$Z$88,0,A32-1),"<0") -> 0 | G32: =SUM(E32:F32) -> 0 | J32: =NOT(ISERR(SEARCH(J$27,$C32))) -> FALSE | K32: =NOT(ISERR(SEARCH(K$27,$C32))) -> FALSE | L32: =NOT(ISERR(SEARCH(L$27,$C32))) -> FALSE | N32: 24 | X32: =IF(P32<NOW(),1,0) -> 1 | Z32: =IF(Z$8=$R32,-$T32,0)+IF(Z$8=$S32,$T32,0) -> 0 | AA32: =IF(AA$8=$R32,-$T32,0)+IF(AA$8=$S32,$T32,0) -> 0 | AB32: =IF(AB$8=$R32,-$T32,0)+IF(AB$8=$S32,$T32,0) -> 0 | AC32: =IF(AC$8=$R32,-$T32,0)+IF(AC$8=$S32,$T32,0) -> 0 | AD32: =IF(AD$8=$R32,-$T32,0)+IF(AD$8=$S32,$T32,0) -> 0 | AE32: =IF(AE$8=$R32,-$T32,0)+IF(AE$8=$S32,$T32,0) -> 0 | AF32: =IF(AF$8=$R32,-$T32,0)+IF(AF$8=$S32,$T32,0) -> 0 | AG32: =IF(AG$8=$R32,-$T32,0)+IF(AG$8=$S32,$T32,0) -> 0 | ... AK32: =IF(AK$8=$R32,-$T32,0)+IF(AK$8=$S32,$T32,0) -> 0
A33: 6 | C33: =C14 -> --- | D33: =D14 | E33: =SUMIF(OFFSET($Z$9:$Z$88,0,A33-1),">0") -> 0 | F33: =SUMIF(OFFSET($Z$9:$Z$88,0,A33-1),"<0") -> 0 | G33: =SUM(E33:F33) -> 0 | J33: =NOT(ISERR(SEARCH(J$27,$C33))) -> FALSE | K33: =NOT(ISERR(SEARCH(K$27,$C33))) -> FALSE | L33: =NOT(ISERR(SEARCH(L$27,$C33))) -> FALSE | N33: 25 | X33: =IF(P33<NOW(),1,0) -> 1 | Z33: =IF(Z$8=$R33,-$T33,0)+IF(Z$8=$S33,$T33,0) -> 0 | AA33: =IF(AA$8=$R33,-$T33,0)+IF(AA$8=$S33,$T33,0) -> 0 | AB33: =IF(AB$8=$R33,-$T33,0)+IF(AB$8=$S33,$T33,0) -> 0 | AC33: =IF(AC$8=$R33,-$T33,0)+IF(AC$8=$S33,$T33,0) -> 0 | AD33: =IF(AD$8=$R33,-$T33,0)+IF(AD$8=$S33,$T33,0) -> 0 | AE33: =IF(AE$8=$R33,-$T33,0)+IF(AE$8=$S33,$T33,0) -> 0 | AF33: =IF(AF$8=$R33,-$T33,0)+IF(AF$8=$S33,$T33,0) -> 0 | AG33: =IF(AG$8=$R33,-$T33,0)+IF(AG$8=$S33,$T33,0) -> 0 | ... AK33: =IF(AK$8=$R33,-$T33,0)+IF(AK$8=$S33,$T33,0) -> 0
A34: 7 | C34: =C15 -> --- | D34: =D15 | E34: =SUMIF(OFFSET($Z$9:$Z$88,0,A34-1),">0") -> 0 | F34: =SUMIF(OFFSET($Z$9:$Z$88,0,A34-1),"<0") -> 0 | G34: =SUM(E34:F34) -> 0 | J34: =NOT(ISERR(SEARCH(J$27,$C34))) -> FALSE | K34: =NOT(ISERR(SEARCH(K$27,$C34))) -> FALSE | L34: =NOT(ISERR(SEARCH(L$27,$C34))) -> FALSE | N34: 26 | X34: =IF(P34<NOW(),1,0) -> 1 | Z34: =IF(Z$8=$R34,-$T34,0)+IF(Z$8=$S34,$T34,0) -> 0 | AA34: =IF(AA$8=$R34,-$T34,0)+IF(AA$8=$S34,$T34,0) -> 0 | AB34: =IF(AB$8=$R34,-$T34,0)+IF(AB$8=$S34,$T34,0) -> 0 | AC34: =IF(AC$8=$R34,-$T34,0)+IF(AC$8=$S34,$T34,0) -> 0 | AD34: =IF(AD$8=$R34,-$T34,0)+IF(AD$8=$S34,$T34,0) -> 0 | AE34: =IF(AE$8=$R34,-$T34,0)+IF(AE$8=$S34,$T34,0) -> 0 | AF34: =IF(AF$8=$R34,-$T34,0)+IF(AF$8=$S34,$T34,0) -> 0 | AG34: =IF(AG$8=$R34,-$T34,0)+IF(AG$8=$S34,$T34,0) -> 0 | ... AK34: =IF(AK$8=$R34,-$T34,0)+IF(AK$8=$S34,$T34,0) -> 0
A35: 8 | C35: =C16 -> --- | D35: =D16 | E35: =SUMIF(OFFSET($Z$9:$Z$88,0,A35-1),">0") -> 0 | F35: =SUMIF(OFFSET($Z$9:$Z$88,0,A35-1),"<0") -> 0 | G35: =SUM(E35:F35) -> 0 | J35: =NOT(ISERR(SEARCH(J$27,$C35))) -> FALSE | K35: =NOT(ISERR(SEARCH(K$27,$C35))) -> FALSE | L35: =NOT(ISERR(SEARCH(L$27,$C35))) -> FALSE | N35: 27 | X35: =IF(P35<NOW(),1,0) -> 1 | Z35: =IF(Z$8=$R35,-$T35,0)+IF(Z$8=$S35,$T35,0) -> 0 | AA35: =IF(AA$8=$R35,-$T35,0)+IF(AA$8=$S35,$T35,0) -> 0 | AB35: =IF(AB$8=$R35,-$T35,0)+IF(AB$8=$S35,$T35,0) -> 0 | AC35: =IF(AC$8=$R35,-$T35,0)+IF(AC$8=$S35,$T35,0) -> 0 | AD35: =IF(AD$8=$R35,-$T35,0)+IF(AD$8=$S35,$T35,0) -> 0 | AE35: =IF(AE$8=$R35,-$T35,0)+IF(AE$8=$S35,$T35,0) -> 0 | AF35: =IF(AF$8=$R35,-$T35,0)+IF(AF$8=$S35,$T35,0) -> 0 | AG35: =IF(AG$8=$R35,-$T35,0)+IF(AG$8=$S35,$T35,0) -> 0 | ... AK35: =IF(AK$8=$R35,-$T35,0)+IF(AK$8=$S35,$T35,0) -> 0
A36: 9 | C36: =C17 -> --- | D36: =D17 | E36: =SUMIF(OFFSET($Z$9:$Z$88,0,A36-1),">0") -> 0 | F36: =SUMIF(OFFSET($Z$9:$Z$88,0,A36-1),"<0") -> 0 | G36: =SUM(E36:F36) -> 0 | J36: =NOT(ISERR(SEARCH(J$27,$C36))) -> FALSE | K36: =NOT(ISERR(SEARCH(K$27,$C36))) -> FALSE | L36: =NOT(ISERR(SEARCH(L$27,$C36))) -> FALSE | N36: 28 | X36: =IF(P36<NOW(),1,0) -> 1 | Z36: =IF(Z$8=$R36,-$T36,0)+IF(Z$8=$S36,$T36,0) -> 0 | AA36: =IF(AA$8=$R36,-$T36,0)+IF(AA$8=$S36,$T36,0) -> 0 | AB36: =IF(AB$8=$R36,-$T36,0)+IF(AB$8=$S36,$T36,0) -> 0 | AC36: =IF(AC$8=$R36,-$T36,0)+IF(AC$8=$S36,$T36,0) -> 0 | AD36: =IF(AD$8=$R36,-$T36,0)+IF(AD$8=$S36,$T36,0) -> 0 | AE36: =IF(AE$8=$R36,-$T36,0)+IF(AE$8=$S36,$T36,0) -> 0 | AF36: =IF(AF$8=$R36,-$T36,0)+IF(AF$8=$S36,$T36,0) -> 0 | AG36: =IF(AG$8=$R36,-$T36,0)+IF(AG$8=$S36,$T36,0) -> 0 | ... AK36: =IF(AK$8=$R36,-$T36,0)+IF(AK$8=$S36,$T36,0) -> 0
A37: 10 | C37: =C18 -> --- | D37: =D18 | E37: =SUMIF(OFFSET($Z$9:$Z$88,0,A37-1),">0") -> 0 | F37: =SUMIF(OFFSET($Z$9:$Z$88,0,A37-1),"<0") -> 0 | G37: =SUM(E37:F37) -> 0 | J37: =NOT(ISERR(SEARCH(J$27,$C37))) -> FALSE | K37: =NOT(ISERR(SEARCH(K$27,$C37))) -> FALSE | L37: =NOT(ISERR(SEARCH(L$27,$C37))) -> FALSE | N37: 29 | X37: =IF(P37<NOW(),1,0) -> 1 | Z37: =IF(Z$8=$R37,-$T37,0)+IF(Z$8=$S37,$T37,0) -> 0 | AA37: =IF(AA$8=$R37,-$T37,0)+IF(AA$8=$S37,$T37,0) -> 0 | AB37: =IF(AB$8=$R37,-$T37,0)+IF(AB$8=$S37,$T37,0) -> 0 | AC37: =IF(AC$8=$R37,-$T37,0)+IF(AC$8=$S37,$T37,0) -> 0 | AD37: =IF(AD$8=$R37,-$T37,0)+IF(AD$8=$S37,$T37,0) -> 0 | AE37: =IF(AE$8=$R37,-$T37,0)+IF(AE$8=$S37,$T37,0) -> 0 | AF37: =IF(AF$8=$R37,-$T37,0)+IF(AF$8=$S37,$T37,0) -> 0 | AG37: =IF(AG$8=$R37,-$T37,0)+IF(AG$8=$S37,$T37,0) -> 0 | ... AK37: =IF(AK$8=$R37,-$T37,0)+IF(AK$8=$S37,$T37,0) -> 0
A38: 11 | C38: =C19 -> --- | D38: =D19 | E38: =SUMIF(OFFSET($Z$9:$Z$88,0,A38-1),">0") -> 0 | F38: =SUMIF(OFFSET($Z$9:$Z$88,0,A38-1),"<0") -> 0 | G38: =SUM(E38:F38) -> 0 | J38: =NOT(ISERR(SEARCH(J$27,$C38))) -> FALSE | K38: =NOT(ISERR(SEARCH(K$27,$C38))) -> FALSE | L38: =NOT(ISERR(SEARCH(L$27,$C38))) -> FALSE | N38: 30 | X38: =IF(P38<NOW(),1,0) -> 1 | Z38: =IF(Z$8=$R38,-$T38,0)+IF(Z$8=$S38,$T38,0) -> 0 | AA38: =IF(AA$8=$R38,-$T38,0)+IF(AA$8=$S38,$T38,0) -> 0 | AB38: =IF(AB$8=$R38,-$T38,0)+IF(AB$8=$S38,$T38,0) -> 0 | AC38: =IF(AC$8=$R38,-$T38,0)+IF(AC$8=$S38,$T38,0) -> 0 | AD38: =IF(AD$8=$R38,-$T38,0)+IF(AD$8=$S38,$T38,0) -> 0 | AE38: =IF(AE$8=$R38,-$T38,0)+IF(AE$8=$S38,$T38,0) -> 0 | AF38: =IF(AF$8=$R38,-$T38,0)+IF(AF$8=$S38,$T38,0) -> 0 | AG38: =IF(AG$8=$R38,-$T38,0)+IF(AG$8=$S38,$T38,0) -> 0 | ... AK38: =IF(AK$8=$R38,-$T38,0)+IF(AK$8=$S38,$T38,0) -> 0
A39: 12 | C39: =C20 -> --- | D39: =D20 | E39: =SUMIF(OFFSET($Z$9:$Z$88,0,A39-1),">0") -> 0 | F39: =SUMIF(OFFSET($Z$9:$Z$88,0,A39-1),"<0") -> 0 | G39: =SUM(E39:F39) -> 0 | J39: =NOT(ISERR(SEARCH(J$27,$C39))) -> FALSE | K39: =NOT(ISERR(SEARCH(K$27,$C39))) -> FALSE | L39: =NOT(ISERR(SEARCH(L$27,$C39))) -> FALSE | N39: 31 | X39: =IF(P39<NOW(),1,0) -> 1 | Z39: =IF(Z$8=$R39,-$T39,0)+IF(Z$8=$S39,$T39,0) -> 0 | AA39: =IF(AA$8=$R39,-$T39,0)+IF(AA$8=$S39,$T39,0) -> 0 | AB39: =IF(AB$8=$R39,-$T39,0)+IF(AB$8=$S39,$T39,0) -> 0 | AC39: =IF(AC$8=$R39,-$T39,0)+IF(AC$8=$S39,$T39,0) -> 0 | AD39: =IF(AD$8=$R39,-$T39,0)+IF(AD$8=$S39,$T39,0) -> 0 | AE39: =IF(AE$8=$R39,-$T39,0)+IF(AE$8=$S39,$T39,0) -> 0 | AF39: =IF(AF$8=$R39,-$T39,0)+IF(AF$8=$S39,$T39,0) -> 0 | AG39: =IF(AG$8=$R39,-$T39,0)+IF(AG$8=$S39,$T39,0) -> 0 | ... AK39: =IF(AK$8=$R39,-$T39,0)+IF(AK$8=$S39,$T39,0) -> 0
N40: 32 | X40: =IF(P40<NOW(),1,0) -> 1 | Z40: =IF(Z$8=$R40,-$T40,0)+IF(Z$8=$S40,$T40,0) -> 0 | AA40: =IF(AA$8=$R40,-$T40,0)+IF(AA$8=$S40,$T40,0) -> 0 | AB40: =IF(AB$8=$R40,-$T40,0)+IF(AB$8=$S40,$T40,0) -> 0 | AC40: =IF(AC$8=$R40,-$T40,0)+IF(AC$8=$S40,$T40,0) -> 0 | AD40: =IF(AD$8=$R40,-$T40,0)+IF(AD$8=$S40,$T40,0) -> 0 | AE40: =IF(AE$8=$R40,-$T40,0)+IF(AE$8=$S40,$T40,0) -> 0 | AF40: =IF(AF$8=$R40,-$T40,0)+IF(AF$8=$S40,$T40,0) -> 0 | AG40: =IF(AG$8=$R40,-$T40,0)+IF(AG$8=$S40,$T40,0) -> 0 | ... AK40: =IF(AK$8=$R40,-$T40,0)+IF(AK$8=$S40,$T40,0) -> 0
N41: 33 | X41: =IF(P41<NOW(),1,0) -> 1 | Z41: =IF(Z$8=$R41,-$T41,0)+IF(Z$8=$S41,$T41,0) -> 0 | AA41: =IF(AA$8=$R41,-$T41,0)+IF(AA$8=$S41,$T41,0) -> 0 | AB41: =IF(AB$8=$R41,-$T41,0)+IF(AB$8=$S41,$T41,0) -> 0 | AC41: =IF(AC$8=$R41,-$T41,0)+IF(AC$8=$S41,$T41,0) -> 0 | AD41: =IF(AD$8=$R41,-$T41,0)+IF(AD$8=$S41,$T41,0) -> 0 | AE41: =IF(AE$8=$R41,-$T41,0)+IF(AE$8=$S41,$T41,0) -> 0 | AF41: =IF(AF$8=$R41,-$T41,0)+IF(AF$8=$S41,$T41,0) -> 0 | AG41: =IF(AG$8=$R41,-$T41,0)+IF(AG$8=$S41,$T41,0) -> 0 | ... AK41: =IF(AK$8=$R41,-$T41,0)+IF(AK$8=$S41,$T41,0) -> 0
N42: 34 | X42: =IF(P42<NOW(),1,0) -> 1 | Z42: =IF(Z$8=$R42,-$T42,0)+IF(Z$8=$S42,$T42,0) -> 0 | AA42: =IF(AA$8=$R42,-$T42,0)+IF(AA$8=$S42,$T42,0) -> 0 | AB42: =IF(AB$8=$R42,-$T42,0)+IF(AB$8=$S42,$T42,0) -> 0 | AC42: =IF(AC$8=$R42,-$T42,0)+IF(AC$8=$S42,$T42,0) -> 0 | AD42: =IF(AD$8=$R42,-$T42,0)+IF(AD$8=$S42,$T42,0) -> 0 | AE42: =IF(AE$8=$R42,-$T42,0)+IF(AE$8=$S42,$T42,0) -> 0 | AF42: =IF(AF$8=$R42,-$T42,0)+IF(AF$8=$S42,$T42,0) -> 0 | AG42: =IF(AG$8=$R42,-$T42,0)+IF(AG$8=$S42,$T42,0) -> 0 | ... AK42: =IF(AK$8=$R42,-$T42,0)+IF(AK$8=$S42,$T42,0) -> 0
C43: MOVIMENTAÇÕES DO MÊS POR GRUPO DE CONTAS | N43: 35 | X43: =IF(P43<NOW(),1,0) -> 1 | Z43: =IF(Z$8=$R43,-$T43,0)+IF(Z$8=$S43,$T43,0) -> 0 | AA43: =IF(AA$8=$R43,-$T43,0)+IF(AA$8=$S43,$T43,0) -> 0 | AB43: =IF(AB$8=$R43,-$T43,0)+IF(AB$8=$S43,$T43,0) -> 0 | AC43: =IF(AC$8=$R43,-$T43,0)+IF(AC$8=$S43,$T43,0) -> 0 | AD43: =IF(AD$8=$R43,-$T43,0)+IF(AD$8=$S43,$T43,0) -> 0 | AE43: =IF(AE$8=$R43,-$T43,0)+IF(AE$8=$S43,$T43,0) -> 0 | AF43: =IF(AF$8=$R43,-$T43,0)+IF(AF$8=$S43,$T43,0) -> 0 | AG43: =IF(AG$8=$R43,-$T43,0)+IF(AG$8=$S43,$T43,0) -> 0 | ... AK43: =IF(AK$8=$R43,-$T43,0)+IF(AK$8=$S43,$T43,0) -> 0
...

Sheet M2
B1: =DATE(ANUAL!B5,B2,8) -> 40217 | I1: >> | M1: << | W1: >> | AL1: <<
B2: ='M1'!B2+1 -> 2
C5: LISTA DE CONTAS | P5: MOVIMENTAÇÕES DO MÊS
C7: CONTA | D7: DESCRIÇÃO | E7: SALDO | P7: DATA | Q7: DESCRIÇÃO | R7: TRANFERÊNCIAS | T7: VALOR | U7: CODIGO
E8: ANTERIOR | F8: ATUAL | G8: PREVISTO | P8: DATA | Q8: DESCRIÇÃO | R8: SAÍDA | S8: ENTRADA | T8: VALOR | X8: ATUAL | Z8: =$C$9 | AA8: =$C$10 -> INV1 | AB8: =$C$11 -> DINH1 | AC8: =$C$12 -> CRED1 | AD8: =$C$13 -> --- | AE8: =$C$14 -> --- | AF8: =$C$15 -> --- | AG8: =$C$16 -> --- | AH8: =$C$17 -> --- | AI8: =$C$18 -> --- | AJ8: =$C$19 -> --- | AK8: =$C$20 -> ---
A9: 1 | C9: =TRIM(ANUAL!C13) | D9: =TRIM(ANUAL!D13) -> CONTA CORRENTE BANCO 1 | E9: =INDIRECT("M"&B$2-1&"!G"&A9+ROW(A$8)) -> 0 | F9: =E9+SUMIF(X$9:X$88,1,OFFSET($Z$9:$Z$88,0,A9-1)) -> 0 | G9: =E9+SUM(OFFSET($Z$9:$Z$88,0,A9-1)) -> 0 | J9: =NOT(ISERR(SEARCH(J$27,$C9))) -> FALSE | K9: =NOT(ISERR(SEARCH(K$27,$C9))) -> FALSE | L9: =NOT(ISERR(SEARCH(L$27,$C9))) -> FALSE | N9: 1 | X9: =IF(P9<NOW(),1,0) -> 1 | Z9: =IF(Z$8=$R9,-$T9,0)+IF(Z$8=$S9,$T9,0) -> 0 | AA9: =IF(AA$8=$R9,-$T9,0)+IF(AA$8=$S9,$T9,0) -> 0 | AB9: =IF(AB$8=$R9,-$T9,0)+IF(AB$8=$S9,$T9,0) -> 0 | AC9: =IF(AC$8=$R9,-$T9,0)+IF(AC$8=$S9,$T9,0) -> 0 | AD9: =IF(AD$8=$R9,-$T9,0)+IF(AD$8=$S9,$T9,0) -> 0 | AE9: =IF(AE$8=$R9,-$T9,0)+IF(AE$8=$S9,$T9,0) -> 0 | AF9: =IF(AF$8=$R9,-$T9,0)+IF(AF$8=$S9,$T9,0) -> 0 | AG9: =IF(AG$8=$R9,-$T9,0)+IF(AG$8=$S9,$T9,0) -> 0 | ... AK9: =IF(AK$8=$R9,-$T9,0)+IF(AK$8=$S9,$T9,0) -> 0
A10: 2 | C10: =TRIM(ANUAL!C14) -> INV1 | D10: =TRIM(ANUAL!D14) -> POUPANÇA BANCO 1 | E10: =INDIRECT("M"&B$2-1&"!G"&A10+ROW(A$8)) -> 0 | F10: =E10+SUMIF(X$9:X$88,1,OFFSET($Z$9:$Z$88,0,A10-1)) -> 0 | G10: =E10+SUM(OFFSET($Z$9:$Z$88,0,A10-1)) -> 0 | J10: =NOT(ISERR(SEARCH(J$27,$C10))) -> FALSE | K10: =NOT(ISERR(SEARCH(K$27,$C10))) -> TRUE | L10: =NOT(ISERR(SEARCH(L$27,$C10))) -> FALSE | N10: 2 | X10: =IF(P10<NOW(),1,0) -> 1 | Z10: =IF(Z$8=$R10,-$T10,0)+IF(Z$8=$S10,$T10,0) -> 0 | AA10: =IF(AA$8=$R10,-$T10,0)+IF(AA$8=$S10,$T10,0) -> 0 | AB10: =IF(AB$8=$R10,-$T10,0)+IF(AB$8=$S10,$T10,0) -> 0 | AC10: =IF(AC$8=$R10,-$T10,0)+IF(AC$8=$S10,$T10,0) -> 0 | AD10: =IF(AD$8=$R10,-$T10,0)+IF(AD$8=$S10,$T10,0) -> 0 | AE10: =IF(AE$8=$R10,-$T10,0)+IF(AE$8=$S10,$T10,0) -> 0 | AF10: =IF(AF$8=$R10,-$T10,0)+IF(AF$8=$S10,$T10,0) -> 0 | AG10: =IF(AG$8=$R10,-$T10,0)+IF(AG$8=$S10,$T10,0) -> 0 | ... AK10: =IF(AK$8=$R10,-$T10,0)+IF(AK$8=$S10,$T10,0) -> 0
A11: 3 | C11: =TRIM(ANUAL!C15) -> DINH1 | D11: =TRIM(ANUAL!D15) -> EM ESPÉCIE | E11: =INDIRECT("M"&B$2-1&"!G"&A11+ROW(A$8)) -> 0 | F11: =E11+SUMIF(X$9:X$88,1,OFFSET($Z$9:$Z$88,0,A11-1)) -> 0 | G11: =E11+SUM(OFFSET($Z$9:$Z$88,0,A11-1)) -> 0 | J11: =NOT(ISERR(SEARCH(J$27,$C11))) -> FALSE | K11: =NOT(ISERR(SEARCH(K$27,$C11))) -> FALSE | L11: =NOT(ISERR(SEARCH(L$27,$C11))) -> TRUE | N11: 3 | X11: =IF(P11<NOW(),1,0) -> 1 | Z11: =IF(Z$8=$R11,-$T11,0)+IF(Z$8=$S11,$T11,0) -> 0 | AA11: =IF(AA$8=$R11,-$T11,0)+IF(AA$8=$S11,$T11,0) -> 0 | AB11: =IF(AB$8=$R11,-$T11,0)+IF(AB$8=$S11,$T11,0) -> 0 | AC11: =IF(AC$8=$R11,-$T11,0)+IF(AC$8=$S11,$T11,0) -> 0 | AD11: =IF(AD$8=$R11,-$T11,0)+IF(AD$8=$S11,$T11,0) -> 0 | AE11: =IF(AE$8=$R11,-$T11,0)+IF(AE$8=$S11,$T11,0) -> 0 | AF11: =IF(AF$8=$R11,-$T11,0)+IF(AF$8=$S11,$T11,0) -> 0 | AG11: =IF(AG$8=$R11,-$T11,0)+IF(AG$8=$S11,$T11,0) -> 0 | ... AK11: =IF(AK$8=$R11,-$T11,0)+IF(AK$8=$S11,$T11,0) -> 0
A12: 4 | C12: =TRIM(ANUAL!C16) -> CRED1 | D12: =TRIM(ANUAL!D16) -> CARTÃO DE CRÉDITO 1 | E12: =INDIRECT("M"&B$2-1&"!G"&A12+ROW(A$8)) -> 0 | F12: =E12+SUMIF(X$9:X$88,1,OFFSET($Z$9:$Z$88,0,A12-1)) -> 0 | G12: =E12+SUM(OFFSET($Z$9:$Z$88,0,A12-1)) -> 0 | J12: =NOT(ISERR(SEARCH(J$27,$C12))) -> FALSE | K12: =NOT(ISERR(SEARCH(K$27,$C12))) -> FALSE | L12: =NOT(ISERR(SEARCH(L$27,$C12))) -> FALSE | N12: 4 | X12: =IF(P12<NOW(),1,0) -> 1 | Z12: =IF(Z$8=$R12,-$T12,0)+IF(Z$8=$S12,$T12,0) -> 0 | AA12: =IF(AA$8=$R12,-$T12,0)+IF(AA$8=$S12,$T12,0) -> 0 | AB12: =IF(AB$8=$R12,-$T12,0)+IF(AB$8=$S12,$T12,0) -> 0 | AC12: =IF(AC$8=$R12,-$T12,0)+IF(AC$8=$S12,$T12,0) -> 0 | AD12: =IF(AD$8=$R12,-$T12,0)+IF(AD$8=$S12,$T12,0) -> 0 | AE12: =IF(AE$8=$R12,-$T12,0)+IF(AE$8=$S12,$T12,0) -> 0 | AF12: =IF(AF$8=$R12,-$T12,0)+IF(AF$8=$S12,$T12,0) -> 0 | AG12: =IF(AG$8=$R12,-$T12,0)+IF(AG$8=$S12,$T12,0) -> 0 | ... AK12: =IF(AK$8=$R12,-$T12,0)+IF(AK$8=$S12,$T12,0) -> 0
A13: 5 | C13: =TRIM(ANUAL!C17) -> --- | D13: =TRIM(ANUAL!D17) | E13: =INDIRECT("M"&B$2-1&"!G"&A13+ROW(A$8)) -> 0 | F13: =E13+SUMIF(X$9:X$88,1,OFFSET($Z$9:$Z$88,0,A13-1)) -> 0 | G13: =E13+SUM(OFFSET($Z$9:$Z$88,0,A13-1)) -> 0 | J13: =NOT(ISERR(SEARCH(J$27,$C13))) -> FALSE | K13: =NOT(ISERR(SEARCH(K$27,$C13))) -> FALSE | L13: =NOT(ISERR(SEARCH(L$27,$C13))) -> FALSE | N13: 5 | X13: =IF(P13<NOW(),1,0) -> 1 | Z13: =IF(Z$8=$R13,-$T13,0)+IF(Z$8=$S13,$T13,0) -> 0 | AA13: =IF(AA$8=$R13,-$T13,0)+IF(AA$8=$S13,$T13,0) -> 0 | AB13: =IF(AB$8=$R13,-$T13,0)+IF(AB$8=$S13,$T13,0) -> 0 | AC13: =IF(AC$8=$R13,-$T13,0)+IF(AC$8=$S13,$T13,0) -> 0 | AD13: =IF(AD$8=$R13,-$T13,0)+IF(AD$8=$S13,$T13,0) -> 0 | AE13: =IF(AE$8=$R13,-$T13,0)+IF(AE$8=$S13,$T13,0) -> 0 | AF13: =IF(AF$8=$R13,-$T13,0)+IF(AF$8=$S13,$T13,0) -> 0 | AG13: =IF(AG$8=$R13,-$T13,0)+IF(AG$8=$S13,$T13,0) -> 0 | ... AK13: =IF(AK$8=$R13,-$T13,0)+IF(AK$8=$S13,$T13,0) -> 0
A14: 6 | C14: =TRIM(ANUAL!C18) -> --- | D14: =TRIM(ANUAL!D18) | E14: =INDIRECT("M"&B$2-1&"!G"&A14+ROW(A$8)) -> 0 | F14: =E14+SUMIF(X$9:X$88,1,OFFSET($Z$9:$Z$88,0,A14-1)) -> 0 | G14: =E14+SUM(OFFSET($Z$9:$Z$88,0,A14-1)) -> 0 | J14: =NOT(ISERR(SEARCH(J$27,$C14))) -> FALSE | K14: =NOT(ISERR(SEARCH(K$27,$C14))) -> FALSE | L14: =NOT(ISERR(SEARCH(L$27,$C14))) -> FALSE | N14: 6 | X14: =IF(P14<NOW(),1,0) -> 1 | Z14: =IF(Z$8=$R14,-$T14,0)+IF(Z$8=$S14,$T14,0) -> 0 | AA14: =IF(AA$8=$R14,-$T14,0)+IF(AA$8=$S14,$T14,0) -> 0 | AB14: =IF(AB$8=$R14,-$T14,0)+IF(AB$8=$S14,$T14,0) -> 0 | AC14: =IF(AC$8=$R14,-$T14,0)+IF(AC$8=$S14,$T14,0) -> 0 | AD14: =IF(AD$8=$R14,-$T14,0)+IF(AD$8=$S14,$T14,0) -> 0 | AE14: =IF(AE$8=$R14,-$T14,0)+IF(AE$8=$S14,$T14,0) -> 0 | AF14: =IF(AF$8=$R14,-$T14,0)+IF(AF$8=$S14,$T14,0) -> 0 | AG14: =IF(AG$8=$R14,-$T14,0)+IF(AG$8=$S14,$T14,0) -> 0 | ... AK14: =IF(AK$8=$R14,-$T14,0)+IF(AK$8=$S14,$T14,0) -> 0
A15: 7 | C15: =TRIM(ANUAL!C19) -> --- | D15: =TRIM(ANUAL!D19) | E15: =INDIRECT("M"&B$2-1&"!G"&A15+ROW(A$8)) -> 0 | F15: =E15+SUMIF(X$9:X$88,1,OFFSET($Z$9:$Z$88,0,A15-1)) -> 0 | G15: =E15+SUM(OFFSET($Z$9:$Z$88,0,A15-1)) -> 0 | J15: =NOT(ISERR(SEARCH(J$27,$C15))) -> FALSE | K15: =NOT(ISERR(SEARCH(K$27,$C15))) -> FALSE | L15: =NOT(ISERR(SEARCH(L$27,$C15))) -> FALSE | N15: 7 | X15: =IF(P15<NOW(),1,0) -> 1 | Z15: =IF(Z$8=$R15,-$T15,0)+IF(Z$8=$S15,$T15,0) -> 0 | AA15: =IF(AA$8=$R15,-$T15,0)+IF(AA$8=$S15,$T15,0) -> 0 | AB15: =IF(AB$8=$R15,-$T15,0)+IF(AB$8=$S15,$T15,0) -> 0 | AC15: =IF(AC$8=$R15,-$T15,0)+IF(AC$8=$S15,$T15,0) -> 0 | AD15: =IF(AD$8=$R15,-$T15,0)+IF(AD$8=$S15,$T15,0) -> 0 | AE15: =IF(AE$8=$R15,-$T15,0)+IF(AE$8=$S15,$T15,0) -> 0 | AF15: =IF(AF$8=$R15,-$T15,0)+IF(AF$8=$S15,$T15,0) -> 0 | AG15: =IF(AG$8=$R15,-$T15,0)+IF(AG$8=$S15,$T15,0) -> 0 | ... AK15: =IF(AK$8=$R15,-$T15,0)+IF(AK$8=$S15,$T15,0) -> 0
A16: 8 | C16: =TRIM(ANUAL!C20) -> --- | D16: =TRIM(ANUAL!D20) | E16: =INDIRECT("M"&B$2-1&"!G"&A16+ROW(A$8)) -> 0 | F16: =E16+SUMIF(X$9:X$88,1,OFFSET($Z$9:$Z$88,0,A16-1)) -> 0 | G16: =E16+SUM(OFFSET($Z$9:$Z$88,0,A16-1)) -> 0 | J16: =NOT(ISERR(SEARCH(J$27,$C16))) -> FALSE | K16: =NOT(ISERR(SEARCH(K$27,$C16))) -> FALSE | L16: =NOT(ISERR(SEARCH(L$27,$C16))) -> FALSE | N16: 8 | X16: =IF(P16<NOW(),1,0) -> 1 | Z16: =IF(Z$8=$R16,-$T16,0)+IF(Z$8=$S16,$T16,0) -> 0 | AA16: =IF(AA$8=$R16,-$T16,0)+IF(AA$8=$S16,$T16,0) -> 0 | AB16: =IF(AB$8=$R16,-$T16,0)+IF(AB$8=$S16,$T16,0) -> 0 | AC16: =IF(AC$8=$R16,-$T16,0)+IF(AC$8=$S16,$T16,0) -> 0 | AD16: =IF(AD$8=$R16,-$T16,0)+IF(AD$8=$S16,$T16,0) -> 0 | AE16: =IF(AE$8=$R16,-$T16,0)+IF(AE$8=$S16,$T16,0) -> 0 | AF16: =IF(AF$8=$R16,-$T16,0)+IF(AF$8=$S16,$T16,0) -> 0 | AG16: =IF(AG$8=$R16,-$T16,0)+IF(AG$8=$S16,$T16,0) -> 0 | ... AK16: =IF(AK$8=$R16,-$T16,0)+IF(AK$8=$S16,$T16,0) -> 0
A17: 9 | C17: =TRIM(ANUAL!C21) -> --- | D17: =TRIM(ANUAL!D21) | E17: =INDIRECT("M"&B$2-1&"!G"&A17+ROW(A$8)) -> 0 | F17: =E17+SUMIF(X$9:X$88,1,OFFSET($Z$9:$Z$88,0,A17-1)) -> 0 | G17: =E17+SUM(OFFSET($Z$9:$Z$88,0,A17-1)) -> 0 | J17: =NOT(ISERR(SEARCH(J$27,$C17))) -> FALSE | K17: =NOT(ISERR(SEARCH(K$27,$C17))) -> FALSE | L17: =NOT(ISERR(SEARCH(L$27,$C17))) -> FALSE | N17: 9 | X17: =IF(P17<NOW(),1,0) -> 1 | Z17: =IF(Z$8=$R17,-$T17,0)+IF(Z$8=$S17,$T17,0) -> 0 | AA17: =IF(AA$8=$R17,-$T17,0)+IF(AA$8=$S17,$T17,0) -> 0 | AB17: =IF(AB$8=$R17,-$T17,0)+IF(AB$8=$S17,$T17,0) -> 0 | AC17: =IF(AC$8=$R17,-$T17,0)+IF(AC$8=$S17,$T17,0) -> 0 | AD17: =IF(AD$8=$R17,-$T17,0)+IF(AD$8=$S17,$T17,0) -> 0 | AE17: =IF(AE$8=$R17,-$T17,0)+IF(AE$8=$S17,$T17,0) -> 0 | AF17: =IF(AF$8=$R17,-$T17,0)+IF(AF$8=$S17,$T17,0) -> 0 | AG17: =IF(AG$8=$R17,-$T17,0)+IF(AG$8=$S17,$T17,0) -> 0 | ... AK17: =IF(AK$8=$R17,-$T17,0)+IF(AK$8=$S17,$T17,0) -> 0
A18: 10 | C18: =TRIM(ANUAL!C22) -> --- | D18: =TRIM(ANUAL!D22) | E18: =INDIRECT("M"&B$2-1&"!G"&A18+ROW(A$8)) -> 0 | F18: =E18+SUMIF(X$9:X$88,1,OFFSET($Z$9:$Z$88,0,A18-1)) -> 0 | G18: =E18+SUM(OFFSET($Z$9:$Z$88,0,A18-1)) -> 0 | J18: =NOT(ISERR(SEARCH(J$27,$C18))) -> FALSE | K18: =NOT(ISERR(SEARCH(K$27,$C18))) -> FALSE | L18: =NOT(ISERR(SEARCH(L$27,$C18))) -> FALSE | N18: 10 | X18: =IF(P18<NOW(),1,0) -> 1 | Z18: =IF(Z$8=$R18,-$T18,0)+IF(Z$8=$S18,$T18,0) -> 0 | AA18: =IF(AA$8=$R18,-$T18,0)+IF(AA$8=$S18,$T18,0) -> 0 | AB18: =IF(AB$8=$R18,-$T18,0)+IF(AB$8=$S18,$T18,0) -> 0 | AC18: =IF(AC$8=$R18,-$T18,0)+IF(AC$8=$S18,$T18,0) -> 0 | AD18: =IF(AD$8=$R18,-$T18,0)+IF(AD$8=$S18,$T18,0) -> 0 | AE18: =IF(AE$8=$R18,-$T18,0)+IF(AE$8=$S18,$T18,0) -> 0 | AF18: =IF(AF$8=$R18,-$T18,0)+IF(AF$8=$S18,$T18,0) -> 0 | AG18: =IF(AG$8=$R18,-$T18,0)+IF(AG$8=$S18,$T18,0) -> 0 | ... AK18: =IF(AK$8=$R18,-$T18,0)+IF(AK$8=$S18,$T18,0) -> 0
A19: 11 | C19: =TRIM(ANUAL!C23) -> --- | D19: =TRIM(ANUAL!D23) | E19: =INDIRECT("M"&B$2-1&"!G"&A19+ROW(A$8)) -> 0 | F19: =E19+SUMIF(X$9:X$88,1,OFFSET($Z$9:$Z$88,0,A19-1)) -> 0 | G19: =E19+SUM(OFFSET($Z$9:$Z$88,0,A19-1)) -> 0 | J19: =NOT(ISERR(SEARCH(J$27,$C19))) -> FALSE | K19: =NOT(ISERR(SEARCH(K$27,$C19))) -> FALSE | L19: =NOT(ISERR(SEARCH(L$27,$C19))) -> FALSE | N19: 11 | X19: =IF(P19<NOW(),1,0) -> 1 | Z19: =IF(Z$8=$R19,-$T19,0)+IF(Z$8=$S19,$T19,0) -> 0 | AA19: =IF(AA$8=$R19,-$T19,0)+IF(AA$8=$S19,$T19,0) -> 0 | AB19: =IF(AB$8=$R19,-$T19,0)+IF(AB$8=$S19,$T19,0) -> 0 | AC19: =IF(AC$8=$R19,-$T19,0)+IF(AC$8=$S19,$T19,0) -> 0 | AD19: =IF(AD$8=$R19,-$T19,0)+IF(AD$8=$S19,$T19,0) -> 0 | AE19: =IF(AE$8=$R19,-$T19,0)+IF(AE$8=$S19,$T19,0) -> 0 | AF19: =IF(AF$8=$R19,-$T19,0)+IF(AF$8=$S19,$T19,0) -> 0 | AG19: =IF(AG$8=$R19,-$T19,0)+IF(AG$8=$S19,$T19,0) -> 0 | ... AK19: =IF(AK$8=$R19,-$T19,0)+IF(AK$8=$S19,$T19,0) -> 0
A20: 12 | C20: =TRIM(ANUAL!C24) -> --- | D20: =TRIM(ANUAL!D24) | E20: =INDIRECT("M"&B$2-1&"!G"&A20+ROW(A$8)) -> 0 | F20: =E20+SUMIF(X$9:X$88,1,OFFSET($Z$9:$Z$88,0,A20-1)) -> 0 | G20: =E20+SUM(OFFSET($Z$9:$Z$88,0,A20-1)) -> 0 | J20: =NOT(ISERR(SEARCH(J$27,$C20))) -> FALSE | K20: =NOT(ISERR(SEARCH(K$27,$C20))) -> FALSE | L20: =NOT(ISERR(SEARCH(L$27,$C20))) -> FALSE | N20: 12 | X20: =IF(P20<NOW(),1,0) -> 1 | Z20: =IF(Z$8=$R20,-$T20,0)+IF(Z$8=$S20,$T20,0) -> 0 | AA20: =IF(AA$8=$R20,-$T20,0)+IF(AA$8=$S20,$T20,0) -> 0 | AB20: =IF(AB$8=$R20,-$T20,0)+IF(AB$8=$S20,$T20,0) -> 0 | AC20: =IF(AC$8=$R20,-$T20,0)+IF(AC$8=$S20,$T20,0) -> 0 | AD20: =IF(AD$8=$R20,-$T20,0)+IF(AD$8=$S20,$T20,0) -> 0 | AE20: =IF(AE$8=$R20,-$T20,0)+IF(AE$8=$S20,$T20,0) -> 0 | AF20: =IF(AF$8=$R20,-$T20,0)+IF(AF$8=$S20,$T20,0) -> 0 | AG20: =IF(AG$8=$R20,-$T20,0)+IF(AG$8=$S20,$T20,0) -> 0 | ... AK20: =IF(AK$8=$R20,-$T20,0)+IF(AK$8=$S20,$T20,0) -> 0
N21: 13 | X21: =IF(P21<NOW(),1,0) -> 1 | Z21: =IF(Z$8=$R21,-$T21,0)+IF(Z$8=$S21,$T21,0) -> 0 | AA21: =IF(AA$8=$R21,-$T21,0)+IF(AA$8=$S21,$T21,0) -> 0 | AB21: =IF(AB$8=$R21,-$T21,0)+IF(AB$8=$S21,$T21,0) -> 0 | AC21: =IF(AC$8=$R21,-$T21,0)+IF(AC$8=$S21,$T21,0) -> 0 | AD21: =IF(AD$8=$R21,-$T21,0)+IF(AD$8=$S21,$T21,0) -> 0 | AE21: =IF(AE$8=$R21,-$T21,0)+IF(AE$8=$S21,$T21,0) -> 0 | AF21: =IF(AF$8=$R21,-$T21,0)+IF(AF$8=$S21,$T21,0) -> 0 | AG21: =IF(AG$8=$R21,-$T21,0)+IF(AG$8=$S21,$T21,0) -> 0 | ... AK21: =IF(AK$8=$R21,-$T21,0)+IF(AK$8=$S21,$T21,0) -> 0
N22: 14 | X22: =IF(P22<NOW(),1,0) -> 1 | Z22: =IF(Z$8=$R22,-$T22,0)+IF(Z$8=$S22,$T22,0) -> 0 | AA22: =IF(AA$8=$R22,-$T22,0)+IF(AA$8=$S22,$T22,0) -> 0 | AB22: =IF(AB$8=$R22,-$T22,0)+IF(AB$8=$S22,$T22,0) -> 0 | AC22: =IF(AC$8=$R22,-$T22,0)+IF(AC$8=$S22,$T22,0) -> 0 | AD22: =IF(AD$8=$R22,-$T22,0)+IF(AD$8=$S22,$T22,0) -> 0 | AE22: =IF(AE$8=$R22,-$T22,0)+IF(AE$8=$S22,$T22,0) -> 0 | AF22: =IF(AF$8=$R22,-$T22,0)+IF(AF$8=$S22,$T22,0) -> 0 | AG22: =IF(AG$8=$R22,-$T22,0)+IF(AG$8=$S22,$T22,0) -> 0 | ... AK22: =IF(AK$8=$R22,-$T22,0)+IF(AK$8=$S22,$T22,0) -> 0
N23: 15 | X23: =IF(P23<NOW(),1,0) -> 1 | Z23: =IF(Z$8=$R23,-$T23,0)+IF(Z$8=$S23,$T23,0) -> 0 | AA23: =IF(AA$8=$R23,-$T23,0)+IF(AA$8=$S23,$T23,0) -> 0 | AB23: =IF(AB$8=$R23,-$T23,0)+IF(AB$8=$S23,$T23,0) -> 0 | AC23: =IF(AC$8=$R23,-$T23,0)+IF(AC$8=$S23,$T23,0) -> 0 | AD23: =IF(AD$8=$R23,-$T23,0)+IF(AD$8=$S23,$T23,0) -> 0 | AE23: =IF(AE$8=$R23,-$T23,0)+IF(AE$8=$S23,$T23,0) -> 0 | AF23: =IF(AF$8=$R23,-$T23,0)+IF(AF$8=$S23,$T23,0) -> 0 | AG23: =IF(AG$8=$R23,-$T23,0)+IF(AG$8=$S23,$T23,0) -> 0 | ... AK23: =IF(AK$8=$R23,-$T23,0)+IF(AK$8=$S23,$T23,0) -> 0
C24: VARIAÇÃO MENSAL POR CONTA | N24: 16 | X24: =IF(P24<NOW(),1,0) -> 1 | Z24: =IF(Z$8=$R24,-$T24,0)+IF(Z$8=$S24,$T24,0) -> 0 | AA24: =IF(AA$8=$R24,-$T24,0)+IF(AA$8=$S24,$T24,0) -> 0 | AB24: =IF(AB$8=$R24,-$T24,0)+IF(AB$8=$S24,$T24,0) -> 0 | AC24: =IF(AC$8=$R24,-$T24,0)+IF(AC$8=$S24,$T24,0) -> 0 | AD24: =IF(AD$8=$R24,-$T24,0)+IF(AD$8=$S24,$T24,0) -> 0 | AE24: =IF(AE$8=$R24,-$T24,0)+IF(AE$8=$S24,$T24,0) -> 0 | AF24: =IF(AF$8=$R24,-$T24,0)+IF(AF$8=$S24,$T24,0) -> 0 | AG24: =IF(AG$8=$R24,-$T24,0)+IF(AG$8=$S24,$T24,0) -> 0 | ... AK24: =IF(AK$8=$R24,-$T24,0)+IF(AK$8=$S24,$T24,0) -> 0
N25: 17 | X25: =IF(P25<NOW(),1,0) -> 1 | Z25: =IF(Z$8=$R25,-$T25,0)+IF(Z$8=$S25,$T25,0) -> 0 | AA25: =IF(AA$8=$R25,-$T25,0)+IF(AA$8=$S25,$T25,0) -> 0 | AB25: =IF(AB$8=$R25,-$T25,0)+IF(AB$8=$S25,$T25,0) -> 0 | AC25: =IF(AC$8=$R25,-$T25,0)+IF(AC$8=$S25,$T25,0) -> 0 | AD25: =IF(AD$8=$R25,-$T25,0)+IF(AD$8=$S25,$T25,0) -> 0 | AE25: =IF(AE$8=$R25,-$T25,0)+IF(AE$8=$S25,$T25,0) -> 0 | AF25: =IF(AF$8=$R25,-$T25,0)+IF(AF$8=$S25,$T25,0) -> 0 | AG25: =IF(AG$8=$R25,-$T25,0)+IF(AG$8=$S25,$T25,0) -> 0 | ... AK25: =IF(AK$8=$R25,-$T25,0)+IF(AK$8=$S25,$T25,0) -> 0
C26: CONTA | D26: DESCRIÇÃO | E26: TRANSFERÊNCIAS | F26: SAÍDA | G26: SALDO | N26: 18 | X26: =IF(P26<NOW(),1,0) -> 1 | Z26: =IF(Z$8=$R26,-$T26,0)+IF(Z$8=$S26,$T26,0) -> 0 | AA26: =IF(AA$8=$R26,-$T26,0)+IF(AA$8=$S26,$T26,0) -> 0 | AB26: =IF(AB$8=$R26,-$T26,0)+IF(AB$8=$S26,$T26,0) -> 0 | AC26: =IF(AC$8=$R26,-$T26,0)+IF(AC$8=$S26,$T26,0) -> 0 | AD26: =IF(AD$8=$R26,-$T26,0)+IF(AD$8=$S26,$T26,0) -> 0 | AE26: =IF(AE$8=$R26,-$T26,0)+IF(AE$8=$S26,$T26,0) -> 0 | AF26: =IF(AF$8=$R26,-$T26,0)+IF(AF$8=$S26,$T26,0) -> 0 | AG26: =IF(AG$8=$R26,-$T26,0)+IF(AG$8=$S26,$T26,0) -> 0 | ... AK26: =IF(AK$8=$R26,-$T26,0)+IF(AK$8=$S26,$T26,0) -> 0
E27: ENTRADA | F27: SAÍDA | G27: VARIAÇÃO | J27: =ANUAL!C115 -> CC | K27: =ANUAL!C116 -> INV | L27: =ANUAL!C117 -> DINH | N27: 19 | X27: =IF(P27<NOW(),1,0) -> 1 | Z27: =IF(Z$8=$R27,-$T27,0)+IF(Z$8=$S27,$T27,0) -> 0 | AA27: =IF(AA$8=$R27,-$T27,0)+IF(AA$8=$S27,$T27,0) -> 0 | AB27: =IF(AB$8=$R27,-$T27,0)+IF(AB$8=$S27,$T27,0) -> 0 | AC27: =IF(AC$8=$R27,-$T27,0)+IF(AC$8=$S27,$T27,0) -> 0 | AD27: =IF(AD$8=$R27,-$T27,0)+IF(AD$8=$S27,$T27,0) -> 0 | AE27: =IF(AE$8=$R27,-$T27,0)+IF(AE$8=$S27,$T27,0) -> 0 | AF27: =IF(AF$8=$R27,-$T27,0)+IF(AF$8=$S27,$T27,0) -> 0 | AG27: =IF(AG$8=$R27,-$T27,0)+IF(AG$8=$S27,$T27,0) -> 0 | ... AK27: =IF(AK$8=$R27,-$T27,0)+IF(AK$8=$S27,$T27,0) -> 0
A28: 1 | C28: =C9 | D28: =D9 -> CONTA CORRENTE BANCO 1 | E28: =SUMIF(OFFSET($Z$9:$Z$88,0,A28-1),">0") -> 0 | F28: =SUMIF(OFFSET($Z$9:$Z$88,0,A28-1),"<0") -> 0 | G28: =SUM(E28:F28) -> 0 | J28: =NOT(ISERR(SEARCH(J$27,$C28))) -> FALSE | K28: =NOT(ISERR(SEARCH(K$27,$C28))) -> FALSE | L28: =NOT(ISERR(SEARCH(L$27,$C28))) -> FALSE | N28: 20 | X28: =IF(P28<NOW(),1,0) -> 1 | Z28: =IF(Z$8=$R28,-$T28,0)+IF(Z$8=$S28,$T28,0) -> 0 | AA28: =IF(AA$8=$R28,-$T28,0)+IF(AA$8=$S28,$T28,0) -> 0 | AB28: =IF(AB$8=$R28,-$T28,0)+IF(AB$8=$S28,$T28,0) -> 0 | AC28: =IF(AC$8=$R28,-$T28,0)+IF(AC$8=$S28,$T28,0) -> 0 | AD28: =IF(AD$8=$R28,-$T28,0)+IF(AD$8=$S28,$T28,0) -> 0 | AE28: =IF(AE$8=$R28,-$T28,0)+IF(AE$8=$S28,$T28,0) -> 0 | AF28: =IF(AF$8=$R28,-$T28,0)+IF(AF$8=$S28,$T28,0) -> 0 | AG28: =IF(AG$8=$R28,-$T28,0)+IF(AG$8=$S28,$T28,0) -> 0 | ... AK28: =IF(AK$8=$R28,-$T28,0)+IF(AK$8=$S28,$T28,0) -> 0
A29: 2 | C29: =C10 -> INV1 | D29: =D10 -> POUPANÇA BANCO 1 | E29: =SUMIF(OFFSET($Z$9:$Z$88,0,A29-1),">0") -> 0 | F29: =SUMIF(OFFSET($Z$9:$Z$88,0,A29-1),"<0") -> 0 | G29: =SUM(E29:F29) -> 0 | J29: =NOT(ISERR(SEARCH(J$27,$C29))) -> FALSE | K29: =NOT(ISERR(SEARCH(K$27,$C29))) -> TRUE | L29: =NOT(ISERR(SEARCH(L$27,$C29))) -> FALSE | N29: 21 | X29: =IF(P29<NOW(),1,0) -> 1 | Z29: =IF(Z$8=$R29,-$T29,0)+IF(Z$8=$S29,$T29,0) -> 0 | AA29: =IF(AA$8=$R29,-$T29,0)+IF(AA$8=$S29,$T29,0) -> 0 | AB29: =IF(AB$8=$R29,-$T29,0)+IF(AB$8=$S29,$T29,0) -> 0 | AC29: =IF(AC$8=$R29,-$T29,0)+IF(AC$8=$S29,$T29,0) -> 0 | AD29: =IF(AD$8=$R29,-$T29,0)+IF(AD$8=$S29,$T29,0) -> 0 | AE29: =IF(AE$8=$R29,-$T29,0)+IF(AE$8=$S29,$T29,0) -> 0 | AF29: =IF(AF$8=$R29,-$T29,0)+IF(AF$8=$S29,$T29,0) -> 0 | AG29: =IF(AG$8=$R29,-$T29,0)+IF(AG$8=$S29,$T29,0) -> 0 | ... AK29: =IF(AK$8=$R29,-$T29,0)+IF(AK$8=$S29,$T29,0) -> 0
