Workbook

Sheet Previsão Orçamentária 
B2: CONDOMINIO VILLAS DE CASTILLA I
B3: DESPESAS ORDINÁRIAS | C3: CUSTO IND. | D3: Prev. Orç Mensal | E3: N° | F3: Prev. Orç Anual
B4: Pessoal | C4: =SUM(C5:C9) -> 89.174183 | D4: =SUM(D5:D9) -> 22561.068 | E4: =SUM(E5:E9) -> 60 | F4: =SUM(F5:F9) -> 270732.82 | I4: Descrição | J4: Gasto Real | K4: Previsto | L4: Variação
B5: SÍNDICO | C5: =D5/253 -> 7.541502 | D5: ='Folha de Pagamento'!M34 -> 1908 | E5: 12 | F5: =(D5*E5) -> 22896 | I5: Cto Portaria | J5: 60808.717 | K5: 60900 | L5: =K5-J5 -> 91.2826
B6: Funcionarios (Portaria) | C6: =D6/253 -> 23.003953 | D6: ='Folha de Pagamento'!M32+'Folha de Pagamento'!M33 -> 5820 | E6: 12 | F6: =(D6*E6) -> 69840
B7: Funcionarios condomínio (Serviços Gerais) | C7: =D7/253 -> 8.5217391 | D7: ='Folha de Pagamento'!M30 -> 2156 | E7: 12 | F7: =(D7*E7) -> 25872
B8: Funcionarios condomínio (Zelador) | C8: =D8/253 -> 7.9051383 | D8: ='Folha de Pagamento'!M31 -> 2000 | E8: 12 | F8: =(D8*E8) -> 24000
B9: Tributos sobre Folha | C9: =D9/253 -> 42.201851 | D9: ='Folha de Pagamento'!N35 -> 10677.068 | E9: 12 | F9: =(D9*E9) -> 128124.82 | I9: Cto Limpeza | J9: 36840.718 | K9: 30900 | L9: =K9-J9 -> -5940.718
B10: Segurança Patrimonial E Manutenção | C10: =D10/253 -> 47.332016 | D10: =SUM(D11:D31) -> 11975 | E10: =SUM(E11:E31) -> 252 | F10: =SUM(F11:F31) -> 143700 | I10: Admin | J10: 5979.07 | K10: 5880 | L10: =K10-J10 -> -99.07
B11: CTO JARDIM | C11: =D11/253 -> 7.9051383 | D11: 2000 | E11: 12 | F11: =D11*E11 -> 24000 | I11: Manutenção | J11: 0 | K11: 1200 | L11: =K11-J11 -> 1200
B12: PH CAIXA DAGUA, DESINSETIZAÇÃO E DESRATIFICAÇÃO, MANUTENÇÃO | C12: =D12/253 -> 1.9762846 | D12: 500 | E12: 12 | F12: =D12*E12 -> 6000 | I12: Extintores | J12: 1470 | K12: 360 | L12: =K12-J12 -> -1110
B13: MANUTENÇÃO ELEVADOR | C13: =D13/253 -> 11.462451 | D13: 2900 | E13: 12 | F13: =D13*E13 -> 34800 | I13: Custo Eventual | J13: 0 | K13: =3000+((90*110)*2) -> 22800 | L13: =K13-J13 -> 22800
B14: PEÇAS ELEVADOR | C14: =D14/253 -> 1.9762846 | D14: 500 | E14: 12 | F14: =D14*E14 -> 6000
B15: LIMPEZA E SUCÇÃO DE CAIXAS DE GORDURA E LODO BIOLÓGICO | C15: =D15/253 -> 0.98814229 | D15: 250 | E15: 12 | F15: =D15*E15 -> 3000 | I15: Controles Portão | J15: 0 | K15: 0 | L15: =K15-J15 -> 0
B16: MANUTENÇÃO DO MOTOR / SENSORES E TRILHOS DO PORTÃO | C16: =D16/253 -> 1.5810277 | D16: 400 | E16: 12 | F16: =D16*E16 -> 4800 | I16: Móveis | J16: 230 | K16: 0 | L16: =K16-J16 -> -230
B17: COMPRA DE LÂMPADAS E MAT ELÊTRICOS (LED)/PEÇAS | C17: =D17/253 -> 1.9762846 | D17: 500 | E17: 12 | F17: =D17*E17 -> 6000 | I17: Lixeiras | J17: 0 | K17: 0 | L17: =K17-J17 -> 0
B18: MATERIAL DE LIMPEZA | C18: =D18/253 -> 2.3715415 | D18: 600 | E18: 12 | F18: =D18*E18 -> 7200
B19: RECARGA DOS EXTINTORES/TESTES HIDROSTÁSTICOS DE MANGUEIRAS | C19: =D19/253 -> 1.9762846 | D19: 500 | E19: 12 | F19: =D19*E19 -> 6000 | I19: Locação | J19: 0 | K19: 0 | L19: =K19-J19 -> 0
B20: MANUTENÇÃO PLAYGROUND (MATERIAL E M.O.) | C20: =D20/253 -> 0.39525692 | D20: 100 | E20: 12 | F20: =D20*E20 -> 1200 | I20: Honorários Cobrança | J20: 336.67 | K20: 0 | L20: =K20-J20 -> -336.67
B21: CONSERTO DE FECHADURAS E ACESSORIOS | C21: =D21/253 -> 0.79051383 | D21: 200 | E21: 12 | F21: =D21*E21 -> 2400 | I21: Piscina | J21: 700 | K21: 0 | L21: =K21-J21 -> -700
B22: LOCAÇÃO DE CAÇAMBAS (PARA RETIRADA DOS LIXOS DA MANUTENÇÃO DO JARDIM) | C22: =D22/253 -> 0.79051383 | D22: 200 | E22: 12 | F22: =D22*E22 -> 2400 | I22: Impostos | J22: 1889.03 | K22: 0 | L22: =K22-J22 -> -1889.03
B23: MATERIAL MANUTENÇÃO PORTAS E VIDROS | C23: =D23/253 -> 0.79051383 | D23: 200 | E23: 12 | F23: =D23*E23 -> 2400 | I23: Esgoto | J23: 400 | K23: 0 | L23: =K23-J23 -> -400
B24: LIMPEZA DE AR CONDICIONADO PORTARIA (2 LIMPEZAS ANUAIS) | C24: =D24/253 -> 0.098814229 | D24: 25 | E24: 12 | F24: =D24*E24 -> 300 | I24: Devolução pgto a maior | J24: 269.04 | K24: 0 | L24: =K24-J24 -> -269.04
B25: PLANO DE COMBATE Á INCÊNDIO- CURSO BRIGADISTA | C25: =D25/253 -> 0.98814229 | D25: 250 | E25: 12 | F25: =D25*E25 -> 3000 | I25: Material Psicina | J25: 644 | K25: 0 | L25: =K25-J25 -> -644
B26: RENOVAÇÃO ALVARÁ PPCI (ANUAL) | C26: =D26/253 -> 0.98814229 | D26: 250 | E26: 12 | F26: =D26*E26 -> 3000 | I26: Desinsetização | J26: 445 | K26: 0 | L26: =K26-J26 -> -445
B27: MANUTENÇÃO CERCA ELÉTRICA | C27: =D27/253 -> 0.98814229 | D27: 250 | E27: 12 | F27: =D27*E27 -> 3000
B28: MANUTENÇÃO CÂMERAS DE SEGURANÇA | C28: =D28/253 -> 3.9525692 | D28: 1000 | E28: 12 | F28: =D28*E28 -> 12000
B29: SERRALHEIRO | C29: =D29/253 -> 1.3833992 | D29: 350 | E29: 12 | F29: =D29*E29 -> 4200
B30: MANUTENÇÃO CASA DE MÁQUINAS - BOMBA DA CX D'AGUA | C30: =D30/253 -> 1.9762846 | D30: 500 | E30: 12 | F30: =D30*E30 -> 6000
B31: MANUTENÇÕES DIVERSAS | C31: =D31/253 -> 1.9762846 | D31: 500 | E31: 12 | F31: =D31*E31 -> 6000
B32: Administrativas | C32: =D32/253 -> 63.229249 | D32: =SUM(D33:D46) -> 15997 | E32: =SUM(E33:E46) -> 101 | F32: =SUM(F33:F46) -> 170314
B33: ADMINISTRADORA | C33: =D33/253 -> 9.0909091 | D33: 2300 | E33: 12 | F33: =D33*E33 -> 27600
B34: DESPESAS ASSEMBLÉIAS DE CONDOMÍNIO (PROJETANDO 3 ASSEMBLÉIAS ANUAIS) | C34: =D34/253 -> 2.2134387 | D34: 560 | E34: 3 | F34: =D34*E34 -> 1680
B35: DESPESAS COPIAS | C35: =D35/253 -> 0.39525692 | D35: 100 | E35: 12 | F35: =D35*E35 -> 1200
B36: TARIFA BANCARIA | C36: =D36/253 -> 2.3201581 | D36: 587 | E36: 12 | F36: =D36*E36 -> 7044
B37: CERTIFICADO DIGITAL (ANUAL) | C37: =D37/253 -> 0.83003953 | D37: 210 | E37: 1 | F37: =D37*E37 -> 210
B38: CARTORIO | C38: =D38/253 -> 0.4743083 | D38: 120 | E38: 3 | F38: =D38*E38 -> 360
B39: ENERGIA ELÉTRICA | C39: =D39/253 -> 17.786561 | D39: 4500 | E39: 12 | F39: =D39*E39 -> 54000
B40: ÁGUA E ESGOTO | C40: =D40/253 -> 7.9051383 | D40: 2000 | E40: 12 | F40: =D40*E40 -> 24000
B41: GÁS | C41: =D41/253 -> 13.833992 | D41: 3500 | E41: 12 | F41: =D41*E41 -> 42000
...

Sheet Folha de Pagamento
B2: CUSTOS TRABALHISTAS CONDOMÍNIOS | F2: CUSTOS TRABALHISTAS CONDOMÍNIOS | J2: CUSTOS TRABALHISTAS CONDOMÍNIOS
B4: Serviços Gerais | F4: Zelador | J4: Sindico(a)
B5: Sobre um salário base em horas | C5: (%) | D5: (%) | F5: Sobre um salário base em horas | G5: (%) | H5: (%) | J5: Sobre um salário base em horas | K5: (%) | L5: (%)
B6: 13º salário | D6: =1/12 -> 0.083333333 | F6: 13º salário | H6: =1/12 -> 0.083333333 | J6: 13º salário | L6: 0
B7: Férias | D7: =1/12*1.3333333 -> 0.11111111 | F7: Férias | H7: =1/12*1.3333333 -> 0.11111111 | J7: Férias | L7: 0
B8: INSS | C8: 0.2 | F8: INSS | G8: 0.2 | J8: INSS (Patronal) | K8: 0.2
B9: SAT/até | C9: 0.03 | F9: SAT/até | G9: 0.03 | J9: INSS (Sindico) | K9: 0.11
B10: Sal.Educação | C10: 0.025 | F10: Sal.Educação | G10: 0.025 | J10: Sal.Educação | K10: 0
B11: INCRA/SENAI/SESI/SEBRAE | C11: =0.2%+1%+1.5%+0.6% -> 0.033 | F11: INCRA/SENAI/SESI/SEBRAE | G11: =0.2%+1%+1.5%+0.6% -> 0.033 | J11: INCRA/SENAI/SESI/SEBRAE | K11: 0
B12: FGTS | C12: 0.08 | F12: FGTS | G12: 0.08 | J12: FGTS | K12: 0
B13: FGTS/Resc. | C13: =8%*50% -> 0.04 | F13: FGTS/Resc. | G13: =8%*50% -> 0.04 | J13: FGTS/Resc. | K13: 0
B14: Total Previdenciário | D14: =SUM(C8:C13) -> 0.408 | F14: Total Previdenciário | H14: =SUM(G8:G13) -> 0.408 | J14: Total Previdenciário | L14: =SUM(K8:K13) -> 0.31
B15: Previdenciário s/13º e Férias | D15: =D14*(D7+D6) -> 0.079333332 | F15: Previdenciário s/13º e Férias | H15: =H14*(H7+H6) -> 0.079333332 | J15: Previdenciário s/13º e Férias | L15: =L14*(L7+L6) -> 0
B16: Vale Transporte | D16: 0.06 | F16: Vale Transporte | H16: 0.06 | J16: Vale Transporte | L16: 0
B17: Pis S/ Folha | D17: 0.01 | F17: Pis S/ Folha | H17: 0.01 | J17: Pis S/ Folha | L17: 0.01
B18: SOMA BÁSICO | D18: =SUM(D6:D17) -> 0.75177777 | F18: SOMA BÁSICO | H18: =SUM(H6:H17) -> 0.75177777 | J18: SOMA BÁSICO | L18: =SUM(L6:L17) -> 0.32
B19: Salário/Mensal | D19: 1000 | F19: Salário/Mensal | H19: 2000 | J19: Salário/Mensal | L19: =954*2 -> 1908
B20: Encargos sobre o salário mensal | D20: =D19*D18 -> 751.77777 | F20: Encargos sobre o salário mensal | H20: =H19*H18 -> 1503.5555 | J20: Encargos sobre o salário mensal | L20: =L19*L18 -> 610.56
B21: Vale Transporte | D21: 192.4 | F21: Vale Transporte | H21: 192.4
B22: Vale Alimentação | D22: =22*10 -> 220 | F22: Vale Alimentação | H22: =22*10 -> 220
B23: Total Custo/Mensal | D23: =SUM(D19:D22) -> 2164.1778 | F23: Total Custo/Mensal | H23: =SUM(H19:H22) -> 3915.9555 | J23: Total Custo/Mensal | L23: =SUM(L19:L20) -> 2518.56
B25: CUSTOS TRABALHISTAS CONDOMÍNIOS | F25: CUSTOS TRABALHISTAS CONDOMÍNIOS
B27: Porteiro Diurno | F27: Porteiro Noturno
B28: Sobre um salário base em horas | C28: (%) | D28: (%) | F28: Sobre um salário base em horas | G28: (%) | H28: (%)
B29: 13º salário | D29: =1/12 -> 0.083333333 | F29: 13º salário | H29: =1/12 -> 0.083333333 | J29: Cargo | K29: Qtde | L29: Salário Base | M29: Total Salario | N29: Impostos
B30: Férias | D30: =1/12*1.3333333 -> 0.11111111 | F30: Férias | H30: =1/12*1.3333333 -> 0.11111111 | J30: Serviços Gerais | K30: 2 | L30: 1078 | M30: =K30*L30 -> 2156 | N30: =SUM(D20:D22)*K30 -> 2328.3555
B31: INSS | C31: 0.2 | F31: INSS | G31: 0.2 | J31: Zeladoria | K31: 1 | L31: 2000 | M31: =K31*L31 -> 2000 | N31: =SUM(H20:H22)*K31 -> 1915.9555
B32: SAT/até | C32: 0.03 | F32: SAT/até | G32: 0.03 | J32: Porteiro Diurno | K32: 2 | L32: 1206 | M32: =K32*L32 -> 2412 | N32: =SUM(D43:D45)*K32 -> 2661.0874
B33: Sal.Educação | C33: 0.025 | F33: Sal.Educação | G33: 0.025 | J33: Porteiro Noturno | K33: 2 | L33: 1704 | M33: =K33*L33 -> 3408 | N33: =SUM(H43:H45)*K33 -> 3161.1098
B34: INCRA/SENAI/SESI/SEBRAE | C34: =0.2%+1%+1.5%+0.6% -> 0.033 | F34: INCRA/SENAI/SESI/SEBRAE | G34: =0.2%+1%+1.5%+0.6% -> 0.033 | J34: Sindico(a) | K34: 1 | L34: 1908 | M34: 1908 | N34: =L20*K34 -> 610.56
B35: FGTS | C35: 0.08 | F35: FGTS | G35: 0.08 | J35: Total | K35: =SUM(K30:K34) -> 8 | L35: =SUM(L30:L34) -> 7896 | M35: =SUM(M30:M34) -> 11884 | N35: =SUM(N30:N34) -> 10677.068
B36: FGTS/Resc. | C36: =8%*50% -> 0.04 | F36: FGTS/Resc. | G36: =8%*50% -> 0.04 | N36: =M35+N35 -> 22561.068
B37: Total Previdenciário | D37: =SUM(C31:C36) -> 0.408 | F37: Total Previdenciário | H37: =SUM(G31:G36) -> 0.408
B38: Previdenciário s/13º e Férias | D38: =D37*(D30+D29) -> 0.079333332 | F38: Previdenciário s/13º e Férias | H38: =H37*(H30+H29) -> 0.079333332
B39: Vale Transporte | D39: 0.06 | F39: Vale Transporte | H39: 0.06
B40: Pis S/ Folha | D40: 0.01 | F40: Pis S/ Folha | H40: 0.01
B41: SOMA BÁSICO | D41: =SUM(D29:D40) -> 0.75177777 | F41: SOMA BÁSICO | H41: =SUM(H29:H40) -> 0.75177777
B42: Salário/Mensal | D42: 1349.26 | F42: Salário/Mensal | H42: 1681.82
B43: Encargos sobre o salário mensal | D43: =D42*D41 -> 1014.3437 | F43: Encargos sobre o salário mensal | H43: =H42*H41 -> 1264.3549
B44: Vale Transporte | D44: 96.2 | F44: Vale Transporte | H44: 96.2
...

Sheet APLICAÇÕES
B2: APLICAÇÃO - FUNDO RESERVA
B3: 43070 | C3: 43101 | D3: 43132 | E3: 43160 | F3: 43191 | G3: 43221 | H3: 43252 | I3: 43282 | J3: 43313 | K3: 43344 | L3: 43374 | M3: 43405 | N3: 43435
B4: =15.92*256 -> 4075.52 | C4: =15.92*256 -> 4075.52 | D4: =15.92*256 -> 4075.52 | E4: =15.92*256 -> 4075.52 | F4: 5053.31 | G4: 5053.31 | H4: 5053.31 | I4: 5053.31 | J4: 5053.31 | K4: 5053.31 | L4: 5053.31 | M4: 5053.31 | N4: 5053.31
B5: =B4 -> 4075.52 | C5: =B4+C4 -> 8151.04 | D5: =C5+D4 -> 12226.56 | E5: =D5+E4 -> 16302.08 | F5: =E5+F4 -> 21355.39 | G5: =F5+G4 -> 26408.7 | H5: =G5+H4 -> 31462.01 | I5: =H5+I4 -> 36515.32 | J5: =I5+J4 -> 41568.63 | K5: =J5+K4 -> 46621.94 | ... N5: =M5+N4 -> 61781.87
B7: FÉRIAS E 13° E FUNCIONARIO SUBSTITUTO
B8: 43070 | C8: 43101 | D8: 43132 | E8: 43160 | F8: 43191 | G8: 43221 | H8: 43252 | I8: 43282 | J8: 43313 | K8: 43344 | L8: 43374 | M8: 43405 | N8: 43435
B9: 0 | C9: 0 | D9: 4267.23 | E9: 4267.23 | F9: 4267.23 | G9: 4267.23 | H9: 4267.23 | I9: 4267.23 | J9: 4267.23 | K9: 4267.23 | L9: 4267.23 | M9: 4267.23 | N9: 4267.23
D10: =D9 -> 4267.23 | E10: =D9+E9 -> 8534.46 | F10: =E10+F9 -> 12801.69 | G10: =F10+G9 -> 17068.92 | H10: =G10+H9 -> 21336.15 | I10: =H10+I9 -> 25603.38 | J10: =I10+J9 -> 29870.61 | K10: =J10+K9 -> 34137.84 | L10: =K10+L9 -> 38405.07 | M10: =L10+M9 -> 42672.3 | N10: =M10+N9 -> 46939.53
B11: 20100 | C11: =B11*2 -> 40200 | E11: % | N11: =SUM(B9:N9) -> 46939.53
B12: =B11*E12% -> 5503.38 | C12: =B12*2 -> 11006.76 | E12: 27.38
B13: =B11+B12 -> 25603.38 | C13: =C11+C12 -> 51206.76 | D13: =C13/12 -> 4267.23
B15: RECARGA DOS EXTINTORES/TESTES HIDROSTÁSTICOS DE MANGUEIRAS | E15: 500
B16: LIMPEZA DE AR CONDICIONADO PORTARIA (2 LIMPEZAS ANUAIS) | E16: 25
B17: PLANO DE COMBATE Á INCÊNDIO- CURSO BRIGADISTA | E17: 250
B18: RENOVAÇÃO ALVARÁ PPCI (ANUAL) | E18: 250 | F18: =SUM(E15:E18) -> 1025 | G18: =SUM(F15:F18) -> 1025 | H18: =SUM(G15:G18) -> 1025 | I18: =SUM(H15:H18) -> 1025 | J18: =SUM(I15:I18) -> 1025 | K18: =SUM(J15:J18) -> 1025 | L18: =SUM(K15:K18) -> 1025 | M18: =SUM(L15:L18) -> 1025 | N18: =SUM(M15:M18) -> 1025
B20: TOTAL MENSAL
B21: 43070 | C21: 43101 | D21: 43132 | E21: 43160 | F21: 43191 | G21: 43221 | H21: 43252 | I21: 43282 | J21: 43313 | K21: 43344 | L21: 43374 | M21: 43405 | N21: 43435
B22: =B5+B10 -> 4075.52 | C22: =C5+C10 -> 8151.04 | D22: =D5+D10 -> 16493.79 | E22: =E5+E10 -> 24836.54 | F22: =F5+F10+F18 -> 35182.08 | G22: =G5+G10+G18 -> 44502.62 | H22: =H5+H10+H18 -> 53823.16 | I22: =I5+I10+I18 -> 63143.7 | J22: =J5+J10+J18 -> 72464.24 | K22: =K5+K10+K18 -> 81784.78 | L22: =L5+L10+L18 -> 91105.32 | M22: =M5+M10+M18 -> 100425.86 | N22: =N5+N10+N18 -> 109746.4
N23: =N5+N11 -> 108721.4
G27: =G9+G4 -> 9320.54
G28: =G27+1500 -> 10820.54

Sheet taxa distribuidia por n de apto
A1: 2018 | D1: 2017 | G1: PROJEÇÃO DO BOLETO
A2: SUBTOTAL | C2: ='Previsão Orçamentária '!C47 -> 199.73545 | D2: =SUM(D3:D5) -> 0 | J2: VALOR
A3: Fundo de reserva (fixo) | C3: ='Previsão Orçamentária '!D48/254 -> 19.894909 | G3: VALOR DO CONDOMINIO | J3: ='Previsão Orçamentária '!C47 -> 199.73545
A4: Fundo de reserva Equipagem (fixo) | C4: 0 | G4: AGUA | J4: 0
A5: Taxa sem fundo de reserva (fixo) | C5: =('Previsão Orçamentária '!D47+'taxa distribuidia por n de apto'!D52)/254 -> 198.94909 | G5: TAXA EXTRA | J5: 0
A6: Inadimplência | B6: 0.1 | C6: =C5*10% -> 19.894909 | D6: =D2*$B$6 -> 0 | G6: FUNDO DE RESERVA | J6: =C3 -> 19.894909
A7: TAXA | C7: =C2+C6+C3 -> 239.52527 | D7: =D2+D6 -> 0 | G7: MARGEM PARA CAIXA | J7: 0
G8: FUNDO DE INADIMPLÊNCIA | J8: 0
G9: TOTAL DO BOLETO DE MARÇO | J9: =SUM(J3:J8) -> 219.63036
G10: CONTROLE ADICIONAL | J10: 0
A11: AQUISIÇÃO DOS EQUIPAMENTOS QUIOSQUES | G11: TOTAL COM CONTROLE | J11: =SUM(J9:J10) -> 219.63036
A12: 4 - FREEZER OU GELADEIRA(QUIOSQUE) | B12: =C12/256 -> 2.6041667 | C12: =F12/E12 -> 666.66667 | E12: 6 | F12: 4000
A13: 8 - JOGO DE MESA DE PLASTICO(QUIOSQUE) | B13: =C13/256 -> 0.98958333 | C13: =F13/E13 -> 253.33333 | E13: 6 | F13: 1520
A14: ARMARIO (QUIOSQUE) | B14: =C14/256 -> 1.3020833 | C14: =F14/E14 -> 333.33333 | E14: 6 | F14: 2000
A15: 9 - LIXEIRAS EXTERNAS /4 - QUIOSQUE | B15: =C15/256 -> 1.2890625 | C15: =F15/E15 -> 330 | E15: 6 | F15: 1980
A16: TOTAL | B16: =SUM(B12:B15) -> 6.1848958 | C16: =SUM(C12:C15) -> 1583.3333 | D16: =SUM(D12:D15) -> 0 | E16: - | F16: =SUM(F12:F15) -> 9500

Sheet Previsão estraordinária
B3: SPAZIO PORTO CRISTAL
B4: DESPESAS EXTRAORDINÁRIAS | C4: Previsto Orçado | D4: N° | E4: Prev. Orç Mensal
B5: Aquisições
B6: SEGURANÇA | C6: =SUM(C7:C12) -> 21813 | E6: =SUM(E7:E13) -> 228.045
B7: Muro | C7: 5063 | D7: 110 | E7: =(C7/D7)*15%+(C7/D7) -> 52.931364
B8: Cerca | D8: 110 | E8: =(C8/D8)*15%+(C8/D8) -> 0
B9: Câmeras | C9: 8000 | D9: 110 | E9: =(C9/D9)*15%+(C9/D9) -> 83.636364
B10: Iluminação | C10: 5000 | D10: 110 | E10: =(C10/D10)*15%+(C10/D10) -> 52.272727
B11: Alarme | C11: 3750 | D11: 110 | E11: =(C11/D11)*15%+(C11/D11) -> 39.204545
B12: cercado | D12: 110 | E12: =(C12/D12)*15%+(C12/D12) -> 0
B13: Adesivo para carros RFID - Automatech | D13: 110
B14: ACESSIBILIDADE | C14: =SUM(C15:C21) -> 21550 | E14: =SUM(E15:E21) -> 170.40909
B15: Faixa Pedestre - entrada condominio | C15: =700+600 -> 1300 | D15: 110 | E15: =((C15/D15)*15%+(C15/D15))*0 -> 0
B16: Tapetes | C16: 3950 | D16: 110 | E16: =((C16/D16)*15%+(C16/D16))*0 -> 0
B17: Toldos entrada Blocos (policarbonato)- Toldo zeladoria e salão de festas (5) | C17: =860*5 -> 4300 | D17: 110 | E17: =(C17/D17)*15%+(C17/D17) -> 44.954545
B18: Telhado Portaria e caixa de correspondência | C18: 12000 | D18: 110 | E18: =(C18/D18)*15%+(C18/D18) -> 125.45455
B19: Garagem (telhado (policarbonato) | D19: 110 | E19: =(C19/D19)*15%+(C19/D19) -> 0
B22: MELHORIAS | C22: =SUM(C23:C36) -> 29558 | E22: =SUM(E23:E41) -> 356.68818
B23: Pracinha e brinquedos novos | C23: 3900 | D23: 110 | E23: =(C23/D23)*15%+(C23/D23) -> 40.772727
B24: Carrinho de super 1 unidade com chave | C24: =360+130+(4*110) -> 930 | D24: 110 | E24: =(C24/D24)*15%+(C24/D24) -> 9.7227273 | F24: http://www.produtosmb.com.br/
B25: Sala Zeladoria ( porcelanato) | C25: 1600 | D25: 110 | E25: =(C25/D25)*15%+(C25/D25) -> 16.727273
B26: Sala Zeladoria ( parede) | C26: 1500 | D26: 110 | E26: =(C26/D26)*15%+(C26/D26) -> 15.681818
B27: Ampliação Portaria ( cozinha) | C27: 2571 | D27: 110 | E27: =(C27/D27)*15%+(C27/D27) -> 26.878636
B28: Chão próximo portaria e zeladoria Pedra caxambu e manutenções | C28: =116*10 -> 1160 | D28: 110 | E28: =(C28/D28)*15%+(C28/D28) -> 12.127273
B29: Cadeiras de praias (piscina) (3) | C29: =199*3 -> 597 | D29: 110 | E29: =(C29/D29)*15%+(C29/D29) -> 6.2413636
B30: Cadeiras Brancas ( beira da Piscina) (10) | C30: =44*10 -> 440 | D30: 110 | E30: =(C30/D30)*15%+(C30/D30) -> 4.6
B31: Mesa branca para piscina e um guarda sol | D31: 110 | E31: =(C31/D31)*15%+(C31/D31) -> 0
B32: Bancos de Jardim | C32: =900*5 -> 4500 | D32: 110 | E32: =(C32/D32)*15%+(C32/D32) -> 47.045455
B33: Churrasqueira proximo salão de festa | D33: 110 | E33: =(C33/D33)*15%+(C33/D33) -> 0
B34: Bandeja coletora coletiva para dreno- ar condicionado | D34: 110 | E34: =(C34/D34)*15%+(C34/D34) -> 0
B35: toldo para churrasqueira | C35: 12000 | D35: 110 | E35: =(C35/D35)*15%+(C35/D35) -> 125.45455
B36: Espelhos saída garagem | C36: =180*2 -> 360 | D36: 110 | E36: =((C36/D36)*15%+(C36/D36))*0 -> 0
B37: MATERIAL DE MANUTENÇÃO DE SINALIZAÇÃO ( complemento) | C37: 300 | D37: 110 | E37: =(C37/D37)*15%+(C37/D37) -> 3.1363636
B38: sala de lixo trilho | C38: 1620 | D38: 110 | E38: =(C38/D38)*15%+(C38/D38) -> 16.936364
B39: Chuveiro proximo salão de festa | D39: 110 | E39: =(C39/D39)*15%+(C39/D39) -> 0
B40: Capa protestora Elevador (2) | C40: =1500*2 -> 3000 | D40: 110 | E40: =(C40/D40)*15%+(C40/D40) -> 31.363636
D41: 110 | E41: =(C41/D41)*15%+(C41/D41) -> 0
B42: SALÃO DE FESTA/BRINCADOTECA/ACADEMIA E BICICLETÁRI0 | C42: =SUM(C43:C47) -> 36640 | E42: =SUM(E43:E48) -> 383.05455
B43: Móveis para o salão | C43: 30000 | D43: 110 | E43: =(C43/D43)*15%+(C43/D43) -> 313.63636
B44: Utensílios para Salão de Festa | C44: 5000 | D44: 110 | E44: =(C44/D44)*15%+(C44/D44) -> 52.272727
...

Sheet sugestão
C1: 0.15
A2: porta de entrada A, B, Salão de festa, zeladoria | B2: =790*5 -> 3950 | D2: =(B2*$C$1)+B2 -> 4542.5
A3: cobertura portão | B3: 1100 | D3: =(B3*$C$1)+B3 -> 1265
A4: cobertura caixa de correio | B4: 1790 | D4: =(B4*$C$1)+B4 -> 2058.5 | E4: =SUM(D2:D4) -> 7866
A5: Espaço Piscina | B5: 1508 | D5: =(B5*$C$1)+B5 -> 1734.2
A6: bicicletário | B6: 1640 | D6: =(B6*$C$1)+B6 -> 1886
A7: carrinho de compras | B7: 930 | D7: =(B7*$C$1)+B7 -> 1069.5
A8: pracinha | B8: 3900 | D8: =(B8*$C$1)+B8 -> 4485
A9: churrasqueira | B9: =649*2 -> 1298 | D9: =(B9*$C$1)+B9 -> 1492.7
A10: mesa 4 cadeiras | B10: 330 | D10: =(B10*$C$1)+B10 -> 379.5
A11: espaço churrasqueira | B11: =2300+2500 -> 4800 | D11: =(B11*$C$1)+B11 -> 5520
A12: zeladoria | B12: 2000 | D12: =(B12*$C$1)+B12 -> 2300
A13: Ampliação Portaria | B13: 2571 | D13: =(B13*$C$1)+B13 -> 2956.65
A14: pedras caxambu | B14: =116*10 -> 1160 | D14: =(B14*$C$1)+B14 -> 1334
A15: Telhado Ampliação Portaria | B15: 1100 | D15: =(B15*$C$1)+B15 -> 1265
A16: Material para Jardim | B16: 2000 | D16: =(B16*$C$1)+B16 -> 2300
A17: Ventilador Zeladoria (2) | B17: =300*2 -> 600 | D17: =(B17*$C$1)+B17 -> 690
A18: Mesa salão de Festa (4) | B18: =84*4 -> 336 | D18: =(B18*$C$1)+B18 -> 386.4
A19: Cadeira sação ( 5) | B19: =39.9*15 -> 598.5 | D19: =(B19*$C$1)+B19 -> 688.275
A20: Capa Protetora elevador | B20: =1000+1000 -> 2000 | D20: =(B20*$C$1)+B20 -> 2300
D21: =(B21*$C$1)+B21 -> 0
B22: =SUM(B2:B21) -> 33611.5 | D22: =SUM(D2:D21) -> 38653.225 | E22: =D22/110 -> 351.39295 | F22: =E22/6 -> 58.565492
E23: 110 cond | F23: 6 vezes

Sheet Rateio
A1: ='Previsão Orçamentária '!F53 -> 673706.87 | B1: =(A1/12) -> 56142.239
A2: Anual | B2: Mensal | D2: =56-4+56 -> 108 | E2: =(#REF!/D2)-F2 -> #REF!
A4: BLOCO A | G4: BLOCO B
A5: APARTAMENTOS | B5: BOXES | C5: Fração | D5: Valor Fração Ideal | E5: Quotas | F5: Valor por Quotas | G5: APARTAMENTOS | H5: BOXES | I5: Fração | J5: Valor Fração Ideal | K5: Quotas | L5: Valor por Quotas
A6: 101 | B6: 56 | C6: 0.011087 | D6: =($B$1*C6)+(655.74/108) -> 628.52067 | E6: 1 | F6: =$B$1/109 -> 515.06641 | G6: 101 | H6: 83 | I6: 0.011047 | J6: =($B$1*I6)+(655.74/108) -> 626.27498 | K6: 1 | L6: =$B$1/109 -> 515.06641
A7: 102 | B7: 57 | C7: 0.009697 | D7: =($B$1*C7)+(655.74/108) -> 550.48296 | E7: 1 | F7: =$B$1/109 -> 515.06641 | G7: 102 | H7: 84 | I7: 0.009144 | J7: =($B$1*I7)+(655.74/108) -> 519.4363 | K7: 1 | L7: =$B$1/109 -> 515.06641
A8: 103 | B8: 58 | C8: 0.009686 | D8: =($B$1*C8)+(655.74/108) -> 549.86539 | E8: 1 | F8: =$B$1/109 -> 515.06641 | G8: 103 | H8: 85 | I8: 0.009117 | J8: =($B$1*I8)+(655.74/108) -> 517.92046 | K8: 1 | L8: =$B$1/109 -> 515.06641
A9: 104 | B9: 59 | C9: 0.011179 | D9: =($B$1*C9)+(655.74/108) -> 633.68575 | E9: 1 | F9: =$B$1/109 -> 515.06641 | G9: 104 | H9: 86 | I9: 0.010819 | J9: =($B$1*I9)+(655.74/108) -> 613.47455 | K9: 1 | L9: =$B$1/109 -> 515.06641
A10: 105 | B10: zelador | C10: 0 | D10: =$B$1*C10 -> 0 | G10: 105 | H10: 87 | I10: 0.009567 | J10: =($B$1*I10)+(655.74/108) -> 543.18447 | K10: 1 | L10: =$B$1/109 -> 515.06641
A11: 106 | B11: 60 | C11: 0.008268 | D11: =($B$1*C11)+(655.74/108) -> 470.2557 | E11: 1 | F11: =$B$1/109 -> 515.06641 | G11: 106 | H11: 88 | I11: 0.006155 | J11: =($B$1*I11)+(655.74/108) -> 351.62715 | K11: 1 | L11: =$B$1/109 -> 515.06641
A12: 107 | B12: 61 | C12: 0.010045 | D12: =($B$1*C12)+(655.74/108) -> 570.02046 | E12: 1 | F12: =$B$1/109 -> 515.06641 | G12: 107 | H12: 89 | I12: 0.008535 | J12: =($B$1*I12)+(655.74/108) -> 485.24567 | K12: 1 | L12: =$B$1/109 -> 515.06641
A13: 108 | B13: salão | C13: 0 | D13: =$B$1*C13 -> 0 | G13: 108 | H13: 90 | I13: 0.011322 | J13: =($B$1*I13)+(655.74/108) -> 641.71409 | K13: 1 | L13: =$B$1/109 -> 515.06641
A14: 201 | B14: 62 | C14: 0.009491 | D14: =($B$1*C14)+(655.74/108) -> 538.91766 | E14: 1 | F14: =$B$1/109 -> 515.06641 | G14: 201 | H14: 91 | I14: 0.009491 | J14: =($B$1*I14)+(655.74/108) -> 538.91766 | K14: 1 | L14: =$B$1/109 -> 515.06641
A15: 202 | B15: 63 | C15: 0.008123 | D15: =($B$1*C15)*0 -> 0 | F15: =$B$1/109 -> 515.06641 | G15: 202 | H15: 92 | I15: 0.008123 | J15: =($B$1*I15)+(655.74/108) -> 462.11507 | K15: 1 | L15: =$B$1/109 -> 515.06641
A16: 203 | B16: 64 | C16: 0.008123 | D16: =($B$1*C16)+(655.74/108) -> 462.11507 | E16: 1 | F16: =$B$1/109 -> 515.06641 | G16: 203 | H16: 93 | I16: 0.008123 | J16: =($B$1*I16)+(655.74/108) -> 462.11507 | K16: 1 | L16: =$B$1/109 -> 515.06641
A17: 204 | B17: 65 | C17: 0.009491 | D17: =($B$1*C17)+(655.74/108) -> 538.91766 | E17: 1 | F17: =$B$1/109 -> 515.06641 | G17: 204 | H17: 94 | I17: 0.009491 | J17: =($B$1*I17)+(655.74/108) -> 538.91766 | K17: 1 | L17: =$B$1/109 -> 515.06641
A18: 205 | B18: 66 | C18: 0.009491 | D18: =($B$1*C18)+(655.74/108) -> 538.91766 | E18: 1 | F18: =$B$1/109 -> 515.06641 | G18: 205 | H18: 95 | I18: 0.009491 | J18: =($B$1*I18)+(655.74/108) -> 538.91766 | K18: 1 | L18: =$B$1/109 -> 515.06641
A19: 206 | B19: 67 | C19: 0.007921 | D19: =($B$1*C19)+(655.74/108) -> 450.77434 | F19: =$B$1/109 -> 515.06641 | G19: 206 | H19: 96 | I19: 0.007921 | J19: =($B$1*I19)+(655.74/108) -> 450.77434 | K19: 1 | L19: =$B$1/109 -> 515.06641
A20: 207 | B20: 68 | C20: 0.007921 | D20: =($B$1*C20)+(655.74/108) -> 450.77434 | E20: 1 | F20: =$B$1/109 -> 515.06641 | G20: 207 | H20: 97 | I20: 0.007921 | J20: =($B$1*I20)+(655.74/108) -> 450.77434 | K20: 1 | L20: =$B$1/109 -> 515.06641
A21: 208 | B21: 69 | C21: 0.009491 | D21: =($B$1*C21)+(655.74/108) -> 538.91766 | E21: 1 | F21: =$B$1/109 -> 515.06641 | G21: 208 | H21: 98 | I21: 0.009491 | J21: =($B$1*I21)+(655.74/108) -> 538.91766 | K21: 1 | L21: =$B$1/109 -> 515.06641
A22: 301 | B22: 70 | C22: 0.009491 | D22: =($B$1*C22)+(655.74/108) -> 538.91766 | E22: 1 | F22: =$B$1/109 -> 515.06641 | G22: 301 | H22: 1 | I22: 0.009912 | J22: =($B$1*I22)+(655.74/108) -> 562.55354 | K22: 1 | L22: =$B$1/109 -> 515.06641
A23: 302 | B23: 71 | C23: 0.008123 | D23: =($B$1*C23)+(655.74/108) -> 462.11507 | E23: 1 | F23: =$B$1/109 -> 515.06641 | G23: 302 | H23: 99 | I23: 0.008123 | J23: =($B$1*I23)+(655.74/108) -> 462.11507 | K23: 1 | L23: =$B$1/109 -> 515.06641
A24: 303 | B24: 72 | C24: 0.008123 | D24: =($B$1*C24)+(655.74/108) -> 462.11507 | E24: 1 | F24: =$B$1/109 -> 515.06641 | G24: 303 | H24: 100 | I24: 0.008123 | J24: =($B$1*I24)+(655.74/108) -> 462.11507 | K24: 1 | L24: =$B$1/109 -> 515.06641
A25: 304 | B25: 29 | C25: 0.009912 | D25: =($B$1*C25)+(655.74/108) -> 562.55354 | E25: 1 | F25: =$B$1/109 -> 515.06641 | G25: 304 | H25: 2 | I25: 0.009912 | J25: =($B$1*I25)+(655.74/108) -> 562.55354 | K25: 1 | L25: =$B$1/109 -> 515.06641
A26: 305 | B26: 30 | C26: 0.009912 | D26: =($B$1*C26)+(655.74/108) -> 562.55354 | E26: 1 | F26: =$B$1/109 -> 515.06641 | G26: 305 | H26: 3 | I26: 0.009912 | J26: =($B$1*I26)+(655.74/108) -> 562.55354 | K26: 1 | L26: =$B$1/109 -> 515.06641
A27: 306 | B27: 73 | C27: 0.007921 | D27: =($B$1*C27)+(655.74/108) -> 450.77434 | E27: 1 | F27: =$B$1/109 -> 515.06641 | G27: 306 | H27: 101 | I27: 0.007921 | J27: =($B$1*I27)*0 -> 0 | K27: 1 | L27: =($B$1/108)*0 -> 0
A28: 307 | B28: 74 | C28: 0.007921 | D28: =($B$1*C28)+(655.74/108) -> 450.77434 | E28: 1 | F28: =$B$1/109 -> 515.06641 | G28: 307 | H28: 102 | I28: 0.007921 | J28: =($B$1*I28)+(655.74/108) -> 450.77434 | K28: 1 | L28: =$B$1/109 -> 515.06641
A29: 308 | B29: 31 | C29: 0.009912 | D29: =($B$1*C29)+(655.74/108) -> 562.55354 | E29: 1 | F29: =$B$1/109 -> 515.06641 | G29: 308 | H29: 4 | I29: 0.009912 | J29: =($B$1*I29)+(655.74/108) -> 562.55354 | K29: 1 | L29: =$B$1/109 -> 515.06641
A30: 401 | B30: 32 | C30: 0.009912 | D30: =($B$1*C30)+(655.74/108) -> 562.55354 | E30: 1 | F30: =$B$1/109 -> 515.06641 | G30: 401 | H30: 5 | I30: 0.009912 | J30: =($B$1*I30)+(655.74/108) -> 562.55354 | K30: 1 | L30: =$B$1/109 -> 515.06641
A31: 402 | B31: 75 | C31: 0.008123 | D31: =($B$1*C31)+(655.74/108) -> 462.11507 | E31: 1 | F31: =$B$1/109 -> 515.06641 | G31: 402 | H31: 103 | I31: 0.008123 | J31: =($B$1*I31)+(655.74/108) -> 462.11507 | K31: 1 | L31: =$B$1/109 -> 515.06641
A32: 403 | B32: 76 | C32: 0.008123 | D32: =($B$1*C32)+(655.74/108) -> 462.11507 | E32: 1 | F32: =$B$1/109 -> 515.06641 | G32: 403 | H32: 104 | I32: 0.008123 | J32: =($B$1*I32)+(655.74/108) -> 462.11507 | K32: 1 | L32: =$B$1/109 -> 515.06641
A33: 404 | B33: 33 | C33: 0.009912 | D33: =($B$1*C33)+(655.74/108) -> 562.55354 | E33: 1 | F33: =$B$1/109 -> 515.06641 | G33: 404 | H33: 6 | I33: 0.009912 | J33: =($B$1*I33)+(655.74/108) -> 562.55354 | K33: 1 | L33: =$B$1/109 -> 515.06641
A34: 405 | B34: 34 | C34: 0.009912 | D34: =($B$1*C34)+(655.74/108) -> 562.55354 | E34: 1 | F34: =$B$1/109 -> 515.06641 | G34: 405 | H34: 7/COB | I34: 0.009912 | J34: =($B$1*I34)+(655.74/108) -> 562.55354 | K34: 1 | L34: =$B$1/109 -> 515.06641
A35: 406 | B35: 77 | C35: 0.007921 | D35: =($B$1*C35)+(655.74/108) -> 450.77434 | E35: 1 | F35: =$B$1/109 -> 515.06641 | G35: 406 | H35: 105 | I35: 0.007921 | J35: =($B$1*I35)+(655.74/108) -> 450.77434 | K35: 1 | L35: =$B$1/109 -> 515.06641
A36: 407 | B36: 78 | C36: 0.007921 | D36: =($B$1*C36)+(655.74/108) -> 450.77434 | E36: 1 | F36: =$B$1/109 -> 515.06641 | G36: 407 | H36: 106 | I36: 0.007921 | J36: =($B$1*I36)+(655.74/108) -> 450.77434 | K36: 1 | L36: =$B$1/109 -> 515.06641
A37: 408 | B37: 35 | C37: 0.009912 | D37: =($B$1*C37)+(655.74/108) -> 562.55354 | E37: 1 | F37: =$B$1/109 -> 515.06641 | G37: 408 | H37: 8 | I37: 0.009912 | J37: =($B$1*I37)+(655.74/108) -> 562.55354 | K37: 1 | L37: =$B$1/109 -> 515.06641
A38: 501 | B38: 36 | C38: 0.009912 | D38: =($B$1*C38)+(655.74/108) -> 562.55354 | E38: 1 | F38: =$B$1/109 -> 515.06641 | G38: 501 | H38: 9 | I38: 0.009912 | J38: =($B$1*I38)+(655.74/108) -> 562.55354 | K38: 1 | L38: =$B$1/109 -> 515.06641
A39: 502 | B39: 79 | C39: 0.008123 | D39: =($B$1*C39)+(655.74/108) -> 462.11507 | E39: 1 | F39: =$B$1/109 -> 515.06641 | G39: 502 | H39: 107 | I39: 0.008123 | J39: =($B$1*I39)+(655.74/108) -> 462.11507 | K39: 1 | L39: =$B$1/109 -> 515.06641
A40: 503 | B40: 80 | C40: 0.008123 | D40: =($B$1*C40)+(655.74/108) -> 462.11507 | E40: 1 | F40: =$B$1/109 -> 515.06641 | G40: 503 | H40: 108 | I40: 0.008123 | J40: =($B$1*I40)+(655.74/108) -> 462.11507 | K40: 1 | L40: =$B$1/109 -> 515.06641
A41: 504 | B41: 37 | C41: 0.009912 | D41: =($B$1*C41)+(655.74/108) -> 562.55354 | E41: 1 | F41: =$B$1/109 -> 515.06641 | G41: 504 | H41: 10 | I41: 0.009912 | J41: =($B$1*I41)+(655.74/108) -> 562.55354 | K41: 1 | L41: =$B$1/109 -> 515.06641
...

Sheet SETEMBRO
K2: B
B3: A | I3: Valor que vai diminuir no mês a mês | R3: Valor que vai diminuir no mês a mês
A4: BLOCO A | J4: BLOCO B
A5: APARTAMENTOS | B5: APARTAMENTOS | C5: Valor Fração Ideal | D5: Valor por Quotas | E5: água | F5: gás | G5: Total A | H5: VLR PG IMOB | I5: Diferença | J5: APARTAMENTOS | K5: APARTAMENTOS | L5: Valor Fração Ideal | M5: Valor por Quotas | N5: água | O5: gás | P5: Total A | Q5: VLR PG IMOB | R5: Diferença
A6: 101 | B6: 101A | C6: =VLOOKUP(A6,Rateio!A:L,4,0) -> 628.52067 | D6: =VLOOKUP(A6,Rateio!A:L,6,0) -> 515.06641 | E6: =0 -> 0 | F6: 0 | G6: =D6+E6+F6 -> 515.06641 | H6: =IF(ISERROR(VLOOKUP(B6,BASE!$C$3:$D$109,2,0)),0,(VLOOKUP(B6,BASE!$C$3:$D$109,2,0))) -> 0 | I6: =G6-H6 -> 515.06641 | J6: 101 | K6: =J6&$K$2 -> 101B | L6: =VLOOKUP(J6,Rateio!G:L,4,0) -> 626.27498 | M6: =VLOOKUP(J6,Rateio!G:L,6,0) -> 515.06641 | N6: 0 | O6: 0 | P6: =M6+N6+O6 -> 515.06641 | Q6: =IF(ISERROR(VLOOKUP(K6,BASE!$C$3:$D$109,2,0)),0,(VLOOKUP(K6,BASE!$C$3:$D$109,2,0))) -> 377.13 | R6: =P6-Q6 -> 137.93641
A7: 102 | B7: 102A | C7: =VLOOKUP(A7,Rateio!A:L,4,0) -> 550.48296 | D7: =VLOOKUP(A7,Rateio!A:L,6,0) -> 515.06641 | E7: =28.98 -> 28.98 | F7: 22.82 | G7: =D7+E7+F7 -> 566.86641 | H7: =IF(ISERROR(VLOOKUP(B7,BASE!$C$3:$D$109,2,0)),0,(VLOOKUP(B7,BASE!$C$3:$D$109,2,0))) -> 430.38 | I7: =G7-H7 -> 136.48641 | J7: 102 | K7: =J7&$K$2 -> 102B | L7: =VLOOKUP(J7,Rateio!G:L,4,0) -> 519.4363 | M7: =VLOOKUP(J7,Rateio!G:L,6,0) -> 515.06641 | N7: 0 | O7: 0 | P7: =M7+N7+O7 -> 515.06641 | Q7: =IF(ISERROR(VLOOKUP(K7,BASE!$C$3:$D$109,2,0)),0,(VLOOKUP(K7,BASE!$C$3:$D$109,2,0))) -> 0 | R7: =P7-Q7 -> 515.06641
A8: 103 | B8: 103A | C8: =VLOOKUP(A8,Rateio!A:L,4,0) -> 549.86539 | D8: =VLOOKUP(A8,Rateio!A:L,6,0) -> 515.06641 | E8: =54.29 -> 54.29 | F8: 74.53 | G8: =D8+E8+F8 -> 643.88641 | H8: =IF(ISERROR(VLOOKUP(B8,BASE!$C$3:$D$109,2,0)),0,(VLOOKUP(B8,BASE!$C$3:$D$109,2,0))) -> 555.91 | I8: =G8-H8 -> 87.976411 | J8: 103 | K8: =J8&$K$2 -> 103B | L8: =VLOOKUP(J8,Rateio!G:L,4,0) -> 517.92046 | M8: =VLOOKUP(J8,Rateio!G:L,6,0) -> 515.06641 | N8: 32.63 | O8: 9.45 | P8: =M8+N8+O8 -> 557.14641 | Q8: =IF(ISERROR(VLOOKUP(K8,BASE!$C$3:$D$109,2,0)),0,(VLOOKUP(K8,BASE!$C$3:$D$109,2,0))) -> 415.35 | R8: =P8-Q8 -> 141.79641
A9: 104 | B9: 104A | C9: =VLOOKUP(A9,Rateio!A:L,4,0) -> 633.68575 | D9: =VLOOKUP(A9,Rateio!A:L,6,0) -> 515.06641 | E9: =33.25 -> 33.25 | F9: 89.68 | G9: =D9+E9+F9 -> 637.99641 | H9: =IF(ISERROR(VLOOKUP(B9,BASE!$C$3:$D$109,2,0)),0,(VLOOKUP(B9,BASE!$C$3:$D$109,2,0))) -> 516.99 | I9: =G9-H9 -> 121.00641 | J9: 104 | K9: =J9&$K$2 -> 104B | L9: =VLOOKUP(J9,Rateio!G:L,4,0) -> 613.47455 | M9: =VLOOKUP(J9,Rateio!G:L,6,0) -> 515.06641 | N9: 81.99 | O9: 87.31 | P9: =M9+N9+O9 -> 684.36641 | Q9: =IF(ISERROR(VLOOKUP(K9,BASE!$C$3:$D$109,2,0)),0,(VLOOKUP(K9,BASE!$C$3:$D$109,2,0))) -> 432.16 | R9: =P9-Q9 -> 252.20641
A10: 105 | B10: 105A | C10: =VLOOKUP(A10,Rateio!A:L,4,0) -> 0 | D10: =VLOOKUP(A10,Rateio!A:L,6,0) -> 0 | E10: 0 | F10: 0 | G10: =D10+E10+F10 -> 0 | H10: =F10-G10 -> 0 | I10: =G10-H10 -> 0 | J10: 105 | K10: =J10&$K$2 -> 105B | L10: =VLOOKUP(J10,Rateio!G:L,4,0) -> 543.18447 | M10: =VLOOKUP(J10,Rateio!G:L,6,0) -> 515.06641 | N10: 5.51 | O10: 0 | P10: =M10+N10+O10 -> 520.57641 | Q10: =IF(ISERROR(VLOOKUP(K10,BASE!$C$3:$D$109,2,0)),0,(VLOOKUP(K10,BASE!$C$3:$D$109,2,0))) -> 0 | R10: =P10-Q10 -> 520.57641
A11: 106 | B11: 106A | C11: =VLOOKUP(A11,Rateio!A:L,4,0) -> 470.2557 | D11: =VLOOKUP(A11,Rateio!A:L,6,0) -> 515.06641 | E11: =17.24 -> 17.24 | F11: 1.53 | G11: =D11+E11+F11 -> 533.83641 | H11: =IF(ISERROR(VLOOKUP(B11,BASE!$C$3:$D$109,2,0)),0,(VLOOKUP(B11,BASE!$C$3:$D$109,2,0))) -> 367.06 | I11: =G11-H11 -> 166.77641 | J11: 106 | K11: =J11&$K$2 -> 106B | L11: =VLOOKUP(J11,Rateio!G:L,4,0) -> 351.62715 | M11: =VLOOKUP(J11,Rateio!G:L,6,0) -> 515.06641 | N11: 28.03 | O11: 11.26 | P11: =M11+N11+O11 -> 554.35641 | Q11: =IF(ISERROR(VLOOKUP(K11,BASE!$C$3:$D$109,2,0)),0,(VLOOKUP(K11,BASE!$C$3:$D$109,2,0))) -> 404.75 | R11: =P11-Q11 -> 149.60641
A12: 107 | B12: 107A | C12: =VLOOKUP(A12,Rateio!A:L,4,0) -> 570.02046 | D12: =VLOOKUP(A12,Rateio!A:L,6,0) -> 515.06641 | E12: =0 -> 0 | F12: 0 | G12: =D12+E12+F12 -> 515.06641 | H12: =IF(ISERROR(VLOOKUP(B12,BASE!$C$3:$D$109,2,0)),0,(VLOOKUP(B12,BASE!$C$3:$D$109,2,0))) -> 0 | I12: =G12-H12 -> 515.06641 | J12: 107 | K12: =J12&$K$2 -> 107B | L12: =VLOOKUP(J12,Rateio!G:L,4,0) -> 485.24567 | M12: =VLOOKUP(J12,Rateio!G:L,6,0) -> 515.06641 | N12: 18.67 | O12: 51.02 | P12: =M12+N12+O12 -> 584.75641 | Q12: =IF(ISERROR(VLOOKUP(K12,BASE!$C$3:$D$109,2,0)),0,(VLOOKUP(K12,BASE!$C$3:$D$109,2,0))) -> 419.46 | R12: =P12-Q12 -> 165.29641
A13: 108 | B13: 108A | C13: =VLOOKUP(A13,Rateio!A:L,4,0) -> 0 | D13: =VLOOKUP(A13,Rateio!A:L,6,0) -> 0 | F13: 0 | G13: =D13+E13+F13 -> 0 | H13: =F13-G13 -> 0 | I13: =G13-H13 -> 0 | J13: 108 | K13: =J13&$K$2 -> 108B | L13: =VLOOKUP(J13,Rateio!G:L,4,0) -> 641.71409 | M13: =VLOOKUP(J13,Rateio!G:L,6,0) -> 515.06641 | N13: 0 | O13: 0 | P13: =M13+N13+O13 -> 515.06641 | Q13: =IF(ISERROR(VLOOKUP(K13,BASE!$C$3:$D$109,2,0)),0,(VLOOKUP(K13,BASE!$C$3:$D$109,2,0))) -> 369.54 | R13: =P13-Q13 -> 145.52641
A14: 201 | B14: 201A | C14: =VLOOKUP(A14,Rateio!A:L,4,0) -> 538.91766 | D14: =VLOOKUP(A14,Rateio!A:L,6,0) -> 515.06641 | E14: =66.22 -> 66.22 | F14: 57.12 | G14: =D14+E14+F14 -> 638.40641 | H14: =IF(ISERROR(VLOOKUP(B14,BASE!$C$3:$D$109,2,0)),0,(VLOOKUP(B14,BASE!$C$3:$D$109,2,0))) -> 483.64 | I14: =G14-H14 -> 154.76641 | J14: 201 | K14: =J14&$K$2 -> 201B | L14: =VLOOKUP(J14,Rateio!G:L,4,0) -> 538.91766 | M14: =VLOOKUP(J14,Rateio!G:L,6,0) -> 515.06641 | N14: 49.92 | O14: 13.67 | P14: =M14+N14+O14 -> 578.65641 | Q14: =IF(ISERROR(VLOOKUP(K14,BASE!$C$3:$D$109,2,0)),0,(VLOOKUP(K14,BASE!$C$3:$D$109,2,0))) -> 430.82 | R14: =P14-Q14 -> 147.83641
A15: 202 | B15: 202A | C15: =VLOOKUP(A15,Rateio!A:L,4,0) -> 0 | D15: =VLOOKUP(A15,Rateio!A:L,6,0) -> 515.06641 | E15: =41.14 -> 41.14 | F15: 48.06 | G15: =D15+E15+F15 -> 604.26641 | H15: =IF(ISERROR(VLOOKUP(B15,BASE!$C$3:$D$109,2,0)),0,(VLOOKUP(B15,BASE!$C$3:$D$109,2,0))) -> 454.46 | I15: =G15-H15 -> 149.80641 | J15: 202 | K15: =J15&$K$2 -> 202B | L15: =VLOOKUP(J15,Rateio!G:L,4,0) -> 462.11507 | M15: =VLOOKUP(J15,Rateio!G:L,6,0) -> 515.06641 | N15: 24.51 | O15: 4.71 | P15: =M15+N15+O15 -> 544.28641 | Q15: =IF(ISERROR(VLOOKUP(K15,BASE!$C$3:$D$109,2,0)),0,(VLOOKUP(K15,BASE!$C$3:$D$109,2,0))) -> 400.11 | R15: =P15-Q15 -> 144.17641
A16: 203 | B16: 203A | C16: =VLOOKUP(A16,Rateio!A:L,4,0) -> 462.11507 | D16: =VLOOKUP(A16,Rateio!A:L,6,0) -> 515.06641 | E16: 28.98 | F16: 0 | G16: =D16+E16+F16 -> 544.04641 | H16: =IF(ISERROR(VLOOKUP(B16,BASE!$C$3:$D$109,2,0)),0,(VLOOKUP(B16,BASE!$C$3:$D$109,2,0))) -> 393.68 | I16: =G16-H16 -> 150.36641 | J16: 203 | K16: =J16&$K$2 -> 203B | L16: =VLOOKUP(J16,Rateio!G:L,4,0) -> 462.11507 | M16: =VLOOKUP(J16,Rateio!G:L,6,0) -> 515.06641 | N16: 56.95 | O16: 57.4 | P16: =M16+N16+O16 -> 629.41641 | Q16: =IF(ISERROR(VLOOKUP(K16,BASE!$C$3:$D$109,2,0)),0,(VLOOKUP(K16,BASE!$C$3:$D$109,2,0))) -> 198.48 | R16: =P16-Q16 -> 430.93641
A17: 204 | B17: 204A | C17: =VLOOKUP(A17,Rateio!A:L,4,0) -> 538.91766 | D17: =VLOOKUP(A17,Rateio!A:L,6,0) -> 515.06641 | E17: 46.46 | F17: 14.12 | G17: =D17+E17+F17 -> 575.64641 | H17: =IF(ISERROR(VLOOKUP(B17,BASE!$C$3:$D$109,2,0)),0,(VLOOKUP(B17,BASE!$C$3:$D$109,2,0))) -> 0 | I17: =G17-H17 -> 575.64641 | J17: 204 | K17: =J17&$K$2 -> 204B | L17: =VLOOKUP(J17,Rateio!G:L,4,0) -> 538.91766 | M17: =VLOOKUP(J17,Rateio!G:L,6,0) -> 515.06641 | N17: 0 | O17: 0 | P17: =M17+N17+O17 -> 515.06641 | Q17: =IF(ISERROR(VLOOKUP(K17,BASE!$C$3:$D$109,2,0)),0,(VLOOKUP(K17,BASE!$C$3:$D$109,2,0))) -> 368.05 | R17: =P17-Q17 -> 147.01641
A18: 205 | B18: 205A | C18: =VLOOKUP(A18,Rateio!A:L,4,0) -> 538.91766 | D18: =VLOOKUP(A18,Rateio!A:L,6,0) -> 515.06641 | E18: 0 | F18: 0 | G18: =D18+E18+F18 -> 515.06641 | H18: =IF(ISERROR(VLOOKUP(B18,BASE!$C$3:$D$109,2,0)),0,(VLOOKUP(B18,BASE!$C$3:$D$109,2,0))) -> 0 | I18: =G18-H18 -> 515.06641 | J18: 205 | K18: =J18&$K$2 -> 205B | L18: =VLOOKUP(J18,Rateio!G:L,4,0) -> 538.91766 | M18: =VLOOKUP(J18,Rateio!G:L,6,0) -> 515.06641 | N18: 11.5 | O18: 4.75 | P18: =M18+N18+O18 -> 531.31641 | Q18: =IF(ISERROR(VLOOKUP(K18,BASE!$C$3:$D$109,2,0)),0,(VLOOKUP(K18,BASE!$C$3:$D$109,2,0))) -> 0 | R18: =P18-Q18 -> 531.31641
A19: 206 | B19: 206A | C19: =VLOOKUP(A19,Rateio!A:L,4,0) -> 450.77434 | D19: =VLOOKUP(A19,Rateio!A:L,6,0) -> 515.06641 | E19: 30.16 | F19: 29.79 | G19: =D19+E19+F19 -> 575.01641 | H19: =IF(ISERROR(VLOOKUP(B19,BASE!$C$3:$D$109,2,0)),0,(VLOOKUP(B19,BASE!$C$3:$D$109,2,0))) -> 148.41 | I19: =G19-H19 -> 426.60641 | J19: 206 | K19: =J19&$K$2 -> 206B | L19: =VLOOKUP(J19,Rateio!G:L,4,0) -> 450.77434 | M19: =VLOOKUP(J19,Rateio!G:L,6,0) -> 515.06641 | N19: 13.63 | O19: 4.98 | P19: =M19+N19+O19 -> 533.67641 | Q19: =IF(ISERROR(VLOOKUP(K19,BASE!$C$3:$D$109,2,0)),0,(VLOOKUP(K19,BASE!$C$3:$D$109,2,0))) -> 386.11 | R19: =P19-Q19 -> 147.56641
A20: 207 | B20: 207A | C20: =VLOOKUP(A20,Rateio!A:L,4,0) -> 450.77434 | D20: =VLOOKUP(A20,Rateio!A:L,6,0) -> 515.06641 | E20: 70.16 | F20: 51.42 | G20: =D20+E20+F20 -> 636.64641 | H20: =IF(ISERROR(VLOOKUP(B20,BASE!$C$3:$D$109,2,0)),0,(VLOOKUP(B20,BASE!$C$3:$D$109,2,0))) -> 429.81 | I20: =G20-H20 -> 206.83641 | J20: 207 | K20: =J20&$K$2 -> 207B | L20: =VLOOKUP(J20,Rateio!G:L,4,0) -> 450.77434 | M20: =VLOOKUP(J20,Rateio!G:L,6,0) -> 515.06641 | N20: 34.77 | O20: 58.69 | P20: =M20+N20+O20 -> 608.52641 | Q20: =IF(ISERROR(VLOOKUP(K20,BASE!$C$3:$D$109,2,0)),0,(VLOOKUP(K20,BASE!$C$3:$D$109,2,0))) -> 392.24 | R20: =P20-Q20 -> 216.28641
A21: 208 | B21: 208A | C21: =VLOOKUP(A21,Rateio!A:L,4,0) -> 538.91766 | D21: =VLOOKUP(A21,Rateio!A:L,6,0) -> 515.06641 | E21: 62.46 | F21: 54.66 | G21: =D21+E21+F21 -> 632.18641 | H21: =IF(ISERROR(VLOOKUP(B21,BASE!$C$3:$D$109,2,0)),0,(VLOOKUP(B21,BASE!$C$3:$D$109,2,0))) -> 497.95 | I21: =G21-H21 -> 134.23641 | J21: 208 | K21: =J21&$K$2 -> 208B | L21: =VLOOKUP(J21,Rateio!G:L,4,0) -> 538.91766 | M21: =VLOOKUP(J21,Rateio!G:L,6,0) -> 515.06641 | N21: 66.26 | O21: 74.31 | P21: =M21+N21+O21 -> 655.63641 | Q21: =IF(ISERROR(VLOOKUP(K21,BASE!$C$3:$D$109,2,0)),0,(VLOOKUP(K21,BASE!$C$3:$D$109,2,0))) -> 491.18 | R21: =P21-Q21 -> 164.45641
A22: 301 | B22: 301A | C22: =VLOOKUP(A22,Rateio!A:L,4,0) -> 538.91766 | D22: =VLOOKUP(A22,Rateio!A:L,6,0) -> 515.06641 | E22: 94.05 | F22: 88.01 | G22: =D22+E22+F22 -> 697.12641 | H22: =IF(ISERROR(VLOOKUP(B22,BASE!$C$3:$D$109,2,0)),0,(VLOOKUP(B22,BASE!$C$3:$D$109,2,0))) -> 593.7 | I22: =G22-H22 -> 103.42641 | J22: 301 | K22: =J22&$K$2 -> 301B | L22: =VLOOKUP(J22,Rateio!G:L,4,0) -> 562.55354 | M22: =VLOOKUP(J22,Rateio!G:L,6,0) -> 515.06641 | N22: 4.18 | O22: 0 | P22: =M22+N22+O22 -> 519.24641 | Q22: =IF(ISERROR(VLOOKUP(K22,BASE!$C$3:$D$109,2,0)),0,(VLOOKUP(K22,BASE!$C$3:$D$109,2,0))) -> 368.39 | R22: =P22-Q22 -> 150.85641
A23: 302 | B23: 302A | C23: =VLOOKUP(A23,Rateio!A:L,4,0) -> 462.11507 | D23: =VLOOKUP(A23,Rateio!A:L,6,0) -> 515.06641 | E23: 21.38 | F23: 17.64 | G23: =D23+E23+F23 -> 554.08641 | H23: =IF(ISERROR(VLOOKUP(B23,BASE!$C$3:$D$109,2,0)),0,(VLOOKUP(B23,BASE!$C$3:$D$109,2,0))) -> 418.48 | I23: =G23-H23 -> 135.60641 | J23: 302 | K23: =J23&$K$2 -> 302B | L23: =VLOOKUP(J23,Rateio!G:L,4,0) -> 462.11507 | M23: =VLOOKUP(J23,Rateio!G:L,6,0) -> 515.06641 | N23: 41.99 | O23: 60.84 | P23: =M23+N23+O23 -> 617.89641 | Q23: =IF(ISERROR(VLOOKUP(K23,BASE!$C$3:$D$109,2,0)),0,(VLOOKUP(K23,BASE!$C$3:$D$109,2,0))) -> 437.78 | R23: =P23-Q23 -> 180.11641
A24: 303 | B24: 303A | C24: =VLOOKUP(A24,Rateio!A:L,4,0) -> 462.11507 | D24: =VLOOKUP(A24,Rateio!A:L,6,0) -> 515.06641 | E24: 82.46 | F24: 88.53 | G24: =D24+E24+F24 -> 686.05641 | H24: =IF(ISERROR(VLOOKUP(B24,BASE!$C$3:$D$109,2,0)),0,(VLOOKUP(B24,BASE!$C$3:$D$109,2,0))) -> 506.57 | I24: =G24-H24 -> 179.48641 | J24: 303 | K24: =J24&$K$2 -> 303B | L24: =VLOOKUP(J24,Rateio!G:L,4,0) -> 462.11507 | M24: =VLOOKUP(J24,Rateio!G:L,6,0) -> 515.06641 | N24: 63.32 | O24: 66.16 | P24: =M24+N24+O24 -> 644.54641 | Q24: =IF(ISERROR(VLOOKUP(K24,BASE!$C$3:$D$109,2,0)),0,(VLOOKUP(K24,BASE!$C$3:$D$109,2,0))) -> 479.48 | R24: =P24-Q24 -> 165.06641
A25: 304 | B25: 304A | C25: =VLOOKUP(A25,Rateio!A:L,4,0) -> 562.55354 | D25: =VLOOKUP(A25,Rateio!A:L,6,0) -> 515.06641 | E25: 43.99 | F25: 35.9 | G25: =D25+E25+F25 -> 594.95641 | H25: =IF(ISERROR(VLOOKUP(B25,BASE!$C$3:$D$109,2,0)),0,(VLOOKUP(B25,BASE!$C$3:$D$109,2,0))) -> 0 | I25: =G25-H25 -> 594.95641 | J25: 304 | K25: =J25&$K$2 -> 304B | L25: =VLOOKUP(J25,Rateio!G:L,4,0) -> 562.55354 | M25: =VLOOKUP(J25,Rateio!G:L,6,0) -> 515.06641 | N25: 4.61 | O25: 0 | P25: =M25+N25+O25 -> 519.67641 | Q25: =IF(ISERROR(VLOOKUP(K25,BASE!$C$3:$D$109,2,0)),0,(VLOOKUP(K25,BASE!$C$3:$D$109,2,0))) -> 368.39 | R25: =P25-Q25 -> 151.28641
A26: 305 | B26: 305A | C26: =VLOOKUP(A26,Rateio!A:L,4,0) -> 562.55354 | D26: =VLOOKUP(A26,Rateio!A:L,6,0) -> 515.06641 | E26: 52.73 | F26: 0 | G26: =D26+E26+F26 -> 567.79641 | H26: =IF(ISERROR(VLOOKUP(B26,BASE!$C$3:$D$109,2,0)),0,(VLOOKUP(B26,BASE!$C$3:$D$109,2,0))) -> 425.23 | I26: =G26-H26 -> 142.56641 | J26: 305 | K26: =J26&$K$2 -> 305B | L26: =VLOOKUP(J26,Rateio!G:L,4,0) -> 562.55354 | M26: =VLOOKUP(J26,Rateio!G:L,6,0) -> 515.06641 | N26: 41.47 | O26: 38.87 | P26: =M26+N26+O26 -> 595.40641 | Q26: =IF(ISERROR(VLOOKUP(K26,BASE!$C$3:$D$109,2,0)),0,(VLOOKUP(K26,BASE!$C$3:$D$109,2,0))) -> 444.07 | R26: =P26-Q26 -> 151.33641
A27: 306 | B27: 306A | C27: =VLOOKUP(A27,Rateio!A:L,4,0) -> 450.77434 | D27: =VLOOKUP(A27,Rateio!A:L,6,0) -> 515.06641 | E27: 43.04 | F27: 7.83 | G27: =D27+E27+F27 -> 565.93641 | H27: =IF(ISERROR(VLOOKUP(B27,BASE!$C$3:$D$109,2,0)),0,(VLOOKUP(B27,BASE!$C$3:$D$109,2,0))) -> 412.36 | I27: =G27-H27 -> 153.57641 | J27: 306 | K27: =J27&$K$2 -> 306B | L27: =VLOOKUP(J27,Rateio!G:L,4,0) -> 0 | M27: =VLOOKUP(J27,Rateio!G:L,6,0) -> 0 | N27: 26.46 | O27: 16.2 | P27: =M27+N27+O27 -> 42.66 | Q27: =IF(ISERROR(VLOOKUP(K27,BASE!$C$3:$D$109,2,0)),0,(VLOOKUP(K27,BASE!$C$3:$D$109,2,0))) -> 428.63 | R27: =P27-Q27 -> -385.97
... A61: 708 | B61: 708A | C61: =VLOOKUP(A61,Rateio!A:L,4,0) -> 571.31173 | D61: =VLOOKUP(A61,Rateio!A:L,6,0) -> 515.06641 | E61: 32.82 | F61: 25.96 | G61: =D61+E61+F61 -> 573.84641 | H61: =IF(ISERROR(VLOOKUP(B61,BASE!$C$3:$D$109,2,0)),0,(VLOOKUP(B61,BASE!$C$3:$D$109,2,0))) -> 450.78 | I61: =G61-H61 -> 123.06641 | J61: 708 | K61: =J61&$K$2 -> 708B | L61: =VLOOKUP(J61,Rateio!G:L,4,0) -> 562.55354 | M61: =VLOOKUP(J61,Rateio!G:L,6,0) -> 515.06641 | N61: 0 | O61: 0 | P61: =M61+N61+O61 -> 515.06641 | Q61: =IF(ISERROR(VLOOKUP(K61,BASE!$C$3:$D$109,2,0)),0,(VLOOKUP(K61,BASE!$C$3:$D$109,2,0))) -> 368.39 | R61: =P61-Q61 -> 146.67641
A62: Subtotal | C62: =SUM(C6:C61) -> 27498.403 | D62: =SUM(D6:D61) -> 27813.586 | E62: =SUM(E6:E61) -> 1587.06 | F62: =SUM(F6:F61) -> 1417.94 | G62: =SUM(G6:G61) -> 30818.586 | H62: =SUM(H6:H61) -> 17768.17 | I62: =SUM(I6:I61) -> 13050.416 | J62: =SUM(J6:J61) -> 22652 | ... R62: =SUM(R6:R61) -> 11007.493
E63: =E62+N62 -> 3266.98 | F63: =F62+O62 -> 2900.78
G67: =G62+P62 -> 62309.999
G68: =H62+Q62 -> 38252.09

Sheet OUTUBRO
K2: B
B3: A | I3: Valor que vai diminuir no mês a mês | R3: Valor que vai diminuir no mês a mês
A4: BLOCO A | J4: BLOCO B
A5: APARTAMENTOS | B5: APARTAMENTOS | C5: Valor Fração Ideal | D5: Valor por Quotas | E5: água | F5: gás | G5: Total A | H5: VLR PG IMOB | I5: Diferença | J5: APARTAMENTOS | K5: APARTAMENTOS | L5: Valor Fração Ideal | M5: Valor por Quotas | N5: água | O5: gás | P5: Total B | Q5: VLR PG IMOB | R5: Diferença
A6: 101 | B6: 101A | C6: =VLOOKUP(A6,Rateio!A:L,4,0) -> 628.52067 | D6: =VLOOKUP(A6,Rateio!A:L,6,0) -> 515.06641 | E6: 0 | F6: 0 | G6: =D6+E6+F6 -> 515.06641 | H6: =IF(ISERROR(VLOOKUP(B6,BASE!$H$3:$I$109,2,0)),0,(VLOOKUP(B6,BASE!$H$3:$I$109,2,0))) -> 0 | I6: =G6-H6 -> 515.06641 | J6: 101 | K6: =J6&$K$2 -> 101B | L6: =VLOOKUP(J6,Rateio!G:L,4,0) -> 626.27498 | M6: =VLOOKUP(J6,Rateio!G:L,6,0) -> 515.06641 | N6: 0 | O6: 0 | P6: =M6+N6+O6 -> 515.06641 | Q6: =IF(ISERROR(VLOOKUP(K6,BASE!$H$3:$I$109,2,0)),0,(VLOOKUP(K6,BASE!$H$3:$I$109,2,0))) -> 376.75 | R6: =P6-Q6 -> 138.31641
A7: 102 | B7: 102A | C7: =VLOOKUP(A7,Rateio!A:L,4,0) -> 550.48296 | D7: =VLOOKUP(A7,Rateio!A:L,6,0) -> 515.06641 | E7: 46.36 | F7: 35.16 | G7: =D7+E7+F7 -> 596.58641 | H7: =IF(ISERROR(VLOOKUP(B7,BASE!$H$3:$I$109,2,0)),0,(VLOOKUP(B7,BASE!$H$3:$I$109,2,0))) -> 427.46 | I7: =G7-H7 -> 169.12641 | J7: 102 | K7: =J7&$K$2 -> 102B | L7: =VLOOKUP(J7,Rateio!G:L,4,0) -> 519.4363 | M7: =VLOOKUP(J7,Rateio!G:L,6,0) -> 515.06641 | N7: 0 | O7: 0 | P7: =M7+N7+O7 -> 515.06641 | Q7: =IF(ISERROR(VLOOKUP(K7,BASE!$H$3:$I$109,2,0)),0,(VLOOKUP(K7,BASE!$H$3:$I$109,2,0))) -> 0 | R7: =P7-Q7 -> 515.06641
A8: 103 | B8: 103A | C8: =VLOOKUP(A8,Rateio!A:L,4,0) -> 549.86539 | D8: =VLOOKUP(A8,Rateio!A:L,6,0) -> 515.06641 | E8: 69.64 | F8: 86.55 | G8: =D8+E8+F8 -> 671.25641 | H8: =IF(ISERROR(VLOOKUP(B8,BASE!$H$3:$I$109,2,0)),0,(VLOOKUP(B8,BASE!$H$3:$I$109,2,0))) -> 504.47 | I8: =G8-H8 -> 166.78641 | J8: 103 | K8: =J8&$K$2 -> 103B | L8: =VLOOKUP(J8,Rateio!G:L,4,0) -> 517.92046 | M8: =VLOOKUP(J8,Rateio!G:L,6,0) -> 515.06641 | N8: 72.39 | O8: 28.53 | P8: =M8+N8+O8 -> 615.98641 | Q8: =IF(ISERROR(VLOOKUP(K8,BASE!$H$3:$I$109,2,0)),0,(VLOOKUP(K8,BASE!$H$3:$I$109,2,0))) -> 417.27 | R8: =P8-Q8 -> 198.71641
A9: 104 | B9: 104A | C9: =VLOOKUP(A9,Rateio!A:L,4,0) -> 633.68575 | D9: =VLOOKUP(A9,Rateio!A:L,6,0) -> 515.06641 | E9: 135.57 | F9: 94.26 | G9: =D9+E9+F9 -> 744.89641 | H9: =IF(ISERROR(VLOOKUP(B9,BASE!$H$3:$I$109,2,0)),0,(VLOOKUP(B9,BASE!$H$3:$I$109,2,0))) -> 499.79 | I9: =G9-H9 -> 245.10641 | J9: 104 | K9: =J9&$K$2 -> 104B | L9: =VLOOKUP(J9,Rateio!G:L,4,0) -> 613.47455 | M9: =VLOOKUP(J9,Rateio!G:L,6,0) -> 515.06641 | N9: 105.36 | O9: 111.45 | P9: =M9+N9+O9 -> 731.87641 | Q9: =IF(ISERROR(VLOOKUP(K9,BASE!$H$3:$I$109,2,0)),0,(VLOOKUP(K9,BASE!$H$3:$I$109,2,0))) -> 545.87 | R9: =P9-Q9 -> 186.00641
A10: 105 | B10: 105A | C10: =VLOOKUP(A10,Rateio!A:L,4,0) -> 0 | D10: =VLOOKUP(A10,Rateio!A:L,6,0) -> 0 | E10: 0 | F10: 0 | G10: =D10+E10+F10 -> 0 | H10: =IF(ISERROR(VLOOKUP(B10,BASE!$H$3:$I$109,2,0)),0,(VLOOKUP(B10,BASE!$H$3:$I$109,2,0))) -> 0 | I10: =G10-H10 -> 0 | J10: 105 | K10: =J10&$K$2 -> 105B | L10: =VLOOKUP(J10,Rateio!G:L,4,0) -> 543.18447 | M10: =VLOOKUP(J10,Rateio!G:L,6,0) -> 515.06641 | N10: 6.6 | O10: 0 | P10: =M10+N10+O10 -> 521.66641 | Q10: =IF(ISERROR(VLOOKUP(K10,BASE!$H$3:$I$109,2,0)),0,(VLOOKUP(K10,BASE!$H$3:$I$109,2,0))) -> 0 | R10: =P10-Q10 -> 521.66641
A11: 106 | B11: 106A | C11: =VLOOKUP(A11,Rateio!A:L,4,0) -> 470.2557 | D11: =VLOOKUP(A11,Rateio!A:L,6,0) -> 515.06641 | E11: 23.09 | F11: 0 | G11: =D11+E11+F11 -> 538.15641 | H11: =IF(ISERROR(VLOOKUP(B11,BASE!$H$3:$I$109,2,0)),0,(VLOOKUP(B11,BASE!$H$3:$I$109,2,0))) -> 0 | I11: =G11-H11 -> 538.15641 | J11: 106 | K11: =J11&$K$2 -> 106B | L11: =VLOOKUP(J11,Rateio!G:L,4,0) -> 351.62715 | M11: =VLOOKUP(J11,Rateio!G:L,6,0) -> 515.06641 | N11: 33.01 | O11: 9.54 | P11: =M11+N11+O11 -> 557.61641 | Q11: =IF(ISERROR(VLOOKUP(K11,BASE!$H$3:$I$109,2,0)),0,(VLOOKUP(K11,BASE!$H$3:$I$109,2,0))) -> 412.07 | R11: =P11-Q11 -> 145.54641
A12: 107 | B12: 107A | C12: =VLOOKUP(A12,Rateio!A:L,4,0) -> 570.02046 | D12: =VLOOKUP(A12,Rateio!A:L,6,0) -> 515.06641 | E12: 0 | F12: 0 | G12: =D12+E12+F12 -> 515.06641 | H12: =IF(ISERROR(VLOOKUP(B12,BASE!$H$3:$I$109,2,0)),0,(VLOOKUP(B12,BASE!$H$3:$I$109,2,0))) -> 0 | I12: =G12-H12 -> 515.06641 | J12: 107 | K12: =J12&$K$2 -> 107B | L12: =VLOOKUP(J12,Rateio!G:L,4,0) -> 485.24567 | M12: =VLOOKUP(J12,Rateio!G:L,6,0) -> 515.06641 | N12: 14.44 | O12: 69.67 | P12: =M12+N12+O12 -> 599.17641 | Q12: =IF(ISERROR(VLOOKUP(K12,BASE!$H$3:$I$109,2,0)),0,(VLOOKUP(K12,BASE!$H$3:$I$109,2,0))) -> 453.62 | R12: =P12-Q12 -> 145.55641
A13: 108 | B13: 108A | C13: =VLOOKUP(A13,Rateio!A:L,4,0) -> 0 | D13: =VLOOKUP(A13,Rateio!A:L,6,0) -> 0 | E13: 0 | F13: 0 | G13: =D13+E13+F13 -> 0 | H13: =IF(ISERROR(VLOOKUP(B13,BASE!$H$3:$I$109,2,0)),0,(VLOOKUP(B13,BASE!$H$3:$I$109,2,0))) -> 0 | I13: =G13-H13 -> 0 | J13: 108 | K13: =J13&$K$2 -> 108B | L13: =VLOOKUP(J13,Rateio!G:L,4,0) -> 641.71409 | M13: =VLOOKUP(J13,Rateio!G:L,6,0) -> 515.06641 | N13: 0 | O13: 0 | P13: =M13+N13+O13 -> 515.06641 | Q13: =IF(ISERROR(VLOOKUP(K13,BASE!$H$3:$I$109,2,0)),0,(VLOOKUP(K13,BASE!$H$3:$I$109,2,0))) -> 376.98 | R13: =P13-Q13 -> 138.08641
A14: 201 | B14: 201A | C14: =VLOOKUP(A14,Rateio!A:L,4,0) -> 538.91766 | D14: =VLOOKUP(A14,Rateio!A:L,6,0) -> 515.06641 | E14: 85.07 | F14: 68.52 | G14: =D14+E14+F14 -> 668.65641 | H14: =IF(ISERROR(VLOOKUP(B14,BASE!$H$3:$I$109,2,0)),0,(VLOOKUP(B14,BASE!$H$3:$I$109,2,0))) -> 498.83 | I14: =G14-H14 -> 169.82641 | J14: 201 | K14: =J14&$K$2 -> 201B | L14: =VLOOKUP(J14,Rateio!G:L,4,0) -> 538.91766 | M14: =VLOOKUP(J14,Rateio!G:L,6,0) -> 515.06641 | N14: 64.6 | O14: 15.06 | P14: =M14+N14+O14 -> 594.72641 | Q14: =IF(ISERROR(VLOOKUP(K14,BASE!$H$3:$I$109,2,0)),0,(VLOOKUP(K14,BASE!$H$3:$I$109,2,0))) -> 439.08 | R14: =P14-Q14 -> 155.64641
A15: 202 | B15: 202A | C15: =VLOOKUP(A15,Rateio!A:L,4,0) -> 0 | D15: =VLOOKUP(A15,Rateio!A:L,6,0) -> 515.06641 | E15: 49.5 | F15: 41.98 | G15: =D15+E15+F15 -> 606.54641 | H15: =IF(ISERROR(VLOOKUP(B15,BASE!$H$3:$I$109,2,0)),0,(VLOOKUP(B15,BASE!$H$3:$I$109,2,0))) -> 463.58 | I15: =G15-H15 -> 142.96641 | J15: 202 | K15: =J15&$K$2 -> 202B | L15: =VLOOKUP(J15,Rateio!G:L,4,0) -> 462.11507 | M15: =VLOOKUP(J15,Rateio!G:L,6,0) -> 515.06641 | N15: 36.01 | O15: 6.93 | P15: =M15+N15+O15 -> 558.00641 | Q15: =IF(ISERROR(VLOOKUP(K15,BASE!$H$3:$I$109,2,0)),0,(VLOOKUP(K15,BASE!$H$3:$I$109,2,0))) -> 403.6 | R15: =P15-Q15 -> 154.40641
A16: 203 | B16: 203A | C16: =VLOOKUP(A16,Rateio!A:L,4,0) -> 462.11507 | D16: =VLOOKUP(A16,Rateio!A:L,6,0) -> 515.06641 | E16: 29.83 | F16: 0 | G16: =D16+E16+F16 -> 544.89641 | H16: =IF(ISERROR(VLOOKUP(B16,BASE!$H$3:$I$109,2,0)),0,(VLOOKUP(B16,BASE!$H$3:$I$109,2,0))) -> 403.36 | I16: =G16-H16 -> 141.53641 | J16: 203 | K16: =J16&$K$2 -> 203B | L16: =VLOOKUP(J16,Rateio!G:L,4,0) -> 462.11507 | M16: =VLOOKUP(J16,Rateio!G:L,6,0) -> 515.06641 | N16: 57.62 | O16: 60.21 | P16: =M16+N16+O16 -> 632.89641 | Q16: =IF(ISERROR(VLOOKUP(K16,BASE!$H$3:$I$109,2,0)),0,(VLOOKUP(K16,BASE!$H$3:$I$109,2,0))) -> 240.65 | R16: =P16-Q16 -> 392.24641
A17: 204 | B17: 204A | C17: =VLOOKUP(A17,Rateio!A:L,4,0) -> 538.91766 | D17: =VLOOKUP(A17,Rateio!A:L,6,0) -> 515.06641 | E17: 54.86 | F17: 23.45 | G17: =D17+E17+F17 -> 593.37641 | H17: =IF(ISERROR(VLOOKUP(B17,BASE!$H$3:$I$109,2,0)),0,(VLOOKUP(B17,BASE!$H$3:$I$109,2,0))) -> 0 | I17: =G17-H17 -> 593.37641 | J17: 204 | K17: =J17&$K$2 -> 204B | L17: =VLOOKUP(J17,Rateio!G:L,4,0) -> 538.91766 | M17: =VLOOKUP(J17,Rateio!G:L,6,0) -> 515.06641 | N17: 0 | O17: 0 | P17: =M17+N17+O17 -> 515.06641 | Q17: =IF(ISERROR(VLOOKUP(K17,BASE!$H$3:$I$109,2,0)),0,(VLOOKUP(K17,BASE!$H$3:$I$109,2,0))) -> 0 | R17: =P17-Q17 -> 515.06641
... A54: 701 | B54: 701A | C54: =VLOOKUP(A54,Rateio!A:L,4,0) -> 584.39287 | D54: =VLOOKUP(A54,Rateio!A:L,6,0) -> 515.06641 | E54: 0 | F54: 0 | G54: =D54+E54+F54 -> 515.06641 | H54: =IF(ISERROR(VLOOKUP(B54,BASE!$H$3:$I$109,2,0)),0,(VLOOKUP(B54,BASE!$H$3:$I$109,2,0))) -> 376.15 | I54: =G54-H54 -> 138.91641 | J54: 701 | K54: =J54&$K$2 -> 701B | L54: =VLOOKUP(J54,Rateio!G:L,4,0) -> 562.55354 | M54: =VLOOKUP(J54,Rateio!G:L,6,0) -> 515.06641 | N54: 43.18 | O54: 44.51 | P54: =M54+N54+O54 -> 602.75641 | Q54: =IF(ISERROR(VLOOKUP(K54,BASE!$H$3:$I$109,2,0)),0,(VLOOKUP(K54,BASE!$H$3:$I$109,2,0))) -> 512.07 | R54: =P54-Q54 -> 90.686411
A55: 702 | B55: 702A | C55: =VLOOKUP(A55,Rateio!A:L,4,0) -> 485.8071 | D55: =VLOOKUP(A55,Rateio!A:L,6,0) -> 515.06641 | E55: 32.59 | F55: 9.63 | G55: =D55+E55+F55 -> 557.28641 | H55: =IF(ISERROR(VLOOKUP(B55,BASE!$H$3:$I$109,2,0)),0,(VLOOKUP(B55,BASE!$H$3:$I$109,2,0))) -> 411.02 | I55: =G55-H55 -> 146.26641 | J55: 702 | K55: =J55&$K$2 -> 702B | L55: =VLOOKUP(J55,Rateio!G:L,4,0) -> 485.8071 | M55: =VLOOKUP(J55,Rateio!G:L,6,0) -> 515.06641 | N55: =60.94-0.3-0.6 -> 60.04 | O55: 61.1 | P55: =M55+N55+O55 -> 636.20641 | Q55: =IF(ISERROR(VLOOKUP(K55,BASE!$H$3:$I$109,2,0)),0,(VLOOKUP(K55,BASE!$H$3:$I$109,2,0))) -> 468.57 | R55: =P55-Q55 -> 167.63641
A56: 703 | B56: 703A | C56: =VLOOKUP(A56,Rateio!A:L,4,0) -> 485.8071 | D56: =VLOOKUP(A56,Rateio!A:L,6,0) -> 515.06641 | E56: 77.62 | F56: 72.68 | G56: =D56+E56+F56 -> 665.36641 | H56: =IF(ISERROR(VLOOKUP(B56,BASE!$H$3:$I$109,2,0)),0,(VLOOKUP(B56,BASE!$H$3:$I$109,2,0))) -> 511.98 | I56: =G56-H56 -> 153.38641 | J56: 703 | K56: =J56&$K$2 -> 703B | L56: =VLOOKUP(J56,Rateio!G:L,4,0) -> 485.8071 | M56: =VLOOKUP(J56,Rateio!G:L,6,0) -> 515.06641 | N56: 60.33 | O56: 59.57 | P56: =M56+N56+O56 -> 634.96641 | Q56: =IF(ISERROR(VLOOKUP(K56,BASE!$H$3:$I$109,2,0)),0,(VLOOKUP(K56,BASE!$H$3:$I$109,2,0))) -> 0 | R56: =P56-Q56 -> 634.96641
A57: 704 | B57: 704A | C57: =VLOOKUP(A57,Rateio!A:L,4,0) -> 562.55354 | D57: =VLOOKUP(A57,Rateio!A:L,6,0) -> 515.06641 | E57: 0 | F57: 0 | G57: =D57+E57+F57 -> 515.06641 | H57: =IF(ISERROR(VLOOKUP(B57,BASE!$H$3:$I$109,2,0)),0,(VLOOKUP(B57,BASE!$H$3:$I$109,2,0))) -> 0 | I57: =G57-H57 -> 515.06641 | J57: 704 | K57: =J57&$K$2 -> 704B | L57: =VLOOKUP(J57,Rateio!G:L,4,0) -> 562.55354 | M57: =VLOOKUP(J57,Rateio!G:L,6,0) -> 515.06641 | N57: 0 | O57: 0 | P57: =M57+N57+O57 -> 515.06641 | Q57: =IF(ISERROR(VLOOKUP(K57,BASE!$H$3:$I$109,2,0)),0,(VLOOKUP(K57,BASE!$H$3:$I$109,2,0))) -> 375.83 | R57: =P57-Q57 -> 139.23641
A58: 705 | B58: 705A | C58: =VLOOKUP(A58,Rateio!A:L,4,0) -> 562.55354 | D58: =VLOOKUP(A58,Rateio!A:L,6,0) -> 515.06641 | E58: 0 | F58: 0 | G58: =D58+E58+F58 -> 515.06641 | H58: =IF(ISERROR(VLOOKUP(B58,BASE!$H$3:$I$109,2,0)),0,(VLOOKUP(B58,BASE!$H$3:$I$109,2,0))) -> 269.21 | I58: =G58-H58 -> 245.85641 | J58: 705 | K58: =J58&$K$2 -> 705B | L58: =VLOOKUP(J58,Rateio!G:L,4,0) -> 562.55354 | M58: =VLOOKUP(J58,Rateio!G:L,6,0) -> 515.06641 | N58: 0 | O58: 0 | P58: =M58+N58+O58 -> 515.06641 | Q58: =IF(ISERROR(VLOOKUP(K58,BASE!$H$3:$I$109,2,0)),0,(VLOOKUP(K58,BASE!$H$3:$I$109,2,0))) -> 375.83 | R58: =P58-Q58 -> 139.23641
A59: 706 | B59: 706A | C59: =VLOOKUP(A59,Rateio!A:L,4,0) -> 474.41022 | D59: =VLOOKUP(A59,Rateio!A:L,6,0) -> 515.06641 | E59: 0 | F59: 44.13 | G59: =D59+E59+F59 -> 559.19641 | H59: =IF(ISERROR(VLOOKUP(B59,BASE!$H$3:$I$109,2,0)),0,(VLOOKUP(B59,BASE!$H$3:$I$109,2,0))) -> 422.58 | I59: =G59-H59 -> 136.61641 | J59: 706 | K59: =J59&$K$2 -> 706B | L59: =VLOOKUP(J59,Rateio!G:L,4,0) -> 474.41022 | M59: =VLOOKUP(J59,Rateio!G:L,6,0) -> 515.06641 | N59: 0 | O59: 0 | P59: =M59+N59+O59 -> 515.06641 | Q59: =IF(ISERROR(VLOOKUP(K59,BASE!$H$3:$I$109,2,0)),0,(VLOOKUP(K59,BASE!$H$3:$I$109,2,0))) -> 0 | R59: =P59-Q59 -> 515.06641
A60: 707 | B60: 707A | C60: =VLOOKUP(A60,Rateio!A:L,4,0) -> 474.41022 | D60: =VLOOKUP(A60,Rateio!A:L,6,0) -> 515.06641 | E60: 0 | F60: 0 | G60: =D60+E60+F60 -> 515.06641 | H60: =IF(ISERROR(VLOOKUP(B60,BASE!$H$3:$I$109,2,0)),0,(VLOOKUP(B60,BASE!$H$3:$I$109,2,0))) -> 0 | I60: =G60-H60 -> 515.06641 | J60: 707 | K60: =J60&$K$2 -> 707B | L60: =VLOOKUP(J60,Rateio!G:L,4,0) -> 474.41022 | M60: =VLOOKUP(J60,Rateio!G:L,6,0) -> 515.06641 | N60: 40.61 | O60: 0 | P60: =M60+N60+O60 -> 555.67641 | Q60: =IF(ISERROR(VLOOKUP(K60,BASE!$H$3:$I$109,2,0)),0,(VLOOKUP(K60,BASE!$H$3:$I$109,2,0))) -> 417.6 | R60: =P60-Q60 -> 138.07641
A61: 708 | B61: 708A | C61: =VLOOKUP(A61,Rateio!A:L,4,0) -> 571.31173 | D61: =VLOOKUP(A61,Rateio!A:L,6,0) -> 515.06641 | E61: 46.5 | F61: 36.79 | G61: =D61+E61+F61 -> 598.35641 | H61: =IF(ISERROR(VLOOKUP(B61,BASE!$H$3:$I$109,2,0)),0,(VLOOKUP(B61,BASE!$H$3:$I$109,2,0))) -> 434.74 | I61: =G61-H61 -> 163.61641 | J61: 708 | K61: =J61&$K$2 -> 708B | L61: =VLOOKUP(J61,Rateio!G:L,4,0) -> 562.55354 | M61: =VLOOKUP(J61,Rateio!G:L,6,0) -> 515.06641 | N61: 0 | O61: 0 | P61: =M61+N61+O61 -> 515.06641 | Q61: =IF(ISERROR(VLOOKUP(K61,BASE!$H$3:$I$109,2,0)),0,(VLOOKUP(K61,BASE!$H$3:$I$109,2,0))) -> 375.83 | R61: =P61-Q61 -> 139.23641
A62: Subtotal | C62: =SUM(C6:C61) -> 27498.403 | D62: =SUM(D6:D61) -> 27813.586 | E62: =SUM(E6:E61) -> 2009.26 | F62: =SUM(F6:F61) -> 1674.39 | G62: =SUM(G6:G61) -> 31497.236 | H62: =SUM(H6:H61) -> 15201.96 | I62: =SUM(I6:I61) -> 16295.276 | J62: =SUM(J6:J61) -> 22652 | ... R62: =SUM(R6:R61) -> 14004.273
E63: =E62+N62 -> 3967.7 | F63: =F62+O62 -> 3262.81
G70: Nova taxa
G71: =G62+P62 -> 63372.749
G72: Taxa velha
G73: =H62+Q62 -> 33073.2

Sheet BASE
A1: SETEMBRO | F1: OUTUBRO
A2: Mês | B2: Competência | C2: Apto | D2: Total | F2: Mês | G2: Competência | H2: Apto | I2: Total
A3: 42248 | B3: 42186 | C3: 303A | D3: 506.57 | F3: 42278 | G3: 41821 | H3: 705A | I3: 269.21
A4: 42248 | B4: 42217 | C4: 303A | D4: 535.95 | F4: 42278 | G4: 41852 | H4: 705A | I4: 269.21
A5: 42248 | B5: 42217 | C5: 706A | D5: 405.73 | F5: 42278 | G5: 41883 | H5: 705A | I5: 269.21
A6: 42248 | B6: 42248 | C6: 101B | D6: 377.13 | F6: 42278 | G6: 41913 | H6: 705A | I6: 269.21
A7: 42248 | B7: 42248 | C7: 102A | D7: 430.38 | F7: 42278 | G7: 41944 | H7: 705A | I7: 269.21
A8: 42248 | B8: 42248 | C8: 103A | D8: 555.91 | F8: 42278 | G8: 41974 | H8: 705A | I8: 269.21
A9: 42248 | B9: 42248 | C9: 103B | D9: 415.35 | F9: 42278 | G9: 42005 | H9: 705A | I9: 269.21
A10: 42248 | B10: 42248 | C10: 104A | D10: 516.99 | F10: 42278 | G10: 42036 | H10: 705A | I10: 269.21
A11: 42248 | B11: 42248 | C11: 104B | D11: 432.16 | F11: 42278 | G11: 42064 | H11: 705A | I11: 269.21
A12: 42248 | B12: 42248 | C12: 106A | D12: 367.06 | F12: 42278 | G12: 42095 | H12: 705A | I12: 269.21
A13: 42248 | B13: 42248 | C13: 106B | D13: 404.75 | F13: 42278 | G13: 42125 | H13: 705A | I13: 269.21
A14: 42248 | B14: 42248 | C14: 107B | D14: 419.46 | F14: 42278 | G14: 42156 | H14: 705A | I14: 269.21
... A93: 42248 | B93: 42248 | C93: 708B | D93: 368.39 | F93: 42278 | G93: 42278 | H93: 705A | I93: 645.04
A94: 42248 | B94: 42278 | C94: 401B | D94: 375.83
A95: 42248 | B95: 42278 | C95: 402A | D95: 374.38
A96: 42248 | B96: 42278 | C96: 402B | D96: 374.38
A97: 42248 | B97: 42278 | C97: 403A | D97: 374.38
A98: 42248 | B98: 42278 | C98: 403B | D98: 374.38
A99: 42248 | B99: 42278 | C99: 404A | D99: 375.83
A100: 42248 | B100: 42278 | C100: 404B | D100: 375.83
A101: 42248 | B101: 42278 | C101: 405A | D101: 375.83
A102: 42248 | B102: 42278 | C102: 406A | D102: 374.22
A103: 42248 | B103: 42278 | C103: 406B | D103: 374.22
A104: 42248 | B104: 42278 | C104: 407A | D104: 374.22
A105: 42248 | B105: 42278 | C105: 407B | D105: 374.22
... A109: 42248 | B109: 42278 | C109: 703B | D109: 509.91

Sheet Plan1
A1: 3108-4331 | B1: Jorge | E1: 51 3364-2891
E2: http://www.estinsul.com.br/produtos_e_servicos
A4: diagnóstico isso 31000
A5: laudo que ajuda em caso de acionar seguro
A6: curso de brigadista
A7: orientacoes do condominio : manual de procedimentos
A8: http://www.suldefense.com.br/servi%C3%A7os.html
A10: curso rt014
A11: curso de brigadista
A15: 32883176 ou 3173

Sheet Plan2
A1: SINDICO E CONSELHO CONDOMÍNIO PORTO CRISTAL | J1: APARTAMENTOS | K1: CELULAR/WHATSAPP | M1: INSCRIÇÃO PARA SINDICO E CONSELHO CONDOMÍNIO PORTO CRISTAL
