Workbook

Sheet Análise
A2: Ano | B2: M | C2: RBT | D2: Folha | F2: Anexo 2018: | I2: Anexo 2017: | U2: 2018 | V2: 4 | W2: LP | X2: 7
C3: 2017 | L3: =SUMIF(Mestres!I3:I23,J22,Mestres!K3:K23) -> 540000 | U3: 2017 | V3: 1
A4: 2017 | B4: 1 | C4: 36755.3 | D4: 5500
A5: 2017 | B5: 2 | C5: =C4 -> 36755.3 | D5: =D4 -> 5500 | F5: RBT12 - Ultimos 12 Meses Ant. Ano Apuração | G5: =C16 -> 441063.6
A6: 2017 | B6: 3 | C6: =C5 -> 36755.3 | D6: =D5 -> 5500 | F6: RBA - Receita Bruta Acumulada Ano Calendário | G6: =C29 -> 36755.3
A7: 2017 | B7: 4 | C7: =C6 -> 36755.3 | D7: =D6 -> 5500 | F7: Excesso: | G7: =IF(G6>Mestres!D9,Análise!G6-Mestres!D9,0) -> 0
A8: 2017 | B8: 5 | C8: =C7 -> 36755.3 | D8: =D7 -> 5500 | U8: Lucro Presumido
A9: 2017 | B9: 6 | C9: =C8 -> 36755.3 | D9: =D8 -> 5500 | F9: CÁLCULO DO SIMPLES | U9: PIS | V9: 0.0065 | W9: =$J$11*V9 -> 238.90945
A10: 2017 | B10: 7 | C10: =C9 -> 36755.3 | D10: =D9 -> 5500 | U10: COFINS | V10: 0.03 | W10: =$J$11*V10 -> 1102.659
A11: 2017 | B11: 8 | C11: =C10 -> 36755.3 | D11: =D10 -> 5500 | F11: Alíquota | G11: =SUMIFS('Anexos 2018'!E:E,'Anexos 2018'!A:A,Análise!V2,'Anexos 2018'!C:C,Análise!G22) -> 0.102 | I11: Faturamento do Período | J11: =C17 -> 36755.3 | U11: S/ Receita | W11: =SUM(W9:W10) -> 1341.5685
A12: 2017 | B12: 9 | C12: =C11 -> 36755.3 | D12: =D11 -> 5500 | F12: Redutor | G12: =SUMIFS('Anexos 2018'!F:F,'Anexos 2018'!A:A,Análise!V2,'Anexos 2018'!C:C,Análise!G22) -> 12420 | U12: IRPJ | V12: =32%*15% -> 0.048 | W12: =$J$11*V12 -> 1764.2544
A13: 2017 | B13: 10 | C13: =C12 -> 36755.3 | D13: =D12 -> 5500 | F13: Alíquota Efetiva | G13: =((C16*G11)-G12)/C16 -> 0.073840796 | I13: Imposto Devido | J13: =J11*G13 -> 2714.0406 | U13: AD | W13: =IF(((C17*3)*0.32)<60000,0,((C17*3)*0.32)-60000)*0.1 -> 0 | X13: =C17*3 -> 110265.9
A14: 2017 | B14: 11 | C14: =C13 -> 36755.3 | D14: =D13 -> 5500 | I14: Alíquota do Excedente | J14: =IF(G7=0,0,G13*1.2) -> 0 | U14: CSLL | V14: =32%*9% -> 0.0288 | W14: =$J$11*V14 -> 1058.5526 | X14: =X13*32% -> 35285.088
A15: 2017 | B15: 12 | C15: =C14 -> 36755.3 | D15: =D14 -> 5500 | F15: Fator "R" | G15: =IF(V2=3,D16/C16,"N/A") -> N/A | I15: Imposto Excesso Devido | J15: =G7*J14 -> 0 | U15: ISS | V15: 0.05 | W15: =$J$11*V15 -> 1837.765 | X15: =X14*32% -> 11291.228
C16: =SUM(C4:C15) -> 441063.6 | D16: =SUM(D4:D15) -> 66000 | F16: =IF(V2<>3,"",IF(G15<0.28,"MIGRAR PARA ANEXO V","")) | I16: Total SIMPLES Devido | J16: =J15+J13 -> 2714.0406 | S16: 3800000 | U16: INSS Pat | V16: 0.2 | W16: =V16*D17 -> 1100
A17: 2018 | B17: 1 | C17: =C15 -> 36755.3 | D17: =D15 -> 5500 | S17: 3600000 | U17: Total | W17: =SUM(W9:W16) -> 8443.7089
A18: 2018 | B18: 2 | F18: COMPARATIVO | S18: 4320000 | W18: =W17/J11 -> 0.22972766
A19: 2018 | B19: 3 | S19: =S18-S17 -> 720000 | W19: =W17-J13 -> 5729.6683
A20: 2018 | B20: 4 | F20: SIMPLES - 2018 | G20: =J16 -> 2714.0406 | I20: SIMPLES - 2017 | J20: =J21*J11 -> 2514.0625 | S20: =S19/S17 -> 0.2
A21: 2018 | B21: 5 | F21: Alíquota Efetiva | G21: =G13 -> 0.073840796 | I21: Alíquota Efetiva | J21: =SUMIFS('Anexos 2017'!E:E,'Anexos 2017'!B:B,Análise!J22,'Anexos 2017'!A:A,Análise!V3) -> 0.0684
A22: 2018 | B22: 6 | F22: Faixa | G22: =IF(C16<=Mestres!D4,Mestres!B4,IF(C16<=Mestres!D5,Mestres!B5,IF(C16<=Mestres!D6,Mestres!B6,IF(C16<=Mestres!D7,Mestres!B7,IF(C16<=Mestres!D8,Mestres!B8,Mestres!B9))))) -> 3 | I22: Faixa | J22: =IF(C16<=Mestres!K4,Mestres!I4,IF(C16<=Mestres!K5,Mestres!I5,IF(C16<=Mestres!K6,Mestres!I6,IF(C16<=Mestres!K7,Mestres!I7,IF(C16<=Mestres!K8,Mestres!I8,IF(C16<=Mestres!K9,Mestres!I9,IF(C16<=Mestres!K10,Mestres!I10,IF(C16<=Mestres!K11,Mestres!I11,IF(C16<=Mestres!K12,Mestres!I12,IF(C16<=Mestres!K13,Mestres!I13,IF(C16<=Mestres!K14,Mestres!I14,IF(C16<=Mestres!K15,Mestres!I15,IF(C16<=Mestres!K16,Mestres!I16,IF(C16<=Mestres!K17,Mestres!I17,IF(C16<=Mestres!K18,Mestres!I18,IF(C16<=Mestres!K19,Mestres!I19,IF(C16<=Mestres!K20,Mestres!I20,IF(C16<=Mestres!K21,Mestres!I21,IF(C16<=Mestres!K22,Mestres!I22,Mestres!I23))))))))))))))))))) -> 3
A23: 2018 | B23: 7
A24: 2018 | B24: 8 | M24: =F20 -> SIMPLES - 2018 | N24: =G20 -> 2714.0406
A25: 2018 | B25: 9 | M25: =I20 -> SIMPLES - 2017 | N25: =J20 -> 2514.0625
A26: 2018 | B26: 10
A27: 2018 | B27: 11
A28: 2018 | B28: 12
C29: =SUM(C17:C28) -> 36755.3 | D29: =SUM(D17:D28) -> 5500
F34: COMPARATIVO - LUCRO PRESUMIDO
M36: Total | N36: =SUM(N37:N43) -> 0.2313
M37: PIS | N37: 0.0065
M38: COFINS | N38: 0.03 | O38: MP
F39: SIMPLES - 2018 | G39: =J16 -> 2714.0406 | I39: Lucro Presumido | J39: =J41*J11 -> 9601.5009 | M39: IRPJ | N39: =SUMIF(Mestres!M4:M13,X2,Mestres!N4:N13)*0.15 -> 0.048 | O39: =SUMIF(Mestres!M4:M13,X2,Mestres!N4:N13) -> 0.32
F40: Alíquota Efetiva | G40: =G13 -> 0.073840796 | I40: INSS Patronal | J40: =D17*N44 -> 1100 | M40: AD | N40: =IF(O40>20000,(O40-20000)/J11*0.1,0) -> 0 | O40: =O39*J11 -> 11761.696
F41: Faixa | G41: =G22 -> 3 | I41: Alíquota Efetiva | J41: =N36+(J40/J11) -> 0.26122766 | M41: CSLL | N41: =SUMIF(Mestres!M4:M13,X2,Mestres!N4:N13)*0.09 -> 0.0288
M42: ISS | N42: 0 | Q42: Valor | R42: ICMS
M43: ICMS | N43: =R45 -> 0.118 | P43: Compra | Q43: 100 | R43: =-Q43*0.17 -> -17
M44: INSS | N44: 0.2 | P44: Venda | Q44: =Q43*1.6 -> 160 | R44: =Q44*0.18 -> 28.8
Q45: ICMS Estimado | R45: =SUM(R43:R44)/100 -> 0.118
M47: =F39 -> SIMPLES - 2018 | N47: =G39 -> 2714.0406
...

Sheet Mestres
B2: 2018 | F2: 2018 | I2: 2017 | M2: Lucro Presumido
B3: Faixas | C3: Vigencia | D3: Limite | F3: Anexos | G3: Descrição | I3: Faixas | J3: Vigencia | K3: Limite | M3: Faixa | N3: Margem | O3: Atividade exercida
B4: 1 | C4: 2018 | D4: 180000 | F4: 1 | G4: Anexo I - Comércio | I4: 1 | J4: 2017 | K4: 180000 | M4: 1 | N4: 0.016 | O4: Revenda de combustíveis e gás natural
B5: 2 | C5: 2018 | D5: 360000 | F5: 2 | G5: Anexo II - Indústria | I5: 2 | J5: 2017 | K5: 360000 | M5: 2 | N5: 0.08 | O5: Transporte de cargas
B6: 3 | C6: 2018 | D6: 720000 | F6: 3 | G6: Anexo III - Serviço | I6: 3 | J6: 2017 | K6: 540000 | M6: 3 | N6: 0.08 | O6: Atividades imobiliárias
B7: 4 | C7: 2018 | D7: 1800000 | F7: 4 | G7: Anexo IV - Serviço II | I7: 4 | J7: 2017 | K7: 720000 | M7: 4 | N7: 0.08 | O7: Industrialização para terceiros com recebimento do material
B8: 5 | C8: 2018 | D8: 3600000 | F8: 5 | G8: Anexo V - Serviço III | I8: 5 | J8: 2017 | K8: 900000 | M8: 5 | N8: 0.08 | O8: Demais atividades não especificadas que não sejam prestação de serviço
B9: 6 | C9: 2018 | D9: 4800000 | I9: 6 | J9: 2017 | K9: 1080000 | M9: 6 | N9: 0.16 | O9: Transporte que não seja de cargas e serviços em geral
F10: 2017 | I10: =I9+1 -> 7 | J10: 2017 | K10: 1260000 | M10: =M9+1 -> 7 | N10: 0.32 | O10: Serviços profissionais que exijam formação técnica ou acadêmica - como advocacia e engenharia
F11: Anexos | G11: Descrição | I11: =I10+1 -> 8 | J11: 2017 | K11: 1440000 | M11: =M10+1 -> 8 | N11: 0.32 | O11: Intermediação de negócios
F12: 1 | G12: Anexo I - Comércio | I12: =I11+1 -> 9 | J12: 2017 | K12: 1620000 | M12: =M11+1 -> 9 | N12: 0.32 | O12: Administração de bens móveis ou imóveis, locação ou cessão desses mesmos bens
F13: 2 | G13: Anexo II - Indústria | I13: =I12+1 -> 10 | J13: 2017 | K13: 1800000 | M13: =M12+1 -> 10 | N13: 0.32 | O13: Construção civil e serviços em geral
F14: 3 | G14: Anexo III - Serviço | I14: =I13+1 -> 11 | J14: 2017 | K14: 1980000
F15: 4 | G15: Anexo IV - Serviço II | I15: =I14+1 -> 12 | J15: 2017 | K15: 2160000
F16: 5.1 | G16: Anexo V - Serviço III | I16: =I15+1 -> 13 | J16: 2017 | K16: 2340000
F17: 5.2 | G17: Anexo V - Serviço III | I17: =I16+1 -> 14 | J17: 2017 | K17: 2520000
F18: 5.3 | G18: Anexo V - Serviço III | I18: =I17+1 -> 15 | J18: 2017 | K18: 2700000
I19: =I18+1 -> 16 | J19: 2017 | K19: 2880000
I20: =I19+1 -> 17 | J20: 2017 | K20: 3060000
I21: =I20+1 -> 18 | J21: 2017 | K21: 3240000
I22: =I21+1 -> 19 | J22: 2017 | K22: 3420000
I23: =I22+1 -> 20 | J23: 2017 | K23: 3600000

Sheet Anexos 2018
A1: Anexo | B1: Vigência | C1: Faixa | D1: Receita Bruta | E1: Alíquota | F1: Desconto
A2: 1 | B2: 2018 | C2: 1 | D2: 180000 | E2: 0.04 | F2: 0
A3: 1 | B3: 2018 | C3: 2 | D3: 360000 | E3: 0.073 | F3: 5940
A4: 1 | B4: 2018 | C4: 3 | D4: 720000 | E4: 0.095 | F4: 13860
A5: 1 | B5: 2018 | C5: 4 | D5: 1800000 | E5: 0.107 | F5: 22500
A6: 1 | B6: 2018 | C6: 5 | D6: 3600000 | E6: 0.143 | F6: 87300
A7: 1 | B7: 2018 | C7: 6 | D7: 4800000 | E7: 0.19 | F7: 378000
A8: 2 | B8: 2018 | C8: 1 | D8: 180000 | E8: 0.045 | F8: 0
A9: 2 | B9: 2018 | C9: 2 | D9: 360000 | E9: 0.079 | F9: 5940
A10: 2 | B10: 2018 | C10: 3 | D10: 720000 | E10: 0.1 | F10: 13860
A11: 2 | B11: 2018 | C11: 4 | D11: 1800000 | E11: 0.112 | F11: 22500
A12: 2 | B12: 2018 | C12: 5 | D12: 3600000 | E12: 0.147 | F12: 85000
A13: 2 | B13: 2018 | C13: 6 | D13: 4800000 | E13: 0.3 | F13: 720000
... A31: 5 | B31: 2018 | C31: 6 | D31: 4800000 | E31: 0.305 | F31: 540000

Sheet Anexos 2017
A1: Anexo | B1: Faixa | C1: Limite Faturamento | D1: Receita Bruta em 12 meses (em R$) | E1: Alíquota | F1: IRPJ | G1: CSLL | H1: Cofins | I1: PIS/Pasep | J1: CPP | K1: ICMS | L1: IPI | M1: ISS
A2: 1 | B2: =1 -> 1 | C2: 180000 | D2: Até 180.000,00 | E2: 0.04 | F2: 0 | G2: 0 | H2: 0 | I2: 0 | J2: 0.0275 | K2: 0.0125
A3: 1 | B3: =B2+1 -> 2 | C3: 360000 | D3: De 180.000,01 a 360.000,00 | E3: 0.0547 | F3: 0 | G3: 0 | H3: 0.0086 | I3: 0 | J3: 0.0275 | K3: 0.0186
A4: 1 | B4: =B3+1 -> 3 | C4: 540000 | D4: De 360.000,01 a 540.000,00 | E4: 0.0684 | F4: 0.0027 | G4: 0.0031 | H4: 0.0095 | I4: 0.0023 | J4: 0.0275 | K4: 0.0233
A5: 1 | B5: =B4+1 -> 4 | C5: 720000 | D5: De 540.000,01 a 720.000,00 | E5: 0.0754 | F5: 0.0035 | G5: 0.0035 | H5: 0.0104 | I5: 0.0025 | J5: 0.0299 | K5: 0.0256
A6: 1 | B6: =B5+1 -> 5 | C6: 900000 | D6: De 720.000,01 a 900.000,00 | E6: 0.076 | F6: 0.0035 | G6: 0.0035 | H6: 0.0105 | I6: 0.0025 | J6: 0.0302 | K6: 0.0258
A7: 1 | B7: =B6+1 -> 6 | C7: 1080000 | D7: De 900.000,01 a 1.080.000,00 | E7: 0.0828 | F7: 0.0038 | G7: 0.0038 | H7: 0.0115 | I7: 0.0027 | J7: 0.0328 | K7: 0.0282
A8: 1 | B8: =B7+1 -> 7 | C8: 1260000 | D8: De 1.080.000,01 a 1.260.000,00 | E8: 0.0836 | F8: 0.0039 | G8: 0.0039 | H8: 0.0116 | I8: 0.0028 | J8: 0.033 | K8: 0.0284
A9: 1 | B9: =B8+1 -> 8 | C9: 1440000 | D9: De 1.260.000,01 a 1.440.000,00 | E9: 0.0845 | F9: 0.0039 | G9: 0.0039 | H9: 0.0117 | I9: 0.0028 | J9: 0.0335 | K9: 0.0287
A10: 1 | B10: =B9+1 -> 9 | C10: 1620000 | D10: De 1.440.000,01 a 1.620.000,00 | E10: 0.0903 | F10: 0.0042 | G10: 0.0042 | H10: 0.0125 | I10: 0.003 | J10: 0.0357 | K10: 0.0307
A11: 1 | B11: =B10+1 -> 10 | C11: 1800000 | D11: De 1.620.000,01 a 1.800.000,00 | E11: 0.0912 | F11: 0.0043 | G11: 0.0043 | H11: 0.0126 | I11: 0.003 | J11: 0.036 | K11: 0.031
A12: 1 | B12: =B11+1 -> 11 | C12: 1980000 | D12: De 1.800.000,01 a 1.980.000,00 | E12: 0.0995 | F12: 0.0046 | G12: 0.0046 | H12: 0.0138 | I12: 0.0033 | J12: 0.0394 | K12: 0.0338
A13: 1 | B13: =B12+1 -> 12 | C13: 2160000 | D13: De 1.980.000,01 a 2.160.000,00 | E13: 0.1004 | F13: 0.0046 | G13: 0.0046 | H13: 0.0139 | I13: 0.0033 | J13: 0.0399 | K13: 0.0341
A14: 1 | B14: =B13+1 -> 13 | C14: 2340000 | D14: De 2.160.000,01 a 2.340.000,00 | E14: 0.1013 | F14: 0.0047 | G14: 0.0047 | H14: 0.014 | I14: 0.0033 | J14: 0.0401 | K14: 0.0345
... A21: 1 | B21: =B20+1 -> 20 | C21: 3600000 | D21: De 3.420.000,01 a 3.600.000,00 | E21: 0.1161 | F21: 0.0054 | G21: 0.0054 | H21: 0.016 | I21: 0.0038 | J21: 0.046 | K21: 0.0395
A22: 2 | B22: =1 -> 1 | C22: 180000 | D22: Até 180.000,00 | E22: 0.045 | F22: 0 | G22: 0 | H22: 0 | I22: 0 | J22: 0.0275 | K22: 0.0125 | L22: 0.005
A23: 2 | B23: =B22+1 -> 2 | C23: 360000 | D23: De 180.000,01 a 360.000,00 | E23: 0.0597 | F23: 0 | G23: 0 | H23: 0.0086 | I23: 0 | J23: 0.0275 | K23: 0.0186 | L23: 0.005
A24: 2 | B24: =B23+1 -> 3 | C24: 540000 | D24: De 360.000,01 a 540.000,00 | E24: 0.0734 | F24: 0.0027 | G24: 0.0031 | H24: 0.0095 | I24: 0.0023 | J24: 0.0275 | K24: 0.0233 | L24: 0.005
A25: 2 | B25: =B24+1 -> 4 | C25: 720000 | D25: De 540.000,01 a 720.000,00 | E25: 0.0804 | F25: 0.0035 | G25: 0.0035 | H25: 0.0104 | I25: 0.0025 | J25: 0.0299 | K25: 0.0256 | L25: 0.005
A26: 2 | B26: =B25+1 -> 5 | C26: 900000 | D26: De 720.000,01 a 900.000,00 | E26: 0.081 | F26: 0.0035 | G26: 0.0035 | H26: 0.0105 | I26: 0.0025 | J26: 0.0302 | K26: 0.0258 | L26: 0.005
A27: 2 | B27: =B26+1 -> 6 | C27: 1080000 | D27: De 900.000,01 a 1.080.000,00 | E27: 0.0878 | F27: 0.0038 | G27: 0.0038 | H27: 0.0115 | I27: 0.0027 | J27: 0.0328 | K27: 0.0282 | L27: 0.005
A28: 2 | B28: =B27+1 -> 7 | C28: 1260000 | D28: De 1.080.000,01 a 1.260.000,00 | E28: 0.0886 | F28: 0.0039 | G28: 0.0039 | H28: 0.0116 | I28: 0.0028 | J28: 0.033 | K28: 0.0284 | L28: 0.005
A29: 2 | B29: =B28+1 -> 8 | C29: 1440000 | D29: De 1.260.000,01 a 1.440.000,00 | E29: 0.0895 | F29: 0.0039 | G29: 0.0039 | H29: 0.0117 | I29: 0.0028 | J29: 0.0335 | K29: 0.0287 | L29: 0.005
A30: 2 | B30: =B29+1 -> 9 | C30: 1620000 | D30: De 1.440.000,01 a 1.620.000,00 | E30: 0.0953 | F30: 0.0042 | G30: 0.0042 | H30: 0.0125 | I30: 0.003 | J30: 0.0357 | K30: 0.0307 | L30: 0.005
A31: 2 | B31: =B30+1 -> 10 | C31: 1800000 | D31: De 1.620.000,01 a 1.800.000,00 | E31: 0.0962 | F31: 0.0042 | G31: 0.0042 | H31: 0.0126 | I31: 0.003 | J31: 0.0362 | K31: 0.031 | L31: 0.005
A32: 2 | B32: =B31+1 -> 11 | C32: 1980000 | D32: De 1.800.000,01 a 1.980.000,00 | E32: 0.1045 | F32: 0.0046 | G32: 0.0046 | H32: 0.0138 | I32: 0.0033 | J32: 0.0394 | K32: 0.0338 | L32: 0.005
A33: 2 | B33: =B32+1 -> 12 | C33: 2160000 | D33: De 1.980.000,01 a 2.160.000,00 | E33: 0.1054 | F33: 0.0046 | G33: 0.0046 | H33: 0.0139 | I33: 0.0033 | J33: 0.0399 | K33: 0.0341 | L33: 0.005
A34: 2 | B34: =B33+1 -> 13 | C34: 2340000 | D34: De 2.160.000,01 a 2.340.000,00 | E34: 0.1063 | F34: 0.0047 | G34: 0.0047 | H34: 0.014 | I34: 0.0033 | J34: 0.0401 | K34: 0.0345 | L34: 0.005
... A41: 2 | B41: =B40+1 -> 20 | C41: 3600000 | D41: De 3.420.000,01 a 3.600.000,00 | E41: 0.1211 | F41: 0.0054 | G41: 0.0054 | H41: 0.016 | I41: 0.0038 | J41: 0.046 | K41: 0.0395 | L41: 0.005
D42: Receita Bruta em 12 meses (em R$) | E42: Alíquota | F42: IRPJ | G42: CSLL | H42: Cofins | I42: PIS/Pasep | J42: CPP | M42: ISS
A43: 3 | B43: =1 -> 1 | C43: 180000 | D43: Até 180.000,00 | E43: 0.06 | F43: 0 | G43: 0 | H43: 0 | I43: 0 | J43: 0.04 | M43: 0.02
A44: 3 | B44: =B43+1 -> 2 | C44: 360000 | D44: De 180.000,01 a 360.000,00 | E44: 0.0821 | F44: 0 | G44: 0 | H44: 0.0142 | I44: 0 | J44: 0.04 | M44: 0.0279
A45: 3 | B45: =B44+1 -> 3 | C45: 540000 | D45: De 360.000,01 a 540.000,00 | E45: 0.1026 | F45: 0.0048 | G45: 0.0043 | H45: 0.0143 | I45: 0.0035 | J45: 0.0407 | M45: 0.035
A46: 3 | B46: =B45+1 -> 4 | C46: 720000 | D46: De 540.000,01 a 720.000,00 | E46: 0.1131 | F46: 0.0053 | G46: 0.0053 | H46: 0.0156 | I46: 0.0038 | J46: 0.0447 | M46: 0.0384
A47: 3 | B47: =B46+1 -> 5 | C47: 900000 | D47: De 720.000,01 a 900.000,00 | E47: 0.114 | F47: 0.0053 | G47: 0.0052 | H47: 0.0158 | I47: 0.0038 | J47: 0.0452 | M47: 0.0387
A48: 3 | B48: =B47+1 -> 6 | C48: 1080000 | D48: De 900.000,01 a 1.080.000,00 | E48: 0.1242 | F48: 0.0057 | G48: 0.0057 | H48: 0.0173 | I48: 0.004 | J48: 0.0492 | M48: 0.0423
A49: 3 | B49: =B48+1 -> 7 | C49: 1260000 | D49: De 1.080.000,01 a 1.260.000,00 | E49: 0.1254 | F49: 0.0059 | G49: 0.0056 | H49: 0.0174 | I49: 0.0042 | J49: 0.0497 | M49: 0.0426
A50: 3 | B50: =B49+1 -> 8 | C50: 1440000 | D50: De 1.260.000,01 a 1.440.000,00 | E50: 0.1268 | F50: 0.0059 | G50: 0.0057 | H50: 0.0176 | I50: 0.0042 | J50: 0.0503 | M50: 0.0431
A51: 3 | B51: =B50+1 -> 9 | C51: 1620000 | D51: De 1.440.000,01 a 1.620.000,00 | E51: 0.1355 | F51: 0.0063 | G51: 0.0061 | H51: 0.0188 | I51: 0.0045 | J51: 0.0537 | M51: 0.0461
A52: 3 | B52: =B51+1 -> 10 | C52: 1800000 | D52: De 1.620.000,01 a 1.800.000,00 | E52: 0.1368 | F52: 0.0063 | G52: 0.0064 | H52: 0.0189 | I52: 0.0045 | J52: 0.0542 | M52: 0.0465
...
