Workbook

Sheet Simples Nacional 2017
A1: SIMPLES NACIONAL 2017
A2: Anexo I
A4: Receita Bruta em 12 meses (em R$) | B4: Alíquota
A5: Até 180.000,00 | B5: =4%-1.25% -> 0.0275
A6: De 180.000,01 a 360.000,00 | B6: 0.0361
A7: De 360.000,01 a 540.000,00 | B7: =6.84%-2.33%+0.67% -> 0.0518
A8: De 540.000,01 a 720.000,00 | B8: =7.54%-2.56%+1.07% -> 0.0605
A9: De 720.000,01 a 900.000,00 | B9: =7.6%-2.58%+1.33% -> 0.0635
A10: De 900.000,01 a 1.080.000,00 | B10: =8.28%-2.82%+1.52% -> 0.0698
A11: De 1.080.000,01 a 1.260.000,00 | B11: =8.36%-2.84%+1.83% -> 0.0735
A12: De 1.260.000,01 a 1.440.000,00 | B12: =8.45%-2.87%+2.07% -> 0.0765
A13: De 1.440.000,01 a 1.620.000,00 | B13: =9.03%-3.07%+2.27% -> 0.0823
A14: De 1.620.000,01 a 1.800.000,00 | B14: =9.12%-3.1%+2.42% -> 0.0844
A15: De 1.800.000,01 a 1.980.000,00 | B15: =9.95%-3.38%+2.56% -> 0.0913
A16: De 1.980.000,01 a 2.160.000,00 | B16: =10.04%-3.41%+2.67% -> 0.093
A17: De 2.160.000,01 a 2.340.000,00 | B17: =10.23%-3.48%+2.76% -> 0.0951
A18: De 2.340.000,01 a 2.520.000,00 | B18: =10.23%-3.48%-2.84% -> 0.0391
A19: De 2.520.000,01 a 2.700.000,00 | B19: =10.32%-3.51%+2.92% -> 0.0973
A20: De 2.700.000,01 a 2.880.000,00 | B20: =11.23%-3.82%+3.06% -> 0.1047
A21: De 2.880.000,01 a 3.060.000,00 | B21: =11.32%-3.85%+3.19% -> 0.1066
A22: De 3.060.000,01 a 3.240.000,00 | B22: =11.42%-3.88%+3.3% -> 0.1084
A23: De 3.240.000,01 a 3.420.000,00 | B23: =11.51%-3.91%+3.4% -> 0.11
A24: De 3.420.000,01 a 3.600.000,00 | B24: =11.61%-3.95%+3.5% -> 0.1116

Sheet SIMULAÇÃO
A1: Empresa:
A2: CNPJ:
A4: Empresa prestadora de serviços
A5: Atividade: 4781-4/00 Comércio Varejista de Artigos do Vestuário e Acessórios
A9: SIMPLES NACIONAL 2018
A10: Anexo I
A12: Receita Bruta em 12 Meses (em R$) | C12: Alíquota | D12: Valor a Deduzir (em R$) | E12: % ICMS NA ALIQUOTA | F12: % a Deduzir ICMS | G12: % REDUÇÃO ICMS NO IMPOSTO
A13: 1ª Faixa | B13: Até 180.000,00 | C13: 0.04 | D13: 0 | E13: 0.34 | F13: 1 | G13: =E13*F13 -> 0.34
A14: 2ª Faixa | B14: De 180.000,01 a 360.000,00 | C14: 0.073 | D14: 5940 | E14: 0.34 | F14: 1 | G14: =E14*F14 -> 0.34
A15: 3ª Faixa | B15: De 360.000,01 a 720.000,00 | C15: 0.095 | D15: 13860 | E15: 0.335 | F15: 0.7124 | G15: =E15*F15 -> 0.238654
A16: 4ª Faixa | B16: De 720.000,01 a 1.800.000,00 | C16: 0.107 | D16: 22500 | E16: 0.335 | F16: 0.4845 | G16: =E16*F16 -> 0.1623075
A17: 5ª Faixa | B17: De 1.800.000,01 a 3.600.000,00 | C17: 0.143 | D17: 87300 | E17: 0.335 | F17: 0.2496 | G17: =E17*F17 -> 0.083616
A18: 6ª Faixa | B18: De 3.600.000,01 a 4.800.000,00 | C18: 0.19 | D18: 378000 | E18: - | F18: -
A20: VALORES FATURAMENTO 2017
A21: 42736 | B21: 42767 | C21: 42795 | D21: 42826 | E21: 42856 | F21: 42887
H22: *** PESSOAL PREENCHER COM OS VALORES DE 2017, PARA ENCONTRAR A FAIXA PARA 2018
A23: 42917 | B23: 42948 | C23: 42979 | D23: 43009 | E23: 43040 | F23: 43070
A26: RECEITA BRUTA ACUMULADA 12 MESES - 2017 | D26: =SUM(A22,B22,C22,D22,E22,F22,A24,B24,C24,D24,E24,F24) -> 0
A28: SIMULAÇÃO SIMPLES NACIONAL 2018
A29: MÊS | B29: RECEITA MENSAL | C29: RBT ÚLTIMOS 12 MESES | D29: Alíquota nominal | E29: Dedução | F29: Alíquota Efetiva c/ICMS | G29: Alíquota Efetiva c/redução de ICMS | H29: Alíquota DAS 2017 | I29: Vl DAS 2018 | J29: VL DAS LEGISLAÇÃO 2017 | K29: Legislação 2018 - 2017
A30: Janeiro | B30: 0 | C30: =SUM(A22,B22,C22,D22,E22,F22,A24,B24,C24,D24,E24,F24) -> 0 | D30: =IF(C30<=180000,$C$13,IF(AND(C30>180000,C30<=360000),$C$14,IF(AND(C30<=720000,C30>=360000.01),$C$15,IF(AND(C30<=1800000,C30>=720000.01),$C$16,IF(AND(C30<=3600000,C30>=1800000.01),$C$17,IF(AND(C30<=4800000,C30>=3600000.01),$C$18)))))) -> 0.04 | E30: =LOOKUP(D30,$C$13:$C$18,$D$13:$D$18) -> 0 | F30: =(((C30*D30)-E30)/C30) -> #DIV/0! | G30: =F30 -(F30*(LOOKUP(D30,$C$13:$C$18,$G$13:$G$18))) -> #DIV/0! | H30: =IF(C30<=180000,'Simples Nacional 2017'!$B$5,IF(AND(C30>180000,C30<=360000),'Simples Nacional 2017'!$B$6,IF(AND(C30<=540000,C30>=360000.01),'Simples Nacional 2017'!$B$7,IF(AND(C30<=720000,C30>=540000.01),'Simples Nacional 2017'!$B$8,IF(AND(C30<=900000,C30>=720000.01),'Simples Nacional 2017'!$B$9,IF(AND(C30<=1080000,C30>=900000.01),'Simples Nacional 2017'!$B$10,IF(AND(C30<=1260000,C30>=1080000.01),'Simples Nacional 2017'!$B$11,IF(AND(C30<=1440000,C30>=1260000.01),'Simples Nacional 2017'!$B$12,IF(AND(C30<=1620000,C30>=1440000.01),'Simples Nacional 2017'!$B$13,IF(AND(C30<=1800000,C30>=1620000.01),'Simples Nacional 2017'!$B$14,IF(AND(C30<=1980000,C30>=1800000.01),'Simples Nacional 2017'!$B$15,IF(AND(C30<=2160000,C30>=1980000.01),'Simples Nacional 2017'!$B$16,IF(AND(C30<=2340000,C30>=2160000.01),'Simples Nacional 2017'!$B$17,IF(AND(C30<=2520000,C30>=2340000.01),'Simples Nacional 2017'!$B$18,IF(AND(C30<=2700000,C30>=2520000.01),'Simples Nacional 2017'!$B$19,IF(AND(C30<=2880000,C30>=2700000.01),'Simples Nacional 2017'!$B$20,IF(AND(C30<=3060000,C30>=2880000.01),'Simples Nacional 2017'!$B$21,IF(AND(C30<=3240000,C30>=3060000.01),'Simples Nacional 2017'!$B$22,IF(AND(C30<=3420000,C30>=3240000.01),'Simples Nacional 2017'!$B$23,IF(AND(C30<=3600000,C30>=3420000.01),'Simples Nacional 2017'!$B$24)))))))))))))))))))) -> 0.0275 | I30: =B30*F30 -> #DIV/0! | J30: =B30*H30 -> 0 | K30: =I30-J30 -> #DIV/0!
A31: Fevereiro | B31: 0 | C31: =SUM(B22,C22,D22,E22,F22,A24,B24,C24,D24,E24,F24,B30) -> 0 | D31: =IF(C31<=180000,$C$13,IF(AND(C31>180000,C31<=360000),$C$14,IF(AND(C31<=720000,C31>=360000.01),$C$15,IF(AND(C31<=1800000,C31>=720000.01),$C$16,IF(AND(C31<=3600000,C31>=1800000.01),$C$17,IF(AND(C31<=4800000,C31>=3600000.01),$C$18)))))) -> 0.04 | E31: =LOOKUP(D31,$C$13:$C$18,$D$13:$D$18) -> 0 | F31: =((C31*D31)-E31)/C31 -> #DIV/0! | G31: =F31 -(F31*(LOOKUP(D31,$C$13:$C$18,$G$13:$G$18))) -> #DIV/0! | H31: =IF(C31<=180000,'Simples Nacional 2017'!$B$5,IF(AND(C31>180000,C31<=360000),'Simples Nacional 2017'!$B$6,IF(AND(C31<=540000,C31>=360000.01),'Simples Nacional 2017'!$B$7,IF(AND(C31<=720000,C31>=540000.01),'Simples Nacional 2017'!$B$8,IF(AND(C31<=900000,C31>=720000.01),'Simples Nacional 2017'!$B$9,IF(AND(C31<=1080000,C31>=900000.01),'Simples Nacional 2017'!$B$10,IF(AND(C31<=1260000,C31>=1080000.01),'Simples Nacional 2017'!$B$11,IF(AND(C31<=1440000,C31>=1260000.01),'Simples Nacional 2017'!$B$12,IF(AND(C31<=1620000,C31>=1440000.01),'Simples Nacional 2017'!$B$13,IF(AND(C31<=1800000,C31>=1620000.01),'Simples Nacional 2017'!$B$14,IF(AND(C31<=1980000,C31>=1800000.01),'Simples Nacional 2017'!$B$15,IF(AND(C31<=2160000,C31>=1980000.01),'Simples Nacional 2017'!$B$16,IF(AND(C31<=2340000,C31>=2160000.01),'Simples Nacional 2017'!$B$17,IF(AND(C31<=2520000,C31>=2340000.01),'Simples Nacional 2017'!$B$18,IF(AND(C31<=2700000,C31>=2520000.01),'Simples Nacional 2017'!$B$19,IF(AND(C31<=2880000,C31>=2700000.01),'Simples Nacional 2017'!$B$20,IF(AND(C31<=3060000,C31>=2880000.01),'Simples Nacional 2017'!$B$21,IF(AND(C31<=3240000,C31>=3060000.01),'Simples Nacional 2017'!$B$22,IF(AND(C31<=3420000,C31>=3240000.01),'Simples Nacional 2017'!$B$23,IF(AND(C31<=3600000,C31>=3420000.01),'Simples Nacional 2017'!$B$24)))))))))))))))))))) -> 0.0275 | I31: =B31*F31 -> #DIV/0! | J31: =B31*H31 -> 0 | K31: =I31-J31 -> #DIV/0!
A32: Março | B32: 0 | C32: =SUM(C22,D22,E22,F22,A24,B24,C24,D24,E24,F24,B30,B31) -> 0 | D32: =IF(C32<=180000,$C$13,IF(AND(C32>180000,C32<=360000),$C$14,IF(AND(C32<=720000,C32>=360000.01),$C$15,IF(AND(C32<=1800000,C32>=720000.01),$C$16,IF(AND(C32<=3600000,C32>=1800000.01),$C$17,IF(AND(C32<=4800000,C32>=3600000.01),$C$18)))))) -> 0.04 | E32: =LOOKUP(D32,$C$13:$C$18,$D$13:$D$18) -> 0 | F32: =((C32*D32)-E32)/C32 -> #DIV/0! | G32: =F32 -(F32*(LOOKUP(D32,$C$13:$C$18,$G$13:$G$18))) -> #DIV/0! | H32: =IF(C32<=180000,'Simples Nacional 2017'!$B$5,IF(AND(C32>180000,C32<=360000),'Simples Nacional 2017'!$B$6,IF(AND(C32<=540000,C32>=360000.01),'Simples Nacional 2017'!$B$7,IF(AND(C32<=720000,C32>=540000.01),'Simples Nacional 2017'!$B$8,IF(AND(C32<=900000,C32>=720000.01),'Simples Nacional 2017'!$B$9,IF(AND(C32<=1080000,C32>=900000.01),'Simples Nacional 2017'!$B$10,IF(AND(C32<=1260000,C32>=1080000.01),'Simples Nacional 2017'!$B$11,IF(AND(C32<=1440000,C32>=1260000.01),'Simples Nacional 2017'!$B$12,IF(AND(C32<=1620000,C32>=1440000.01),'Simples Nacional 2017'!$B$13,IF(AND(C32<=1800000,C32>=1620000.01),'Simples Nacional 2017'!$B$14,IF(AND(C32<=1980000,C32>=1800000.01),'Simples Nacional 2017'!$B$15,IF(AND(C32<=2160000,C32>=1980000.01),'Simples Nacional 2017'!$B$16,IF(AND(C32<=2340000,C32>=2160000.01),'Simples Nacional 2017'!$B$17,IF(AND(C32<=2520000,C32>=2340000.01),'Simples Nacional 2017'!$B$18,IF(AND(C32<=2700000,C32>=2520000.01),'Simples Nacional 2017'!$B$19,IF(AND(C32<=2880000,C32>=2700000.01),'Simples Nacional 2017'!$B$20,IF(AND(C32<=3060000,C32>=2880000.01),'Simples Nacional 2017'!$B$21,IF(AND(C32<=3240000,C32>=3060000.01),'Simples Nacional 2017'!$B$22,IF(AND(C32<=3420000,C32>=3240000.01),'Simples Nacional 2017'!$B$23,IF(AND(C32<=3600000,C32>=3420000.01),'Simples Nacional 2017'!$B$24)))))))))))))))))))) -> 0.0275 | I32: =B32*F32 -> #DIV/0! | J32: =B32*H32 -> 0 | K32: =I32-J32 -> #DIV/0!
A33: Abril | B33: 0 | C33: =SUM(D22,E22,F22,A24,B24,C24,D24,E24,F24,B30,B31,B32) -> 0 | D33: =IF(C33<=180000,$C$13,IF(AND(C33>180000,C33<=360000),$C$14,IF(AND(C33<=720000,C33>=360000.01),$C$15,IF(AND(C33<=1800000,C33>=720000.01),$C$16,IF(AND(C33<=3600000,C33>=1800000.01),$C$17,IF(AND(C33<=4800000,C33>=3600000.01),$C$18)))))) -> 0.04 | E33: =LOOKUP(D33,$C$13:$C$18,$D$13:$D$18) -> 0 | F33: =((C33*D33)-E33)/C33 -> #DIV/0! | G33: =F33 -(F33*(LOOKUP(D33,$C$13:$C$18,$G$13:$G$18))) -> #DIV/0! | H33: =IF(C33<=180000,'Simples Nacional 2017'!$B$5,IF(AND(C33>180000,C33<=360000),'Simples Nacional 2017'!$B$6,IF(AND(C33<=540000,C33>=360000.01),'Simples Nacional 2017'!$B$7,IF(AND(C33<=720000,C33>=540000.01),'Simples Nacional 2017'!$B$8,IF(AND(C33<=900000,C33>=720000.01),'Simples Nacional 2017'!$B$9,IF(AND(C33<=1080000,C33>=900000.01),'Simples Nacional 2017'!$B$10,IF(AND(C33<=1260000,C33>=1080000.01),'Simples Nacional 2017'!$B$11,IF(AND(C33<=1440000,C33>=1260000.01),'Simples Nacional 2017'!$B$12,IF(AND(C33<=1620000,C33>=1440000.01),'Simples Nacional 2017'!$B$13,IF(AND(C33<=1800000,C33>=1620000.01),'Simples Nacional 2017'!$B$14,IF(AND(C33<=1980000,C33>=1800000.01),'Simples Nacional 2017'!$B$15,IF(AND(C33<=2160000,C33>=1980000.01),'Simples Nacional 2017'!$B$16,IF(AND(C33<=2340000,C33>=2160000.01),'Simples Nacional 2017'!$B$17,IF(AND(C33<=2520000,C33>=2340000.01),'Simples Nacional 2017'!$B$18,IF(AND(C33<=2700000,C33>=2520000.01),'Simples Nacional 2017'!$B$19,IF(AND(C33<=2880000,C33>=2700000.01),'Simples Nacional 2017'!$B$20,IF(AND(C33<=3060000,C33>=2880000.01),'Simples Nacional 2017'!$B$21,IF(AND(C33<=3240000,C33>=3060000.01),'Simples Nacional 2017'!$B$22,IF(AND(C33<=3420000,C33>=3240000.01),'Simples Nacional 2017'!$B$23,IF(AND(C33<=3600000,C33>=3420000.01),'Simples Nacional 2017'!$B$24)))))))))))))))))))) -> 0.0275 | I33: =B33*F33 -> #DIV/0! | J33: =B33*H33 -> 0 | K33: =I33-J33 -> #DIV/0!
A34: Maio | B34: 0 | C34: =SUM(E22,F22,A24,B24,C24,D24,E24,F24,B30,B31,B32,B33) -> 0 | D34: =IF(C34<=180000,$C$13,IF(AND(C34>180000,C34<=360000),$C$14,IF(AND(C34<=720000,C34>=360000.01),$C$15,IF(AND(C34<=1800000,C34>=720000.01),$C$16,IF(AND(C34<=3600000,C34>=1800000.01),$C$17,IF(AND(C34<=4800000,C34>=3600000.01),$C$18)))))) -> 0.04 | E34: =LOOKUP(D34,$C$13:$C$18,$D$13:$D$18) -> 0 | F34: =((C34*D34)-E34)/C34 -> #DIV/0! | G34: =F34 -(F34*(LOOKUP(D34,$C$13:$C$18,$G$13:$G$18))) -> #DIV/0! | H34: =IF(C34<=180000,'Simples Nacional 2017'!$B$5,IF(AND(C34>180000,C34<=360000),'Simples Nacional 2017'!$B$6,IF(AND(C34<=540000,C34>=360000.01),'Simples Nacional 2017'!$B$7,IF(AND(C34<=720000,C34>=540000.01),'Simples Nacional 2017'!$B$8,IF(AND(C34<=900000,C34>=720000.01),'Simples Nacional 2017'!$B$9,IF(AND(C34<=1080000,C34>=900000.01),'Simples Nacional 2017'!$B$10,IF(AND(C34<=1260000,C34>=1080000.01),'Simples Nacional 2017'!$B$11,IF(AND(C34<=1440000,C34>=1260000.01),'Simples Nacional 2017'!$B$12,IF(AND(C34<=1620000,C34>=1440000.01),'Simples Nacional 2017'!$B$13,IF(AND(C34<=1800000,C34>=1620000.01),'Simples Nacional 2017'!$B$14,IF(AND(C34<=1980000,C34>=1800000.01),'Simples Nacional 2017'!$B$15,IF(AND(C34<=2160000,C34>=1980000.01),'Simples Nacional 2017'!$B$16,IF(AND(C34<=2340000,C34>=2160000.01),'Simples Nacional 2017'!$B$17,IF(AND(C34<=2520000,C34>=2340000.01),'Simples Nacional 2017'!$B$18,IF(AND(C34<=2700000,C34>=2520000.01),'Simples Nacional 2017'!$B$19,IF(AND(C34<=2880000,C34>=2700000.01),'Simples Nacional 2017'!$B$20,IF(AND(C34<=3060000,C34>=2880000.01),'Simples Nacional 2017'!$B$21,IF(AND(C34<=3240000,C34>=3060000.01),'Simples Nacional 2017'!$B$22,IF(AND(C34<=3420000,C34>=3240000.01),'Simples Nacional 2017'!$B$23,IF(AND(C34<=3600000,C34>=3420000.01),'Simples Nacional 2017'!$B$24)))))))))))))))))))) -> 0.0275 | I34: =B34*F34 -> #DIV/0! | J34: =B34*H34 -> 0 | K34: =I34-J34 -> #DIV/0!
A35: Junho | B35: 0 | C35: =SUM(F22,A24,B24,C24,D24,E24,F24,B30,B31,B32,B33,B34) -> 0 | D35: =IF(C35<=180000,$C$13,IF(AND(C35>180000,C35<=360000),$C$14,IF(AND(C35<=720000,C35>=360000.01),$C$15,IF(AND(C35<=1800000,C35>=720000.01),$C$16,IF(AND(C35<=3600000,C35>=1800000.01),$C$17,IF(AND(C35<=4800000,C35>=3600000.01),$C$18)))))) -> 0.04 | E35: =LOOKUP(D35,$C$13:$C$18,$D$13:$D$18) -> 0 | F35: =((C35*D35)-E35)/C35 -> #DIV/0! | G35: =F35 -(F35*(LOOKUP(D35,$C$13:$C$18,$G$13:$G$18))) -> #DIV/0! | H35: =IF(C35<=180000,'Simples Nacional 2017'!$B$5,IF(AND(C35>180000,C35<=360000),'Simples Nacional 2017'!$B$6,IF(AND(C35<=540000,C35>=360000.01),'Simples Nacional 2017'!$B$7,IF(AND(C35<=720000,C35>=540000.01),'Simples Nacional 2017'!$B$8,IF(AND(C35<=900000,C35>=720000.01),'Simples Nacional 2017'!$B$9,IF(AND(C35<=1080000,C35>=900000.01),'Simples Nacional 2017'!$B$10,IF(AND(C35<=1260000,C35>=1080000.01),'Simples Nacional 2017'!$B$11,IF(AND(C35<=1440000,C35>=1260000.01),'Simples Nacional 2017'!$B$12,IF(AND(C35<=1620000,C35>=1440000.01),'Simples Nacional 2017'!$B$13,IF(AND(C35<=1800000,C35>=1620000.01),'Simples Nacional 2017'!$B$14,IF(AND(C35<=1980000,C35>=1800000.01),'Simples Nacional 2017'!$B$15,IF(AND(C35<=2160000,C35>=1980000.01),'Simples Nacional 2017'!$B$16,IF(AND(C35<=2340000,C35>=2160000.01),'Simples Nacional 2017'!$B$17,IF(AND(C35<=2520000,C35>=2340000.01),'Simples Nacional 2017'!$B$18,IF(AND(C35<=2700000,C35>=2520000.01),'Simples Nacional 2017'!$B$19,IF(AND(C35<=2880000,C35>=2700000.01),'Simples Nacional 2017'!$B$20,IF(AND(C35<=3060000,C35>=2880000.01),'Simples Nacional 2017'!$B$21,IF(AND(C35<=3240000,C35>=3060000.01),'Simples Nacional 2017'!$B$22,IF(AND(C35<=3420000,C35>=3240000.01),'Simples Nacional 2017'!$B$23,IF(AND(C35<=3600000,C35>=3420000.01),'Simples Nacional 2017'!$B$24)))))))))))))))))))) -> 0.0275 | I35: =B35*F35 -> #DIV/0! | J35: =B35*H35 -> 0 | K35: =I35-J35 -> #DIV/0! | M35: *** PESSOAL PREENCHER A RECEITA MENSAL
A36: Julho | B36: 0 | C36: =SUM(A24,B24,C24,D24,E24,F24,B30,B31,B32,B33,B34,B35) -> 0 | D36: =IF(C36<=180000,$C$13,IF(AND(C36>180000,C36<=360000),$C$14,IF(AND(C36<=720000,C36>=360000.01),$C$15,IF(AND(C36<=1800000,C36>=720000.01),$C$16,IF(AND(C36<=3600000,C36>=1800000.01),$C$17,IF(AND(C36<=4800000,C36>=3600000.01),$C$18)))))) -> 0.04 | E36: =LOOKUP(D36,$C$13:$C$18,$D$13:$D$18) -> 0 | F36: =((C36*D36)-E36)/C36 -> #DIV/0! | G36: =F36 -(F36*(LOOKUP(D36,$C$13:$C$18,$G$13:$G$18))) -> #DIV/0! | H36: =IF(C36<=180000,'Simples Nacional 2017'!$B$5,IF(AND(C36>180000,C36<=360000),'Simples Nacional 2017'!$B$6,IF(AND(C36<=540000,C36>=360000.01),'Simples Nacional 2017'!$B$7,IF(AND(C36<=720000,C36>=540000.01),'Simples Nacional 2017'!$B$8,IF(AND(C36<=900000,C36>=720000.01),'Simples Nacional 2017'!$B$9,IF(AND(C36<=1080000,C36>=900000.01),'Simples Nacional 2017'!$B$10,IF(AND(C36<=1260000,C36>=1080000.01),'Simples Nacional 2017'!$B$11,IF(AND(C36<=1440000,C36>=1260000.01),'Simples Nacional 2017'!$B$12,IF(AND(C36<=1620000,C36>=1440000.01),'Simples Nacional 2017'!$B$13,IF(AND(C36<=1800000,C36>=1620000.01),'Simples Nacional 2017'!$B$14,IF(AND(C36<=1980000,C36>=1800000.01),'Simples Nacional 2017'!$B$15,IF(AND(C36<=2160000,C36>=1980000.01),'Simples Nacional 2017'!$B$16,IF(AND(C36<=2340000,C36>=2160000.01),'Simples Nacional 2017'!$B$17,IF(AND(C36<=2520000,C36>=2340000.01),'Simples Nacional 2017'!$B$18,IF(AND(C36<=2700000,C36>=2520000.01),'Simples Nacional 2017'!$B$19,IF(AND(C36<=2880000,C36>=2700000.01),'Simples Nacional 2017'!$B$20,IF(AND(C36<=3060000,C36>=2880000.01),'Simples Nacional 2017'!$B$21,IF(AND(C36<=3240000,C36>=3060000.01),'Simples Nacional 2017'!$B$22,IF(AND(C36<=3420000,C36>=3240000.01),'Simples Nacional 2017'!$B$23,IF(AND(C36<=3600000,C36>=3420000.01),'Simples Nacional 2017'!$B$24)))))))))))))))))))) -> 0.0275 | I36: =B36*F36 -> #DIV/0! | J36: =B36*H36 -> 0 | K36: =I36-J36 -> #DIV/0!
A37: Agosto | B37: 0 | C37: =SUM(B24,C24,D24,E24,F24,B30,B31,B32,B33,B34,B35,B36) -> 0 | D37: =IF(C37<=180000,$C$13,IF(AND(C37>180000,C37<=360000),$C$14,IF(AND(C37<=720000,C37>=360000.01),$C$15,IF(AND(C37<=1800000,C37>=720000.01),$C$16,IF(AND(C37<=3600000,C37>=1800000.01),$C$17,IF(AND(C37<=4800000,C37>=3600000.01),$C$18)))))) -> 0.04 | E37: =LOOKUP(D37,$C$13:$C$18,$D$13:$D$18) -> 0 | F37: =((C37*D37)-E37)/C37 -> #DIV/0! | G37: =F37 -(F37*(LOOKUP(D37,$C$13:$C$18,$G$13:$G$18))) -> #DIV/0! | H37: =IF(C37<=180000,'Simples Nacional 2017'!$B$5,IF(AND(C37>180000,C37<=360000),'Simples Nacional 2017'!$B$6,IF(AND(C37<=540000,C37>=360000.01),'Simples Nacional 2017'!$B$7,IF(AND(C37<=720000,C37>=540000.01),'Simples Nacional 2017'!$B$8,IF(AND(C37<=900000,C37>=720000.01),'Simples Nacional 2017'!$B$9,IF(AND(C37<=1080000,C37>=900000.01),'Simples Nacional 2017'!$B$10,IF(AND(C37<=1260000,C37>=1080000.01),'Simples Nacional 2017'!$B$11,IF(AND(C37<=1440000,C37>=1260000.01),'Simples Nacional 2017'!$B$12,IF(AND(C37<=1620000,C37>=1440000.01),'Simples Nacional 2017'!$B$13,IF(AND(C37<=1800000,C37>=1620000.01),'Simples Nacional 2017'!$B$14,IF(AND(C37<=1980000,C37>=1800000.01),'Simples Nacional 2017'!$B$15,IF(AND(C37<=2160000,C37>=1980000.01),'Simples Nacional 2017'!$B$16,IF(AND(C37<=2340000,C37>=2160000.01),'Simples Nacional 2017'!$B$17,IF(AND(C37<=2520000,C37>=2340000.01),'Simples Nacional 2017'!$B$18,IF(AND(C37<=2700000,C37>=2520000.01),'Simples Nacional 2017'!$B$19,IF(AND(C37<=2880000,C37>=2700000.01),'Simples Nacional 2017'!$B$20,IF(AND(C37<=3060000,C37>=2880000.01),'Simples Nacional 2017'!$B$21,IF(AND(C37<=3240000,C37>=3060000.01),'Simples Nacional 2017'!$B$22,IF(AND(C37<=3420000,C37>=3240000.01),'Simples Nacional 2017'!$B$23,IF(AND(C37<=3600000,C37>=3420000.01),'Simples Nacional 2017'!$B$24)))))))))))))))))))) -> 0.0275 | I37: =B37*F37 -> #DIV/0! | J37: =B37*H37 -> 0 | K37: =I37-J37 -> #DIV/0!
A38: Setembro | B38: 0 | C38: =SUM(C24,D24,E24,F24,B30,B31,B32,B33,B34,B35,B36,B37) -> 0 | D38: =IF(C38<=180000,$C$13,IF(AND(C38>180000,C38<=360000),$C$14,IF(AND(C38<=720000,C38>=360000.01),$C$15,IF(AND(C38<=1800000,C38>=720000.01),$C$16,IF(AND(C38<=3600000,C38>=1800000.01),$C$17,IF(AND(C38<=4800000,C38>=3600000.01),$C$18)))))) -> 0.04 | E38: =LOOKUP(D38,$C$13:$C$18,$D$13:$D$18) -> 0 | F38: =((C38*D38)-E38)/C38 -> #DIV/0! | G38: =F38 -(F38*(LOOKUP(D38,$C$13:$C$18,$G$13:$G$18))) -> #DIV/0! | H38: =IF(C38<=180000,'Simples Nacional 2017'!$B$5,IF(AND(C38>180000,C38<=360000),'Simples Nacional 2017'!$B$6,IF(AND(C38<=540000,C38>=360000.01),'Simples Nacional 2017'!$B$7,IF(AND(C38<=720000,C38>=540000.01),'Simples Nacional 2017'!$B$8,IF(AND(C38<=900000,C38>=720000.01),'Simples Nacional 2017'!$B$9,IF(AND(C38<=1080000,C38>=900000.01),'Simples Nacional 2017'!$B$10,IF(AND(C38<=1260000,C38>=1080000.01),'Simples Nacional 2017'!$B$11,IF(AND(C38<=1440000,C38>=1260000.01),'Simples Nacional 2017'!$B$12,IF(AND(C38<=1620000,C38>=1440000.01),'Simples Nacional 2017'!$B$13,IF(AND(C38<=1800000,C38>=1620000.01),'Simples Nacional 2017'!$B$14,IF(AND(C38<=1980000,C38>=1800000.01),'Simples Nacional 2017'!$B$15,IF(AND(C38<=2160000,C38>=1980000.01),'Simples Nacional 2017'!$B$16,IF(AND(C38<=2340000,C38>=2160000.01),'Simples Nacional 2017'!$B$17,IF(AND(C38<=2520000,C38>=2340000.01),'Simples Nacional 2017'!$B$18,IF(AND(C38<=2700000,C38>=2520000.01),'Simples Nacional 2017'!$B$19,IF(AND(C38<=2880000,C38>=2700000.01),'Simples Nacional 2017'!$B$20,IF(AND(C38<=3060000,C38>=2880000.01),'Simples Nacional 2017'!$B$21,IF(AND(C38<=3240000,C38>=3060000.01),'Simples Nacional 2017'!$B$22,IF(AND(C38<=3420000,C38>=3240000.01),'Simples Nacional 2017'!$B$23,IF(AND(C38<=3600000,C38>=3420000.01),'Simples Nacional 2017'!$B$24)))))))))))))))))))) -> 0.0275 | I38: =B38*F38 -> #DIV/0! | J38: =B38*H38 -> 0 | K38: =I38-J38 -> #DIV/0!
A39: Outubro | B39: 0 | C39: =SUM(D24,E24,F24,B30,B31,B32,B33,B34,B35,B36,B37,B38) -> 0 | D39: =IF(C39<=180000,$C$13,IF(AND(C39>180000,C39<=360000),$C$14,IF(AND(C39<=720000,C39>=360000.01),$C$15,IF(AND(C39<=1800000,C39>=720000.01),$C$16,IF(AND(C39<=3600000,C39>=1800000.01),$C$17,IF(AND(C39<=4800000,C39>=3600000.01),$C$18)))))) -> 0.04 | E39: =LOOKUP(D39,$C$13:$C$18,$D$13:$D$18) -> 0 | F39: =((C39*D39)-E39)/C39 -> #DIV/0! | G39: =F39 -(F39*(LOOKUP(D39,$C$13:$C$18,$G$13:$G$18))) -> #DIV/0! | H39: =IF(C39<=180000,'Simples Nacional 2017'!$B$5,IF(AND(C39>180000,C39<=360000),'Simples Nacional 2017'!$B$6,IF(AND(C39<=540000,C39>=360000.01),'Simples Nacional 2017'!$B$7,IF(AND(C39<=720000,C39>=540000.01),'Simples Nacional 2017'!$B$8,IF(AND(C39<=900000,C39>=720000.01),'Simples Nacional 2017'!$B$9,IF(AND(C39<=1080000,C39>=900000.01),'Simples Nacional 2017'!$B$10,IF(AND(C39<=1260000,C39>=1080000.01),'Simples Nacional 2017'!$B$11,IF(AND(C39<=1440000,C39>=1260000.01),'Simples Nacional 2017'!$B$12,IF(AND(C39<=1620000,C39>=1440000.01),'Simples Nacional 2017'!$B$13,IF(AND(C39<=1800000,C39>=1620000.01),'Simples Nacional 2017'!$B$14,IF(AND(C39<=1980000,C39>=1800000.01),'Simples Nacional 2017'!$B$15,IF(AND(C39<=2160000,C39>=1980000.01),'Simples Nacional 2017'!$B$16,IF(AND(C39<=2340000,C39>=2160000.01),'Simples Nacional 2017'!$B$17,IF(AND(C39<=2520000,C39>=2340000.01),'Simples Nacional 2017'!$B$18,IF(AND(C39<=2700000,C39>=2520000.01),'Simples Nacional 2017'!$B$19,IF(AND(C39<=2880000,C39>=2700000.01),'Simples Nacional 2017'!$B$20,IF(AND(C39<=3060000,C39>=2880000.01),'Simples Nacional 2017'!$B$21,IF(AND(C39<=3240000,C39>=3060000.01),'Simples Nacional 2017'!$B$22,IF(AND(C39<=3420000,C39>=3240000.01),'Simples Nacional 2017'!$B$23,IF(AND(C39<=3600000,C39>=3420000.01),'Simples Nacional 2017'!$B$24)))))))))))))))))))) -> 0.0275 | I39: =B39*F39 -> #DIV/0! | J39: =B39*H39 -> 0 | K39: =I39-J39 -> #DIV/0!
A40: Novembro | B40: 0 | C40: =SUM(E24,F24,B30,B31,B32,B33,B34,B35,B36,B37,B38,B39) -> 0 | D40: =IF(C40<=180000,$C$13,IF(AND(C40>180000,C40<=360000),$C$14,IF(AND(C40<=720000,C40>=360000.01),$C$15,IF(AND(C40<=1800000,C40>=720000.01),$C$16,IF(AND(C40<=3600000,C40>=1800000.01),$C$17,IF(AND(C40<=4800000,C40>=3600000.01),$C$18)))))) -> 0.04 | E40: =LOOKUP(D40,$C$13:$C$18,$D$13:$D$18) -> 0 | F40: =((C40*D40)-E40)/C40 -> #DIV/0! | G40: =F40 -(F40*(LOOKUP(D40,$C$13:$C$18,$G$13:$G$18))) -> #DIV/0! | H40: =IF(C40<=180000,'Simples Nacional 2017'!$B$5,IF(AND(C40>180000,C40<=360000),'Simples Nacional 2017'!$B$6,IF(AND(C40<=540000,C40>=360000.01),'Simples Nacional 2017'!$B$7,IF(AND(C40<=720000,C40>=540000.01),'Simples Nacional 2017'!$B$8,IF(AND(C40<=900000,C40>=720000.01),'Simples Nacional 2017'!$B$9,IF(AND(C40<=1080000,C40>=900000.01),'Simples Nacional 2017'!$B$10,IF(AND(C40<=1260000,C40>=1080000.01),'Simples Nacional 2017'!$B$11,IF(AND(C40<=1440000,C40>=1260000.01),'Simples Nacional 2017'!$B$12,IF(AND(C40<=1620000,C40>=1440000.01),'Simples Nacional 2017'!$B$13,IF(AND(C40<=1800000,C40>=1620000.01),'Simples Nacional 2017'!$B$14,IF(AND(C40<=1980000,C40>=1800000.01),'Simples Nacional 2017'!$B$15,IF(AND(C40<=2160000,C40>=1980000.01),'Simples Nacional 2017'!$B$16,IF(AND(C40<=2340000,C40>=2160000.01),'Simples Nacional 2017'!$B$17,IF(AND(C40<=2520000,C40>=2340000.01),'Simples Nacional 2017'!$B$18,IF(AND(C40<=2700000,C40>=2520000.01),'Simples Nacional 2017'!$B$19,IF(AND(C40<=2880000,C40>=2700000.01),'Simples Nacional 2017'!$B$20,IF(AND(C40<=3060000,C40>=2880000.01),'Simples Nacional 2017'!$B$21,IF(AND(C40<=3240000,C40>=3060000.01),'Simples Nacional 2017'!$B$22,IF(AND(C40<=3420000,C40>=3240000.01),'Simples Nacional 2017'!$B$23,IF(AND(C40<=3600000,C40>=3420000.01),'Simples Nacional 2017'!$B$24)))))))))))))))))))) -> 0.0275 | I40: =B40*F40 -> #DIV/0! | J40: =B40*H40 -> 0 | K40: =I40-J40 -> #DIV/0!
A41: Dezembro | B41: 0 | C41: =SUM(F24,B30,B31,B32,B33,B34,B35,B36,B37,B38,B39,B40) -> 0 | D41: =IF(C41<=180000,$C$13,IF(AND(C41>180000,C41<=360000),$C$14,IF(AND(C41<=720000,C41>=360000.01),$C$15,IF(AND(C41<=1800000,C41>=720000.01),$C$16,IF(AND(C41<=3600000,C41>=1800000.01),$C$17,IF(AND(C41<=4800000,C41>=3600000.01),$C$18)))))) -> 0.04 | E41: =LOOKUP(D41,$C$13:$C$18,$D$13:$D$18) -> 0 | F41: =((C41*D41)-E41)/C41 -> #DIV/0! | G41: =F41 -(F41*(LOOKUP(D41,$C$13:$C$18,$G$13:$G$18))) -> #DIV/0! | H41: =IF(C41<=180000,'Simples Nacional 2017'!$B$5,IF(AND(C41>180000,C41<=360000),'Simples Nacional 2017'!$B$6,IF(AND(C41<=540000,C41>=360000.01),'Simples Nacional 2017'!$B$7,IF(AND(C41<=720000,C41>=540000.01),'Simples Nacional 2017'!$B$8,IF(AND(C41<=900000,C41>=720000.01),'Simples Nacional 2017'!$B$9,IF(AND(C41<=1080000,C41>=900000.01),'Simples Nacional 2017'!$B$10,IF(AND(C41<=1260000,C41>=1080000.01),'Simples Nacional 2017'!$B$11,IF(AND(C41<=1440000,C41>=1260000.01),'Simples Nacional 2017'!$B$12,IF(AND(C41<=1620000,C41>=1440000.01),'Simples Nacional 2017'!$B$13,IF(AND(C41<=1800000,C41>=1620000.01),'Simples Nacional 2017'!$B$14,IF(AND(C41<=1980000,C41>=1800000.01),'Simples Nacional 2017'!$B$15,IF(AND(C41<=2160000,C41>=1980000.01),'Simples Nacional 2017'!$B$16,IF(AND(C41<=2340000,C41>=2160000.01),'Simples Nacional 2017'!$B$17,IF(AND(C41<=2520000,C41>=2340000.01),'Simples Nacional 2017'!$B$18,IF(AND(C41<=2700000,C41>=2520000.01),'Simples Nacional 2017'!$B$19,IF(AND(C41<=2880000,C41>=2700000.01),'Simples Nacional 2017'!$B$20,IF(AND(C41<=3060000,C41>=2880000.01),'Simples Nacional 2017'!$B$21,IF(AND(C41<=3240000,C41>=3060000.01),'Simples Nacional 2017'!$B$22,IF(AND(C41<=3420000,C41>=3240000.01),'Simples Nacional 2017'!$B$23,IF(AND(C41<=3600000,C41>=3420000.01),'Simples Nacional 2017'!$B$24)))))))))))))))))))) -> 0.0275 | I41: =B41*F41 -> #DIV/0! | J41: =B41*H41 -> 0 | K41: =I41-J41 -> #DIV/0!
A42: TOTAL | I42: =SUM(I30:I41) -> #DIV/0! | J42: =SUM(J30:J41) -> 0 | K42: =SUM(K30:K41) -> #DIV/0!
A44: SIMULAÇÃO LUCRO PRESUMIDO 2018
A45: MÊS | B45: FATURAMENTO | C45: ICMS | D45: PIS | E45: COFINS | F45: IRPJ | G45: ADIC. DE IRPJ | H45: CSLL | I45: TOTAL IMPOSTOS
A46: Janeiro | B46: =B30 -> 0 | C46: =B46*6% -> 0 | D46: =B46*0.65% -> 0 | E46: =B46*3% -> 0 | F46: =(B46*8%)*15% -> 0 | G46: 0 | H46: =B46*12%*9% -> 0 | I46: =C46+D46+E46+F46+G46+H46 -> 0
A47: Fevereiro | B47: =B31 -> 0 | C47: =B47*6% -> 0 | D47: =B47*0.65% -> 0 | E47: =B47*3% -> 0 | F47: =(B47*8%)*15% -> 0 | G47: 0 | H47: =B47*12%*9% -> 0 | I47: =C47+D47+E47+F47+G47+H47 -> 0
A48: Março | B48: =B32 -> 0 | C48: =B48*6% -> 0 | D48: =B48*0.65% -> 0 | E48: =B48*3% -> 0 | F48: =(B48*8%)*15% -> 0 | G48: 0 | H48: =B48*12%*9% -> 0 | I48: =C48+D48+E48+F48+G48+H48 -> 0
A49: Abril | B49: =B33 -> 0 | C49: =B49*6% -> 0 | D49: =B49*0.65% -> 0 | E49: =B49*3% -> 0 | F49: =(B49*8%)*15% -> 0 | G49: 0 | H49: =B49*12%*9% -> 0 | I49: =C49+D49+E49+F49+G49+H49 -> 0
A50: Maio | B50: =B34 -> 0 | C50: =B50*6% -> 0 | D50: =B50*0.65% -> 0 | E50: =B50*3% -> 0 | F50: =(B50*8%)*15% -> 0 | G50: 0 | H50: =B50*12%*9% -> 0 | I50: =C50+D50+E50+F50+G50+H50 -> 0
...
