Workbook

Sheet PIS e COFINS
A2: EMPRESA FULANO DE TAL
A3: CNPJ 00.000.000/0000-00
A5: PIS 8109 | C5: 2020
C6: JAN | D6: FEV | E6: MAR | F6: ABR | G6: MAI | H6: JUN | I6: JUL | J6: AGO | K6: SET | L6: OUT | M6: NOV | N6: DEZ
A7: Receita Venda de Mercadoria
A8: Receita Venda de Serviço | C8: 0 | D8: 0 | E8: 0 | F8: 0 | G8: 0 | H8: 0 | I8: 0 | J8: 0 | K8: 0 | L8: 0 | M8: 0
A9: Demais Receitas | C9: 0 | D9: 0 | E9: 0 | F9: 0 | G9: 0 | H9: 0 | I9: 0 | J9: 0 | K9: 0 | L9: 0 | M9: 0 | N9: 0
A10: Base de Cálculo - 0,65% | C10: =SUM(C7:C9) -> 0 | D10: =SUM(D7:D9) -> 0 | E10: =SUM(E7:E9) -> 0 | F10: =SUM(F7:F9) -> 0 | G10: =SUM(G7:G9) -> 0 | H10: =SUM(H7:H9) -> 0 | I10: =SUM(I7:I9) -> 0 | J10: =SUM(J7:J9) -> 0 | ... N10: =SUM(N7:N9) -> 0
A11: PIS Devido | C11: =C10*0.65% -> 0 | D11: =D10*0.65% -> 0 | E11: =E10*0.65% -> 0 | F11: =F10*0.65% -> 0 | G11: =G10*0.65% -> 0 | H11: =H10*0.65% -> 0 | I11: =I10*0.65% -> 0 | J11: =J10*0.65% -> 0 | ... N11: =N10*0.65% -> 0
A12: COFINS Retido
A13: COFINS a Compensar
A14: SUB TOTAL | C14: =C11-C12-C13 -> 0 | D14: =D11-D12-D13 -> 0 | E14: =E11-E12-E13 -> 0 | F14: =F11-F12-F13 -> 0 | G14: =G11-G12-G13 -> 0 | H14: =H11-H12-H13 -> 0 | I14: =I11-I12-I13 -> 0 | J14: =J11-J12-J13 -> 0 | ... N14: =N11-N12-N13 -> 0
A15: COFINS Período Anterios
A16: PIS A RECOLHER | C16: =C14+C15 -> 0 | D16: =D14+D15 -> 0 | E16: =E14+E15 -> 0 | F16: =F14+F15 -> 0 | G16: =G14+G15 -> 0 | H16: =H14+H15+0.01 -> 0.01 | I16: =I14+I15 -> 0 | J16: =J14+J15 -> 0 | K16: =K14+K15 -> 0 | L16: =L14+L15 -> 0 | M16: =M14+M15 -> 0 | N16: =N14+N15 -> 0
A18: COFINS 2172 | C18: 2020
C19: JAN | D19: FEV | E19: MAR | F19: ABR | G19: MAI | H19: JUN | I19: JUL | J19: AGO | K19: SET | L19: OUT | M19: NOV | N19: DEZ
A20: Receita Venda de Venda | C20: =C7 -> 0 | D20: =D7 -> 0 | E20: =E7 -> 0 | F20: =F7 -> 0 | G20: =G7 -> 0 | H20: =H7 -> 0 | I20: =I7 -> 0 | J20: =J7 -> 0 | ... N20: =N7 -> 0
A21: Receita Venda de Serviço | C21: =C8 -> 0 | D21: =D8 -> 0 | E21: =E8 -> 0 | F21: =F8 -> 0 | G21: =G8 -> 0 | H21: =H8 -> 0 | I21: =I8 -> 0 | J21: =J8 -> 0 | ... N21: =N8 -> 0
A22: Demais Receitas | C22: =C9 -> 0 | D22: =D9 -> 0 | E22: =E9 -> 0 | F22: =F9 -> 0 | G22: =G9 -> 0 | H22: =H9 -> 0 | I22: =I9 -> 0 | J22: =J9 -> 0 | ... N22: =N9 -> 0
A23: Base de Cálculo - 3% | C23: =SUM(C20:C22) -> 0 | D23: =SUM(D20:D22) -> 0 | E23: =SUM(E20:E22) -> 0 | F23: =SUM(F20:F22) -> 0 | G23: =SUM(G20:G22) -> 0 | H23: =SUM(H20:H22) -> 0 | I23: =SUM(I20:I22) -> 0 | J23: =SUM(J20:J22) -> 0 | ... N23: =SUM(N20:N22) -> 0
A24: COFINS Devido | C24: =C23*3% -> 0 | D24: =D23*3% -> 0 | E24: =E23*3% -> 0 | F24: =F23*3% -> 0 | G24: =G23*3% -> 0 | H24: =H23*3% -> 0 | I24: =I23*3% -> 0 | J24: =J23*3% -> 0 | ... N24: =N23*3% -> 0
A25: COFINS Retido | C25: 0
A26: COFINS a Compensar | C26: 0
A27: SUB TOTAL | C27: =C24-C25-C26 -> 0 | D27: =D24-D25-D26 -> 0 | E27: =E24-E25-E26 -> 0 | F27: =F24-F25-F26 -> 0 | G27: =G24-G25-G26 -> 0 | H27: =H24-H25-H26 -> 0 | I27: =I24-I25-I26 -> 0 | J27: =J24-J25-J26 -> 0 | ... N27: =N24-N25-N26 -> 0
A28: COFINS Período Anterios | C28: 0
A29: COFINS A RECOLHER | C29: =C27+C28 -> 0 | D29: =D27+D28 -> 0 | E29: =E27+E28 -> 0 | F29: =F27+F28 -> 0 | G29: =G27+G28 -> 0 | H29: =H27+H28 -> 0 | I29: =I27+I28 -> 0 | J29: =J27+J28 -> 0 | ... N29: =N27+N28 -> 0
A31: DCTF | C31: Ok | D31: Ok | E31: Ok | F31: Ok | G31: Ok | H31: Ok | I31: Ok | J31: Ok | K31: Ok | L31: Ok | M31: OK | N31: OK

Sheet IRPF e CSLL
A2: ='PIS e COFINS'!A2:N2 -> EMPRESA FULANO DE TAL
A3: ='PIS e COFINS'!A3:N3 -> CNPJ 00.000.000/0000-00
A5: IRPJ 2089 | C5: 2020
C6: 1º TRIM | D6: 2º TRIM | E6: 3º TRIM | F6: 4º TRIM
A7: Receita de Venda | C7: =SUM('PIS e COFINS'!C7:E7) -> 0 | D7: =SUM('PIS e COFINS'!F7:H7) -> 0 | E7: =SUM('PIS e COFINS'!I7:K7) -> 0 | F7: =SUM('PIS e COFINS'!L7:N7) -> 0
A8: Receita de Serviços | C8: =SUM('PIS e COFINS'!C8:E8) -> 0 | D8: =SUM('PIS e COFINS'!F8:H8) -> 0 | E8: =SUM('PIS e COFINS'!I8:K8) -> 0 | F8: =SUM('PIS e COFINS'!L8:N8) -> 0
A9: Receita de Serviços (Técnico) | C9: 0
A10: Receita de Serviços (Construção) | C10: 0
A11: Total de Receita | C11: =SUM(C7:C10) -> 0 | D11: =SUM(D7:D10) -> 0 | E11: =SUM(E7:E10) -> 0 | F11: =SUM(F7:F10) -> 0
A12: Lucro Presumido (8%) | C12: =(C7*8)/100 -> 0 | D12: =(D7*8)/100 -> 0 | E12: =(E7*8)/100 -> 0 | F12: =(F7*8)/100 -> 0
A13: Lucro Presumido (32%) | C13: =(C8*32)/100 -> 0 | D13: =(D8*32)/100 -> 0 | E13: =(E8*32)/100 -> 0 | F13: =(F8*32)/100 -> 0
A14: Demais Receitas | C14: 0 | D14: 0 | E14: 0 | F14: 0
A15: Base de Cálculo | C15: =SUM(C12:C14) -> 0 | D15: =SUM(D12:D14) -> 0 | E15: =SUM(E12:E14) -> 0 | F15: =SUM(F12:F14) -> 0
A16: IRPJ (15%) | C16: =(C15*15)/100 -> 0 | D16: =(D15*15)/100 -> 0 | E16: =(E15*15)/100 -> 0 | F16: =(F15*15)/100 -> 0
A17: Adicional
A18: IRPJ Devido | C18: =C17+C16 -> 0 | D18: =D17+D16 -> 0 | E18: =E17+E16 -> 0 | F18: =F17+F16 -> 0
A19: IRPJ Retido na Fonte | C19: =86.39+219.28+211.65-0.08 -> 517.24 | D19: =151+171.94+127.73 -> 450.67 | E19: =208.82+223.97+342.07 -> 774.86 | F19: =167.82+21.78 -> 189.6
A20: IRPJ a Compensar
A21: IRPJ A RECOLHER | C21: =C18-C19-C20 -> -517.24 | D21: =D18-D19-D20 -> -450.67 | E21: =E18-E19-E20 -> -774.86 | F21: =F18-F19-F20 -> -189.6
A22: Valor da Quota (Opcional) | C22: =C21/3 -> -172.41333 | D22: =D21/3 -> -150.22333 | E22: =E21/3 -> -258.28667 | F22: =F21/3 -> -63.2
A24: CSLL 2372 | C24: 2020
C25: 1º TRIM | D25: 2º TRIM | E25: 3º TRIM | F25: 4º TRIM
A26: Receita de Venda | C26: =C7 -> 0 | D26: =D7 -> 0 | E26: =E7 -> 0 | F26: =F7 -> 0
A27: Receita de Serviços | C27: =C8 -> 0 | D27: =D8 -> 0 | E27: =E8 -> 0 | F27: =F8 -> 0
A28: Receita de Serviços (Técnico) | C28: =C9 -> 0 | D28: =D9 -> 0 | E28: =E9 -> 0 | F28: =F9 -> 0
A29: Receita de Serviços (Construção) | C29: =C10 -> 0 | D29: =D10 -> 0 | E29: =E10 -> 0 | F29: =F10 -> 0
A30: Total de Receita | C30: =SUM(C26:C29) -> 0 | D30: =SUM(D26:D29) -> 0 | E30: =SUM(E26:E29) -> 0 | F30: =SUM(F26:F29) -> 0
A31: Lucro Presumido (12%) | C31: =(C26*12)/100 -> 0 | D31: =(D26*12)/100 -> 0 | E31: =(E26*12)/100 -> 0 | F31: =(F26*12)/100 -> 0
A32: Lucro Presumido (32%) | C32: =(C27*32)/100 -> 0 | D32: =(D27*32)/100 -> 0 | E32: =(E27*32)/100 -> 0 | F32: =(F27*32)/100 -> 0
A33: Demais Receitas | C33: 0 | D33: 0 | E33: 0 | F33: 0
A34: Base de Cálculo | C34: =SUM(C31:C33) -> 0 | D34: =SUM(D31:D33) -> 0 | E34: =SUM(E31:E33) -> 0 | F34: =SUM(F31:F33) -> 0
A35: CSLL Devida (9%) | C35: =(C34*9)/100 -> 0 | D35: =(D34*9)/100 -> 0 | E35: =(E34*9)/100 -> 0 | F35: =(F34*9)/100 -> 0
A36: CSLL Retida na Fonte
A37: CSLL a Compensar | C37: =C36/3 -> 0 | D37: =D36/3 -> 0 | E37: =E36/3 -> 0 | F37: =F36/3 -> 0
A38: CSLL Recolhida | C38: =C37/3 -> 0 | D38: =D37/3 -> 0 | E38: =E37/3 -> 0 | F38: =F37/3 -> 0
A39: CSLL A RECOLHER | C39: =C35-C36-C37-C38 -> 0 | D39: =D35-D36-D37-D38 -> 0 | E39: =E35-E36-E37-E38 -> 0 | F39: =F35-F36-F37-F38 -> 0
A40: Valor da Quota (Opcional) | C40: =C39/3 -> 0 | D40: =D39/3 -> 0 | E40: =E39/3 -> 0 | F40: =F39/3 -> 0
A42: 1º TRIM | D42: 2º TRIM
A43: 1º Quota - Venc - 30/04/2020 | D43: 1º Quota - Venc - 31/07/2020
A44: 2º Quota - Venc - 31/05/2020 | D44: 2º Quota - Venc - 31/08/2020
...
