Workbook
Name Concluído: 'Atividades detalhadas'!$U$1:$U$3
Name listastatus: 'Atividades detalhadas'!$U$1:$U$4
Name Status: 'Atividades detalhadas'!$U$1:$U$3
Name Statusesocial: 'Atividades detalhadas'!$U$1:$U$3

Sheet Atividades detalhadas
B1: Trabalho de Implantação do eSocial - Cliente XYZ INDUST | U1: Concluído
A2: Faturamento em 2016 - R$ 281.920.188,35 | E2: =AVERAGE(K16,K38,K56,K78,K102,K120,K138,K152,K164,K178,K191,K203,K215,K226,K251,K265,K275,K293,K306,K319,K326,K335,K343,K350,K358,K365,K373,K395,K417,K442,K458,K472,K487,K504,K523,K533,K542,K569,K600,K616,K637,K653,K663,K678,K692,K719,K728) -> 0.51818734 | G2: Concluído | H2: Atualizado em: | K2: 43068 | U2: Em andamento
A3: 1 | B3: Qualificação Cadastral | E3: Prazo da Atividade | G3: Responsável | I3: Acompanhamento | U3: Atrasado
E4: Início | F4: Fim | G4: Contabilidade | H4: Cliente | I4: Status | J4: Data conclusão | K4: % Conclusão | U4: Não Iniciado
C5: 1.1 | D5: Gerar informações do sistema para envio a Qualificação Cadastral em Lote | E5: 42919 | F5: 43084 | G5: Equipe DP | I5: Não Iniciado | J5: 42930 | K5: 0
C6: 1.2 | D6: Importar para o Sistema o arquivo retorno | E6: 42919 | F6: 43084 | G6: Equipe DP | I6: Concluído | J6: 42933 | K6: 1
C7: 1.3 | D7: Analise dos ajustes à serem realizados | E7: 42919 | F7: 43084 | G7: Equipe DP | I7: Concluído | J7: 42937 | K7: 1
C8: 1.4 | D8: Encaminhar informações para ajuste necessários | E8: 42919 | F8: 43084 | G8: Equipe DP | I8: Concluído | J8: 42940 | K8: 1
C9: 1.5 | D9: Receber informações para ajuste dos dados do Colaborador | E9: 42919 | F9: 43084 | H9: RH - Cliente | I9: Concluído | J9: 42941 | K9: 1
C10: 1.6 | D10: Solicitar o Colaborador para realizar o ajuste nos orgãos Governamentais | E10: 42919 | F10: 43084 | H10: RH - Cliente | I10: Concluído | J10: 42944 | K10: 1
C11: 1.7 | D11: Devolver as informações dos Colaboradores ajustadas | E11: 42919 | F11: 43084 | H11: RH - Cliente | I11: Concluído | J11: 42951 | K11: 1
C12: 1.8 | D12: Receber informações para ajuste dos dados do Colaborador no sistema | E12: 42919 | F12: 43084 | G12: Equipe DP | I12: Concluído | J12: 42954 | K12: 1
C13: 1.9 | D13: Corrigir as informações no sistema | E13: 42919 | F13: 43084 | G13: Equipe DP | I13: Concluído | J13: 42962 | K13: 1
C14: 1.12 | D14: Retransmitir para o eSocial (Qualif.Cadastral) | E14: 42919 | F14: 43084 | G14: Equipe DP | I14: Concluído | J14: 42965 | K14: 1
C15: 1.13 | D15: Fazer qualificação cadastral para os admitidos desta data em diante | E15: 42979 | F15: 42979 | H15: RH - Cliente | I15: Concluído | J15: 42979 | K15: 1
H16: Percentual de conclusão desta etapa: | K16: =AVERAGE(K5:K15) -> 0.90909091
A18: 2 | B18: Saneamento da Base - Análise de Impacto (Robô) | E18: Prazo da Atividade | G18: Responsável | I18: Acompanhamento
E19: Início | F19: Fim | G19: Contabilidade | H19: Cliente | I19: Status | J19: Data conclusão | K19: % Conclusão
C20: 2.1 | D20: Instalação do "Robô" para realizar Análise de Impacto das informações do eSocial | E20: 42919 | F20: 43084 | G20: Equipe T.I. | I20: Concluído | J20: 42923 | K20: 1
C21: 2.2 | D21: Treinamento da ferramenta "Robô" para equipe do DP | E21: 42919 | F21: 43084 | G21: Equipe T.I. | I21: Concluído | J21: 42926 | K21: 1
C22: 2.3 | D22: Multiplicar Treinamento da Ferramenta "Robô" a toda equipe DP | E22: 42919 | F22: 43084 | G22: Gestor DP | I22: Concluído | J22: 42927 | K22: 1
C23: 2.4 | D23: Esclarecimento de dúvidas de utilização da ferramenta "Robo" para equipe DP | E23: 42919 | F23: 43084 | G23: Gestor DP | I23: Concluído | J23: 42930 | K23: 1
C24: 2.5 | D24: Analise dos dados básicos do Empregador no Sistema de Folha de pagamento | E24: 42919 | F24: 43084 | G24: Equipe DP | I24: Concluído | J24: 42934 | K24: 1
C25: 2.6 | D25: Corrigir as informações do Empregador (se necessário) | E25: 42919 | F25: 43084 | G25: Equipe DP | I25: Concluído | J25: 42937 | K25: 1
C26: 2.7 | D26: Analisar se o Sistema de folha está adptado para atender as exigências do eSocial | E26: 42919 | F26: 43084 | G26: Equipe DP | I26: Concluído | J26: 42948 | K26: 1
C27: 2.8 | D27: Verificar todas as rubricas pagas em folha de pagamento nos ultimos 24 meses | E27: 42919 | F27: 43084 | G27: Equipe DP | I27: Concluído | J27: 42972 | K27: 1
C28: 2.9 | D28: Entender a necessidade de cada rubrica paga em folha de pagamento | E28: 42919 | F28: 43084 | G28: Equipe DP | I28: Concluído | J28: 42978 | K28: 1
C29: 2.10 | D29: Verificar as incidências dos Eventos e ajustar (se for necessário) | E29: 42919 | F29: 43084 | G29: Equipe DP | I29: Concluído | J29: 42993 | K29: 1
C30: 2.11 | D30: Verificar todos os cargos se estão com os CBO corretos | E30: 42919 | F30: 43084 | G30: Equipe DP | I30: Concluído | J30: 42990 | K30: 1
C31: 2.12 | D31: Ajustar os cargos que estão com o CBO não correspondente ao cargo | E31: 42919 | F31: 43084 | G31: Equipe DP | I31: Concluído | J31: 42993 | K31: 1
... C37: 2.18 | D37: Analisar as tabelas de horários (Registro de Ponto) | E37: 42919 | F37: 43084 | G37: Equipe DP | I37: Concluído | J37: 42993 | K37: 1
H38: Percentual de conclusão desta etapa: | K38: =AVERAGE(K20:K37) -> 1
A40: 3 | B40: Readequação dos Processos Internos | E40: Prazo da Atividade | G40: Responsável | I40: Acompanhamento
E41: Início | F41: Fim | G41: Contabilidade | H41: Cliente | I41: Status | J41: Data conclusão | K41: % Conclusão
C42: 3.1 | D42: Analisar as Admissões se atendem as exigências do eSocial | E42: 42919 | F42: 43084 | G42: Equipe DP | I42: Concluído | J42: 43007 | K42: 1
C43: 3.2 | D43: Analisar se todas as admissões possuem exame admissional com data correta | E43: 42919 | F43: 43084 | G43: Equipe DP | I43: Concluído | J43: 43007 | K43: 1
C44: 3.3 | D44: Analisar o cadastro de todas as admissões no sistema, se estão corretos e completos | E44: 42919 | F44: 43084 | G44: Equipe DP | I44: Concluído | J44: 43007 | K44: 1
C45: 3.4 | D45: Analisar os contratos de Estagiários, se atendem as exigências do eSocial | E45: 42919 | F45: 43084 | G45: Equipe DP | I45: Concluído | J45: 42998 | K45: 1
C46: 3.5 | D46: Analisar a cota dos Menores Aprendizes | E46: 42919 | F46: 43084 | G46: Equipe DP | I46: Concluído | J46: 43000 | K46: 1
C47: 3.6 | D47: Analisar a cota das Pessoas com Deficiência | E47: 42919 | F47: 43084 | G47: Equipe DP | I47: Concluído | J47: 43000 | K47: 1
...

Sheet Resumo e Grafico
A3: ETAPAS DE IMPLANTAÇÃO DO e_SOCIAL | C3: % CONCLUSÃO XYZ INDUST S/A
A4: 1 | B4: Consciêntização Diretoria/Colab./Terceiros | C4: 1
A5: 2 | B5: Palestras com o Cliente sobre o eSocial | C5: 1
A6: 3 | B6: ='Atividades detalhadas'!B3 -> Qualificação Cadastral | C6: ='Atividades detalhadas'!K16 -> 0.90909091
A7: 4 | B7: ='Atividades detalhadas'!B18 -> Saneamento da Base - Análise de Impacto (Robô) | C7: ='Atividades detalhadas'!K38 -> 1
A8: 5 | B8: ='Atividades detalhadas'!B40 -> Readequação dos Processos Internos | C8: ='Atividades detalhadas'!K56 -> 0.98714286
A9: 6 | B9: Análise das Tabelas e Eventos | C9: =AVERAGE(C12:C55) -> 0.48769481
A10: 7 | B10: Entrega Oficial do eSocial | C10: =AVERAGE(C4:C8,C12:C55) -> 0.53785317
A12: 4 | B12: ='Atividades detalhadas'!B58 -> Análise da tabela S1000 - Informações do Empregador/Contribuinte | C12: ='Atividades detalhadas'!K78 -> 1
A13: 5 | B13: ='Atividades detalhadas'!B80 -> Análise da tabela S1005 - Tabela de Estabelecimentos, Obras ou Unidades de Órgãos Públicos | C13: ='Atividades detalhadas'!K102 -> 1
A14: 6 | B14: ='Atividades detalhadas'!B104 -> Análise da tabela S1010 - Tabela de Rúbricas | C14: ='Atividades detalhadas'!K120 -> 1
A15: 7 | B15: ='Atividades detalhadas'!B122 -> Análise da tabela S1020 - Lotações Tributárias | C15: ='Atividades detalhadas'!K138 -> 0.57857143
A16: 8 | B16: ='Atividades detalhadas'!B140 -> Análise da tabela S1030 - Tabela de Cargos/Empregos Públicos | C16: ='Atividades detalhadas'!K152 -> 0.9
A17: 9 | B17: ='Atividades detalhadas'!B154 -> Análise da tabela S1035 - Tabela de Carreiras Públicas | C17: ='Atividades detalhadas'!K164 -> 1
A18: 10 | B18: ='Atividades detalhadas'!B166 -> Análise da tabela S1040 - Tabela de Funções/Cargos em Comissão | C18: ='Atividades detalhadas'!K178 -> 1
A19: 11 | B19: ='Atividades detalhadas'!B180 -> Análise da tabela S1050 - Tabela de Horários/Turnos de Trabalho | C19: ='Atividades detalhadas'!K191 -> 1
A20: 12 | B20: ='Atividades detalhadas'!B193 -> Análise da tabela S1060 - Tabela de Ambientes de Trabalho | C20: ='Atividades detalhadas'!K203 -> 1
A21: 13 | B21: ='Atividades detalhadas'!B205 -> Análise da tabela S1070 - Tabela de Processos Administrativos/Judiciais | C21: ='Atividades detalhadas'!K215 -> 0
A22: 14 | B22: ='Atividades detalhadas'!B217 -> Análise da tabela S1080 - Tabela de Operadores Portuários | C22: ='Atividades detalhadas'!K226 -> 1
A23: 15 | B23: ='Atividades detalhadas'!B228 -> Análise da tabela S1200 - Remuneração de trabalhador vinculado ao Regime Geral de Previd. Social | C23: ='Atividades detalhadas'!K251 -> 1
A24: 16 | B24: ='Atividades detalhadas'!B253 -> Análise da tabela S1202 - Remuneração de servidor vinculado a Regime Próprio de Previd. Social | C24: ='Atividades detalhadas'!K265 -> 1
A25: 17 | B25: ='Atividades detalhadas'!B267 -> Análise da tabela S1207 - Benefícios previdenciários - RPPS | C25: ='Atividades detalhadas'!K275 -> 1
A26: 18 | B26: ='Atividades detalhadas'!B277 -> Análise da tabela S1210 - Pagamentos de Rendimentos do Trabalho | C26: ='Atividades detalhadas'!K293 -> 1
A27: 19 | B27: ='Atividades detalhadas'!B295 -> Análise da tabela S1250 - Aquisição de Produção Rural | C27: ='Atividades detalhadas'!K306 -> 1
A28: 20 | B28: ='Atividades detalhadas'!B308 -> Análise da tabela S1260 - Comercialização da Produção Rural Pessoa Física | C28: ='Atividades detalhadas'!K319 -> 1
A29: 21 | B29: ='Atividades detalhadas'!B321 -> Análise da tabela S1270 - Contratação de Trabalhadores Avulsos Não Portuários | C29: ='Atividades detalhadas'!K326 -> 1
A30: 22 | B30: ='Atividades detalhadas'!B328 -> Análise da tabela S1280 - Informações Complementares aos Eventos Periódicos | C30: ='Atividades detalhadas'!K335 -> 1
A31: 23 | B31: ='Atividades detalhadas'!B337 -> Análise da tabela S1295 - Solicitação de Totalização para Pagamento em Contingência | C31: ='Atividades detalhadas'!K343 -> 0
A32: 24 | B32: ='Atividades detalhadas'!B345 -> Análise da tabela S1298 - Reabertura dos Eventos Periódicos | C32: ='Atividades detalhadas'!K350 -> 0
A33: 25 | B33: ='Atividades detalhadas'!B352 -> Análise da tabela S1299 - Fechamento dos Eventos Periódicos | C33: ='Atividades detalhadas'!K358 -> 0
A34: 26 | B34: ='Atividades detalhadas'!B360 -> Análise da tabela S1300 - Contribuição Sindical Patronal | C34: ='Atividades detalhadas'!K365 -> 0
A35: 27 | B35: ='Atividades detalhadas'!B367 -> Análise da tabela S2190 - Admissão de Trabalhador - Registro Preliminar | C35: ='Atividades detalhadas'!K373 -> 1
A36: 28 | B36: ='Atividades detalhadas'!B375 -> Análise da tabela S2200 - Cadastramento Inicial do Vínculo e Admissão/Ingresso de Trabalhador | C36: ='Atividades detalhadas'!K395 -> 0.8
A37: 29 | B37: ='Atividades detalhadas'!B397 -> Análise da tabela S2205 - Alteração de Dados Cadastrais do Trabalhador | C37: ='Atividades detalhadas'!K417 -> 0
A38: 30 | B38: ='Atividades detalhadas'!B419 -> Análise da tabela S2206 - Alteração de Contrato de Trabalho | C38: ='Atividades detalhadas'!K442 -> 0
A39: 31 | B39: ='Atividades detalhadas'!B444 -> Análise da tabela S2210 - Comunicação de Acidente de Trabalho | C39: ='Atividades detalhadas'!K458 -> 0
A40: 32 | B40: ='Atividades detalhadas'!B460 -> Análise da tabela S2220 - Monitoramento da Saúde do Trabalhador (A partir de Julho/2017) | C40: ='Atividades detalhadas'!K472 -> 0
A41: 33 | B41: ='Atividades detalhadas'!B474 -> Análise da tabela S2230 - Afastamento Temporário | C41: ='Atividades detalhadas'!K487 -> 0
A42: 34 | B42: ='Atividades detalhadas'!B489 -> Análise da tabela S2240 - Condições Ambientais do Trabalho - Fatores de Risco (A partir de Julho/2017) | C42: ='Atividades detalhadas'!K504 -> 0
A43: 35 | B43: ='Atividades detalhadas'!B506 -> Análise da tabela S2241 - Insalubridade, Periculosidade e Aposentadoria Especial | C43: ='Atividades detalhadas'!K523 -> 0
...
